Workbook
Name _Dates_Conc: #REF!
Name _scen: #REF!
Name _scen1: #REF!
Name _scen2: #REF!
Name _SCenarios: #REF!
Name _Sens1: #REF!
Name _Sens2: #REF!
Name _sensRes1: #REF!
Name _sensRes2: #REF!
Name _sensRes3: #REF!
Name _sensRes4: #REF!
Name _sensRes5: #REF!
Name _sensRes6: #REF!
Name _sensRes7: #REF!
Name DateRange: #REF!
Name Monetary_Unit: #REF!
Name Months: #REF!
Name Rng_Dealers_Names: #REF!
Name Rng_Dlr_Dates: #REF!
Name Titre: #REF!

Sheet Paramètre
B3: Quarter | C3: Q2 2026
B6: BUDGET | F6: BUDGET RÉVISÉ | J6: ACTUAL | N6: LAST YEAR
B7: Ventes | C7: Profits bruts | D7: BAIIA | E7: EBIT | F7: Ventes | G7: Profits bruts | H7: BAIIA | I7: EBIT | J7: Ventes | K7: Profits bruts | L7: BAIIA | M7: EBIT | N7: Ventes | O7: Profits bruts | P7: BAIIA | Q7: EBIT
A8: CTRL | B8: =+B9-B10 -> #VALUE! | C8: =+C9-C10 -> 0 | D8: =+D9-D10 -> 0 | E8: =+E9-E10 -> 0 | F8: =+F9-F10 -> #VALUE! | G8: =+G9-G10 -> 0 | H8: =+H9-H10 -> 0 | I8: =+I9-I10 -> 0 | ... Q8: =+Q9-Q10 -> 0
A9: CONSO | B9: =+Conso!$Z$406 -> $TOTAL | C9: =+Conso!$Z$407 -> 18042432 | D9: =+Conso!$Z$483 -> 0 | E9: =+Conso!$Z$498 -> 0 | F9: =+Conso!$AC$406 -> $TOTAL | G9: =+Conso!$AC$407 -> 0 | H9: =+Conso!$AC$483 -> 0 | I9: =+Conso!$AC$498 -> 0 | J9: =+Conso!$AF$406 -> $TOTAL | K9: =+Conso!$AF$407 -> 19326469 | L9: =+Conso!$AF$483 -> 0 | M9: =+Conso!$AF$498 -> 0 | N9: =+Conso!$AL$406 -> $TOTAL | O9: =+Conso!$AL$407 -> 14964562 | P9: =+Conso!$AL$483 -> 0 | Q9: =+Conso!$AL$498 -> 0
A10: TOTAL | B10: =+SUM(B11:B13) -> 0 | C10: =+SUM(C11:C13) -> 18042432 | D10: =+SUM(D11:D13) -> 0 | E10: =+SUM(E11:E13) -> 0 | F10: =+SUM(F11:F13) -> 0 | G10: =+SUM(G11:G13) -> 0 | H10: =+SUM(H11:H13) -> 0 | I10: =+SUM(I11:I13) -> 0 | ... Q10: =+SUM(Q11:Q13) -> 0
A11: Mois 1 | B11: =+'Mois 1'!$Z$406 -> $TOTAL | C11: =+'Mois 1'!$Z$407 -> 5932390.6 | D11: =+'Mois 1'!$Z$483 -> 0 | E11: =+'Mois 1'!$Z$498 -> 0 | F11: =+'Mois 1'!$AC$406 -> 0 | G11: =+'Mois 1'!$AC$407 -> 0 | H11: =+'Mois 1'!$AC$483 -> 0 | I11: =+'Mois 1'!$AC$498 -> 0 | J11: =+'Mois 1'!$AF$406 -> $TOTAL | K11: =+'Mois 1'!$AF$407 -> 6155759.5 | L11: =+'Mois 1'!$AF$483 -> 0 | M11: =+'Mois 1'!$AF$498 -> 0 | N11: =+'Mois 1'!$AL$406 -> $TOTAL | O11: =+'Mois 1'!$AL$407 -> 4784256.5 | P11: =+'Mois 1'!$AL$483 -> 0 | Q11: =+'Mois 1'!$AL$498 -> 0
A12: Mois 2 | B12: =+'Mois 2'!$Z$406 -> $TOTAL | C12: =+'Mois 2'!$Z$407 -> 6617137.8 | D12: =+'Mois 2'!$Z$483 -> 0 | E12: =+'Mois 2'!$Z$498 -> 0 | F12: =+'Mois 2'!$AC$406 -> 0 | G12: =+'Mois 2'!$AC$407 -> 0 | H12: =+'Mois 2'!$AC$483 -> 0 | I12: =+'Mois 2'!$AC$498 -> 0 | J12: =+'Mois 2'!$AF$406 -> $TOTAL | K12: =+'Mois 2'!$AF$407 -> 6778938.7 | L12: =+'Mois 2'!$AF$483 -> 0 | M12: =+'Mois 2'!$AF$498 -> 0 | N12: =+'Mois 2'!$AL$406 -> $TOTAL | O12: =+'Mois 2'!$AL$407 -> 6366734.3 | P12: =+'Mois 2'!$AL$483 -> 0 | Q12: =+'Mois 2'!$AL$498 -> 0
A13: Mois 3 | B13: =+'Mois 3'!$Z$406 -> $TOTAL | C13: =+'Mois 3'!$Z$407 -> 5492903.3 | D13: =+'Mois 3'!$Z$483 -> 0 | E13: =+'Mois 3'!$Z$498 -> 0 | F13: =+'Mois 3'!$AC$406 -> 0 | G13: =+'Mois 3'!$AC$407 -> 0 | H13: =+'Mois 3'!$AC$483 -> 0 | I13: =+'Mois 3'!$AC$498 -> 0 | J13: =+'Mois 3'!$AF$406 -> $TOTAL | K13: =+'Mois 3'!$AF$407 -> 6391770.9 | L13: =+'Mois 3'!$AF$483 -> 0 | M13: =+'Mois 3'!$AF$498 -> 0 | N13: =+'Mois 3'!$AL$406 -> $TOTAL | O13: =+'Mois 3'!$AL$407 -> 3813571.5 | P13: =+'Mois 3'!$AL$483 -> 0 | Q13: =+'Mois 3'!$AL$498 -> 0

Sheet Conso
C1: BMW Sherbrooke | K1: Véhicules neufs | S1: =CONCATENATE("Réalisé"," ",Paramètre!$C$2," ",Paramètre!$C$3) -> Réalisé Q2 2026
D2: X | E2: O | F2: U | G2: X | H2: O | I2: U
D3: BUDGET ORIGINAL | G3: BUDGET REVISE | J3: RÉALISATION | M3: ÉCART réel / Budget | O3: ANNÉE PRÉCÉDENTE | R3: ECART (réel/ Ann.Préc.)
D4: UNITE | E4: $P/UNITÉ | F4: $PROFITS | G4: UNITE | H4: $P/UNITÉ | I4: $PROFITS | J4: UNITE | K4: $P/UNITE | L4: $PROFITS | M4: UNFTÉ | N4: $PROFITS | O4: UNITE | P4: $P/UNITE | Q4: $PROFITS | R4: UNITE | S4: $PROFITS
A5: =+B5&C5 -> Véhicules neufsVentes nettes | B5: =+$K$1 -> Véhicules neufs | C5: Ventes nettes | F5: =+SUM(START:END!F5) -> 9500834.8 | I5: =+SUM(START:END!I5) -> 0 | L5: =+SUM(START:END!L5) -> 10082677 | Q5: =+SUM(START:END!Q5) -> 8603227.3
A6: =+B6&C6 -> Véhicules neufsAutos détail | B6: =+$K$1 -> Véhicules neufs | C6: Autos détail | D6: =+SUM(START:END!D6) -> 28 | E6: =IF(D6=0,0,F6/D6) -> 4701.1765 | F6: =+SUM(START:END!F6) -> 131632.94 | G6: =+SUM(START:END!G6) -> 0 | H6: =IF(G6=0,0,I6/G6) -> 0 | I6: =+SUM(START:END!I6) -> 0 | J6: =+SUM(START:END!J6) -> 37 | K6: =IF(J6=0,0,L6/J6) -> 5547.4197 | L6: =+SUM(START:END!L6) -> 205254.53 | M6: =J6-D6 -> 9 | N6: =L6-F6 -> 73621.589 | O6: =+SUM(START:END!O6) -> 27 | P6: =IF(O6=0,0,Q6/O6) -> 5997.1281 | Q6: =+SUM(START:END!Q6) -> 161922.46 | R6: =J6-O6 -> 10 | S6: =L6-Q6 -> 43332.07
A7: =+B7&C7 -> Véhicules neufsCamions détail | B7: =+$K$1 -> Véhicules neufs | C7: Camions détail | D7: =+SUM(START:END!D7) -> 65 | E7: =IF(D7=0,0,F7/D7) -> 3928.5 | F7: =+SUM(START:END!F7) -> 255352.5 | G7: =+SUM(START:END!G7) -> 0 | H7: =IF(G7=0,0,I7/G7) -> 0 | I7: =+SUM(START:END!I7) -> 0 | J7: =+SUM(START:END!J7) -> 45 | K7: =IF(J7=0,0,L7/J7) -> 3957.2978 | L7: =+SUM(START:END!L7) -> 178078.4 | M7: =J7-D7 -> -20 | N7: =L7-F7 -> -77274.1 | O7: =+SUM(START:END!O7) -> 45 | P7: =IF(O7=0,0,Q7/O7) -> 4008.3438 | Q7: =+SUM(START:END!Q7) -> 180375.47 | R7: =J7-O7 -> 0 | S7: =L7-Q7 -> -2297.07
A8: =+B8&C8 -> Véhicules neufsSprinter | B8: =+$K$1 -> Véhicules neufs | C8: Sprinter | D8: =+SUM(START:END!D8) -> 0 | E8: =IF(D8=0,0,F8/D8) -> 0 | F8: =+SUM(START:END!F8) -> 0 | G8: =+SUM(START:END!G8) -> 0 | H8: =IF(G8=0,0,I8/G8) -> 0 | I8: =+SUM(START:END!I8) -> 0 | J8: =+SUM(START:END!J8) -> 0 | K8: =IF(J8=0,0,L8/J8) -> 0 | L8: =+SUM(START:END!L8) -> 0 | M8: =J8-D8 -> 0 | N8: =L8-F8 -> 0 | O8: =+SUM(START:END!O8) -> 0 | P8: =IF(O8=0,0,Q8/O8) -> 0 | Q8: =+SUM(START:END!Q8) -> 0 | R8: =J8-O8 -> 0 | S8: =L8-Q8 -> 0
A9: =+B9&C9 -> Véhicules neufsMoto détail | B9: =+$K$1 -> Véhicules neufs | C9: Moto détail | D9: =+SUM(START:END!D9) -> 0 | E9: =IF(D9=0,0,F9/D9) -> 0 | F9: =+SUM(START:END!F9) -> 0 | G9: =+SUM(START:END!G9) -> 0 | H9: =IF(G9=0,0,I9/G9) -> 0 | I9: =+SUM(START:END!I9) -> 0 | J9: =+SUM(START:END!J9) -> 0 | K9: =IF(J9=0,0,L9/J9) -> 0 | L9: =+SUM(START:END!L9) -> 0 | M9: =J9-D9 -> 0 | N9: =L9-F9 -> 0 | O9: =+SUM(START:END!O9) -> 0 | P9: =IF(O9=0,0,Q9/O9) -> 0 | Q9: =+SUM(START:END!Q9) -> 0 | R9: =J9-O9 -> 0 | S9: =L9-Q9 -> 0
A10: =+B10&C10 -> Véhicules neufs[...] | B10: =+$K$1 -> Véhicules neufs | C10: [...] | D10: =+SUM(START:END!D10) -> 0 | E10: =IF(D10=0,0,F10/D10) -> 0 | F10: =+SUM(START:END!F10) -> 0 | G10: =+SUM(START:END!G10) -> 0 | H10: =IF(G10=0,0,I10/G10) -> 0 | I10: =+SUM(START:END!I10) -> 0 | J10: =+SUM(START:END!J10) -> 0 | K10: =IF(J10=0,0,L10/J10) -> 0 | L10: =+SUM(START:END!L10) -> 0 | M10: =J10-D10 -> 0 | N10: =L10-F10 -> 0 | O10: =+SUM(START:END!O10) -> 0 | P10: =IF(O10=0,0,Q10/O10) -> 0 | Q10: =+SUM(START:END!Q10) -> 0 | R10: =J10-O10 -> 0 | S10: =L10-Q10 -> 0
A11: =+B11&C11 -> Véhicules neufs[...] | B11: =+$K$1 -> Véhicules neufs | C11: [...] | D11: =+SUM(START:END!D11) -> 0 | E11: =IF(D11=0,0,F11/D11) -> 0 | F11: =+SUM(START:END!F11) -> 0 | G11: =+SUM(START:END!G11) -> 0 | H11: =IF(G11=0,0,I11/G11) -> 0 | I11: =+SUM(START:END!I11) -> 0 | J11: =+SUM(START:END!J11) -> 0 | K11: =IF(J11=0,0,L11/J11) -> 0 | L11: =+SUM(START:END!L11) -> 0 | M11: =J11-D11 -> 0 | N11: =L11-F11 -> 0 | O11: =+SUM(START:END!O11) -> 0 | P11: =IF(O11=0,0,Q11/O11) -> 0 | Q11: =+SUM(START:END!Q11) -> 0 | R11: =J11-O11 -> 0 | S11: =L11-Q11 -> 0
A12: =+B12&C12 -> Véhicules neufs[...] | B12: =+$K$1 -> Véhicules neufs | C12: [...] | D12: =+SUM(START:END!D12) -> 0 | E12: =IF(D12=0,0,F12/D12) -> 0 | F12: =+SUM(START:END!F12) -> 0 | G12: =+SUM(START:END!G12) -> 0 | H12: =IF(G12=0,0,I12/G12) -> 0 | I12: =+SUM(START:END!I12) -> 0 | J12: =+SUM(START:END!J12) -> 0 | K12: =IF(J12=0,0,L12/J12) -> 0 | L12: =+SUM(START:END!L12) -> 0 | M12: =J12-D12 -> 0 | N12: =L12-F12 -> 0 | O12: =+SUM(START:END!O12) -> 0 | P12: =IF(O12=0,0,Q12/O12) -> 0 | Q12: =+SUM(START:END!Q12) -> 0 | R12: =J12-O12 -> 0 | S12: =L12-Q12 -> 0
A13: =+B13&C13 -> Véhicules neufsTotal Neufs | B13: =+$K$1 -> Véhicules neufs | C13: Total Neufs | D13: =+SUM(D6:D12) -> 93 | E13: =IF(D13<=0,0,F13/D13) -> 4161.1338 | F13: =+SUM(F6:F12) -> 386985.44 | G13: =+SUM(G6:G12) -> 0 | H13: =IF(G13<=0,0,I13/G13) -> 0 | I13: =+SUM(I6:I12) -> 0 | J13: =+SUM(J6:J12) -> 82 | K13: =IF(J13<=0,0,L13/J13) -> 4674.7918 | L13: =+SUM(L6:L12) -> 383332.93 | M13: =+SUM(M6:M12) -> -11 | N13: =+SUM(N6:N12) -> -3652.5112 | O13: =+SUM(O6:O12) -> 72 | P13: =IF(O13<=0,0,Q13/O13) -> 4754.1379 | Q13: =+SUM(Q6:Q12) -> 342297.93 | R13: =+SUM(R6:R12) -> 10 | S13: =+SUM(S6:S12) -> 41035
A14: =+B14&C14 -> Véhicules neufs | B14: =+$K$1 -> Véhicules neufs | M14: =IF(D13=0,0,M13/D13) -> -0.11827957 | N14: =IF(F13=0,0,N13/F13) -> -0.0094383684 | R14: =R13/O13 -> 0.13888889 | S14: =IF(Q13=0,0,(S13/Q13)) -> 0.11988095
A15: =+B15&C15 -> Véhicules neufsEx-Démos et courtoisies | B15: =+$K$1 -> Véhicules neufs | C15: Ex-Démos et courtoisies | D15: =+SUM(START:END!D15) -> 10 | E15: =IF(D15=0,0,F15/D15) -> 1200 | F15: =+SUM(START:END!F15) -> 12000 | G15: =+SUM(START:END!G15) -> 0 | H15: =IF(G15=0,0,I15/G15) -> 0 | I15: =+SUM(START:END!I15) -> 0 | J15: =+SUM(START:END!J15) -> 11 | K15: =IF(J15=0,0,L15/J15) -> 398.09545 | L15: =+SUM(START:END!L15) -> 4379.05 | M15: =J15-D15 -> 1 | N15: =L15-F15 -> -7620.95 | O15: =+SUM(START:END!O15) -> 21 | P15: =IF(O15=0,0,Q15/O15) -> 2815.8662 | Q15: =+SUM(START:END!Q15) -> 59133.19 | R15: =J15-O15 -> -10 | S15: =L15-Q15 -> -54754.14
A16: =+B16&C16 -> Véhicules neufs | B16: =+$K$1 -> Véhicules neufs
A17: =+B17&C17 -> Véhicules neufsFlottes | B17: =+$K$1 -> Véhicules neufs | C17: Flottes | D17: =+SUM(START:END!D17) -> 6 | E17: =IF(D17=0,0,F17/D17) -> 750 | F17: =+SUM(START:END!F17) -> 4500 | G17: =+SUM(START:END!G17) -> 0 | H17: =IF(G17=0,0,I17/G17) -> 0 | I17: =+SUM(START:END!I17) -> 0 | J17: =+SUM(START:END!J17) -> 11 | K17: =IF(J17=0,0,L17/J17) -> 484.49727 | L17: =+SUM(START:END!L17) -> 5329.47 | M17: =J17-D17 -> 5 | N17: =L17-F17 -> 829.47 | O17: =+SUM(START:END!O17) -> 0 | P17: =IF(O17=0,0,Q17/O17) -> 0 | Q17: =+SUM(START:END!Q17) -> 0 | R17: =J17-O17 -> 11 | S17: =L17-Q17 -> 5329.47
A18: =+B18&C18 -> Véhicules neufs | B18: =+$K$1 -> Véhicules neufs
A19: =+B19&C19 -> Véhicules neufsRachat bail | B19: =+$K$1 -> Véhicules neufs | C19: Rachat bail | F19: =+SUM(START:END!F19) -> 0 | I19: =+SUM(START:END!I19) -> 0 | L19: =+SUM(START:END!L19) -> 0 | N19: =L19-F19 -> 0 | Q19: =+SUM(START:END!Q19) -> 0 | R19: =O19-K19 -> 0 | S19: =L19-Q19 -> 0
A20: =+B20&C20 -> Véhicules neufs | B20: =+$K$1 -> Véhicules neufs
A21: =+B21&C21 -> Véhicules neufsRev. Finances | B21: =+$K$1 -> Véhicules neufs | C21: Rev. Finances | D21: 0 | E21: =IF(D21=0,0,F21/D21) -> 0 | F21: =+SUM(START:END!F21) -> 721 | G21: 0 | H21: =IF(G21=0,0,I21/G21) -> 0 | I21: =+SUM(START:END!I21) -> 0 | K21: =IF(J13=0,0,L21/(J13+J15)) -> 14.300108 | L21: =+SUM(START:END!L21) -> 1329.91 | N21: =L21-F21 -> 608.91 | P21: =IF(O13=0,0,Q21/(O13+O15)) -> 5.2893548 | Q21: =+SUM(START:END!Q21) -> 491.91 | R21: =O21-K21 -> -14.300108 | S21: =L21-Q21 -> 838
A22: =+B22&C22 -> Véhicules neufsRev. Protections | B22: =+$K$1 -> Véhicules neufs | C22: Rev. Protections | D22: 0 | E22: =IF(D22=0,0,F22/D22) -> 0 | F22: =+SUM(START:END!F22) -> 118450 | G22: 0 | H22: =IF(G22=0,0,I22/G22) -> 0 | I22: =+SUM(START:END!I22) -> 0 | K22: =IF(J13=0,0,L22/(J13+J15)) -> 563.04624 | L22: =+SUM(START:END!L22) -> 52363.3 | N22: =L22-F22 -> -66086.7 | P22: =IF(O13=0,0,Q22/(O13+O15)) -> 1464.1901 | Q22: =+SUM(START:END!Q22) -> 136169.68 | R22: =O22-K22 -> -563.04624 | S22: =L22-Q22 -> -83806.38
A23: =+B23&C23 -> Véhicules neufsRev. Autres | B23: =+$K$1 -> Véhicules neufs | C23: Rev. Autres | D23: 0 | E23: =IF(D23=0,0,F23/D23) -> 0 | F23: =+SUM(START:END!F23) -> 45629 | G23: 0 | H23: =IF(G23=0,0,I23/G23) -> 0 | I23: =+SUM(START:END!I23) -> 0 | K23: =IF(J13=0,0,L23/(J13+J15)) -> 495.57247 | L23: =+SUM(START:END!L23) -> 46088.24 | N23: =L23-F23 -> 459.24 | P23: =IF(O13=0,0,Q23/(O13+O15)) -> 802.84452 | Q23: =+SUM(START:END!Q23) -> 74664.54 | R23: =O23-K23 -> -495.57247 | S23: =L23-Q23 -> -28576.3
A24: =+B24&C24 -> Véhicules neufsTotal F&I | B24: =+$K$1 -> Véhicules neufs | C24: Total F&I | D24: =+D15+D13 -> 103 | E24: =IF(D24<=0,0,F24/D24) -> 1600 | F24: =F21+F22+F23 -> 164800 | G24: =+G15+G13 -> 0 | H24: =IF(G24<=0,0,I24/G24) -> 0 | I24: =I21+I22+I23 -> 0 | J24: =+J15+J13 -> 93 | K24: =IF(J24<=0,0,L24/J24) -> 1072.9188 | L24: =L21+L22+L23 -> 99781.45 | M24: =J24-D24 -> -10 | N24: =L24-F24 -> -65018.55 | O24: =+O15+O13 -> 93 | P24: =IF(O24<=0,0,Q24/O24) -> 2272.324 | Q24: =Q21+Q22+Q23 -> 211326.13 | S24: =L24-Q24 -> -111544.68
A25: =+B25&C25 -> Véhicules neufs | B25: =+$K$1 -> Véhicules neufs | N25: =IF(N24=0,0,N24/F24) -> -0.39453004 | S25: =IF(Q24=0,0,(S24/Q24)) -> -0.52783193
A26: =+B26&C26 -> Véhicules neufs | B26: =+$K$1 -> Véhicules neufs
A27: =+B27&C27 -> Véhicules neufsTotal Dépt. Neufs | B27: =+$K$1 -> Véhicules neufs | C27: Total Dépt. Neufs | D27: =+D13+D15+D17 -> 109 | E27: =IF(D27<=0,0,F27/D27) -> 5213.6279 | F27: =F13+F17+F24+F19+F15 -> 568285.44 | G27: =+G13+G15+G17 -> 0 | H27: =IF(G27<=0,0,I27/G27) -> 0 | I27: =I13+I17+I24+I19+I15 -> 0 | J27: =+J13+J15+J17 -> 104 | K27: =IF(J27<=0,0,L27/J27) -> 4738.6817 | L27: =L13+L17+L24+L19+L15 -> 492822.9 | M27: =J27-D27 -> -5 | N27: =L27-F27 -> -75462.541 | O27: =+O13+O15+O17 -> 93 | P27: =IF(O27<=0,0,Q27/O27) -> 6588.7876 | Q27: =Q13+Q17+Q24+Q19+Q15 -> 612757.25 | R27: =J27-O27 -> 11 | S27: =L27-Q27 -> -119934.35
A28: =+B28&C28 -> Véhicules neufs | B28: =+$K$1 -> Véhicules neufs | M28: =M27/D27 -> -0.04587156 | N28: =N27/F27 -> -0.13278985 | R28: =R27/O27 -> 0.11827957 | S28: =IF(Q27=0,0,S27/Q27) -> -0.19572898
A29: =+B29&C29 -> Véhicules neufs | B29: =+$K$1 -> Véhicules neufs
A30: =+B30&C30 -> Véhicules neufsDEPENSES | B30: =+$K$1 -> Véhicules neufs | C30: DEPENSES
A31: =+B31&C31 -> Véhicules neufsComm. vendeurs | B31: =+$K$1 -> Véhicules neufs | C31: Comm. vendeurs | D31: =F31/(F13+F15) -> 0.27413523 | E31: =F31/D$24 -> 1061.9026 | F31: =+SUM(START:END!F31) -> 109375.96 | H31: =I31/G$24 -> #DIV/0! | I31: =+SUM(START:END!I31) -> 0 | J31: =L31/(L13+L15) -> 0.26539273 | K31: =IF(L31=0,0,L31/J$24) -> 1106.408 | L31: =+SUM(START:END!L31) -> 102895.94 | N31: =L31-F31 -> -6480.0237 | O31: =Q31/(Q13+Q15+Q17) -> 0.25727176 | P31: =IF(Q31=0,0,Q31/O$24) -> 1110.5042 | Q31: =+SUM(START:END!Q31) -> 103276.89 | S31: =L31-Q31 -> -380.95
A32: =+B32&C32 -> Véhicules neufsComm. F&I | B32: =+$K$1 -> Véhicules neufs | C32: Comm. F&I | D32: =F32/F24 -> 0.305 | E32: =F32/D$24 -> 488 | F32: =+SUM(START:END!F32) -> 50264 | H32: =I32/G$24 -> #DIV/0! | I32: =+SUM(START:END!I32) -> 0 | J32: =L32/L24 -> 0.23001189 | K32: =IF(L32=0,0,L32/J$24) -> 246.78409 | L32: =+SUM(START:END!L32) -> 22950.92 | N32: =L32-F32 -> -27313.08 | O32: =Q32/Q24 -> 0.3409876 | P32: =IF(Q32=0,0,Q32/O$24) -> 774.8343 | Q32: =+SUM(START:END!Q32) -> 72059.59 | S32: =L32-Q32 -> -49108.67
A33: =+B33&C33 -> Véhicules neufsFrais de livraison | B33: =+$K$1 -> Véhicules neufs | C33: Frais de livraison | E33: =F33/D$24 -> 120 | F33: =+SUM(START:END!F33) -> 12360 | H33: =I33/G$24 -> #DIV/0! | I33: =+SUM(START:END!I33) -> 0 | K33: =IF(L33=0,0,L33/J$24) -> 167.99355 | L33: =+SUM(START:END!L33) -> 15623.4 | N33: =L33-F33 -> 3263.4 | P33: =IF(Q33=0,0,Q33/O$24) -> 122.49 | Q33: =+SUM(START:END!Q33) -> 11391.57 | S33: =L33-Q33 -> 4231.83
A34: =+B34&C34 -> Véhicules neufsService gratuit 1 | B34: =+$K$1 -> Véhicules neufs | C34: Service gratuit 1 | E34: =F34/D$24 -> 35 | F34: =+SUM(START:END!F34) -> 3605 | H34: =I34/G$24 -> #DIV/0! | I34: =+SUM(START:END!I34) -> 0 | K34: =IF(L34=0,0,L34/J$24) -> 51.072366 | L34: =+SUM(START:END!L34) -> 4749.73 | N34: =L34-F34 -> 1144.73 | P34: =IF(Q34=0,0,Q34/O$24) -> 37.78129 | Q34: =+SUM(START:END!Q34) -> 3513.66 | S34: =L34-Q34 -> 1236.07
A35: =+B35&C35 -> Véhicules neufsEntretien stock | B35: =+$K$1 -> Véhicules neufs | C35: Entretien stock | E35: =F35/D$24 -> 95.718447 | F35: =+SUM(START:END!F35) -> 9859 | H35: =I35/G$24 -> #DIV/0! | I35: =+SUM(START:END!I35) -> 0 | K35: =IF(L35=0,0,L35/J$24) -> 96.994086 | L35: =+SUM(START:END!L35) -> 9020.45 | N35: =L35-F35 -> -838.55 | P35: =IF(Q35=0,0,Q35/O$24) -> 52.236774 | Q35: =+SUM(START:END!Q35) -> 4858.02 | S35: =L35-Q35 -> 4162.43
A36: =+B36&C36 -> Véhicules neufsPublicité 1 | B36: =+$K$1 -> Véhicules neufs | C36: Publicité 1 | E36: =F36/D$24 -> 234.88788 | F36: =+SUM(START:END!F36) -> 24193.452 | H36: =I36/G$24 -> #DIV/0! | I36: =+SUM(START:END!I36) -> 0 | K36: =IF(L36=0,0,L36/J$24) -> 180.01914 | L36: =+SUM(START:END!L36) -> 16741.78 | N36: =L36-F36 -> -7451.6715 | P36: =IF(Q36=0,0,Q36/O$24) -> 494.38527 | Q36: =+SUM(START:END!Q36) -> 45977.83 | S36: =L36-Q36 -> -29236.05
A37: =+B37&C37 -> Véhicules neufsIntérêt de gros | B37: =+$K$1 -> Véhicules neufs | C37: Intérêt de gros | E37: =F37/D$24 -> 686.46233 | F37: =+SUM(START:END!F37) -> 70705.62 | H37: =I37/G$24 -> #DIV/0! | I37: =+SUM(START:END!I37) -> 0 | K37: =IF(L37=0,0,L37/J$24) -> 689.2943 | L37: =+SUM(START:END!L37) -> 64104.37 | N37: =L37-F37 -> -6601.2505 | P37: =IF(Q37=0,0,Q37/O$24) -> 800.39151 | Q37: =+SUM(START:END!Q37) -> 74436.41 | S37: =L37-Q37 -> -10332.04
A38: =+B38&C38 -> Véhicules neufs[...] | B38: =+$K$1 -> Véhicules neufs | C38: [...] | E38: =F38/D$24 -> 0 | F38: =+SUM(START:END!F38) -> 0 | H38: =I38/G$24 -> #DIV/0! | I38: =+SUM(START:END!I38) -> 0 | K38: =IF(L38=0,0,L38/J$24) -> 0 | L38: =+SUM(START:END!L38) -> 0 | N38: =L38-F38 -> 0 | P38: =IF(Q38=0,0,Q38/O$24) -> 0 | Q38: =+SUM(START:END!Q38) -> 0 | S38: =L38-Q38 -> 0
A39: =+B39&C39 -> Véhicules neufs[...] | B39: =+$K$1 -> Véhicules neufs | C39: [...] | E39: =F39/D$24 -> 0 | F39: =+SUM(START:END!F39) -> 0 | H39: =I39/G$24 -> #DIV/0! | I39: =+SUM(START:END!I39) -> 0 | K39: =IF(L39=0,0,L39/J$24) -> 0 | L39: =+SUM(START:END!L39) -> 0 | N39: =L39-F39 -> 0 | P39: =IF(Q39=0,0,Q39/O$24) -> 0 | Q39: =+SUM(START:END!Q39) -> 0 | S39: =L39-Q39 -> 0
A40: =+B40&C40 -> Véhicules neufs[...] | B40: =+$K$1 -> Véhicules neufs | C40: [...] | E40: =F40/D$24 -> 0 | F40: =+SUM(START:END!F40) -> 0 | H40: =I40/G$24 -> #DIV/0! | I40: =+SUM(START:END!I40) -> 0 | K40: =IF(L40=0,0,L40/J$24) -> 0 | L40: =+SUM(START:END!L40) -> 0 | N40: =L40-F40 -> 0 | P40: =IF(Q40=0,0,Q40/O$24) -> 0 | Q40: =+SUM(START:END!Q40) -> 0 | S40: =L40-Q40 -> 0
...

Sheet START

Sheet Mois 1
C1: BMW Sherbrooke | K1: Véhicules neufs | S1: Réalisé, Avril 2026
D2: X | E2: O | F2: U | J2: NB | L2: $ | O2: X | P2: O | Q2: U
D3: BUDGET ORIGINAL | J3: RÉALISATION | M3: ÉCART réel / Budget | O3: ANNÉE PRÉCÉDENTE | R3: ECART (réel/ Ann.Préc.)
D4: UNITE | E4: $P/UNITÉ | F4: $PROFITS | J4: UNITE | K4: $P/UNITE | L4: $PROFITS | M4: UNFTÉ | N4: $PROFITS | O4: UNITE | P4: $P/UNITÉ | Q4: $PROFITS | R4: UNITE | S4: $PROFITS
A5: =+B5&C5 -> Véhicules neufsVentes nettes | B5: =+$K$1 -> Véhicules neufs | C5: Ventes nettes | F5: 3149139.2 | L5: 2930239.2 | Q5: 2822748.8
A6: =+B6&C6 -> Véhicules neufsAutos détail | B6: =+$K$1 -> Véhicules neufs | C6: Autos détail | D6: 10 | E6: =IF(D6=0,0,F6/D6) -> 4701.1765 | F6: 47011.765 | J6: 10 | K6: =IF(J6=0,0,L6/J6) -> 4249.874 | L6: 42498.74 | M6: =J6-D6 -> 0 | N6: =L6-F6 -> -4513.0247 | O6: 6 | P6: =IF(O6=0,0,Q6/O6) -> 6338.2117 | Q6: 38029.27 | R6: =J6-O6 -> 4 | S6: =L6-Q6 -> 4469.47
A7: =+B7&C7 -> Véhicules neufsCamions détail | B7: =+$K$1 -> Véhicules neufs | C7: Camions détail | D7: 20 | E7: =IF(D7=0,0,F7/D7) -> 3928.5 | F7: 78570 | J7: 15 | K7: =IF(J7=0,0,L7/J7) -> 3894.7053 | L7: 58420.58 | M7: =J7-D7 -> -5 | N7: =L7-F7 -> -20149.42 | O7: 15 | P7: =IF(O7=0,0,Q7/O7) -> 4719.5127 | Q7: 70792.69 | R7: =J7-O7 -> 0 | S7: =L7-Q7 -> -12372.11
A8: =+B8&C8 -> Véhicules neufsSprinter | B8: =+$K$1 -> Véhicules neufs | C8: Sprinter | D8: 0 | E8: =IF(D8=0,0,F8/D8) -> 0 | F8: 0 | J8: 0 | K8: =IF(J8=0,0,L8/J8) -> 0 | L8: 0 | M8: =J8-D8 -> 0 | N8: =L8-F8 -> 0 | O8: 0 | P8: =IF(O8=0,0,Q8/O8) -> 0 | Q8: 0 | R8: =J8-O8 -> 0 | S8: =L8-Q8 -> 0
A9: =+B9&C9 -> Véhicules neufsMoto détail | B9: =+$K$1 -> Véhicules neufs | C9: Moto détail | D9: 0 | E9: =IF(D9=0,0,F9/D9) -> 0 | F9: 0 | J9: 0 | K9: =IF(J9=0,0,L9/J9) -> 0 | L9: 0 | M9: =J9-D9 -> 0 | N9: =L9-F9 -> 0 | O9: 0 | P9: =IF(O9=0,0,Q9/O9) -> 0 | Q9: 0 | R9: =J9-O9 -> 0 | S9: =L9-Q9 -> 0
A10: =+B10&C10 -> Véhicules neufs[...] | B10: =+$K$1 -> Véhicules neufs | C10: [...] | D10: 0 | E10: =IF(D10=0,0,F10/D10) -> 0 | F10: 0 | J10: 0 | K10: =IF(J10=0,0,L10/J10) -> 0 | L10: 0 | M10: =J10-D10 -> 0 | N10: =L10-F10 -> 0 | O10: 0 | P10: =IF(O10=0,0,Q10/O10) -> 0 | Q10: 0 | R10: =J10-O10 -> 0 | S10: =L10-Q10 -> 0
A11: =+B11&C11 -> Véhicules neufs[...] | B11: =+$K$1 -> Véhicules neufs | C11: [...] | D11: 0 | E11: =IF(D11=0,0,F11/D11) -> 0 | F11: 0 | J11: 0 | K11: =IF(J11=0,0,L11/J11) -> 0 | L11: 0 | M11: =J11-D11 -> 0 | N11: =L11-F11 -> 0 | O11: 0 | P11: =IF(O11=0,0,Q11/O11) -> 0 | Q11: 0 | R11: =J11-O11 -> 0 | S11: =L11-Q11 -> 0
A12: =+B12&C12 -> Véhicules neufs[...] | B12: =+$K$1 -> Véhicules neufs | C12: [...] | D12: 0 | E12: =IF(D12=0,0,F12/D12) -> 0 | F12: 0 | J12: 0 | K12: =IF(J12=0,0,L12/J12) -> 0 | L12: 0 | M12: =J12-D12 -> 0 | N12: =L12-F12 -> 0 | O12: 0 | P12: =IF(O12=0,0,Q12/O12) -> 0 | Q12: 0 | R12: =J12-O12 -> 0 | S12: =L12-Q12 -> 0
A13: =+B13&C13 -> Véhicules neufsTotal Neufs | B13: =+$K$1 -> Véhicules neufs | C13: Total Neufs | D13: =+SUM(D6:D12) -> 30 | E13: =IF(D13<=0,0,F13/D13) -> 4186.0588 | F13: =+SUM(F6:F12) -> 125581.76 | J13: =+SUM(J6:J12) -> 25 | K13: =IF(J13<=0,0,L13/J13) -> 4036.7728 | L13: =+SUM(L6:L12) -> 100919.32 | M13: =+SUM(M6:M12) -> -5 | N13: =+SUM(N6:N12) -> -24662.445 | O13: =+SUM(O6:O12) -> 21 | P13: =IF(O13<=0,0,Q13/O13) -> 5181.9981 | Q13: =+SUM(Q6:Q12) -> 108821.96 | R13: =+SUM(R6:R12) -> 4 | S13: =+SUM(S6:S12) -> -7902.64
A14: =+B14&C14 -> Véhicules neufs | B14: =+$K$1 -> Véhicules neufs | M14: =IF(D13=0,0,M13/D13) -> -0.16666667 | N14: =IF(F13=0,0,N13/F13) -> -0.19638556 | R14: =R13/O13 -> 0.19047619 | S14: =IF(Q13=0,0,(S13/Q13)) -> -0.072619901
A15: =+B15&C15 -> Véhicules neufsEx-Démos et courtoisies | B15: =+$K$1 -> Véhicules neufs | C15: Ex-Démos et courtoisies | D15: 4 | E15: =IF(D15=0,0,F15/D15) -> 1200 | F15: 4800 | J15: 1 | K15: =IF(J15=0,0,L15/J15) -> 1824.91 | L15: 1824.91 | M15: =J15-D15 -> -3 | N15: =L15-F15 -> -2975.09 | O15: 8 | P15: =IF(O15=0,0,Q15/O15) -> 2225.18 | Q15: 17801.44 | R15: =J15-O15 -> -7 | S15: =L15-Q15 -> -15976.53
A16: =+B16&C16 -> Véhicules neufs | B16: =+$K$1 -> Véhicules neufs
A17: =+B17&C17 -> Véhicules neufsFlottes | B17: =+$K$1 -> Véhicules neufs | C17: Flottes | D17: 2 | E17: =IF(D17=0,0,F17/D17) -> 750 | F17: 1500 | J17: 5 | K17: =IF(J17=0,0,L17/J17) -> 1065.894 | L17: 5329.47 | M17: =J17-D17 -> 3 | N17: =L17-F17 -> 3829.47 | O17: 0 | P17: =IF(O17=0,0,Q17/O17) -> 0 | Q17: 0 | R17: =J17-O17 -> 5 | S17: =L17-Q17 -> 5329.47
A18: =+B18&C18 -> Véhicules neufs | B18: =+$K$1 -> Véhicules neufs
B19: =+$K$1 -> Véhicules neufs
A20: =+B20&C20 -> Véhicules neufs | B20: =+$K$1 -> Véhicules neufs
A21: =+B21&C21 -> Véhicules neufsRev. Finances | B21: =+$K$1 -> Véhicules neufs | C21: Rev. Finances | E21: =IF(D13=0,0,F21/(D13+D15)) -> 7 | F21: 238 | K21: =IF(J13=0,0,L21/(J13+J15)) -> 51.150385 | L21: 1329.91 | N21: =L21-F21 -> 1091.91 | P21: =IF(O13=0,0,Q21/(O13+O15)) -> 16.962414 | Q21: 491.91 | R21: =O21-K21 -> -51.150385 | S21: =L21-Q21 -> 838
A22: =+B22&C22 -> Véhicules neufsRev. Protections | B22: =+$K$1 -> Véhicules neufs | C22: Rev. Protections | E22: =IF(D13=0,0,F22/(D13+D15)) -> 1150 | F22: 39100 | K22: =IF(J13=0,0,L22/(J13+J15)) -> 685.80769 | L22: 17831 | N22: =L22-F22 -> -21269 | P22: =IF(O13=0,0,Q22/(O13+O15)) -> 1674.7852 | Q22: 48568.77 | R22: =O22-K22 -> -685.80769 | S22: =L22-Q22 -> -30737.77
A23: =+B23&C23 -> Véhicules neufsRev. Autres | B23: =+$K$1 -> Véhicules neufs | C23: Rev. Autres | E23: =IF(D13=0,0,F23/(D13+D15)) -> 443 | F23: 15062 | K23: =IF(J13=0,0,L23/(J13+J15)) -> 451.71308 | L23: 11744.54 | N23: =L23-F23 -> -3317.46 | P23: =IF(O13=0,0,Q23/(O13+O15)) -> 843.75828 | Q23: 24468.99 | R23: =O23-K23 -> -451.71308 | S23: =L23-Q23 -> -12724.45
A24: =+B24&C24 -> Véhicules neufsTotal F&I | B24: =+$K$1 -> Véhicules neufs | C24: Total F&I | D24: =+D15+D13 -> 34 | E24: =IF(D24<=0,0,F24/D24) -> 1600 | F24: =F21+F22+F23 -> 54400 | J24: =+J15+J13 -> 26 | K24: =IF(J24<=0,0,L24/J24) -> 1188.6712 | L24: =L21+L22+L23 -> 30905.45 | M24: =J24-D24 -> -8 | N24: =L24-F24 -> -23494.55 | O24: =+O15+O13 -> 29 | P24: =IF(O24<=0,0,Q24/O24) -> 2535.5059 | Q24: =Q21+Q22+Q23 -> 73529.67 | S24: =L24-Q24 -> -42624.22
A25: =+B25&C25 -> Véhicules neufs | B25: =+$K$1 -> Véhicules neufs | N25: =IF(N24=0,0,N24/F24) -> -0.43188511 | S25: =IF(Q24=0,0,(S24/Q24)) -> -0.57968736
A26: =+B26&C26 -> Véhicules neufs | B26: =+$K$1 -> Véhicules neufs
A27: =+B27&C27 -> Véhicules neufsTotal Dépt. Neufs | B27: =+$K$1 -> Véhicules neufs | C27: Total Dépt. Neufs | D27: =+D13+D15+D17 -> 36 | E27: =IF(D27<=0,0,F27/D27) -> 5174.4935 | F27: =F13+F17+F24+F15 -> 186281.76 | J27: =+J13+J15+J17 -> 31 | K27: =IF(J27<=0,0,L27/J27) -> 4483.1984 | L27: =L13+L17+L24+L15 -> 138979.15 | M27: =J27-D27 -> -5 | N27: =L27-F27 -> -47302.615 | O27: =+O13+O15+O17 -> 29 | P27: =IF(O27<=0,0,Q27/O27) -> 6901.83 | Q27: =Q13+Q17+Q24+Q15 -> 200153.07 | R27: =J27-O27 -> 2 | S27: =L27-Q27 -> -61173.92
A28: =+B28&C28 -> Véhicules neufs | B28: =+$K$1 -> Véhicules neufs | M28: =M27/D27 -> -0.13888889 | N28: =N27/F27 -> -0.25393046 | R28: =R27/O27 -> 0.068965517 | S28: =IF(Q27=0,0,S27/Q27) -> -0.30563568
A29: =+B29&C29 -> Véhicules neufs | B29: =+$K$1 -> Véhicules neufs
A30: =+B30&C30 -> Véhicules neufsDEPENSES | B30: =+$K$1 -> Véhicules neufs | C30: DEPENSES
A31: =+B31&C31 -> Véhicules neufsComm. vendeurs | B31: =+$K$1 -> Véhicules neufs | C31: Comm. vendeurs | D31: =F31/(F13+F15) -> 0.27513307 | E31: =F31/D$24 -> 1055.0687 | F31: 35872.335 | J31: =L31/(L13+L15) -> 0.21791316 | K31: =IF(L31=0,0,L31/J$24) -> 861.12769 | L31: 22389.32 | N31: =L31-F31 -> -13483.015 | O31: =Q31/(Q13+Q15+Q17) -> 0.24913105 | P31: =Q31/O$24 -> 1087.7869 | Q31: 31545.82 | S31: =L31-Q31 -> -9156.5
A32: =+B32&C32 -> Véhicules neufsComm. F&I | B32: =+$K$1 -> Véhicules neufs | C32: Comm. F&I | D32: =F32/F24 -> 0.305 | E32: =F32/D$24 -> 488 | F32: 16592 | J32: =L32/L24 -> 0.26398936 | K32: =IF(L32=0,0,L32/J$24) -> 313.79654 | L32: 8158.71 | N32: =L32-F32 -> -8433.29 | O32: =Q32/Q24 -> 0.34564999 | P32: =Q32/O$24 -> 876.39759 | Q32: 25415.53 | S32: =L32-Q32 -> -17256.82
A33: =+B33&C33 -> Véhicules neufsFrais de livraison | B33: =+$K$1 -> Véhicules neufs | C33: Frais de livraison | E33: =F33/D$24 -> 120 | F33: 4080 | K33: =IF(L33=0,0,L33/J$24) -> 188.28269 | L33: 4895.35 | N33: =L33-F33 -> 815.35 | P33: =Q33/O$24 -> 132.36483 | Q33: 3838.58 | S33: =L33-Q33 -> 1056.77 | V33: Transport
A34: =+B34&C34 -> Véhicules neufsService gratuit 1 | B34: =+$K$1 -> Véhicules neufs | C34: Service gratuit 1 | E34: =F34/D$24 -> 35 | F34: 1190 | K34: =IF(L34=0,0,L34/J$24) -> 40.125 | L34: 1043.25 | N34: =L34-F34 -> -146.75 | P34: =Q34/O$24 -> 62.720345 | Q34: 1818.89 | S34: =L34-Q34 -> -775.64
A35: =+B35&C35 -> Véhicules neufsEntretien stock | B35: =+$K$1 -> Véhicules neufs | C35: Entretien stock | E35: =F35/D$24 -> 95.794118 | F35: 3257 | K35: =IF(L35=0,0,L35/J$24) -> 64.176923 | L35: 1668.6 | N35: =L35-F35 -> -1588.4 | P35: =Q35/O$24 -> 37.223793 | Q35: 1079.49 | S35: =L35-Q35 -> 589.11
A36: =+B36&C36 -> Véhicules neufsPublicité 1 | B36: =+$K$1 -> Véhicules neufs | C36: Publicité 1 | E36: =F36/D$24 -> 234.88788 | F36: 7986.1879 | K36: =IF(L36=0,0,L36/J$24) -> 187.42346 | L36: 4873.01 | N36: =L36-F36 -> -3113.1779 | P36: =Q36/O$24 -> 595.14138 | Q36: 17259.1 | S36: =L36-Q36 -> -12386.09
A37: =+B37&C37 -> Véhicules neufsIntérêt de gros | B37: =+$K$1 -> Véhicules neufs | C37: Intérêt de gros | E37: =F37/D$24 -> 733.27477 | F37: 24931.342 | K37: =IF(L37=0,0,L37/J$24) -> 774.34885 | L37: 20133.07 | N37: =L37-F37 -> -4798.2722 | P37: =Q37/O$24 -> 853.67172 | Q37: 24756.48 | S37: =L37-Q37 -> -4623.41 | V37: 20133
A38: =+B38&C38 -> Véhicules neufs[...] | B38: =+$K$1 -> Véhicules neufs | C38: [...] | E38: =F38/D$24 -> 0 | F38: 0 | K38: =IF(L38=0,0,L38/J$24) -> 0 | L38: 0 | N38: =L38-F38 -> 0 | P38: =Q38/O$24 -> 0 | Q38: 0 | S38: =L38-Q38 -> 0
A39: =+B39&C39 -> Véhicules neufs[...] | B39: =+$K$1 -> Véhicules neufs | C39: [...] | E39: =F39/D$24 -> 0 | F39: 0 | K39: =IF(L39=0,0,L39/J$24) -> 0 | L39: 0 | N39: =L39-F39 -> 0 | P39: =Q39/O$24 -> 0 | Q39: 0 | S39: =L39-Q39 -> 0
A40: =+B40&C40 -> Véhicules neufs[...] | B40: =+$K$1 -> Véhicules neufs | C40: [...] | E40: =F40/D$24 -> 0 | F40: 0 | K40: =IF(L40=0,0,L40/J$24) -> 0 | L40: 0 | N40: =L40-F40 -> 0 | P40: =Q40/O$24 -> 0 | Q40: 0 | S40: =L40-Q40 -> 0
...

Sheet Mois 2
C1: BMW Sherbrooke | K1: Véhicules neufs | S1: Réalisé, Mai 2026
D2: X | E2: O | F2: U | J2: NB | L2: $ | O2: X | P2: O | Q2: U
D3: BUDGET ORIGINAL | J3: RÉALISATION | M3: ÉCART réel / Budget | O3: ANNÉE PRÉCÉDENTE | R3: ECART (réel/ Ann.Préc.)
D4: UNITE | E4: $P/UNITÉ | F4: $PROFITS | J4: UNITE | K4: $P/UNITE | L4: $PROFITS | M4: UNFTÉ | N4: $PROFITS | O4: UNITE | P4: $P/UNITÉ | Q4: $PROFITS | R4: UNITE | S4: $PROFITS
A5: =+B5&C5 -> Véhicules neufsVentes nettes | B5: =+$K$1 -> Véhicules neufs | C5: Ventes nettes | F5: 3877423.6 | L5: 4159629.3 | Q5: 3847659.5
A6: =+B6&C6 -> Véhicules neufsAutos détail | B6: =+$K$1 -> Véhicules neufs | C6: Autos détail | D6: 9 | E6: =IF(D6=0,0,F6/D6) -> 4701.1765 | F6: 42310.588 | J6: 17 | K6: =IF(J6=0,0,L6/J6) -> 5664.9376 | L6: 96303.94 | M6: =J6-D6 -> 8 | N6: =L6-F6 -> 53993.352 | O6: 12 | P6: =IF(O6=0,0,Q6/O6) -> 5958.9625 | Q6: 71507.55 | R6: =J6-O6 -> 5 | S6: =L6-Q6 -> 24796.39
A7: =+B7&C7 -> Véhicules neufsCamions détail | B7: =+$K$1 -> Véhicules neufs | C7: Camions détail | D7: 31 | E7: =IF(D7=0,0,F7/D7) -> 3928.5 | F7: 121783.5 | J7: 18 | K7: =IF(J7=0,0,L7/J7) -> 3509.155 | L7: 63164.79 | M7: =J7-D7 -> -13 | N7: =L7-F7 -> -58618.71 | O7: 23 | P7: =IF(O7=0,0,Q7/O7) -> 3685.7178 | Q7: 84771.51 | R7: =J7-O7 -> -5 | S7: =L7-Q7 -> -21606.72
A8: =+B8&C8 -> Véhicules neufsSprinter | B8: =+$K$1 -> Véhicules neufs | C8: Sprinter | D8: 0 | E8: =IF(D8=0,0,F8/D8) -> 0 | F8: 0 | J8: 0 | K8: =IF(J8=0,0,L8/J8) -> 0 | L8: 0 | M8: =J8-D8 -> 0 | N8: =L8-F8 -> 0 | O8: 0 | P8: =IF(O8=0,0,Q8/O8) -> 0 | Q8: 0 | R8: =J8-O8 -> 0 | S8: =L8-Q8 -> 0
A9: =+B9&C9 -> Véhicules neufsMoto détail | B9: =+$K$1 -> Véhicules neufs | C9: Moto détail | D9: 0 | E9: =IF(D9=0,0,F9/D9) -> 0 | F9: 0 | J9: 0 | K9: =IF(J9=0,0,L9/J9) -> 0 | L9: 0 | M9: =J9-D9 -> 0 | N9: =L9-F9 -> 0 | O9: 0 | P9: =IF(O9=0,0,Q9/O9) -> 0 | Q9: 0 | R9: =J9-O9 -> 0 | S9: =L9-Q9 -> 0
A10: =+B10&C10 -> Véhicules neufs[...] | B10: =+$K$1 -> Véhicules neufs | C10: [...] | D10: 0 | E10: =IF(D10=0,0,F10/D10) -> 0 | F10: 0 | J10: 0 | K10: =IF(J10=0,0,L10/J10) -> 0 | L10: 0 | M10: =J10-D10 -> 0 | N10: =L10-F10 -> 0 | O10: 0 | P10: =IF(O10=0,0,Q10/O10) -> 0 | Q10: 0 | R10: =J10-O10 -> 0 | S10: =L10-Q10 -> 0
A11: =+B11&C11 -> Véhicules neufs[...] | B11: =+$K$1 -> Véhicules neufs | C11: [...] | D11: 0 | E11: =IF(D11=0,0,F11/D11) -> 0 | F11: 0 | J11: 0 | K11: =IF(J11=0,0,L11/J11) -> 0 | L11: 0 | M11: =J11-D11 -> 0 | N11: =L11-F11 -> 0 | O11: 0 | P11: =IF(O11=0,0,Q11/O11) -> 0 | Q11: 0 | R11: =J11-O11 -> 0 | S11: =L11-Q11 -> 0
A12: =+B12&C12 -> Véhicules neufs[...] | B12: =+$K$1 -> Véhicules neufs | C12: [...] | D12: 0 | E12: =IF(D12=0,0,F12/D12) -> 0 | F12: 0 | J12: 0 | K12: =IF(J12=0,0,L12/J12) -> 0 | L12: 0 | M12: =J12-D12 -> 0 | N12: =L12-F12 -> 0 | O12: 0 | P12: =IF(O12=0,0,Q12/O12) -> 0 | Q12: 0 | R12: =J12-O12 -> 0 | S12: =L12-Q12 -> 0
A13: =+B13&C13 -> Véhicules neufsTotal Neufs | B13: =+$K$1 -> Véhicules neufs | C13: Total Neufs | D13: =+SUM(D6:D12) -> 40 | E13: =IF(D13<=0,0,F13/D13) -> 4102.3522 | F13: =+SUM(F6:F12) -> 164094.09 | J13: =+SUM(J6:J12) -> 35 | K13: =IF(J13<=0,0,L13/J13) -> 4556.2494 | L13: =+SUM(L6:L12) -> 159468.73 | M13: =+SUM(M6:M12) -> -5 | N13: =+SUM(N6:N12) -> -4625.3582 | O13: =+SUM(O6:O12) -> 35 | P13: =IF(O13<=0,0,Q13/O13) -> 4465.116 | Q13: =+SUM(Q6:Q12) -> 156279.06 | R13: =+SUM(R6:R12) -> 0 | S13: =+SUM(S6:S12) -> 3189.67
A14: =+B14&C14 -> Véhicules neufs | B14: =+$K$1 -> Véhicules neufs | M14: =IF(D13=0,0,M13/D13) -> -0.125 | N14: =IF(F13=0,0,N13/F13) -> -0.028187233 | R14: =R13/O13 -> 0 | S14: =IF(Q13=0,0,(S13/Q13)) -> 0.020410092
A15: =+B15&C15 -> Véhicules neufsEx-Démos et courtoisies | B15: =+$K$1 -> Véhicules neufs | C15: Ex-Démos et courtoisies | D15: 3 | E15: =IF(D15=0,0,F15/D15) -> 1200 | F15: 3600 | J15: 8 | K15: =IF(J15=0,0,L15/J15) -> 309.51125 | L15: 2476.09 | M15: =J15-D15 -> 5 | N15: =L15-F15 -> -1123.91 | O15: 9 | P15: =IF(O15=0,0,Q15/O15) -> 3505.6622 | Q15: 31550.96 | R15: =J15-O15 -> -1 | S15: =L15-Q15 -> -29074.87
A16: =+B16&C16 -> Véhicules neufs | B16: =+$K$1 -> Véhicules neufs
A17: =+B17&C17 -> Véhicules neufsFlottes | B17: =+$K$1 -> Véhicules neufs | C17: Flottes | D17: 2 | E17: =IF(D17=0,0,F17/D17) -> 750 | F17: 1500 | J17: 0 | K17: =IF(J17=0,0,L17/J17) -> 0 | L17: 0 | M17: =J17-D17 -> -2 | N17: =L17-F17 -> -1500 | O17: 0 | P17: =IF(O17=0,0,Q17/O17) -> 0 | Q17: 0 | R17: =J17-O17 -> 0 | S17: =L17-Q17 -> 0
A18: =+B18&C18 -> Véhicules neufs | B18: =+$K$1 -> Véhicules neufs
B19: =+$K$1 -> Véhicules neufs
A20: =+B20&C20 -> Véhicules neufs | B20: =+$K$1 -> Véhicules neufs
A21: =+B21&C21 -> Véhicules neufsRev. Finances | B21: =+$K$1 -> Véhicules neufs | C21: Rev. Finances | E21: =IF(D13=0,0,F21/(D13+D15)) -> 7 | F21: 301 | K21: =IF(J13=0,0,L21/(J13+J15)) -> 0 | L21: 0 | N21: =L21-F21 -> -301 | P21: =IF(O13=0,0,Q21/(O13+O15)) -> 0 | Q21: 0 | R21: =O21-K21 -> 0 | S21: =L21-Q21 -> 0
A22: =+B22&C22 -> Véhicules neufsRev. Protections | B22: =+$K$1 -> Véhicules neufs | C22: Rev. Protections | E22: =IF(D13=0,0,F22/(D13+D15)) -> 1150 | F22: 49450 | K22: =IF(J13=0,0,L22/(J13+J15)) -> 530.09302 | L22: 22794 | N22: =L22-F22 -> -26656 | P22: =IF(O13=0,0,Q22/(O13+O15)) -> 1383.58 | Q22: 60877.52 | R22: =O22-K22 -> -530.09302 | S22: =L22-Q22 -> -38083.52
A23: =+B23&C23 -> Véhicules neufsRev. Autres | B23: =+$K$1 -> Véhicules neufs | C23: Rev. Autres | E23: =IF(D13=0,0,F23/(D13+D15)) -> 443 | F23: 19049 | K23: =IF(J13=0,0,L23/(J13+J15)) -> 550.17512 | L23: 23657.53 | N23: =L23-F23 -> 4608.53 | P23: =IF(O13=0,0,Q23/(O13+O15)) -> 730.50318 | Q23: 32142.14 | R23: =O23-K23 -> -550.17512 | S23: =L23-Q23 -> -8484.61
A24: =+B24&C24 -> Véhicules neufsTotal F&I | B24: =+$K$1 -> Véhicules neufs | C24: Total F&I | D24: =+D15+D13 -> 43 | E24: =IF(D24<=0,0,F24/D24) -> 1600 | F24: =F21+F22+F23 -> 68800 | J24: =+J15+J13 -> 43 | K24: =IF(J24<=0,0,L24/J24) -> 1080.2681 | L24: =L21+L22+L23 -> 46451.53 | M24: =J24-D24 -> 0 | N24: =L24-F24 -> -22348.47 | O24: =+O15+O13 -> 44 | P24: =IF(O24<=0,0,Q24/O24) -> 2114.0832 | Q24: =Q21+Q22+Q23 -> 93019.66 | S24: =L24-Q24 -> -46568.13
A25: =+B25&C25 -> Véhicules neufs | B25: =+$K$1 -> Véhicules neufs | N25: =IF(N24=0,0,N24/F24) -> -0.32483241 | S25: =IF(Q24=0,0,(S24/Q24)) -> -0.50062675
A26: =+B26&C26 -> Véhicules neufs | B26: =+$K$1 -> Véhicules neufs
A27: =+B27&C27 -> Véhicules neufsTotal Dépt. Neufs | B27: =+$K$1 -> Véhicules neufs | C27: Total Dépt. Neufs | D27: =+D13+D15+D17 -> 45 | E27: =IF(D27<=0,0,F27/D27) -> 5288.7575 | F27: =F13+F17+F24+F15 -> 237994.09 | J27: =+J13+J15+J17 -> 43 | K27: =IF(J27<=0,0,L27/J27) -> 4846.4267 | L27: =L13+L17+L24+L15 -> 208396.35 | M27: =J27-D27 -> -2 | N27: =L27-F27 -> -29597.738 | O27: =+O13+O15+O17 -> 44 | P27: =IF(O27<=0,0,Q27/O27) -> 6382.9473 | Q27: =Q13+Q17+Q24+Q15 -> 280849.68 | R27: =J27-O27 -> -1 | S27: =L27-Q27 -> -72453.33
A28: =+B28&C28 -> Véhicules neufs | B28: =+$K$1 -> Véhicules neufs | M28: =M27/D27 -> -0.044444444 | N28: =N27/F27 -> -0.12436333 | R28: =R27/O27 -> -0.022727273 | S28: =IF(Q27=0,0,S27/Q27) -> -0.25797904
A29: =+B29&C29 -> Véhicules neufs | B29: =+$K$1 -> Véhicules neufs
A30: =+B30&C30 -> Véhicules neufsDEPENSES | B30: =+$K$1 -> Véhicules neufs | C30: DEPENSES
A31: =+B31&C31 -> Véhicules neufsComm. vendeurs | B31: =+$K$1 -> Véhicules neufs | C31: Comm. vendeurs | D31: =F31/(F13+F15) -> 0.26746308 | E31: =F31/D$24 -> 1043.0692 | F31: 44851.977 | J31: =L31/(L13+L15) -> 0.28095798 | K31: =IF(L31=0,0,L31/J$24) -> 1058.1323 | L31: 45499.69 | N31: =L31-F31 -> 647.71309 | O31: =Q31/(Q13+Q15+Q17) -> 0.26266919 | P31: =Q31/O$24 -> 1121.2991 | Q31: 49337.16 | S31: =L31-Q31 -> -3837.47
A32: =+B32&C32 -> Véhicules neufsComm. F&I | B32: =+$K$1 -> Véhicules neufs | C32: Comm. F&I | D32: =F32/F24 -> 0.305 | E32: =F32/D$24 -> 488 | F32: 20984 | J32: =L32/L24 -> 0.21132953 | K32: =IF(L32=0,0,L32/J$24) -> 228.29256 | L32: 9816.58 | N32: =L32-F32 -> -11167.42 | O32: =Q32/Q24 -> 0.33628934 | P32: =Q32/O$24 -> 710.94364 | Q32: 31281.52 | S32: =L32-Q32 -> -21464.94
A33: =+B33&C33 -> Véhicules neufsFrais de livraison | B33: =+$K$1 -> Véhicules neufs | C33: Frais de livraison | E33: =F33/D$24 -> 120 | F33: 5160 | K33: =IF(L33=0,0,L33/J$24) -> 94.995581 | L33: 4084.81 | N33: =L33-F33 -> -1075.19 | P33: =Q33/O$24 -> 77.407727 | Q33: 3405.94 | S33: =L33-Q33 -> 678.87
A34: =+B34&C34 -> Véhicules neufsService gratuit 1 | B34: =+$K$1 -> Véhicules neufs | C34: Service gratuit 1 | E34: =F34/D$24 -> 35 | F34: 1505 | K34: =IF(L34=0,0,L34/J$24) -> 33.011628 | L34: 1419.5 | N34: =L34-F34 -> -85.5 | P34: =Q34/O$24 -> 38.5175 | Q34: 1694.77 | S34: =L34-Q34 -> -275.27
A35: =+B35&C35 -> Véhicules neufsEntretien stock | B35: =+$K$1 -> Véhicules neufs | C35: Entretien stock | E35: =F35/D$24 -> 94.162791 | F35: 4049 | K35: =IF(L35=0,0,L35/J$24) -> 53.356977 | L35: 2294.35 | N35: =L35-F35 -> -1754.65 | P35: =Q35/O$24 -> 38.751818 | Q35: 1705.08 | S35: =L35-Q35 -> 589.27
A36: =+B36&C36 -> Véhicules neufsPublicité 1 | B36: =+$K$1 -> Véhicules neufs | C36: Publicité 1 | E36: =F36/D$24 -> 234.88788 | F36: 10100.179 | K36: =IF(L36=0,0,L36/J$24) -> 147.20814 | L36: 6329.95 | N36: =L36-F36 -> -3770.2288 | P36: =Q36/O$24 -> 421.36636 | Q36: 18540.12 | S36: =L36-Q36 -> -12210.17
A37: =+B37&C37 -> Véhicules neufsIntérêt de gros | B37: =+$K$1 -> Véhicules neufs | C37: Intérêt de gros | E37: =F37/D$24 -> 575.03984 | F37: 24726.713 | K37: =IF(L37=0,0,L37/J$24) -> 530.82279 | L37: 22825.38 | N37: =L37-F37 -> -1901.3331 | P37: =Q37/O$24 -> 600.04409 | Q37: 26401.94 | S37: =L37-Q37 -> -3576.56 | V37: 22825
A38: =+B38&C38 -> Véhicules neufs[...] | B38: =+$K$1 -> Véhicules neufs | C38: [...] | E38: =F38/D$24 -> 0 | F38: 0 | K38: =IF(L38=0,0,L38/J$24) -> 0 | L38: 0 | N38: =L38-F38 -> 0 | P38: =Q38/O$24 -> 0 | Q38: 0 | S38: =L38-Q38 -> 0
A39: =+B39&C39 -> Véhicules neufs[...] | B39: =+$K$1 -> Véhicules neufs | C39: [...] | E39: =F39/D$24 -> 0 | F39: 0 | K39: =IF(L39=0,0,L39/J$24) -> 0 | L39: 0 | N39: =L39-F39 -> 0 | P39: =Q39/O$24 -> 0 | Q39: 0 | S39: =L39-Q39 -> 0
A40: =+B40&C40 -> Véhicules neufs[...] | B40: =+$K$1 -> Véhicules neufs | C40: [...] | E40: =F40/D$24 -> 0 | F40: 0 | K40: =IF(L40=0,0,L40/J$24) -> 0 | L40: 0 | N40: =L40-F40 -> 0 | P40: =Q40/O$24 -> 0 | Q40: 0 | S40: =L40-Q40 -> 0
...

Sheet Mois 3
C1: BMW Sherbrooke | K1: Véhicules neufs | S1: Réalisé, Juin 2026
D2: X | E2: O | F2: U | J2: NB | L2: $ | O2: X | P2: O | Q2: U
D3: BUDGET ORIGINAL | J3: RÉALISATION | M3: ÉCART réel / Budget | O3: ANNÉE PRÉCÉDENTE | R3: ECART (réel/ Ann.Préc.)
D4: UNITE | E4: $P/UNITÉ | F4: $PROFITS | J4: UNITE | K4: $P/UNITE | L4: $PROFITS | M4: UNFTÉ | N4: $PROFITS | O4: UNITE | P4: $P/UNITÉ | Q4: $PROFITS | R4: UNITE | S4: $PROFITS
A5: =+B5&C5 -> Véhicules neufsVentes nettes | B5: =+$K$1 -> Véhicules neufs | C5: Ventes nettes | F5: 2474272 | L5: 2992808.7 | Q5: 1932819
A6: =+B6&C6 -> Véhicules neufsAutos détail | B6: =+$K$1 -> Véhicules neufs | C6: Autos détail | D6: 9 | E6: =IF(D6=0,0,F6/D6) -> 4701.1765 | F6: 42310.588 | J6: 10 | K6: =IF(J6=0,0,L6/J6) -> 6645.185 | L6: 66451.85 | M6: =J6-D6 -> 1 | N6: =L6-F6 -> 24141.262 | O6: 9 | P6: =IF(O6=0,0,Q6/O6) -> 5820.6267 | Q6: 52385.64 | R6: =J6-O6 -> 1 | S6: =L6-Q6 -> 14066.21
A7: =+B7&C7 -> Véhicules neufsCamions détail | B7: =+$K$1 -> Véhicules neufs | C7: Camions détail | D7: 14 | E7: =IF(D7=0,0,F7/D7) -> 3928.5 | F7: 54999 | J7: 12 | K7: =IF(J7=0,0,L7/J7) -> 4707.7525 | L7: 56493.03 | M7: =J7-D7 -> -2 | N7: =L7-F7 -> 1494.03 | O7: 7 | P7: =IF(O7=0,0,Q7/O7) -> 3544.4671 | Q7: 24811.27 | R7: =J7-O7 -> 5 | S7: =L7-Q7 -> 31681.76
A8: =+B8&C8 -> Véhicules neufsSprinter | B8: =+$K$1 -> Véhicules neufs | C8: Sprinter | D8: 0 | E8: =IF(D8=0,0,F8/D8) -> 0 | F8: 0 | J8: 0 | K8: =IF(J8=0,0,L8/J8) -> 0 | L8: 0 | M8: =J8-D8 -> 0 | N8: =L8-F8 -> 0 | O8: 0 | P8: =IF(O8=0,0,Q8/O8) -> 0 | Q8: 0 | R8: =J8-O8 -> 0 | S8: =L8-Q8 -> 0
A9: =+B9&C9 -> Véhicules neufsMoto détail | B9: =+$K$1 -> Véhicules neufs | C9: Moto détail | D9: 0 | E9: =IF(D9=0,0,F9/D9) -> 0 | F9: 0 | J9: 0 | K9: =IF(J9=0,0,L9/J9) -> 0 | L9: 0 | M9: =J9-D9 -> 0 | N9: =L9-F9 -> 0 | O9: 0 | P9: =IF(O9=0,0,Q9/O9) -> 0 | Q9: 0 | R9: =J9-O9 -> 0 | S9: =L9-Q9 -> 0
A10: =+B10&C10 -> Véhicules neufs[...] | B10: =+$K$1 -> Véhicules neufs | C10: [...] | D10: 0 | E10: =IF(D10=0,0,F10/D10) -> 0 | F10: 0 | J10: 0 | K10: =IF(J10=0,0,L10/J10) -> 0 | L10: 0 | M10: =J10-D10 -> 0 | N10: =L10-F10 -> 0 | O10: 0 | P10: =IF(O10=0,0,Q10/O10) -> 0 | Q10: 0 | R10: =J10-O10 -> 0 | S10: =L10-Q10 -> 0
A11: =+B11&C11 -> Véhicules neufs[...] | B11: =+$K$1 -> Véhicules neufs | C11: [...] | D11: 0 | E11: =IF(D11=0,0,F11/D11) -> 0 | F11: 0 | J11: 0 | K11: =IF(J11=0,0,L11/J11) -> 0 | L11: 0 | M11: =J11-D11 -> 0 | N11: =L11-F11 -> 0 | O11: 0 | P11: =IF(O11=0,0,Q11/O11) -> 0 | Q11: 0 | R11: =J11-O11 -> 0 | S11: =L11-Q11 -> 0
A12: =+B12&C12 -> Véhicules neufs[...] | B12: =+$K$1 -> Véhicules neufs | C12: [...] | D12: 0 | E12: =IF(D12=0,0,F12/D12) -> 0 | F12: 0 | J12: 0 | K12: =IF(J12=0,0,L12/J12) -> 0 | L12: 0 | M12: =J12-D12 -> 0 | N12: =L12-F12 -> 0 | O12: 0 | P12: =IF(O12=0,0,Q12/O12) -> 0 | Q12: 0 | R12: =J12-O12 -> 0 | S12: =L12-Q12 -> 0
A13: =+B13&C13 -> Véhicules neufsTotal Neufs | B13: =+$K$1 -> Véhicules neufs | C13: Total Neufs | D13: =+SUM(D6:D12) -> 23 | E13: =IF(D13<=0,0,F13/D13) -> 4230.8517 | F13: =+SUM(F6:F12) -> 97309.588 | J13: =+SUM(J6:J12) -> 22 | K13: =IF(J13<=0,0,L13/J13) -> 5588.4036 | L13: =+SUM(L6:L12) -> 122944.88 | M13: =+SUM(M6:M12) -> -1 | N13: =+SUM(N6:N12) -> 25635.292 | O13: =+SUM(O6:O12) -> 16 | P13: =IF(O13<=0,0,Q13/O13) -> 4824.8069 | Q13: =+SUM(Q6:Q12) -> 77196.91 | R13: =+SUM(R6:R12) -> 6 | S13: =+SUM(S6:S12) -> 45747.97
A14: =+B14&C14 -> Véhicules neufs | B14: =+$K$1 -> Véhicules neufs | M14: =IF(D13=0,0,M13/D13) -> -0.043478261 | N14: =IF(F13=0,0,N13/F13) -> 0.26344055 | R14: =R13/O13 -> 0.375 | S14: =IF(Q13=0,0,(S13/Q13)) -> 0.592614
A15: =+B15&C15 -> Véhicules neufsEx-Démos et courtoisies | B15: =+$K$1 -> Véhicules neufs | C15: Ex-Démos et courtoisies | D15: 3 | E15: =IF(D15=0,0,F15/D15) -> 1200 | F15: 3600 | J15: 2 | K15: =IF(J15=0,0,L15/J15) -> 39.025 | L15: 78.05 | M15: =J15-D15 -> -1 | N15: =L15-F15 -> -3521.95 | O15: 4 | P15: =IF(O15=0,0,Q15/O15) -> 2445.1975 | Q15: 9780.79 | R15: =J15-O15 -> -2 | S15: =L15-Q15 -> -9702.74
A16: =+B16&C16 -> Véhicules neufs | B16: =+$K$1 -> Véhicules neufs
A17: =+B17&C17 -> Véhicules neufsFlottes | B17: =+$K$1 -> Véhicules neufs | C17: Flottes | D17: 2 | E17: =IF(D17=0,0,F17/D17) -> 750 | F17: 1500 | J17: 6 | K17: =IF(J17=0,0,L17/J17) -> 0 | L17: 0 | M17: =J17-D17 -> 4 | N17: =L17-F17 -> -1500 | O17: 0 | P17: =IF(O17=0,0,Q17/O17) -> 0 | Q17: 0 | R17: =J17-O17 -> 6 | S17: =L17-Q17 -> 0
A18: =+B18&C18 -> Véhicules neufs | B18: =+$K$1 -> Véhicules neufs
B19: =+$K$1 -> Véhicules neufs
A20: =+B20&C20 -> Véhicules neufs | B20: =+$K$1 -> Véhicules neufs
A21: =+B21&C21 -> Véhicules neufsRev. Finances | B21: =+$K$1 -> Véhicules neufs | C21: Rev. Finances | E21: =IF(D13=0,0,F21/(D13+D15)) -> 7 | F21: 182 | K21: =IF(J13=0,0,L21/(J13+J15)) -> 0 | L21: 0 | N21: =L21-F21 -> -182 | P21: =IF(O13=0,0,Q21/(O13+O15)) -> 0 | Q21: 0 | R21: =O21-K21 -> 0 | S21: =L21-Q21 -> 0
A22: =+B22&C22 -> Véhicules neufsRev. Protections | B22: =+$K$1 -> Véhicules neufs | C22: Rev. Protections | E22: =IF(D13=0,0,F22/(D13+D15)) -> 1150 | F22: 29900 | K22: =IF(J13=0,0,L22/(J13+J15)) -> 489.09583 | L22: 11738.3 | N22: =L22-F22 -> -18161.7 | P22: =IF(O13=0,0,Q22/(O13+O15)) -> 1336.1695 | Q22: 26723.39 | R22: =O22-K22 -> -489.09583 | S22: =L22-Q22 -> -14985.09
A23: =+B23&C23 -> Véhicules neufsRev. Autres | B23: =+$K$1 -> Véhicules neufs | C23: Rev. Autres | E23: =IF(D13=0,0,F23/(D13+D15)) -> 443 | F23: 11518 | K23: =IF(J13=0,0,L23/(J13+J15)) -> 445.25708 | L23: 10686.17 | N23: =L23-F23 -> -831.83 | P23: =IF(O13=0,0,Q23/(O13+O15)) -> 902.6705 | Q23: 18053.41 | R23: =O23-K23 -> -445.25708 | S23: =L23-Q23 -> -7367.24
A24: =+B24&C24 -> Véhicules neufsTotal F&I | B24: =+$K$1 -> Véhicules neufs | C24: Total F&I | D24: =+D15+D13 -> 26 | E24: =IF(D24<=0,0,F24/D24) -> 1600 | F24: =F21+F22+F23 -> 41600 | J24: =+J15+J13 -> 24 | K24: =IF(J24<=0,0,L24/J24) -> 934.35292 | L24: =L21+L22+L23 -> 22424.47 | M24: =J24-D24 -> -2 | N24: =L24-F24 -> -19175.53 | O24: =+O15+O13 -> 20 | P24: =IF(O24<=0,0,Q24/O24) -> 2238.84 | Q24: =Q21+Q22+Q23 -> 44776.8 | S24: =L24-Q24 -> -22352.33
A25: =+B25&C25 -> Véhicules neufs | B25: =+$K$1 -> Véhicules neufs | N25: =IF(N24=0,0,N24/F24) -> -0.46095024 | S25: =IF(Q24=0,0,(S24/Q24)) -> -0.49919445
A26: =+B26&C26 -> Véhicules neufs | B26: =+$K$1 -> Véhicules neufs
A27: =+B27&C27 -> Véhicules neufsTotal Dépt. Neufs | B27: =+$K$1 -> Véhicules neufs | C27: Total Dépt. Neufs | D27: =+D13+D15+D17 -> 28 | E27: =IF(D27<=0,0,F27/D27) -> 5143.1996 | F27: =F13+F17+F24+F15 -> 144009.59 | J27: =+J13+J15+J17 -> 30 | K27: =IF(J27<=0,0,L27/J27) -> 4848.2467 | L27: =L13+L17+L24+L15 -> 145447.4 | M27: =J27-D27 -> 2 | N27: =L27-F27 -> 1437.8118 | O27: =+O13+O15+O17 -> 20 | P27: =IF(O27<=0,0,Q27/O27) -> 6587.725 | Q27: =Q13+Q17+Q24+Q15 -> 131754.5 | R27: =J27-O27 -> 10 | S27: =L27-Q27 -> 13692.9
A28: =+B28&C28 -> Véhicules neufs | B28: =+$K$1 -> Véhicules neufs | M28: =M27/D27 -> 0.071428571 | N28: =N27/F27 -> 0.0099841391 | R28: =R27/O27 -> 0.5 | S28: =IF(Q27=0,0,S27/Q27) -> 0.10392738
A29: =+B29&C29 -> Véhicules neufs | B29: =+$K$1 -> Véhicules neufs
A30: =+B30&C30 -> Véhicules neufsDEPENSES | B30: =+$K$1 -> Véhicules neufs | C30: DEPENSES
A31: =+B31&C31 -> Véhicules neufsComm. vendeurs | B31: =+$K$1 -> Véhicules neufs | C31: Comm. vendeurs | D31: =F31/(F13+F15) -> 0.28393389 | E31: =F31/D$24 -> 1101.9866 | F31: 28651.652 | J31: =L31/(L13+L15) -> 0.28455614 | K31: =IF(L31=0,0,L31/J$24) -> 1458.6221 | L31: 35006.93 | N31: =L31-F31 -> 6355.2782 | O31: =Q31/(Q13+Q15+Q17) -> 0.25746726 | P31: =Q31/O$24 -> 1119.6955 | Q31: 22393.91 | S31: =L31-Q31 -> 12613.02
A32: =+B32&C32 -> Véhicules neufsComm. F&I | B32: =+$K$1 -> Véhicules neufs | C32: Comm. F&I | D32: =F32/F24 -> 0.305 | E32: =F32/D$24 -> 488 | F32: 12688 | J32: =L32/L24 -> 0.22188395 | K32: =IF(L32=0,0,L32/J$24) -> 207.31792 | L32: 4975.63 | N32: =L32-F32 -> -7712.37 | O32: =Q32/Q24 -> 0.34309151 | P32: =Q32/O$24 -> 768.127 | Q32: 15362.54 | S32: =L32-Q32 -> -10386.91
A33: =+B33&C33 -> Véhicules neufsFrais de livraison | B33: =+$K$1 -> Véhicules neufs | C33: Frais de livraison | E33: =F33/D$24 -> 120 | F33: 3120 | K33: =IF(L33=0,0,L33/J$24) -> 276.80167 | L33: 6643.24 | N33: =L33-F33 -> 3523.24 | P33: =Q33/O$24 -> 207.3525 | Q33: 4147.05 | S33: =L33-Q33 -> 2496.19 | V33: Essences + transport
A34: =+B34&C34 -> Véhicules neufsService gratuit 1 | B34: =+$K$1 -> Véhicules neufs | C34: Service gratuit 1 | E34: =F34/D$24 -> 35 | F34: 910 | K34: =IF(L34=0,0,L34/J$24) -> 95.290833 | L34: 2286.98 | N34: =L34-F34 -> 1376.98 | P34: =Q34/O$24 -> 0 | Q34: 0 | S34: =L34-Q34 -> 2286.98 | V34: 1.4K Freins ancien démo Yvon vendu janv 2026
A35: =+B35&C35 -> Véhicules neufsEntretien stock | B35: =+$K$1 -> Véhicules neufs | C35: Entretien stock | E35: =F35/D$24 -> 98.192308 | F35: 2553 | K35: =IF(L35=0,0,L35/J$24) -> 210.72917 | L35: 5057.5 | N35: =L35-F35 -> 2504.5 | P35: =Q35/O$24 -> 103.6725 | Q35: 2073.45 | S35: =L35-Q35 -> 2984.05 | V35: 2k Lavavage ligne essaie
A36: =+B36&C36 -> Véhicules neufsPublicité 1 | B36: =+$K$1 -> Véhicules neufs | C36: Publicité 1 | E36: =F36/D$24 -> 234.88788 | F36: 6107.0848 | K36: =IF(L36=0,0,L36/J$24) -> 230.78417 | L36: 5538.82 | N36: =L36-F36 -> -568.26485 | P36: =Q36/O$24 -> 508.9305 | Q36: 10178.61 | S36: =L36-Q36 -> -4639.79
A37: =+B37&C37 -> Véhicules neufsIntérêt de gros | B37: =+$K$1 -> Véhicules neufs | C37: Intérêt de gros | E37: =F37/D$24 -> 809.52174 | F37: 21047.565 | K37: =IF(L37=0,0,L37/J$24) -> 881.08 | L37: 21145.92 | N37: =L37-F37 -> 98.354754 | P37: =Q37/O$24 -> 1163.8995 | Q37: 23277.99 | S37: =L37-Q37 -> -2132.07 | V37: 21146
A38: =+B38&C38 -> Véhicules neufs[...] | B38: =+$K$1 -> Véhicules neufs | C38: [...] | E38: =F38/D$24 -> 0 | F38: 0 | K38: =IF(L38=0,0,L38/J$24) -> 0 | L38: 0 | N38: =L38-F38 -> 0 | P38: =Q38/O$24 -> 0 | Q38: 0 | S38: =L38-Q38 -> 0
A39: =+B39&C39 -> Véhicules neufs[...] | B39: =+$K$1 -> Véhicules neufs | C39: [...] | E39: =F39/D$24 -> 0 | F39: 0 | K39: =IF(L39=0,0,L39/J$24) -> 0 | L39: 0 | N39: =L39-F39 -> 0 | P39: =Q39/O$24 -> 0 | Q39: 0 | S39: =L39-Q39 -> 0
A40: =+B40&C40 -> Véhicules neufs[...] | B40: =+$K$1 -> Véhicules neufs | C40: [...] | E40: =F40/D$24 -> 0 | F40: 0 | K40: =IF(L40=0,0,L40/J$24) -> 0 | L40: 0 | N40: =L40-F40 -> 0 | P40: =Q40/O$24 -> 0 | Q40: 0 | S40: =L40-Q40 -> 0
...

Sheet END
