Workbook
Name _Dates_Conc: [1]Dealers!$BF$37:$KA$63
Name _Dates_Conc: #REF!
Name _scen: '[1]Scen & Sens'!$E$26
Name _scen: #REF!
Name _scen1: '[1]Scen & Sens'!$E$27
Name _scen1: #REF!
Name _scen2: '[1]Scen & Sens'!$E$28
Name _scen2: #REF!
Name _SCenarios: '[1]Scen & Sens'!$J$26:$O$26
Name _SCenarios: #REF!
Name _Sens1: '[1]Scen & Sens'!$F$9
Name _Sens1: #REF!
Name _Sens2: '[1]Scen & Sens'!$F$10
Name _Sens2: #REF!
Name _sensRes1: '[1]Scen & Sens'!$E$15
Name _sensRes1: #REF!
Name _sensRes2: '[1]Scen & Sens'!$E$16
Name _sensRes2: #REF!
Name _sensRes3: '[1]Scen & Sens'!$E$17
Name _sensRes3: #REF!
Name _sensRes4: '[1]Scen & Sens'!$E$18
Name _sensRes4: #REF!
Name _sensRes5: '[1]Scen & Sens'!$E$19
Name _sensRes5: #REF!
Name _sensRes6: '[1]Scen & Sens'!$E$20
Name _sensRes6: #REF!
Name _sensRes7: '[1]Scen & Sens'!$E$21
Name _sensRes7: #REF!
Name Compco1: {"Page1",#N/A,FALSE,"CompCo";"Page2",#N/A,FALSE,"CompCo"}
Name Compco2: {"Page1",#N/A,FALSE,"CompCo";"Page2",#N/A,FALSE,"CompCo"}
Name DateRange: [1]Volkswagen!$BF$6:$DY$6
Name DateRange: #REF!
Name DateRangePr: OFFSET([2]!DateRangePriceMain,5,0,COUNTA([2]!DateRangePriceMain)-COUNTA(#REF!),1)
Name DateRangePrice: OFFSET([3]!DateRangePriceMain,5,0,COUNTA([3]!DateRangePriceMain)-COUNTA(#REF!),1)
Name DateRangePrice1: OFFSET([3]!DateRangePriceMain,5,0,COUNTA([3]!DateRangePriceMain)-COUNTA(#REF!),1)
Name DateRangePrice2: OFFSET([2]!DateRangePriceMain,5,0,COUNTA([2]!DateRangePriceMain)-COUNTA(#REF!),1)
Name ERT: {"execsum",#N/A,FALSE,"ExecSum";"finstatement",#N/A,FALSE,"Fin_St"}
Name hn.Delete015: '[4]CREDIT STATS'!$B$9:$K$14,'[4]CREDIT STATS'!$O$11:$X$18,'[4]CREDIT STATS'!$B$28:$K$37,'[4]CREDIT STATS'!$O$28:$X$32,'[4]CREDIT STATS'!$O$46:$X$46
Name kjjkghkhj: {"finana",#N/A,FALSE,"Fin"}
Name lkhkhj: {"sub1",#N/A,FALSE,"Subs";"pac1",#N/A,FALSE,"Packages";"rev1",#N/A,FALSE,"2. Revenues"}
Name Monetary_Unit: [1]Parameters!$B$15
Name Monetary_Unit: #REF!
Name Months: [1]Parameters!$E$9:$E$20
Name Months: #REF!
Name PriceRange: OFFSET([3]!PriceRangeMain,5,0,COUNTA([3]!PriceRangeMain)-COUNTA(#REF!),1)
Name PriceRange2: OFFSET([2]!PriceRangeMain,5,0,COUNTA([2]!PriceRangeMain)-COUNTA(#REF!),1)
Name Rng_Dealers_Names: [1]!Tbl_Dealers[Dealer Name]
Name Rng_Dealers_Names: #REF!
Name Rng_Dlr_Dates: [1]!Tbl_V_Dlr_Dates[Date]
Name Rng_Dlr_Dates: #REF!
Name test: {"execsum",#N/A,FALSE,"ExecSum";"finstatement",#N/A,FALSE,"Fin_St"}
Name test21: OFFSET([2]!DateRangePriceMain,5,0,COUNTA([2]!DateRangePriceMain)-COUNTA(#REF!),1)
Name Ticker: #REF!
Name Ticker: #REF!
Name Titre: [1]Front!$A$9
Name Titre: #REF!
Name value: OFFSET([3]!DateRangePriceMain,5,0,COUNTA([3]!DateRangePriceMain)-COUNTA(#REF!),1)
Name value2: OFFSET([2]!DateRangePriceMain,5,0,COUNTA([2]!DateRangePriceMain)-COUNTA(#REF!),1)
Name wrn.amendement.: {#N/A,#N/A,FALSE,"amendement"}
Name wrn.amendement..: {#N/A,#N/A,FALSE,"amendement"}

Sheet Parametres
A1: Compagnie | B1: BMW Sherbrooke
G2: 1-Mémo | M2: Mois | N2: YTD
A3: Mois Courant | B3: Novembre | C3: =+VLOOKUP(B3,$K$3:$L$14,2,0) -> 11 | G3: 10-Compte compteur | K3: Janvier | L3: 1 | M3: =+IF($K3=$B$3,"X","") | N3: =+IF(K3=B3,"X",IF(L3<=$C$3,"X","")) -> X
A4: Année | B4: 2024 | K4: Février | L4: 2 | M4: =+IF($K4=$B$3,"X","") | N4: =+IF(K4=B4,"X",IF(L4<=$C$3,"X","")) -> X
K5: Mars | L5: 3 | M5: =+IF($K5=$B$3,"X","") | N5: =+IF(K5=B5,"X",IF(L5<=$C$3,"X","")) -> X
K6: Avril | L6: 4 | M6: =+IF($K6=$B$3,"X","") | N6: =+IF(K6=B6,"X",IF(L6<=$C$3,"X","")) -> X
K7: Mai | L7: 5 | M7: =+IF($K7=$B$3,"X","") | N7: =+IF(K7=B7,"X",IF(L7<=$C$3,"X","")) -> X
K8: Juin | L8: 6 | M8: =+IF($K8=$B$3,"X","") | N8: =+IF(K8=B8,"X",IF(L8<=$C$3,"X","")) -> X
A9: Sélectionner le mois en B3 | K9: Juillet | L9: 7 | M9: =+IF($K9=$B$3,"X","") | N9: =+IF(K9=B9,"X",IF(L9<=$C$3,"X","")) -> X
A10: Coller les balances de vérification respectives en cellule A1 dans les onglets BV_Data_An_Cour et BV_Data_An_Prec | K10: Août | L10: 8 | M10: =+IF($K10=$B$3,"X","") | N10: =+IF(K10=B10,"X",IF(L10<=$C$3,"X","")) -> X
A11: Vérifier s'il y a des #N/A dans les colonnes T à X des onlgets de BV | K11: Septembre | L11: 9 | M11: =+IF($K11=$B$3,"X","") | N11: =+IF(K11=B11,"X",IF(L11<=$C$3,"X","")) -> X
A12: Vérifier les chiffres avec l'état financier et les réalisés an passé pour les résultat net mois et aad | K12: Octobre | L12: 10 | M12: =+IF($K12=$B$3,"X","") | N12: =+IF(K12=B12,"X",IF(L12<=$C$3,"X","")) -> X
K13: Novembre | L13: 11 | M13: =+IF($K13=$B$3,"X","") -> X | N13: =+IF(K13=B13,"X",IF(L13<=$C$3,"X","")) -> X
K14: Décembre | L14: 12 | M14: =+IF($K14=$B$3,"X","") | N14: =+IF(K14=B14,"X",IF(L14<=$C$3,"X",""))

Sheet Bilan
A1: BILAN
A2: =+Parametres!B1 -> BMW Sherbrooke
A3: =CONCATENATE("",,Parametres!B3," ",Parametres!B4) -> Novembre 2024
A5: Encaisse | B5: =SUMIFS(BV_Data_An_Cour!$P:$P,BV_Data_An_Cour!$U:$U,$A$1,BV_Data_An_Cour!$V:$V,$A5) -> 2440862.7 | D5: Marge de crédit | E5: =-SUMIFS(BV_Data_An_Cour!$P:$P,BV_Data_An_Cour!$U:$U,$A$1,BV_Data_An_Cour!$V:$V,$D5) -> 0
A6: Total Trésorerie et équivalent de Trésorerie | B6: =SUM(B5) -> 2440862.7
D7: Portion Court Terme de la Dette Long Terme | E7: =-SUMIFS(BV_Data_An_Cour!$P:$P,BV_Data_An_Cour!$U:$U,$A$1,BV_Data_An_Cour!$V:$V,$D7) -> 0
A8: Recevables Contrats en Transit | B8: =SUMIFS(BV_Data_An_Cour!$P:$P,BV_Data_An_Cour!$U:$U,$A$1,BV_Data_An_Cour!$V:$V,$A8) -> 888209.78
A9: Recevables Véhicules | B9: =SUMIFS(BV_Data_An_Cour!$P:$P,BV_Data_An_Cour!$U:$U,$A$1,BV_Data_An_Cour!$V:$V,$A9) -> 379657.91 | D9: Avances à payer | E9: =-SUMIFS(BV_Data_An_Cour!$P:$P,BV_Data_An_Cour!$U:$U,$A$1,BV_Data_An_Cour!$V:$V,$D9) -> 0
A10: Recevables Manufacturier | B10: =SUMIFS(BV_Data_An_Cour!$P:$P,BV_Data_An_Cour!$U:$U,$A$1,BV_Data_An_Cour!$V:$V,$A10) -> 186777.23 | D10: Comptes à Payer Fournisseurs | E10: =-SUMIFS(BV_Data_An_Cour!$P:$P,BV_Data_An_Cour!$U:$U,$A$1,BV_Data_An_Cour!$V:$V,$D10) -> 143819.34
A11: Recevables Pièces et Service | B11: =SUMIFS(BV_Data_An_Cour!$P:$P,BV_Data_An_Cour!$U:$U,$A$1,BV_Data_An_Cour!$V:$V,$A11) -> 85322.32 | D11: Taxes de Vente à Payer | E11: =-SUMIFS(BV_Data_An_Cour!$P:$P,BV_Data_An_Cour!$U:$U,$A$1,BV_Data_An_Cour!$V:$V,$D11) -> 152285.74
A12: Recevables Garantie Manufacturier | B12: =SUMIFS(BV_Data_An_Cour!$P:$P,BV_Data_An_Cour!$U:$U,$A$1,BV_Data_An_Cour!$V:$V,$A12) -> 9684.84 | D12: Impôts à payer | E12: =-SUMIFS(BV_Data_An_Cour!$P:$P,BV_Data_An_Cour!$U:$U,$A$1,BV_Data_An_Cour!$V:$V,$D12) -> 815718.83
A13: Recevables Carrosserie | B13: =SUMIFS(BV_Data_An_Cour!$P:$P,BV_Data_An_Cour!$U:$U,$A$1,BV_Data_An_Cour!$V:$V,$A13) -> 0 | D13: Dépôts de Client | E13: =-SUMIFS(BV_Data_An_Cour!$P:$P,BV_Data_An_Cour!$U:$U,$A$1,BV_Data_An_Cour!$V:$V,$D13) -> 68353.99
A14: Recevables Intercos | B14: =SUMIFS(BV_Data_An_Cour!$P:$P,BV_Data_An_Cour!$U:$U,$A$1,BV_Data_An_Cour!$V:$V,$A14) -> 101148.05 | D14: Payables Intercos | E14: =-SUMIFS(BV_Data_An_Cour!$P:$P,BV_Data_An_Cour!$U:$U,$A$1,BV_Data_An_Cour!$V:$V,$D14) -> 43862.67
A15: Recevables Autres | B15: =SUMIFS(BV_Data_An_Cour!$P:$P,BV_Data_An_Cour!$U:$U,$A$1,BV_Data_An_Cour!$V:$V,$A15) -> 114128.4 | D15: Autres Comptes à Payer | E15: =-SUMIFS(BV_Data_An_Cour!$P:$P,BV_Data_An_Cour!$U:$U,$A$1,BV_Data_An_Cour!$V:$V,$D15) -> 238458.25
A16: Total Comptes à Recevoir | B16: =+SUM(B8:B15) -> 1764928.5 | D16: Total Comptes à Payer | E16: =+SUM(E10:E15) -> 1462498.8
A18: Inventaire Véhicules Neufs | B18: =SUMIFS(BV_Data_An_Cour!$P:$P,BV_Data_An_Cour!$U:$U,$A$1,BV_Data_An_Cour!$V:$V,$A18) -> 5652047.2 | D18: Effet à Payer Véhicules Neufs | E18: =-SUMIFS(BV_Data_An_Cour!$P:$P,BV_Data_An_Cour!$U:$U,$A$1,BV_Data_An_Cour!$V:$V,$D18) -> 7960933.7
A19: Inventaire Véhicules Usagés | B19: =SUMIFS(BV_Data_An_Cour!$P:$P,BV_Data_An_Cour!$U:$U,$A$1,BV_Data_An_Cour!$V:$V,$A19) -> 1659837.8 | D19: Effet à Payer Véhicules Usagés | E19: =-SUMIFS(BV_Data_An_Cour!$P:$P,BV_Data_An_Cour!$U:$U,$A$1,BV_Data_An_Cour!$V:$V,$D19) -> 969394.43
A20: Inventaire Pièces, Pneus, Huile | B20: =SUMIFS(BV_Data_An_Cour!$P:$P,BV_Data_An_Cour!$U:$U,$A$1,BV_Data_An_Cour!$V:$V,$A20) -> 485823.52 | D20: Total Effets à Payer | E20: =+SUM(E18:E19) -> 8930328.1
A21: Total Inventaires | B21: =SUM(B18:B20) -> 7797708.5
D22: Salaires à Payer | E22: =-SUMIFS(BV_Data_An_Cour!$P:$P,BV_Data_An_Cour!$U:$U,$A$1,BV_Data_An_Cour!$V:$V,$D22) -> 294882.04
A23: Avances à recevoir | B23: =SUMIFS(BV_Data_An_Cour!$P:$P,BV_Data_An_Cour!$U:$U,$A$1,BV_Data_An_Cour!$V:$V,$A23) -> 0 | D23: DAS à Payer | E23: =-SUMIFS(BV_Data_An_Cour!$P:$P,BV_Data_An_Cour!$U:$U,$A$1,BV_Data_An_Cour!$V:$V,$D23) -> 15194.57
A24: Travaux en Cours | B24: =SUMIFS(BV_Data_An_Cour!$P:$P,BV_Data_An_Cour!$U:$U,$A$1,BV_Data_An_Cour!$V:$V,$A24) -> 1632.81 | D24: Autres Courus | E24: =-SUMIFS(BV_Data_An_Cour!$P:$P,BV_Data_An_Cour!$U:$U,$A$1,BV_Data_An_Cour!$V:$V,$D24) -> 190984.53
A25: Sous-Traitance | B25: =SUMIFS(BV_Data_An_Cour!$P:$P,BV_Data_An_Cour!$U:$U,$A$1,BV_Data_An_Cour!$V:$V,$A25) -> 1405.96 | D25: [...] | E25: =-SUMIFS(BV_Data_An_Cour!$P:$P,BV_Data_An_Cour!$U:$U,$A$1,BV_Data_An_Cour!$V:$V,$D25) -> 0
A26: Frais Payés d'Avance | B26: =SUMIFS(BV_Data_An_Cour!$P:$P,BV_Data_An_Cour!$U:$U,$A$1,BV_Data_An_Cour!$V:$V,$A26) -> 17815.9 | D26: [...] | E26: =-SUMIFS(BV_Data_An_Cour!$P:$P,BV_Data_An_Cour!$U:$U,$A$1,BV_Data_An_Cour!$V:$V,$D26) -> 0
A27: [...] | B27: =SUMIFS(BV_Data_An_Cour!$P:$P,BV_Data_An_Cour!$U:$U,$A$1,BV_Data_An_Cour!$V:$V,$A27) -> 0 | D27: [...] | E27: =-SUMIFS(BV_Data_An_Cour!$P:$P,BV_Data_An_Cour!$U:$U,$A$1,BV_Data_An_Cour!$V:$V,$D27) -> 0
A28: [...] | B28: =SUMIFS(BV_Data_An_Cour!$P:$P,BV_Data_An_Cour!$U:$U,$A$1,BV_Data_An_Cour!$V:$V,$A28) -> 0 | D28: Total Frais Courus | E28: =SUM(E22:E24) -> 501061.14
A29: [...] | B29: =SUMIFS(BV_Data_An_Cour!$P:$P,BV_Data_An_Cour!$U:$U,$A$1,BV_Data_An_Cour!$V:$V,$A29) -> 0
A30: Total Autres | B30: =SUM(B23:B29) -> 20854.67 | D30: Total Passif Court Terme | E30: =+E5+E7+E16+E20+E28 -> 10893888
A32: Total Actif Court Terme | B32: =+B6+B16+B21+B30 -> 12024354
D33: Impôts Futurs à payer | E33: =-SUMIFS(BV_Data_An_Cour!$P:$P,BV_Data_An_Cour!$U:$U,$A$1,BV_Data_An_Cour!$V:$V,$D33) -> 1101731
A35: Terrain | B35: =SUMIFS(BV_Data_An_Cour!$P:$P,BV_Data_An_Cour!$U:$U,$A$1,BV_Data_An_Cour!$V:$V,$A35) -> 0 | D35: Avances Long Terme à Payer | E35: =-SUMIFS(BV_Data_An_Cour!$P:$P,BV_Data_An_Cour!$U:$U,$A$1,BV_Data_An_Cour!$V:$V,$D35) -> 0
A36: Bâtisse | B36: =SUMIFS(BV_Data_An_Cour!$P:$P,BV_Data_An_Cour!$U:$U,$A$1,BV_Data_An_Cour!$V:$V,$A36) -> 0 | D36: Hypothèque à Payer | E36: =-SUMIFS(BV_Data_An_Cour!$P:$P,BV_Data_An_Cour!$U:$U,$A$1,BV_Data_An_Cour!$V:$V,$D36) -> 0
A37: Améliorations Locatives | B37: =SUMIFS(BV_Data_An_Cour!$P:$P,BV_Data_An_Cour!$U:$U,$A$1,BV_Data_An_Cour!$V:$V,$A37) -> 654545.41 | D37: Dette à Long Terme | E37: =-SUMIFS(BV_Data_An_Cour!$P:$P,BV_Data_An_Cour!$U:$U,$A$1,BV_Data_An_Cour!$V:$V,$D37) -> 0
A38: Améliorations Locatives Permanentes | B38: =SUMIFS(BV_Data_An_Cour!$P:$P,BV_Data_An_Cour!$U:$U,$A$1,BV_Data_An_Cour!$V:$V,$A38) -> 0 | D38: Autres Dettes à Long Terme | E38: =-SUMIFS(BV_Data_An_Cour!$P:$P,BV_Data_An_Cour!$U:$U,$A$1,BV_Data_An_Cour!$V:$V,$D38) -> 0
A39: Équipements Service | B39: =SUMIFS(BV_Data_An_Cour!$P:$P,BV_Data_An_Cour!$U:$U,$A$1,BV_Data_An_Cour!$V:$V,$A39) -> 215251.67 | D39: [...] | E39: =-SUMIFS(BV_Data_An_Cour!$P:$P,BV_Data_An_Cour!$U:$U,$A$1,BV_Data_An_Cour!$V:$V,$D39) -> 0
A40: Mobilier | B40: =SUMIFS(BV_Data_An_Cour!$P:$P,BV_Data_An_Cour!$U:$U,$A$1,BV_Data_An_Cour!$V:$V,$A40) -> 114073.19 | D40: [...] | E40: =-SUMIFS(BV_Data_An_Cour!$P:$P,BV_Data_An_Cour!$U:$U,$A$1,BV_Data_An_Cour!$V:$V,$D40) -> 0
A41: Équipements Informatique | B41: =SUMIFS(BV_Data_An_Cour!$P:$P,BV_Data_An_Cour!$U:$U,$A$1,BV_Data_An_Cour!$V:$V,$A41) -> 14287.41 | D41: [...] | E41: =-SUMIFS(BV_Data_An_Cour!$P:$P,BV_Data_An_Cour!$U:$U,$A$1,BV_Data_An_Cour!$V:$V,$D41) -> 0
A42: Équipements Téléphonique | B42: =SUMIFS(BV_Data_An_Cour!$P:$P,BV_Data_An_Cour!$U:$U,$A$1,BV_Data_An_Cour!$V:$V,$A42) -> 0 | D42: Total Passif long terme | E42: =+SUM(E33:E38) -> 1101731
A43: Enseigne | B43: =SUMIFS(BV_Data_An_Cour!$P:$P,BV_Data_An_Cour!$U:$U,$A$1,BV_Data_An_Cour!$V:$V,$A43) -> 15453.32
A44: Total Immobilisations Nettes | B44: =SUM(B35:B43) -> 1013611
...

Sheet Budget original
B1: ="Budget 2023 Mensuel"&" "&Parametres!$B$1 -> Budget 2023 Mensuel BMW Sherbrooke
B2: Mois | F2: =+IF(Parametres!$B$3=F$6,"X","") | G2: =+IF(Parametres!$B$3=F$6,"O","") | H2: =+IF(Parametres!$B$3=F$6,"U","") | I2: =+IF(Parametres!$B$3=I$6,"X","") | J2: =+IF(Parametres!$B$3=I$6,"O","") | K2: =+IF(Parametres!$B$3=I$6,"U","") | L2: =+IF(Parametres!$B$3=L$6,"X","") | M2: =+IF(Parametres!$B$3=L$6,"O","") | N2: =+IF(Parametres!$B$3=L$6,"U","") | O2: =+IF(Parametres!$B$3=O$6,"X","") | P2: =+IF(Parametres!$B$3=O$6,"O","") | Q2: =+IF(Parametres!$B$3=O$6,"U","") | R2: =+IF(Parametres!$B$3=R$6,"X","") | S2: =+IF(Parametres!$B$3=R$6,"O","") | T2: =+IF(Parametres!$B$3=R$6,"U","") | U2: =+IF(Parametres!$B$3=U$6,"X","") | V2: =+IF(Parametres!$B$3=U$6,"O","") | W2: =+IF(Parametres!$B$3=U$6,"U","") | X2: =+IF(Parametres!$B$3=X$6,"X","") | Y2: =+IF(Parametres!$B$3=X$6,"O","") | Z2: =+IF(Parametres!$B$3=X$6,"U","") | AA2: =+IF(Parametres!$B$3=AA$6,"X","") | AB2: =+IF(Parametres!$B$3=AA$6,"O","") | AC2: =+IF(Parametres!$B$3=AA$6,"U","") | AD2: =+IF(Parametres!$B$3=AD$6,"X","") | AE2: =+IF(Parametres!$B$3=AD$6,"O","") | AF2: =+IF(Parametres!$B$3=AD$6,"U","") | AG2: =+IF(Parametres!$B$3=AG$6,"X","") | AH2: =+IF(Parametres!$B$3=AG$6,"O","") | AI2: =+IF(Parametres!$B$3=AG$6,"U","") | AJ2: =+IF(Parametres!$B$3=AJ$6,"X","") -> X | AK2: =+IF(Parametres!$B$3=AJ$6,"O","") -> O | AL2: =+IF(Parametres!$B$3=AJ$6,"U","") -> U | AM2: =+IF(Parametres!$B$3=AM$6,"X","") | AN2: =+IF(Parametres!$B$3=AM$6,"O","") | AO2: =+IF(Parametres!$B$3=AM$6,"U","")
B3: YTD | F3: =+IF(VLOOKUP(F$6,Parametres!$K$3:$N$14,4,0)="X","X","") -> X | G3: =+IF(VLOOKUP(F$6,Parametres!$K$3:$N$14,4,0)="X","O","") -> O | H3: =+IF(VLOOKUP(F$6,Parametres!$K$3:$N$14,4,0)="X","U","") -> U | I3: =+IF(VLOOKUP(I$6,Parametres!$K$3:$N$14,4,0)="X","X","") -> X | J3: =+IF(VLOOKUP(I$6,Parametres!$K$3:$N$14,4,0)="X","O","") -> O | K3: =+IF(VLOOKUP(I$6,Parametres!$K$3:$N$14,4,0)="X","U","") -> U | L3: =+IF(VLOOKUP(L$6,Parametres!$K$3:$N$14,4,0)="X","X","") -> X | M3: =+IF(VLOOKUP(L$6,Parametres!$K$3:$N$14,4,0)="X","O","") -> O | N3: =+IF(VLOOKUP(L$6,Parametres!$K$3:$N$14,4,0)="X","U","") -> U | O3: =+IF(VLOOKUP(O$6,Parametres!$K$3:$N$14,4,0)="X","X","") -> X | P3: =+IF(VLOOKUP(O$6,Parametres!$K$3:$N$14,4,0)="X","O","") -> O | Q3: =+IF(VLOOKUP(O$6,Parametres!$K$3:$N$14,4,0)="X","U","") -> U | R3: =+IF(VLOOKUP(R$6,Parametres!$K$3:$N$14,4,0)="X","X","") -> X | S3: =+IF(VLOOKUP(R$6,Parametres!$K$3:$N$14,4,0)="X","O","") -> O | T3: =+IF(VLOOKUP(R$6,Parametres!$K$3:$N$14,4,0)="X","U","") -> U | U3: =+IF(VLOOKUP(U$6,Parametres!$K$3:$N$14,4,0)="X","X","") -> X | V3: =+IF(VLOOKUP(U$6,Parametres!$K$3:$N$14,4,0)="X","O","") -> O | W3: =+IF(VLOOKUP(U$6,Parametres!$K$3:$N$14,4,0)="X","U","") -> U | X3: =+IF(VLOOKUP(X$6,Parametres!$K$3:$N$14,4,0)="X","X","") -> X | Y3: =+IF(VLOOKUP(X$6,Parametres!$K$3:$N$14,4,0)="X","O","") -> O | Z3: =+IF(VLOOKUP(X$6,Parametres!$K$3:$N$14,4,0)="X","U","") -> U | AA3: =+IF(VLOOKUP(AA$6,Parametres!$K$3:$N$14,4,0)="X","X","") -> X | AB3: =+IF(VLOOKUP(AA$6,Parametres!$K$3:$N$14,4,0)="X","O","") -> O | AC3: =+IF(VLOOKUP(AA$6,Parametres!$K$3:$N$14,4,0)="X","U","") -> U | AD3: =+IF(VLOOKUP(AD$6,Parametres!$K$3:$N$14,4,0)="X","X","") -> X | AE3: =+IF(VLOOKUP(AD$6,Parametres!$K$3:$N$14,4,0)="X","O","") -> O | AF3: =+IF(VLOOKUP(AD$6,Parametres!$K$3:$N$14,4,0)="X","U","") -> U | AG3: =+IF(VLOOKUP(AG$6,Parametres!$K$3:$N$14,4,0)="X","X","") -> X | AH3: =+IF(VLOOKUP(AG$6,Parametres!$K$3:$N$14,4,0)="X","O","") -> O | AI3: =+IF(VLOOKUP(AG$6,Parametres!$K$3:$N$14,4,0)="X","U","") -> U | AJ3: =+IF(VLOOKUP(AJ$6,Parametres!$K$3:$N$14,4,0)="X","X","") -> X | AK3: =+IF(VLOOKUP(AJ$6,Parametres!$K$3:$N$14,4,0)="X","O","") -> O | AL3: =+IF(VLOOKUP(AJ$6,Parametres!$K$3:$N$14,4,0)="X","U","") -> U | AM3: =+IF(VLOOKUP(AM$6,Parametres!$K$3:$N$14,4,0)="X","X","") | AN3: =+IF(VLOOKUP(AM$6,Parametres!$K$3:$N$14,4,0)="X","O","") | AO3: =+IF(VLOOKUP(AM$6,Parametres!$K$3:$N$14,4,0)="X","U","")
B4: Budget 2024 | C4: Véhicules neufs
B6: Mois | C6: 2024 | F6: Janvier | I6: Février | L6: Mars | O6: Avril | R6: Mai | U6: Juin | X6: Juillet | AA6: Août | AD6: Septembre | AG6: Octobre | AJ6: Novembre | AM6: Décembre
C7: UNITE | D7: $P/UNITE | E7: $PROFITS | F7: UNITE | G7: $P/UNITE | H7: $PROFITS | I7: UNITE | J7: $P/UNITE | K7: $PROFITS | L7: UNITE | M7: $P/UNITE | N7: $PROFITS | O7: UNITE | P7: $P/UNITE | Q7: $PROFITS | R7: UNITE | S7: $P/UNITE | T7: $PROFITS | U7: UNITE | V7: $P/UNITE | W7: $PROFITS | X7: UNITE | Y7: $P/UNITE | Z7: $PROFITS | AA7: UNITE | AB7: $P/UNITE | AC7: $PROFITS | AD7: UNITE | AE7: $P/UNITE | AF7: $PROFITS | AG7: UNITE | AH7: $P/UNITE | AI7: $PROFITS | AJ7: UNITE | AK7: $P/UNITE | AL7: $PROFITS | AM7: UNITE | AN7: $P/UNITE | AO7: $PROFITS
A8: =+$C$4&B8 -> Véhicules neufsVentes nettes | B8: Ventes nettes | E8: 23738856 | H8: 908508.74 | K8: 1154769.3 | N8: 2794294.1 | Q8: 3032403.6 | T8: 2803316.5 | W8: 2000167.3 | Z8: 1608193.6 | AC8: 2002452.1 | AF8: 2407689.2 | AI8: 1708172.4 | AL8: 1856597 | AO8: 1462292.2
A9: =+$C$4&B9 -> Véhicules neufsAutos détail | B9: Autos détail | C9: 81 | D9: 5144.9383 | E9: 416740 | F9: 3 | G9: 5144.9383 | H9: 15434.815 | I9: 4 | J9: 5144.9383 | K9: 20579.753 | L9: 9 | M9: 5144.9383 | N9: 46304.444 | O9: 10 | P9: 5144.9383 | Q9: 51449.383 | R9: 9 | S9: 5144.9383 | T9: 46304.444 | U9: 7 | V9: 5144.9383 | W9: 36014.568 | X9: 6 | Y9: 5144.9383 | Z9: 30869.63 | AA9: 7 | AB9: 5144.9383 | AC9: 36014.568 | AD9: 9 | AE9: 5144.9383 | AF9: 46304.444 | AG9: 6 | AH9: 5144.9383 | AI9: 30869.63 | AJ9: 6 | AK9: 5144.9383 | AL9: 30869.63 | AM9: 5 | AN9: 5144.9383 | AO9: 25724.691
A10: =+$C$4&B10 -> Véhicules neufsCamions détail | B10: Camions détail | C10: 151 | D10: 5386.4238 | E10: 813350 | F10: 6 | G10: 5386.4238 | H10: 32318.543 | I10: 7 | J10: 5386.4238 | K10: 37704.967 | L10: 18 | M10: 5386.4238 | N10: 96955.629 | O10: 19 | P10: 5386.4238 | Q10: 102342.05 | R10: 17 | S10: 5386.4238 | T10: 91569.205 | U10: 13 | V10: 5386.4238 | W10: 70023.51 | X10: 10 | Y10: 5386.4238 | Z10: 53864.238 | AA10: 13 | AB10: 5386.4238 | AC10: 70023.51 | AD10: 15 | AE10: 5386.4238 | AF10: 80796.358 | AG10: 11 | AH10: 5386.4238 | AI10: 59250.662 | AJ10: 12 | AK10: 5386.4238 | AL10: 64637.086 | AM10: 10 | AN10: 5386.4238 | AO10: 53864.238
A11: =+$C$4&B11 -> Véhicules neufsSprinter | B11: Sprinter | C11: 0 | D11: 0 | E11: 0 | F11: 0 | G11: 0 | H11: 0 | I11: 0 | J11: 0 | K11: 0 | L11: 0 | M11: 0 | N11: 0 | O11: 0 | P11: 0 | Q11: 0 | R11: 0 | S11: 0 | T11: 0 | U11: 0 | V11: 0 | W11: 0 | X11: 0 | Y11: 0 | Z11: 0 | AA11: 0 | AB11: 0 | AC11: 0 | AD11: 0 | AE11: 0 | AF11: 0 | AG11: 0 | AH11: 0 | AI11: 0 | AJ11: 0 | AK11: 0 | AL11: 0 | AM11: 0 | AN11: 0 | AO11: 0
A12: =+$C$4&B12 -> Véhicules neufsMoto détail | B12: Moto détail | C12: 0 | D12: 0 | E12: 0 | F12: 0 | G12: 0 | H12: 0 | I12: 0 | J12: 0 | K12: 0 | L12: 0 | M12: 0 | N12: 0 | O12: 0 | P12: 0 | Q12: 0 | R12: 0 | S12: 0 | T12: 0 | U12: 0 | V12: 0 | W12: 0 | X12: 0 | Y12: 0 | Z12: 0 | AA12: 0 | AB12: 0 | AC12: 0 | AD12: 0 | AE12: 0 | AF12: 0 | AG12: 0 | AH12: 0 | AI12: 0 | AJ12: 0 | AK12: 0 | AL12: 0 | AM12: 0 | AN12: 0 | AO12: 0
A13: =+$C$4&B13 -> Véhicules neufs[...] | B13: [...] | C13: 0 | D13: 0 | E13: 0 | G13: 0 | J13: 0 | M13: 0 | P13: 0 | S13: 0 | V13: 0 | Y13: 0 | AB13: 0 | AE13: 0 | AH13: 0 | AK13: 0 | AN13: 0
A14: =+$C$4&B14 -> Véhicules neufs[...] | B14: [...] | C14: 0 | D14: 0 | E14: 0 | G14: 0 | J14: 0 | M14: 0 | P14: 0 | S14: 0 | V14: 0 | Y14: 0 | AB14: 0 | AE14: 0 | AH14: 0 | AK14: 0 | AN14: 0
A15: =+$C$4&B15 -> Véhicules neufs[...] | B15: [...] | C15: 0 | D15: 0 | E15: 0 | G15: 0 | J15: 0 | M15: 0 | P15: 0 | S15: 0 | V15: 0 | Y15: 0 | AB15: 0 | AE15: 0 | AH15: 0 | AK15: 0 | AN15: 0
A16: =+$C$4&B16 -> Véhicules neufsTotal Neufs | B16: Total Neufs | C16: 232 | D16: 5302.1121 | E16: 1230090 | F16: 9 | G16: 5305.9287 | H16: 47753.358 | I16: 11 | J16: 5298.6109 | K16: 58284.72 | L16: 27 | M16: 5305.9287 | N16: 143260.07 | O16: 29 | P16: 5303.153 | Q16: 153791.44 | R16: 26 | S16: 5302.8327 | T16: 137873.65 | U16: 20 | V16: 5301.9039 | W16: 106038.08 | X16: 16 | Y16: 5295.8668 | Z16: 84733.868 | AA16: 20 | AB16: 5301.9039 | AC16: 106038.08 | AD16: 24 | AE16: 5295.8668 | AF16: 127100.8 | AG16: 17 | AH16: 5301.1936 | AI16: 90120.292 | AJ16: 18 | AK16: 5305.9287 | AL16: 95506.716 | AM16: 15 | AN16: 5305.9287 | AO16: 79588.93
A17: =+$C$4&B17 -> Véhicules neufs
A18: =+$C$4&B18 -> Véhicules neufsEx-Démos et courtoisies | B18: Ex-Démos et courtoisies | C18: 24 | D18: 2500 | E18: 60000 | F18: 1 | G18: 2500 | H18: 2500 | I18: 1 | J18: 2500 | K18: 2500 | L18: 3 | M18: 2500 | N18: 7500 | O18: 3 | P18: 2500 | Q18: 7500 | R18: 3 | S18: 2500 | T18: 7500 | U18: 2 | V18: 2500 | W18: 5000 | X18: 2 | Y18: 2500 | Z18: 5000 | AA18: 2 | AB18: 2500 | AC18: 5000 | AD18: 2 | AE18: 2500 | AF18: 5000 | AG18: 2 | AH18: 2500 | AI18: 5000 | AJ18: 2 | AK18: 2500 | AL18: 5000 | AM18: 1 | AN18: 2500 | AO18: 2500
A19: =+$C$4&B19 -> Véhicules neufs
A20: =+$C$4&B20 -> Véhicules neufsFlottes | B20: Flottes | C20: 4 | D20: 2500 | E20: 10000 | F20: 0 | G20: 0 | H20: 0 | I20: 0 | J20: 0 | K20: 0 | L20: 1 | M20: 2500 | N20: 2500 | O20: 1 | P20: 2500 | Q20: 2500 | R20: 1 | S20: 2500 | T20: 2500 | U20: 0 | V20: 0 | W20: 0 | X20: 0 | Y20: 0 | Z20: 0 | AA20: 0 | AB20: 0 | AC20: 0 | AD20: 1 | AE20: 2500 | AF20: 2500 | AG20: 0 | AH20: 0 | AI20: 0 | AJ20: 0 | AK20: 0 | AL20: 0 | AM20: 0 | AN20: 0 | AO20: 0
A21: =+$C$4&B21 -> Véhicules neufs
A22: =+$C$4&B22 -> Véhicules neufsRachat bail | B22: Rachat bail | E22: 38961 | H22: 1386.4053 | K22: 3512.1376 | N22: 3667.8254 | Q22: 5546.8032 | T22: 6629.0564 | W22: 2988.0085 | Z22: 1827.3374 | AC22: 3057.1768 | AF22: 2093.133 | AI22: 2165.8719 | AL22: 3970.9903 | AO22: 2116.2542
A23: =+$C$4&B23 -> Véhicules neufs
A24: =+$C$4&B24 -> Véhicules neufsRev. Finances | B24: Rev. Finances | D24: 85 | E24: 21760 | G24: 85 | H24: 850 | J24: 85 | K24: 1020 | M24: 85 | N24: 2550 | P24: 85 | Q24: 2720 | S24: 85 | T24: 2465 | V24: 85 | W24: 1870 | Y24: 85 | Z24: 1530 | AB24: 85 | AC24: 1870 | AE24: 85 | AF24: 2210 | AH24: 85 | AI24: 1615 | AK24: 85 | AL24: 1700 | AN24: 85 | AO24: 1360
A25: =+$C$4&B25 -> Véhicules neufsRev. Protections | B25: Rev. Protections | D25: 1020 | E25: 261120 | G25: 1020 | H25: 10200 | J25: 1020 | K25: 12240 | M25: 1020 | N25: 30600 | P25: 1020 | Q25: 32640 | S25: 1020 | T25: 29580 | V25: 1020 | W25: 22440 | Y25: 1020 | Z25: 18360 | AB25: 1020 | AC25: 22440 | AE25: 1020 | AF25: 26520 | AH25: 1020 | AI25: 19380 | AK25: 1020 | AL25: 20400 | AN25: 1020 | AO25: 16320
A26: =+$C$4&B26 -> Véhicules neufsRev. Autres | B26: Rev. Autres | D26: 495 | E26: 126720 | G26: 495 | H26: 4950 | J26: 495 | K26: 5940 | M26: 495 | N26: 14850 | P26: 495 | Q26: 15840 | S26: 495 | T26: 14355 | V26: 495 | W26: 10890 | Y26: 495 | Z26: 8910 | AB26: 495 | AC26: 10890 | AE26: 495 | AF26: 12870 | AH26: 495 | AI26: 9405 | AK26: 495 | AL26: 9900 | AN26: 495 | AO26: 7920
A27: =+$C$4&B27 -> Véhicules neufsTotal F&I | B27: Total F&I | C27: 256 | D27: 1600 | E27: 409600 | F27: 10 | G27: 1600 | H27: 16000 | I27: 12 | J27: 1600 | K27: 19200 | L27: 30 | M27: 1600 | N27: 48000 | O27: 32 | P27: 1600 | Q27: 51200 | R27: 29 | S27: 1600 | T27: 46400 | U27: 22 | V27: 1600 | W27: 35200 | X27: 18 | Y27: 1600 | Z27: 28800 | AA27: 22 | AB27: 1600 | AC27: 35200 | AD27: 26 | AE27: 1600 | AF27: 41600 | AG27: 19 | AH27: 1600 | AI27: 30400 | AJ27: 20 | AK27: 1600 | AL27: 32000 | AM27: 16 | AN27: 1600 | AO27: 25600
A28: =+$C$4&B28 -> Véhicules neufs
A29: =+$C$4&B29 -> Véhicules neufs
A30: =+$C$4&B30 -> Véhicules neufsTotal Dépt. Neufs | B30: Total Dépt. Neufs | C30: 260 | D30: 6725.5808 | E30: 1748651 | F30: 10 | G30: 6763.9763 | H30: 67639.763 | I30: 12 | J30: 6958.0715 | K30: 83496.858 | L30: 31 | M30: 6610.5774 | N30: 204927.9 | O30: 33 | P30: 6682.9769 | Q30: 220538.24 | R30: 30 | S30: 6696.7569 | T30: 200902.71 | U30: 22 | V30: 6783.0039 | W30: 149226.09 | X30: 18 | Y30: 6686.7336 | Z30: 120361.21 | AA30: 22 | AB30: 6786.1479 | AC30: 149295.25 | AD30: 27 | AE30: 6603.4791 | AF30: 178293.94 | AG30: 19 | AH30: 6720.3244 | AI30: 127686.16 | AJ30: 20 | AK30: 6823.8853 | AL30: 136477.71 | AM30: 16 | AN30: 6862.824 | AO30: 109805.18
A31: =+$C$4&B31 -> Véhicules neufs
A32: =+$C$4&B32 -> Véhicules neufs
A33: =+$C$4&B33 -> Véhicules neufsDEPENSES | B33: DEPENSES
A34: =+$C$4&B34 -> Véhicules neufsComm. vendeurs | B34: Comm. vendeurs | C34: 0.29576514 | D34: 1490.483 | E34: 381563.65 | F34: 0.3259414 | G34: 1637.965 | H34: 16379.65 | I34: 0.31901474 | J34: 1615.9352 | K34: 19391.222 | L34: 0.28836372 | M34: 1449.1245 | N34: 43473.736 | O34: 0.29022398 | P34: 1462.8326 | Q34: 46810.642 | R34: 0.29628195 | S34: 1485.2272 | T34: 43071.589 | U34: 0.28996409 | V34: 1463.5025 | W34: 32197.055 | X34: 0.29815739 | Y34: 1486.3786 | Z34: 26754.816 | AA34: 0.29244348 | AB34: 1476.0165 | AC34: 32472.362 | AD34: 0.28939001 | AE34: 1470.3328 | AF34: 38228.652 | AG34: 0.29688638 | AH34: 1486.3115 | AI34: 28239.919 | AJ34: 0.29683244 | AK34: 1491.6827 | AL34: 29833.654 | AM34: 0.30101931 | AN34: 1544.3971 | AO34: 24710.353
A35: =+$C$4&B35 -> Véhicules neufsComm. F&I | B35: Comm. F&I | C35: 0.25 | D35: 400 | E35: 102400 | F35: 0.25 | G35: 400 | H35: 4000 | I35: 0.25 | J35: 400 | K35: 4800 | L35: 0.25 | M35: 400 | N35: 12000 | O35: 0.25 | P35: 400 | Q35: 12800 | R35: 0.25 | S35: 400 | T35: 11600 | U35: 0.25 | V35: 400 | W35: 8800 | X35: 0.25 | Y35: 400 | Z35: 7200 | AA35: 0.25 | AB35: 400 | AC35: 8800 | AD35: 0.25 | AE35: 400 | AF35: 10400 | AG35: 0.25 | AH35: 400 | AI35: 7600 | AJ35: 0.25 | AK35: 400 | AL35: 8000 | AM35: 0.25 | AN35: 400 | AO35: 6400
A36: =+$C$4&B36 -> Véhicules neufsFrais de livraison | B36: Frais de livraison | D36: 100 | E36: 25600 | G36: 100 | H36: 1000 | J36: 100 | K36: 1200 | M36: 100 | N36: 3000 | P36: 100 | Q36: 3200 | S36: 100 | T36: 2900 | V36: 100 | W36: 2200 | Y36: 100 | Z36: 1800 | AB36: 100 | AC36: 2200 | AE36: 100 | AF36: 2600 | AH36: 100 | AI36: 1900 | AK36: 100 | AL36: 2000 | AN36: 100 | AO36: 1600
A37: =+$C$4&B37 -> Véhicules neufsService gratuit 1 | B37: Service gratuit 1 | D37: 45 | E37: 11520 | G37: 45 | H37: 450 | J37: 45 | K37: 540 | M37: 45 | N37: 1350 | P37: 45 | Q37: 1440 | S37: 45 | T37: 1305 | V37: 45 | W37: 990 | Y37: 45 | Z37: 810 | AB37: 45 | AC37: 990 | AE37: 45 | AF37: 1170 | AH37: 45 | AI37: 855 | AK37: 45 | AL37: 900 | AN37: 45 | AO37: 720
A38: =+$C$4&B38 -> Véhicules neufsEntretien stock | B38: Entretien stock | D38: 47.03125 | E38: 12040 | G38: 55 | H38: 550 | J38: 52.5 | K38: 630 | M38: 45 | N38: 1350 | P38: 44.6875 | Q38: 1430 | S38: 45.172414 | T38: 1310 | V38: 46.818182 | W38: 1030 | Y38: 48.333333 | Z38: 870 | AB38: 46.818182 | AC38: 1030 | AE38: 45.769231 | AF38: 1190 | AH38: 47.894737 | AI38: 910 | AK38: 47.5 | AL38: 950 | AN38: 49.375 | AO38: 790
A39: =+$C$4&B39 -> Véhicules neufsPublicité 1 | B39: Publicité 1 | D39: 496.60938 | E39: 127132 | G39: 496.60938 | H39: 4966.0938 | J39: 496.60938 | K39: 5959.3125 | M39: 496.60938 | N39: 14898.281 | P39: 496.60938 | Q39: 15891.5 | S39: 496.60938 | T39: 14401.672 | V39: 496.60938 | W39: 10925.406 | Y39: 496.60938 | Z39: 8938.9688 | AB39: 496.60938 | AC39: 10925.406 | AE39: 496.60938 | AF39: 12911.844 | AH39: 496.60938 | AI39: 9435.5781 | AK39: 496.60938 | AL39: 9932.1875 | AN39: 496.60938 | AO39: 7945.75
A40: =+$C$4&B40 -> Véhicules neufsIntérêt de gros | B40: Intérêt de gros | D40: 1254.1719 | E40: 321068.01 | G40: 2225.557 | H40: 22255.57 | J40: 2114.5035 | K40: 25374.042 | M40: 1066.4127 | N40: 31992.382 | P40: 960.50061 | Q40: 30736.02 | S40: 1007.2564 | T40: 29210.436 | V40: 1162.5435 | W40: 25575.958 | Y40: 1468.2494 | Z40: 26428.49 | AB40: 1296.1341 | AC40: 28514.95 | AE40: 1035.4639 | AF40: 26922.061 | AH40: 1378.7716 | AI40: 26196.661 | AK40: 1233.9278 | AL40: 24678.556 | AN40: 1448.9304 | AO40: 23182.886
A41: =+$C$4&B41 -> Véhicules neufs[...] | B41: [...] | D41: 0 | E41: 0 | G41: 0 | J41: 0 | M41: 0 | P41: 0 | S41: 0 | V41: 0 | Y41: 0 | AB41: 0 | AE41: 0 | AH41: 0 | AK41: 0 | AN41: 0
...

Sheet Réel 2023
B1: ="Budget 2023 Mensuel"&" "&Parametres!$B$1 -> Budget 2023 Mensuel BMW Sherbrooke
B2: Mois | F2: =+IF(Parametres!$B$3=F$6,"X","") | G2: =+IF(Parametres!$B$3=F$6,"O","") | H2: =+IF(Parametres!$B$3=F$6,"U","") | I2: =+IF(Parametres!$B$3=I$6,"X","") | J2: =+IF(Parametres!$B$3=I$6,"O","") | K2: =+IF(Parametres!$B$3=I$6,"U","") | L2: =+IF(Parametres!$B$3=L$6,"X","") | M2: =+IF(Parametres!$B$3=L$6,"O","") | N2: =+IF(Parametres!$B$3=L$6,"U","") | O2: =+IF(Parametres!$B$3=O$6,"X","") | P2: =+IF(Parametres!$B$3=O$6,"O","") | Q2: =+IF(Parametres!$B$3=O$6,"U","") | R2: =+IF(Parametres!$B$3=R$6,"X","") | S2: =+IF(Parametres!$B$3=R$6,"O","") | T2: =+IF(Parametres!$B$3=R$6,"U","") | U2: =+IF(Parametres!$B$3=U$6,"X","") | V2: =+IF(Parametres!$B$3=U$6,"O","") | W2: =+IF(Parametres!$B$3=U$6,"U","") | X2: =+IF(Parametres!$B$3=X$6,"X","") | Y2: =+IF(Parametres!$B$3=X$6,"O","") | Z2: =+IF(Parametres!$B$3=X$6,"U","") | AA2: =+IF(Parametres!$B$3=AA$6,"X","") | AB2: =+IF(Parametres!$B$3=AA$6,"O","") | AC2: =+IF(Parametres!$B$3=AA$6,"U","") | AD2: =+IF(Parametres!$B$3=AD$6,"X","") | AE2: =+IF(Parametres!$B$3=AD$6,"O","") | AF2: =+IF(Parametres!$B$3=AD$6,"U","") | AG2: =+IF(Parametres!$B$3=AG$6,"X","") | AH2: =+IF(Parametres!$B$3=AG$6,"O","") | AI2: =+IF(Parametres!$B$3=AG$6,"U","") | AJ2: =+IF(Parametres!$B$3=AJ$6,"X","") -> X | AK2: =+IF(Parametres!$B$3=AJ$6,"O","") -> O | AL2: =+IF(Parametres!$B$3=AJ$6,"U","") -> U | AM2: =+IF(Parametres!$B$3=AM$6,"X","") | AN2: =+IF(Parametres!$B$3=AM$6,"O","") | AO2: =+IF(Parametres!$B$3=AM$6,"U","")
B3: YTD | F3: =+IF(VLOOKUP(F$6,Parametres!$K$3:$N$14,4,0)="X","X","") -> X | G3: =+IF(VLOOKUP(F$6,Parametres!$K$3:$N$14,4,0)="X","O","") -> O | H3: =+IF(VLOOKUP(F$6,Parametres!$K$3:$N$14,4,0)="X","U","") -> U | I3: =+IF(VLOOKUP(I$6,Parametres!$K$3:$N$14,4,0)="X","X","") -> X | J3: =+IF(VLOOKUP(I$6,Parametres!$K$3:$N$14,4,0)="X","O","") -> O | K3: =+IF(VLOOKUP(I$6,Parametres!$K$3:$N$14,4,0)="X","U","") -> U | L3: =+IF(VLOOKUP(L$6,Parametres!$K$3:$N$14,4,0)="X","X","") -> X | M3: =+IF(VLOOKUP(L$6,Parametres!$K$3:$N$14,4,0)="X","O","") -> O | N3: =+IF(VLOOKUP(L$6,Parametres!$K$3:$N$14,4,0)="X","U","") -> U | O3: =+IF(VLOOKUP(O$6,Parametres!$K$3:$N$14,4,0)="X","X","") -> X | P3: =+IF(VLOOKUP(O$6,Parametres!$K$3:$N$14,4,0)="X","O","") -> O | Q3: =+IF(VLOOKUP(O$6,Parametres!$K$3:$N$14,4,0)="X","U","") -> U | R3: =+IF(VLOOKUP(R$6,Parametres!$K$3:$N$14,4,0)="X","X","") -> X | S3: =+IF(VLOOKUP(R$6,Parametres!$K$3:$N$14,4,0)="X","O","") -> O | T3: =+IF(VLOOKUP(R$6,Parametres!$K$3:$N$14,4,0)="X","U","") -> U | U3: =+IF(VLOOKUP(U$6,Parametres!$K$3:$N$14,4,0)="X","X","") -> X | V3: =+IF(VLOOKUP(U$6,Parametres!$K$3:$N$14,4,0)="X","O","") -> O | W3: =+IF(VLOOKUP(U$6,Parametres!$K$3:$N$14,4,0)="X","U","") -> U | X3: =+IF(VLOOKUP(X$6,Parametres!$K$3:$N$14,4,0)="X","X","") -> X | Y3: =+IF(VLOOKUP(X$6,Parametres!$K$3:$N$14,4,0)="X","O","") -> O | Z3: =+IF(VLOOKUP(X$6,Parametres!$K$3:$N$14,4,0)="X","U","") -> U | AA3: =+IF(VLOOKUP(AA$6,Parametres!$K$3:$N$14,4,0)="X","X","") -> X | AB3: =+IF(VLOOKUP(AA$6,Parametres!$K$3:$N$14,4,0)="X","O","") -> O | AC3: =+IF(VLOOKUP(AA$6,Parametres!$K$3:$N$14,4,0)="X","U","") -> U | AD3: =+IF(VLOOKUP(AD$6,Parametres!$K$3:$N$14,4,0)="X","X","") -> X | AE3: =+IF(VLOOKUP(AD$6,Parametres!$K$3:$N$14,4,0)="X","O","") -> O | AF3: =+IF(VLOOKUP(AD$6,Parametres!$K$3:$N$14,4,0)="X","U","") -> U | AG3: =+IF(VLOOKUP(AG$6,Parametres!$K$3:$N$14,4,0)="X","X","") -> X | AH3: =+IF(VLOOKUP(AG$6,Parametres!$K$3:$N$14,4,0)="X","O","") -> O | AI3: =+IF(VLOOKUP(AG$6,Parametres!$K$3:$N$14,4,0)="X","U","") -> U | AJ3: =+IF(VLOOKUP(AJ$6,Parametres!$K$3:$N$14,4,0)="X","X","") -> X | AK3: =+IF(VLOOKUP(AJ$6,Parametres!$K$3:$N$14,4,0)="X","O","") -> O | AL3: =+IF(VLOOKUP(AJ$6,Parametres!$K$3:$N$14,4,0)="X","U","") -> U | AM3: =+IF(VLOOKUP(AM$6,Parametres!$K$3:$N$14,4,0)="X","X","") | AN3: =+IF(VLOOKUP(AM$6,Parametres!$K$3:$N$14,4,0)="X","O","") | AO3: =+IF(VLOOKUP(AM$6,Parametres!$K$3:$N$14,4,0)="X","U","")
B4: Réel 2023 | C4: Véhicules neufs
B6: Mois | C6: 2023 | F6: Janvier | I6: Février | L6: Mars | O6: Avril | R6: Mai | U6: Juin | X6: Juillet | AA6: Août | AD6: Septembre | AG6: Octobre | AJ6: Novembre | AM6: Décembre
C7: UNITE | D7: $P/UNITE | E7: $PROFITS | F7: UNITE | G7: $P/UNITE | H7: $PROFITS | I7: UNITE | J7: $P/UNITE | K7: $PROFITS | L7: UNITE | M7: $P/UNITE | N7: $PROFITS | O7: UNITE | P7: $P/UNITE | Q7: $PROFITS | R7: UNITE | S7: $P/UNITE | T7: $PROFITS | U7: UNITE | V7: $P/UNITE | W7: $PROFITS | X7: UNITE | Y7: $P/UNITE | Z7: $PROFITS | AA7: UNITE | AB7: $P/UNITE | AC7: $PROFITS | AD7: UNITE | AE7: $P/UNITE | AF7: $PROFITS | AG7: UNITE | AH7: $P/UNITE | AI7: $PROFITS | AJ7: UNITE | AK7: $P/UNITE | AL7: $PROFITS | AM7: UNITE | AN7: $P/UNITE | AO7: $PROFITS
A8: =+$C$4&B8 -> Véhicules neufsVentes nettes | B8: Ventes nettes | E8: 44786734 | H8: 1359610 | K8: 788251.23 | N8: 2739760.8 | Q8: 2399882.7 | T8: 3061839.7 | W8: 1791786.6 | Z8: 1070672.8 | AC8: 2532428.1 | AF8: 2506516.8 | AI8: 8285274.9 | AL8: 10151414 | AO8: 8099296.2
A9: =+$C$4&B9 -> Véhicules neufsAutos détail | B9: Autos détail | C9: 86 | D9: 5345.9624 | E9: 459752.77 | F9: 4 | G9: 5270.98 | H9: 21083.92 | I9: 4 | J9: 3943.36 | K9: 15773.44 | L9: 9 | M9: 5970.7556 | N9: 53736.8 | O9: 9 | P9: 6333.3722 | Q9: 57000.35 | R9: 12 | S9: 4855.6392 | T9: 58267.67 | U9: 5 | V9: 5865.958 | W9: 29329.79 | X9: 2 | Y9: 4970.88 | Z9: 9941.76 | AA9: 9 | AB9: 5589.2289 | AC9: 50303.06 | AD9: 7 | AE9: 5593.4486 | AF9: 39154.14 | AG9: 5 | AH9: 4279.278 | AI9: 21396.39 | AJ9: 14 | AK9: 5054.9321 | AL9: 70769.05 | AM9: 6 | AN9: 5499.4 | AO9: 32996.4
A10: =+$C$4&B10 -> Véhicules neufsCamions détail | B10: Camions détail | C10: 136 | D10: 5686.1199 | E10: 773312.31 | F10: 6 | G10: 4340.0667 | H10: 26040.4 | I10: 4 | J10: 4483.6225 | K10: 17934.49 | L10: 15 | M10: 6103.068 | N10: 91546.02 | O10: 14 | P10: 6103.68 | Q10: 85451.52 | R10: 16 | S10: 5055.2144 | T10: 80883.43 | U10: 13 | V10: 5473.6615 | W10: 71157.6 | X10: 9 | Y10: 5731.4567 | Z10: 51583.11 | AA10: 14 | AB10: 5896.9686 | AC10: 82557.56 | AD10: 17 | AE10: 7536.4665 | AF10: 128119.93 | AG10: 13 | AH10: 4990.9962 | AI10: 64882.95 | AJ10: 8 | AK10: 4481.7612 | AL10: 35854.09 | AM10: 7 | AN10: 5328.7443 | AO10: 37301.21
A11: =+$C$4&B11 -> Véhicules neufsSprinter | B11: Sprinter | C11: 0 | D11: 0 | E11: 0 | F11: 0 | G11: 0 | H11: 0 | I11: 0 | J11: 0 | K11: 0 | L11: 0 | M11: 0 | N11: 0 | O11: 0 | P11: 0 | Q11: 0 | R11: 0 | S11: 0 | T11: 0 | U11: 0 | V11: 0 | W11: 0 | X11: 0 | Y11: 0 | Z11: 0 | AA11: 0 | AB11: 0 | AC11: 0 | AD11: 0 | AE11: 0 | AF11: 0 | AG11: 0 | AH11: 0 | AI11: 0 | AJ11: 0 | AK11: 0 | AL11: 0 | AM11: 0 | AN11: 0 | AO11: 0
A12: =+$C$4&B12 -> Véhicules neufsMoto détail | B12: Moto détail | C12: 0 | D12: 0 | E12: 0 | F12: 0 | G12: 0 | H12: 0 | I12: 0 | J12: 0 | K12: 0 | L12: 0 | M12: 0 | N12: 0 | O12: 0 | P12: 0 | Q12: 0 | R12: 0 | S12: 0 | T12: 0 | U12: 0 | V12: 0 | W12: 0 | X12: 0 | Y12: 0 | Z12: 0 | AA12: 0 | AB12: 0 | AC12: 0 | AD12: 0 | AE12: 0 | AF12: 0 | AG12: 0 | AH12: 0 | AI12: 0 | AJ12: 0 | AK12: 0 | AL12: 0 | AM12: 0 | AN12: 0 | AO12: 0
A13: =+$C$4&B13 -> Véhicules neufs[...] | B13: [...] | C13: 0 | D13: 0 | E13: 0 | G13: 0 | J13: 0 | M13: 0 | P13: 0 | S13: 0 | V13: 0 | Y13: 0 | AB13: 0 | AE13: 0 | AH13: 0 | AK13: 0 | AN13: 0
A14: =+$C$4&B14 -> Véhicules neufs[...] | B14: [...] | C14: 0 | D14: 0 | E14: 0 | G14: 0 | J14: 0 | M14: 0 | P14: 0 | S14: 0 | V14: 0 | Y14: 0 | AB14: 0 | AE14: 0 | AH14: 0 | AK14: 0 | AN14: 0
A15: =+$C$4&B15 -> Véhicules neufs[...] | B15: [...] | C15: 0 | D15: 0 | E15: 0 | G15: 0 | J15: 0 | M15: 0 | P15: 0 | S15: 0 | V15: 0 | Y15: 0 | AB15: 0 | AE15: 0 | AH15: 0 | AK15: 0 | AN15: 0
A16: =+$C$4&B16 -> Véhicules neufsTotal Neufs | B16: Total Neufs | C16: 222 | D16: 5554.3472 | E16: 1233065.1 | F16: 10 | G16: 4712.432 | H16: 47124.32 | I16: 8 | J16: 4213.4913 | K16: 33707.93 | L16: 24 | M16: 6053.4508 | N16: 145282.82 | O16: 23 | P16: 6193.5596 | Q16: 142451.87 | R16: 28 | S16: 4969.6821 | T16: 139151.1 | U16: 18 | V16: 5582.6328 | W16: 100487.39 | X16: 11 | Y16: 5593.17 | Z16: 61524.87 | AA16: 23 | AB16: 5776.5487 | AC16: 132860.62 | AD16: 24 | AE16: 6969.7529 | AF16: 167274.07 | AG16: 18 | AH16: 4793.2967 | AI16: 86279.34 | AJ16: 22 | AK16: 4846.5064 | AL16: 106623.14 | AM16: 13 | AN16: 5407.5085 | AO16: 70297.61
A17: =+$C$4&B17 -> Véhicules neufs
A18: =+$C$4&B18 -> Véhicules neufsEx-Démos et courtoisies | B18: Ex-Démos et courtoisies | C18: 21 | D18: 2993.8876 | E18: 62871.64 | F18: 2 | G18: 2750 | H18: 5500 | I18: 0 | J18: 0 | K18: 0 | L18: 1 | M18: 2500 | N18: 2500 | O18: 0 | P18: 0 | Q18: 0 | R18: 4 | S18: 5079.2875 | T18: 20317.15 | U18: 2 | V18: 5000 | W18: 10000 | X18: 2 | Y18: 7404.6 | Z18: 14809.2 | AA18: 3 | AB18: 2568.3867 | AC18: 7705.16 | AD18: 0 | AE18: 0 | AF18: -558.61 | AG18: 4 | AH18: 3882.6525 | AI18: 15530.61 | AJ18: 0 | AK18: 0 | AL18: -150 | AM18: 3 | AN18: -4260.6233 | AO18: -12781.87
A19: =+$C$4&B19 -> Véhicules neufs
A20: =+$C$4&B20 -> Véhicules neufsFlottes | B20: Flottes | C20: 4 | D20: 3136.3025 | E20: 12545.21 | F20: 1 | G20: 0 | H20: 0 | I20: 0 | J20: 0 | K20: 0 | L20: 2 | M20: 3453.48 | N20: 6906.96 | O20: 1 | P20: 5638.25 | Q20: 5638.25 | R20: 0 | S20: 0 | T20: 0 | U20: 0 | V20: 0 | W20: 0 | X20: 0 | Y20: 0 | Z20: 0 | AA20: 0 | AB20: 0 | AC20: 0 | AD20: 0 | AE20: 0 | AF20: 0 | AG20: 0 | AH20: 0 | AI20: 0 | AJ20: 0 | AK20: 0 | AL20: 0 | AM20: 0 | AN20: 0 | AO20: 0
A21: =+$C$4&B21 -> Véhicules neufs
A22: =+$C$4&B22 -> Véhicules neufsRachat bail | B22: Rachat bail | E22: 83269.17 | H22: 6793 | K22: 2996.96 | N22: 7991.96 | Q22: 8990.92 | T22: 8515.33 | W22: 9990 | Z22: 3486 | AC22: 9990 | AF22: 3996 | AI22: 4995 | AL22: 6029 | AO22: 9495
A23: =+$C$4&B23 -> Véhicules neufs
A24: =+$C$4&B24 -> Véhicules neufsRev. Finances | B24: Rev. Finances | D24: 65.425844 | E24: 15898.48 | G24: 117.1225 | H24: 1405.47 | J24: 0 | K24: 0 | M24: 16 | N24: 400 | P24: 47.826087 | Q24: 1100 | S24: 252.4375 | T24: 8078 | V24: 0 | W24: 0 | Y24: 17.089231 | Z24: 222.16 | AB24: 169.18077 | AC24: 4398.7 | AE24: -4.1666667 | AF24: -100 | AH24: 0 | AI24: 0 | AK24: 17.915909 | AL24: 394.15 | AN24: 0 | AO24: 0
A25: =+$C$4&B25 -> Véhicules neufsRev. Protections | B25: Rev. Protections | D25: 1042.7458 | E25: 253387.23 | G25: 1740 | H25: 20880 | J25: 504.29125 | K25: 4034.33 | M25: 798.16 | N25: 19954 | P25: 1404.4491 | Q25: 32302.33 | S25: 1132.4553 | T25: 36238.57 | V25: 993.7 | W25: 19874 | Y25: 1323.3077 | Z25: 17203 | AB25: 857.69231 | AC25: 22300 | AE25: 505.83333 | AF25: 12140 | AH25: 1077.7273 | AI25: 23710 | AK25: 1069.5 | AL25: 23529 | AN25: 1326.375 | AO25: 21222
A26: =+$C$4&B26 -> Véhicules neufsRev. Autres | B26: Rev. Autres | D26: 471.4023 | E26: 114550.76 | G26: 370.74167 | H26: 4448.9 | J26: 475.125 | K26: 3801 | M26: 603.5596 | N26: 15088.99 | P26: 452.38913 | Q26: 10404.95 | S26: 433.41875 | T26: 13869.4 | V26: 509 | W26: 10180 | Y26: 529.47615 | Z26: 6883.19 | AB26: 544.04769 | AC26: 14145.24 | AE26: 411.16667 | AF26: 9868 | AH26: 425.595 | AI26: 9363.09 | AK26: 411.54545 | AL26: 9054 | AN26: 465.25 | AO26: 7444
A27: =+$C$4&B27 -> Véhicules neufsTotal F&I | B27: Total F&I | C27: 243 | D27: 1579.574 | E27: 383836.47 | F27: 12 | G27: 2227.8642 | H27: 26734.37 | I27: 8 | J27: 979.41625 | K27: 7835.33 | L27: 25 | M27: 1417.7196 | N27: 35442.99 | O27: 23 | P27: 1904.6643 | Q27: 43807.28 | R27: 32 | S27: 1818.3116 | T27: 58185.97 | U27: 20 | V27: 1502.7 | W27: 30054 | X27: 13 | Y27: 1869.8731 | Z27: 24308.35 | AA27: 26 | AB27: 1570.9208 | AC27: 40843.94 | AD27: 24 | AE27: 912.83333 | AF27: 21908 | AG27: 22 | AH27: 1503.3223 | AI27: 33073.09 | AJ27: 22 | AK27: 1498.9614 | AL27: 32977.15 | AM27: 16 | AN27: 1791.625 | AO27: 28666
A28: =+$C$4&B28 -> Véhicules neufs
A29: =+$C$4&B29 -> Véhicules neufs
A30: =+$C$4&B30 -> Véhicules neufsTotal Dépt. Neufs | B30: Total Dépt. Neufs | C30: 247 | D30: 7188.6136 | E30: 1775587.6 | F30: 13 | G30: 6627.0531 | H30: 86151.69 | I30: 8 | J30: 5567.5275 | K30: 44540.22 | L30: 27 | M30: 7337.953 | N30: 198124.73 | O30: 24 | P30: 8370.3467 | Q30: 200888.32 | R30: 32 | S30: 7067.7984 | T30: 226169.55 | U30: 20 | V30: 7526.5695 | W30: 150531.39 | X30: 13 | Y30: 8009.8785 | Z30: 104128.42 | AA30: 26 | AB30: 7361.5277 | AC30: 191399.72 | AD30: 24 | AE30: 8025.8108 | AF30: 192619.46 | AG30: 22 | AH30: 6358.0927 | AI30: 139878.04 | AJ30: 22 | AK30: 6612.695 | AL30: 145479.29 | AM30: 16 | AN30: 5979.7963 | AO30: 95676.74
A31: =+$C$4&B31 -> Véhicules neufs
A32: =+$C$4&B32 -> Véhicules neufs
A33: =+$C$4&B33 -> Véhicules neufsDEPENSES | B33: DEPENSES
A34: =+$C$4&B34 -> Véhicules neufsComm. vendeurs | B34: Comm. vendeurs | C34: 0.29749071 | D34: 1586.5396 | E34: 385529.13 | F34: 0.34976528 | G34: 1533.8467 | H34: 18406.16 | I34: 0.29601996 | J34: 1247.2775 | K34: 9978.22 | L34: 0.27019853 | M34: 1597.228 | N34: 39930.7 | O34: 0.28986239 | P34: 1795.28 | Q34: 41291.44 | R34: 0.31640662 | S34: 1576.7753 | T34: 50456.81 | U34: 0.27667411 | V34: 1528.45 | W34: 30569 | X34: 0.26208271 | Y34: 1538.9108 | Z34: 20005.84 | AA34: 0.29395383 | AB34: 1589.225 | AC34: 41319.85 | AD34: 0.2302309 | AE34: 1599.2938 | AF34: 38383.05 | AG34: 0.39350525 | AH34: 1821.0341 | AI34: 40062.75 | AJ34: 0.30887114 | AK34: 1494.84 | AL34: 32886.48 | AM34: 0.38665642 | AN34: 1389.9269 | AO34: 22238.83
A35: =+$C$4&B35 -> Véhicules neufsComm. F&I | B35: Comm. F&I | C35: 0.24949122 | D35: 394.08984 | E35: 95763.83 | F35: 0.24999916 | G35: 556.96417 | H35: 6683.57 | I35: 0.24999968 | J35: 244.85375 | K35: 1958.83 | L35: 0.25000007 | M35: 354.43 | N35: 8860.75 | O35: 0.24755201 | P35: 471.50348 | Q35: 10844.58 | R35: 0.24986195 | S35: 454.32687 | T35: 14538.46 | U35: 0.24983363 | V35: 375.425 | W35: 7508.5 | X35: 0.25102856 | Y35: 469.39154 | Z35: 6102.09 | AA35: 0.25000012 | AB35: 392.73038 | AC35: 10210.99 | AD35: 0.25 | AE35: 228.20833 | AF35: 5477 | AG35: 0.24168501 | AH35: 363.33045 | AI35: 7993.27 | AJ35: 0.25379058 | AK35: 380.42227 | AL35: 8369.29 | AM35: 0.25174423 | AN35: 451.03125 | AO35: 7216.5
A36: =+$C$4&B36 -> Véhicules neufsFrais de livraison | B36: Frais de livraison | D36: 92.279918 | E36: 22424.02 | G36: 95.435833 | H36: 1145.23 | J36: 117.30375 | K36: 938.43 | M36: 64.8876 | N36: 1622.19 | P36: 88.415217 | Q36: 2033.55 | S36: 41.204375 | T36: 1318.54 | V36: 112.023 | W36: 2240.46 | Y36: 167.71846 | Z36: 2180.34 | AB36: 97.216538 | AC36: 2527.63 | AE36: 142.46208 | AF36: 3419.09 | AH36: 105.57727 | AI36: 2322.7 | AK36: 74.969545 | AL36: 1649.33 | AN36: 64.158125 | AO36: 1026.53
A37: =+$C$4&B37 -> Véhicules neufsService gratuit 1 | B37: Service gratuit 1 | D37: 44.81214 | E37: 10889.35 | G37: 66.046667 | H37: 792.56 | J37: 146 | K37: 1168 | M37: 13.0708 | N37: 326.77 | P37: 32.104783 | Q37: 738.41 | S37: 49.581562 | T37: 1586.61 | V37: 25.25 | W37: 505 | Y37: 67.839231 | Z37: 881.91 | AB37: 62.066538 | AC37: 1613.73 | AE37: 36.605 | AF37: 878.52 | AH37: 27.948182 | AI37: 614.86 | AK37: 53.87 | AL37: 1185.14 | AN37: 37.365 | AO37: 597.84
A38: =+$C$4&B38 -> Véhicules neufsEntretien stock | B38: Entretien stock | D38: 46.574733 | E38: 11317.66 | G38: 90.208333 | H38: 1082.5 | J38: 124.125 | K38: 993 | M38: 11.76 | N38: 294 | P38: 25.156522 | Q38: 578.6 | S38: 52.022188 | T38: 1664.71 | V38: 29.45 | W38: 589 | Y38: 37.923077 | Z38: 493 | AB38: 31.988462 | AC38: 831.7 | AE38: 52.96875 | AF38: 1271.25 | AH38: 55.568182 | AI38: 1222.5 | AK38: 55.704545 | AL38: 1225.5 | AN38: 66.99375 | AO38: 1071.9
A39: =+$C$4&B39 -> Véhicules neufsPublicité 1 | B39: Publicité 1 | D39: 588.02543 | E39: 142890.18 | G39: 705.6325 | H39: 8467.59 | J39: 1116.2625 | K39: 8930.1 | M39: 728.6512 | N39: 18216.28 | P39: 727.05478 | Q39: 16722.26 | S39: 436.2675 | T39: 13960.56 | V39: 542.347 | W39: 10846.94 | Y39: 730.09769 | Z39: 9491.27 | AB39: 353.25038 | AC39: 9184.51 | AE39: 444.47583 | AF39: 10667.42 | AH39: 466.17045 | AI39: 10255.75 | AK39: 667.48727 | AL39: 14684.72 | AN39: 716.42375 | AO39: 11462.78
A40: =+$C$4&B40 -> Véhicules neufsIntérêt de gros | B40: Intérêt de gros | D40: 476.63449 | E40: 115822.18 | G40: 441.83417 | H40: 5302.01 | J40: 750.3125 | K40: 6002.5 | M40: 128.7224 | N40: 3218.06 | P40: 227.60826 | Q40: 5234.99 | S40: 236.32094 | T40: 7562.27 | V40: 276.6485 | W40: 5532.97 | Y40: 532.72154 | Z40: 6925.38 | AB40: 563.735 | AC40: 14657.11 | AE40: 711.69708 | AF40: 17080.73 | AH40: 631.93545 | AI40: 13902.58 | AK40: 645.76591 | AL40: 14206.85 | AN40: 1012.2956 | AO40: 16196.73
A41: =+$C$4&B41 -> Véhicules neufs[...] | B41: [...] | D41: 0 | E41: 0 | G41: 0 | J41: 0 | M41: 0 | P41: 0 | S41: 0 | V41: 0 | Y41: 0 | AB41: 0 | AE41: 0 | AH41: 0 | AK41: 0 | AN41: 0
...

Sheet Capex
A1: CONCESSION
A2: Forecast Immobilisation 2024 | H2: 1 | I2: 2 | J2: 3 | K2: 4 | L2: 5 | M2: 6 | N2: 7 | O2: 8 | P2: 9 | Q2: 10 | R2: 11 | S2: 12
H3: =+IF(VLOOKUP(H2,Parametres!$L$3:$N$14,3,0)="X","REEL","FORECAST") -> REEL | I3: =+IF(VLOOKUP(I2,Parametres!$L$3:$N$14,3,0)="X","REEL","FORECAST") -> REEL | J3: =+IF(VLOOKUP(J2,Parametres!$L$3:$N$14,3,0)="X","REEL","FORECAST") -> REEL | K3: =+IF(VLOOKUP(K2,Parametres!$L$3:$N$14,3,0)="X","REEL","FORECAST") -> REEL | L3: =+IF(VLOOKUP(L2,Parametres!$L$3:$N$14,3,0)="X","REEL","FORECAST") -> REEL | M3: =+IF(VLOOKUP(M2,Parametres!$L$3:$N$14,3,0)="X","REEL","FORECAST") -> REEL | N3: =+IF(VLOOKUP(N2,Parametres!$L$3:$N$14,3,0)="X","REEL","FORECAST") -> REEL | O3: =+IF(VLOOKUP(O2,Parametres!$L$3:$N$14,3,0)="X","REEL","FORECAST") -> REEL | ... S3: =+IF(VLOOKUP(S2,Parametres!$L$3:$N$14,3,0)="X","REEL","FORECAST") -> FORECAST
A4: Concession | B4: Budgété / Non budgété | C4: Projet | D4: Catégorie Immo | E4: Total forecast | F4: Budget Annuel | G4: Écart vs budget | H4: January | I4: February | J4: March | K4: April | L4: May | M4: June | N4: July | O4: August | P4: September | Q4: October | R4: November | S4: December | T4: Raison / Description
C5: Total | E5: =+SUM(E6:E40) -> 209190 | F5: =+SUM(F6:F40) -> 240000 | G5: =+SUM(G6:G40) -> -30810 | H5: =+SUM(H6:H40) -> 1922 | I5: =+SUM(I6:I40) -> 5358 | J5: =+SUM(J6:J40) -> 4856 | K5: =+SUM(K6:K40) -> 3323 | L5: =+SUM(L6:L40) -> 0 | ... S5: =+SUM(S6:S40) -> 164806 | X5: Terrain
A6: =+Parametres!$B$1 -> BMW Sherbrooke | B6: oui | C6: Borne électrique | D6: Équipements Service | E6: =+SUM(H6:S6) -> 126000 | F6: 145000 | G6: =+E6-F6 -> -19000 | S6: 126000 | X6: Bâtisse
A7: =+Parametres!$B$1 -> BMW Sherbrooke | B7: oui | C7: Mise à jour pour MSP | D7: Améliorations Locatives | E7: =+SUM(H7:S7) -> 40000 | F7: 40000 | G7: =+E7-F7 -> 0 | K7: 1324 | N7: 5192 | P7: 12688 | Q7: 1990 | S7: 18806 | X7: Améliorations Locatives
A8: =+Parametres!$B$1 -> BMW Sherbrooke | B8: oui | C8: Pilon enseigne | D8: Améliorations Locatives | E8: =+SUM(H8:S8) -> 0 | F8: 25000 | G8: =+E8-F8 -> -25000 | X8: Améliorations Locatives Permanentes
A9: =+Parametres!$B$1 -> BMW Sherbrooke | B9: oui | C9: Mise à niveau entreposage | D9: Améliorations Locatives | E9: =+SUM(H9:S9) -> 20000 | F9: 20000 | G9: =+E9-F9 -> 0 | S9: 20000 | X9: Équipements Service
A10: =+Parametres!$B$1 -> BMW Sherbrooke | B10: non | C10: Outils obligatoire | D10: Équipements Service | E10: =+SUM(H10:S10) -> 16033 | F10: 10000 | G10: =+E10-F10 -> 6033 | H10: 1922 | I10: 2688 | J10: 3856 | K10: 1999 | M10: 722 | N10: 1783 | P10: 1120 | Q10: 1943 | X10: Mobilier
A11: =+Parametres!$B$1 -> BMW Sherbrooke | B11: non | C11: Repeindre salle conférence | D11: Améliorations Locatives Permanentes | E11: =+SUM(H11:S11) -> 2670 | G11: =+E11-F11 -> 2670 | I11: 2670 | X11: Équipements Informatique
A12: =+Parametres!$B$1 -> BMW Sherbrooke | B12: non | C12: Chaises salle conférence | D12: Mobilier | E12: =+SUM(H12:S12) -> 1000 | G12: =+E12-F12 -> 1000 | J12: 1000 | X12: Équipements Téléphonique
A13: =+Parametres!$B$1 -> BMW Sherbrooke | B13: non | C13: Ordinateur atelier | E13: =+SUM(H13:S13) -> 2447 | G13: =+E13-F13 -> 2447 | O13: 2447 | X13: Enseigne
A14: =+Parametres!$B$1 -> BMW Sherbrooke | B14: non | C14: Caméras | E14: =+SUM(H14:S14) -> 1040 | G14: =+E14-F14 -> 1040 | O14: 1040
A15: =+Parametres!$B$1 -> BMW Sherbrooke | B15: non | E15: =+SUM(H15:S15) -> 0 | G15: =+E15-F15 -> 0
A16: =+Parametres!$B$1 -> BMW Sherbrooke | B16: non | E16: =+SUM(H16:S16) -> 0 | G16: =+E16-F16 -> 0
A17: =+Parametres!$B$1 -> BMW Sherbrooke | B17: non | E17: =+SUM(H17:S17) -> 0 | G17: =+E17-F17 -> 0
A18: =+Parametres!$B$1 -> BMW Sherbrooke | B18: non | E18: =+SUM(H18:S18) -> 0 | G18: =+E18-F18 -> 0
A19: =+Parametres!$B$1 -> BMW Sherbrooke | B19: non | E19: =+SUM(H19:S19) -> 0 | G19: =+E19-F19 -> 0
A20: =+Parametres!$B$1 -> BMW Sherbrooke | B20: non | E20: =+SUM(H20:S20) -> 0 | G20: =+E20-F20 -> 0
A21: =+Parametres!$B$1 -> BMW Sherbrooke | B21: non | E21: =+SUM(H21:S21) -> 0 | G21: =+E21-F21 -> 0
A22: =+Parametres!$B$1 -> BMW Sherbrooke | B22: non | E22: =+SUM(H22:S22) -> 0 | G22: =+E22-F22 -> 0
A23: =+Parametres!$B$1 -> BMW Sherbrooke | B23: non | E23: =+SUM(H23:S23) -> 0 | G23: =+E23-F23 -> 0
A24: =+Parametres!$B$1 -> BMW Sherbrooke | B24: non | E24: =+SUM(H24:S24) -> 0 | G24: =+E24-F24 -> 0
A25: =+Parametres!$B$1 -> BMW Sherbrooke | B25: non | E25: =+SUM(H25:S25) -> 0 | G25: =+E25-F25 -> 0
A26: =+Parametres!$B$1 -> BMW Sherbrooke | B26: non | E26: =+SUM(H26:S26) -> 0 | G26: =+E26-F26 -> 0
... A35: =+Parametres!$B$1 -> BMW Sherbrooke | B35: non | E35: =+SUM(H35:S35) -> 0 | G35: =+E35-F35 -> 0
A36: =+Parametres!$B$1 -> BMW Sherbrooke | B36: non | E36: =+SUM(H36:S36) -> 0 | G36: =+E36-F36 -> 0 | X36: oui
A37: =+Parametres!$B$1 -> BMW Sherbrooke | B37: non | E37: =+SUM(H37:S37) -> 0 | G37: =+E37-F37 -> 0 | X37: non
A38: =+Parametres!$B$1 -> BMW Sherbrooke | B38: non | E38: =+SUM(H38:S38) -> 0 | G38: =+E38-F38 -> 0
A39: =+Parametres!$B$1 -> BMW Sherbrooke | B39: non | E39: =+SUM(H39:S39) -> 0 | G39: =+E39-F39 -> 0
A40: =+Parametres!$B$1 -> BMW Sherbrooke | B40: non | E40: =+SUM(H40:S40) -> 0 | G40: =+E40-F40 -> 0

Sheet Inventaire_Neuf
A1: #Contrôle | B1: Année | C1: Marque | D1: Modèle | E1: $ Inventaire | F1: $ Financé | G1: NIV | H1: Jours en stock | L1: $ Inventaire | M1: $ Financé
A2: 23019 | B2: 2023 | C2: BMW | D2: 430 | E2: 65121.87 | F2: -60905.25 | G2: WBA73AP05PCL27730 | H2: 478 | K2: CTRL | L2: =+SUM(E2:E10000) -> 3938633.3 | M2: =+SUM(F2:F10000) -> -3910068
A3: 23020 | B3: 2023 | C3: BMW | D3: 430 | E3: 63963.67 | G3: WBA73AP06PCL26036 | H3: 465 | L3: =+COUNT(E2:E10000) -> 45
A4: 23084 | B4: 2023 | C4: BMW | D4: 530xe | E4: 75509.5 | G4: WBA33AG06PCL42221 | H4: 411
A5: 23218 | B5: 2023 | C5: BMW SAV | D5: X3 | E5: 84833.61 | F5: -88452 | G5: 5UX83DP04P9T17873 | H5: 146
A6: 23221 | B6: 2023 | C6: BMW | D6: SERIE 2 | E6: 66617.36 | F6: -69326.25 | G6: 3MW53CM06P8D70441 | H6: 151
A7: 23228 | B7: 2023 | C7: BMW SAV | D7: X3 | E7: 73335.37 | F7: -69809.25 | G7: 5UX53DP06P9T28635 | H7: 143
A8: 23240 | B8: 2023 | C8: BMW SAV | D8: X1 | E8: 50471.49 | F8: -50473.5 | G8: WBX73EF02P5X85602 | H8: 67
A9: 23241 | B9: 2023 | C9: BMW SAV | D9: X1 | E9: 50262.11 | F9: -52143 | G9: WBX73EF00P5X86053 | H9: 58
A10: 24019 | B10: 2024 | C10: BMW SAV | D10: X5 | E10: 95266.49 | F10: -95303.25 | G10: 5UX23EU05R9T15522 | H10: 158
A11: 24023 | B11: 2024 | C11: BMW SAV | D11: X7 | E11: 126612.36 | F11: -131675.25 | G11: 5UX23EM04R9T23238 | H11: 149
A12: 24024 | B12: 2024 | C12: BMWI | D12: IX40 | E12: 97633.14 | F12: -97203.75 | G12: WB513CF03RCN76497 | H12: 152
A13: 24032 | B13: 2024 | C13: BMW SAV | D13: X6 | E13: 103328.55 | F13: -107651.25 | G13: 5UX33EX02R9T31595 | H13: 144
A14: 24034 | B14: 2024 | C14: BMW | D14: SERIE 4 | E14: 66533.61 | F14: -69237 | G14: WBA73AP07RCN92250 | H14: 144
A15: 24038 | B15: 2024 | C15: BMWI | D15: I7 | E15: 159476.47 | F15: -173664.75 | G15: WBY53EJ01RCN94634 | H15: 142
A16: 24051 | B16: 2024 | C16: BMW | D16: SERIE 3 | E16: 62907.21 | F16: -60149.52 | G16: 3MW89FF00R8D80878 | H16: 117
... A46: 24130 | B46: 2024 | C46: BMW SAV | D46: X3 | E46: 65370 | F46: -68638.5 | G46: 5UX53DP06R9U99484 | H46: 9

Sheet Inventaire_Used
A1: #Contrôle | B1: Année | C1: Marque | D1: Description | E1: Amount | F1: Financé | G1: NIV | H1: Jours en stock | L1: $ Inventaire | M1: $ Financé
A2: P0512 | B2: 2004 | C2: CHEVROLET TRUCK | D2: SILVERADO 2500 | E2: 3856.45 | G2: 1GCGK23U14F218132 | H2: 1482 | K2: CTRL | L2: =+SUM(E2:E9999) -> 1972155.4 | M2: =+SUM(F2:F9999) -> -1357394.6
A3: P2173 | B3: 2022 | C3: BMW | D3: 540i | E3: 75917.21 | F3: -50220 | G3: WBA73BJ07NWX54871 | H3: 490 | L3: =+COUNT(E2:E10000) -> 50
A4: P2259 | B4: 2021 | C4: BMW SAV | D4: X5 | E4: 75668.81 | F4: -55025 | G4: 5UXTA6C07M9G89398 | H4: 306
A5: P2282 | B5: 2019 | C5: BMW | D5: Z4 | E5: 61477.55 | F5: -55037.5 | G5: WBAHF3C57KWW21386 | H5: 235
A6: P2321 | B6: 2021 | C6: JEEP | D6: GLADIATOR 4X4 | E6: 57247.58 | F6: -48210.15 | G6: 1C6HJTAG8ML543623 | H6: 144
A7: P2327 | B7: 2023 | C7: BMW SAV | D7: X1 | E7: 51697.81 | F7: -49599.39 | G7: WBX73EF03P5W40276 | H7: 137
A8: 23231A | B8: 2020 | C8: MINI | D8: COUNTRYMAN | E8: 35295.85 | F8: -20589.76 | G8: WMZYZ9C04L3L18702 | H8: 125
A9: P2334 | B9: 2019 | C9: BMW | D9: 330i | E9: 31287.41 | F9: -23537.41 | G9: WBA5R7C54KFH22955 | H9: 111
A10: 23193A | B10: 2022 | C10: VOLVO | D10: XC60 | E10: 58424.95 | F10: -80500 | G10: LYV062RL8NB979235 | H10: 108
A11: P2335 | B11: 2020 | C11: BMW SAV | D11: X3 | E11: 30904.85 | F11: -21000 | G11: 5UXTY5C03L9D44647 | H11: 103
A12: 24082A | B12: 2023 | C12: MAZDA | D12: MX-5 | E12: 34707.45 | F12: -32060.23 | G12: JM1NDAD7XP0552574 | H12: 73
A13: 23225A | B13: 2023 | C13: BMW | D13: 330i | E13: 54482.17 | F13: -37837.25 | G13: WBA83FF0XPFN75280 | H13: 72
A14: P2342A | B14: 2023 | C14: BMW | D14: 530e | E14: 65103.95 | F14: -45150 | G14: WBA33AG00PCL72878 | H14: 72
A15: P2343 | B15: 2023 | C15: ACURA | D15: Integra | E15: 39059.95 | F15: -35100 | G15: 19UDE4G72PA800656 | H15: 67
... A28: P2356 | B28: 2021 | C28: ACURA | D28: TLX | E28: 39793.95 | F28: -35550 | G28: 19UUB6F51MA801958 | H28: 38
A29: 24098A | B29: 2015 | C29: MINI | D29: 5 DOOR | E29: 8000 | G29: WMWXS5C59FT837198 | H29: 38
A30: 23116B | B30: 2021 | C30: JEEP | D30: Wrangler Unlim | E30: 43899.95 | F30: -30450 | G30: 1C4HJXEN3MW680010 | H30: 37
A31: 24078A | B31: 2023 | C31: VOLKSWAGEN | D31: ID.4 | E31: 47899.95 | F31: -34300 | G31: 1V2JNPE8XPC021183 | H31: 31
A32: 23243A | B32: 2020 | C32: BMW | D32: 2 SERIES | E32: 29024.85 | F32: -19599.51 | G32: WBA73AK0XL7G01503 | H32: 26
A33: P2361 | B33: 2014 | C33: BMW | D33: 320i | E33: 11164.86 | G33: WBA3C3C57EK200069 | H33: 22
A34: P2362 | B34: 2023 | C34: BMW | D34: M240i xDrive | E34: 53250.2 | F34: -52796.25 | G34: 3MW53CM03P8C99750 | H34: 20
A35: P2363 | B35: 2023 | C35: BMW | D35: 230i | E35: 42103.5 | F35: -41658.65 | G35: 3MW33CM08P8C93109 | H35: 18
A36: P2364 | B36: 2017 | C36: BMW SAV | D36: X4 | E36: 27407.01 | F36: -24300 | G36: 5UXXW3C37H0T79741 | H36: 17
A37: 24040A | B37: 2023 | C37: BMW SAV | D37: X4 | E37: 58745 | F37: -45726.94 | G37: 5UX33DT01P9N56202 | H37: 13
A38: P2367 | B38: 2019 | C38: NISSAN | D38: Micra | E38: 11000 | F38: -9900 | G38: 3N1CK3CP5KL236170 | H38: 10
A39: 23244A | B39: 2019 | C39: BMW SAV | D39: X2 | E39: 26995 | F39: -16020.18 | G39: WBXYJ5C54K5N01549 | H39: 10
A40: 24103A | B40: 2021 | C40: BMW SAV | D40: X3 | E40: 42500 | F40: -30072.18 | G40: 5UXTS1C06M9H64396 | H40: 10
A41: P2223A | B41: 2023 | C41: BMW | D41: I4 | E41: 51776.06 | F41: -29211.39 | G41: WBY43AW09PFP45888 | H41: 10
A42: P2366 | B42: 2012 | C42: BMW | D42: M3 | E42: 37500 | G42: WBSKG9C53CE798848 | H42: 10
A43: P2365 | B43: 2021 | C43: DODGE TRUCK | D43: RAM 1500 Class | E43: 32547.15 | F43: -32547.15 | G43: 3C6RR7KG7MG709002 | H43: 9
A44: 23227A | B44: 2017 | C44: HONDA | D44: CIVIC HATCHBAC | E44: 14000 | G44: SHHFK7H26HU304092 | H44: 9
A45: 24097A | B45: 2018 | C45: AUDI | D45: A5 Sportback | E45: 18500 | G45: WAUANCF51JA004190 | H45: 3
A46: 24126A | B46: 2017 | C46: BMW | D46: 2 SERIES | E46: 28000 | G46: WBA2L3C32HV667851 | H46: 3
A47: 24091B | B47: 2013 | C47: VOLKSWAGEN | D47: JETTA | E47: 1500 | G47: 3VW1K7AJ9DM416983 | H47: 2
A48: 24125B | B48: 2017 | C48: BMW | D48: 650i | E48: 37000 | G48: WBA6F7C50HD930698 | H48: 2
A49: 23122A | B49: 2022 | C49: BMW | D49: 2 SERIES | E49: 37500 | G49: WBA13AL03N7K75967 | H49: 2
A50: 24125A | B50: 2021 | C50: BMW SAV | D50: X5 | E50: 60000 | G50: 5UXJU4C08M9E22693 | H50: 2
A51: 24104B | B51: 2019 | C51: BMW SAV | D51: X2 | E51: 31000 | G51: WBXYN1C56K5N23209 | H51: 0

Sheet Démo
B1: Suivi de Démo
B2: # Stock | C2: NIV | D2: Année | E2: Marque | F2: Modèle | G2: $ Valeur | H2: Nom | I2: Prénom | J2: Titre / Fonction
B4: 25063 | C4: 5UX53GP06S9Y02514 | D4: 2025 | E4: BMW | F4: X3 | G4: 67775 | H4: Rosa | I4: Yvon | J4: Conseiller aux ventes
B5: P2477 | C5: 3TYLB5JN7RT043814 | D5: 2024 | E5: Toyota | F5: Tacoma | G5: 63335 | H5: Beaudoin | I5: Sébastien | J5: VPDG

Sheet Wholesale
C1: ="Analyse Wholesale "&Parametres!B1 -> Analyse Wholesale BMW Sherbrooke
D2: $ | F2: X | G2: U | L2: $ | N2: X | O2: U
E4: =CONCATENATE("Pièces Wholesale ",Parametres!B3," ",Parametres!B4) -> Pièces Wholesale Novembre 2024 | J4: =CONCATENATE("Pièces Wholesale AAD ",Parametres!B4) -> Pièces Wholesale AAD 2024
E5: Réel | F5: Budget | G5: ▲ $ | H5: ▲ % | J5: Réel | K5: Budget | L5: ▲ $ | M5: ▲ %
C6: NB de livraisons | E6: =SUMIF(A37:A48,"X",E37:E48) -> 9 | F6: =SUMIF(A37:A48,"X",F37:F48) -> 30 | G6: =E6-F6 -> -21 | H6: =G6/F6 -> -0.7 | J6: =SUMIF($B$37:$B$48,"X",$E$37:$E$48) -> 219 | K6: =SUMIF($B$37:$B$48,"X",$F$37:$F$48) -> 330 | L6: =J6-K6 -> -111 | M6: =L6/K6 -> -0.33636364
A7: =B7&C7 -> piècesVentes de Gros | B7: pièces | C7: Ventes de Gros | E7: =-SUMIFS(BV_Data_An_Cour!$O:$O,BV_Data_An_Cour!$X:$X,"Oui",BV_Data_An_Cour!$U:$U,$B7,BV_Data_An_Cour!$V:$V,$C7) -> 54580.51 | F7: =+INDEX('Budget original'!$A$2:$AO$501,MATCH($A7,'Budget original'!$A$2:$A$501,0),MATCH(F$2,'Budget original'!$A$2:$AO$2,0)) -> 66469.273 | G7: =E7-F7 -> -11888.763 | H7: =G7/F7 -> -0.17886104 | J7: =-SUMIFS(BV_Data_An_Cour!$P:$P,BV_Data_An_Cour!$X:$X,"Oui",BV_Data_An_Cour!$U:$U,$B7,BV_Data_An_Cour!$V:$V,$C7) -> 498337.62 | K7: {=+SUMPRODUCT(('Budget original'!$A$8:$A$501=$A7)*('Budget original'!$C$3:$AO$3=N$2),'Budget original'!$C$8:$AO$501)} -> 718112.28 | L7: =J7-K7 -> -219774.66 | M7: =L7/K7 -> -0.30604498
C8: Coûts | E8: =E7-E9 -> 41910.39 | F8: =F7-F9 -> 49386.668 | G8: =E8-F8 -> -7476.2781 | H8: =G8/F8 -> -0.15138252 | J8: =J7-J9 -> 378453.97 | K8: =K7-K9 -> 533557.44 | L8: =J8-K8 -> -155103.47 | M8: =L8/K8 -> -0.29069685
C9: Profit brut | E9: =E12+E11 -> 12670.12 | F9: =F12+F11 -> 17082.605 | G9: =E9-F9 -> -4412.4852 | H9: =G9/F9 -> -0.25830283 | J9: =J12+J11 -> 119883.65 | K9: =K12+K11 -> 184554.85 | L9: =J9-K9 -> -64671.196 | M9: =L9/K9 -> -0.35041722
C10: % avant redevances | E10: =E9/E7 -> 0.23213634 | F10: =F9/F7 -> 0.25700003 | G10: =E10-F10 -> -0.024863687 | J10: =J9/J7 -> 0.24056713 | K10: =K9/K7 -> 0.25699999 | L10: =J10-K10 -> -0.016432858
C11: Coûts de redevance | E11: =SUMIFS(BV_Data_An_Cour!$O:$O,BV_Data_An_Cour!$W:$W,$D$2,BV_Data_An_Cour!L:L,C31) -> 956.16 | F11: =SUMIF($A$37:$A$48,"X",$G$37:$G$48) -> 2924.65 | G11: =E11-F11 -> -1968.49 | H11: =G11/F11 -> -0.67306857 | J11: =SUMIFS(BV_Data_An_Cour!$P:$P,BV_Data_An_Cour!$W:$W,$L$2,BV_Data_An_Cour!T:T,C31) -> 16710.25 | K11: =SUMIF($B$37:$B$48,"X",$G$37:$G$48) -> 31596.93 | L11: =J11-K11 -> -14886.68 | M11: =L11/K11 -> -0.47114324
