Workbook
Name _Dates_Conc: #REF!
Name _Dates_Conc: #REF!
Name _scen: #REF!
Name _scen: #REF!
Name _scen1: #REF!
Name _scen1: #REF!
Name _scen2: #REF!
Name _scen2: #REF!
Name _SCenarios: #REF!
Name _SCenarios: #REF!
Name _Sens1: #REF!
Name _Sens1: #REF!
Name _Sens2: #REF!
Name _Sens2: #REF!
Name _sensRes1: #REF!
Name _sensRes1: #REF!
Name _sensRes2: #REF!
Name _sensRes2: #REF!
Name _sensRes3: #REF!
Name _sensRes3: #REF!
Name _sensRes4: #REF!
Name _sensRes4: #REF!
Name _sensRes5: #REF!
Name _sensRes5: #REF!
Name _sensRes6: #REF!
Name _sensRes6: #REF!
Name _sensRes7: #REF!
Name _sensRes7: #REF!
Name Compco1: {"Page1",#N/A,FALSE,"CompCo";"Page2",#N/A,FALSE,"CompCo"}
Name Compco2: {"Page1",#N/A,FALSE,"CompCo";"Page2",#N/A,FALSE,"CompCo"}
Name DateRange: #REF!
Name DateRange: #REF!
Name DateRangePr: OFFSET(#REF!,5,0,COUNTA(#REF!)-COUNTA(#REF!),1)
Name DateRangePrice: OFFSET(#REF!,5,0,COUNTA(#REF!)-COUNTA(#REF!),1)
Name DateRangePrice1: OFFSET(#REF!,5,0,COUNTA(#REF!)-COUNTA(#REF!),1)
Name DateRangePrice2: OFFSET(#REF!,5,0,COUNTA(#REF!)-COUNTA(#REF!),1)
Name ERT: {"execsum",#N/A,FALSE,"ExecSum";"finstatement",#N/A,FALSE,"Fin_St"}
Name hn.Delete015: #REF!,#REF!,#REF!,#REF!,#REF!
Name kjjkghkhj: {"finana",#N/A,FALSE,"Fin"}
Name lkhkhj: {"sub1",#N/A,FALSE,"Subs";"pac1",#N/A,FALSE,"Packages";"rev1",#N/A,FALSE,"2. Revenues"}
Name Monetary_Unit: #REF!
Name Monetary_Unit: #REF!
Name Months: #REF!
Name Months: #REF!
Name PriceRange: OFFSET(#REF!,5,0,COUNTA(#REF!)-COUNTA(#REF!),1)
Name PriceRange2: OFFSET(#REF!,5,0,COUNTA(#REF!)-COUNTA(#REF!),1)
Name Rng_Dealers_Names: #REF!
Name Rng_Dealers_Names: #REF!
Name Rng_Dlr_Dates: #REF!
Name Rng_Dlr_Dates: #REF!
Name test: {"execsum",#N/A,FALSE,"ExecSum";"finstatement",#N/A,FALSE,"Fin_St"}
Name test21: OFFSET(#REF!,5,0,COUNTA(#REF!)-COUNTA(#REF!),1)
Name Ticker: #REF!
Name Ticker: #REF!
Name Titre: #REF!
Name Titre: #REF!
Name value: OFFSET(#REF!,5,0,COUNTA(#REF!)-COUNTA(#REF!),1)
Name value2: OFFSET(#REF!,5,0,COUNTA(#REF!)-COUNTA(#REF!),1)
Name wrn.amendement.: {#N/A,#N/A,FALSE,"amendement"}
Name wrn.amendement..: {#N/A,#N/A,FALSE,"amendement"}

Sheet Parametres
A1: Compagnie | B1: BMW Sherbrooke
G2: 1-Mémo | M2: Mois | N2: YTD
A3: Mois Courant | B3: Juin | C3: =+VLOOKUP(B3,$K$3:$L$14,2,0) -> 6 | G3: 10-Compte compteur | K3: Janvier | L3: 1 | M3: =+IF($K3=$B$3,"X","") | N3: =+IF(K3=B3,"X",IF(L3<=$C$3,"X","")) -> X
A4: Année | B4: 2026 | K4: Février | L4: 2 | M4: =+IF($K4=$B$3,"X","") | N4: =+IF(K4=B4,"X",IF(L4<=$C$3,"X","")) -> X
K5: Mars | L5: 3 | M5: =+IF($K5=$B$3,"X","") | N5: =+IF(K5=B5,"X",IF(L5<=$C$3,"X","")) -> X
K6: Avril | L6: 4 | M6: =+IF($K6=$B$3,"X","") | N6: =+IF(K6=B6,"X",IF(L6<=$C$3,"X","")) -> X
K7: Mai | L7: 5 | M7: =+IF($K7=$B$3,"X","") | N7: =+IF(K7=B7,"X",IF(L7<=$C$3,"X","")) -> X
K8: Juin | L8: 6 | M8: =+IF($K8=$B$3,"X","") -> X | N8: =+IF(K8=B8,"X",IF(L8<=$C$3,"X","")) -> X
A9: Sélectionner le mois en B3 | K9: Juillet | L9: 7 | M9: =+IF($K9=$B$3,"X","") | N9: =+IF(K9=B9,"X",IF(L9<=$C$3,"X",""))
A10: Coller les balances de vérification respectives en cellule A1 dans les onglets BV_Data_An_Cour et BV_Data_An_Prec | K10: Août | L10: 8 | M10: =+IF($K10=$B$3,"X","") | N10: =+IF(K10=B10,"X",IF(L10<=$C$3,"X",""))
A11: Vérifier s'il y a des #N/A dans les colonnes T à X des onlgets de BV | K11: Septembre | L11: 9 | M11: =+IF($K11=$B$3,"X","") | N11: =+IF(K11=B11,"X",IF(L11<=$C$3,"X",""))
A12: Vérifier les chiffres avec l'état financier et les réalisés an passé pour les résultat net mois et aad | K12: Octobre | L12: 10 | M12: =+IF($K12=$B$3,"X","") | N12: =+IF(K12=B12,"X",IF(L12<=$C$3,"X",""))
K13: Novembre | L13: 11 | M13: =+IF($K13=$B$3,"X","") | N13: =+IF(K13=B13,"X",IF(L13<=$C$3,"X",""))
K14: Décembre | L14: 12 | M14: =+IF($K14=$B$3,"X","") | N14: =+IF(K14=B14,"X",IF(L14<=$C$3,"X",""))

Sheet Bilan
A1: BILAN
A2: =+Parametres!B1 -> BMW Sherbrooke
A3: =CONCATENATE("",,Parametres!B3," ",Parametres!B4) -> Juin 2026
A5: Encaisse | B5: =SUMIFS(BV_Data_An_Cour!$P:$P,BV_Data_An_Cour!$U:$U,$A$1,BV_Data_An_Cour!$V:$V,$A5) -> 1514025.7 | D5: Marge de crédit | E5: =-SUMIFS(BV_Data_An_Cour!$P:$P,BV_Data_An_Cour!$U:$U,$A$1,BV_Data_An_Cour!$V:$V,$D5) -> 0
A6: Total Trésorerie et équivalent de Trésorerie | B6: =SUM(B5) -> 1514025.7
D7: Portion Court Terme de la Dette Long Terme | E7: =-SUMIFS(BV_Data_An_Cour!$P:$P,BV_Data_An_Cour!$U:$U,$A$1,BV_Data_An_Cour!$V:$V,$D7) -> 0
A8: Recevables Contrats en Transit | B8: =SUMIFS(BV_Data_An_Cour!$P:$P,BV_Data_An_Cour!$U:$U,$A$1,BV_Data_An_Cour!$V:$V,$A8) -> 1303189.8
A9: Recevables Véhicules | B9: =SUMIFS(BV_Data_An_Cour!$P:$P,BV_Data_An_Cour!$U:$U,$A$1,BV_Data_An_Cour!$V:$V,$A9) -> 143841.73 | D9: Avances à payer | E9: =-SUMIFS(BV_Data_An_Cour!$P:$P,BV_Data_An_Cour!$U:$U,$A$1,BV_Data_An_Cour!$V:$V,$D9) -> 0
A10: Recevables Manufacturier | B10: =SUMIFS(BV_Data_An_Cour!$P:$P,BV_Data_An_Cour!$U:$U,$A$1,BV_Data_An_Cour!$V:$V,$A10) -> 225476.84 | D10: Comptes à Payer Fournisseurs | E10: =-SUMIFS(BV_Data_An_Cour!$P:$P,BV_Data_An_Cour!$U:$U,$A$1,BV_Data_An_Cour!$V:$V,$D10) -> 178046.18
A11: Recevables Pièces et Service | B11: =SUMIFS(BV_Data_An_Cour!$P:$P,BV_Data_An_Cour!$U:$U,$A$1,BV_Data_An_Cour!$V:$V,$A11) -> 167071.97 | D11: Taxes de Vente à Payer | E11: =-SUMIFS(BV_Data_An_Cour!$P:$P,BV_Data_An_Cour!$U:$U,$A$1,BV_Data_An_Cour!$V:$V,$D11) -> 9549.47
A12: Recevables Garantie Manufacturier | B12: =SUMIFS(BV_Data_An_Cour!$P:$P,BV_Data_An_Cour!$U:$U,$A$1,BV_Data_An_Cour!$V:$V,$A12) -> 81342.3 | D12: Impôts à payer | E12: =-SUMIFS(BV_Data_An_Cour!$P:$P,BV_Data_An_Cour!$U:$U,$A$1,BV_Data_An_Cour!$V:$V,$D12) -> 0
A13: Recevables Carrosserie | B13: =SUMIFS(BV_Data_An_Cour!$P:$P,BV_Data_An_Cour!$U:$U,$A$1,BV_Data_An_Cour!$V:$V,$A13) -> 0 | D13: Dépôts de Client | E13: =-SUMIFS(BV_Data_An_Cour!$P:$P,BV_Data_An_Cour!$U:$U,$A$1,BV_Data_An_Cour!$V:$V,$D13) -> 88092
A14: Recevables Intercos | B14: =SUMIFS(BV_Data_An_Cour!$P:$P,BV_Data_An_Cour!$U:$U,$A$1,BV_Data_An_Cour!$V:$V,$A14) -> 511009.67 | D14: Payables Intercos | E14: =-SUMIFS(BV_Data_An_Cour!$P:$P,BV_Data_An_Cour!$U:$U,$A$1,BV_Data_An_Cour!$V:$V,$D14) -> -7272.58
A15: Recevables Autres | B15: =SUMIFS(BV_Data_An_Cour!$P:$P,BV_Data_An_Cour!$U:$U,$A$1,BV_Data_An_Cour!$V:$V,$A15) -> 189329.77 | D15: Autres Comptes à Payer | E15: =-SUMIFS(BV_Data_An_Cour!$P:$P,BV_Data_An_Cour!$U:$U,$A$1,BV_Data_An_Cour!$V:$V,$D15) -> 21261.4
A16: Total Comptes à Recevoir | B16: =+SUM(B8:B15) -> 2621262.1 | D16: Total Comptes à Payer | E16: =+SUM(E10:E15) -> 289676.47
A18: Inventaire Véhicules Neufs | B18: =SUMIFS(BV_Data_An_Cour!$P:$P,BV_Data_An_Cour!$U:$U,$A$1,BV_Data_An_Cour!$V:$V,$A18) -> 6853697.9 | D18: Effet à Payer Véhicules Neufs | E18: =-SUMIFS(BV_Data_An_Cour!$P:$P,BV_Data_An_Cour!$U:$U,$A$1,BV_Data_An_Cour!$V:$V,$D18) -> 8390410.8
A19: Inventaire Véhicules Usagés | B19: =SUMIFS(BV_Data_An_Cour!$P:$P,BV_Data_An_Cour!$U:$U,$A$1,BV_Data_An_Cour!$V:$V,$A19) -> 2870817.2 | D19: Effet à Payer Véhicules Usagés | E19: =-SUMIFS(BV_Data_An_Cour!$P:$P,BV_Data_An_Cour!$U:$U,$A$1,BV_Data_An_Cour!$V:$V,$D19) -> 2388609.2
A20: Inventaire Pièces, Pneus, Huile | B20: =SUMIFS(BV_Data_An_Cour!$P:$P,BV_Data_An_Cour!$U:$U,$A$1,BV_Data_An_Cour!$V:$V,$A20) -> 459789.78 | D20: Total Effets à Payer | E20: =+SUM(E18:E19) -> 10779020
A21: Total Inventaires | B21: =SUM(B18:B20) -> 10184305
D22: Salaires à Payer | E22: =-SUMIFS(BV_Data_An_Cour!$P:$P,BV_Data_An_Cour!$U:$U,$A$1,BV_Data_An_Cour!$V:$V,$D22) -> 274230.53
A23: Avances à recevoir | B23: =SUMIFS(BV_Data_An_Cour!$P:$P,BV_Data_An_Cour!$U:$U,$A$1,BV_Data_An_Cour!$V:$V,$A23) -> 0 | D23: DAS à Payer | E23: =-SUMIFS(BV_Data_An_Cour!$P:$P,BV_Data_An_Cour!$U:$U,$A$1,BV_Data_An_Cour!$V:$V,$D23) -> 674.57
A24: Travaux en Cours | B24: =SUMIFS(BV_Data_An_Cour!$P:$P,BV_Data_An_Cour!$U:$U,$A$1,BV_Data_An_Cour!$V:$V,$A24) -> 7366.75 | D24: Autres Courus | E24: =-SUMIFS(BV_Data_An_Cour!$P:$P,BV_Data_An_Cour!$U:$U,$A$1,BV_Data_An_Cour!$V:$V,$D24) -> 286667.63
A25: Sous-Traitance | B25: =SUMIFS(BV_Data_An_Cour!$P:$P,BV_Data_An_Cour!$U:$U,$A$1,BV_Data_An_Cour!$V:$V,$A25) -> -15287.65 | D25: [...] | E25: =-SUMIFS(BV_Data_An_Cour!$P:$P,BV_Data_An_Cour!$U:$U,$A$1,BV_Data_An_Cour!$V:$V,$D25) -> 0
A26: Frais Payés d'Avance | B26: =SUMIFS(BV_Data_An_Cour!$P:$P,BV_Data_An_Cour!$U:$U,$A$1,BV_Data_An_Cour!$V:$V,$A26) -> 374795.63 | D26: [...] | E26: =-SUMIFS(BV_Data_An_Cour!$P:$P,BV_Data_An_Cour!$U:$U,$A$1,BV_Data_An_Cour!$V:$V,$D26) -> 0
A27: [...] | B27: =SUMIFS(BV_Data_An_Cour!$P:$P,BV_Data_An_Cour!$U:$U,$A$1,BV_Data_An_Cour!$V:$V,$A27) -> 0 | D27: [...] | E27: =-SUMIFS(BV_Data_An_Cour!$P:$P,BV_Data_An_Cour!$U:$U,$A$1,BV_Data_An_Cour!$V:$V,$D27) -> 0
A28: [...] | B28: =SUMIFS(BV_Data_An_Cour!$P:$P,BV_Data_An_Cour!$U:$U,$A$1,BV_Data_An_Cour!$V:$V,$A28) -> 0 | D28: Total Frais Courus | E28: =SUM(E22:E24) -> 561572.73
A29: [...] | B29: =SUMIFS(BV_Data_An_Cour!$P:$P,BV_Data_An_Cour!$U:$U,$A$1,BV_Data_An_Cour!$V:$V,$A29) -> 0
A30: Total Autres | B30: =SUM(B23:B29) -> 366874.73 | D30: Total Passif Court Terme | E30: =+E5+E7+E16+E20+E28 -> 11630269
A32: Total Actif Court Terme | B32: =+B6+B16+B21+B30 -> 14686467
D33: Impôts Futurs à payer | E33: =-SUMIFS(BV_Data_An_Cour!$P:$P,BV_Data_An_Cour!$U:$U,$A$1,BV_Data_An_Cour!$V:$V,$D33) -> 0
A35: Terrain | B35: =SUMIFS(BV_Data_An_Cour!$P:$P,BV_Data_An_Cour!$U:$U,$A$1,BV_Data_An_Cour!$V:$V,$A35) -> 0 | D35: Avances Long Terme à Payer | E35: =-SUMIFS(BV_Data_An_Cour!$P:$P,BV_Data_An_Cour!$U:$U,$A$1,BV_Data_An_Cour!$V:$V,$D35) -> 10494016
A36: Bâtisse | B36: =SUMIFS(BV_Data_An_Cour!$P:$P,BV_Data_An_Cour!$U:$U,$A$1,BV_Data_An_Cour!$V:$V,$A36) -> 0 | D36: Hypothèque à Payer | E36: =-SUMIFS(BV_Data_An_Cour!$P:$P,BV_Data_An_Cour!$U:$U,$A$1,BV_Data_An_Cour!$V:$V,$D36) -> 0
A37: Améliorations Locatives | B37: =SUMIFS(BV_Data_An_Cour!$P:$P,BV_Data_An_Cour!$U:$U,$A$1,BV_Data_An_Cour!$V:$V,$A37) -> 1841 | D37: Dette à Long Terme | E37: =-SUMIFS(BV_Data_An_Cour!$P:$P,BV_Data_An_Cour!$U:$U,$A$1,BV_Data_An_Cour!$V:$V,$D37) -> 10281476
A38: Améliorations Locatives Permanentes | B38: =SUMIFS(BV_Data_An_Cour!$P:$P,BV_Data_An_Cour!$U:$U,$A$1,BV_Data_An_Cour!$V:$V,$A38) -> 0 | D38: Autres Dettes à Long Terme | E38: =-SUMIFS(BV_Data_An_Cour!$P:$P,BV_Data_An_Cour!$U:$U,$A$1,BV_Data_An_Cour!$V:$V,$D38) -> 0
A39: Équipements Service | B39: =SUMIFS(BV_Data_An_Cour!$P:$P,BV_Data_An_Cour!$U:$U,$A$1,BV_Data_An_Cour!$V:$V,$A39) -> 208761.14 | D39: [...] | E39: =-SUMIFS(BV_Data_An_Cour!$P:$P,BV_Data_An_Cour!$U:$U,$A$1,BV_Data_An_Cour!$V:$V,$D39) -> 0
A40: Mobilier | B40: =SUMIFS(BV_Data_An_Cour!$P:$P,BV_Data_An_Cour!$U:$U,$A$1,BV_Data_An_Cour!$V:$V,$A40) -> 189875.51 | D40: [...] | E40: =-SUMIFS(BV_Data_An_Cour!$P:$P,BV_Data_An_Cour!$U:$U,$A$1,BV_Data_An_Cour!$V:$V,$D40) -> 0
A41: Équipements Informatique | B41: =SUMIFS(BV_Data_An_Cour!$P:$P,BV_Data_An_Cour!$U:$U,$A$1,BV_Data_An_Cour!$V:$V,$A41) -> 27372.98 | D41: [...] | E41: =-SUMIFS(BV_Data_An_Cour!$P:$P,BV_Data_An_Cour!$U:$U,$A$1,BV_Data_An_Cour!$V:$V,$D41) -> 0
A42: Équipements Téléphonique | B42: =SUMIFS(BV_Data_An_Cour!$P:$P,BV_Data_An_Cour!$U:$U,$A$1,BV_Data_An_Cour!$V:$V,$A42) -> 0 | D42: Total Passif long terme | E42: =+SUM(E33:E38) -> 20775492
A43: Enseigne | B43: =SUMIFS(BV_Data_An_Cour!$P:$P,BV_Data_An_Cour!$U:$U,$A$1,BV_Data_An_Cour!$V:$V,$A43) -> 9327.02
A44: Total Immobilisations Nettes | B44: =SUM(B35:B43) -> 437177.65
...

Sheet Inventaire_Neuf
A1: #Contrôle | B1: Année | C1: Marque | D1: Modèle | E1: $ Inventaire | F1: $ Financé | G1: NIV | H1: Jours en stock | L1: $ Inventaire | M1: $ Financé
A2: 23019 | B2: 2023 | C2: BMW | D2: 430 | E2: 65121.87 | F2: -60905.25 | G2: WBA73AP05PCL27730 | H2: 478 | K2: CTRL | L2: =+SUM(E2:E10000) -> 3938633.3 | M2: =+SUM(F2:F10000) -> -3910068
A3: 23020 | B3: 2023 | C3: BMW | D3: 430 | E3: 63963.67 | G3: WBA73AP06PCL26036 | H3: 465 | L3: =+COUNT(E2:E10000) -> 45
A4: 23084 | B4: 2023 | C4: BMW | D4: 530xe | E4: 75509.5 | G4: WBA33AG06PCL42221 | H4: 411
A5: 23218 | B5: 2023 | C5: BMW SAV | D5: X3 | E5: 84833.61 | F5: -88452 | G5: 5UX83DP04P9T17873 | H5: 146
A6: 23221 | B6: 2023 | C6: BMW | D6: SERIE 2 | E6: 66617.36 | F6: -69326.25 | G6: 3MW53CM06P8D70441 | H6: 151
A7: 23228 | B7: 2023 | C7: BMW SAV | D7: X3 | E7: 73335.37 | F7: -69809.25 | G7: 5UX53DP06P9T28635 | H7: 143
A8: 23240 | B8: 2023 | C8: BMW SAV | D8: X1 | E8: 50471.49 | F8: -50473.5 | G8: WBX73EF02P5X85602 | H8: 67
A9: 23241 | B9: 2023 | C9: BMW SAV | D9: X1 | E9: 50262.11 | F9: -52143 | G9: WBX73EF00P5X86053 | H9: 58
A10: 24019 | B10: 2024 | C10: BMW SAV | D10: X5 | E10: 95266.49 | F10: -95303.25 | G10: 5UX23EU05R9T15522 | H10: 158
A11: 24023 | B11: 2024 | C11: BMW SAV | D11: X7 | E11: 126612.36 | F11: -131675.25 | G11: 5UX23EM04R9T23238 | H11: 149
A12: 24024 | B12: 2024 | C12: BMWI | D12: IX40 | E12: 97633.14 | F12: -97203.75 | G12: WB513CF03RCN76497 | H12: 152
A13: 24032 | B13: 2024 | C13: BMW SAV | D13: X6 | E13: 103328.55 | F13: -107651.25 | G13: 5UX33EX02R9T31595 | H13: 144
A14: 24034 | B14: 2024 | C14: BMW | D14: SERIE 4 | E14: 66533.61 | F14: -69237 | G14: WBA73AP07RCN92250 | H14: 144
A15: 24038 | B15: 2024 | C15: BMWI | D15: I7 | E15: 159476.47 | F15: -173664.75 | G15: WBY53EJ01RCN94634 | H15: 142
A16: 24051 | B16: 2024 | C16: BMW | D16: SERIE 3 | E16: 62907.21 | F16: -60149.52 | G16: 3MW89FF00R8D80878 | H16: 117
... A46: 24130 | B46: 2024 | C46: BMW SAV | D46: X3 | E46: 65370 | F46: -68638.5 | G46: 5UX53DP06R9U99484 | H46: 9

Sheet Inventaire_Used
A1: #Contrôle | B1: Année | C1: Marque | D1: Description | E1: Amount | F1: Financé | G1: NIV | H1: Jours en stock | L1: $ Inventaire | M1: $ Financé
A2: P0512 | B2: 2004 | C2: CHEVROLET TRUCK | D2: SILVERADO 2500 | E2: 3856.45 | G2: 1GCGK23U14F218132 | H2: 1482 | K2: CTRL | L2: =+SUM(E2:E9999) -> 1972155.4 | M2: =+SUM(F2:F9999) -> -1357394.6
A3: P2173 | B3: 2022 | C3: BMW | D3: 540i | E3: 75917.21 | F3: -50220 | G3: WBA73BJ07NWX54871 | H3: 490 | L3: =+COUNT(E2:E10000) -> 50
A4: P2259 | B4: 2021 | C4: BMW SAV | D4: X5 | E4: 75668.81 | F4: -55025 | G4: 5UXTA6C07M9G89398 | H4: 306
A5: P2282 | B5: 2019 | C5: BMW | D5: Z4 | E5: 61477.55 | F5: -55037.5 | G5: WBAHF3C57KWW21386 | H5: 235
A6: P2321 | B6: 2021 | C6: JEEP | D6: GLADIATOR 4X4 | E6: 57247.58 | F6: -48210.15 | G6: 1C6HJTAG8ML543623 | H6: 144
A7: P2327 | B7: 2023 | C7: BMW SAV | D7: X1 | E7: 51697.81 | F7: -49599.39 | G7: WBX73EF03P5W40276 | H7: 137
A8: 23231A | B8: 2020 | C8: MINI | D8: COUNTRYMAN | E8: 35295.85 | F8: -20589.76 | G8: WMZYZ9C04L3L18702 | H8: 125
A9: P2334 | B9: 2019 | C9: BMW | D9: 330i | E9: 31287.41 | F9: -23537.41 | G9: WBA5R7C54KFH22955 | H9: 111
A10: 23193A | B10: 2022 | C10: VOLVO | D10: XC60 | E10: 58424.95 | F10: -80500 | G10: LYV062RL8NB979235 | H10: 108
A11: P2335 | B11: 2020 | C11: BMW SAV | D11: X3 | E11: 30904.85 | F11: -21000 | G11: 5UXTY5C03L9D44647 | H11: 103
A12: 24082A | B12: 2023 | C12: MAZDA | D12: MX-5 | E12: 34707.45 | F12: -32060.23 | G12: JM1NDAD7XP0552574 | H12: 73
A13: 23225A | B13: 2023 | C13: BMW | D13: 330i | E13: 54482.17 | F13: -37837.25 | G13: WBA83FF0XPFN75280 | H13: 72
A14: P2342A | B14: 2023 | C14: BMW | D14: 530e | E14: 65103.95 | F14: -45150 | G14: WBA33AG00PCL72878 | H14: 72
A15: P2343 | B15: 2023 | C15: ACURA | D15: Integra | E15: 39059.95 | F15: -35100 | G15: 19UDE4G72PA800656 | H15: 67
... A28: P2356 | B28: 2021 | C28: ACURA | D28: TLX | E28: 39793.95 | F28: -35550 | G28: 19UUB6F51MA801958 | H28: 38
A29: 24098A | B29: 2015 | C29: MINI | D29: 5 DOOR | E29: 8000 | G29: WMWXS5C59FT837198 | H29: 38
A30: 23116B | B30: 2021 | C30: JEEP | D30: Wrangler Unlim | E30: 43899.95 | F30: -30450 | G30: 1C4HJXEN3MW680010 | H30: 37
A31: 24078A | B31: 2023 | C31: VOLKSWAGEN | D31: ID.4 | E31: 47899.95 | F31: -34300 | G31: 1V2JNPE8XPC021183 | H31: 31
A32: 23243A | B32: 2020 | C32: BMW | D32: 2 SERIES | E32: 29024.85 | F32: -19599.51 | G32: WBA73AK0XL7G01503 | H32: 26
A33: P2361 | B33: 2014 | C33: BMW | D33: 320i | E33: 11164.86 | G33: WBA3C3C57EK200069 | H33: 22
A34: P2362 | B34: 2023 | C34: BMW | D34: M240i xDrive | E34: 53250.2 | F34: -52796.25 | G34: 3MW53CM03P8C99750 | H34: 20
A35: P2363 | B35: 2023 | C35: BMW | D35: 230i | E35: 42103.5 | F35: -41658.65 | G35: 3MW33CM08P8C93109 | H35: 18
A36: P2364 | B36: 2017 | C36: BMW SAV | D36: X4 | E36: 27407.01 | F36: -24300 | G36: 5UXXW3C37H0T79741 | H36: 17
A37: 24040A | B37: 2023 | C37: BMW SAV | D37: X4 | E37: 58745 | F37: -45726.94 | G37: 5UX33DT01P9N56202 | H37: 13
A38: P2367 | B38: 2019 | C38: NISSAN | D38: Micra | E38: 11000 | F38: -9900 | G38: 3N1CK3CP5KL236170 | H38: 10
A39: 23244A | B39: 2019 | C39: BMW SAV | D39: X2 | E39: 26995 | F39: -16020.18 | G39: WBXYJ5C54K5N01549 | H39: 10
A40: 24103A | B40: 2021 | C40: BMW SAV | D40: X3 | E40: 42500 | F40: -30072.18 | G40: 5UXTS1C06M9H64396 | H40: 10
A41: P2223A | B41: 2023 | C41: BMW | D41: I4 | E41: 51776.06 | F41: -29211.39 | G41: WBY43AW09PFP45888 | H41: 10
A42: P2366 | B42: 2012 | C42: BMW | D42: M3 | E42: 37500 | G42: WBSKG9C53CE798848 | H42: 10
A43: P2365 | B43: 2021 | C43: DODGE TRUCK | D43: RAM 1500 Class | E43: 32547.15 | F43: -32547.15 | G43: 3C6RR7KG7MG709002 | H43: 9
A44: 23227A | B44: 2017 | C44: HONDA | D44: CIVIC HATCHBAC | E44: 14000 | G44: SHHFK7H26HU304092 | H44: 9
A45: 24097A | B45: 2018 | C45: AUDI | D45: A5 Sportback | E45: 18500 | G45: WAUANCF51JA004190 | H45: 3
A46: 24126A | B46: 2017 | C46: BMW | D46: 2 SERIES | E46: 28000 | G46: WBA2L3C32HV667851 | H46: 3
A47: 24091B | B47: 2013 | C47: VOLKSWAGEN | D47: JETTA | E47: 1500 | G47: 3VW1K7AJ9DM416983 | H47: 2
A48: 24125B | B48: 2017 | C48: BMW | D48: 650i | E48: 37000 | G48: WBA6F7C50HD930698 | H48: 2
A49: 23122A | B49: 2022 | C49: BMW | D49: 2 SERIES | E49: 37500 | G49: WBA13AL03N7K75967 | H49: 2
A50: 24125A | B50: 2021 | C50: BMW SAV | D50: X5 | E50: 60000 | G50: 5UXJU4C08M9E22693 | H50: 2
A51: 24104B | B51: 2019 | C51: BMW SAV | D51: X2 | E51: 31000 | G51: WBXYN1C56K5N23209 | H51: 0

Sheet Réalisé Mois
C1: =Parametres!B1 -> BMW Sherbrooke | K1: Véhicules neufs | S1: =CONCATENATE("Réalisé,"," ",Parametres!B3," ",Parametres!B4) -> Réalisé, Juin 2026
D2: X | E2: O | F2: U | J2: NB | L2: $ | O2: X | P2: O | Q2: U
D3: BUDGET ORIGINAL | J3: RÉALISATION | M3: ÉCART réel / Budget | O3: ANNÉE PRÉCÉDENTE | R3: ECART (réel/ Ann.Préc.)
D4: UNITE | E4: $P/UNITÉ | F4: $PROFITS | J4: UNITE | K4: $P/UNITE | L4: $PROFITS | M4: UNFTÉ | N4: $PROFITS | O4: UNITE | P4: $P/UNITÉ | Q4: $PROFITS | R4: UNITE | S4: $PROFITS
A5: =+B5&C5 -> Véhicules neufsVentes nettes | B5: =+$K$1 -> Véhicules neufs | C5: Ventes nettes | F5: =+INDEX('Budget original'!$A$2:$AO$501,MATCH($A5,'Budget original'!$A$2:$A$501,0),MATCH(F$2,'Budget original'!$A$2:$AO$2,0)) -> 2474272 | L5: =-SUMIFS(BV_Data_An_Cour!$O:$O,BV_Data_An_Cour!$X:$X,"Oui",BV_Data_An_Cour!$U:$U,$B5) -> 2992808.7 | Q5: {=+INDEX('Réel 2025'!$A$2:$AO$500,MATCH($A5,'Réel 2025'!$A$2:$A$500,0),MATCH(Q$2,'Réel 2025'!$A$2:$AO$2,0))} -> 1932819
A6: =+B6&C6 -> Véhicules neufsAutos détail | B6: =+$K$1 -> Véhicules neufs | C6: Autos détail | D6: =+INDEX('Budget original'!$A$2:$AO$501,MATCH($A6,'Budget original'!$A$2:$A$501,0),MATCH(D$2,'Budget original'!$A$2:$AO$2,0)) -> 9 | E6: =IF(D6=0,0,F6/D6) -> 4701.1765 | F6: =+INDEX('Budget original'!$A$2:$AO$501,MATCH($A6,'Budget original'!$A$2:$A$501,0),MATCH(F$2,'Budget original'!$A$2:$AO$2,0)) -> 42310.588 | J6: =-SUMIFS(BV_Data_An_Cour!$O:$O,BV_Data_An_Cour!$U:$U,$B6,BV_Data_An_Cour!$V:$V,$C6,BV_Data_An_Cour!$W:$W,J$2) -> 10 | K6: =IF(J6=0,0,L6/J6) -> 6645.185 | L6: =-SUMIFS(BV_Data_An_Cour!$O:$O,BV_Data_An_Cour!$U:$U,$B6,BV_Data_An_Cour!$V:$V,$C6,BV_Data_An_Cour!$W:$W,L$2) -> 66451.85 | M6: =J6-D6 -> 1 | N6: =L6-F6 -> 24141.262 | O6: =+INDEX('Réel 2025'!$A$2:$AO$500,MATCH($A6,'Réel 2025'!$A$2:$A$500,0),MATCH(O$2,'Réel 2025'!$A$2:$AO$2,0)) -> 9 | P6: =IF(O6=0,0,Q6/O6) -> 5820.6267 | Q6: {=+INDEX('Réel 2025'!$A$2:$AO$500,MATCH($A6,'Réel 2025'!$A$2:$A$500,0),MATCH(Q$2,'Réel 2025'!$A$2:$AO$2,0))} -> 52385.64 | R6: =J6-O6 -> 1 | S6: =L6-Q6 -> 14066.21
A7: =+B7&C7 -> Véhicules neufsCamions détail | B7: =+$K$1 -> Véhicules neufs | C7: Camions détail | D7: =+INDEX('Budget original'!$A$2:$AO$501,MATCH($A7,'Budget original'!$A$2:$A$501,0),MATCH(D$2,'Budget original'!$A$2:$AO$2,0)) -> 14 | E7: =IF(D7=0,0,F7/D7) -> 3928.5 | F7: =+INDEX('Budget original'!$A$2:$AO$501,MATCH($A7,'Budget original'!$A$2:$A$501,0),MATCH(F$2,'Budget original'!$A$2:$AO$2,0)) -> 54999 | J7: =-SUMIFS(BV_Data_An_Cour!$O:$O,BV_Data_An_Cour!$U:$U,$B7,BV_Data_An_Cour!$V:$V,$C7,BV_Data_An_Cour!$W:$W,J$2) -> 12 | K7: =IF(J7=0,0,L7/J7) -> 4707.7525 | L7: =-SUMIFS(BV_Data_An_Cour!$O:$O,BV_Data_An_Cour!$U:$U,$B7,BV_Data_An_Cour!$V:$V,$C7,BV_Data_An_Cour!$W:$W,L$2) -> 56493.03 | M7: =J7-D7 -> -2 | N7: =L7-F7 -> 1494.03 | O7: {=+INDEX('Réel 2025'!$A$2:$AO$500,MATCH($A7,'Réel 2025'!$A$2:$A$500,0),MATCH(O$2,'Réel 2025'!$A$2:$AO$2,0))} -> 7 | P7: =IF(O7=0,0,Q7/O7) -> 3544.4671 | Q7: {=+INDEX('Réel 2025'!$A$2:$AO$500,MATCH($A7,'Réel 2025'!$A$2:$A$500,0),MATCH(Q$2,'Réel 2025'!$A$2:$AO$2,0))} -> 24811.27 | R7: =J7-O7 -> 5 | S7: =L7-Q7 -> 31681.76
A8: =+B8&C8 -> Véhicules neufsSprinter | B8: =+$K$1 -> Véhicules neufs | C8: Sprinter | D8: =+INDEX('Budget original'!$A$2:$AO$501,MATCH($A8,'Budget original'!$A$2:$A$501,0),MATCH(D$2,'Budget original'!$A$2:$AO$2,0)) -> 0 | E8: =IF(D8=0,0,F8/D8) -> 0 | F8: =+INDEX('Budget original'!$A$2:$AO$501,MATCH($A8,'Budget original'!$A$2:$A$501,0),MATCH(F$2,'Budget original'!$A$2:$AO$2,0)) -> 0 | J8: =-SUMIFS(BV_Data_An_Cour!$O:$O,BV_Data_An_Cour!$U:$U,$B8,BV_Data_An_Cour!$V:$V,$C8,BV_Data_An_Cour!$W:$W,J$2) -> 0 | K8: =IF(J8=0,0,L8/J8) -> 0 | L8: =-SUMIFS(BV_Data_An_Cour!$O:$O,BV_Data_An_Cour!$U:$U,$B8,BV_Data_An_Cour!$V:$V,$C8,BV_Data_An_Cour!$W:$W,L$2) -> 0 | M8: =J8-D8 -> 0 | N8: =L8-F8 -> 0 | O8: {=+INDEX('Réel 2025'!$A$2:$AO$500,MATCH($A8,'Réel 2025'!$A$2:$A$500,0),MATCH(O$2,'Réel 2025'!$A$2:$AO$2,0))} -> 0 | P8: =IF(O8=0,0,Q8/O8) -> 0 | Q8: {=+INDEX('Réel 2025'!$A$2:$AO$500,MATCH($A8,'Réel 2025'!$A$2:$A$500,0),MATCH(Q$2,'Réel 2025'!$A$2:$AO$2,0))} -> 0 | R8: =J8-O8 -> 0 | S8: =L8-Q8 -> 0
A9: =+B9&C9 -> Véhicules neufsMoto détail | B9: =+$K$1 -> Véhicules neufs | C9: Moto détail | D9: =+INDEX('Budget original'!$A$2:$AO$501,MATCH($A9,'Budget original'!$A$2:$A$501,0),MATCH(D$2,'Budget original'!$A$2:$AO$2,0)) -> 0 | E9: =IF(D9=0,0,F9/D9) -> 0 | F9: =+INDEX('Budget original'!$A$2:$AO$501,MATCH($A9,'Budget original'!$A$2:$A$501,0),MATCH(F$2,'Budget original'!$A$2:$AO$2,0)) -> 0 | J9: =-SUMIFS(BV_Data_An_Cour!$O:$O,BV_Data_An_Cour!$U:$U,$B9,BV_Data_An_Cour!$V:$V,$C9,BV_Data_An_Cour!$W:$W,J$2) -> 0 | K9: =IF(J9=0,0,L9/J9) -> 0 | L9: =-SUMIFS(BV_Data_An_Cour!$O:$O,BV_Data_An_Cour!$U:$U,$B9,BV_Data_An_Cour!$V:$V,$C9,BV_Data_An_Cour!$W:$W,L$2) -> 0 | M9: =J9-D9 -> 0 | N9: =L9-F9 -> 0 | O9: {=+INDEX('Réel 2025'!$A$2:$AO$500,MATCH($A9,'Réel 2025'!$A$2:$A$500,0),MATCH(O$2,'Réel 2025'!$A$2:$AO$2,0))} -> 0 | P9: =IF(O9=0,0,Q9/O9) -> 0 | Q9: {=+INDEX('Réel 2025'!$A$2:$AO$500,MATCH($A9,'Réel 2025'!$A$2:$A$500,0),MATCH(Q$2,'Réel 2025'!$A$2:$AO$2,0))} -> 0 | R9: =J9-O9 -> 0 | S9: =L9-Q9 -> 0
A10: =+B10&C10 -> Véhicules neufs[...] | B10: =+$K$1 -> Véhicules neufs | C10: [...] | D10: =+INDEX('Budget original'!$A$2:$AO$501,MATCH($A10,'Budget original'!$A$2:$A$501,0),MATCH(D$2,'Budget original'!$A$2:$AO$2,0)) -> 0 | E10: =IF(D10=0,0,F10/D10) -> 0 | F10: =+INDEX('Budget original'!$A$2:$AO$501,MATCH($A10,'Budget original'!$A$2:$A$501,0),MATCH(F$2,'Budget original'!$A$2:$AO$2,0)) -> 0 | J10: =-SUMIFS(BV_Data_An_Cour!$O:$O,BV_Data_An_Cour!$U:$U,$B10,BV_Data_An_Cour!$V:$V,$C10,BV_Data_An_Cour!$W:$W,J$2) -> 0 | K10: =IF(J10=0,0,L10/J10) -> 0 | L10: =-SUMIFS(BV_Data_An_Cour!$O:$O,BV_Data_An_Cour!$U:$U,$B10,BV_Data_An_Cour!$V:$V,$C10,BV_Data_An_Cour!$W:$W,L$2) -> 0 | M10: =J10-D10 -> 0 | N10: =L10-F10 -> 0 | O10: {=+INDEX('Réel 2025'!$A$2:$AO$500,MATCH($A10,'Réel 2025'!$A$2:$A$500,0),MATCH(O$2,'Réel 2025'!$A$2:$AO$2,0))} -> 0 | P10: =IF(O10=0,0,Q10/O10) -> 0 | Q10: {=+INDEX('Réel 2025'!$A$2:$AO$500,MATCH($A10,'Réel 2025'!$A$2:$A$500,0),MATCH(Q$2,'Réel 2025'!$A$2:$AO$2,0))} -> 0 | R10: =J10-O10 -> 0 | S10: =L10-Q10 -> 0
A11: =+B11&C11 -> Véhicules neufs[...] | B11: =+$K$1 -> Véhicules neufs | C11: [...] | D11: =+INDEX('Budget original'!$A$2:$AO$501,MATCH($A11,'Budget original'!$A$2:$A$501,0),MATCH(D$2,'Budget original'!$A$2:$AO$2,0)) -> 0 | E11: =IF(D11=0,0,F11/D11) -> 0 | F11: =+INDEX('Budget original'!$A$2:$AO$501,MATCH($A11,'Budget original'!$A$2:$A$501,0),MATCH(F$2,'Budget original'!$A$2:$AO$2,0)) -> 0 | J11: =-SUMIFS(BV_Data_An_Cour!$O:$O,BV_Data_An_Cour!$U:$U,$B11,BV_Data_An_Cour!$V:$V,$C11,BV_Data_An_Cour!$W:$W,J$2) -> 0 | K11: =IF(J11=0,0,L11/J11) -> 0 | L11: =-SUMIFS(BV_Data_An_Cour!$O:$O,BV_Data_An_Cour!$U:$U,$B11,BV_Data_An_Cour!$V:$V,$C11,BV_Data_An_Cour!$W:$W,L$2) -> 0 | M11: =J11-D11 -> 0 | N11: =L11-F11 -> 0 | O11: {=+INDEX('Réel 2025'!$A$2:$AO$500,MATCH($A11,'Réel 2025'!$A$2:$A$500,0),MATCH(O$2,'Réel 2025'!$A$2:$AO$2,0))} -> 0 | P11: =IF(O11=0,0,Q11/O11) -> 0 | Q11: {=+INDEX('Réel 2025'!$A$2:$AO$500,MATCH($A11,'Réel 2025'!$A$2:$A$500,0),MATCH(Q$2,'Réel 2025'!$A$2:$AO$2,0))} -> 0 | R11: =J11-O11 -> 0 | S11: =L11-Q11 -> 0
A12: =+B12&C12 -> Véhicules neufs[...] | B12: =+$K$1 -> Véhicules neufs | C12: [...] | D12: =+INDEX('Budget original'!$A$2:$AO$501,MATCH($A12,'Budget original'!$A$2:$A$501,0),MATCH(D$2,'Budget original'!$A$2:$AO$2,0)) -> 0 | E12: =IF(D12=0,0,F12/D12) -> 0 | F12: =+INDEX('Budget original'!$A$2:$AO$501,MATCH($A12,'Budget original'!$A$2:$A$501,0),MATCH(F$2,'Budget original'!$A$2:$AO$2,0)) -> 0 | J12: =-SUMIFS(BV_Data_An_Cour!$O:$O,BV_Data_An_Cour!$U:$U,$B12,BV_Data_An_Cour!$V:$V,$C12,BV_Data_An_Cour!$W:$W,J$2) -> 0 | K12: =IF(J12=0,0,L12/J12) -> 0 | L12: =-SUMIFS(BV_Data_An_Cour!$O:$O,BV_Data_An_Cour!$U:$U,$B12,BV_Data_An_Cour!$V:$V,$C12,BV_Data_An_Cour!$W:$W,L$2) -> 0 | M12: =J12-D12 -> 0 | N12: =L12-F12 -> 0 | O12: {=+INDEX('Réel 2025'!$A$2:$AO$500,MATCH($A12,'Réel 2025'!$A$2:$A$500,0),MATCH(O$2,'Réel 2025'!$A$2:$AO$2,0))} -> 0 | P12: =IF(O12=0,0,Q12/O12) -> 0 | Q12: {=+INDEX('Réel 2025'!$A$2:$AO$500,MATCH($A12,'Réel 2025'!$A$2:$A$500,0),MATCH(Q$2,'Réel 2025'!$A$2:$AO$2,0))} -> 0 | R12: =J12-O12 -> 0 | S12: =L12-Q12 -> 0
A13: =+B13&C13 -> Véhicules neufsTotal Neufs | B13: =+$K$1 -> Véhicules neufs | C13: Total Neufs | D13: =+SUM(D6:D12) -> 23 | E13: =IF(D13<=0,0,F13/D13) -> 4230.8517 | F13: =+SUM(F6:F12) -> 97309.588 | J13: =+SUM(J6:J12) -> 22 | K13: =IF(J13<=0,0,L13/J13) -> 5588.4036 | L13: =+SUM(L6:L12) -> 122944.88 | M13: =+SUM(M6:M12) -> -1 | N13: =+SUM(N6:N12) -> 25635.292 | O13: =+SUM(O6:O12) -> 16 | P13: =IF(O13<=0,0,Q13/O13) -> 4824.8069 | Q13: =+SUM(Q6:Q12) -> 77196.91 | R13: =+SUM(R6:R12) -> 6 | S13: =+SUM(S6:S12) -> 45747.97
A14: =+B14&C14 -> Véhicules neufs | B14: =+$K$1 -> Véhicules neufs | M14: =IF(D13=0,0,M13/D13) -> -0.043478261 | N14: =IF(F13=0,0,N13/F13) -> 0.26344055 | R14: =R13/O13 -> 0.375 | S14: =IF(Q13=0,0,(S13/Q13)) -> 0.592614
A15: =+B15&C15 -> Véhicules neufsEx-Démos et courtoisies | B15: =+$K$1 -> Véhicules neufs | C15: Ex-Démos et courtoisies | D15: =+INDEX('Budget original'!$A$2:$AO$501,MATCH($A15,'Budget original'!$A$2:$A$501,0),MATCH(D$2,'Budget original'!$A$2:$AO$2,0)) -> 3 | E15: =IF(D15=0,0,F15/D15) -> 1200 | F15: =+INDEX('Budget original'!$A$2:$AO$501,MATCH($A15,'Budget original'!$A$2:$A$501,0),MATCH(F$2,'Budget original'!$A$2:$AO$2,0)) -> 3600 | J15: =-SUMIFS(BV_Data_An_Cour!$O:$O,BV_Data_An_Cour!$U:$U,$B15,BV_Data_An_Cour!$V:$V,$C15,BV_Data_An_Cour!$W:$W,J$2) -> 2 | K15: =IF(J15=0,0,L15/J15) -> 39.025 | L15: =-SUMIFS(BV_Data_An_Cour!$O:$O,BV_Data_An_Cour!$U:$U,$B15,BV_Data_An_Cour!$V:$V,$C15,BV_Data_An_Cour!$W:$W,L$2) -> 78.05 | M15: =J15-D15 -> -1 | N15: =L15-F15 -> -3521.95 | O15: {=+INDEX('Réel 2025'!$A$2:$AO$500,MATCH($A15,'Réel 2025'!$A$2:$A$500,0),MATCH(O$2,'Réel 2025'!$A$2:$AO$2,0))} -> 4 | P15: =IF(O15=0,0,Q15/O15) -> 2445.1975 | Q15: {=+INDEX('Réel 2025'!$A$2:$AO$500,MATCH($A15,'Réel 2025'!$A$2:$A$500,0),MATCH(Q$2,'Réel 2025'!$A$2:$AO$2,0))} -> 9780.79 | R15: =J15-O15 -> -2 | S15: =L15-Q15 -> -9702.74
A16: =+B16&C16 -> Véhicules neufs | B16: =+$K$1 -> Véhicules neufs
A17: =+B17&C17 -> Véhicules neufsFlottes | B17: =+$K$1 -> Véhicules neufs | C17: Flottes | D17: =+INDEX('Budget original'!$A$2:$AO$501,MATCH($A17,'Budget original'!$A$2:$A$501,0),MATCH(D$2,'Budget original'!$A$2:$AO$2,0)) -> 2 | E17: =IF(D17=0,0,F17/D17) -> 750 | F17: =+INDEX('Budget original'!$A$2:$AO$501,MATCH($A17,'Budget original'!$A$2:$A$501,0),MATCH(F$2,'Budget original'!$A$2:$AO$2,0)) -> 1500 | J17: =-SUMIFS(BV_Data_An_Cour!$O:$O,BV_Data_An_Cour!$U:$U,$B17,BV_Data_An_Cour!$V:$V,$C17,BV_Data_An_Cour!$W:$W,J$2) -> 6 | K17: =IF(J17=0,0,L17/J17) -> 0 | L17: =-SUMIFS(BV_Data_An_Cour!$O:$O,BV_Data_An_Cour!$U:$U,$B17,BV_Data_An_Cour!$V:$V,$C17,BV_Data_An_Cour!$W:$W,L$2) -> 0 | M17: =J17-D17 -> 4 | N17: =L17-F17 -> -1500 | O17: {=+INDEX('Réel 2025'!$A$2:$AO$500,MATCH($A17,'Réel 2025'!$A$2:$A$500,0),MATCH(O$2,'Réel 2025'!$A$2:$AO$2,0))} -> 0 | P17: =IF(O17=0,0,Q17/O17) -> 0 | Q17: {=+INDEX('Réel 2025'!$A$2:$AO$500,MATCH($A17,'Réel 2025'!$A$2:$A$500,0),MATCH(Q$2,'Réel 2025'!$A$2:$AO$2,0))} -> 0 | R17: =J17-O17 -> 6 | S17: =L17-Q17 -> 0
A18: =+B18&C18 -> Véhicules neufs | B18: =+$K$1 -> Véhicules neufs
B19: =+$K$1 -> Véhicules neufs
A20: =+B20&C20 -> Véhicules neufs | B20: =+$K$1 -> Véhicules neufs
A21: =+B21&C21 -> Véhicules neufsRev. Finances | B21: =+$K$1 -> Véhicules neufs | C21: Rev. Finances | E21: =IF(D13=0,0,F21/(D13+D15)) -> 7 | F21: =+INDEX('Budget original'!$A$2:$AO$501,MATCH($A21,'Budget original'!$A$2:$A$501,0),MATCH(F$2,'Budget original'!$A$2:$AO$2,0)) -> 182 | K21: =IF(J13=0,0,L21/(J13+J15)) -> 0 | L21: =-SUMIFS(BV_Data_An_Cour!$O:$O,BV_Data_An_Cour!$U:$U,$B21,BV_Data_An_Cour!$V:$V,$C21,BV_Data_An_Cour!$W:$W,L$2) -> 0 | N21: =L21-F21 -> -182 | P21: =IF(O13=0,0,Q21/(O13+O15)) -> 0 | Q21: {=+INDEX('Réel 2025'!$A$2:$AO$500,MATCH($A21,'Réel 2025'!$A$2:$A$500,0),MATCH(Q$2,'Réel 2025'!$A$2:$AO$2,0))} -> 0 | R21: =O21-K21 -> 0 | S21: =L21-Q21 -> 0
A22: =+B22&C22 -> Véhicules neufsRev. Protections | B22: =+$K$1 -> Véhicules neufs | C22: Rev. Protections | E22: =IF(D13=0,0,F22/(D13+D15)) -> 1150 | F22: =+INDEX('Budget original'!$A$2:$AO$501,MATCH($A22,'Budget original'!$A$2:$A$501,0),MATCH(F$2,'Budget original'!$A$2:$AO$2,0)) -> 29900 | K22: =IF(J13=0,0,L22/(J13+J15)) -> 489.09583 | L22: =-SUMIFS(BV_Data_An_Cour!$O:$O,BV_Data_An_Cour!$U:$U,$B22,BV_Data_An_Cour!$V:$V,$C22,BV_Data_An_Cour!$W:$W,L$2) -> 11738.3 | N22: =L22-F22 -> -18161.7 | P22: =IF(O13=0,0,Q22/(O13+O15)) -> 1336.1695 | Q22: {=+INDEX('Réel 2025'!$A$2:$AO$500,MATCH($A22,'Réel 2025'!$A$2:$A$500,0),MATCH(Q$2,'Réel 2025'!$A$2:$AO$2,0))} -> 26723.39 | R22: =O22-K22 -> -489.09583 | S22: =L22-Q22 -> -14985.09
A23: =+B23&C23 -> Véhicules neufsRev. Autres | B23: =+$K$1 -> Véhicules neufs | C23: Rev. Autres | E23: =IF(D13=0,0,F23/(D13+D15)) -> 443 | F23: =+INDEX('Budget original'!$A$2:$AO$501,MATCH($A23,'Budget original'!$A$2:$A$501,0),MATCH(F$2,'Budget original'!$A$2:$AO$2,0)) -> 11518 | K23: =IF(J13=0,0,L23/(J13+J15)) -> 445.25708 | L23: =-SUMIFS(BV_Data_An_Cour!$O:$O,BV_Data_An_Cour!$U:$U,$B23,BV_Data_An_Cour!$V:$V,$C23,BV_Data_An_Cour!$W:$W,L$2) -> 10686.17 | N23: =L23-F23 -> -831.83 | P23: =IF(O13=0,0,Q23/(O13+O15)) -> 902.6705 | Q23: {=+INDEX('Réel 2025'!$A$2:$AO$500,MATCH($A23,'Réel 2025'!$A$2:$A$500,0),MATCH(Q$2,'Réel 2025'!$A$2:$AO$2,0))} -> 18053.41 | R23: =O23-K23 -> -445.25708 | S23: =L23-Q23 -> -7367.24
A24: =+B24&C24 -> Véhicules neufsTotal F&I | B24: =+$K$1 -> Véhicules neufs | C24: Total F&I | D24: =+D15+D13 -> 26 | E24: =IF(D24<=0,0,F24/D24) -> 1600 | F24: =F21+F22+F23 -> 41600 | J24: =+J15+J13 -> 24 | K24: =IF(J24<=0,0,L24/J24) -> 934.35292 | L24: =L21+L22+L23 -> 22424.47 | M24: =J24-D24 -> -2 | N24: =L24-F24 -> -19175.53 | O24: =+O15+O13 -> 20 | P24: =IF(O24<=0,0,Q24/O24) -> 2238.84 | Q24: =Q21+Q22+Q23 -> 44776.8 | S24: =L24-Q24 -> -22352.33
A25: =+B25&C25 -> Véhicules neufs | B25: =+$K$1 -> Véhicules neufs | N25: =IF(N24=0,0,N24/F24) -> -0.46095024 | S25: =IF(Q24=0,0,(S24/Q24)) -> -0.49919445
A26: =+B26&C26 -> Véhicules neufs | B26: =+$K$1 -> Véhicules neufs
A27: =+B27&C27 -> Véhicules neufsTotal Dépt. Neufs | B27: =+$K$1 -> Véhicules neufs | C27: Total Dépt. Neufs | D27: =+D13+D15+D17 -> 28 | E27: =IF(D27<=0,0,F27/D27) -> 5143.1996 | F27: =F13+F17+F24+F15 -> 144009.59 | J27: =+J13+J15+J17 -> 30 | K27: =IF(J27<=0,0,L27/J27) -> 4848.2467 | L27: =L13+L17+L24+L15 -> 145447.4 | M27: =J27-D27 -> 2 | N27: =L27-F27 -> 1437.8118 | O27: =+O13+O15+O17 -> 20 | P27: =IF(O27<=0,0,Q27/O27) -> 6587.725 | Q27: =Q13+Q17+Q24+Q15 -> 131754.5 | R27: =J27-O27 -> 10 | S27: =L27-Q27 -> 13692.9
A28: =+B28&C28 -> Véhicules neufs | B28: =+$K$1 -> Véhicules neufs | M28: =M27/D27 -> 0.071428571 | N28: =N27/F27 -> 0.0099841391 | R28: =R27/O27 -> 0.5 | S28: =IF(Q27=0,0,S27/Q27) -> 0.10392738
A29: =+B29&C29 -> Véhicules neufs | B29: =+$K$1 -> Véhicules neufs
A30: =+B30&C30 -> Véhicules neufsDEPENSES | B30: =+$K$1 -> Véhicules neufs | C30: DEPENSES
A31: =+B31&C31 -> Véhicules neufsComm. vendeurs | B31: =+$K$1 -> Véhicules neufs | C31: Comm. vendeurs | D31: =F31/(F13+F15) -> 0.28393389 | E31: =F31/D$24 -> 1101.9866 | F31: =+INDEX('Budget original'!$A$2:$AO$501,MATCH($A31,'Budget original'!$A$2:$A$501,0),MATCH(F$2,'Budget original'!$A$2:$AO$2,0)) -> 28651.652 | J31: =L31/(L13+L15) -> 0.28455614 | K31: =IF(L31=0,0,L31/J$24) -> 1458.6221 | L31: =SUMIFS(BV_Data_An_Cour!$O:$O,BV_Data_An_Cour!$U:$U,$B31,BV_Data_An_Cour!$V:$V,$C31,BV_Data_An_Cour!$W:$W,L$2) -> 35006.93 | N31: =L31-F31 -> 6355.2782 | O31: =Q31/(Q13+Q15+Q17) -> 0.25746726 | P31: =Q31/O$24 -> 1119.6955 | Q31: {=+INDEX('Réel 2025'!$A$2:$AO$500,MATCH($A31,'Réel 2025'!$A$2:$A$500,0),MATCH(Q$2,'Réel 2025'!$A$2:$AO$2,0))} -> 22393.91 | S31: =L31-Q31 -> 12613.02
A32: =+B32&C32 -> Véhicules neufsComm. F&I | B32: =+$K$1 -> Véhicules neufs | C32: Comm. F&I | D32: =F32/F24 -> 0.305 | E32: =F32/D$24 -> 488 | F32: =+INDEX('Budget original'!$A$2:$AO$501,MATCH($A32,'Budget original'!$A$2:$A$501,0),MATCH(F$2,'Budget original'!$A$2:$AO$2,0)) -> 12688 | J32: =L32/L24 -> 0.22188395 | K32: =IF(L32=0,0,L32/J$24) -> 207.31792 | L32: =SUMIFS(BV_Data_An_Cour!$O:$O,BV_Data_An_Cour!$U:$U,$B32,BV_Data_An_Cour!$V:$V,$C32,BV_Data_An_Cour!$W:$W,L$2) -> 4975.63 | N32: =L32-F32 -> -7712.37 | O32: =Q32/Q24 -> 0.34309151 | P32: =Q32/O$24 -> 768.127 | Q32: {=+INDEX('Réel 2025'!$A$2:$AO$500,MATCH($A32,'Réel 2025'!$A$2:$A$500,0),MATCH(Q$2,'Réel 2025'!$A$2:$AO$2,0))} -> 15362.54 | S32: =L32-Q32 -> -10386.91
A33: =+B33&C33 -> Véhicules neufsFrais de livraison | B33: =+$K$1 -> Véhicules neufs | C33: Frais de livraison | E33: =F33/D$24 -> 120 | F33: =+INDEX('Budget original'!$A$2:$AO$501,MATCH($A33,'Budget original'!$A$2:$A$501,0),MATCH(F$2,'Budget original'!$A$2:$AO$2,0)) -> 3120 | K33: =IF(L33=0,0,L33/J$24) -> 276.80167 | L33: =SUMIFS(BV_Data_An_Cour!$O:$O,BV_Data_An_Cour!$U:$U,$B33,BV_Data_An_Cour!$V:$V,$C33,BV_Data_An_Cour!$W:$W,L$2) -> 6643.24 | N33: =L33-F33 -> 3523.24 | P33: =Q33/O$24 -> 207.3525 | Q33: {=+INDEX('Réel 2025'!$A$2:$AO$500,MATCH($A33,'Réel 2025'!$A$2:$A$500,0),MATCH(Q$2,'Réel 2025'!$A$2:$AO$2,0))} -> 4147.05 | S33: =L33-Q33 -> 2496.19 | V33: Essences + transport
A34: =+B34&C34 -> Véhicules neufsService gratuit 1 | B34: =+$K$1 -> Véhicules neufs | C34: Service gratuit 1 | E34: =F34/D$24 -> 35 | F34: =+INDEX('Budget original'!$A$2:$AO$501,MATCH($A34,'Budget original'!$A$2:$A$501,0),MATCH(F$2,'Budget original'!$A$2:$AO$2,0)) -> 910 | K34: =IF(L34=0,0,L34/J$24) -> 95.290833 | L34: =SUMIFS(BV_Data_An_Cour!$O:$O,BV_Data_An_Cour!$U:$U,$B34,BV_Data_An_Cour!$V:$V,$C34,BV_Data_An_Cour!$W:$W,L$2) -> 2286.98 | N34: =L34-F34 -> 1376.98 | P34: =Q34/O$24 -> 0 | Q34: {=+INDEX('Réel 2025'!$A$2:$AO$500,MATCH($A34,'Réel 2025'!$A$2:$A$500,0),MATCH(Q$2,'Réel 2025'!$A$2:$AO$2,0))} -> 0 | S34: =L34-Q34 -> 2286.98 | V34: 1.4K Freins ancien démo Yvon vendu janv 2026
A35: =+B35&C35 -> Véhicules neufsEntretien stock | B35: =+$K$1 -> Véhicules neufs | C35: Entretien stock | E35: =F35/D$24 -> 98.192308 | F35: =+INDEX('Budget original'!$A$2:$AO$501,MATCH($A35,'Budget original'!$A$2:$A$501,0),MATCH(F$2,'Budget original'!$A$2:$AO$2,0)) -> 2553 | K35: =IF(L35=0,0,L35/J$24) -> 210.72917 | L35: =SUMIFS(BV_Data_An_Cour!$O:$O,BV_Data_An_Cour!$U:$U,$B35,BV_Data_An_Cour!$V:$V,$C35,BV_Data_An_Cour!$W:$W,L$2) -> 5057.5 | N35: =L35-F35 -> 2504.5 | P35: =Q35/O$24 -> 103.6725 | Q35: {=+INDEX('Réel 2025'!$A$2:$AO$500,MATCH($A35,'Réel 2025'!$A$2:$A$500,0),MATCH(Q$2,'Réel 2025'!$A$2:$AO$2,0))} -> 2073.45 | S35: =L35-Q35 -> 2984.05 | V35: 2k Lavavage ligne essaie
A36: =+B36&C36 -> Véhicules neufsPublicité 1 | B36: =+$K$1 -> Véhicules neufs | C36: Publicité 1 | E36: =F36/D$24 -> 234.88788 | F36: =+INDEX('Budget original'!$A$2:$AO$501,MATCH($A36,'Budget original'!$A$2:$A$501,0),MATCH(F$2,'Budget original'!$A$2:$AO$2,0)) -> 6107.0848 | K36: =IF(L36=0,0,L36/J$24) -> 230.78417 | L36: =SUMIFS(BV_Data_An_Cour!$O:$O,BV_Data_An_Cour!$U:$U,$B36,BV_Data_An_Cour!$V:$V,$C36,BV_Data_An_Cour!$W:$W,L$2) -> 5538.82 | N36: =L36-F36 -> -568.26485 | P36: =Q36/O$24 -> 508.9305 | Q36: {=+INDEX('Réel 2025'!$A$2:$AO$500,MATCH($A36,'Réel 2025'!$A$2:$A$500,0),MATCH(Q$2,'Réel 2025'!$A$2:$AO$2,0))} -> 10178.61 | S36: =L36-Q36 -> -4639.79
A37: =+B37&C37 -> Véhicules neufsIntérêt de gros | B37: =+$K$1 -> Véhicules neufs | C37: Intérêt de gros | E37: =F37/D$24 -> 809.52174 | F37: =+INDEX('Budget original'!$A$2:$AO$501,MATCH($A37,'Budget original'!$A$2:$A$501,0),MATCH(F$2,'Budget original'!$A$2:$AO$2,0)) -> 21047.565 | K37: =IF(L37=0,0,L37/J$24) -> 881.08 | L37: =SUMIFS(BV_Data_An_Cour!$O:$O,BV_Data_An_Cour!$U:$U,$B37,BV_Data_An_Cour!$V:$V,$C37,BV_Data_An_Cour!$W:$W,L$2) -> 21145.92 | N37: =L37-F37 -> 98.354754 | P37: =Q37/O$24 -> 1163.8995 | Q37: {=+INDEX('Réel 2025'!$A$2:$AO$500,MATCH($A37,'Réel 2025'!$A$2:$A$500,0),MATCH(Q$2,'Réel 2025'!$A$2:$AO$2,0))} -> 23277.99 | S37: =L37-Q37 -> -2132.07 | V37: 21146
A38: =+B38&C38 -> Véhicules neufs[...] | B38: =+$K$1 -> Véhicules neufs | C38: [...] | E38: =F38/D$24 -> 0 | F38: =+INDEX('Budget original'!$A$2:$AO$501,MATCH($A38,'Budget original'!$A$2:$A$501,0),MATCH(F$2,'Budget original'!$A$2:$AO$2,0)) -> 0 | K38: =IF(L38=0,0,L38/J$24) -> 0 | L38: =SUMIFS(BV_Data_An_Cour!$O:$O,BV_Data_An_Cour!$U:$U,$B38,BV_Data_An_Cour!$V:$V,$C38,BV_Data_An_Cour!$W:$W,L$2) -> 0 | N38: =L38-F38 -> 0 | P38: =Q38/O$24 -> 0 | Q38: {=+INDEX('Réel 2025'!$A$2:$AO$500,MATCH($A38,'Réel 2025'!$A$2:$A$500,0),MATCH(Q$2,'Réel 2025'!$A$2:$AO$2,0))} -> 0 | S38: =L38-Q38 -> 0
A39: =+B39&C39 -> Véhicules neufs[...] | B39: =+$K$1 -> Véhicules neufs | C39: [...] | E39: =F39/D$24 -> 0 | F39: =+INDEX('Budget original'!$A$2:$AO$501,MATCH($A39,'Budget original'!$A$2:$A$501,0),MATCH(F$2,'Budget original'!$A$2:$AO$2,0)) -> 0 | K39: =IF(L39=0,0,L39/J$24) -> 0 | L39: =SUMIFS(BV_Data_An_Cour!$O:$O,BV_Data_An_Cour!$U:$U,$B39,BV_Data_An_Cour!$V:$V,$C39,BV_Data_An_Cour!$W:$W,L$2) -> 0 | N39: =L39-F39 -> 0 | P39: =Q39/O$24 -> 0 | Q39: {=+INDEX('Réel 2025'!$A$2:$AO$500,MATCH($A39,'Réel 2025'!$A$2:$A$500,0),MATCH(Q$2,'Réel 2025'!$A$2:$AO$2,0))} -> 0 | S39: =L39-Q39 -> 0
A40: =+B40&C40 -> Véhicules neufs[...] | B40: =+$K$1 -> Véhicules neufs | C40: [...] | E40: =F40/D$24 -> 0 | F40: =+INDEX('Budget original'!$A$2:$AO$501,MATCH($A40,'Budget original'!$A$2:$A$501,0),MATCH(F$2,'Budget original'!$A$2:$AO$2,0)) -> 0 | K40: =IF(L40=0,0,L40/J$24) -> 0 | L40: =SUMIFS(BV_Data_An_Cour!$O:$O,BV_Data_An_Cour!$U:$U,$B40,BV_Data_An_Cour!$V:$V,$C40,BV_Data_An_Cour!$W:$W,L$2) -> 0 | N40: =L40-F40 -> 0 | P40: =Q40/O$24 -> 0 | Q40: {=+INDEX('Réel 2025'!$A$2:$AO$500,MATCH($A40,'Réel 2025'!$A$2:$A$500,0),MATCH(Q$2,'Réel 2025'!$A$2:$AO$2,0))} -> 0 | S40: =L40-Q40 -> 0
...

Sheet Réalisé AAD
C1: =Parametres!B1 -> BMW Sherbrooke | K1: Véhicules neufs | S1: =CONCATENATE("Réalisé,"," ",Parametres!B3," ",Parametres!B4," AAD") -> Réalisé, Juin 2026 AAD
D2: X | E2: O | F2: U | J2: NB | L2: $ | O2: X | P2: O | Q2: U | X2: X | Y2: O | Z2: U | AJ2: X | AK2: O | AL2: U
D3: BUDGET ORIGINAL | J3: RÉALISATION | M3: ÉCART réel / Budget | O3: ANNÉE PRÉCÉDENTE | R3: ECART (réel/ Ann.Préc.)
D4: UNITE | E4: $P/UNITÉ | F4: $PROFITS | J4: UNITE | K4: $P/UNITE | L4: $PROFITS | M4: UNFTÉ | N4: $PROFITS | O4: UNITE | P4: $P/UNITÉ | Q4: $PROFITS | R4: UNITE | S4: $PROFITS
A5: =+B5&C5 -> Véhicules neufsVentes nettes | B5: =+$K$1 -> Véhicules neufs | C5: Ventes nettes | F5: {=+SUMPRODUCT(('Budget original'!$A$8:$A$501=$A5)*('Budget original'!$C$3:$AO$3=F$2),'Budget original'!$C$8:$AO$501)} -> 15771359 | L5: =-SUMIFS(BV_Data_An_Cour!$P:$P,BV_Data_An_Cour!$X:$X,"Oui",BV_Data_An_Cour!$U:$U,$B5) -> 15645004 | Q5: {=+SUMPRODUCT(('Réel 2025'!$A$8:$A$500=$A5)*('Réel 2025'!$C$3:$AO$3=Q$2),'Réel 2025'!$C$8:$AO$500)} -> 13069579
A6: =+B6&C6 -> Véhicules neufsAutos détail | B6: =+$K$1 -> Véhicules neufs | C6: Autos détail | D6: {=+SUMPRODUCT(('Budget original'!$A$8:$A$501=$A6)*('Budget original'!$C$3:$AO$3=D$2),'Budget original'!$C$8:$AO$501)} -> 44 | E6: =IF(D6=0,0,F6/D6) -> 4701.1765 | F6: {=+SUMPRODUCT(('Budget original'!$A$8:$A$501=$A6)*('Budget original'!$C$3:$AO$3=F$2),'Budget original'!$C$8:$AO$501)} -> 206851.76 | J6: =-SUMIFS(BV_Data_An_Cour!$P:$P,BV_Data_An_Cour!$U:$U,$B6,BV_Data_An_Cour!$V:$V,$C6,BV_Data_An_Cour!$W:$W,J$2) -> 44 | K6: =IF(J6=0,0,L6/J6) -> 5508.025 | L6: =-SUMIFS(BV_Data_An_Cour!$P:$P,BV_Data_An_Cour!$U:$U,$B6,BV_Data_An_Cour!$V:$V,$C6,BV_Data_An_Cour!$W:$W,L$2) -> 242353.1 | M6: =J6-D6 -> 0 | N6: =L6-F6 -> 35501.335 | O6: {=+SUMPRODUCT(('Réel 2025'!$A$8:$A$500=$A6)*('Réel 2025'!$C$3:$AO$3=O$2),'Réel 2025'!$C$8:$AO$500)} -> 42 | P6: =IF(O6=0,0,Q6/O6) -> 5248.6988 | Q6: {=+SUMPRODUCT(('Réel 2025'!$A$8:$A$500=$A6)*('Réel 2025'!$C$3:$AO$3=Q$2),'Réel 2025'!$C$8:$AO$500)} -> 220445.35 | R6: =J6-O6 -> 2 | S6: =L6-Q6 -> 21907.75
A7: =+B7&C7 -> Véhicules neufsCamions détail | B7: =+$K$1 -> Véhicules neufs | C7: Camions détail | D7: {=+SUMPRODUCT(('Budget original'!$A$8:$A$501=$A7)*('Budget original'!$C$3:$AO$3=D$2),'Budget original'!$C$8:$AO$501)} -> 104 | E7: =IF(D7=0,0,F7/D7) -> 3928.5 | F7: {=+SUMPRODUCT(('Budget original'!$A$8:$A$501=$A7)*('Budget original'!$C$3:$AO$3=F$2),'Budget original'!$C$8:$AO$501)} -> 408564 | J7: =-SUMIFS(BV_Data_An_Cour!$P:$P,BV_Data_An_Cour!$U:$U,$B7,BV_Data_An_Cour!$V:$V,$C7,BV_Data_An_Cour!$W:$W,J$2) -> 74 | K7: =IF(J7=0,0,L7/J7) -> 3986.0123 | L7: =-SUMIFS(BV_Data_An_Cour!$P:$P,BV_Data_An_Cour!$U:$U,$B7,BV_Data_An_Cour!$V:$V,$C7,BV_Data_An_Cour!$W:$W,L$2) -> 294964.91 | M7: =J7-D7 -> -30 | N7: =L7-F7 -> -113599.09 | O7: {=+SUMPRODUCT(('Réel 2025'!$A$8:$A$500=$A7)*('Réel 2025'!$C$3:$AO$3=O$2),'Réel 2025'!$C$8:$AO$500)} -> 74 | P7: =IF(O7=0,0,Q7/O7) -> 4139.8992 | Q7: {=+SUMPRODUCT(('Réel 2025'!$A$8:$A$500=$A7)*('Réel 2025'!$C$3:$AO$3=Q$2),'Réel 2025'!$C$8:$AO$500)} -> 306352.54 | R7: =J7-O7 -> 0 | S7: =L7-Q7 -> -11387.63
A8: =+B8&C8 -> Véhicules neufsSprinter | B8: =+$K$1 -> Véhicules neufs | C8: Sprinter | D8: {=+SUMPRODUCT(('Budget original'!$A$8:$A$501=$A8)*('Budget original'!$C$3:$AO$3=D$2),'Budget original'!$C$8:$AO$501)} -> 0 | E8: =IF(D8=0,0,F8/D8) -> 0 | F8: {=+SUMPRODUCT(('Budget original'!$A$8:$A$501=$A8)*('Budget original'!$C$3:$AO$3=F$2),'Budget original'!$C$8:$AO$501)} -> 0 | J8: =-SUMIFS(BV_Data_An_Cour!$P:$P,BV_Data_An_Cour!$U:$U,$B8,BV_Data_An_Cour!$V:$V,$C8,BV_Data_An_Cour!$W:$W,J$2) -> 0 | K8: =IF(J8=0,0,L8/J8) -> 0 | L8: =-SUMIFS(BV_Data_An_Cour!$P:$P,BV_Data_An_Cour!$U:$U,$B8,BV_Data_An_Cour!$V:$V,$C8,BV_Data_An_Cour!$W:$W,L$2) -> 0 | M8: =J8-D8 -> 0 | N8: =L8-F8 -> 0 | O8: {=+SUMPRODUCT(('Réel 2025'!$A$8:$A$500=$A8)*('Réel 2025'!$C$3:$AO$3=O$2),'Réel 2025'!$C$8:$AO$500)} -> 0 | P8: =IF(O8=0,0,Q8/O8) -> 0 | Q8: {=+SUMPRODUCT(('Réel 2025'!$A$8:$A$500=$A8)*('Réel 2025'!$C$3:$AO$3=Q$2),'Réel 2025'!$C$8:$AO$500)} -> 0 | R8: =J8-O8 -> 0 | S8: =L8-Q8 -> 0
A9: =+B9&C9 -> Véhicules neufsMoto détail | B9: =+$K$1 -> Véhicules neufs | C9: Moto détail | D9: {=+SUMPRODUCT(('Budget original'!$A$8:$A$501=$A9)*('Budget original'!$C$3:$AO$3=D$2),'Budget original'!$C$8:$AO$501)} -> 0 | E9: =IF(D9=0,0,F9/D9) -> 0 | F9: {=+SUMPRODUCT(('Budget original'!$A$8:$A$501=$A9)*('Budget original'!$C$3:$AO$3=F$2),'Budget original'!$C$8:$AO$501)} -> 0 | J9: =-SUMIFS(BV_Data_An_Cour!$P:$P,BV_Data_An_Cour!$U:$U,$B9,BV_Data_An_Cour!$V:$V,$C9,BV_Data_An_Cour!$W:$W,J$2) -> 0 | K9: =IF(J9=0,0,L9/J9) -> 0 | L9: =-SUMIFS(BV_Data_An_Cour!$P:$P,BV_Data_An_Cour!$U:$U,$B9,BV_Data_An_Cour!$V:$V,$C9,BV_Data_An_Cour!$W:$W,L$2) -> 0 | M9: =J9-D9 -> 0 | N9: =L9-F9 -> 0 | O9: {=+SUMPRODUCT(('Réel 2025'!$A$8:$A$500=$A9)*('Réel 2025'!$C$3:$AO$3=O$2),'Réel 2025'!$C$8:$AO$500)} -> 0 | P9: =IF(O9=0,0,Q9/O9) -> 0 | Q9: {=+SUMPRODUCT(('Réel 2025'!$A$8:$A$500=$A9)*('Réel 2025'!$C$3:$AO$3=Q$2),'Réel 2025'!$C$8:$AO$500)} -> 0 | R9: =J9-O9 -> 0 | S9: =L9-Q9 -> 0
A10: =+B10&C10 -> Véhicules neufs[...] | B10: =+$K$1 -> Véhicules neufs | C10: [...] | D10: {=+SUMPRODUCT(('Budget original'!$A$8:$A$501=$A10)*('Budget original'!$C$3:$AO$3=D$2),'Budget original'!$C$8:$AO$501)} -> 0 | E10: =IF(D10=0,0,F10/D10) -> 0 | F10: {=+SUMPRODUCT(('Budget original'!$A$8:$A$501=$A10)*('Budget original'!$C$3:$AO$3=F$2),'Budget original'!$C$8:$AO$501)} -> 0 | J10: =-SUMIFS(BV_Data_An_Cour!$P:$P,BV_Data_An_Cour!$U:$U,$B10,BV_Data_An_Cour!$V:$V,$C10,BV_Data_An_Cour!$W:$W,J$2) -> 0 | K10: =IF(J10=0,0,L10/J10) -> 0 | L10: =-SUMIFS(BV_Data_An_Cour!$P:$P,BV_Data_An_Cour!$U:$U,$B10,BV_Data_An_Cour!$V:$V,$C10,BV_Data_An_Cour!$W:$W,L$2) -> 0 | M10: =J10-D10 -> 0 | N10: =L10-F10 -> 0 | O10: {=+SUMPRODUCT(('Réel 2025'!$A$8:$A$500=$A10)*('Réel 2025'!$C$3:$AO$3=O$2),'Réel 2025'!$C$8:$AO$500)} -> 0 | P10: =IF(O10=0,0,Q10/O10) -> 0 | Q10: {=+SUMPRODUCT(('Réel 2025'!$A$8:$A$500=$A10)*('Réel 2025'!$C$3:$AO$3=Q$2),'Réel 2025'!$C$8:$AO$500)} -> 0 | R10: =J10-O10 -> 0 | S10: =L10-Q10 -> 0
A11: =+B11&C11 -> Véhicules neufs[...] | B11: =+$K$1 -> Véhicules neufs | C11: [...] | D11: {=+SUMPRODUCT(('Budget original'!$A$8:$A$501=$A11)*('Budget original'!$C$3:$AO$3=D$2),'Budget original'!$C$8:$AO$501)} -> 0 | E11: =IF(D11=0,0,F11/D11) -> 0 | F11: {=+SUMPRODUCT(('Budget original'!$A$8:$A$501=$A11)*('Budget original'!$C$3:$AO$3=F$2),'Budget original'!$C$8:$AO$501)} -> 0 | J11: =-SUMIFS(BV_Data_An_Cour!$P:$P,BV_Data_An_Cour!$U:$U,$B11,BV_Data_An_Cour!$V:$V,$C11,BV_Data_An_Cour!$W:$W,J$2) -> 0 | K11: =IF(J11=0,0,L11/J11) -> 0 | L11: =-SUMIFS(BV_Data_An_Cour!$P:$P,BV_Data_An_Cour!$U:$U,$B11,BV_Data_An_Cour!$V:$V,$C11,BV_Data_An_Cour!$W:$W,L$2) -> 0 | M11: =J11-D11 -> 0 | N11: =L11-F11 -> 0 | O11: {=+SUMPRODUCT(('Réel 2025'!$A$8:$A$500=$A11)*('Réel 2025'!$C$3:$AO$3=O$2),'Réel 2025'!$C$8:$AO$500)} -> 0 | P11: =IF(O11=0,0,Q11/O11) -> 0 | Q11: {=+SUMPRODUCT(('Réel 2025'!$A$8:$A$500=$A11)*('Réel 2025'!$C$3:$AO$3=Q$2),'Réel 2025'!$C$8:$AO$500)} -> 0 | R11: =J11-O11 -> 0 | S11: =L11-Q11 -> 0
A12: =+B12&C12 -> Véhicules neufs[...] | B12: =+$K$1 -> Véhicules neufs | C12: [...] | D12: {=+SUMPRODUCT(('Budget original'!$A$8:$A$501=$A12)*('Budget original'!$C$3:$AO$3=D$2),'Budget original'!$C$8:$AO$501)} -> 0 | E12: =IF(D12=0,0,F12/D12) -> 0 | F12: {=+SUMPRODUCT(('Budget original'!$A$8:$A$501=$A12)*('Budget original'!$C$3:$AO$3=F$2),'Budget original'!$C$8:$AO$501)} -> 0 | J12: =-SUMIFS(BV_Data_An_Cour!$P:$P,BV_Data_An_Cour!$U:$U,$B12,BV_Data_An_Cour!$V:$V,$C12,BV_Data_An_Cour!$W:$W,J$2) -> 0 | K12: =IF(J12=0,0,L12/J12) -> 0 | L12: =-SUMIFS(BV_Data_An_Cour!$P:$P,BV_Data_An_Cour!$U:$U,$B12,BV_Data_An_Cour!$V:$V,$C12,BV_Data_An_Cour!$W:$W,L$2) -> 0 | M12: =J12-D12 -> 0 | N12: =L12-F12 -> 0 | O12: {=+SUMPRODUCT(('Réel 2025'!$A$8:$A$500=$A12)*('Réel 2025'!$C$3:$AO$3=O$2),'Réel 2025'!$C$8:$AO$500)} -> 0 | P12: =IF(O12=0,0,Q12/O12) -> 0 | Q12: {=+SUMPRODUCT(('Réel 2025'!$A$8:$A$500=$A12)*('Réel 2025'!$C$3:$AO$3=Q$2),'Réel 2025'!$C$8:$AO$500)} -> 0 | R12: =J12-O12 -> 0 | S12: =L12-Q12 -> 0
A13: =+B13&C13 -> Véhicules neufsTotal Neufs | B13: =+$K$1 -> Véhicules neufs | C13: Total Neufs | D13: =+SUM(D6:D12) -> 148 | E13: =IF(D13<=0,0,F13/D13) -> 4158.2146 | F13: =+SUM(F6:F12) -> 615415.76 | J13: =+SUM(J6:J12) -> 118 | K13: =IF(J13<=0,0,L13/J13) -> 4553.5425 | L13: =+SUM(L6:L12) -> 537318.01 | M13: =+SUM(M6:M12) -> -30 | N13: =+SUM(N6:N12) -> -78097.755 | O13: =+SUM(O6:O12) -> 116 | P13: =IF(O13<=0,0,Q13/O13) -> 4541.3611 | Q13: =+SUM(Q6:Q12) -> 526797.89 | R13: =+SUM(R6:R12) -> 2 | S13: =+SUM(S6:S12) -> 10520.12
A14: =+B14&C14 -> Véhicules neufs | B14: =+$K$1 -> Véhicules neufs | M14: =IF(D13=0,0,M13/D13) -> -0.2027027 | N14: =IF(F13=0,0,N13/F13) -> -0.12690243 | R14: =R13/O13 -> 0.017241379 | S14: =IF(Q13=0,0,(S13/Q13)) -> 0.019969936
A15: =+B15&C15 -> Véhicules neufsEx-Démos et courtoisies | B15: =+$K$1 -> Véhicules neufs | C15: Ex-Démos et courtoisies | D15: {=+SUMPRODUCT(('Budget original'!$A$8:$A$501=$A15)*('Budget original'!$C$3:$AO$3=D$2),'Budget original'!$C$8:$AO$501)} -> 24 | E15: =IF(D15=0,0,F15/D15) -> 1200 | F15: {=+SUMPRODUCT(('Budget original'!$A$8:$A$501=$A15)*('Budget original'!$C$3:$AO$3=F$2),'Budget original'!$C$8:$AO$501)} -> 28800 | J15: =-SUMIFS(BV_Data_An_Cour!$P:$P,BV_Data_An_Cour!$U:$U,$B15,BV_Data_An_Cour!$V:$V,$C15,BV_Data_An_Cour!$W:$W,J$2) -> 28 | K15: =IF(J15=0,0,L15/J15) -> 639.2325 | L15: =-SUMIFS(BV_Data_An_Cour!$P:$P,BV_Data_An_Cour!$U:$U,$B15,BV_Data_An_Cour!$V:$V,$C15,BV_Data_An_Cour!$W:$W,L$2) -> 17898.51 | M15: =J15-D15 -> 4 | N15: =L15-F15 -> -10901.49 | O15: {=+SUMPRODUCT(('Réel 2025'!$A$8:$A$500=$A15)*('Réel 2025'!$C$3:$AO$3=O$2),'Réel 2025'!$C$8:$AO$500)} -> 27 | P15: =IF(O15=0,0,Q15/O15) -> 2777.6352 | Q15: {=+SUMPRODUCT(('Réel 2025'!$A$8:$A$500=$A15)*('Réel 2025'!$C$3:$AO$3=Q$2),'Réel 2025'!$C$8:$AO$500)} -> 74996.15 | R15: =J15-O15 -> 1 | S15: =L15-Q15 -> -57097.64
A16: =+B16&C16 -> Véhicules neufs | B16: =+$K$1 -> Véhicules neufs
A17: =+B17&C17 -> Véhicules neufsFlottes | B17: =+$K$1 -> Véhicules neufs | C17: Flottes | D17: {=+SUMPRODUCT(('Budget original'!$A$8:$A$501=$A17)*('Budget original'!$C$3:$AO$3=D$2),'Budget original'!$C$8:$AO$501)} -> 10 | E17: =IF(D17=0,0,F17/D17) -> 750 | F17: {=+SUMPRODUCT(('Budget original'!$A$8:$A$501=$A17)*('Budget original'!$C$3:$AO$3=F$2),'Budget original'!$C$8:$AO$501)} -> 7500 | J17: =-SUMIFS(BV_Data_An_Cour!$P:$P,BV_Data_An_Cour!$U:$U,$B17,BV_Data_An_Cour!$V:$V,$C17,BV_Data_An_Cour!$W:$W,J$2) -> 17 | K17: =IF(J17=0,0,L17/J17) -> 2339.4729 | L17: =-SUMIFS(BV_Data_An_Cour!$P:$P,BV_Data_An_Cour!$U:$U,$B17,BV_Data_An_Cour!$V:$V,$C17,BV_Data_An_Cour!$W:$W,L$2) -> 39771.04 | M17: =J17-D17 -> 7 | N17: =L17-F17 -> 32271.04 | O17: {=+SUMPRODUCT(('Réel 2025'!$A$8:$A$500=$A17)*('Réel 2025'!$C$3:$AO$3=O$2),'Réel 2025'!$C$8:$AO$500)} -> 0 | P17: =IF(O17=0,0,Q17/O17) -> 0 | Q17: {=+SUMPRODUCT(('Réel 2025'!$A$8:$A$500=$A17)*('Réel 2025'!$C$3:$AO$3=Q$2),'Réel 2025'!$C$8:$AO$500)} -> 0 | R17: =J17-O17 -> 17 | S17: =L17-Q17 -> 39771.04 | V17: -9 unités fleet Maxim
A18: =+B18&C18 -> Véhicules neufs | B18: =+$K$1 -> Véhicules neufs
B19: =+$K$1 -> Véhicules neufs
A20: =+B20&C20 -> Véhicules neufs | B20: =+$K$1 -> Véhicules neufs
A21: =+B21&C21 -> Véhicules neufsRev. Finances | B21: =+$K$1 -> Véhicules neufs | C21: Rev. Finances | E21: =IF(D13=0,0,F21/(D13+D15)) -> 7 | F21: {=+SUMPRODUCT(('Budget original'!$A$8:$A$501=$A21)*('Budget original'!$C$3:$AO$3=F$2),'Budget original'!$C$8:$AO$501)} -> 1204 | K21: =IF(J13=0,0,L21/(J13+J15)) -> 28.668973 | L21: =-SUMIFS(BV_Data_An_Cour!$P:$P,BV_Data_An_Cour!$U:$U,$B21,BV_Data_An_Cour!$V:$V,$C21,BV_Data_An_Cour!$W:$W,L$2) -> 4185.67 | N21: =L21-F21 -> 2981.67 | P21: =IF(O13=0,0,Q21/(O13+O15)) -> 24.586294 | Q21: {=+SUMPRODUCT(('Réel 2025'!$A$8:$A$500=$A21)*('Réel 2025'!$C$3:$AO$3=Q$2),'Réel 2025'!$C$8:$AO$500)} -> 3515.84 | R21: =O21-K21 -> -28.668973 | S21: =L21-Q21 -> 669.83
A22: =+B22&C22 -> Véhicules neufsRev. Protections | B22: =+$K$1 -> Véhicules neufs | C22: Rev. Protections | E22: =IF(D13=0,0,F22/(D13+D15)) -> 1150 | F22: {=+SUMPRODUCT(('Budget original'!$A$8:$A$501=$A22)*('Budget original'!$C$3:$AO$3=F$2),'Budget original'!$C$8:$AO$501)} -> 197800 | K22: =IF(J13=0,0,L22/(J13+J15)) -> 696.18644 | L22: =-SUMIFS(BV_Data_An_Cour!$P:$P,BV_Data_An_Cour!$U:$U,$B22,BV_Data_An_Cour!$V:$V,$C22,BV_Data_An_Cour!$W:$W,L$2) -> 101643.22 | N22: =L22-F22 -> -96156.78 | P22: =IF(O13=0,0,Q22/(O13+O15)) -> 1280.4615 | Q22: {=+SUMPRODUCT(('Réel 2025'!$A$8:$A$500=$A22)*('Réel 2025'!$C$3:$AO$3=Q$2),'Réel 2025'!$C$8:$AO$500)} -> 183106 | R22: =O22-K22 -> -696.18644 | S22: =L22-Q22 -> -81462.78
A23: =+B23&C23 -> Véhicules neufsRev. Autres | B23: =+$K$1 -> Véhicules neufs | C23: Rev. Autres | E23: =IF(D13=0,0,F23/(D13+D15)) -> 443 | F23: {=+SUMPRODUCT(('Budget original'!$A$8:$A$501=$A23)*('Budget original'!$C$3:$AO$3=F$2),'Budget original'!$C$8:$AO$501)} -> 76196 | K23: =IF(J13=0,0,L23/(J13+J15)) -> 470.32781 | L23: =-SUMIFS(BV_Data_An_Cour!$P:$P,BV_Data_An_Cour!$U:$U,$B23,BV_Data_An_Cour!$V:$V,$C23,BV_Data_An_Cour!$W:$W,L$2) -> 68667.86 | N23: =L23-F23 -> -7528.14 | P23: =IF(O13=0,0,Q23/(O13+O15)) -> 680.62895 | Q23: {=+SUMPRODUCT(('Réel 2025'!$A$8:$A$500=$A23)*('Réel 2025'!$C$3:$AO$3=Q$2),'Réel 2025'!$C$8:$AO$500)} -> 97329.94 | R23: =O23-K23 -> -470.32781 | S23: =L23-Q23 -> -28662.08
A24: =+B24&C24 -> Véhicules neufsTotal F&I | B24: =+$K$1 -> Véhicules neufs | C24: Total F&I | D24: =+D15+D13 -> 172 | E24: =IF(D24<=0,0,F24/D24) -> 1600 | F24: =F21+F22+F23 -> 275200 | J24: =+J15+J13 -> 146 | K24: =IF(J24<=0,0,L24/J24) -> 1195.1832 | L24: =L21+L22+L23 -> 174496.75 | M24: =J24-D24 -> -26 | N24: =L24-F24 -> -100703.25 | O24: =+O15+O13 -> 143 | P24: =IF(O24<=0,0,Q24/O24) -> 1985.6768 | Q24: =Q21+Q22+Q23 -> 283951.78 | S24: =L24-Q24 -> -109455.03
A25: =+B25&C25 -> Véhicules neufs | B25: =+$K$1 -> Véhicules neufs | N25: =IF(N24=0,0,N24/F24) -> -0.36592751 | S25: =IF(Q24=0,0,(S24/Q24)) -> -0.38547048
A26: =+B26&C26 -> Véhicules neufs | B26: =+$K$1 -> Véhicules neufs
A27: =+B27&C27 -> Véhicules neufsTotal Dépt. Neufs | B27: =+$K$1 -> Véhicules neufs | C27: Total Dépt. Neufs | D27: =+D13+D15+D17 -> 182 | E27: =IF(D27<=0,0,F27/D27) -> 5092.9438 | F27: =F13+F17+F24+F15 -> 926915.76 | J27: =+J13+J15+J17 -> 163 | K27: =IF(J27<=0,0,L27/J27) -> 4720.7626 | L27: =L13+L17+L24+L15 -> 769484.31 | M27: =J27-D27 -> -19 | N27: =L27-F27 -> -157431.45 | O27: =+O13+O15+O17 -> 143 | P27: =IF(O27<=0,0,Q27/O27) -> 6194.0267 | Q27: =Q13+Q17+Q24+Q15 -> 885745.82 | R27: =J27-O27 -> 20 | S27: =L27-Q27 -> -116261.51
A28: =+B28&C28 -> Véhicules neufs | B28: =+$K$1 -> Véhicules neufs | M28: =M27/D27 -> -0.1043956 | N28: =N27/F27 -> -0.1698444 | R28: =R27/O27 -> 0.13986014 | S28: =IF(Q27=0,0,S27/Q27) -> -0.13125832
A29: =+B29&C29 -> Véhicules neufs | B29: =+$K$1 -> Véhicules neufs
A30: =+B30&C30 -> Véhicules neufsDEPENSES | B30: =+$K$1 -> Véhicules neufs | C30: DEPENSES
A31: =+B31&C31 -> Véhicules neufsComm. vendeurs | B31: =+$K$1 -> Véhicules neufs | C31: Comm. vendeurs | E31: =F31/D$24 -> 1049.7241 | F31: {=+SUMPRODUCT(('Budget original'!$A$8:$A$501=$A31)*('Budget original'!$C$3:$AO$3=F$2),'Budget original'!$C$8:$AO$501)} -> 180552.55 | J31: =L31/(L13+L15) -> 0.29512049 | K31: =IF(L31=0,0,L31/J$24) -> 1122.2998 | L31: =SUMIFS(BV_Data_An_Cour!$P:$P,BV_Data_An_Cour!$U:$U,$B31,BV_Data_An_Cour!$V:$V,$C31,BV_Data_An_Cour!$W:$W,L$2) -> 163855.77 | N31: =L31-F31 -> -16696.776 | P31: =Q31/O$24 -> 1077.8079 | Q31: {=+SUMPRODUCT(('Réel 2025'!$A$8:$A$500=$A31)*('Réel 2025'!$C$3:$AO$3=Q$2),'Réel 2025'!$C$8:$AO$500)} -> 154126.53 | S31: =L31-Q31 -> 9729.24
A32: =+B32&C32 -> Véhicules neufsComm. F&I | B32: =+$K$1 -> Véhicules neufs | C32: Comm. F&I | E32: =F32/D$24 -> 488 | F32: {=+SUMPRODUCT(('Budget original'!$A$8:$A$501=$A32)*('Budget original'!$C$3:$AO$3=F$2),'Budget original'!$C$8:$AO$501)} -> 83936 | J32: =L32/L24 -> 0.25958661 | K32: =IF(L32=0,0,L32/J$24) -> 310.25356 | L32: =SUMIFS(BV_Data_An_Cour!$P:$P,BV_Data_An_Cour!$U:$U,$B32,BV_Data_An_Cour!$V:$V,$C32,BV_Data_An_Cour!$W:$W,L$2) -> 45297.02 | N32: =L32-F32 -> -38638.98 | P32: =Q32/O$24 -> 616.53706 | Q32: {=+SUMPRODUCT(('Réel 2025'!$A$8:$A$500=$A32)*('Réel 2025'!$C$3:$AO$3=Q$2),'Réel 2025'!$C$8:$AO$500)} -> 88164.8 | S32: =L32-Q32 -> -42867.78
A33: =+B33&C33 -> Véhicules neufsFrais de livraison | B33: =+$K$1 -> Véhicules neufs | C33: Frais de livraison | E33: =F33/D$24 -> 120 | F33: {=+SUMPRODUCT(('Budget original'!$A$8:$A$501=$A33)*('Budget original'!$C$3:$AO$3=F$2),'Budget original'!$C$8:$AO$501)} -> 20640 | K33: =IF(L33=0,0,L33/J$24) -> 145.29808 | L33: =SUMIFS(BV_Data_An_Cour!$P:$P,BV_Data_An_Cour!$U:$U,$B33,BV_Data_An_Cour!$V:$V,$C33,BV_Data_An_Cour!$W:$W,L$2) -> 21213.52 | N33: =L33-F33 -> 573.52 | P33: =Q33/O$24 -> 98.698322 | Q33: {=+SUMPRODUCT(('Réel 2025'!$A$8:$A$500=$A33)*('Réel 2025'!$C$3:$AO$3=Q$2),'Réel 2025'!$C$8:$AO$500)} -> 14113.86 | S33: =L33-Q33 -> 7099.66
A34: =+B34&C34 -> Véhicules neufsService gratuit 1 | B34: =+$K$1 -> Véhicules neufs | C34: Service gratuit 1 | E34: =F34/D$24 -> 35 | F34: {=+SUMPRODUCT(('Budget original'!$A$8:$A$501=$A34)*('Budget original'!$C$3:$AO$3=F$2),'Budget original'!$C$8:$AO$501)} -> 6020 | K34: =IF(L34=0,0,L34/J$24) -> 45.968288 | L34: =SUMIFS(BV_Data_An_Cour!$P:$P,BV_Data_An_Cour!$U:$U,$B34,BV_Data_An_Cour!$V:$V,$C34,BV_Data_An_Cour!$W:$W,L$2) -> 6711.37 | N34: =L34-F34 -> 691.37 | P34: =Q34/O$24 -> 31.451608 | Q34: {=+SUMPRODUCT(('Réel 2025'!$A$8:$A$500=$A34)*('Réel 2025'!$C$3:$AO$3=Q$2),'Réel 2025'!$C$8:$AO$500)} -> 4497.58 | S34: =L34-Q34 -> 2213.79
A35: =+B35&C35 -> Véhicules neufsEntretien stock | B35: =+$K$1 -> Véhicules neufs | C35: Entretien stock | E35: =F35/D$24 -> 97.244186 | F35: {=+SUMPRODUCT(('Budget original'!$A$8:$A$501=$A35)*('Budget original'!$C$3:$AO$3=F$2),'Budget original'!$C$8:$AO$501)} -> 16726 | K35: =IF(L35=0,0,L35/J$24) -> 112.72801 | L35: =SUMIFS(BV_Data_An_Cour!$P:$P,BV_Data_An_Cour!$U:$U,$B35,BV_Data_An_Cour!$V:$V,$C35,BV_Data_An_Cour!$W:$W,L$2) -> 16458.29 | N35: =L35-F35 -> -267.71 | P35: =Q35/O$24 -> 67.835175 | Q35: {=+SUMPRODUCT(('Réel 2025'!$A$8:$A$500=$A35)*('Réel 2025'!$C$3:$AO$3=Q$2),'Réel 2025'!$C$8:$AO$500)} -> 9700.43 | S35: =L35-Q35 -> 6757.86
A36: =+B36&C36 -> Véhicules neufsPublicité 1 | B36: =+$K$1 -> Véhicules neufs | C36: Publicité 1 | E36: =F36/D$24 -> 234.88788 | F36: {=+SUMPRODUCT(('Budget original'!$A$8:$A$501=$A36)*('Budget original'!$C$3:$AO$3=F$2),'Budget original'!$C$8:$AO$501)} -> 40400.715 | K36: =IF(L36=0,0,L36/J$24) -> 200.45459 | L36: =SUMIFS(BV_Data_An_Cour!$P:$P,BV_Data_An_Cour!$U:$U,$B36,BV_Data_An_Cour!$V:$V,$C36,BV_Data_An_Cour!$W:$W,L$2) -> 29266.37 | N36: =L36-F36 -> -11134.345 | P36: =Q36/O$24 -> 560.01084 | Q36: {=+SUMPRODUCT(('Réel 2025'!$A$8:$A$500=$A36)*('Réel 2025'!$C$3:$AO$3=Q$2),'Réel 2025'!$C$8:$AO$500)} -> 80081.55 | S36: =L36-Q36 -> -50815.18
A37: =+B37&C37 -> Véhicules neufsIntérêt de gros | B37: =+$K$1 -> Véhicules neufs | C37: Intérêt de gros | E37: =F37/D$24 -> 790.44912 | F37: {=+SUMPRODUCT(('Budget original'!$A$8:$A$501=$A37)*('Budget original'!$C$3:$AO$3=F$2),'Budget original'!$C$8:$AO$501)} -> 135957.25 | K37: =IF(L37=0,0,L37/J$24) -> 856.32993 | L37: =SUMIFS(BV_Data_An_Cour!$P:$P,BV_Data_An_Cour!$U:$U,$B37,BV_Data_An_Cour!$V:$V,$C37,BV_Data_An_Cour!$W:$W,L$2) -> 125024.17 | N37: =L37-F37 -> -10933.079 | P37: =Q37/O$24 -> 995.17364 | Q37: {=+SUMPRODUCT(('Réel 2025'!$A$8:$A$500=$A37)*('Réel 2025'!$C$3:$AO$3=Q$2),'Réel 2025'!$C$8:$AO$500)} -> 142309.83 | S37: =L37-Q37 -> -17285.66
A38: =+B38&C38 -> Véhicules neufs[...] | B38: =+$K$1 -> Véhicules neufs | C38: [...] | E38: =F38/D$24 -> 0 | F38: {=+SUMPRODUCT(('Budget original'!$A$8:$A$501=$A38)*('Budget original'!$C$3:$AO$3=F$2),'Budget original'!$C$8:$AO$501)} -> 0 | K38: =IF(L38=0,0,L38/J$24) -> 0 | L38: =SUMIFS(BV_Data_An_Cour!$P:$P,BV_Data_An_Cour!$U:$U,$B38,BV_Data_An_Cour!$V:$V,$C38,BV_Data_An_Cour!$W:$W,L$2) -> 0 | N38: =L38-F38 -> 0 | P38: =Q38/O$24 -> 0 | Q38: {=+SUMPRODUCT(('Réel 2025'!$A$8:$A$500=$A38)*('Réel 2025'!$C$3:$AO$3=Q$2),'Réel 2025'!$C$8:$AO$500)} -> 0 | S38: =L38-Q38 -> 0
