Workbook
Name _Dates_Conc: [1]Dealers!$BF$37:$KA$63
Name _Dates_Conc: #REF!
Name _scen: '[1]Scen & Sens'!$E$26
Name _scen: #REF!
Name _scen1: '[1]Scen & Sens'!$E$27
Name _scen1: #REF!
Name _scen2: '[1]Scen & Sens'!$E$28
Name _scen2: #REF!
Name _SCenarios: '[1]Scen & Sens'!$J$26:$O$26
Name _SCenarios: #REF!
Name _Sens1: '[1]Scen & Sens'!$F$9
Name _Sens1: #REF!
Name _Sens2: '[1]Scen & Sens'!$F$10
Name _Sens2: #REF!
Name _sensRes1: '[1]Scen & Sens'!$E$15
Name _sensRes1: #REF!
Name _sensRes2: '[1]Scen & Sens'!$E$16
Name _sensRes2: #REF!
Name _sensRes3: '[1]Scen & Sens'!$E$17
Name _sensRes3: #REF!
Name _sensRes4: '[1]Scen & Sens'!$E$18
Name _sensRes4: #REF!
Name _sensRes5: '[1]Scen & Sens'!$E$19
Name _sensRes5: #REF!
Name _sensRes6: '[1]Scen & Sens'!$E$20
Name _sensRes6: #REF!
Name _sensRes7: '[1]Scen & Sens'!$E$21
Name _sensRes7: #REF!
Name Compco1: {"Page1",#N/A,FALSE,"CompCo";"Page2",#N/A,FALSE,"CompCo"}
Name Compco2: {"Page1",#N/A,FALSE,"CompCo";"Page2",#N/A,FALSE,"CompCo"}
Name DateRange: [1]Volkswagen!$BF$6:$DY$6
Name DateRange: #REF!
Name DateRangePr: OFFSET([2]!DateRangePriceMain,5,0,COUNTA([2]!DateRangePriceMain)-COUNTA(#REF!),1)
Name DateRangePrice: OFFSET([3]!DateRangePriceMain,5,0,COUNTA([3]!DateRangePriceMain)-COUNTA(#REF!),1)
Name DateRangePrice1: OFFSET([3]!DateRangePriceMain,5,0,COUNTA([3]!DateRangePriceMain)-COUNTA(#REF!),1)
Name DateRangePrice2: OFFSET([2]!DateRangePriceMain,5,0,COUNTA([2]!DateRangePriceMain)-COUNTA(#REF!),1)
Name ERT: {"execsum",#N/A,FALSE,"ExecSum";"finstatement",#N/A,FALSE,"Fin_St"}
Name hn.Delete015: '[4]CREDIT STATS'!$B$9:$K$14,'[4]CREDIT STATS'!$O$11:$X$18,'[4]CREDIT STATS'!$B$28:$K$37,'[4]CREDIT STATS'!$O$28:$X$32,'[4]CREDIT STATS'!$O$46:$X$46
Name kjjkghkhj: {"finana",#N/A,FALSE,"Fin"}
Name lkhkhj: {"sub1",#N/A,FALSE,"Subs";"pac1",#N/A,FALSE,"Packages";"rev1",#N/A,FALSE,"2. Revenues"}
Name Monetary_Unit: [1]Parameters!$B$15
Name Monetary_Unit: #REF!
Name Months: [1]Parameters!$E$9:$E$20
Name Months: #REF!
Name PriceRange: OFFSET([3]!PriceRangeMain,5,0,COUNTA([3]!PriceRangeMain)-COUNTA(#REF!),1)
Name PriceRange2: OFFSET([2]!PriceRangeMain,5,0,COUNTA([2]!PriceRangeMain)-COUNTA(#REF!),1)
Name Rng_Dealers_Names: [1]!Tbl_Dealers[Dealer Name]
Name Rng_Dealers_Names: #REF!
Name Rng_Dlr_Dates: [1]!Tbl_V_Dlr_Dates[Date]
Name Rng_Dlr_Dates: #REF!
Name test: {"execsum",#N/A,FALSE,"ExecSum";"finstatement",#N/A,FALSE,"Fin_St"}
Name test21: OFFSET([2]!DateRangePriceMain,5,0,COUNTA([2]!DateRangePriceMain)-COUNTA(#REF!),1)
Name Ticker: #REF!
Name Ticker: #REF!
Name Titre: [1]Front!$A$9
Name Titre: #REF!
Name value: OFFSET([3]!DateRangePriceMain,5,0,COUNTA([3]!DateRangePriceMain)-COUNTA(#REF!),1)
Name value2: OFFSET([2]!DateRangePriceMain,5,0,COUNTA([2]!DateRangePriceMain)-COUNTA(#REF!),1)
Name wrn.amendement.: {#N/A,#N/A,FALSE,"amendement"}
Name wrn.amendement..: {#N/A,#N/A,FALSE,"amendement"}

Sheet Parametres
A1: Compagnie | B1: BMW Sherbrooke
G2: 1-Mémo | M2: Mois | N2: YTD
A3: Mois Courant | B3: Avril | C3: =+VLOOKUP(B3,$K$3:$L$14,2,0) -> 4 | G3: 10-Compte compteur | K3: Janvier | L3: 1 | M3: =+IF($K3=$B$3,"X","") | N3: =+IF(K3=B3,"X",IF(L3<=$C$3,"X","")) -> X
A4: Année | B4: 2025 | K4: Février | L4: 2 | M4: =+IF($K4=$B$3,"X","") | N4: =+IF(K4=B4,"X",IF(L4<=$C$3,"X","")) -> X
K5: Mars | L5: 3 | M5: =+IF($K5=$B$3,"X","") | N5: =+IF(K5=B5,"X",IF(L5<=$C$3,"X","")) -> X
K6: Avril | L6: 4 | M6: =+IF($K6=$B$3,"X","") -> X | N6: =+IF(K6=B6,"X",IF(L6<=$C$3,"X","")) -> X
K7: Mai | L7: 5 | M7: =+IF($K7=$B$3,"X","") | N7: =+IF(K7=B7,"X",IF(L7<=$C$3,"X",""))
K8: Juin | L8: 6 | M8: =+IF($K8=$B$3,"X","") | N8: =+IF(K8=B8,"X",IF(L8<=$C$3,"X",""))
A9: Sélectionner le mois en B3 | K9: Juillet | L9: 7 | M9: =+IF($K9=$B$3,"X","") | N9: =+IF(K9=B9,"X",IF(L9<=$C$3,"X",""))
A10: Coller les balances de vérification respectives en cellule A1 dans les onglets BV_Data_An_Cour et BV_Data_An_Prec | K10: Août | L10: 8 | M10: =+IF($K10=$B$3,"X","") | N10: =+IF(K10=B10,"X",IF(L10<=$C$3,"X",""))
A11: Vérifier s'il y a des #N/A dans les colonnes T à X des onlgets de BV | K11: Septembre | L11: 9 | M11: =+IF($K11=$B$3,"X","") | N11: =+IF(K11=B11,"X",IF(L11<=$C$3,"X",""))
A12: Vérifier les chiffres avec l'état financier et les réalisés an passé pour les résultat net mois et aad | K12: Octobre | L12: 10 | M12: =+IF($K12=$B$3,"X","") | N12: =+IF(K12=B12,"X",IF(L12<=$C$3,"X",""))
K13: Novembre | L13: 11 | M13: =+IF($K13=$B$3,"X","") | N13: =+IF(K13=B13,"X",IF(L13<=$C$3,"X",""))
K14: Décembre | L14: 12 | M14: =+IF($K14=$B$3,"X","") | N14: =+IF(K14=B14,"X",IF(L14<=$C$3,"X",""))

Sheet Bilan
A1: BILAN
A2: =+Parametres!B1 -> BMW Sherbrooke
A3: =CONCATENATE("",,Parametres!B3," ",Parametres!B4) -> Avril 2025
A5: Encaisse | B5: =SUMIFS(BV_Data_An_Cour!$P:$P,BV_Data_An_Cour!$U:$U,$A$1,BV_Data_An_Cour!$V:$V,$A5) -> 1999437.1 | D5: Marge de crédit | E5: =-SUMIFS(BV_Data_An_Cour!$P:$P,BV_Data_An_Cour!$U:$U,$A$1,BV_Data_An_Cour!$V:$V,$D5) -> 0
A6: Total Trésorerie et équivalent de Trésorerie | B6: =SUM(B5) -> 1999437.1
D7: Portion Court Terme de la Dette Long Terme | E7: =-SUMIFS(BV_Data_An_Cour!$P:$P,BV_Data_An_Cour!$U:$U,$A$1,BV_Data_An_Cour!$V:$V,$D7) -> 0
A8: Recevables Contrats en Transit | B8: =SUMIFS(BV_Data_An_Cour!$P:$P,BV_Data_An_Cour!$U:$U,$A$1,BV_Data_An_Cour!$V:$V,$A8) -> 1458301.8
A9: Recevables Véhicules | B9: =SUMIFS(BV_Data_An_Cour!$P:$P,BV_Data_An_Cour!$U:$U,$A$1,BV_Data_An_Cour!$V:$V,$A9) -> 146427.85 | D9: Avances à payer | E9: =-SUMIFS(BV_Data_An_Cour!$P:$P,BV_Data_An_Cour!$U:$U,$A$1,BV_Data_An_Cour!$V:$V,$D9) -> 0
A10: Recevables Manufacturier | B10: =SUMIFS(BV_Data_An_Cour!$P:$P,BV_Data_An_Cour!$U:$U,$A$1,BV_Data_An_Cour!$V:$V,$A10) -> 131631.39 | D10: Comptes à Payer Fournisseurs | E10: =-SUMIFS(BV_Data_An_Cour!$P:$P,BV_Data_An_Cour!$U:$U,$A$1,BV_Data_An_Cour!$V:$V,$D10) -> 198236.38
A11: Recevables Pièces et Service | B11: =SUMIFS(BV_Data_An_Cour!$P:$P,BV_Data_An_Cour!$U:$U,$A$1,BV_Data_An_Cour!$V:$V,$A11) -> 83181.14 | D11: Taxes de Vente à Payer | E11: =-SUMIFS(BV_Data_An_Cour!$P:$P,BV_Data_An_Cour!$U:$U,$A$1,BV_Data_An_Cour!$V:$V,$D11) -> 83154.01
A12: Recevables Garantie Manufacturier | B12: =SUMIFS(BV_Data_An_Cour!$P:$P,BV_Data_An_Cour!$U:$U,$A$1,BV_Data_An_Cour!$V:$V,$A12) -> 9862.56 | D12: Impôts à payer | E12: =-SUMIFS(BV_Data_An_Cour!$P:$P,BV_Data_An_Cour!$U:$U,$A$1,BV_Data_An_Cour!$V:$V,$D12) -> 867228.05
A13: Recevables Carrosserie | B13: =SUMIFS(BV_Data_An_Cour!$P:$P,BV_Data_An_Cour!$U:$U,$A$1,BV_Data_An_Cour!$V:$V,$A13) -> 0 | D13: Dépôts de Client | E13: =-SUMIFS(BV_Data_An_Cour!$P:$P,BV_Data_An_Cour!$U:$U,$A$1,BV_Data_An_Cour!$V:$V,$D13) -> 99853.99
A14: Recevables Intercos | B14: =SUMIFS(BV_Data_An_Cour!$P:$P,BV_Data_An_Cour!$U:$U,$A$1,BV_Data_An_Cour!$V:$V,$A14) -> 86400 | D14: Payables Intercos | E14: =-SUMIFS(BV_Data_An_Cour!$P:$P,BV_Data_An_Cour!$U:$U,$A$1,BV_Data_An_Cour!$V:$V,$D14) -> 163854.91
A15: Recevables Autres | B15: =SUMIFS(BV_Data_An_Cour!$P:$P,BV_Data_An_Cour!$U:$U,$A$1,BV_Data_An_Cour!$V:$V,$A15) -> 17533.8 | D15: Autres Comptes à Payer | E15: =-SUMIFS(BV_Data_An_Cour!$P:$P,BV_Data_An_Cour!$U:$U,$A$1,BV_Data_An_Cour!$V:$V,$D15) -> 382442.56
A16: Total Comptes à Recevoir | B16: =+SUM(B8:B15) -> 1933338.5 | D16: Total Comptes à Payer | E16: =+SUM(E10:E15) -> 1794769.9
A18: Inventaire Véhicules Neufs | B18: =SUMIFS(BV_Data_An_Cour!$P:$P,BV_Data_An_Cour!$U:$U,$A$1,BV_Data_An_Cour!$V:$V,$A18) -> 6367035 | D18: Effet à Payer Véhicules Neufs | E18: =-SUMIFS(BV_Data_An_Cour!$P:$P,BV_Data_An_Cour!$U:$U,$A$1,BV_Data_An_Cour!$V:$V,$D18) -> 8488042.7
A19: Inventaire Véhicules Usagés | B19: =SUMIFS(BV_Data_An_Cour!$P:$P,BV_Data_An_Cour!$U:$U,$A$1,BV_Data_An_Cour!$V:$V,$A19) -> 2063058.6 | D19: Effet à Payer Véhicules Usagés | E19: =-SUMIFS(BV_Data_An_Cour!$P:$P,BV_Data_An_Cour!$U:$U,$A$1,BV_Data_An_Cour!$V:$V,$D19) -> 937246.05
A20: Inventaire Pièces, Pneus, Huile | B20: =SUMIFS(BV_Data_An_Cour!$P:$P,BV_Data_An_Cour!$U:$U,$A$1,BV_Data_An_Cour!$V:$V,$A20) -> 520521 | D20: Total Effets à Payer | E20: =+SUM(E18:E19) -> 9425288.7
A21: Total Inventaires | B21: =SUM(B18:B20) -> 8950614.7
D22: Salaires à Payer | E22: =-SUMIFS(BV_Data_An_Cour!$P:$P,BV_Data_An_Cour!$U:$U,$A$1,BV_Data_An_Cour!$V:$V,$D22) -> 346036.22
A23: Avances à recevoir | B23: =SUMIFS(BV_Data_An_Cour!$P:$P,BV_Data_An_Cour!$U:$U,$A$1,BV_Data_An_Cour!$V:$V,$A23) -> 0 | D23: DAS à Payer | E23: =-SUMIFS(BV_Data_An_Cour!$P:$P,BV_Data_An_Cour!$U:$U,$A$1,BV_Data_An_Cour!$V:$V,$D23) -> 8220.3
A24: Travaux en Cours | B24: =SUMIFS(BV_Data_An_Cour!$P:$P,BV_Data_An_Cour!$U:$U,$A$1,BV_Data_An_Cour!$V:$V,$A24) -> 8749.73 | D24: Autres Courus | E24: =-SUMIFS(BV_Data_An_Cour!$P:$P,BV_Data_An_Cour!$U:$U,$A$1,BV_Data_An_Cour!$V:$V,$D24) -> 206376.49
A25: Sous-Traitance | B25: =SUMIFS(BV_Data_An_Cour!$P:$P,BV_Data_An_Cour!$U:$U,$A$1,BV_Data_An_Cour!$V:$V,$A25) -> 321.29 | D25: [...] | E25: =-SUMIFS(BV_Data_An_Cour!$P:$P,BV_Data_An_Cour!$U:$U,$A$1,BV_Data_An_Cour!$V:$V,$D25) -> 0
A26: Frais Payés d'Avance | B26: =SUMIFS(BV_Data_An_Cour!$P:$P,BV_Data_An_Cour!$U:$U,$A$1,BV_Data_An_Cour!$V:$V,$A26) -> -37207.24 | D26: [...] | E26: =-SUMIFS(BV_Data_An_Cour!$P:$P,BV_Data_An_Cour!$U:$U,$A$1,BV_Data_An_Cour!$V:$V,$D26) -> 0
A27: [...] | B27: =SUMIFS(BV_Data_An_Cour!$P:$P,BV_Data_An_Cour!$U:$U,$A$1,BV_Data_An_Cour!$V:$V,$A27) -> 0 | D27: [...] | E27: =-SUMIFS(BV_Data_An_Cour!$P:$P,BV_Data_An_Cour!$U:$U,$A$1,BV_Data_An_Cour!$V:$V,$D27) -> 0
A28: [...] | B28: =SUMIFS(BV_Data_An_Cour!$P:$P,BV_Data_An_Cour!$U:$U,$A$1,BV_Data_An_Cour!$V:$V,$A28) -> 0 | D28: Total Frais Courus | E28: =SUM(E22:E24) -> 560633.01
A29: [...] | B29: =SUMIFS(BV_Data_An_Cour!$P:$P,BV_Data_An_Cour!$U:$U,$A$1,BV_Data_An_Cour!$V:$V,$A29) -> 0
A30: Total Autres | B30: =SUM(B23:B29) -> -28136.22 | D30: Total Passif Court Terme | E30: =+E5+E7+E16+E20+E28 -> 11780692
A32: Total Actif Court Terme | B32: =+B6+B16+B21+B30 -> 12855254
D33: Impôts Futurs à payer | E33: =-SUMIFS(BV_Data_An_Cour!$P:$P,BV_Data_An_Cour!$U:$U,$A$1,BV_Data_An_Cour!$V:$V,$D33) -> 1101731
A35: Terrain | B35: =SUMIFS(BV_Data_An_Cour!$P:$P,BV_Data_An_Cour!$U:$U,$A$1,BV_Data_An_Cour!$V:$V,$A35) -> 0 | D35: Avances Long Terme à Payer | E35: =-SUMIFS(BV_Data_An_Cour!$P:$P,BV_Data_An_Cour!$U:$U,$A$1,BV_Data_An_Cour!$V:$V,$D35) -> 0
A36: Bâtisse | B36: =SUMIFS(BV_Data_An_Cour!$P:$P,BV_Data_An_Cour!$U:$U,$A$1,BV_Data_An_Cour!$V:$V,$A36) -> 0 | D36: Hypothèque à Payer | E36: =-SUMIFS(BV_Data_An_Cour!$P:$P,BV_Data_An_Cour!$U:$U,$A$1,BV_Data_An_Cour!$V:$V,$D36) -> 0
A37: Améliorations Locatives | B37: =SUMIFS(BV_Data_An_Cour!$P:$P,BV_Data_An_Cour!$U:$U,$A$1,BV_Data_An_Cour!$V:$V,$A37) -> 608743.91 | D37: Dette à Long Terme | E37: =-SUMIFS(BV_Data_An_Cour!$P:$P,BV_Data_An_Cour!$U:$U,$A$1,BV_Data_An_Cour!$V:$V,$D37) -> 0
A38: Améliorations Locatives Permanentes | B38: =SUMIFS(BV_Data_An_Cour!$P:$P,BV_Data_An_Cour!$U:$U,$A$1,BV_Data_An_Cour!$V:$V,$A38) -> 0 | D38: Autres Dettes à Long Terme | E38: =-SUMIFS(BV_Data_An_Cour!$P:$P,BV_Data_An_Cour!$U:$U,$A$1,BV_Data_An_Cour!$V:$V,$D38) -> 0
A39: Équipements Service | B39: =SUMIFS(BV_Data_An_Cour!$P:$P,BV_Data_An_Cour!$U:$U,$A$1,BV_Data_An_Cour!$V:$V,$A39) -> 207862.96 | D39: [...] | E39: =-SUMIFS(BV_Data_An_Cour!$P:$P,BV_Data_An_Cour!$U:$U,$A$1,BV_Data_An_Cour!$V:$V,$D39) -> 0
A40: Mobilier | B40: =SUMIFS(BV_Data_An_Cour!$P:$P,BV_Data_An_Cour!$U:$U,$A$1,BV_Data_An_Cour!$V:$V,$A40) -> 219658.95 | D40: [...] | E40: =-SUMIFS(BV_Data_An_Cour!$P:$P,BV_Data_An_Cour!$U:$U,$A$1,BV_Data_An_Cour!$V:$V,$D40) -> 0
A41: Équipements Informatique | B41: =SUMIFS(BV_Data_An_Cour!$P:$P,BV_Data_An_Cour!$U:$U,$A$1,BV_Data_An_Cour!$V:$V,$A41) -> 16966.63 | D41: [...] | E41: =-SUMIFS(BV_Data_An_Cour!$P:$P,BV_Data_An_Cour!$U:$U,$A$1,BV_Data_An_Cour!$V:$V,$D41) -> 0
A42: Équipements Téléphonique | B42: =SUMIFS(BV_Data_An_Cour!$P:$P,BV_Data_An_Cour!$U:$U,$A$1,BV_Data_An_Cour!$V:$V,$A42) -> 0 | D42: Total Passif long terme | E42: =+SUM(E33:E38) -> 1101731
A43: Enseigne | B43: =SUMIFS(BV_Data_An_Cour!$P:$P,BV_Data_An_Cour!$U:$U,$A$1,BV_Data_An_Cour!$V:$V,$A43) -> 12885.77
A44: Total Immobilisations Nettes | B44: =SUM(B35:B43) -> 1066118.2
...

Sheet Budget original
B1: ="Budget 2023 Mensuel"&" "&Parametres!$B$1 -> Budget 2023 Mensuel BMW Sherbrooke
B2: Mois | F2: =+IF(Parametres!$B$3=F$6,"X","") | G2: =+IF(Parametres!$B$3=F$6,"O","") | H2: =+IF(Parametres!$B$3=F$6,"U","") | I2: =+IF(Parametres!$B$3=I$6,"X","") | J2: =+IF(Parametres!$B$3=I$6,"O","") | K2: =+IF(Parametres!$B$3=I$6,"U","") | L2: =+IF(Parametres!$B$3=L$6,"X","") | M2: =+IF(Parametres!$B$3=L$6,"O","") | N2: =+IF(Parametres!$B$3=L$6,"U","") | O2: =+IF(Parametres!$B$3=O$6,"X","") -> X | P2: =+IF(Parametres!$B$3=O$6,"O","") -> O | Q2: =+IF(Parametres!$B$3=O$6,"U","") -> U | R2: =+IF(Parametres!$B$3=R$6,"X","") | S2: =+IF(Parametres!$B$3=R$6,"O","") | T2: =+IF(Parametres!$B$3=R$6,"U","") | U2: =+IF(Parametres!$B$3=U$6,"X","") | V2: =+IF(Parametres!$B$3=U$6,"O","") | W2: =+IF(Parametres!$B$3=U$6,"U","") | X2: =+IF(Parametres!$B$3=X$6,"X","") | Y2: =+IF(Parametres!$B$3=X$6,"O","") | Z2: =+IF(Parametres!$B$3=X$6,"U","") | AA2: =+IF(Parametres!$B$3=AA$6,"X","") | AB2: =+IF(Parametres!$B$3=AA$6,"O","") | AC2: =+IF(Parametres!$B$3=AA$6,"U","") | AD2: =+IF(Parametres!$B$3=AD$6,"X","") | AE2: =+IF(Parametres!$B$3=AD$6,"O","") | AF2: =+IF(Parametres!$B$3=AD$6,"U","") | AG2: =+IF(Parametres!$B$3=AG$6,"X","") | AH2: =+IF(Parametres!$B$3=AG$6,"O","") | AI2: =+IF(Parametres!$B$3=AG$6,"U","") | AJ2: =+IF(Parametres!$B$3=AJ$6,"X","") | AK2: =+IF(Parametres!$B$3=AJ$6,"O","") | AL2: =+IF(Parametres!$B$3=AJ$6,"U","") | AM2: =+IF(Parametres!$B$3=AM$6,"X","") | AN2: =+IF(Parametres!$B$3=AM$6,"O","") | AO2: =+IF(Parametres!$B$3=AM$6,"U","")
B3: YTD | F3: =+IF(VLOOKUP(F$6,Parametres!$K$3:$N$14,4,0)="X","X","") -> X | G3: =+IF(VLOOKUP(F$6,Parametres!$K$3:$N$14,4,0)="X","O","") -> O | H3: =+IF(VLOOKUP(F$6,Parametres!$K$3:$N$14,4,0)="X","U","") -> U | I3: =+IF(VLOOKUP(I$6,Parametres!$K$3:$N$14,4,0)="X","X","") -> X | J3: =+IF(VLOOKUP(I$6,Parametres!$K$3:$N$14,4,0)="X","O","") -> O | K3: =+IF(VLOOKUP(I$6,Parametres!$K$3:$N$14,4,0)="X","U","") -> U | L3: =+IF(VLOOKUP(L$6,Parametres!$K$3:$N$14,4,0)="X","X","") -> X | M3: =+IF(VLOOKUP(L$6,Parametres!$K$3:$N$14,4,0)="X","O","") -> O | N3: =+IF(VLOOKUP(L$6,Parametres!$K$3:$N$14,4,0)="X","U","") -> U | O3: =+IF(VLOOKUP(O$6,Parametres!$K$3:$N$14,4,0)="X","X","") -> X | P3: =+IF(VLOOKUP(O$6,Parametres!$K$3:$N$14,4,0)="X","O","") -> O | Q3: =+IF(VLOOKUP(O$6,Parametres!$K$3:$N$14,4,0)="X","U","") -> U | R3: =+IF(VLOOKUP(R$6,Parametres!$K$3:$N$14,4,0)="X","X","") | S3: =+IF(VLOOKUP(R$6,Parametres!$K$3:$N$14,4,0)="X","O","") | T3: =+IF(VLOOKUP(R$6,Parametres!$K$3:$N$14,4,0)="X","U","") | U3: =+IF(VLOOKUP(U$6,Parametres!$K$3:$N$14,4,0)="X","X","") | V3: =+IF(VLOOKUP(U$6,Parametres!$K$3:$N$14,4,0)="X","O","") | W3: =+IF(VLOOKUP(U$6,Parametres!$K$3:$N$14,4,0)="X","U","") | X3: =+IF(VLOOKUP(X$6,Parametres!$K$3:$N$14,4,0)="X","X","") | Y3: =+IF(VLOOKUP(X$6,Parametres!$K$3:$N$14,4,0)="X","O","") | Z3: =+IF(VLOOKUP(X$6,Parametres!$K$3:$N$14,4,0)="X","U","") | AA3: =+IF(VLOOKUP(AA$6,Parametres!$K$3:$N$14,4,0)="X","X","") | AB3: =+IF(VLOOKUP(AA$6,Parametres!$K$3:$N$14,4,0)="X","O","") | AC3: =+IF(VLOOKUP(AA$6,Parametres!$K$3:$N$14,4,0)="X","U","") | AD3: =+IF(VLOOKUP(AD$6,Parametres!$K$3:$N$14,4,0)="X","X","") | AE3: =+IF(VLOOKUP(AD$6,Parametres!$K$3:$N$14,4,0)="X","O","") | AF3: =+IF(VLOOKUP(AD$6,Parametres!$K$3:$N$14,4,0)="X","U","") | AG3: =+IF(VLOOKUP(AG$6,Parametres!$K$3:$N$14,4,0)="X","X","") | AH3: =+IF(VLOOKUP(AG$6,Parametres!$K$3:$N$14,4,0)="X","O","") | AI3: =+IF(VLOOKUP(AG$6,Parametres!$K$3:$N$14,4,0)="X","U","") | AJ3: =+IF(VLOOKUP(AJ$6,Parametres!$K$3:$N$14,4,0)="X","X","") | AK3: =+IF(VLOOKUP(AJ$6,Parametres!$K$3:$N$14,4,0)="X","O","") | AL3: =+IF(VLOOKUP(AJ$6,Parametres!$K$3:$N$14,4,0)="X","U","") | AM3: =+IF(VLOOKUP(AM$6,Parametres!$K$3:$N$14,4,0)="X","X","") | AN3: =+IF(VLOOKUP(AM$6,Parametres!$K$3:$N$14,4,0)="X","O","") | AO3: =+IF(VLOOKUP(AM$6,Parametres!$K$3:$N$14,4,0)="X","U","")
B4: Budget 2025 | C4: Véhicules neufs
B6: Mois | C6: 2025 | F6: Janvier | I6: Février | L6: Mars | O6: Avril | R6: Mai | U6: Juin | X6: Juillet | AA6: Août | AD6: Septembre | AG6: Octobre | AJ6: Novembre | AM6: Décembre
C7: UNITE | D7: $P/UNITE | E7: $PROFITS | F7: UNITE | G7: $P/UNITE | H7: $PROFITS | I7: UNITE | J7: $P/UNITE | K7: $PROFITS | L7: UNITE | M7: $P/UNITE | N7: $PROFITS | O7: UNITE | P7: $P/UNITE | Q7: $PROFITS | R7: UNITE | S7: $P/UNITE | T7: $PROFITS | U7: UNITE | V7: $P/UNITE | W7: $PROFITS | X7: UNITE | Y7: $P/UNITE | Z7: $PROFITS | AA7: UNITE | AB7: $P/UNITE | AC7: $PROFITS | AD7: UNITE | AE7: $P/UNITE | AF7: $PROFITS | AG7: UNITE | AH7: $P/UNITE | AI7: $PROFITS | AJ7: UNITE | AK7: $P/UNITE | AL7: $PROFITS | AM7: UNITE | AN7: $P/UNITE | AO7: $PROFITS
A8: =+$C$4&B8 -> Véhicules neufsVentes nettes | B8: Ventes nettes | E8: 25300742 | H8: 1392233.6 | K8: 1203869.3 | N8: 2376592 | Q8: 3027277.1 | T8: 3315725.1 | W8: 2132666.7 | Z8: 1576929.9 | AC8: 2044724.1 | AF8: 2351226.7 | AI8: 2297872.1 | AL8: 1921112.5 | AO8: 1660512.8
A9: =+$C$4&B9 -> Véhicules neufsAutos détail | B9: Autos détail | C9: 86 | D9: 4306.3953 | E9: 370350 | F9: 5 | G9: 4306.3953 | H9: 21531.977 | I9: 4 | J9: 4306.3953 | K9: 17225.581 | L9: 8 | M9: 4306.3953 | N9: 34451.163 | O9: 10 | P9: 4306.3953 | Q9: 43063.953 | R9: 11 | S9: 4306.3953 | T9: 47370.349 | U9: 7 | V9: 4306.3953 | W9: 30144.767 | X9: 5 | Y9: 4306.3953 | Z9: 21531.977 | AA9: 7 | AB9: 4306.3953 | AC9: 30144.767 | AD9: 8 | AE9: 4306.3953 | AF9: 34451.163 | AG9: 8 | AH9: 4306.3953 | AI9: 34451.163 | AJ9: 7 | AK9: 4306.3953 | AL9: 30144.767 | AM9: 6 | AN9: 4306.3953 | AO9: 25838.372
A10: =+$C$4&B10 -> Véhicules neufsCamions détail | B10: Camions détail | C10: 151 | D10: 4000.3311 | E10: 604050 | F10: 8 | G10: 4000.3311 | H10: 32002.649 | I10: 7 | J10: 4000.3311 | K10: 28002.318 | L10: 14 | M10: 4000.3311 | N10: 56004.636 | O10: 18 | P10: 4000.3311 | Q10: 72005.96 | R10: 20 | S10: 4000.3311 | T10: 80006.623 | U10: 13 | V10: 4000.3311 | W10: 52004.305 | X10: 10 | Y10: 4000.3311 | Z10: 40003.311 | AA10: 12 | AB10: 4000.3311 | AC10: 48003.974 | AD10: 14 | AE10: 4000.3311 | AF10: 56004.636 | AG10: 14 | AH10: 4000.3311 | AI10: 56004.636 | AJ10: 11 | AK10: 4000.3311 | AL10: 44003.642 | AM10: 10 | AN10: 4000.3311 | AO10: 40003.311
A11: =+$C$4&B11 -> Véhicules neufsSprinter | B11: Sprinter | C11: 0 | D11: 0 | E11: 0 | F11: 0 | G11: 0 | H11: 0 | I11: 0 | J11: 0 | K11: 0 | L11: 0 | M11: 0 | N11: 0 | O11: 0 | P11: 0 | Q11: 0 | R11: 0 | S11: 0 | T11: 0 | U11: 0 | V11: 0 | W11: 0 | X11: 0 | Y11: 0 | Z11: 0 | AA11: 0 | AB11: 0 | AC11: 0 | AD11: 0 | AE11: 0 | AF11: 0 | AG11: 0 | AH11: 0 | AI11: 0 | AJ11: 0 | AK11: 0 | AL11: 0 | AM11: 0 | AN11: 0 | AO11: 0
A12: =+$C$4&B12 -> Véhicules neufsMoto détail | B12: Moto détail | C12: 0 | D12: 0 | E12: 0 | F12: 0 | G12: 0 | H12: 0 | I12: 0 | J12: 0 | K12: 0 | L12: 0 | M12: 0 | N12: 0 | O12: 0 | P12: 0 | Q12: 0 | R12: 0 | S12: 0 | T12: 0 | U12: 0 | V12: 0 | W12: 0 | X12: 0 | Y12: 0 | Z12: 0 | AA12: 0 | AB12: 0 | AC12: 0 | AD12: 0 | AE12: 0 | AF12: 0 | AG12: 0 | AH12: 0 | AI12: 0 | AJ12: 0 | AK12: 0 | AL12: 0 | AM12: 0 | AN12: 0 | AO12: 0
A13: =+$C$4&B13 -> Véhicules neufs[...] | B13: [...] | C13: 0 | D13: 0 | E13: 0 | G13: 0 | J13: 0 | M13: 0 | P13: 0 | S13: 0 | V13: 0 | Y13: 0 | AB13: 0 | AE13: 0 | AH13: 0 | AK13: 0 | AN13: 0
A14: =+$C$4&B14 -> Véhicules neufs[...] | B14: [...] | C14: 0 | D14: 0 | E14: 0 | G14: 0 | J14: 0 | M14: 0 | P14: 0 | S14: 0 | V14: 0 | Y14: 0 | AB14: 0 | AE14: 0 | AH14: 0 | AK14: 0 | AN14: 0
A15: =+$C$4&B15 -> Véhicules neufs[...] | B15: [...] | C15: 0 | D15: 0 | E15: 0 | G15: 0 | J15: 0 | M15: 0 | P15: 0 | S15: 0 | V15: 0 | Y15: 0 | AB15: 0 | AE15: 0 | AH15: 0 | AK15: 0 | AN15: 0
A16: =+$C$4&B16 -> Véhicules neufsTotal Neufs | B16: Total Neufs | C16: 237 | D16: 4111.3924 | E16: 974400 | F16: 13 | G16: 4118.0481 | H16: 53534.626 | I16: 11 | J16: 4111.6272 | K16: 45227.899 | L16: 22 | M16: 4111.6272 | N16: 90455.799 | O16: 28 | P16: 4109.6398 | Q16: 115069.91 | R16: 31 | S16: 4108.9346 | T16: 127376.97 | U16: 20 | V16: 4107.4536 | W16: 82149.072 | X16: 15 | Y16: 4102.3525 | Z16: 61535.288 | AA16: 19 | AB16: 4113.0916 | AC16: 78148.741 | AD16: 22 | AE16: 4111.6272 | AF16: 90455.799 | AG16: 22 | AH16: 4111.6272 | AI16: 90455.799 | AJ16: 18 | AK16: 4119.3561 | AL16: 74148.41 | AM16: 16 | AN16: 4115.1052 | AO16: 65841.683
A17: =+$C$4&B17 -> Véhicules neufs
A18: =+$C$4&B18 -> Véhicules neufsEx-Démos et courtoisies | B18: Ex-Démos et courtoisies | C18: 35 | D18: 750 | E18: 26250 | F18: 2 | G18: 750 | H18: 1500 | I18: 2 | J18: 750 | K18: 1500 | L18: 3 | M18: 750 | N18: 2250 | O18: 4 | P18: 750 | Q18: 3000 | R18: 5 | S18: 750 | T18: 3750 | U18: 3 | V18: 750 | W18: 2250 | X18: 2 | Y18: 750 | Z18: 1500 | AA18: 3 | AB18: 750 | AC18: 2250 | AD18: 3 | AE18: 750 | AF18: 2250 | AG18: 3 | AH18: 750 | AI18: 2250 | AJ18: 3 | AK18: 750 | AL18: 2250 | AM18: 2 | AN18: 750 | AO18: 1500
A19: =+$C$4&B19 -> Véhicules neufs
A20: =+$C$4&B20 -> Véhicules neufsFlottes | B20: Flottes | C20: 3 | D20: 0 | E20: 0 | F20: 0 | G20: 0 | H20: 0 | I20: 0 | J20: 0 | K20: 0 | L20: 1 | M20: 0 | N20: 0 | O20: 1 | P20: 0 | Q20: 0 | R20: 0 | S20: 0 | T20: 0 | U20: 0 | V20: 0 | W20: 0 | X20: 0 | Y20: 0 | Z20: 0 | AA20: 0 | AB20: 0 | AC20: 0 | AD20: 1 | AE20: 0 | AF20: 0 | AG20: 0 | AH20: 0 | AI20: 0 | AJ20: 0 | AK20: 0 | AL20: 0 | AM20: 0 | AN20: 0 | AO20: 0
A21: =+$C$4&B21 -> Véhicules neufs
A22: =+$C$4&B22 -> Véhicules neufsRachat bail | B22: Rachat bail | E22: 29970 | H22: 2006.507 | K22: 1744.6741 | N22: 2495.9768 | Q22: 3500.0986 | T22: 4034.9001 | W22: 3007.1267 | Z22: 2178.6402 | AC22: 3072.8225 | AF22: 1622.1855 | AI22: 2471.1767 | AL22: 1909.7847 | AO22: 1926.1072
A23: =+$C$4&B23 -> Véhicules neufs
A24: =+$C$4&B24 -> Véhicules neufsRev. Finances | B24: Rev. Finances | D24: 25 | E24: 6800 | G24: 25 | H24: 375 | J24: 25 | K24: 325 | M24: 25 | N24: 625 | P24: 25 | Q24: 800 | S24: 25 | T24: 900 | V24: 25 | W24: 575 | Y24: 25 | Z24: 425 | AB24: 25 | AC24: 550 | AE24: 25 | AF24: 625 | AH24: 25 | AI24: 625 | AK24: 25 | AL24: 525 | AN24: 25 | AO24: 450
A25: =+$C$4&B25 -> Véhicules neufsRev. Protections | B25: Rev. Protections | D25: 1150 | E25: 312800 | G25: 1150 | H25: 17250 | J25: 1150 | K25: 14950 | M25: 1150 | N25: 28750 | P25: 1150 | Q25: 36800 | S25: 1150 | T25: 41400 | V25: 1150 | W25: 26450 | Y25: 1150 | Z25: 19550 | AB25: 1150 | AC25: 25300 | AE25: 1150 | AF25: 28750 | AH25: 1150 | AI25: 28750 | AK25: 1150 | AL25: 24150 | AN25: 1150 | AO25: 20700
A26: =+$C$4&B26 -> Véhicules neufsRev. Autres | B26: Rev. Autres | D26: 480 | E26: 130560 | G26: 480 | H26: 7200 | J26: 480 | K26: 6240 | M26: 480 | N26: 12000 | P26: 480 | Q26: 15360 | S26: 480 | T26: 17280 | V26: 480 | W26: 11040 | Y26: 480 | Z26: 8160 | AB26: 480 | AC26: 10560 | AE26: 480 | AF26: 12000 | AH26: 480 | AI26: 12000 | AK26: 480 | AL26: 10080 | AN26: 480 | AO26: 8640
A27: =+$C$4&B27 -> Véhicules neufsTotal F&I | B27: Total F&I | C27: 272 | D27: 1655 | E27: 450160 | F27: 15 | G27: 1655 | H27: 24825 | I27: 13 | J27: 1655 | K27: 21515 | L27: 25 | M27: 1655 | N27: 41375 | O27: 32 | P27: 1655 | Q27: 52960 | R27: 36 | S27: 1655 | T27: 59580 | U27: 23 | V27: 1655 | W27: 38065 | X27: 17 | Y27: 1655 | Z27: 28135 | AA27: 22 | AB27: 1655 | AC27: 36410 | AD27: 25 | AE27: 1655 | AF27: 41375 | AG27: 25 | AH27: 1655 | AI27: 41375 | AJ27: 21 | AK27: 1655 | AL27: 34755 | AM27: 18 | AN27: 1655 | AO27: 29790
A28: =+$C$4&B28 -> Véhicules neufs
A29: =+$C$4&B29 -> Véhicules neufs
A30: =+$C$4&B30 -> Véhicules neufsTotal Dépt. Neufs | B30: Total Dépt. Neufs | C30: 275 | D30: 5384.6545 | E30: 1480780 | F30: 15 | G30: 5457.7422 | H30: 81866.133 | I30: 13 | J30: 5383.6595 | K30: 69987.573 | L30: 26 | M30: 5252.9529 | N30: 136576.78 | O30: 33 | P30: 5288.7883 | Q30: 174530.01 | R30: 36 | S30: 5409.4964 | T30: 194741.87 | U30: 23 | V30: 5455.2695 | W30: 125471.2 | X30: 17 | Y30: 5491.1134 | Z30: 93348.928 | AA30: 22 | AB30: 5449.162 | AC30: 119881.56 | AD30: 26 | AE30: 5219.3455 | AF30: 135702.98 | AG30: 25 | AH30: 5462.079 | AI30: 136551.98 | AJ30: 21 | AK30: 5383.9616 | AL30: 113063.19 | AM30: 18 | AN30: 5503.2106 | AO30: 99057.791
A31: =+$C$4&B31 -> Véhicules neufs
A32: =+$C$4&B32 -> Véhicules neufs
A33: =+$C$4&B33 -> Véhicules neufsDEPENSES | B33: DEPENSES
A34: =+$C$4&B34 -> Véhicules neufsComm. vendeurs | B34: Comm. vendeurs | C34: 0.29126568 | D34: 1071.5257 | E34: 291455 | F34: 0.31323602 | G34: 1149.2551 | H34: 17238.827 | I34: 0.31476231 | J34: 1131.3986 | K34: 14708.182 | L34: 0.28606608 | M34: 1060.7994 | N34: 26519.984 | O34: 0.2815412 | P34: 1038.7983 | Q34: 33241.545 | R34: 0.27942009 | S34: 1017.7642 | T34: 36639.51 | U34: 0.29112986 | V34: 1068.3083 | W34: 24571.09 | X34: 0.30589257 | Y34: 1134.2368 | Z34: 19282.026 | AA34: 0.2933806 | AB34: 1072.156 | AC34: 23587.431 | AD34: 0.28510663 | AE34: 1057.2415 | AF34: 26431.038 | AG34: 0.28879302 | AH34: 1070.9115 | AI34: 26772.788 | AJ34: 0.29015116 | AK34: 1055.5756 | AL34: 22167.087 | AM34: 0.30138082 | AN34: 1127.5273 | AO34: 20295.492
A35: =+$C$4&B35 -> Véhicules neufsComm. F&I | B35: Comm. F&I | C35: 0.275 | D35: 455.125 | E35: 123794 | F35: 0.275 | G35: 455.125 | H35: 6826.875 | I35: 0.275 | J35: 455.125 | K35: 5916.625 | L35: 0.275 | M35: 455.125 | N35: 11378.125 | O35: 0.275 | P35: 455.125 | Q35: 14564 | R35: 0.275 | S35: 455.125 | T35: 16384.5 | U35: 0.275 | V35: 455.125 | W35: 10467.875 | X35: 0.275 | Y35: 455.125 | Z35: 7737.125 | AA35: 0.275 | AB35: 455.125 | AC35: 10012.75 | AD35: 0.275 | AE35: 455.125 | AF35: 11378.125 | AG35: 0.275 | AH35: 455.125 | AI35: 11378.125 | AJ35: 0.275 | AK35: 455.125 | AL35: 9557.625 | AM35: 0.275 | AN35: 455.125 | AO35: 8192.25
A36: =+$C$4&B36 -> Véhicules neufsFrais de livraison | B36: Frais de livraison | D36: 130 | E36: 35360 | G36: 130 | H36: 1950 | J36: 130 | K36: 1690 | M36: 130 | N36: 3250 | P36: 130 | Q36: 4160 | S36: 130 | T36: 4680 | V36: 130 | W36: 2990 | Y36: 130 | Z36: 2210 | AB36: 130 | AC36: 2860 | AE36: 130 | AF36: 3250 | AH36: 130 | AI36: 3250 | AK36: 130 | AL36: 2730 | AN36: 130 | AO36: 2340
A37: =+$C$4&B37 -> Véhicules neufsService gratuit 1 | B37: Service gratuit 1 | D37: 37 | E37: 10064 | G37: 37 | H37: 555 | J37: 37 | K37: 481 | M37: 37 | N37: 925 | P37: 37 | Q37: 1184 | S37: 37 | T37: 1332 | V37: 37 | W37: 851 | Y37: 37 | Z37: 629 | AB37: 37 | AC37: 814 | AE37: 37 | AF37: 925 | AH37: 37 | AI37: 925 | AK37: 37 | AL37: 777 | AN37: 37 | AO37: 666
A38: =+$C$4&B38 -> Véhicules neufsEntretien stock | B38: Entretien stock | D38: 61.617647 | E38: 16760 | G38: 65 | H38: 975 | J38: 66.538462 | K38: 865 | M38: 61 | N38: 1525 | P38: 59.6875 | Q38: 1910 | S38: 59.166667 | T38: 2130 | V38: 61.521739 | W38: 1415 | Y38: 63.823529 | Z38: 1085 | AB38: 61.818182 | AC38: 1360 | AE38: 61 | AF38: 1525 | AH38: 61 | AI38: 1525 | AK38: 62.142857 | AL38: 1305 | AN38: 63.333333 | AO38: 1140
A39: =+$C$4&B39 -> Véhicules neufsPublicité 1 | B39: Publicité 1 | D39: 513.97059 | E39: 139800 | G39: 513.97059 | H39: 7709.5588 | J39: 513.97059 | K39: 6681.6176 | M39: 513.97059 | N39: 12849.265 | P39: 513.97059 | Q39: 16447.059 | S39: 513.97059 | T39: 18502.941 | V39: 513.97059 | W39: 11821.324 | Y39: 513.97059 | Z39: 8737.5 | AB39: 513.97059 | AC39: 11307.353 | AE39: 513.97059 | AF39: 12849.265 | AH39: 513.97059 | AI39: 12849.265 | AK39: 513.97059 | AL39: 10793.382 | AN39: 513.97059 | AO39: 9251.4706
A40: =+$C$4&B40 -> Véhicules neufsIntérêt de gros | B40: Intérêt de gros | D40: 1186.9396 | E40: 322847.56 | G40: 1702.2597 | H40: 25533.896 | J40: 1969.1431 | K40: 25598.861 | M40: 1230.2634 | N40: 30756.585 | P40: 974.98576 | Q40: 31199.544 | S40: 835.15872 | T40: 30065.714 | V40: 1107.6277 | W40: 25475.438 | Y40: 1525.2108 | Z40: 25928.583 | AB40: 1242.6971 | AC40: 27339.336 | AE40: 1069.1875 | AF40: 26729.688 | AH40: 1057.7885 | AI40: 26444.712 | AK40: 1149.0993 | AL40: 24131.086 | AN40: 1313.5622 | AO40: 23644.12
A41: =+$C$4&B41 -> Véhicules neufs[...] | B41: [...] | D41: 0 | E41: 0 | G41: 0 | J41: 0 | M41: 0 | P41: 0 | S41: 0 | V41: 0 | Y41: 0 | AB41: 0 | AE41: 0 | AH41: 0 | AK41: 0 | AN41: 0
...

Sheet Réel 2024
B1: ="Budget 2023 Mensuel"&" "&Parametres!$B$1 -> Budget 2023 Mensuel BMW Sherbrooke
B2: Mois | F2: =+IF(Parametres!$B$3=F$6,"X","") | G2: =+IF(Parametres!$B$3=F$6,"O","") | H2: =+IF(Parametres!$B$3=F$6,"U","") | I2: =+IF(Parametres!$B$3=I$6,"X","") | J2: =+IF(Parametres!$B$3=I$6,"O","") | K2: =+IF(Parametres!$B$3=I$6,"U","") | L2: =+IF(Parametres!$B$3=L$6,"X","") | M2: =+IF(Parametres!$B$3=L$6,"O","") | N2: =+IF(Parametres!$B$3=L$6,"U","") | O2: =+IF(Parametres!$B$3=O$6,"X","") -> X | P2: =+IF(Parametres!$B$3=O$6,"O","") -> O | Q2: =+IF(Parametres!$B$3=O$6,"U","") -> U | R2: =+IF(Parametres!$B$3=R$6,"X","") | S2: =+IF(Parametres!$B$3=R$6,"O","") | T2: =+IF(Parametres!$B$3=R$6,"U","") | U2: =+IF(Parametres!$B$3=U$6,"X","") | V2: =+IF(Parametres!$B$3=U$6,"O","") | W2: =+IF(Parametres!$B$3=U$6,"U","") | X2: =+IF(Parametres!$B$3=X$6,"X","") | Y2: =+IF(Parametres!$B$3=X$6,"O","") | Z2: =+IF(Parametres!$B$3=X$6,"U","") | AA2: =+IF(Parametres!$B$3=AA$6,"X","") | AB2: =+IF(Parametres!$B$3=AA$6,"O","") | AC2: =+IF(Parametres!$B$3=AA$6,"U","") | AD2: =+IF(Parametres!$B$3=AD$6,"X","") | AE2: =+IF(Parametres!$B$3=AD$6,"O","") | AF2: =+IF(Parametres!$B$3=AD$6,"U","") | AG2: =+IF(Parametres!$B$3=AG$6,"X","") | AH2: =+IF(Parametres!$B$3=AG$6,"O","") | AI2: =+IF(Parametres!$B$3=AG$6,"U","") | AJ2: =+IF(Parametres!$B$3=AJ$6,"X","") | AK2: =+IF(Parametres!$B$3=AJ$6,"O","") | AL2: =+IF(Parametres!$B$3=AJ$6,"U","") | AM2: =+IF(Parametres!$B$3=AM$6,"X","") | AN2: =+IF(Parametres!$B$3=AM$6,"O","") | AO2: =+IF(Parametres!$B$3=AM$6,"U","")
B3: YTD | F3: =+IF(VLOOKUP(F$6,Parametres!$K$3:$N$14,4,0)="X","X","") -> X | G3: =+IF(VLOOKUP(F$6,Parametres!$K$3:$N$14,4,0)="X","O","") -> O | H3: =+IF(VLOOKUP(F$6,Parametres!$K$3:$N$14,4,0)="X","U","") -> U | I3: =+IF(VLOOKUP(I$6,Parametres!$K$3:$N$14,4,0)="X","X","") -> X | J3: =+IF(VLOOKUP(I$6,Parametres!$K$3:$N$14,4,0)="X","O","") -> O | K3: =+IF(VLOOKUP(I$6,Parametres!$K$3:$N$14,4,0)="X","U","") -> U | L3: =+IF(VLOOKUP(L$6,Parametres!$K$3:$N$14,4,0)="X","X","") -> X | M3: =+IF(VLOOKUP(L$6,Parametres!$K$3:$N$14,4,0)="X","O","") -> O | N3: =+IF(VLOOKUP(L$6,Parametres!$K$3:$N$14,4,0)="X","U","") -> U | O3: =+IF(VLOOKUP(O$6,Parametres!$K$3:$N$14,4,0)="X","X","") -> X | P3: =+IF(VLOOKUP(O$6,Parametres!$K$3:$N$14,4,0)="X","O","") -> O | Q3: =+IF(VLOOKUP(O$6,Parametres!$K$3:$N$14,4,0)="X","U","") -> U | R3: =+IF(VLOOKUP(R$6,Parametres!$K$3:$N$14,4,0)="X","X","") | S3: =+IF(VLOOKUP(R$6,Parametres!$K$3:$N$14,4,0)="X","O","") | T3: =+IF(VLOOKUP(R$6,Parametres!$K$3:$N$14,4,0)="X","U","") | U3: =+IF(VLOOKUP(U$6,Parametres!$K$3:$N$14,4,0)="X","X","") | V3: =+IF(VLOOKUP(U$6,Parametres!$K$3:$N$14,4,0)="X","O","") | W3: =+IF(VLOOKUP(U$6,Parametres!$K$3:$N$14,4,0)="X","U","") | X3: =+IF(VLOOKUP(X$6,Parametres!$K$3:$N$14,4,0)="X","X","") | Y3: =+IF(VLOOKUP(X$6,Parametres!$K$3:$N$14,4,0)="X","O","") | Z3: =+IF(VLOOKUP(X$6,Parametres!$K$3:$N$14,4,0)="X","U","") | AA3: =+IF(VLOOKUP(AA$6,Parametres!$K$3:$N$14,4,0)="X","X","") | AB3: =+IF(VLOOKUP(AA$6,Parametres!$K$3:$N$14,4,0)="X","O","") | AC3: =+IF(VLOOKUP(AA$6,Parametres!$K$3:$N$14,4,0)="X","U","") | AD3: =+IF(VLOOKUP(AD$6,Parametres!$K$3:$N$14,4,0)="X","X","") | AE3: =+IF(VLOOKUP(AD$6,Parametres!$K$3:$N$14,4,0)="X","O","") | AF3: =+IF(VLOOKUP(AD$6,Parametres!$K$3:$N$14,4,0)="X","U","") | AG3: =+IF(VLOOKUP(AG$6,Parametres!$K$3:$N$14,4,0)="X","X","") | AH3: =+IF(VLOOKUP(AG$6,Parametres!$K$3:$N$14,4,0)="X","O","") | AI3: =+IF(VLOOKUP(AG$6,Parametres!$K$3:$N$14,4,0)="X","U","") | AJ3: =+IF(VLOOKUP(AJ$6,Parametres!$K$3:$N$14,4,0)="X","X","") | AK3: =+IF(VLOOKUP(AJ$6,Parametres!$K$3:$N$14,4,0)="X","O","") | AL3: =+IF(VLOOKUP(AJ$6,Parametres!$K$3:$N$14,4,0)="X","U","") | AM3: =+IF(VLOOKUP(AM$6,Parametres!$K$3:$N$14,4,0)="X","X","") | AN3: =+IF(VLOOKUP(AM$6,Parametres!$K$3:$N$14,4,0)="X","O","") | AO3: =+IF(VLOOKUP(AM$6,Parametres!$K$3:$N$14,4,0)="X","U","")
B4: Réel 2024 | C4: Véhicules neufs
B6: Mois | C6: 2024 | F6: Janvier | I6: Février | L6: Mars | O6: Avril | R6: Mai | U6: Juin | X6: Juillet | AA6: Août | AD6: Septembre | AG6: Octobre | AJ6: Novembre | AM6: Décembre
C7: UNITE | D7: $P/UNITE | E7: $PROFITS | F7: UNITE | G7: $P/UNITE | H7: $PROFITS | I7: UNITE | J7: $P/UNITE | K7: $PROFITS | L7: UNITE | M7: $P/UNITE | N7: $PROFITS | O7: UNITE | P7: $P/UNITE | Q7: $PROFITS | R7: UNITE | S7: $P/UNITE | T7: $PROFITS | U7: UNITE | V7: $P/UNITE | W7: $PROFITS | X7: UNITE | Y7: $P/UNITE | Z7: $PROFITS | AA7: UNITE | AB7: $P/UNITE | AC7: $PROFITS | AD7: UNITE | AE7: $P/UNITE | AF7: $PROFITS | AG7: UNITE | AH7: $P/UNITE | AI7: $PROFITS | AJ7: UNITE | AK7: $P/UNITE | AL7: $PROFITS | AM7: UNITE | AN7: $P/UNITE | AO7: $PROFITS
A8: =+$C$4&B8 -> Véhicules neufsVentes nettes | B8: Ventes nettes | E8: 25487207 | H8: 926822.67 | K8: 745667.64 | N8: 1972302.3 | Q8: 2814437.6 | T8: 3270847.4 | W8: 1710445.6 | Z8: 1425137.4 | AC8: 1468150.1 | AF8: 3148461.5 | AI8: 2092480.4 | AL8: 3424221 | AO8: 2488233.6
A9: =+$C$4&B9 -> Véhicules neufsAutos détail | B9: Autos détail | C9: 87 | D9: 5158.778 | E9: 448813.69 | F9: 2 | G9: 4853.565 | H9: 9707.13 | I9: 5 | J9: 4773.302 | K9: 23866.51 | L9: 4 | M9: 6596.215 | N9: 26384.86 | O9: 13 | P9: 5336.7323 | Q9: 69377.52 | R9: 12 | S9: 4900.445 | T9: 58805.34 | U9: 7 | V9: 4333.9529 | W9: 30337.67 | X9: 0 | Y9: 0 | Z9: -205.85 | AA9: 8 | AB9: 2390.5312 | AC9: 19124.25 | AD9: 5 | AE9: 5369.06 | AF9: 26845.3 | AG9: 10 | AH9: 5653.279 | AI9: 56532.79 | AJ9: 9 | AK9: 5377.2044 | AL9: 48394.84 | AM9: 12 | AN9: 6636.9442 | AO9: 79643.33
A10: =+$C$4&B10 -> Véhicules neufsCamions détail | B10: Camions détail | C10: 142 | D10: 4574.8696 | E10: 649631.49 | F10: 4 | G10: 6340.385 | H10: 25361.54 | I10: 1 | J10: 7866.05 | K10: 7866.05 | L10: 12 | M10: 4793.2275 | N10: 57518.73 | O10: 12 | P10: 4634.92 | Q10: 55619.04 | R10: 22 | S10: 4523.4468 | T10: 99515.83 | U10: 10 | V10: 4305.352 | W10: 43053.52 | X10: 13 | Y10: 4541.1208 | Z10: 59034.57 | AA10: 4 | AB10: 4085.98 | AC10: 16343.92 | AD10: 17 | AE10: 5159.5535 | AF10: 87712.41 | AG10: 13 | AH10: 4282.34 | AI10: 55670.42 | AJ10: 23 | AK10: 3739.0257 | AL10: 85997.59 | AM10: 11 | AN10: 5085.2609 | AO10: 55937.87
A11: =+$C$4&B11 -> Véhicules neufsSprinter | B11: Sprinter | C11: 0 | D11: 0 | E11: 0 | F11: 0 | G11: 0 | H11: 0 | I11: 0 | J11: 0 | K11: 0 | L11: 0 | M11: 0 | N11: 0 | O11: 0 | P11: 0 | Q11: 0 | R11: 0 | S11: 0 | T11: 0 | U11: 0 | V11: 0 | W11: 0 | X11: 0 | Y11: 0 | Z11: 0 | AA11: 0 | AB11: 0 | AC11: 0 | AD11: 0 | AE11: 0 | AF11: 0 | AG11: 0 | AH11: 0 | AI11: 0 | AJ11: 0 | AK11: 0 | AL11: 0 | AM11: 0 | AN11: 0 | AO11: 0
A12: =+$C$4&B12 -> Véhicules neufsMoto détail | B12: Moto détail | C12: 0 | D12: 0 | E12: 0 | F12: 0 | G12: 0 | H12: 0 | I12: 0 | J12: 0 | K12: 0 | L12: 0 | M12: 0 | N12: 0 | O12: 0 | P12: 0 | Q12: 0 | R12: 0 | S12: 0 | T12: 0 | U12: 0 | V12: 0 | W12: 0 | X12: 0 | Y12: 0 | Z12: 0 | AA12: 0 | AB12: 0 | AC12: 0 | AD12: 0 | AE12: 0 | AF12: 0 | AG12: 0 | AH12: 0 | AI12: 0 | AJ12: 0 | AK12: 0 | AL12: 0 | AM12: 0 | AN12: 0 | AO12: 0
A13: =+$C$4&B13 -> Véhicules neufs[...] | B13: [...] | C13: 0 | D13: 0 | E13: 0 | G13: 0 | J13: 0 | M13: 0 | P13: 0 | S13: 0 | V13: 0 | Y13: 0 | AB13: 0 | AE13: 0 | AH13: 0 | AK13: 0 | AN13: 0
A14: =+$C$4&B14 -> Véhicules neufs[...] | B14: [...] | C14: 0 | D14: 0 | E14: 0 | G14: 0 | J14: 0 | M14: 0 | P14: 0 | S14: 0 | V14: 0 | Y14: 0 | AB14: 0 | AE14: 0 | AH14: 0 | AK14: 0 | AN14: 0
A15: =+$C$4&B15 -> Véhicules neufs[...] | B15: [...] | C15: 0 | D15: 0 | E15: 0 | G15: 0 | J15: 0 | M15: 0 | P15: 0 | S15: 0 | V15: 0 | Y15: 0 | AB15: 0 | AE15: 0 | AH15: 0 | AK15: 0 | AN15: 0
A16: =+$C$4&B16 -> Véhicules neufsTotal Neufs | B16: Total Neufs | C16: 229 | D16: 4796.7038 | E16: 1098445.2 | F16: 6 | G16: 5844.7783 | H16: 35068.67 | I16: 6 | J16: 5288.76 | K16: 31732.56 | L16: 16 | M16: 5243.9744 | N16: 83903.59 | O16: 25 | P16: 4999.8624 | Q16: 124996.56 | R16: 34 | S16: 4656.505 | T16: 158321.17 | U16: 17 | V16: 4317.1288 | W16: 73391.19 | X16: 13 | Y16: 4525.2862 | Z16: 58828.72 | AA16: 12 | AB16: 2955.6808 | AC16: 35468.17 | AD16: 22 | AE16: 5207.1686 | AF16: 114557.71 | AG16: 23 | AH16: 4878.4004 | AI16: 112203.21 | AJ16: 32 | AK16: 4199.7634 | AL16: 134392.43 | AM16: 23 | AN16: 5894.8348 | AO16: 135581.2
A17: =+$C$4&B17 -> Véhicules neufs
A18: =+$C$4&B18 -> Véhicules neufsEx-Démos et courtoisies | B18: Ex-Démos et courtoisies | C18: 36 | D18: 1369.8803 | E18: 49315.69 | F18: 2 | G18: 2993.705 | H18: 5987.41 | I18: 3 | J18: 1500 | K18: 4500 | L18: 5 | M18: 3624.56 | N18: 18122.8 | O18: 5 | P18: 3098.878 | Q18: 15494.39 | R18: 5 | S18: 588.606 | T18: 2943.03 | U18: 1 | V18: 1250 | W18: 1250 | X18: 1 | Y18: 10720.5 | Z18: 10720.5 | AA18: 2 | AB18: 1513.885 | AC18: 3027.77 | AD18: 7 | AE18: 403.89429 | AF18: 2827.26 | AG18: 0 | AH18: 0 | AI18: 0 | AJ18: 3 | AK18: -5578.1033 | AL18: -16734.31 | AM18: 2 | AN18: 588.42 | AO18: 1176.84
A19: =+$C$4&B19 -> Véhicules neufs
A20: =+$C$4&B20 -> Véhicules neufsFlottes | B20: Flottes | C20: 5 | D20: 2686.786 | E20: 13433.93 | F20: 1 | G20: 0 | H20: 0 | I20: 0 | J20: 0 | K20: 0 | L20: 0 | M20: 0 | N20: 0 | O20: 0 | P20: 0 | Q20: 0 | R20: 0 | S20: 0 | T20: 0 | U20: 0 | V20: 0 | W20: 0 | X20: 0 | Y20: 0 | Z20: 0 | AA20: 1 | AB20: 12964.17 | AC20: 12964.17 | AD20: 0 | AE20: 0 | AF20: 0 | AG20: 1 | AH20: 416.18 | AI20: 416.18 | AJ20: 2 | AK20: 26.79 | AL20: 53.58 | AM20: 0 | AN20: 0 | AO20: 0
A21: =+$C$4&B21 -> Véhicules neufs
A22: =+$C$4&B22 -> Véhicules neufsRachat bail | B22: Rachat bail | E22: 45746.46 | H22: 3995.96 | K22: 967.39 | N22: 2976.42 | Q22: 3495.39 | T22: 8901.11 | W22: 5993.9 | Z22: 5547.05 | AC22: 5620.95 | AF22: 2371.4 | AI22: 3371.01 | AL22: 999 | AO22: 1506.88
A23: =+$C$4&B23 -> Véhicules neufs
A24: =+$C$4&B24 -> Véhicules neufsRev. Finances | B24: Rev. Finances | D24: 11.362226 | E24: 3010.99 | G24: 0 | H24: 0 | J24: 0 | K24: 0 | M24: 135.6519 | N24: 2848.69 | P24: 0 | Q24: 0 | S24: -31.520769 | T24: -1229.31 | V24: 0 | W24: 0 | Y24: 0 | Z24: 0 | AB24: 0 | AC24: 0 | AE24: 5.1724138 | AF24: 150 | AH24: 0 | AI24: 0 | AK24: 0 | AL24: 0 | AN24: 49.6644 | AO24: 1241.61
A25: =+$C$4&B25 -> Véhicules neufsRev. Protections | B25: Rev. Protections | D25: 1161.4258 | E25: 307777.85 | G25: 1221.5 | H25: 9772 | J25: 1291.0111 | K25: 11619.1 | M25: 1102.7619 | N25: 23158 | P25: 1293.3413 | Q25: 38800.24 | S25: 1158.741 | T25: 45190.9 | V25: 1118.0944 | W25: 20125.7 | Y25: 1086 | Z25: 15204 | AB25: 1140.7714 | AC25: 15970.8 | AE25: 1040.6897 | AF25: 30180 | AH25: 854.43913 | AI25: 19652.1 | AK25: 1455.2969 | AL25: 50935.39 | AN25: 1086.7848 | AO25: 27169.62
A26: =+$C$4&B26 -> Véhicules neufsRev. Autres | B26: Rev. Autres | D26: 470.32717 | E26: 124636.7 | G26: 536.58625 | H26: 4292.69 | J26: 408.33333 | K26: 3675 | M26: 532.99524 | N26: 11192.9 | P26: 448.63467 | Q26: 13459.04 | S26: 440.92179 | T26: 17195.95 | V26: 536.78333 | W26: 9662.1 | Y26: 442.14286 | Z26: 6190 | AB26: 419.92857 | AC26: 5879 | AE26: 564.99621 | AF26: 16384.89 | AH26: 416.13652 | AI26: 9571.14 | AK26: 446.45571 | AL26: 15625.95 | AN26: 460.3216 | AO26: 11508.04
A27: =+$C$4&B27 -> Véhicules neufsTotal F&I | B27: Total F&I | C27: 265 | D27: 1643.1152 | E27: 435425.54 | F27: 8 | G27: 1758.0862 | H27: 14064.69 | I27: 9 | J27: 1699.3444 | K27: 15294.1 | L27: 21 | M27: 1771.409 | N27: 37199.59 | O27: 30 | P27: 1741.976 | Q27: 52259.28 | R27: 39 | S27: 1568.1421 | T27: 61157.54 | U27: 18 | V27: 1654.8778 | W27: 29787.8 | X27: 14 | Y27: 1528.1429 | Z27: 21394 | AA27: 14 | AB27: 1560.7 | AC27: 21849.8 | AD27: 29 | AE27: 1610.8583 | AF27: 46714.89 | AG27: 23 | AH27: 1270.5757 | AI27: 29223.24 | AJ27: 35 | AK27: 1901.7526 | AL27: 66561.34 | AM27: 25 | AN27: 1596.7708 | AO27: 39919.27
A28: =+$C$4&B28 -> Véhicules neufs
A29: =+$C$4&B29 -> Véhicules neufs
A30: =+$C$4&B30 -> Véhicules neufsTotal Dépt. Neufs | B30: Total Dépt. Neufs | C30: 270 | D30: 6082.84 | E30: 1642366.8 | F30: 9 | G30: 6568.5256 | H30: 59116.73 | I30: 9 | J30: 5832.6722 | K30: 52494.05 | L30: 21 | M30: 6771.5429 | N30: 142202.4 | O30: 30 | P30: 6541.5207 | Q30: 196245.62 | R30: 39 | S30: 5931.3551 | T30: 231322.85 | U30: 18 | V30: 6134.605 | W30: 110422.89 | X30: 14 | Y30: 6892.1621 | Z30: 96490.27 | AA30: 15 | AB30: 5262.0573 | AC30: 78930.86 | AD30: 29 | AE30: 5740.3883 | AF30: 166471.26 | AG30: 24 | AH30: 6050.5683 | AI30: 145213.64 | AJ30: 37 | AK30: 5007.3524 | AL30: 185272.04 | AM30: 25 | AN30: 7127.3676 | AO30: 178184.19
A31: =+$C$4&B31 -> Véhicules neufs
A32: =+$C$4&B32 -> Véhicules neufs
A33: =+$C$4&B33 -> Véhicules neufsDEPENSES | B33: DEPENSES
A34: =+$C$4&B34 -> Véhicules neufsComm. vendeurs | B34: Comm. vendeurs | C34: 0.29664052 | D34: 1284.8014 | E34: 340472.38 | F34: 0.33530405 | G34: 1720.7838 | H34: 13766.27 | I34: 0.28977555 | J34: 1166.59 | K34: 10499.31 | L34: 0.26922113 | M34: 1307.9838 | N34: 27467.66 | O34: 0.26502027 | P34: 1241.0983 | Q34: 37232.95 | R34: 0.3222737 | S34: 1332.5951 | T34: 51971.21 | U34: 0.26405313 | V34: 1094.9578 | W34: 19709.24 | X34: 0.26899798 | Y34: 1336.3286 | Z34: 18708.6 | AA34: 0.38257541 | AB34: 1051.9714 | AC34: 14727.6 | AD34: 0.28573266 | AE34: 1156.5766 | AF34: 33540.72 | AG34: 0.27481745 | AH34: 1340.6696 | AI34: 30835.4 | AJ34: 0.39274263 | AK34: 1320.2674 | AL34: 46209.36 | AM34: 0.26180589 | AN34: 1432.1624 | AO34: 35804.06
A35: =+$C$4&B35 -> Véhicules neufsComm. F&I | B35: Comm. F&I | C35: 0.3769204 | D35: 619.32366 | E35: 164120.77 | F35: 0.42523724 | G35: 747.60375 | H35: 5980.83 | I35: 0.38730752 | J35: 658.16889 | K35: 5923.52 | L35: 0.42129228 | M35: 746.28095 | N35: 15671.9 | O35: 0.4073422 | P35: 709.58033 | Q35: 21287.41 | R35: 0.37678559 | S35: 590.85333 | T35: 23043.28 | U35: 0.35239091 | V35: 583.16389 | W35: 10496.95 | X35: 0.3458694 | Y35: 528.53786 | Z35: 7399.53 | AA35: 0.35585955 | AB35: 555.39 | AC35: 7775.46 | AD35: 0.36937388 | AE35: 595.00897 | AF35: 17255.26 | AG35: 0.27134705 | AH35: 344.76696 | AI35: 7929.64 | AJ35: 0.42129741 | AK35: 801.20343 | AL35: 28042.12 | AM35: 0.33354493 | AN35: 532.5948 | AO35: 13314.87
A36: =+$C$4&B36 -> Véhicules neufsFrais de livraison | B36: Frais de livraison | D36: 120.09117 | E36: 31824.16 | G36: 113.19 | H36: 905.52 | J36: 238.40556 | K36: 2145.65 | M36: 117.48429 | N36: 2467.17 | P36: 73.194667 | Q36: 2195.84 | S36: 82.459231 | T36: 3215.91 | V36: 105.80833 | W36: 1904.55 | Y36: 228.45786 | Z36: 3198.41 | AB36: 306.69786 | AC36: 4293.77 | AE36: 128.05552 | AF36: 3713.61 | AH36: 125.91261 | AI36: 2895.99 | AK36: 67.887429 | AL36: 2376.06 | AN36: 100.4672 | AO36: 2511.68
A37: =+$C$4&B37 -> Véhicules neufsService gratuit 1 | B37: Service gratuit 1 | D37: 38.97834 | E37: 10329.26 | G37: 142.45125 | H37: 1139.61 | J37: 57.473333 | K37: 517.26 | M37: 9.5395238 | N37: 200.33 | P37: 26.899 | Q37: 806.97 | S37: 29.536923 | T37: 1151.94 | V37: 18.017778 | W37: 324.32 | Y37: 51.135714 | Z37: 715.9 | AB37: -3.7521429 | AC37: -52.53 | AE37: 73.190345 | AF37: 2122.52 | AH37: 30.172174 | AI37: 693.96 | AK37: 50.454571 | AL37: 1765.91 | AN37: 37.7228 | AO37: 943.07
A38: =+$C$4&B38 -> Véhicules neufsEntretien stock | B38: Entretien stock | D38: 65.46034 | E38: 17346.99 | G38: 120.0625 | H38: 960.5 | J38: 164.54444 | K38: 1480.9 | M38: 30.904762 | N38: 649 | P38: 62.396 | Q38: 1871.88 | S38: 25.282051 | T38: 986 | V38: 50.046111 | W38: 900.83 | Y38: 53.571429 | Z38: 750 | AB38: 115.575 | AC38: 1618.05 | AE38: 60.215862 | AF38: 1746.26 | AH38: 79.394348 | AI38: 1826.07 | AK38: 70.689429 | AL38: 2474.13 | AN38: 83.3348 | AO38: 2083.37
A39: =+$C$4&B39 -> Véhicules neufsPublicité 1 | B39: Publicité 1 | D39: 632.89355 | E39: 167716.79 | G39: 495.99125 | H39: 3967.93 | J39: 981.97778 | K39: 8837.8 | M39: 675.90762 | N39: 14194.06 | P39: 512.11267 | Q39: 15363.38 | S39: 373.90333 | T39: 14582.23 | V39: 750.24333 | W39: 13504.38 | Y39: 759.74143 | Z39: 10636.38 | AB39: 841.815 | AC39: 11785.41 | AE39: 712.53414 | AF39: 20663.49 | AH39: 956.57609 | AI39: 22001.25 | AK39: 338.084 | AL39: 11832.94 | AN39: 813.9016 | AO39: 20347.54
A40: =+$C$4&B40 -> Véhicules neufsIntérêt de gros | B40: Intérêt de gros | D40: 1381.9589 | E40: 366219.1 | G40: 3359.8812 | H40: 26879.05 | J40: 3226.1567 | K40: 29035.41 | M40: 1752.6862 | N40: 36806.41 | P40: 1210.5003 | Q40: 36315.01 | S40: 899.60974 | T40: 35084.78 | V40: 1767.2572 | W40: 31810.63 | Y40: 2453.1979 | Z40: 34344.77 | AB40: 2515.3971 | AC40: 35215.56 | AE40: 721.52345 | AF40: 20924.18 | AH40: 801.96174 | AI40: 18445.12 | AK40: 986.472 | AL40: 34526.52 | AN40: 1073.2664 | AO40: 26831.66
A41: =+$C$4&B41 -> Véhicules neufs[...] | B41: [...] | D41: 0 | E41: 0 | G41: 0 | J41: 0 | M41: 0 | P41: 0 | S41: 0 | V41: 0 | Y41: 0 | AB41: 0 | AE41: 0 | AH41: 0 | AK41: 0 | AN41: 0
...

Sheet Capex
A1: CONCESSION
A2: Forecast Immobilisation 2025 | H2: 1 | I2: 2 | J2: 3 | K2: 4 | L2: 5 | M2: 6 | N2: 7 | O2: 8 | P2: 9 | Q2: 10 | R2: 11 | S2: 12
H3: =+IF(VLOOKUP(H2,Parametres!$L$3:$N$14,3,0)="X","REEL","FORECAST") -> REEL | I3: =+IF(VLOOKUP(I2,Parametres!$L$3:$N$14,3,0)="X","REEL","FORECAST") -> REEL | J3: =+IF(VLOOKUP(J2,Parametres!$L$3:$N$14,3,0)="X","REEL","FORECAST") -> REEL | K3: =+IF(VLOOKUP(K2,Parametres!$L$3:$N$14,3,0)="X","REEL","FORECAST") -> REEL | L3: =+IF(VLOOKUP(L2,Parametres!$L$3:$N$14,3,0)="X","REEL","FORECAST") -> FORECAST | M3: =+IF(VLOOKUP(M2,Parametres!$L$3:$N$14,3,0)="X","REEL","FORECAST") -> FORECAST | N3: =+IF(VLOOKUP(N2,Parametres!$L$3:$N$14,3,0)="X","REEL","FORECAST") -> FORECAST | O3: =+IF(VLOOKUP(O2,Parametres!$L$3:$N$14,3,0)="X","REEL","FORECAST") -> FORECAST | ... S3: =+IF(VLOOKUP(S2,Parametres!$L$3:$N$14,3,0)="X","REEL","FORECAST") -> FORECAST
A4: Concession | B4: Budgété / Non budgété | C4: Projet | D4: Catégorie Immo | E4: Total forecast | F4: Budget Annuel | G4: Écart vs budget | H4: January | I4: February | J4: March | K4: April | L4: May | M4: June | N4: July | O4: August | P4: September | Q4: October | R4: November | S4: December | T4: Raison / Description
C5: Total | E5: =+SUM(E6:E40) -> 130039.14 | F5: =+SUM(F6:F40) -> 233000 | G5: =+SUM(G6:G40) -> -102960.86 | H5: =+SUM(H6:H40) -> 120701.21 | I5: =+SUM(I6:I40) -> 4893.17 | J5: =+SUM(J6:J40) -> 3886.16 | K5: =+SUM(K6:K40) -> 558.6 | L5: =+SUM(L6:L40) -> 0 | ... S5: =+SUM(S6:S40) -> 0 | X5: Terrain
A6: =+Parametres!$B$1 -> BMW Sherbrooke | B6: oui | C6: Outils obligatoire | E6: =+SUM(H6:S6) -> 3155.1 | F6: 10000 | G6: =+E6-F6 -> -6844.9 | I6: 1139.34 | J6: 1457.16 | K6: 558.6 | X6: Bâtisse
A7: =+Parametres!$B$1 -> BMW Sherbrooke | B7: oui | C7: Pilon enseigne | E7: =+SUM(H7:S7) -> 0 | F7: 25000 | G7: =+E7-F7 -> -25000 | X7: Améliorations Locatives
A8: =+Parametres!$B$1 -> BMW Sherbrooke | B8: oui | C8: Mise à niveau entreposage | E8: =+SUM(H8:S8) -> 3958.9 | F8: 20000 | G8: =+E8-F8 -> -16041.1 | H8: 1000 | I8: 1672.9 | J8: 1286 | X8: Améliorations Locatives Permanentes
A9: =+Parametres!$B$1 -> BMW Sherbrooke | B9: oui | C9: Borne électrique | E9: =+SUM(H9:S9) -> 109701.21 | F9: 150000 | G9: =+E9-F9 -> -40298.79 | H9: 109701.21 | X9: Équipements Service
A10: =+Parametres!$B$1 -> BMW Sherbrooke | B10: oui | C10: Lift | E10: =+SUM(H10:S10) -> 0 | F10: 10000 | G10: =+E10-F10 -> -10000 | X10: Mobilier
A11: =+Parametres!$B$1 -> BMW Sherbrooke | B11: oui | C11: Machine AC | E11: =+SUM(H11:S11) -> 10000 | F11: 10000 | G11: =+E11-F11 -> 0 | H11: 10000 | X11: Équipements Informatique
A12: =+Parametres!$B$1 -> BMW Sherbrooke | B12: oui | C12: Ordinateur | E12: =+SUM(H12:S12) -> 2496.5 | F12: 6000 | G12: =+E12-F12 -> -3503.5 | I12: 1353.5 | J12: 1143 | X12: Équipements Téléphonique
A13: =+Parametres!$B$1 -> BMW Sherbrooke | B13: oui | C13: 1 chargeur baterie | E13: =+SUM(H13:S13) -> 0 | F13: 2000 | G13: =+E13-F13 -> -2000 | X13: Enseigne
A14: =+Parametres!$B$1 -> BMW Sherbrooke | C14: Equipement esthétique | E14: =+SUM(H14:S14) -> 727.43 | G14: =+E14-F14 -> 727.43 | I14: 727.43
A15: =+Parametres!$B$1 -> BMW Sherbrooke | E15: =+SUM(H15:S15) -> 0 | G15: =+E15-F15 -> 0
A16: =+Parametres!$B$1 -> BMW Sherbrooke | E16: =+SUM(H16:S16) -> 0 | G16: =+E16-F16 -> 0
A17: =+Parametres!$B$1 -> BMW Sherbrooke | E17: =+SUM(H17:S17) -> 0 | G17: =+E17-F17 -> 0
A18: =+Parametres!$B$1 -> BMW Sherbrooke | E18: =+SUM(H18:S18) -> 0 | G18: =+E18-F18 -> 0
A19: =+Parametres!$B$1 -> BMW Sherbrooke | E19: =+SUM(H19:S19) -> 0 | G19: =+E19-F19 -> 0
A20: =+Parametres!$B$1 -> BMW Sherbrooke | E20: =+SUM(H20:S20) -> 0 | G20: =+E20-F20 -> 0
A21: =+Parametres!$B$1 -> BMW Sherbrooke | E21: =+SUM(H21:S21) -> 0 | G21: =+E21-F21 -> 0
A22: =+Parametres!$B$1 -> BMW Sherbrooke | E22: =+SUM(H22:S22) -> 0 | G22: =+E22-F22 -> 0
A23: =+Parametres!$B$1 -> BMW Sherbrooke | E23: =+SUM(H23:S23) -> 0 | G23: =+E23-F23 -> 0
A24: =+Parametres!$B$1 -> BMW Sherbrooke | E24: =+SUM(H24:S24) -> 0 | G24: =+E24-F24 -> 0
A25: =+Parametres!$B$1 -> BMW Sherbrooke | E25: =+SUM(H25:S25) -> 0 | G25: =+E25-F25 -> 0
A26: =+Parametres!$B$1 -> BMW Sherbrooke | E26: =+SUM(H26:S26) -> 0 | G26: =+E26-F26 -> 0
... A35: =+Parametres!$B$1 -> BMW Sherbrooke | E35: =+SUM(H35:S35) -> 0 | G35: =+E35-F35 -> 0
A36: =+Parametres!$B$1 -> BMW Sherbrooke | E36: =+SUM(H36:S36) -> 0 | G36: =+E36-F36 -> 0 | X36: oui
A37: =+Parametres!$B$1 -> BMW Sherbrooke | E37: =+SUM(H37:S37) -> 0 | G37: =+E37-F37 -> 0 | X37: non
A38: =+Parametres!$B$1 -> BMW Sherbrooke | E38: =+SUM(H38:S38) -> 0 | G38: =+E38-F38 -> 0
A39: =+Parametres!$B$1 -> BMW Sherbrooke | E39: =+SUM(H39:S39) -> 0 | G39: =+E39-F39 -> 0
A40: =+Parametres!$B$1 -> BMW Sherbrooke | E40: =+SUM(H40:S40) -> 0 | G40: =+E40-F40 -> 0
E48: 23

Sheet Inventaire_Neuf
A1: #Contrôle | B1: Année | C1: Marque | D1: Modèle | E1: $ Inventaire | F1: $ Financé | G1: NIV | H1: Jours en stock | L1: $ Inventaire | M1: $ Financé
A2: 23019 | B2: 2023 | C2: BMW | D2: 430 | E2: 65121.87 | F2: -60905.25 | G2: WBA73AP05PCL27730 | H2: 478 | K2: CTRL | L2: =+SUM(E2:E10000) -> 3938633.3 | M2: =+SUM(F2:F10000) -> -3910068
A3: 23020 | B3: 2023 | C3: BMW | D3: 430 | E3: 63963.67 | G3: WBA73AP06PCL26036 | H3: 465 | L3: =+COUNT(E2:E10000) -> 45
A4: 23084 | B4: 2023 | C4: BMW | D4: 530xe | E4: 75509.5 | G4: WBA33AG06PCL42221 | H4: 411
A5: 23218 | B5: 2023 | C5: BMW SAV | D5: X3 | E5: 84833.61 | F5: -88452 | G5: 5UX83DP04P9T17873 | H5: 146
A6: 23221 | B6: 2023 | C6: BMW | D6: SERIE 2 | E6: 66617.36 | F6: -69326.25 | G6: 3MW53CM06P8D70441 | H6: 151
A7: 23228 | B7: 2023 | C7: BMW SAV | D7: X3 | E7: 73335.37 | F7: -69809.25 | G7: 5UX53DP06P9T28635 | H7: 143
A8: 23240 | B8: 2023 | C8: BMW SAV | D8: X1 | E8: 50471.49 | F8: -50473.5 | G8: WBX73EF02P5X85602 | H8: 67
A9: 23241 | B9: 2023 | C9: BMW SAV | D9: X1 | E9: 50262.11 | F9: -52143 | G9: WBX73EF00P5X86053 | H9: 58
A10: 24019 | B10: 2024 | C10: BMW SAV | D10: X5 | E10: 95266.49 | F10: -95303.25 | G10: 5UX23EU05R9T15522 | H10: 158
A11: 24023 | B11: 2024 | C11: BMW SAV | D11: X7 | E11: 126612.36 | F11: -131675.25 | G11: 5UX23EM04R9T23238 | H11: 149
A12: 24024 | B12: 2024 | C12: BMWI | D12: IX40 | E12: 97633.14 | F12: -97203.75 | G12: WB513CF03RCN76497 | H12: 152
A13: 24032 | B13: 2024 | C13: BMW SAV | D13: X6 | E13: 103328.55 | F13: -107651.25 | G13: 5UX33EX02R9T31595 | H13: 144
A14: 24034 | B14: 2024 | C14: BMW | D14: SERIE 4 | E14: 66533.61 | F14: -69237 | G14: WBA73AP07RCN92250 | H14: 144
A15: 24038 | B15: 2024 | C15: BMWI | D15: I7 | E15: 159476.47 | F15: -173664.75 | G15: WBY53EJ01RCN94634 | H15: 142
A16: 24051 | B16: 2024 | C16: BMW | D16: SERIE 3 | E16: 62907.21 | F16: -60149.52 | G16: 3MW89FF00R8D80878 | H16: 117
... A46: 24130 | B46: 2024 | C46: BMW SAV | D46: X3 | E46: 65370 | F46: -68638.5 | G46: 5UX53DP06R9U99484 | H46: 9

Sheet Inventaire_Used
A1: #Contrôle | B1: Année | C1: Marque | D1: Description | E1: Amount | F1: Financé | G1: NIV | H1: Jours en stock | L1: $ Inventaire | M1: $ Financé
A2: P0512 | B2: 2004 | C2: CHEVROLET TRUCK | D2: SILVERADO 2500 | E2: 3856.45 | G2: 1GCGK23U14F218132 | H2: 1482 | K2: CTRL | L2: =+SUM(E2:E9999) -> 1972155.4 | M2: =+SUM(F2:F9999) -> -1357394.6
A3: P2173 | B3: 2022 | C3: BMW | D3: 540i | E3: 75917.21 | F3: -50220 | G3: WBA73BJ07NWX54871 | H3: 490 | L3: =+COUNT(E2:E10000) -> 50
A4: P2259 | B4: 2021 | C4: BMW SAV | D4: X5 | E4: 75668.81 | F4: -55025 | G4: 5UXTA6C07M9G89398 | H4: 306
A5: P2282 | B5: 2019 | C5: BMW | D5: Z4 | E5: 61477.55 | F5: -55037.5 | G5: WBAHF3C57KWW21386 | H5: 235
A6: P2321 | B6: 2021 | C6: JEEP | D6: GLADIATOR 4X4 | E6: 57247.58 | F6: -48210.15 | G6: 1C6HJTAG8ML543623 | H6: 144
A7: P2327 | B7: 2023 | C7: BMW SAV | D7: X1 | E7: 51697.81 | F7: -49599.39 | G7: WBX73EF03P5W40276 | H7: 137
A8: 23231A | B8: 2020 | C8: MINI | D8: COUNTRYMAN | E8: 35295.85 | F8: -20589.76 | G8: WMZYZ9C04L3L18702 | H8: 125
A9: P2334 | B9: 2019 | C9: BMW | D9: 330i | E9: 31287.41 | F9: -23537.41 | G9: WBA5R7C54KFH22955 | H9: 111
A10: 23193A | B10: 2022 | C10: VOLVO | D10: XC60 | E10: 58424.95 | F10: -80500 | G10: LYV062RL8NB979235 | H10: 108
A11: P2335 | B11: 2020 | C11: BMW SAV | D11: X3 | E11: 30904.85 | F11: -21000 | G11: 5UXTY5C03L9D44647 | H11: 103
A12: 24082A | B12: 2023 | C12: MAZDA | D12: MX-5 | E12: 34707.45 | F12: -32060.23 | G12: JM1NDAD7XP0552574 | H12: 73
A13: 23225A | B13: 2023 | C13: BMW | D13: 330i | E13: 54482.17 | F13: -37837.25 | G13: WBA83FF0XPFN75280 | H13: 72
A14: P2342A | B14: 2023 | C14: BMW | D14: 530e | E14: 65103.95 | F14: -45150 | G14: WBA33AG00PCL72878 | H14: 72
A15: P2343 | B15: 2023 | C15: ACURA | D15: Integra | E15: 39059.95 | F15: -35100 | G15: 19UDE4G72PA800656 | H15: 67
... A28: P2356 | B28: 2021 | C28: ACURA | D28: TLX | E28: 39793.95 | F28: -35550 | G28: 19UUB6F51MA801958 | H28: 38
A29: 24098A | B29: 2015 | C29: MINI | D29: 5 DOOR | E29: 8000 | G29: WMWXS5C59FT837198 | H29: 38
A30: 23116B | B30: 2021 | C30: JEEP | D30: Wrangler Unlim | E30: 43899.95 | F30: -30450 | G30: 1C4HJXEN3MW680010 | H30: 37
A31: 24078A | B31: 2023 | C31: VOLKSWAGEN | D31: ID.4 | E31: 47899.95 | F31: -34300 | G31: 1V2JNPE8XPC021183 | H31: 31
A32: 23243A | B32: 2020 | C32: BMW | D32: 2 SERIES | E32: 29024.85 | F32: -19599.51 | G32: WBA73AK0XL7G01503 | H32: 26
A33: P2361 | B33: 2014 | C33: BMW | D33: 320i | E33: 11164.86 | G33: WBA3C3C57EK200069 | H33: 22
A34: P2362 | B34: 2023 | C34: BMW | D34: M240i xDrive | E34: 53250.2 | F34: -52796.25 | G34: 3MW53CM03P8C99750 | H34: 20
A35: P2363 | B35: 2023 | C35: BMW | D35: 230i | E35: 42103.5 | F35: -41658.65 | G35: 3MW33CM08P8C93109 | H35: 18
A36: P2364 | B36: 2017 | C36: BMW SAV | D36: X4 | E36: 27407.01 | F36: -24300 | G36: 5UXXW3C37H0T79741 | H36: 17
A37: 24040A | B37: 2023 | C37: BMW SAV | D37: X4 | E37: 58745 | F37: -45726.94 | G37: 5UX33DT01P9N56202 | H37: 13
A38: P2367 | B38: 2019 | C38: NISSAN | D38: Micra | E38: 11000 | F38: -9900 | G38: 3N1CK3CP5KL236170 | H38: 10
A39: 23244A | B39: 2019 | C39: BMW SAV | D39: X2 | E39: 26995 | F39: -16020.18 | G39: WBXYJ5C54K5N01549 | H39: 10
A40: 24103A | B40: 2021 | C40: BMW SAV | D40: X3 | E40: 42500 | F40: -30072.18 | G40: 5UXTS1C06M9H64396 | H40: 10
A41: P2223A | B41: 2023 | C41: BMW | D41: I4 | E41: 51776.06 | F41: -29211.39 | G41: WBY43AW09PFP45888 | H41: 10
A42: P2366 | B42: 2012 | C42: BMW | D42: M3 | E42: 37500 | G42: WBSKG9C53CE798848 | H42: 10
A43: P2365 | B43: 2021 | C43: DODGE TRUCK | D43: RAM 1500 Class | E43: 32547.15 | F43: -32547.15 | G43: 3C6RR7KG7MG709002 | H43: 9
A44: 23227A | B44: 2017 | C44: HONDA | D44: CIVIC HATCHBAC | E44: 14000 | G44: SHHFK7H26HU304092 | H44: 9
A45: 24097A | B45: 2018 | C45: AUDI | D45: A5 Sportback | E45: 18500 | G45: WAUANCF51JA004190 | H45: 3
A46: 24126A | B46: 2017 | C46: BMW | D46: 2 SERIES | E46: 28000 | G46: WBA2L3C32HV667851 | H46: 3
A47: 24091B | B47: 2013 | C47: VOLKSWAGEN | D47: JETTA | E47: 1500 | G47: 3VW1K7AJ9DM416983 | H47: 2
A48: 24125B | B48: 2017 | C48: BMW | D48: 650i | E48: 37000 | G48: WBA6F7C50HD930698 | H48: 2
A49: 23122A | B49: 2022 | C49: BMW | D49: 2 SERIES | E49: 37500 | G49: WBA13AL03N7K75967 | H49: 2
A50: 24125A | B50: 2021 | C50: BMW SAV | D50: X5 | E50: 60000 | G50: 5UXJU4C08M9E22693 | H50: 2
A51: 24104B | B51: 2019 | C51: BMW SAV | D51: X2 | E51: 31000 | G51: WBXYN1C56K5N23209 | H51: 0

Sheet Démo
B1: Suivi de Démo
B2: # Stock | C2: NIV | D2: Année | E2: Marque | F2: Modèle | G2: $ Valeur | H2: Nom | I2: Prénom | J2: Titre / Fonction
H4: Rosa | I4: Yvon | J4: Conseiller aux ventes
H5: Beaudoin | I5: Sébastien | J5: VPDG
E48: 23

Sheet Wholesale
C1: ="Analyse Wholesale "&Parametres!B1 -> Analyse Wholesale BMW Sherbrooke
D2: $ | F2: X | G2: U | L2: $ | N2: X | O2: U
E4: =CONCATENATE("Pièces Wholesale ",Parametres!B3," ",Parametres!B4) -> Pièces Wholesale Avril 2025 | J4: =CONCATENATE("Pièces Wholesale AAD ",Parametres!B4) -> Pièces Wholesale AAD 2025
E5: Réel | F5: Budget | G5: ▲ $ | H5: ▲ % | J5: Réel | K5: Budget | L5: ▲ $ | M5: ▲ %
C6: NB de livraisons | E6: =SUMIF(A37:A48,"X",E37:E48) -> 37 | F6: =SUMIF(A37:A48,"X",F37:F48) -> 22 | G6: =E6-F6 -> 15 | H6: =G6/F6 -> 0.68181818 | J6: =SUMIF($B$37:$B$48,"X",$E$37:$E$48) -> 115 | K6: =SUMIF($B$37:$B$48,"X",$F$37:$F$48) -> 88 | L6: =J6-K6 -> 27 | M6: =L6/K6 -> 0.30681818
A7: =B7&C7 -> piècesVentes de Gros | B7: pièces | C7: Ventes de Gros | E7: =-SUMIFS(BV_Data_An_Cour!$O:$O,BV_Data_An_Cour!$X:$X,"Oui",BV_Data_An_Cour!$U:$U,$B7,BV_Data_An_Cour!$V:$V,$C7) -> 72740.67 | F7: =+INDEX('Budget original'!$A$2:$AO$501,MATCH($A7,'Budget original'!$A$2:$A$501,0),MATCH(F$2,'Budget original'!$A$2:$AO$2,0)) -> 38846.442 | G7: =E7-F7 -> 33894.228 | H7: =G7/F7 -> 0.8725182 | J7: =-SUMIFS(BV_Data_An_Cour!$P:$P,BV_Data_An_Cour!$X:$X,"Oui",BV_Data_An_Cour!$U:$U,$B7,BV_Data_An_Cour!$V:$V,$C7) -> 229043.23 | K7: {=+SUMPRODUCT(('Budget original'!$A$8:$A$501=$A7)*('Budget original'!$C$3:$AO$3=N$2),'Budget original'!$C$8:$AO$501)} -> 196645.76 | L7: =J7-K7 -> 32397.469 | M7: =L7/K7 -> 0.16475041
C8: Coûts | E8: =E7-E9 -> 56135.46 | F8: =F7-F9 -> 28882.954 | G8: =E8-F8 -> 27252.506 | H8: =G8/F8 -> 0.94354983 | J8: =J7-J9 -> 175916.6 | K8: =K7-K9 -> 146654.26 | L8: =J8-K8 -> 29262.341 | M8: =L8/K8 -> 0.19953284
C9: Profit brut | E9: =E12+E11 -> 16605.21 | F9: =F12+F11 -> 9963.4884 | G9: =E9-F9 -> 6641.7216 | H9: =G9/F9 -> 0.66660604 | J9: =J12+J11 -> 53126.63 | K9: =K12+K11 -> 49991.502 | L9: =J9-K9 -> 3135.1278 | M9: =L9/K9 -> 0.062713215
C10: % avant redevances | E10: =E9/E7 -> 0.22827959 | F10: =F9/F7 -> 0.25648394 | G10: =E10-F10 -> -0.028204352 | J10: =J9/J7 -> 0.23195023 | K10: =K9/K7 -> 0.2542211 | L10: =J10-K10 -> -0.022270872
C11: Coûts de redevance | E11: =SUMIFS(BV_Data_An_Cour!$O:$O,BV_Data_An_Cour!$W:$W,$D$2,BV_Data_An_Cour!L:L,C31) -> 2579.53 | F11: =SUMIF($A$37:$A$48,"X",$G$37:$G$48) -> 2194.2 | G11: =E11-F11 -> 385.33 | H11: =G11/F11 -> 0.17561298 | J11: =SUMIFS(BV_Data_An_Cour!$P:$P,BV_Data_An_Cour!$W:$W,$L$2,BV_Data_An_Cour!T:T,C31) -> 6884.92 | K11: =SUMIF($B$37:$B$48,"X",$G$37:$G$48) -> 10662.35 | L11: =J11-K11 -> -3777.43 | M11: =L11/K11 -> -0.35427743
A12: Ventes de Gros | B12: pièces | C12: Profit | E12: =-SUMIFS(BV_Data_An_Cour!$O:$O,BV_Data_An_Cour!$U:$U,$B12,BV_Data_An_Cour!$V:$V,$A12,BV_Data_An_Cour!$W:$W,$D$2) -> 14025.68 | F12: =+INDEX('Budget original'!$A$2:$AO$501,MATCH(B12&$A12,'Budget original'!$A$2:$A$501,0),MATCH(G$2,'Budget original'!$A$2:$AO$2,0)) -> 7769.2884 | G12: =E12-F12 -> 6256.3916 | H12: =G12/F12 -> 0.80527214 | J12: =-SUMIFS(BV_Data_An_Cour!$P:$P,BV_Data_An_Cour!$U:$U,$B12,BV_Data_An_Cour!$V:$V,$A12,BV_Data_An_Cour!$W:$W,$D$2) -> 46241.71 | K12: {=+SUMPRODUCT(('Budget original'!$A$8:$A$501=B12&$A12)*('Budget original'!$C$3:$AO$3=O$2),'Budget original'!$C$8:$AO$501)} -> 39329.152 | L12: =J12-K12 -> 6912.5578 | M12: =L12/K12 -> 0.17576168
C13: % brut | E13: =(E12)/E7 -> 0.19281758 | F13: =(F12)/F7 -> 0.2 | G13: =E13-F13 -> -0.0071824194 | J13: =(J12)/J7 -> 0.20189075 | K13: =(K12)/K7 -> 0.2 | L13: =J13-K13 -> 0.0018907522
