Workbook
Name _Dates_Conc: #REF!
Name _scen: #REF!
Name _scen1: #REF!
Name _scen2: #REF!
Name _SCenarios: #REF!
Name _Sens1: #REF!
Name _Sens2: #REF!
Name _sensRes1: #REF!
Name _sensRes2: #REF!
Name _sensRes3: #REF!
Name _sensRes4: #REF!
Name _sensRes5: #REF!
Name _sensRes6: #REF!
Name _sensRes7: #REF!
Name DateRange: #REF!
Name Monetary_Unit: #REF!
Name Months: #REF!
Name Rng_Dealers_Names: #REF!
Name Rng_Dlr_Dates: #REF!
Name Titre: #REF!

Sheet Paramètre
B3: Quarter | C3: Q3 2026
B6: BUDGET | F6: BUDGET RÉVISÉ | J6: ACTUAL | N6: LAST YEAR
B7: Ventes | C7: Profits bruts | D7: BAIIA | E7: EBIT | F7: Ventes | G7: Profits bruts | H7: BAIIA | I7: EBIT | J7: Ventes | K7: Profits bruts | L7: BAIIA | M7: EBIT | N7: Ventes | O7: Profits bruts | P7: BAIIA | Q7: EBIT
A8: CTRL | B8: =+B9-B10 -> 0 | C8: =+C9-C10 -> 0 | D8: =+D9-D10 -> 0 | E8: =+E9-E10 -> #N/A | F8: =+F9-F10 -> 0 | G8: =+G9-G10 -> 0 | H8: =+H9-H10 -> 0 | I8: =+I9-I10 -> 0 | ... Q8: =+Q9-Q10 -> 0
A9: CONSO | B9: =+Conso!$Z$406 -> 0 | C9: =+Conso!$Z$407 -> 0 | D9: =+Conso!$Z$483 -> 0 | E9: =+Conso!$Z$498 -> #N/A | F9: =+Conso!$AC$406 -> 0 | G9: =+Conso!$AC$407 -> 0 | H9: =+Conso!$AC$483 -> 0 | I9: =+Conso!$AC$498 -> 0 | J9: =+Conso!$AF$406 -> 0 | K9: =+Conso!$AF$407 -> 0 | L9: =+Conso!$AF$483 -> 0 | M9: =+Conso!$AF$498 -> 79425.5 | N9: =+Conso!$AL$406 -> 0 | O9: =+Conso!$AL$407 -> 0 | P9: =+Conso!$AL$483 -> 0 | Q9: =+Conso!$AL$498 -> -68069.87
A10: TOTAL | B10: =+SUM(B11:B13) -> 0 | C10: =+SUM(C11:C13) -> 0 | D10: =+SUM(D11:D13) -> 0 | E10: =+SUM(E11:E13) -> #N/A | F10: =+SUM(F11:F13) -> 0 | G10: =+SUM(G11:G13) -> 0 | H10: =+SUM(H11:H13) -> 0 | I10: =+SUM(I11:I13) -> 0 | ... Q10: =+SUM(Q11:Q13) -> -68069.87
A11: Mois 1 | B11: =+'Mois 1'!$Z$406 -> 0 | C11: =+'Mois 1'!$Z$407 -> 0 | D11: =+'Mois 1'!$Z$483 -> 0 | E11: =+'Mois 1'!$Z$498 -> 0 | F11: =+'Mois 1'!$AC$406 -> 0 | G11: =+'Mois 1'!$AC$407 -> 0 | H11: =+'Mois 1'!$AC$483 -> 0 | I11: =+'Mois 1'!$AC$498 -> 0 | J11: =+'Mois 1'!$AF$406 -> 0 | K11: =+'Mois 1'!$AF$407 -> 0 | L11: =+'Mois 1'!$AF$483 -> 0 | M11: =+'Mois 1'!$AF$498 -> 54212.21 | N11: =+'Mois 1'!$AL$406 -> 0 | O11: =+'Mois 1'!$AL$407 -> 0 | P11: =+'Mois 1'!$AL$483 -> 0 | Q11: =+'Mois 1'!$AL$498 -> -39608.48
A12: Mois 2 | B12: =+'Mois 2'!$Z$406 -> 0 | C12: =+'Mois 2'!$Z$407 -> 0 | D12: =+'Mois 2'!$Z$483 -> 0 | E12: =+'Mois 2'!$Z$498 -> #N/A | F12: =+'Mois 2'!$AC$406 -> 0 | G12: =+'Mois 2'!$AC$407 -> 0 | H12: =+'Mois 2'!$AC$483 -> 0 | I12: =+'Mois 2'!$AC$498 -> 0 | J12: =+'Mois 2'!$AF$406 -> 0 | K12: =+'Mois 2'!$AF$407 -> 0 | L12: =+'Mois 2'!$AF$483 -> 0 | M12: =+'Mois 2'!$AF$498 -> -2581.44 | N12: =+'Mois 2'!$AL$406 -> 0 | O12: =+'Mois 2'!$AL$407 -> 0 | P12: =+'Mois 2'!$AL$483 -> 0 | Q12: =+'Mois 2'!$AL$498 -> -22956.37
A13: Mois 3 | B13: =+'Mois 3'!$Z$406 -> 0 | C13: =+'Mois 3'!$Z$407 -> 0 | D13: =+'Mois 3'!$Z$483 -> 0 | E13: =+'Mois 3'!$Z$498 -> 0 | F13: =+'Mois 3'!$AC$406 -> 0 | G13: =+'Mois 3'!$AC$407 -> 0 | H13: =+'Mois 3'!$AC$483 -> 0 | I13: =+'Mois 3'!$AC$498 -> 0 | J13: =+'Mois 3'!$AF$406 -> 0 | K13: =+'Mois 3'!$AF$407 -> 0 | L13: =+'Mois 3'!$AF$483 -> 0 | M13: =+'Mois 3'!$AF$498 -> 27794.73 | N13: =+'Mois 3'!$AL$406 -> 0 | O13: =+'Mois 3'!$AL$407 -> 0 | P13: =+'Mois 3'!$AL$483 -> 0 | Q13: =+'Mois 3'!$AL$498 -> -5505.02

Sheet Conso
C1: Ste-Marie Auto | K1: Véhicules neufs | S1: =CONCATENATE("Réalisé"," ",Paramètre!$C$2," ",Paramètre!$C$3) -> Réalisé Q3 2026
D2: X | E2: O | F2: U | G2: X | H2: O | I2: U
D3: BUDGET ORIGINAL | G3: BUDGET REVISE | J3: RÉALISATION | M3: ÉCART réel / Budget | O3: ANNÉE PRÉCÉDENTE | R3: ECART (réel/ Ann.Préc.)
D4: UNITE | E4: $P/UNITÉ | F4: $PROFITS | G4: UNITE | H4: $P/UNITÉ | I4: $PROFITS | J4: UNITE | K4: $P/UNITE | L4: $PROFITS | M4: UNFTÉ | N4: $PROFITS | O4: UNITE | P4: $P/UNITE | Q4: $PROFITS | R4: UNITE | S4: $PROFITS
A5: =+B5&C5 -> Véhicules neufsVentes nettes | B5: =+$K$1 -> Véhicules neufs | C5: Ventes nettes | F5: =+SUM(START:END!F5) -> #N/A | I5: =+SUM(START:END!I5) -> 0 | L5: =+SUM(START:END!L5) -> 20559481 | Q5: =+SUM(START:END!Q5) -> 28344574
A6: =+B6&C6 -> Véhicules neufsAutos détail | B6: =+$K$1 -> Véhicules neufs | C6: Autos détail | D6: =+SUM(START:END!D6) -> #N/A | E6: =IF(D6=0,0,F6/D6) -> #N/A | F6: =+SUM(START:END!F6) -> #N/A | G6: =+SUM(START:END!G6) -> 0 | H6: =IF(G6=0,0,I6/G6) -> 0 | I6: =+SUM(START:END!I6) -> 0 | J6: =+SUM(START:END!J6) -> 2 | K6: =IF(J6=0,0,L6/J6) -> 6531.68 | L6: =+SUM(START:END!L6) -> 13063.36 | M6: =J6-D6 -> #N/A | N6: =L6-F6 -> #N/A | O6: =+SUM(START:END!O6) -> 2 | P6: =IF(O6=0,0,Q6/O6) -> 5561 | Q6: =+SUM(START:END!Q6) -> 11122 | R6: =J6-O6 -> 0 | S6: =L6-Q6 -> 1941.36
A7: =+B7&C7 -> Véhicules neufsCamions détail | B7: =+$K$1 -> Véhicules neufs | C7: Camions détail | D7: =+SUM(START:END!D7) -> #N/A | E7: =IF(D7=0,0,F7/D7) -> #N/A | F7: =+SUM(START:END!F7) -> #N/A | G7: =+SUM(START:END!G7) -> 0 | H7: =IF(G7=0,0,I7/G7) -> 0 | I7: =+SUM(START:END!I7) -> 0 | J7: =+SUM(START:END!J7) -> 88 | K7: =IF(J7=0,0,L7/J7) -> 2402.4967 | L7: =+SUM(START:END!L7) -> 211419.71 | M7: =J7-D7 -> #N/A | N7: =L7-F7 -> #N/A | O7: =+SUM(START:END!O7) -> 164 | P7: =IF(O7=0,0,Q7/O7) -> 2885.1216 | Q7: =+SUM(START:END!Q7) -> 473159.95 | R7: =J7-O7 -> -76 | S7: =L7-Q7 -> -261740.24
A8: =+B8&C8 -> Véhicules neufsSprinter | B8: =+$K$1 -> Véhicules neufs | C8: Sprinter | D8: =+SUM(START:END!D8) -> #N/A | E8: =IF(D8=0,0,F8/D8) -> #N/A | F8: =+SUM(START:END!F8) -> #N/A | G8: =+SUM(START:END!G8) -> 0 | H8: =IF(G8=0,0,I8/G8) -> 0 | I8: =+SUM(START:END!I8) -> 0 | J8: =+SUM(START:END!J8) -> 0 | K8: =IF(J8=0,0,L8/J8) -> 0 | L8: =+SUM(START:END!L8) -> 0 | M8: =J8-D8 -> #N/A | N8: =L8-F8 -> #N/A | O8: =+SUM(START:END!O8) -> 0 | P8: =IF(O8=0,0,Q8/O8) -> 0 | Q8: =+SUM(START:END!Q8) -> 0 | R8: =J8-O8 -> 0 | S8: =L8-Q8 -> 0
A9: =+B9&C9 -> Véhicules neufsMoto détail | B9: =+$K$1 -> Véhicules neufs | C9: Moto détail | D9: =+SUM(START:END!D9) -> #N/A | E9: =IF(D9=0,0,F9/D9) -> #N/A | F9: =+SUM(START:END!F9) -> #N/A | G9: =+SUM(START:END!G9) -> 0 | H9: =IF(G9=0,0,I9/G9) -> 0 | I9: =+SUM(START:END!I9) -> 0 | J9: =+SUM(START:END!J9) -> 96 | K9: =IF(J9=0,0,L9/J9) -> 1377.6127 | L9: =+SUM(START:END!L9) -> 132250.82 | M9: =J9-D9 -> #N/A | N9: =L9-F9 -> #N/A | O9: =+SUM(START:END!O9) -> 53 | P9: =IF(O9=0,0,Q9/O9) -> 1144.1613 | Q9: =+SUM(START:END!Q9) -> 60640.55 | R9: =J9-O9 -> 43 | S9: =L9-Q9 -> 71610.27
A10: =+B10&C10 -> Véhicules neufs[...] | B10: =+$K$1 -> Véhicules neufs | C10: [...] | D10: =+SUM(START:END!D10) -> #N/A | E10: =IF(D10=0,0,F10/D10) -> #N/A | F10: =+SUM(START:END!F10) -> #N/A | G10: =+SUM(START:END!G10) -> 0 | H10: =IF(G10=0,0,I10/G10) -> 0 | I10: =+SUM(START:END!I10) -> 0 | J10: =+SUM(START:END!J10) -> 0 | K10: =IF(J10=0,0,L10/J10) -> 0 | L10: =+SUM(START:END!L10) -> 0 | M10: =J10-D10 -> #N/A | N10: =L10-F10 -> #N/A | O10: =+SUM(START:END!O10) -> 0 | P10: =IF(O10=0,0,Q10/O10) -> 0 | Q10: =+SUM(START:END!Q10) -> 0 | R10: =J10-O10 -> 0 | S10: =L10-Q10 -> 0
A11: =+B11&C11 -> Véhicules neufs[...] | B11: =+$K$1 -> Véhicules neufs | C11: [...] | D11: =+SUM(START:END!D11) -> #N/A | E11: =IF(D11=0,0,F11/D11) -> #N/A | F11: =+SUM(START:END!F11) -> #N/A | G11: =+SUM(START:END!G11) -> 0 | H11: =IF(G11=0,0,I11/G11) -> 0 | I11: =+SUM(START:END!I11) -> 0 | J11: =+SUM(START:END!J11) -> 0 | K11: =IF(J11=0,0,L11/J11) -> 0 | L11: =+SUM(START:END!L11) -> 0 | M11: =J11-D11 -> #N/A | N11: =L11-F11 -> #N/A | O11: =+SUM(START:END!O11) -> 0 | P11: =IF(O11=0,0,Q11/O11) -> 0 | Q11: =+SUM(START:END!Q11) -> 0 | R11: =J11-O11 -> 0 | S11: =L11-Q11 -> 0
A12: =+B12&C12 -> Véhicules neufs[...] | B12: =+$K$1 -> Véhicules neufs | C12: [...] | D12: =+SUM(START:END!D12) -> #N/A | E12: =IF(D12=0,0,F12/D12) -> #N/A | F12: =+SUM(START:END!F12) -> #N/A | G12: =+SUM(START:END!G12) -> 0 | H12: =IF(G12=0,0,I12/G12) -> 0 | I12: =+SUM(START:END!I12) -> 0 | J12: =+SUM(START:END!J12) -> 0 | K12: =IF(J12=0,0,L12/J12) -> 0 | L12: =+SUM(START:END!L12) -> 0 | M12: =J12-D12 -> #N/A | N12: =L12-F12 -> #N/A | O12: =+SUM(START:END!O12) -> 0 | P12: =IF(O12=0,0,Q12/O12) -> 0 | Q12: =+SUM(START:END!Q12) -> 0 | R12: =J12-O12 -> 0 | S12: =L12-Q12 -> 0
A13: =+B13&C13 -> Véhicules neufsTotal Neufs | B13: =+$K$1 -> Véhicules neufs | C13: Total Neufs | D13: =+SUM(D6:D12) -> #N/A | E13: =IF(D13<=0,0,F13/D13) -> #N/A | F13: =+SUM(F6:F12) -> #N/A | G13: =+SUM(G6:G12) -> 0 | H13: =IF(G13<=0,0,I13/G13) -> 0 | I13: =+SUM(I6:I12) -> 0 | J13: =+SUM(J6:J12) -> 186 | K13: =IF(J13<=0,0,L13/J13) -> 1917.9241 | L13: =+SUM(L6:L12) -> 356733.89 | M13: =+SUM(M6:M12) -> #N/A | N13: =+SUM(N6:N12) -> #N/A | O13: =+SUM(O6:O12) -> 219 | P13: =IF(O13<=0,0,Q13/O13) -> 2488.2306 | Q13: =+SUM(Q6:Q12) -> 544922.5 | R13: =+SUM(R6:R12) -> -33 | S13: =+SUM(S6:S12) -> -188188.61
A14: =+B14&C14 -> Véhicules neufs | B14: =+$K$1 -> Véhicules neufs | M14: =IF(D13=0,0,M13/D13) -> #N/A | N14: =IF(F13=0,0,N13/F13) -> #N/A | R14: =R13/O13 -> -0.15068493 | S14: =IF(Q13=0,0,(S13/Q13)) -> -0.34534931
A15: =+B15&C15 -> Véhicules neufsEx-Démos et courtoisies | B15: =+$K$1 -> Véhicules neufs | C15: Ex-Démos et courtoisies | D15: =+SUM(START:END!D15) -> #N/A | E15: =IF(D15=0,0,F15/D15) -> #N/A | F15: =+SUM(START:END!F15) -> #N/A | G15: =+SUM(START:END!G15) -> 0 | H15: =IF(G15=0,0,I15/G15) -> 0 | I15: =+SUM(START:END!I15) -> 0 | J15: =+SUM(START:END!J15) -> 0 | K15: =IF(J15=0,0,L15/J15) -> 0 | L15: =+SUM(START:END!L15) -> 0 | M15: =J15-D15 -> #N/A | N15: =L15-F15 -> #N/A | O15: =+SUM(START:END!O15) -> 0 | P15: =IF(O15=0,0,Q15/O15) -> 0 | Q15: =+SUM(START:END!Q15) -> 0 | R15: =J15-O15 -> 0 | S15: =L15-Q15 -> 0
A16: =+B16&C16 -> Véhicules neufs | B16: =+$K$1 -> Véhicules neufs
A17: =+B17&C17 -> Véhicules neufsFlottes | B17: =+$K$1 -> Véhicules neufs | C17: Flottes | D17: =+SUM(START:END!D17) -> #N/A | E17: =IF(D17=0,0,F17/D17) -> #N/A | F17: =+SUM(START:END!F17) -> #N/A | G17: =+SUM(START:END!G17) -> 0 | H17: =IF(G17=0,0,I17/G17) -> 0 | I17: =+SUM(START:END!I17) -> 0 | J17: =+SUM(START:END!J17) -> 143 | K17: =IF(J17=0,0,L17/J17) -> 607.78049 | L17: =+SUM(START:END!L17) -> 86912.61 | M17: =J17-D17 -> #N/A | N17: =L17-F17 -> #N/A | O17: =+SUM(START:END!O17) -> 229 | P17: =IF(O17=0,0,Q17/O17) -> 627.69668 | Q17: =+SUM(START:END!Q17) -> 143742.54 | R17: =J17-O17 -> -86 | S17: =L17-Q17 -> -56829.93
A18: =+B18&C18 -> Véhicules neufs | B18: =+$K$1 -> Véhicules neufs
A19: =+B19&C19 -> Véhicules neufsRachat bail | B19: =+$K$1 -> Véhicules neufs | C19: Rachat bail | F19: =+SUM(START:END!F19) -> 0 | I19: =+SUM(START:END!I19) -> 0 | L19: =+SUM(START:END!L19) -> 0 | N19: =L19-F19 -> 0 | Q19: =+SUM(START:END!Q19) -> 0 | R19: =O19-K19 -> 0 | S19: =L19-Q19 -> 0
A20: =+B20&C20 -> Véhicules neufs | B20: =+$K$1 -> Véhicules neufs
A21: =+B21&C21 -> Véhicules neufsRev. Finances | B21: =+$K$1 -> Véhicules neufs | C21: Rev. Finances | D21: 0 | E21: =IF(D21=0,0,F21/D21) -> 0 | F21: =+SUM(START:END!F21) -> #N/A | G21: 0 | H21: =IF(G21=0,0,I21/G21) -> 0 | I21: =+SUM(START:END!I21) -> 0 | K21: =IF(J13=0,0,L21/(J13+J15)) -> -1.7697849 | L21: =+SUM(START:END!L21) -> -329.18 | N21: =L21-F21 -> #N/A | P21: =IF(O13=0,0,Q21/(O13+O15)) -> 8.0162557 | Q21: =+SUM(START:END!Q21) -> 1755.56 | R21: =O21-K21 -> 1.7697849 | S21: =L21-Q21 -> -2084.74
A22: =+B22&C22 -> Véhicules neufsRev. Protections | B22: =+$K$1 -> Véhicules neufs | C22: Rev. Protections | D22: 0 | E22: =IF(D22=0,0,F22/D22) -> 0 | F22: =+SUM(START:END!F22) -> #N/A | G22: 0 | H22: =IF(G22=0,0,I22/G22) -> 0 | I22: =+SUM(START:END!I22) -> 0 | K22: =IF(J13=0,0,L22/(J13+J15)) -> 559.97274 | L22: =+SUM(START:END!L22) -> 104154.93 | N22: =L22-F22 -> #N/A | P22: =IF(O13=0,0,Q22/(O13+O15)) -> 689.24918 | Q22: =+SUM(START:END!Q22) -> 150945.57 | R22: =O22-K22 -> -559.97274 | S22: =L22-Q22 -> -46790.64
A23: =+B23&C23 -> Véhicules neufsRev. Autres | B23: =+$K$1 -> Véhicules neufs | C23: Rev. Autres | D23: 0 | E23: =IF(D23=0,0,F23/D23) -> 0 | F23: =+SUM(START:END!F23) -> #N/A | G23: 0 | H23: =IF(G23=0,0,I23/G23) -> 0 | I23: =+SUM(START:END!I23) -> 0 | K23: =IF(J13=0,0,L23/(J13+J15)) -> 55.863656 | L23: =+SUM(START:END!L23) -> 10390.64 | N23: =L23-F23 -> #N/A | P23: =IF(O13=0,0,Q23/(O13+O15)) -> 123.58146 | Q23: =+SUM(START:END!Q23) -> 27064.34 | R23: =O23-K23 -> -55.863656 | S23: =L23-Q23 -> -16673.7
A24: =+B24&C24 -> Véhicules neufsTotal F&I | B24: =+$K$1 -> Véhicules neufs | C24: Total F&I | D24: =+D15+D13 -> #N/A | E24: =IF(D24<=0,0,F24/D24) -> #N/A | F24: =F21+F22+F23 -> #N/A | G24: =+G15+G13 -> 0 | H24: =IF(G24<=0,0,I24/G24) -> 0 | I24: =I21+I22+I23 -> 0 | J24: =+J15+J13 -> 186 | K24: =IF(J24<=0,0,L24/J24) -> 614.06661 | L24: =L21+L22+L23 -> 114216.39 | M24: =J24-D24 -> #N/A | N24: =L24-F24 -> #N/A | O24: =+O15+O13 -> 219 | P24: =IF(O24<=0,0,Q24/O24) -> 820.84689 | Q24: =Q21+Q22+Q23 -> 179765.47 | S24: =L24-Q24 -> -65549.08
A25: =+B25&C25 -> Véhicules neufs | B25: =+$K$1 -> Véhicules neufs | N25: =IF(N24=0,0,N24/F24) -> #N/A | S25: =IF(Q24=0,0,(S24/Q24)) -> -0.36463666
A26: =+B26&C26 -> Véhicules neufs | B26: =+$K$1 -> Véhicules neufs
A27: =+B27&C27 -> Véhicules neufsTotal Dépt. Neufs | B27: =+$K$1 -> Véhicules neufs | C27: Total Dépt. Neufs | D27: =+D13+D15+D17 -> #N/A | E27: =IF(D27<=0,0,F27/D27) -> #N/A | F27: =F13+F17+F24+F19+F15 -> #N/A | G27: =+G13+G15+G17 -> 0 | H27: =IF(G27<=0,0,I27/G27) -> 0 | I27: =I13+I17+I24+I19+I15 -> 0 | J27: =+J13+J15+J17 -> 329 | K27: =IF(J27<=0,0,L27/J27) -> 1695.6319 | L27: =L13+L17+L24+L19+L15 -> 557862.89 | M27: =J27-D27 -> #N/A | N27: =L27-F27 -> #N/A | O27: =+O13+O15+O17 -> 448 | P27: =IF(O27<=0,0,Q27/O27) -> 1938.461 | Q27: =Q13+Q17+Q24+Q19+Q15 -> 868430.51 | R27: =J27-O27 -> -119 | S27: =L27-Q27 -> -310567.62
A28: =+B28&C28 -> Véhicules neufs | B28: =+$K$1 -> Véhicules neufs | M28: =M27/D27 -> #N/A | N28: =N27/F27 -> #N/A | R28: =R27/O27 -> -0.265625 | S28: =IF(Q27=0,0,S27/Q27) -> -0.35761943
A29: =+B29&C29 -> Véhicules neufs | B29: =+$K$1 -> Véhicules neufs
A30: =+B30&C30 -> Véhicules neufsDEPENSES | B30: =+$K$1 -> Véhicules neufs | C30: DEPENSES
A31: =+B31&C31 -> Véhicules neufsComm. vendeurs | B31: =+$K$1 -> Véhicules neufs | C31: Comm. vendeurs | D31: =F31/(F13+F15) -> #N/A | E31: =F31/D$24 -> #N/A | F31: =+SUM(START:END!F31) -> #N/A | H31: =I31/G$24 -> #DIV/0! | I31: =+SUM(START:END!I31) -> 0 | J31: =L31/(L13+L15) -> 0.3566161 | K31: =IF(L31=0,0,L31/J$24) -> 683.96263 | L31: =+SUM(START:END!L31) -> 127217.05 | N31: =L31-F31 -> #N/A | O31: =Q31/(Q13+Q15+Q17) -> 0.24949816 | P31: =IF(Q31=0,0,Q31/O$24) -> 784.56922 | Q31: =+SUM(START:END!Q31) -> 171820.66 | S31: =L31-Q31 -> -44603.61
A32: =+B32&C32 -> Véhicules neufsComm. F&I | B32: =+$K$1 -> Véhicules neufs | C32: Comm. F&I | D32: =F32/F24 -> #N/A | E32: =F32/D$24 -> #N/A | F32: =+SUM(START:END!F32) -> #N/A | H32: =I32/G$24 -> #DIV/0! | I32: =+SUM(START:END!I32) -> 0 | J32: =L32/L24 -> 0.31187477 | K32: =IF(L32=0,0,L32/J$24) -> 191.51188 | L32: =+SUM(START:END!L32) -> 35621.21 | N32: =L32-F32 -> #N/A | O32: =Q32/Q24 -> 0.26191304 | P32: =IF(Q32=0,0,Q32/O$24) -> 214.9905 | Q32: =+SUM(START:END!Q32) -> 47082.92 | S32: =L32-Q32 -> -11461.71
A33: =+B33&C33 -> Véhicules neufsFrais de livraison | B33: =+$K$1 -> Véhicules neufs | C33: Frais de livraison | E33: =F33/D$24 -> #N/A | F33: =+SUM(START:END!F33) -> #N/A | H33: =I33/G$24 -> #DIV/0! | I33: =+SUM(START:END!I33) -> 0 | K33: =IF(L33=0,0,L33/J$24) -> 424.52414 | L33: =+SUM(START:END!L33) -> 78961.49 | N33: =L33-F33 -> #N/A | P33: =IF(Q33=0,0,Q33/O$24) -> -123.47598 | Q33: =+SUM(START:END!Q33) -> -27041.24 | S33: =L33-Q33 -> 106002.73
A34: =+B34&C34 -> Véhicules neufsService gratuit 1 | B34: =+$K$1 -> Véhicules neufs | C34: Service gratuit 1 | E34: =F34/D$24 -> #N/A | F34: =+SUM(START:END!F34) -> #N/A | H34: =I34/G$24 -> #DIV/0! | I34: =+SUM(START:END!I34) -> 0 | K34: =IF(L34=0,0,L34/J$24) -> 8.211828 | L34: =+SUM(START:END!L34) -> 1527.4 | N34: =L34-F34 -> #N/A | P34: =IF(Q34=0,0,Q34/O$24) -> 7.4466667 | Q34: =+SUM(START:END!Q34) -> 1630.82 | S34: =L34-Q34 -> -103.42
A35: =+B35&C35 -> Véhicules neufsEntretien stock | B35: =+$K$1 -> Véhicules neufs | C35: Entretien stock | E35: =F35/D$24 -> #N/A | F35: =+SUM(START:END!F35) -> #N/A | H35: =I35/G$24 -> #DIV/0! | I35: =+SUM(START:END!I35) -> 0 | K35: =IF(L35=0,0,L35/J$24) -> 52.831613 | L35: =+SUM(START:END!L35) -> 9826.68 | N35: =L35-F35 -> #N/A | P35: =IF(Q35=0,0,Q35/O$24) -> 0 | Q35: =+SUM(START:END!Q35) -> 0 | S35: =L35-Q35 -> 9826.68
A36: =+B36&C36 -> Véhicules neufsPublicité 1 | B36: =+$K$1 -> Véhicules neufs | C36: Publicité 1 | E36: =F36/D$24 -> #N/A | F36: =+SUM(START:END!F36) -> #N/A | H36: =I36/G$24 -> #DIV/0! | I36: =+SUM(START:END!I36) -> 0 | K36: =IF(L36=0,0,L36/J$24) -> -206.73672 | L36: =+SUM(START:END!L36) -> -38453.03 | N36: =L36-F36 -> #N/A | P36: =IF(Q36=0,0,Q36/O$24) -> -300.0332 | Q36: =+SUM(START:END!Q36) -> -65707.27 | S36: =L36-Q36 -> 27254.24
A37: =+B37&C37 -> Véhicules neufsIntérêt de gros | B37: =+$K$1 -> Véhicules neufs | C37: Intérêt de gros | E37: =F37/D$24 -> #N/A | F37: =+SUM(START:END!F37) -> #N/A | H37: =I37/G$24 -> #DIV/0! | I37: =+SUM(START:END!I37) -> 0 | K37: =IF(L37=0,0,L37/J$24) -> 666.81253 | L37: =+SUM(START:END!L37) -> 124027.13 | N37: =L37-F37 -> #N/A | P37: =IF(Q37=0,0,Q37/O$24) -> 833.86785 | Q37: =+SUM(START:END!Q37) -> 182617.06 | S37: =L37-Q37 -> -58589.93
A38: =+B38&C38 -> Véhicules neufsCrédit Intérêts Floor Plan | B38: =+$K$1 -> Véhicules neufs | C38: Crédit Intérêts Floor Plan | E38: =F38/D$24 -> #N/A | F38: =+SUM(START:END!F38) -> #N/A | H38: =I38/G$24 -> #DIV/0! | I38: =+SUM(START:END!I38) -> 0 | K38: =IF(L38=0,0,L38/J$24) -> -1753.4539 | L38: =+SUM(START:END!L38) -> -326142.42 | N38: =L38-F38 -> #N/A | P38: =IF(Q38=0,0,Q38/O$24) -> -2034.5403 | Q38: =+SUM(START:END!Q38) -> -445564.33 | S38: =L38-Q38 -> 119421.91
A39: =+B39&C39 -> Véhicules neufsCrédit Boni TD | B39: =+$K$1 -> Véhicules neufs | C39: Crédit Boni TD | E39: =F39/D$24 -> #N/A | F39: =+SUM(START:END!F39) -> #N/A | H39: =I39/G$24 -> #DIV/0! | I39: =+SUM(START:END!I39) -> 0 | K39: =IF(L39=0,0,L39/J$24) -> -167.32565 | L39: =+SUM(START:END!L39) -> -31122.57 | N39: =L39-F39 -> #N/A | P39: =IF(Q39=0,0,Q39/O$24) -> 0 | Q39: =+SUM(START:END!Q39) -> 0 | S39: =L39-Q39 -> -31122.57
A40: =+B40&C40 -> Véhicules neufs[...] | B40: =+$K$1 -> Véhicules neufs | C40: [...] | E40: =F40/D$24 -> #N/A | F40: =+SUM(START:END!F40) -> #N/A | H40: =I40/G$24 -> #DIV/0! | I40: =+SUM(START:END!I40) -> 0 | K40: =IF(L40=0,0,L40/J$24) -> 0 | L40: =+SUM(START:END!L40) -> 0 | N40: =L40-F40 -> #N/A | P40: =IF(Q40=0,0,Q40/O$24) -> 0 | Q40: =+SUM(START:END!Q40) -> 0 | S40: =L40-Q40 -> 0
...

Sheet START

Sheet Mois 1
C1: Ste-Marie Auto | K1: Véhicules neufs | S1: Réalisé, Juillet 2026
D2: X | E2: O | F2: U | J2: NB | L2: $ | O2: NB | Q2: $ | V2: *** NE PAS EFFACER / Pour An Précédente ***
D3: BUDGET ORIGINAL | J3: RÉALISATION | M3: ÉCART réel / Budget | O3: ANNÉE PRÉCÉDENTE | R3: ECART (réel/ Ann.Préc.) | V3: NEUF | W3: 0.45
D4: UNITE | E4: $P/UNITÉ | F4: $PROFITS | J4: UNITÉS | K4: $P/UNITE | L4: $PROFITS | M4: UNITÉS | N4: $PROFITS | O4: UNITÉS | P4: $P/UNITE | Q4: $PROFITS | R4: UNITÉS | S4: $PROFITS | V4: USAGE | W4: 0.1
A5: Véhicules neufsVentes nettes | B5: Véhicules neufs | C5: Ventes nettes | F5: 0 | L5: 7544009.9 | Q5: 11373985 | V5: SERVICE | W5: 0.225
A6: Véhicules neufsAutos détail | B6: Véhicules neufs | C6: Autos détail | D6: 0 | E6: =IF(D6=0,0,F6/D6) -> 0 | F6: 0 | J6: 1 | K6: =IF(J6=0,0,L6/J6) -> 1519 | L6: 1519 | M6: =J6-D6 -> 1 | N6: =L6-F6 -> 1519 | O6: 0 | P6: =IF(O6=0,0,Q6/O6) -> 0 | Q6: 0 | R6: =J6-O6 -> 1 | S6: =L6-Q6 -> 1519 | V6: CARROSSERIE | W6: 0.025
A7: Véhicules neufsCamions détail | B7: Véhicules neufs | C7: Camions détail | D7: 0 | E7: =IF(D7=0,0,F7/D7) -> 0 | F7: 0 | J7: 32 | K7: =IF(J7=0,0,L7/J7) -> 2924.1747 | L7: 93573.59 | M7: =J7-D7 -> 32 | N7: =L7-F7 -> 93573.59 | O7: 59 | P7: =IF(O7=0,0,Q7/O7) -> 3159.409 | Q7: 186405.13 | R7: =J7-O7 -> -27 | S7: =L7-Q7 -> -92831.54 | V7: PIECES | W7: 0.2
A8: Véhicules neufsSprinter | B8: Véhicules neufs | C8: Voitures electriques | D8: 0 | E8: =IF(D8=0,0,F8/D8) -> 0 | F8: 0 | J8: 0 | K8: =IF(J8=0,0,L8/J8) -> 0 | L8: 0 | M8: =J8-D8 -> 0 | N8: =L8-F8 -> 0 | O8: 0 | P8: =IF(O8=0,0,Q8/O8) -> 0 | Q8: 0 | R8: =J8-O8 -> 0 | S8: =L8-Q8 -> 0 | W8: =SUM(W3:W7) -> 1
A9: Véhicules neufsMoto détail | B9: Véhicules neufs | C9: Camions electriques | D9: 0 | E9: =IF(D9=0,0,F9/D9) -> 0 | F9: 0 | J9: 21 | K9: =IF(J9=0,0,L9/J9) -> 1565.2624 | L9: 32870.51 | M9: =J9-D9 -> 21 | N9: =L9-F9 -> 32870.51 | O9: 18 | P9: =IF(O9=0,0,Q9/O9) -> 815.97444 | Q9: 14687.54 | R9: =J9-O9 -> 3 | S9: =L9-Q9 -> 18182.97 | U9: Livre des ventes
A10: Véhicules neufs[...] | B10: Véhicules neufs | C10: [...] | D10: 0 | E10: =IF(D10=0,0,F10/D10) -> 0 | F10: 0 | J10: 0 | K10: =IF(J10=0,0,L10/J10) -> 0 | L10: 0 | M10: =J10-D10 -> 0 | N10: =L10-F10 -> 0 | O10: 0 | P10: =IF(O10=0,0,Q10/O10) -> 0 | Q10: 0 | R10: =J10-O10 -> 0 | S10: =L10-Q10 -> 0
A11: Véhicules neufs[...] | B11: Véhicules neufs | C11: [...] | D11: 0 | E11: =IF(D11=0,0,F11/D11) -> 0 | F11: 0 | J11: 0 | K11: =IF(J11=0,0,L11/J11) -> 0 | L11: 0 | M11: =J11-D11 -> 0 | N11: =L11-F11 -> 0 | O11: 0 | P11: =IF(O11=0,0,Q11/O11) -> 0 | Q11: 0 | R11: =J11-O11 -> 0 | S11: =L11-Q11 -> 0
A12: Véhicules neufs[...] | B12: Véhicules neufs | C12: [...] | D12: 0 | E12: =IF(D12=0,0,F12/D12) -> 0 | F12: 0 | J12: 0 | K12: =IF(J12=0,0,L12/J12) -> 0 | L12: 0 | M12: =J12-D12 -> 0 | N12: =L12-F12 -> 0 | O12: 0 | P12: =IF(O12=0,0,Q12/O12) -> 0 | Q12: 0 | R12: =J12-O12 -> 0 | S12: =L12-Q12 -> 0
A13: Véhicules neufsTotal Neufs | B13: Véhicules neufs | C13: Total Neufs | D13: =+SUM(D6:D12) -> 0 | E13: =IF(D13<=0,0,F13/D13) -> 0 | F13: =+SUM(F6:F12) -> 0 | J13: =+SUM(J6:J12) -> 54 | K13: =IF(J13<=0,0,L13/J13) -> 2369.687 | L13: =+SUM(L6:L12) -> 127963.1 | M13: =+SUM(M6:M12) -> 54 | N13: =+SUM(N6:N12) -> 127963.1 | O13: =+SUM(O6:O12) -> 77 | P13: =IF(O13<=0,0,Q13/O13) -> 2611.5931 | Q13: =+SUM(Q6:Q12) -> 201092.67 | R13: =+SUM(R6:R12) -> -23 | S13: =+SUM(S6:S12) -> -73129.57 | T13: 54 | U13: 127963 | V13: =L13-U13 -> 0.1
A14: Véhicules neufs | B14: Véhicules neufs | M14: =IF(D13=0,0,M13/D13) -> 0 | N14: =IF(F13=0,0,N13/F13) -> 0 | R14: =R13/O13 -> -0.2987013 | S14: =IF(Q13=0,0,(S13/Q13)) -> -0.36366104
A15: Véhicules neufsEx-Démos et courtoisies | B15: Véhicules neufs | C15: Ex-Démos et courtoisies | D15: 0 | E15: =IF(D15=0,0,F15/D15) -> 0 | F15: 0 | J15: 0 | K15: =IF(J15=0,0,L15/J15) -> 0 | L15: 0 | M15: =J15-D15 -> 0 | N15: =L15-F15 -> 0 | O15: 0 | P15: =IF(O15=0,0,Q15/O15) -> 0 | Q15: 0 | R15: =J15-O15 -> 0 | S15: =L15-Q15 -> 0
A16: Véhicules neufs | B16: Véhicules neufs
A17: Véhicules neufsFlottes | B17: Véhicules neufs | C17: Flottes | D17: 0 | E17: =IF(D17=0,0,F17/D17) -> 0 | F17: 0 | J17: 58 | K17: =IF(J17=0,0,L17/J17) -> 503.14414 | L17: 29182.36 | M17: =J17-D17 -> 58 | N17: =L17-F17 -> 29182.36 | O17: 93 | P17: =IF(O17=0,0,Q17/O17) -> 596.45914 | Q17: 55470.7 | R17: =J17-O17 -> -35 | S17: =L17-Q17 -> -26288.34 | T17: 58 | U17: 27397 | V17: =L17-U17 -> 1785.36
A18: Véhicules neufs | B18: Véhicules neufs
A19: Véhicules neufsRachat bail | B19: Véhicules neufs
A20: Véhicules neufs | B20: Véhicules neufs
A21: Véhicules neufsRev. Finances | B21: Véhicules neufs | C21: Rev. Finances | D21: 0 | E21: =IF(D21=0,0,F21/D21) -> 0 | F21: 0 | K21: =IF(J13=0,0,L21/(J13+J15)) -> 18.518519 | L21: 1000 | N21: =L21-F21 -> 1000 | P21: =IF(O13=0,0,Q21/(O13+O15)) -> 21.425455 | Q21: 1649.76 | R21: =P21-K21 -> 2.906936 | S21: =L21-Q21 -> -649.76
A22: Véhicules neufsRev. Protections | B22: Véhicules neufs | C22: Rev. Protections | D22: 0 | E22: =IF(D22=0,0,F22/D22) -> 0 | F22: 0 | K22: =IF(J13=0,0,L22/(J13+J15)) -> 576.52907 | L22: 31132.57 | N22: =L22-F22 -> 31132.57 | P22: =IF(O13=0,0,Q22/(O13+O15)) -> 572.09403 | Q22: 44051.24 | R22: =P22-K22 -> -4.4350481 | S22: =L22-Q22 -> -12918.67
A23: Véhicules neufsRev. Autres | B23: Véhicules neufs | C23: Rev. Autres | D23: 0 | E23: =IF(D23=0,0,F23/D23) -> 0 | F23: 0 | K23: =IF(J13=0,0,L23/(J13+J15)) -> 113.675 | L23: 6138.45 | N23: =L23-F23 -> 6138.45 | P23: =IF(O13=0,0,Q23/(O13+O15)) -> 106.58442 | Q23: 8207 | R23: =P23-K23 -> -7.0905844 | S23: =L23-Q23 -> -2068.55
A24: Véhicules neufsTotal F&I | B24: Véhicules neufs | C24: Total F&I | D24: =+D15+D13 -> 0 | E24: =IF(D24<=0,0,F24/D24) -> 0 | F24: =F21+F22+F23 -> 0 | J24: =+J15+J13 -> 54 | K24: =IF(J24<=0,0,L24/J24) -> 708.72259 | L24: =L21+L22+L23 -> 38271.02 | M24: =J24-D24 -> 54 | N24: =L24-F24 -> 38271.02 | O24: =+O15+O13 -> 77 | P24: =IF(O24<=0,0,Q24/O24) -> 700.1039 | Q24: =Q21+Q22+Q23 -> 53908 | R24: =P24-K24 -> -8.6186965 | S24: =L24-Q24 -> -15636.98 | U24: 38271 | V24: =L24-U24 -> 0.02
A25: Véhicules neufs | B25: Véhicules neufs | N25: =IF(N24=0,0,N24/F24) -> #DIV/0! | S25: =IF(Q24=0,0,(S24/Q24)) -> -0.29006789
A26: Véhicules neufs | B26: Véhicules neufs
A27: Véhicules neufsTotal Dépt. Neufs | B27: Véhicules neufs | C27: Total Dépt. Neufs | D27: =+D13+D15+D17 -> 0 | E27: =IF(D27<=0,0,F27/D27) -> 0 | F27: =F13+F17+F24+F19+F15 -> 0 | J27: =+J13+J15+J17 -> 112 | K27: =IF(J27<=0,0,L27/J27) -> 1744.79 | L27: =L13+L17+L24+L19+L15 -> 195416.48 | M27: =J27-D27 -> 112 | N27: =L27-F27 -> 195416.48 | O27: =+O13+O15+O17 -> 170 | P27: =IF(O27<=0,0,Q27/O27) -> 1826.3022 | Q27: =Q13+Q17+Q24+Q19+Q15 -> 310471.37 | R27: =J27-O27 -> -58 | S27: =L27-Q27 -> -115054.89 | U27: =SUM(U13:U26) -> 193631 | V27: =L27-U27 -> 1785.48
A28: Véhicules neufs | B28: Véhicules neufs | R28: =R27/O27 -> -0.34117647 | S28: =IF(Q27=0,0,S27/Q27) -> -0.37058132
A29: Véhicules neufs | B29: Véhicules neufs
A30: Véhicules neufsDEPENSES | B30: Véhicules neufs | C30: DEPENSES
A31: Véhicules neufsComm. vendeurs | B31: Véhicules neufs | C31: Comm. vendeurs | D31: =F31/(F13+F15) -> #DIV/0! | E31: =F31/D$24 -> #DIV/0! | F31: 0 | J31: =L31/(L15+L13+L17) -> 0.27118334 | K31: =IF(L31=0,0,L31/J$24) -> 789.17093 | L31: 42615.23 | N31: =L31-F31 -> 42615.23 | O31: =Q31/(Q15+Q13+Q17) -> 0.22474853 | P31: =IF(Q31=0,0,Q31/O$24) -> 748.86026 | Q31: 57662.24 | S31: =L31-Q31 -> -15047.01
A32: Véhicules neufsComm. F&I | B32: Véhicules neufs | C32: Comm. F&I | D32: =F32/F24 -> #DIV/0! | E32: =F32/D$24 -> #DIV/0! | F32: 0 | J32: =L32/L24 -> 0.32469947 | K32: =IF(L32=0,0,L32/J$24) -> 230.12185 | L32: 12426.58 | N32: =L32-F32 -> 12426.58 | O32: =Q32/Q24 -> 0.22351729 | P32: =IF(Q32=0,0,Q32/O$24) -> 156.48532 | Q32: 12049.37 | S32: =L32-Q32 -> 377.21
A33: Véhicules neufsFrais de livraison | B33: Véhicules neufs | C33: Frais de livraison | E33: =F33/D$24 -> #DIV/0! | F33: 0 | K33: =IF(L33=0,0,L33/J$24) -> 1001.7337 | L33: 54093.62 | N33: =L33-F33 -> 54093.62 | P33: =IF(Q33=0,0,Q33/O$24) -> -204.81558 | Q33: -15770.8 | S33: =L33-Q33 -> 69864.42 | U33: Frais document reclassé
A34: Véhicules neufsService gratuit 1 | B34: Véhicules neufs | C34: Service gratuit 1 | E34: =F34/D$24 -> #DIV/0! | F34: 0 | K34: =IF(L34=0,0,L34/J$24) -> 18.55963 | L34: 1002.22 | N34: =L34-F34 -> 1002.22 | P34: =IF(Q34=0,0,Q34/O$24) -> 8.701039 | Q34: 669.98 | S34: =L34-Q34 -> 332.24
A35: Véhicules neufsEntretien stock | B35: Véhicules neufs | C35: Entretien stock | E35: =F35/D$24 -> #DIV/0! | F35: 0 | K35: =IF(L35=0,0,L35/J$24) -> 92.806111 | L35: 5011.53 | N35: =L35-F35 -> 5011.53 | P35: =IF(Q35=0,0,Q35/O$24) -> 0 | Q35: 0 | S35: =L35-Q35 -> 5011.53
A36: Véhicules neufsPublicité 1 | B36: Véhicules neufs | C36: Publicité 1 | E36: =F36/D$24 -> #DIV/0! | F36: 0 | K36: =IF(L36=0,0,L36/J$24) -> 277.72907 | L36: 14997.37 | N36: =L36-F36 -> 14997.37 | P36: =IF(Q36=0,0,Q36/O$24) -> 241.33805 | Q36: 18583.03 | S36: =L36-Q36 -> -3585.66
A37: Véhicules neufsIntérêt de gros | B37: Véhicules neufs | C37: Intérêt de gros | E37: =F37/D$24 -> #DIV/0! | F37: 0 | K37: =IF(L37=0,0,L37/J$24) -> 1041.1037 | L37: 56219.6 | N37: =L37-F37 -> 56219.6 | P37: =IF(Q37=0,0,Q37/O$24) -> 824.55675 | Q37: 63490.87 | S37: =L37-Q37 -> -7271.27
A38: Véhicules neufs[...] | B38: Véhicules neufs | C38: Crédit Intérêts Floor Plan | E38: =F38/D$24 -> #DIV/0! | F38: 0 | K38: =IF(L38=0,0,L38/J$24) -> -2437.6989 | L38: -131635.74 | N38: =L38-F38 -> -131635.74 | P38: =IF(Q38=0,0,Q38/O$24) -> -1524.5636 | Q38: -117391.4 | S38: =L38-Q38 -> -14244.34
A39: Véhicules neufs[...] | B39: Véhicules neufs | C39: Crédit Boni TD | E39: =F39/D$24 -> #DIV/0! | F39: 0 | K39: =IF(L39=0,0,L39/J$24) -> -208.49852 | L39: -11258.92 | N39: =L39-F39 -> -11258.92 | P39: =IF(Q39=0,0,Q39/O$24) -> 0 | Q39: 0 | S39: =L39-Q39 -> -11258.92 | T39: -11259 | U39: =L39+L121+L194 -> -16826.18 | V39: Crédit de juin - décalé d'un mois ??
A40: Véhicules neufs[...] | B40: Véhicules neufs | C40: [...] | E40: =F40/D$24 -> #DIV/0! | F40: 0 | K40: =IF(L40=0,0,L40/J$24) -> 0 | L40: 0 | N40: =L40-F40 -> 0 | P40: =IF(Q40=0,0,Q40/O$24) -> 0 | Q40: 0 | S40: =L40-Q40 -> 0
...

Sheet Mois 2
C1: Ste-Marie Auto | K1: Véhicules neufs | S1: Réalisé, Aout 2026
D2: X | E2: O | F2: U | J2: NB | L2: $ | O2: NB | Q2: $ | V2: *** NE PAS EFFACER / Pour An Précédente ***
D3: BUDGET ORIGINAL | J3: RÉALISATION | M3: ÉCART réel / Budget | O3: ANNÉE PRÉCÉDENTE | R3: ECART (réel/ Ann.Préc.) | V3: NEUF | W3: 0.45
D4: UNITE | E4: $P/UNITÉ | F4: $PROFITS | J4: UNITÉS | K4: $P/UNITE | L4: $PROFITS | M4: UNITÉS | N4: $PROFITS | O4: UNITÉS | P4: $P/UNITE | Q4: $PROFITS | R4: UNITÉS | S4: $PROFITS | V4: USAGE | W4: 0.1
A5: Véhicules neufsVentes nettes | B5: Véhicules neufs | C5: Ventes nettes | F5: #N/A | L5: 5549753.4 | Q5: 8048046.4 | U5: =L5/AF493 -> 0.3978662 | V5: SERVICE | W5: 0.225
A6: Véhicules neufsAutos détail | B6: Véhicules neufs | C6: Autos détail | D6: #N/A | E6: =IF(D6=0,0,F6/D6) -> #N/A | F6: #N/A | J6: 0 | K6: =IF(J6=0,0,L6/J6) -> 0 | L6: 0 | M6: =J6-D6 -> #N/A | N6: =L6-F6 -> #N/A | O6: 2 | P6: =IF(O6=0,0,Q6/O6) -> 5561 | Q6: 11122 | R6: =J6-O6 -> -2 | S6: =L6-Q6 -> -11122 | V6: CARROSSERIE | W6: 0.025
A7: Véhicules neufsCamions détail | B7: Véhicules neufs | C7: Camions détail | D7: #N/A | E7: =IF(D7=0,0,F7/D7) -> #N/A | F7: #N/A | J7: 26 | K7: =IF(J7=0,0,L7/J7) -> 2497.6038 | L7: 64937.7 | M7: =J7-D7 -> #N/A | N7: =L7-F7 -> #N/A | O7: 67 | P7: =IF(O7=0,0,Q7/O7) -> 2643.707 | Q7: 177128.37 | R7: =J7-O7 -> -41 | S7: =L7-Q7 -> -112190.67 | V7: PIECES | W7: 0.2
A8: Véhicules neufsSprinter | B8: Véhicules neufs | C8: Voitures electriques | D8: #N/A | E8: =IF(D8=0,0,F8/D8) -> #N/A | F8: #N/A | J8: 0 | K8: =IF(J8=0,0,L8/J8) -> 0 | L8: 0 | M8: =J8-D8 -> #N/A | N8: =L8-F8 -> #N/A | O8: 0 | P8: =IF(O8=0,0,Q8/O8) -> 0 | Q8: 0 | R8: =J8-O8 -> 0 | S8: =L8-Q8 -> 0 | W8: =SUM(W3:W7) -> 1
A9: Véhicules neufsMoto détail | B9: Véhicules neufs | C9: Camions electriques | D9: #N/A | E9: =IF(D9=0,0,F9/D9) -> #N/A | F9: #N/A | J9: 27 | K9: =IF(J9=0,0,L9/J9) -> 1229.7707 | L9: 33203.81 | M9: =J9-D9 -> #N/A | N9: =L9-F9 -> #N/A | O9: 11 | P9: =IF(O9=0,0,Q9/O9) -> 900.23727 | Q9: 9902.61 | R9: =J9-O9 -> 16 | S9: =L9-Q9 -> 23301.2 | U9: Livre des ventes
A10: Véhicules neufs[...] | B10: Véhicules neufs | C10: [...] | D10: #N/A | E10: =IF(D10=0,0,F10/D10) -> #N/A | F10: #N/A | J10: 0 | K10: =IF(J10=0,0,L10/J10) -> 0 | L10: 0 | M10: =J10-D10 -> #N/A | N10: =L10-F10 -> #N/A | O10: 0 | P10: =IF(O10=0,0,Q10/O10) -> 0 | Q10: 0 | R10: =J10-O10 -> 0 | S10: =L10-Q10 -> 0
A11: Véhicules neufs[...] | B11: Véhicules neufs | C11: [...] | D11: #N/A | E11: =IF(D11=0,0,F11/D11) -> #N/A | F11: #N/A | J11: 0 | K11: =IF(J11=0,0,L11/J11) -> 0 | L11: 0 | M11: =J11-D11 -> #N/A | N11: =L11-F11 -> #N/A | O11: 0 | P11: =IF(O11=0,0,Q11/O11) -> 0 | Q11: 0 | R11: =J11-O11 -> 0 | S11: =L11-Q11 -> 0
A12: Véhicules neufs[...] | B12: Véhicules neufs | C12: [...] | D12: #N/A | E12: =IF(D12=0,0,F12/D12) -> #N/A | F12: #N/A | J12: 0 | K12: =IF(J12=0,0,L12/J12) -> 0 | L12: 0 | M12: =J12-D12 -> #N/A | N12: =L12-F12 -> #N/A | O12: 0 | P12: =IF(O12=0,0,Q12/O12) -> 0 | Q12: 0 | R12: =J12-O12 -> 0 | S12: =L12-Q12 -> 0
A13: Véhicules neufsTotal Neufs | B13: Véhicules neufs | C13: Total Neufs | D13: =+SUM(D6:D12) -> #N/A | E13: =IF(D13<=0,0,F13/D13) -> #N/A | F13: =+SUM(F6:F12) -> #N/A | J13: =+SUM(J6:J12) -> 53 | K13: =IF(J13<=0,0,L13/J13) -> 1851.7266 | L13: =+SUM(L6:L12) -> 98141.51 | M13: =+SUM(M6:M12) -> #N/A | N13: =+SUM(N6:N12) -> #N/A | O13: =+SUM(O6:O12) -> 80 | P13: =IF(O13<=0,0,Q13/O13) -> 2476.9123 | Q13: =+SUM(Q6:Q12) -> 198152.98 | R13: =+SUM(R6:R12) -> -27 | S13: =+SUM(S6:S12) -> -100011.47 | T13: 53 | U13: 98142 | V13: =L13-U13 -> -0.49
A14: Véhicules neufs | B14: Véhicules neufs | M14: =IF(D13=0,0,M13/D13) -> #N/A | N14: =IF(F13=0,0,N13/F13) -> #N/A | R14: =R13/O13 -> -0.3375 | S14: =IF(Q13=0,0,(S13/Q13)) -> -0.50471848
A15: Véhicules neufsEx-Démos et courtoisies | B15: Véhicules neufs | C15: Ex-Démos et courtoisies | D15: #N/A | E15: =IF(D15=0,0,F15/D15) -> #N/A | F15: #N/A | J15: 0 | K15: =IF(J15=0,0,L15/J15) -> 0 | L15: 0 | M15: =J15-D15 -> #N/A | N15: =L15-F15 -> #N/A | O15: 0 | P15: =IF(O15=0,0,Q15/O15) -> 0 | Q15: 0 | R15: =J15-O15 -> 0 | S15: =L15-Q15 -> 0
A16: Véhicules neufs | B16: Véhicules neufs
A17: Véhicules neufsFlottes | B17: Véhicules neufs | C17: Flottes | D17: #N/A | E17: =IF(D17=0,0,F17/D17) -> #N/A | F17: #N/A | J17: 34 | K17: =IF(J17=0,0,L17/J17) -> 587.26382 | L17: 19966.97 | M17: =J17-D17 -> #N/A | N17: =L17-F17 -> #N/A | O17: 54 | P17: =IF(O17=0,0,Q17/O17) -> 617.8963 | Q17: 33366.4 | R17: =J17-O17 -> -20 | S17: =L17-Q17 -> -13399.43 | T17: 34 | U17: 18817 | V17: =L17-U17 -> 1149.97
A18: Véhicules neufs | B18: Véhicules neufs
A19: Véhicules neufsRachat bail | B19: Véhicules neufs
A20: Véhicules neufs | B20: Véhicules neufs
A21: Véhicules neufsRev. Finances | B21: Véhicules neufs | C21: Rev. Finances | D21: #N/A | E21: =IF(D21=0,0,F21/D21) -> #N/A | F21: #N/A | K21: =IF(J13=0,0,L21/(J13+J15)) -> 0 | L21: 0 | N21: =L21-F21 -> #N/A | P21: =IF(O13=0,0,Q21/(O13+O15)) -> 1.3225 | Q21: 105.8 | R21: =P21-K21 -> 1.3225 | S21: =L21-Q21 -> -105.8
A22: Véhicules neufsRev. Protections | B22: Véhicules neufs | C22: Rev. Protections | D22: #N/A | E22: =IF(D22=0,0,F22/D22) -> #N/A | F22: #N/A | K22: =IF(J13=0,0,L22/(J13+J15)) -> 538.27321 | L22: 28528.48 | N22: =L22-F22 -> #N/A | P22: =IF(O13=0,0,Q22/(O13+O15)) -> 752.63388 | Q22: 60210.71 | R22: =P22-K22 -> 214.36067 | S22: =L22-Q22 -> -31682.23
A23: Véhicules neufsRev. Autres | B23: Véhicules neufs | C23: Rev. Autres | D23: #N/A | E23: =IF(D23=0,0,F23/D23) -> #N/A | F23: #N/A | K23: =IF(J13=0,0,L23/(J13+J15)) -> -21.713396 | L23: -1150.81 | N23: =L23-F23 -> #N/A | P23: =IF(O13=0,0,Q23/(O13+O15)) -> 180.2505 | Q23: 14420.04 | R23: =P23-K23 -> 201.9639 | S23: =L23-Q23 -> -15570.85
A24: Véhicules neufsTotal F&I | B24: Véhicules neufs | C24: Total F&I | D24: =+D15+D13 -> #N/A | E24: =IF(D24<=0,0,F24/D24) -> #N/A | F24: =F21+F22+F23 -> #N/A | J24: =+J15+J13 -> 53 | K24: =IF(J24<=0,0,L24/J24) -> 516.55981 | L24: =L21+L22+L23 -> 27377.67 | M24: =J24-D24 -> #N/A | N24: =L24-F24 -> #N/A | O24: =+O15+O13 -> 80 | P24: =IF(O24<=0,0,Q24/O24) -> 934.20688 | Q24: =Q21+Q22+Q23 -> 74736.55 | R24: =P24-K24 -> 417.64706 | S24: =L24-Q24 -> -47358.88 | U24: 27378 | V24: =L24-U24 -> -0.33
A25: Véhicules neufs | B25: Véhicules neufs | N25: =IF(N24=0,0,N24/F24) -> #N/A | S25: =IF(Q24=0,0,(S24/Q24)) -> -0.63367763
A26: Véhicules neufs | B26: Véhicules neufs
A27: Véhicules neufsTotal Dépt. Neufs | B27: Véhicules neufs | C27: Total Dépt. Neufs | D27: =+D13+D15+D17 -> #N/A | E27: =IF(D27<=0,0,F27/D27) -> #N/A | F27: =F13+F17+F24+F19+F15 -> #N/A | J27: =+J13+J15+J17 -> 87 | K27: =IF(J27<=0,0,L27/J27) -> 1672.2546 | L27: =L13+L17+L24+L19+L15 -> 145486.15 | M27: =J27-D27 -> #N/A | N27: =L27-F27 -> #N/A | O27: =+O13+O15+O17 -> 134 | P27: =IF(O27<=0,0,Q27/O27) -> 2285.492 | Q27: =Q13+Q17+Q24+Q19+Q15 -> 306255.93 | R27: =J27-O27 -> -47 | S27: =L27-Q27 -> -160769.78 | U27: =SUM(U13:U26) -> 144337 | V27: =L27-U27 -> 1149.15
A28: Véhicules neufs | B28: Véhicules neufs | R28: =R27/O27 -> -0.35074627 | S28: =IF(Q27=0,0,S27/Q27) -> -0.52495238
A29: Véhicules neufs | B29: Véhicules neufs
A30: Véhicules neufsDEPENSES | B30: Véhicules neufs | C30: DEPENSES
A31: Véhicules neufsComm. vendeurs | B31: Véhicules neufs | C31: Comm. vendeurs | D31: =F31/(F13+F15) -> #N/A | E31: =F31/D$24 -> #N/A | F31: #N/A | J31: =L31/(L15+L13+L17) -> 0.36190416 | K31: =IF(L31=0,0,L31/J$24) -> 806.48962 | L31: 42743.95 | N31: =L31-F31 -> #N/A | O31: =Q31/(Q15+Q13+Q17) -> 0.22591202 | P31: =IF(Q31=0,0,Q31/O$24) -> 653.78763 | Q31: 52303.01 | S31: =L31-Q31 -> -9559.06
A32: Véhicules neufsComm. F&I | B32: Véhicules neufs | C32: Comm. F&I | D32: =F32/F24 -> #N/A | E32: =F32/D$24 -> #N/A | F32: #N/A | J32: =L32/L24 -> 0.33094818 | K32: =IF(L32=0,0,L32/J$24) -> 170.95453 | L32: 9060.59 | N32: =L32-F32 -> #N/A | O32: =Q32/Q24 -> 0.24125358 | P32: =IF(Q32=0,0,Q32/O$24) -> 225.38075 | Q32: 18030.46 | S32: =L32-Q32 -> -8969.87
A33: Véhicules neufsFrais de livraison | B33: Véhicules neufs | C33: Frais de livraison | E33: =F33/D$24 -> #N/A | F33: #N/A | K33: =IF(L33=0,0,L33/J$24) -> -63.636981 | L33: -3372.76 | N33: =L33-F33 -> #N/A | P33: =IF(Q33=0,0,Q33/O$24) -> -114.10925 | Q33: -9128.74 | S33: =L33-Q33 -> 5755.98 | T33: =-3973+600 -> -3373 | U33: Frais document reclassé - correction charge de juillet
A34: Véhicules neufsService gratuit 1 | B34: Véhicules neufs | C34: Service gratuit 1 | E34: =F34/D$24 -> #N/A | F34: #N/A | K34: =IF(L34=0,0,L34/J$24) -> 0 | L34: 0 | N34: =L34-F34 -> #N/A | P34: =IF(Q34=0,0,Q34/O$24) -> 7.719375 | Q34: 617.55 | S34: =L34-Q34 -> -617.55
A35: Véhicules neufsEntretien stock | B35: Véhicules neufs | C35: Entretien stock | E35: =F35/D$24 -> #N/A | F35: #N/A | K35: =IF(L35=0,0,L35/J$24) -> 54.977925 | L35: 2913.83 | N35: =L35-F35 -> #N/A | P35: =IF(Q35=0,0,Q35/O$24) -> 0 | Q35: 0 | S35: =L35-Q35 -> 2913.83
A36: Véhicules neufsPublicité 1 | B36: Véhicules neufs | C36: Publicité 1 | E36: =F36/D$24 -> #N/A | F36: #N/A | K36: =IF(L36=0,0,L36/J$24) -> 241.13075 | L36: 12779.93 | N36: =L36-F36 -> #N/A | P36: =IF(Q36=0,0,Q36/O$24) -> 184.15988 | Q36: 14732.79 | S36: =L36-Q36 -> -1952.86
A37: Véhicules neufsIntérêt de gros | B37: Véhicules neufs | C37: Intérêt de gros | E37: =F37/D$24 -> #N/A | F37: #N/A | K37: =IF(L37=0,0,L37/J$24) -> 500.4666 | L37: 26524.73 | N37: =L37-F37 -> #N/A | P37: =IF(Q37=0,0,Q37/O$24) -> 944.36875 | Q37: 75549.5 | S37: =L37-Q37 -> -49024.77
A38: Véhicules neufs[...] | B38: Véhicules neufs | C38: Crédit Intérêts Floor Plan | E38: =F38/D$24 -> #N/A | F38: #N/A | K38: =IF(L38=0,0,L38/J$24) -> -1248.8064 | L38: -66186.74 | N38: =L38-F38 -> #N/A | P38: =IF(Q38=0,0,Q38/O$24) -> -1344.5761 | Q38: -107566.09 | S38: =L38-Q38 -> 41379.35 | T38: 64032
A39: Véhicules neufs[...] | B39: Véhicules neufs | C39: Crédit Boni TD | E39: =F39/D$24 -> #N/A | F39: #N/A | K39: =IF(L39=0,0,L39/J$24) -> -194.33566 | L39: -10299.79 | N39: =L39-F39 -> #N/A | P39: =IF(Q39=0,0,Q39/O$24) -> 0 | Q39: 0 | S39: =L39-Q39 -> -10299.79 | T39: -10300 | U39: =L39+L121+L194 -> -13851.27
A40: Véhicules neufs[...] | B40: Véhicules neufs | C40: [...] | E40: =F40/D$24 -> #N/A | F40: #N/A | K40: =IF(L40=0,0,L40/J$24) -> 0 | L40: 0 | N40: =L40-F40 -> #N/A | P40: =IF(Q40=0,0,Q40/O$24) -> 0 | Q40: 0 | S40: =L40-Q40 -> 0
...

Sheet Mois 3
C1: Ste-Marie Auto | K1: Véhicules neufs | S1: Réalisé, Septembre 2026
D2: X | E2: O | F2: U | J2: NB | L2: $ | O2: NB | Q2: $ | V2: *** NE PAS EFFACER / Pour An Précédente ***
D3: BUDGET ORIGINAL | J3: RÉALISATION | M3: ÉCART réel / Budget | O3: ANNÉE PRÉCÉDENTE | R3: ECART (réel/ Ann.Préc.) | V3: NEUF | W3: 0.45
D4: UNITE | E4: $P/UNITÉ | F4: $PROFITS | J4: UNITÉS | K4: $P/UNITE | L4: $PROFITS | M4: UNITÉS | N4: $PROFITS | O4: UNITÉS | P4: $P/UNITE | Q4: $PROFITS | R4: UNITÉS | S4: $PROFITS | V4: USAGE | W4: 0.1
A5: Véhicules neufsVentes nettes | B5: Véhicules neufs | C5: Ventes nettes | F5: 0 | L5: 7465717.8 | Q5: 8922542.5 | U5: =L5/AF493 -> 0.66682387 | V5: SERVICE | W5: 0.225
A6: Véhicules neufsAutos détail | B6: Véhicules neufs | C6: Autos détail | D6: 0 | E6: =IF(D6=0,0,F6/D6) -> 0 | F6: 0 | J6: 1 | K6: =IF(J6=0,0,L6/J6) -> 11544.36 | L6: 11544.36 | M6: =J6-D6 -> 1 | N6: =L6-F6 -> 11544.36 | O6: 0 | P6: =IF(O6=0,0,Q6/O6) -> 0 | Q6: 0 | R6: =J6-O6 -> 1 | S6: =L6-Q6 -> 11544.36 | V6: CARROSSERIE | W6: 0.025
A7: Véhicules neufsCamions détail | B7: Véhicules neufs | C7: Camions détail | D7: 0 | E7: =IF(D7=0,0,F7/D7) -> 0 | F7: 0 | J7: 30 | K7: =IF(J7=0,0,L7/J7) -> 1763.614 | L7: 52908.42 | M7: =J7-D7 -> 30 | N7: =L7-F7 -> 52908.42 | O7: 38 | P7: =IF(O7=0,0,Q7/O7) -> 2884.9066 | Q7: 109626.45 | R7: =J7-O7 -> -8 | S7: =L7-Q7 -> -56718.03 | V7: PIECES | W7: 0.2
A8: Véhicules neufsSprinter | B8: Véhicules neufs | C8: Voitures electriques | D8: 0 | E8: =IF(D8=0,0,F8/D8) -> 0 | F8: 0 | J8: 0 | K8: =IF(J8=0,0,L8/J8) -> 0 | L8: 0 | M8: =J8-D8 -> 0 | N8: =L8-F8 -> 0 | O8: 0 | P8: =IF(O8=0,0,Q8/O8) -> 0 | Q8: 0 | R8: =J8-O8 -> 0 | S8: =L8-Q8 -> 0 | W8: =SUM(W3:W7) -> 1
A9: Véhicules neufsMoto détail | B9: Véhicules neufs | C9: Camions electriques | D9: 0 | E9: =IF(D9=0,0,F9/D9) -> 0 | F9: 0 | J9: 48 | K9: =IF(J9=0,0,L9/J9) -> 1378.6771 | L9: 66176.5 | M9: =J9-D9 -> 48 | N9: =L9-F9 -> 66176.5 | O9: 24 | P9: =IF(O9=0,0,Q9/O9) -> 1502.1 | Q9: 36050.4 | R9: =J9-O9 -> 24 | S9: =L9-Q9 -> 30126.1 | U9: Livre des ventes
A10: Véhicules neufs[...] | B10: Véhicules neufs | C10: [...] | D10: 0 | E10: =IF(D10=0,0,F10/D10) -> 0 | F10: 0 | J10: 0 | K10: =IF(J10=0,0,L10/J10) -> 0 | L10: 0 | M10: =J10-D10 -> 0 | N10: =L10-F10 -> 0 | O10: 0 | P10: =IF(O10=0,0,Q10/O10) -> 0 | Q10: 0 | R10: =J10-O10 -> 0 | S10: =L10-Q10 -> 0
A11: Véhicules neufs[...] | B11: Véhicules neufs | C11: [...] | D11: 0 | E11: =IF(D11=0,0,F11/D11) -> 0 | F11: 0 | J11: 0 | K11: =IF(J11=0,0,L11/J11) -> 0 | L11: 0 | M11: =J11-D11 -> 0 | N11: =L11-F11 -> 0 | O11: 0 | P11: =IF(O11=0,0,Q11/O11) -> 0 | Q11: 0 | R11: =J11-O11 -> 0 | S11: =L11-Q11 -> 0
A12: Véhicules neufs[...] | B12: Véhicules neufs | C12: [...] | D12: 0 | E12: =IF(D12=0,0,F12/D12) -> 0 | F12: 0 | J12: 0 | K12: =IF(J12=0,0,L12/J12) -> 0 | L12: 0 | M12: =J12-D12 -> 0 | N12: =L12-F12 -> 0 | O12: 0 | P12: =IF(O12=0,0,Q12/O12) -> 0 | Q12: 0 | R12: =J12-O12 -> 0 | S12: =L12-Q12 -> 0
A13: Véhicules neufsTotal Neufs | B13: Véhicules neufs | C13: Total Neufs | D13: =+SUM(D6:D12) -> 0 | E13: =IF(D13<=0,0,F13/D13) -> 0 | F13: =+SUM(F6:F12) -> 0 | J13: =+SUM(J6:J12) -> 79 | K13: =IF(J13<=0,0,L13/J13) -> 1653.5352 | L13: =+SUM(L6:L12) -> 130629.28 | M13: =+SUM(M6:M12) -> 79 | N13: =+SUM(N6:N12) -> 130629.28 | O13: =+SUM(O6:O12) -> 62 | P13: =IF(O13<=0,0,Q13/O13) -> 2349.6266 | Q13: =+SUM(Q6:Q12) -> 145676.85 | R13: =+SUM(R6:R12) -> 17 | S13: =+SUM(S6:S12) -> -15047.57 | T13: 79 | U13: 130630 | V13: =L13-U13 -> -0.72
A14: Véhicules neufs | B14: Véhicules neufs | M14: =IF(D13=0,0,M13/D13) -> 0 | N14: =IF(F13=0,0,N13/F13) -> 0 | R14: =R13/O13 -> 0.27419355 | S14: =IF(Q13=0,0,(S13/Q13)) -> -0.10329417
A15: Véhicules neufsEx-Démos et courtoisies | B15: Véhicules neufs | C15: Ex-Démos et courtoisies | D15: 0 | E15: =IF(D15=0,0,F15/D15) -> 0 | F15: 0 | J15: 0 | K15: =IF(J15=0,0,L15/J15) -> 0 | L15: 0 | M15: =J15-D15 -> 0 | N15: =L15-F15 -> 0 | O15: 0 | P15: =IF(O15=0,0,Q15/O15) -> 0 | Q15: 0 | R15: =J15-O15 -> 0 | S15: =L15-Q15 -> 0
A16: Véhicules neufs | B16: Véhicules neufs
A17: Véhicules neufsFlottes | B17: Véhicules neufs | C17: Flottes | D17: 0 | E17: =IF(D17=0,0,F17/D17) -> 0 | F17: 0 | J17: 51 | K17: =IF(J17=0,0,L17/J17) -> 740.45647 | L17: 37763.28 | M17: =J17-D17 -> 51 | N17: =L17-F17 -> 37763.28 | O17: 82 | P17: =IF(O17=0,0,Q17/O17) -> 669.57854 | Q17: 54905.44 | R17: =J17-O17 -> -31 | S17: =L17-Q17 -> -17142.16 | T17: 51 | U17: 38372 | V17: =L17-U17 -> -608.72
A18: Véhicules neufs | B18: Véhicules neufs
A19: Véhicules neufsRachat bail | B19: Véhicules neufs
A20: Véhicules neufs | B20: Véhicules neufs
A21: Véhicules neufsRev. Finances | B21: Véhicules neufs | C21: Rev. Finances | D21: 0 | E21: =IF(D21=0,0,F21/D21) -> 0 | F21: 0 | K21: =IF(J13=0,0,L21/(J13+J15)) -> -16.825063 | L21: -1329.18 | N21: =L21-F21 -> -1329.18 | P21: =IF(O13=0,0,Q21/(O13+O15)) -> 0 | Q21: 0 | R21: =P21-K21 -> 16.825063 | S21: =L21-Q21 -> -1329.18
A22: Véhicules neufsRev. Protections | B22: Véhicules neufs | C22: Rev. Protections | D22: 0 | E22: =IF(D22=0,0,F22/D22) -> 0 | F22: 0 | K22: =IF(J13=0,0,L22/(J13+J15)) -> 563.21367 | L22: 44493.88 | N22: =L22-F22 -> 44493.88 | P22: =IF(O13=0,0,Q22/(O13+O15)) -> 752.96161 | Q22: 46683.62 | R22: =P22-K22 -> 189.74794 | S22: =L22-Q22 -> -2189.74
A23: Véhicules neufsRev. Autres | B23: Véhicules neufs | C23: Rev. Autres | D23: 0 | E23: =IF(D23=0,0,F23/D23) -> 0 | F23: 0 | K23: =IF(J13=0,0,L23/(J13+J15)) -> 68.392405 | L23: 5403 | N23: =L23-F23 -> 5403 | P23: =IF(O13=0,0,Q23/(O13+O15)) -> 71.569355 | Q23: 4437.3 | R23: =P23-K23 -> 3.1769498 | S23: =L23-Q23 -> 965.7
A24: Véhicules neufsTotal F&I | B24: Véhicules neufs | C24: Total F&I | D24: =+D15+D13 -> 0 | E24: =IF(D24<=0,0,F24/D24) -> 0 | F24: =F21+F22+F23 -> 0 | J24: =+J15+J13 -> 79 | K24: =IF(J24<=0,0,L24/J24) -> 614.78101 | L24: =L21+L22+L23 -> 48567.7 | M24: =J24-D24 -> 79 | N24: =L24-F24 -> 48567.7 | O24: =+O15+O13 -> 62 | P24: =IF(O24<=0,0,Q24/O24) -> 824.53097 | Q24: =Q21+Q22+Q23 -> 51120.92 | R24: =P24-K24 -> 209.74996 | S24: =L24-Q24 -> -2553.22 | U24: 48568 | V24: =L24-U24 -> -0.3
A25: Véhicules neufs | B25: Véhicules neufs | N25: =IF(N24=0,0,N24/F24) -> #DIV/0! | S25: =IF(Q24=0,0,(S24/Q24)) -> -0.049944719
A26: Véhicules neufs | B26: Véhicules neufs
A27: Véhicules neufsTotal Dépt. Neufs | B27: Véhicules neufs | C27: Total Dépt. Neufs | D27: =+D13+D15+D17 -> 0 | E27: =IF(D27<=0,0,F27/D27) -> 0 | F27: =F13+F17+F24+F19+F15 -> 0 | J27: =+J13+J15+J17 -> 130 | K27: =IF(J27<=0,0,L27/J27) -> 1668.9251 | L27: =L13+L17+L24+L19+L15 -> 216960.26 | M27: =J27-D27 -> 130 | N27: =L27-F27 -> 216960.26 | O27: =+O13+O15+O17 -> 144 | P27: =IF(O27<=0,0,Q27/O27) -> 1747.939 | Q27: =Q13+Q17+Q24+Q19+Q15 -> 251703.21 | R27: =J27-O27 -> -14 | S27: =L27-Q27 -> -34742.95 | U27: =SUM(U13:U26) -> 217570 | V27: =L27-U27 -> -609.74
A28: Véhicules neufs | B28: Véhicules neufs | R28: =R27/O27 -> -0.097222222 | S28: =IF(Q27=0,0,S27/Q27) -> -0.13803141
A29: Véhicules neufs | B29: Véhicules neufs
A30: Véhicules neufsDEPENSES | B30: Véhicules neufs | C30: DEPENSES
A31: Véhicules neufsComm. vendeurs | B31: Véhicules neufs | C31: Comm. vendeurs | D31: =F31/(F13+F15) -> #DIV/0! | E31: =F31/D$24 -> #DIV/0! | F31: 0 | J31: =L31/(L15+L13+L17) -> 0.24857316 | K31: =IF(L31=0,0,L31/J$24) -> 529.84646 | L31: 41857.87 | N31: =L31-F31 -> 41857.87 | O31: =Q31/(Q15+Q13+Q17) -> 0.30837922 | P31: =IF(Q31=0,0,Q31/O$24) -> 997.6679 | Q31: 61855.41 | S31: =L31-Q31 -> -19997.54
A32: Véhicules neufsComm. F&I | B32: Véhicules neufs | C32: Comm. F&I | D32: =F32/F24 -> #DIV/0! | E32: =F32/D$24 -> #DIV/0! | F32: 0 | J32: =L32/L24 -> 0.29101728 | K32: =IF(L32=0,0,L32/J$24) -> 178.9119 | L32: 14134.04 | N32: =L32-F32 -> 14134.04 | O32: =Q32/Q24 -> 0.33260532 | P32: =IF(Q32=0,0,Q32/O$24) -> 274.24339 | Q32: 17003.09 | S32: =L32-Q32 -> -2869.05
A33: Véhicules neufsFrais de livraison | B33: Véhicules neufs | C33: Frais de livraison | E33: =F33/D$24 -> #DIV/0! | F33: 0 | K33: =IF(L33=0,0,L33/J$24) -> 357.47633 | L33: 28240.63 | N33: =L33-F33 -> 28240.63 | P33: =IF(Q33=0,0,Q33/O$24) -> -34.543548 | Q33: -2141.7 | S33: =L33-Q33 -> 30382.33 | T33: =-3973+600 -> -3373 | U33: Frais document reclassé - correction charge de juillet
A34: Véhicules neufsService gratuit 1 | B34: Véhicules neufs | C34: Service gratuit 1 | E34: =F34/D$24 -> #DIV/0! | F34: 0 | K34: =IF(L34=0,0,L34/J$24) -> 6.6478481 | L34: 525.18 | N34: =L34-F34 -> 525.18 | P34: =IF(Q34=0,0,Q34/O$24) -> 5.5369355 | Q34: 343.29 | S34: =L34-Q34 -> 181.89
A35: Véhicules neufsEntretien stock | B35: Véhicules neufs | C35: Entretien stock | E35: =F35/D$24 -> #DIV/0! | F35: 0 | K35: =IF(L35=0,0,L35/J$24) -> 24.067342 | L35: 1901.32 | N35: =L35-F35 -> 1901.32 | P35: =IF(Q35=0,0,Q35/O$24) -> 0 | Q35: 0 | S35: =L35-Q35 -> 1901.32
A36: Véhicules neufsPublicité 1 | B36: Véhicules neufs | C36: Publicité 1 | E36: =F36/D$24 -> #DIV/0! | F36: 0 | K36: =IF(L36=0,0,L36/J$24) -> -838.35861 | L36: -66230.33 | N36: =L36-F36 -> -66230.33 | P36: =IF(Q36=0,0,Q36/O$24) -> -1597.1466 | Q36: -99023.09 | S36: =L36-Q36 -> 32792.76
A37: Véhicules neufsIntérêt de gros | B37: Véhicules neufs | C37: Intérêt de gros | E37: =F37/D$24 -> #DIV/0! | F37: 0 | K37: =IF(L37=0,0,L37/J$24) -> 522.56709 | L37: 41282.8 | N37: =L37-F37 -> 41282.8 | P37: =IF(Q37=0,0,Q37/O$24) -> 702.84984 | Q37: 43576.69 | S37: =L37-Q37 -> -2293.89
A38: Véhicules neufs[...] | B38: Véhicules neufs | C38: Crédit Intérêts Floor Plan | E38: =F38/D$24 -> #DIV/0! | F38: 0 | K38: =IF(L38=0,0,L38/J$24) -> -1624.303 | L38: -128319.94 | N38: =L38-F38 -> -128319.94 | P38: =IF(Q38=0,0,Q38/O$24) -> -3558.1748 | Q38: -220606.84 | S38: =L38-Q38 -> 92286.9 | T38: 55741
A39: Véhicules neufs[...] | B39: Véhicules neufs | C39: Crédit Boni TD | E39: =F39/D$24 -> #DIV/0! | F39: 0 | K39: =IF(L39=0,0,L39/J$24) -> -121.06152 | L39: -9563.86 | N39: =L39-F39 -> -9563.86 | P39: =IF(Q39=0,0,Q39/O$24) -> 0 | Q39: 0 | S39: =L39-Q39 -> -9563.86 | T39: -9564 | U39: =L39+L121+L194 -> -11636.6
A40: Véhicules neufs[...] | B40: Véhicules neufs | C40: [...] | E40: =F40/D$24 -> #DIV/0! | F40: 0 | K40: =IF(L40=0,0,L40/J$24) -> 0 | L40: 0 | N40: =L40-F40 -> 0 | P40: =IF(Q40=0,0,Q40/O$24) -> 0 | Q40: 0 | S40: =L40-Q40 -> 0
...

Sheet END
