Workbook
Name Ticker: #REF!

Sheet Parametres
A1: Compagnie | B1: Ste-Marie Auto
M2: Mois | N2: YTD
A3: Mois Courant | B3: Décembre | C3: =+VLOOKUP(B3,$K$3:$L$14,2,0) -> 12 | K3: Janvier | L3: 1 | M3: =+IF($K3=$B$3,"X","") | N3: =+IF(K3=B3,"X",IF(L3<=$C$3,"X","")) -> X
A4: Année | B4: 2025 | K4: Février | L4: 2 | M4: =+IF($K4=$B$3,"X","") | N4: =+IF(K4=B4,"X",IF(L4<=$C$3,"X","")) -> X
K5: Mars | L5: 3 | M5: =+IF($K5=$B$3,"X","") | N5: =+IF(K5=B5,"X",IF(L5<=$C$3,"X","")) -> X
K6: Avril | L6: 4 | M6: =+IF($K6=$B$3,"X","") | N6: =+IF(K6=B6,"X",IF(L6<=$C$3,"X","")) -> X
K7: Mai | L7: 5 | M7: =+IF($K7=$B$3,"X","") | N7: =+IF(K7=B7,"X",IF(L7<=$C$3,"X","")) -> X
K8: Juin | L8: 6 | M8: =+IF($K8=$B$3,"X","") | N8: =+IF(K8=B8,"X",IF(L8<=$C$3,"X","")) -> X
A9: Sélectionner le mois en B3 | K9: Juillet | L9: 7 | M9: =+IF($K9=$B$3,"X","") | N9: =+IF(K9=B9,"X",IF(L9<=$C$3,"X","")) -> X
A10: Coller les balances de vérification respectives en cellule A1 dans les onglets BV_Data_An_Cour | K10: Août | L10: 8 | M10: =+IF($K10=$B$3,"X","") | N10: =+IF(K10=B10,"X",IF(L10<=$C$3,"X","")) -> X
A11: Vérifier s'il y a des #N/A dans les colonnes T à X des onlgets de BV | K11: Septembre | L11: 9 | M11: =+IF($K11=$B$3,"X","") | N11: =+IF(K11=B11,"X",IF(L11<=$C$3,"X","")) -> X
K12: Octobre | L12: 10 | M12: =+IF($K12=$B$3,"X","") | N12: =+IF(K12=B12,"X",IF(L12<=$C$3,"X","")) -> X
K13: Novembre | L13: 11 | M13: =+IF($K13=$B$3,"X","") | N13: =+IF(K13=B13,"X",IF(L13<=$C$3,"X","")) -> X
K14: Décembre | L14: 12 | M14: =+IF($K14=$B$3,"X","") -> X | N14: =+IF(K14=B14,"X",IF(L14<=$C$3,"X","")) -> X

Sheet Bilan
A1: BILAN
A2: =+Parametres!B1 -> Ste-Marie Auto
A3: =CONCATENATE("",,Parametres!B3," ",Parametres!B4) -> Décembre 2025
A5: Encaisse | B5: =SUMIFS(BV_Data_An_Cour!$AN:$AN,BV_Data_An_Cour!$AP:$AP,$A$1,BV_Data_An_Cour!$AQ:$AQ,$A5) -> 5616208.7 | D5: Marge de crédit | E5: =-SUMIFS(BV_Data_An_Cour!$AN:$AN,BV_Data_An_Cour!$AP:$AP,$A$1,BV_Data_An_Cour!$AQ:$AQ,$D5) -> 0
A6: Total Trésorerie et équivalent de Trésorerie | B6: =SUM(B5) -> 5616208.7
D7: Portion Court Terme de la Dette Long Terme | E7: =-SUMIFS(BV_Data_An_Cour!$AN:$AN,BV_Data_An_Cour!$AP:$AP,$A$1,BV_Data_An_Cour!$AQ:$AQ,$D7) -> 0
A8: Recevables Contrats en Transit | B8: =SUMIFS(BV_Data_An_Cour!$AN:$AN,BV_Data_An_Cour!$AP:$AP,$A$1,BV_Data_An_Cour!$AQ:$AQ,$A8) -> 788592.11
A9: Recevables Véhicules | B9: =SUMIFS(BV_Data_An_Cour!$AN:$AN,BV_Data_An_Cour!$AP:$AP,$A$1,BV_Data_An_Cour!$AQ:$AQ,$A9) -> 34777.63 | D9: Avances à payer | E9: =-SUMIFS(BV_Data_An_Cour!$AN:$AN,BV_Data_An_Cour!$AP:$AP,$A$1,BV_Data_An_Cour!$AQ:$AQ,$D9) -> 0
A10: Recevables Manufacturier | B10: =SUMIFS(BV_Data_An_Cour!$AN:$AN,BV_Data_An_Cour!$AP:$AP,$A$1,BV_Data_An_Cour!$AQ:$AQ,$A10) -> -56965.44 | D10: Comptes à Payer Fournisseurs | E10: =-SUMIFS(BV_Data_An_Cour!$AN:$AN,BV_Data_An_Cour!$AP:$AP,$A$1,BV_Data_An_Cour!$AQ:$AQ,$D10) -> 5711191.2
A11: Recevables Pièces et Service | B11: =SUMIFS(BV_Data_An_Cour!$AN:$AN,BV_Data_An_Cour!$AP:$AP,$A$1,BV_Data_An_Cour!$AQ:$AQ,$A11) -> 760891.2 | D11: Taxes de Vente à Payer | E11: =-SUMIFS(BV_Data_An_Cour!$AN:$AN,BV_Data_An_Cour!$AP:$AP,$A$1,BV_Data_An_Cour!$AQ:$AQ,$D11) -> -1695265.1
A12: Recevables Garantie Manufacturier | B12: =SUMIFS(BV_Data_An_Cour!$AN:$AN,BV_Data_An_Cour!$AP:$AP,$A$1,BV_Data_An_Cour!$AQ:$AQ,$A12) -> -9284.43 | D12: Impôts à payer | E12: =-SUMIFS(BV_Data_An_Cour!$AN:$AN,BV_Data_An_Cour!$AP:$AP,$A$1,BV_Data_An_Cour!$AQ:$AQ,$D12) -> 0
A13: Recevables Carrosserie | B13: =SUMIFS(BV_Data_An_Cour!$AN:$AN,BV_Data_An_Cour!$AP:$AP,$A$1,BV_Data_An_Cour!$AQ:$AQ,$A13) -> 35501.4 | D13: Dépôts de Client | E13: =-SUMIFS(BV_Data_An_Cour!$AN:$AN,BV_Data_An_Cour!$AP:$AP,$A$1,BV_Data_An_Cour!$AQ:$AQ,$D13) -> 0
A14: Recevables Intercos | B14: =SUMIFS(BV_Data_An_Cour!$AN:$AN,BV_Data_An_Cour!$AP:$AP,$A$1,BV_Data_An_Cour!$AQ:$AQ,$A14) -> 9552859.9 | D14: Payables Intercos | E14: =-SUMIFS(BV_Data_An_Cour!$AN:$AN,BV_Data_An_Cour!$AP:$AP,$A$1,BV_Data_An_Cour!$AQ:$AQ,$D14) -> 9732219.6 | G14: 30080
A15: Recevables Autres | B15: =SUMIFS(BV_Data_An_Cour!$AN:$AN,BV_Data_An_Cour!$AP:$AP,$A$1,BV_Data_An_Cour!$AQ:$AQ,$A15) -> 712073.66 | D15: Autres Comptes à Payer | E15: =-SUMIFS(BV_Data_An_Cour!$AN:$AN,BV_Data_An_Cour!$AP:$AP,$A$1,BV_Data_An_Cour!$AQ:$AQ,$D15) -> -57803.76 | G15: 33107
A16: Total Comptes à Recevoir | B16: =+SUM(B8:B15) -> 11818446 | D16: Total Comptes à Payer | E16: =+SUM(E10:E15) -> 13690342
A18: Inventaire Véhicules Neufs | B18: =SUMIFS(BV_Data_An_Cour!$AN:$AN,BV_Data_An_Cour!$AP:$AP,$A$1,BV_Data_An_Cour!$AQ:$AQ,$A18) -> 27819233 | D18: Effet à Payer Véhicules Neufs | E18: =-SUMIFS(BV_Data_An_Cour!$AN:$AN,BV_Data_An_Cour!$AP:$AP,$A$1,BV_Data_An_Cour!$AQ:$AQ,$D18) -> 27796998
A19: Inventaire Véhicules Usagés | B19: =SUMIFS(BV_Data_An_Cour!$AN:$AN,BV_Data_An_Cour!$AP:$AP,$A$1,BV_Data_An_Cour!$AQ:$AQ,$A19) -> 21035623 | D19: Effet à Payer Véhicules Usagés | E19: =-SUMIFS(BV_Data_An_Cour!$AN:$AN,BV_Data_An_Cour!$AP:$AP,$A$1,BV_Data_An_Cour!$AQ:$AQ,$D19) -> 19316937
A20: Inventaire Pièces, Pneus, Huile | B20: =SUMIFS(BV_Data_An_Cour!$AN:$AN,BV_Data_An_Cour!$AP:$AP,$A$1,BV_Data_An_Cour!$AQ:$AQ,$A20) -> 651553.54 | D20: Total Effets à Payer | E20: =+SUM(E18:E19) -> 47113935
A21: Total Inventaires | B21: =SUM(B18:B20) -> 49506410
D22: Salaires à Payer | E22: =-SUMIFS(BV_Data_An_Cour!$AN:$AN,BV_Data_An_Cour!$AP:$AP,$A$1,BV_Data_An_Cour!$AQ:$AQ,$D22) -> -2262416.8
A23: Avances à recevoir | B23: =SUMIFS(BV_Data_An_Cour!$AN:$AN,BV_Data_An_Cour!$AP:$AP,$A$1,BV_Data_An_Cour!$AQ:$AQ,$A23) -> 0 | D23: DAS à Payer | E23: =-SUMIFS(BV_Data_An_Cour!$AN:$AN,BV_Data_An_Cour!$AP:$AP,$A$1,BV_Data_An_Cour!$AQ:$AQ,$D23) -> 7093.33
A24: Travaux en Cours | B24: =SUMIFS(BV_Data_An_Cour!$AN:$AN,BV_Data_An_Cour!$AP:$AP,$A$1,BV_Data_An_Cour!$AQ:$AQ,$A24) -> 5681.21 | D24: Autres Courus | E24: =-SUMIFS(BV_Data_An_Cour!$AN:$AN,BV_Data_An_Cour!$AP:$AP,$A$1,BV_Data_An_Cour!$AQ:$AQ,$D24) -> 264053.15
A25: Sous-Traitance | B25: =SUMIFS(BV_Data_An_Cour!$AN:$AN,BV_Data_An_Cour!$AP:$AP,$A$1,BV_Data_An_Cour!$AQ:$AQ,$A25) -> 26584.49 | D25: [...] | E25: =-SUMIFS(BV_Data_An_Cour!$AN:$AN,BV_Data_An_Cour!$AP:$AP,$A$1,BV_Data_An_Cour!$AQ:$AQ,$D25) -> 0
A26: Frais Payés d'Avance | B26: =SUMIFS(BV_Data_An_Cour!$AN:$AN,BV_Data_An_Cour!$AP:$AP,$A$1,BV_Data_An_Cour!$AQ:$AQ,$A26) -> -61145.46 | D26: [...] | E26: =-SUMIFS(BV_Data_An_Cour!$AN:$AN,BV_Data_An_Cour!$AP:$AP,$A$1,BV_Data_An_Cour!$AQ:$AQ,$D26) -> 0
A27: [...] | B27: =SUMIFS(BV_Data_An_Cour!$AN:$AN,BV_Data_An_Cour!$AP:$AP,$A$1,BV_Data_An_Cour!$AQ:$AQ,$A27) -> 0 | D27: [...] | E27: =-SUMIFS(BV_Data_An_Cour!$AN:$AN,BV_Data_An_Cour!$AP:$AP,$A$1,BV_Data_An_Cour!$AQ:$AQ,$D27) -> 0
A28: [...] | B28: =SUMIFS(BV_Data_An_Cour!$AN:$AN,BV_Data_An_Cour!$AP:$AP,$A$1,BV_Data_An_Cour!$AQ:$AQ,$A28) -> 0 | D28: Total Frais Courus | E28: =SUM(E22:E24) -> -1991270.3
A29: [...] | B29: =SUMIFS(BV_Data_An_Cour!$AN:$AN,BV_Data_An_Cour!$AP:$AP,$A$1,BV_Data_An_Cour!$AQ:$AQ,$A29) -> 0
A30: Total Autres | B30: =SUM(B23:B29) -> -28879.76 | D30: Total Passif Court Terme | E30: =+E5+E7+E16+E20+E28 -> 58813007
A32: Total Actif Court Terme | B32: =+B6+B16+B21+B30 -> 66912185
D33: Impôts Futurs à payer | E33: =-SUMIFS(BV_Data_An_Cour!$AN:$AN,BV_Data_An_Cour!$AP:$AP,$A$1,BV_Data_An_Cour!$AQ:$AQ,$D33) -> 88167
A35: Terrain | B35: =SUMIFS(BV_Data_An_Cour!$AN:$AN,BV_Data_An_Cour!$AP:$AP,$A$1,BV_Data_An_Cour!$AQ:$AQ,$A35) -> 0 | D35: Avances Long Terme à Payer | E35: =-SUMIFS(BV_Data_An_Cour!$AN:$AN,BV_Data_An_Cour!$AP:$AP,$A$1,BV_Data_An_Cour!$AQ:$AQ,$D35) -> 0
A36: Bâtisse | B36: =SUMIFS(BV_Data_An_Cour!$AN:$AN,BV_Data_An_Cour!$AP:$AP,$A$1,BV_Data_An_Cour!$AQ:$AQ,$A36) -> 0 | D36: Hypothèque à Payer | E36: =-SUMIFS(BV_Data_An_Cour!$AN:$AN,BV_Data_An_Cour!$AP:$AP,$A$1,BV_Data_An_Cour!$AQ:$AQ,$D36) -> 0
A37: Améliorations Locatives | B37: =SUMIFS(BV_Data_An_Cour!$AN:$AN,BV_Data_An_Cour!$AP:$AP,$A$1,BV_Data_An_Cour!$AQ:$AQ,$A37) -> 133959.44 | D37: Dette à Long Terme | E37: =-SUMIFS(BV_Data_An_Cour!$AN:$AN,BV_Data_An_Cour!$AP:$AP,$A$1,BV_Data_An_Cour!$AQ:$AQ,$D37) -> 0
A38: Améliorations Locatives Permanentes | B38: =SUMIFS(BV_Data_An_Cour!$AN:$AN,BV_Data_An_Cour!$AP:$AP,$A$1,BV_Data_An_Cour!$AQ:$AQ,$A38) -> 0 | D38: Autres Dettes à Long Terme | E38: =-SUMIFS(BV_Data_An_Cour!$AN:$AN,BV_Data_An_Cour!$AP:$AP,$A$1,BV_Data_An_Cour!$AQ:$AQ,$D38) -> 0
A39: Équipements Service | B39: =SUMIFS(BV_Data_An_Cour!$AN:$AN,BV_Data_An_Cour!$AP:$AP,$A$1,BV_Data_An_Cour!$AQ:$AQ,$A39) -> 366219.78 | D39: [...] | E39: =-SUMIFS(BV_Data_An_Cour!$AN:$AN,BV_Data_An_Cour!$AP:$AP,$A$1,BV_Data_An_Cour!$AQ:$AQ,$D39) -> 0
A40: Mobilier | B40: =SUMIFS(BV_Data_An_Cour!$AN:$AN,BV_Data_An_Cour!$AP:$AP,$A$1,BV_Data_An_Cour!$AQ:$AQ,$A40) -> 52630.74 | D40: [...] | E40: =-SUMIFS(BV_Data_An_Cour!$AN:$AN,BV_Data_An_Cour!$AP:$AP,$A$1,BV_Data_An_Cour!$AQ:$AQ,$D40) -> 0
A41: Équipements Informatique | B41: =SUMIFS(BV_Data_An_Cour!$AN:$AN,BV_Data_An_Cour!$AP:$AP,$A$1,BV_Data_An_Cour!$AQ:$AQ,$A41) -> 66748.34 | D41: [...] | E41: =-SUMIFS(BV_Data_An_Cour!$AN:$AN,BV_Data_An_Cour!$AP:$AP,$A$1,BV_Data_An_Cour!$AQ:$AQ,$D41) -> 0
A42: Équipements Téléphonique | B42: =SUMIFS(BV_Data_An_Cour!$AN:$AN,BV_Data_An_Cour!$AP:$AP,$A$1,BV_Data_An_Cour!$AQ:$AQ,$A42) -> 0 | D42: Total Passif long terme | E42: =+SUM(E33:E38) -> 88167
A43: Enseigne | B43: =SUMIFS(BV_Data_An_Cour!$AN:$AN,BV_Data_An_Cour!$AP:$AP,$A$1,BV_Data_An_Cour!$AQ:$AQ,$A43) -> 6707.1
A44: Total Immobilisations Nettes | B44: =SUM(B35:B43) -> 626265.4
...

Sheet Budget original
B1: ="Budget 2024 Mensuel Révisé"&" "&Parametres!$B$1 -> Budget 2024 Mensuel Révisé Ste-Marie Auto
B2: Mois | F2: =+IF(Parametres!$B$3=F$6,"X","") | G2: =+IF(Parametres!$B$3=F$6,"O","") | H2: =+IF(Parametres!$B$3=F$6,"U","") | I2: =+IF(Parametres!$B$3=I$6,"X","") | J2: =+IF(Parametres!$B$3=I$6,"O","") | K2: =+IF(Parametres!$B$3=I$6,"U","") | L2: =+IF(Parametres!$B$3=L$6,"X","") | M2: =+IF(Parametres!$B$3=L$6,"O","") | N2: =+IF(Parametres!$B$3=L$6,"U","") | O2: =+IF(Parametres!$B$3=O$6,"X","") | P2: =+IF(Parametres!$B$3=O$6,"O","") | Q2: =+IF(Parametres!$B$3=O$6,"U","") | R2: =+IF(Parametres!$B$3=R$6,"X","") | S2: =+IF(Parametres!$B$3=R$6,"O","") | T2: =+IF(Parametres!$B$3=R$6,"U","") | U2: =+IF(Parametres!$B$3=U$6,"X","") | V2: =+IF(Parametres!$B$3=U$6,"O","") | W2: =+IF(Parametres!$B$3=U$6,"U","") | X2: =+IF(Parametres!$B$3=X$6,"X","") | Y2: =+IF(Parametres!$B$3=X$6,"O","") | Z2: =+IF(Parametres!$B$3=X$6,"U","") | AA2: =+IF(Parametres!$B$3=AA$6,"X","") | AB2: =+IF(Parametres!$B$3=AA$6,"O","") | AC2: =+IF(Parametres!$B$3=AA$6,"U","") | AD2: =+IF(Parametres!$B$3=AD$6,"X","") | AE2: =+IF(Parametres!$B$3=AD$6,"O","") | AF2: =+IF(Parametres!$B$3=AD$6,"U","") | AG2: =+IF(Parametres!$B$3=AG$6,"X","") | AH2: =+IF(Parametres!$B$3=AG$6,"O","") | AI2: =+IF(Parametres!$B$3=AG$6,"U","") | AJ2: =+IF(Parametres!$B$3=AJ$6,"X","") | AK2: =+IF(Parametres!$B$3=AJ$6,"O","") | AL2: =+IF(Parametres!$B$3=AJ$6,"U","") | AM2: =+IF(Parametres!$B$3=AM$6,"X","") -> X | AN2: =+IF(Parametres!$B$3=AM$6,"O","") -> O | AO2: =+IF(Parametres!$B$3=AM$6,"U","") -> U
B3: YTD | F3: =+IF(VLOOKUP(F$6,Parametres!$K$3:$N$14,4,0)="X","X","") -> X | G3: =+IF(VLOOKUP(F$6,Parametres!$K$3:$N$14,4,0)="X","O","") -> O | H3: =+IF(VLOOKUP(F$6,Parametres!$K$3:$N$14,4,0)="X","U","") -> U | I3: =+IF(VLOOKUP(I$6,Parametres!$K$3:$N$14,4,0)="X","X","") -> X | J3: =+IF(VLOOKUP(I$6,Parametres!$K$3:$N$14,4,0)="X","O","") -> O | K3: =+IF(VLOOKUP(I$6,Parametres!$K$3:$N$14,4,0)="X","U","") -> U | L3: =+IF(VLOOKUP(L$6,Parametres!$K$3:$N$14,4,0)="X","X","") -> X | M3: =+IF(VLOOKUP(L$6,Parametres!$K$3:$N$14,4,0)="X","O","") -> O | N3: =+IF(VLOOKUP(L$6,Parametres!$K$3:$N$14,4,0)="X","U","") -> U | O3: =+IF(VLOOKUP(O$6,Parametres!$K$3:$N$14,4,0)="X","X","") -> X | P3: =+IF(VLOOKUP(O$6,Parametres!$K$3:$N$14,4,0)="X","O","") -> O | Q3: =+IF(VLOOKUP(O$6,Parametres!$K$3:$N$14,4,0)="X","U","") -> U | R3: =+IF(VLOOKUP(R$6,Parametres!$K$3:$N$14,4,0)="X","X","") -> X | S3: =+IF(VLOOKUP(R$6,Parametres!$K$3:$N$14,4,0)="X","O","") -> O | T3: =+IF(VLOOKUP(R$6,Parametres!$K$3:$N$14,4,0)="X","U","") -> U | U3: =+IF(VLOOKUP(U$6,Parametres!$K$3:$N$14,4,0)="X","X","") -> X | V3: =+IF(VLOOKUP(U$6,Parametres!$K$3:$N$14,4,0)="X","O","") -> O | W3: =+IF(VLOOKUP(U$6,Parametres!$K$3:$N$14,4,0)="X","U","") -> U | X3: =+IF(VLOOKUP(X$6,Parametres!$K$3:$N$14,4,0)="X","X","") -> X | Y3: =+IF(VLOOKUP(X$6,Parametres!$K$3:$N$14,4,0)="X","O","") -> O | Z3: =+IF(VLOOKUP(X$6,Parametres!$K$3:$N$14,4,0)="X","U","") -> U | AA3: =+IF(VLOOKUP(AA$6,Parametres!$K$3:$N$14,4,0)="X","X","") -> X | AB3: =+IF(VLOOKUP(AA$6,Parametres!$K$3:$N$14,4,0)="X","O","") -> O | AC3: =+IF(VLOOKUP(AA$6,Parametres!$K$3:$N$14,4,0)="X","U","") -> U | AD3: =+IF(VLOOKUP(AD$6,Parametres!$K$3:$N$14,4,0)="X","X","") -> X | AE3: =+IF(VLOOKUP(AD$6,Parametres!$K$3:$N$14,4,0)="X","O","") -> O | AF3: =+IF(VLOOKUP(AD$6,Parametres!$K$3:$N$14,4,0)="X","U","") -> U | AG3: =+IF(VLOOKUP(AG$6,Parametres!$K$3:$N$14,4,0)="X","X","") -> X | AH3: =+IF(VLOOKUP(AG$6,Parametres!$K$3:$N$14,4,0)="X","O","") -> O | AI3: =+IF(VLOOKUP(AG$6,Parametres!$K$3:$N$14,4,0)="X","U","") -> U | AJ3: =+IF(VLOOKUP(AJ$6,Parametres!$K$3:$N$14,4,0)="X","X","") -> X | AK3: =+IF(VLOOKUP(AJ$6,Parametres!$K$3:$N$14,4,0)="X","O","") -> O | AL3: =+IF(VLOOKUP(AJ$6,Parametres!$K$3:$N$14,4,0)="X","U","") -> U | AM3: =+IF(VLOOKUP(AM$6,Parametres!$K$3:$N$14,4,0)="X","X","") -> X | AN3: =+IF(VLOOKUP(AM$6,Parametres!$K$3:$N$14,4,0)="X","O","") -> O | AO3: =+IF(VLOOKUP(AM$6,Parametres!$K$3:$N$14,4,0)="X","U","") -> U
B4: Budget 2025 | C4: Véhicules neufs
B6: Mois | C6: TOTAL | F6: Janvier | I6: Février | L6: Mars | O6: Avril | R6: Mai | U6: Juin | X6: Juillet | AA6: Août | AD6: Septembre | AG6: Octobre | AJ6: Novembre | AM6: Décembre
C7: UNITE | D7: $P/UNITE | E7: $PROFITS | F7: UNITE | G7: $P/UNITE | H7: $PROFITS | I7: UNITE | J7: $P/UNITE | K7: $PROFITS | L7: UNITE | M7: $P/UNITE | N7: $PROFITS | O7: UNITE | P7: $P/UNITE | Q7: $PROFITS | R7: UNITE | S7: $P/UNITE | T7: $PROFITS | U7: UNITE | V7: $P/UNITE | W7: $PROFITS | X7: UNITE | Y7: $P/UNITE | Z7: $PROFITS | AA7: UNITE | AB7: $P/UNITE | AC7: $PROFITS | AD7: UNITE | AE7: $P/UNITE | AF7: $PROFITS | AG7: UNITE | AH7: $P/UNITE | AI7: $PROFITS | AJ7: UNITE | AK7: $P/UNITE | AL7: $PROFITS | AM7: UNITE | AN7: $P/UNITE | AO7: $PROFITS
A8: =+$C$4&B8 -> Véhicules neufsVentes nettes | B8: Ventes nettes
A9: =+$C$4&B9 -> Véhicules neufsAutos détail | B9: Autos détail
A10: =+$C$4&B10 -> Véhicules neufsCamions détail | B10: Camions détail
A11: =+$C$4&B11 -> Véhicules neufsSprinter | B11: Sprinter
A12: =+$C$4&B12 -> Véhicules neufsMoto détail | B12: Moto détail
A13: =+$C$4&B13 -> Véhicules neufs[...] | B13: [...]
A14: =+$C$4&B14 -> Véhicules neufs[...] | B14: [...]
A15: =+$C$4&B15 -> Véhicules neufs[...] | B15: [...]
A16: =+$C$4&B16 -> Véhicules neufsTotal Neufs | B16: Total Neufs
A17: =+$C$4&B17 -> Véhicules neufs
A18: =+$C$4&B18 -> Véhicules neufsEx-Démos et courtoisies | B18: Ex-Démos et courtoisies
A19: =+$C$4&B19 -> Véhicules neufs
A20: =+$C$4&B20 -> Véhicules neufsFlottes | B20: Flottes
A21: =+$C$4&B21 -> Véhicules neufs
A22: =+$C$4&B22 -> Véhicules neufsRachat bail | B22: Rachat bail
A23: =+$C$4&B23 -> Véhicules neufs
A24: =+$C$4&B24 -> Véhicules neufsRev. Finances | B24: Rev. Finances
A25: =+$C$4&B25 -> Véhicules neufsRev. Protections | B25: Rev. Protections
A26: =+$C$4&B26 -> Véhicules neufsRev. Autres | B26: Rev. Autres
A27: =+$C$4&B27 -> Véhicules neufsTotal F&I | B27: Total F&I
A28: =+$C$4&B28 -> Véhicules neufs
A29: =+$C$4&B29 -> Véhicules neufs
A30: =+$C$4&B30 -> Véhicules neufsTotal Dépt. Neufs | B30: Total Dépt. Neufs
A31: =+$C$4&B31 -> Véhicules neufs
A32: =+$C$4&B32 -> Véhicules neufs
A33: =+$C$4&B33 -> Véhicules neufsDEPENSES | B33: DEPENSES
A34: =+$C$4&B34 -> Véhicules neufsComm. vendeurs | B34: Comm. vendeurs
A35: =+$C$4&B35 -> Véhicules neufsComm. F&I | B35: Comm. F&I
A36: =+$C$4&B36 -> Véhicules neufsFrais de livraison | B36: Frais de livraison
A37: =+$C$4&B37 -> Véhicules neufsService gratuit 1 | B37: Service gratuit 1
A38: =+$C$4&B38 -> Véhicules neufsEntretien stock | B38: Entretien stock
A39: =+$C$4&B39 -> Véhicules neufsPublicité 1 | B39: Publicité 1
A40: =+$C$4&B40 -> Véhicules neufsIntérêt de gros | B40: Intérêt de gros
A41: =+$C$4&B41 -> Véhicules neufs[...] | B41: [...]
...

Sheet Réel 2024
B1: ="Réel 2023 Mensuel Révisé"&" "&Parametres!$B$1 -> Réel 2023 Mensuel Révisé Ste-Marie Auto
B2: Mois | F2: =+IF(Parametres!$B$3=F$6,"X","") | G2: =+IF(Parametres!$B$3=F$6,"O","") | H2: =+IF(Parametres!$B$3=F$6,"U","") | I2: =+IF(Parametres!$B$3=I$6,"X","") | J2: =+IF(Parametres!$B$3=I$6,"O","") | K2: =+IF(Parametres!$B$3=I$6,"U","") | L2: =+IF(Parametres!$B$3=L$6,"X","") | M2: =+IF(Parametres!$B$3=L$6,"O","") | N2: =+IF(Parametres!$B$3=L$6,"U","") | O2: =+IF(Parametres!$B$3=O$6,"X","") | P2: =+IF(Parametres!$B$3=O$6,"O","") | Q2: =+IF(Parametres!$B$3=O$6,"U","") | R2: =+IF(Parametres!$B$3=R$6,"X","") | S2: =+IF(Parametres!$B$3=R$6,"O","") | T2: =+IF(Parametres!$B$3=R$6,"U","") | U2: =+IF(Parametres!$B$3=U$6,"X","") | V2: =+IF(Parametres!$B$3=U$6,"O","") | W2: =+IF(Parametres!$B$3=U$6,"U","") | X2: =+IF(Parametres!$B$3=X$6,"X","") | Y2: =+IF(Parametres!$B$3=X$6,"O","") | Z2: =+IF(Parametres!$B$3=X$6,"U","") | AA2: =+IF(Parametres!$B$3=AA$6,"X","") | AB2: =+IF(Parametres!$B$3=AA$6,"O","") | AC2: =+IF(Parametres!$B$3=AA$6,"U","") | AD2: =+IF(Parametres!$B$3=AD$6,"X","") | AE2: =+IF(Parametres!$B$3=AD$6,"O","") | AF2: =+IF(Parametres!$B$3=AD$6,"U","") | AG2: =+IF(Parametres!$B$3=AG$6,"X","") | AH2: =+IF(Parametres!$B$3=AG$6,"O","") | AI2: =+IF(Parametres!$B$3=AG$6,"U","") | AJ2: =+IF(Parametres!$B$3=AJ$6,"X","") | AK2: =+IF(Parametres!$B$3=AJ$6,"O","") | AL2: =+IF(Parametres!$B$3=AJ$6,"U","") | AM2: =+IF(Parametres!$B$3=AM$6,"X","") -> X | AN2: =+IF(Parametres!$B$3=AM$6,"O","") -> O | AO2: =+IF(Parametres!$B$3=AM$6,"U","") -> U
B3: YTD | F3: =+IF(VLOOKUP(F$6,Parametres!$K$3:$N$14,4,0)="X","X","") -> X | G3: =+IF(VLOOKUP(F$6,Parametres!$K$3:$N$14,4,0)="X","O","") -> O | H3: =+IF(VLOOKUP(F$6,Parametres!$K$3:$N$14,4,0)="X","U","") -> U | I3: =+IF(VLOOKUP(I$6,Parametres!$K$3:$N$14,4,0)="X","X","") -> X | J3: =+IF(VLOOKUP(I$6,Parametres!$K$3:$N$14,4,0)="X","O","") -> O | K3: =+IF(VLOOKUP(I$6,Parametres!$K$3:$N$14,4,0)="X","U","") -> U | L3: =+IF(VLOOKUP(L$6,Parametres!$K$3:$N$14,4,0)="X","X","") -> X | M3: =+IF(VLOOKUP(L$6,Parametres!$K$3:$N$14,4,0)="X","O","") -> O | N3: =+IF(VLOOKUP(L$6,Parametres!$K$3:$N$14,4,0)="X","U","") -> U | O3: =+IF(VLOOKUP(O$6,Parametres!$K$3:$N$14,4,0)="X","X","") -> X | P3: =+IF(VLOOKUP(O$6,Parametres!$K$3:$N$14,4,0)="X","O","") -> O | Q3: =+IF(VLOOKUP(O$6,Parametres!$K$3:$N$14,4,0)="X","U","") -> U | R3: =+IF(VLOOKUP(R$6,Parametres!$K$3:$N$14,4,0)="X","X","") -> X | S3: =+IF(VLOOKUP(R$6,Parametres!$K$3:$N$14,4,0)="X","O","") -> O | T3: =+IF(VLOOKUP(R$6,Parametres!$K$3:$N$14,4,0)="X","U","") -> U | U3: =+IF(VLOOKUP(U$6,Parametres!$K$3:$N$14,4,0)="X","X","") -> X | V3: =+IF(VLOOKUP(U$6,Parametres!$K$3:$N$14,4,0)="X","O","") -> O | W3: =+IF(VLOOKUP(U$6,Parametres!$K$3:$N$14,4,0)="X","U","") -> U | X3: =+IF(VLOOKUP(X$6,Parametres!$K$3:$N$14,4,0)="X","X","") -> X | Y3: =+IF(VLOOKUP(X$6,Parametres!$K$3:$N$14,4,0)="X","O","") -> O | Z3: =+IF(VLOOKUP(X$6,Parametres!$K$3:$N$14,4,0)="X","U","") -> U | AA3: =+IF(VLOOKUP(AA$6,Parametres!$K$3:$N$14,4,0)="X","X","") -> X | AB3: =+IF(VLOOKUP(AA$6,Parametres!$K$3:$N$14,4,0)="X","O","") -> O | AC3: =+IF(VLOOKUP(AA$6,Parametres!$K$3:$N$14,4,0)="X","U","") -> U | AD3: =+IF(VLOOKUP(AD$6,Parametres!$K$3:$N$14,4,0)="X","X","") -> X | AE3: =+IF(VLOOKUP(AD$6,Parametres!$K$3:$N$14,4,0)="X","O","") -> O | AF3: =+IF(VLOOKUP(AD$6,Parametres!$K$3:$N$14,4,0)="X","U","") -> U | AG3: =+IF(VLOOKUP(AG$6,Parametres!$K$3:$N$14,4,0)="X","X","") -> X | AH3: =+IF(VLOOKUP(AG$6,Parametres!$K$3:$N$14,4,0)="X","O","") -> O | AI3: =+IF(VLOOKUP(AG$6,Parametres!$K$3:$N$14,4,0)="X","U","") -> U | AJ3: =+IF(VLOOKUP(AJ$6,Parametres!$K$3:$N$14,4,0)="X","X","") -> X | AK3: =+IF(VLOOKUP(AJ$6,Parametres!$K$3:$N$14,4,0)="X","O","") -> O | AL3: =+IF(VLOOKUP(AJ$6,Parametres!$K$3:$N$14,4,0)="X","U","") -> U | AM3: =+IF(VLOOKUP(AM$6,Parametres!$K$3:$N$14,4,0)="X","X","") -> X | AN3: =+IF(VLOOKUP(AM$6,Parametres!$K$3:$N$14,4,0)="X","O","") -> O | AO3: =+IF(VLOOKUP(AM$6,Parametres!$K$3:$N$14,4,0)="X","U","") -> U
B4: Réel 2024 | C4: Véhicules neufs
B6: Mois | C6: 2024 | F6: Janvier | I6: Février | L6: Mars | O6: Avril | R6: Mai | U6: Juin | X6: Juillet | AA6: Août | AD6: Septembre | AG6: Octobre | AJ6: Novembre | AM6: Décembre
C7: UNITE | D7: $P/UNITE | E7: $PROFITS | F7: UNITE | G7: $P/UNITE | H7: $PROFITS | I7: UNITE | J7: $P/UNITE | K7: $PROFITS | L7: UNITE | M7: $P/UNITE | N7: $PROFITS | O7: UNITE | P7: $P/UNITE | Q7: $PROFITS | R7: UNITE | S7: $P/UNITE | T7: $PROFITS | U7: UNITE | V7: $P/UNITE | W7: $PROFITS | X7: UNITE | Y7: $P/UNITE | Z7: $PROFITS | AA7: UNITE | AB7: $P/UNITE | AC7: $PROFITS | AD7: UNITE | AE7: $P/UNITE | AF7: $PROFITS | AG7: UNITE | AH7: $P/UNITE | AI7: $PROFITS | AJ7: UNITE | AK7: $P/UNITE | AL7: $PROFITS | AM7: UNITE | AN7: $P/UNITE | AO7: $PROFITS
A8: =+$C$4&B8 -> Véhicules neufsVentes nettes | B8: Ventes nettes
A9: =+$C$4&B9 -> Véhicules neufsAutos détail | B9: Autos détail
A10: =+$C$4&B10 -> Véhicules neufsCamions détail | B10: Camions détail
A11: =+$C$4&B11 -> Véhicules neufsSprinter | B11: Sprinter
A12: =+$C$4&B12 -> Véhicules neufsMoto détail | B12: Moto détail
A13: =+$C$4&B13 -> Véhicules neufs[...] | B13: [...]
A14: =+$C$4&B14 -> Véhicules neufs[...] | B14: [...]
A15: =+$C$4&B15 -> Véhicules neufs[...] | B15: [...]
A16: =+$C$4&B16 -> Véhicules neufsTotal Neufs | B16: Total Neufs
A17: =+$C$4&B17 -> Véhicules neufs
A18: =+$C$4&B18 -> Véhicules neufsEx-Démos et courtoisies | B18: Ex-Démos et courtoisies
A19: =+$C$4&B19 -> Véhicules neufs
A20: =+$C$4&B20 -> Véhicules neufsFlottes | B20: Flottes
A21: =+$C$4&B21 -> Véhicules neufs
A22: =+$C$4&B22 -> Véhicules neufsRachat bail | B22: Rachat bail
A23: =+$C$4&B23 -> Véhicules neufs
A24: =+$C$4&B24 -> Véhicules neufsRev. Finances | B24: Rev. Finances
A25: =+$C$4&B25 -> Véhicules neufsRev. Protections | B25: Rev. Protections
A26: =+$C$4&B26 -> Véhicules neufsRev. Autres | B26: Rev. Autres
A27: =+$C$4&B27 -> Véhicules neufsTotal F&I | B27: Total F&I
A28: =+$C$4&B28 -> Véhicules neufs
A29: =+$C$4&B29 -> Véhicules neufs
A30: =+$C$4&B30 -> Véhicules neufsTotal Dépt. Neufs | B30: Total Dépt. Neufs
A31: =+$C$4&B31 -> Véhicules neufs
A32: =+$C$4&B32 -> Véhicules neufs
A33: =+$C$4&B33 -> Véhicules neufsDEPENSES | B33: DEPENSES
A34: =+$C$4&B34 -> Véhicules neufsComm. vendeurs | B34: Comm. vendeurs
A35: =+$C$4&B35 -> Véhicules neufsComm. F&I | B35: Comm. F&I
A36: =+$C$4&B36 -> Véhicules neufsFrais de livraison | B36: Frais de livraison
A37: =+$C$4&B37 -> Véhicules neufsService gratuit 1 | B37: Service gratuit 1
A38: =+$C$4&B38 -> Véhicules neufsEntretien stock | B38: Entretien stock
A39: =+$C$4&B39 -> Véhicules neufsPublicité 1 | B39: Publicité 1
A40: =+$C$4&B40 -> Véhicules neufsIntérêt de gros | B40: Intérêt de gros
A41: =+$C$4&B41 -> Véhicules neufs[...] | B41: [...]
...

Sheet Capex
A1: PARK AVENUE VOLKSWAGEN | B1: PARK AVENUE VOLKSWAGEN
A2: Forecast Immobilisation 2022 | B2: Forecast Immobilisation 2025 | H2: 1 | I2: 2 | J2: 3 | K2: 4 | L2: 5 | M2: 6 | N2: 7 | O2: 8 | P2: 9 | Q2: 10 | R2: 11 | S2: 12
H3: =+IF(VLOOKUP(H2,Parametres!$L$3:$N$14,3,0)="X","REEL","FORECAST") -> REEL | I3: =+IF(VLOOKUP(I2,Parametres!$L$3:$N$14,3,0)="X","REEL","FORECAST") -> REEL | J3: =+IF(VLOOKUP(J2,Parametres!$L$3:$N$14,3,0)="X","REEL","FORECAST") -> REEL | K3: =+IF(VLOOKUP(K2,Parametres!$L$3:$N$14,3,0)="X","REEL","FORECAST") -> REEL | L3: =+IF(VLOOKUP(L2,Parametres!$L$3:$N$14,3,0)="X","REEL","FORECAST") -> REEL | M3: =+IF(VLOOKUP(M2,Parametres!$L$3:$N$14,3,0)="X","REEL","FORECAST") -> REEL | N3: =+IF(VLOOKUP(N2,Parametres!$L$3:$N$14,3,0)="X","REEL","FORECAST") -> REEL | O3: =+IF(VLOOKUP(O2,Parametres!$L$3:$N$14,3,0)="X","REEL","FORECAST") -> REEL | ... S3: =+IF(VLOOKUP(S2,Parametres!$L$3:$N$14,3,0)="X","REEL","FORECAST") -> REEL
A4: Concession | B4: Budgété / Non budgété | C4: Projet | D4: Catégorie Immo | E4: Total forecast | F4: Budget Annuel | G4: Écart vs budget | H4: January | I4: February | J4: March | K4: April | L4: May | M4: June | N4: July | O4: August | P4: September | Q4: October | R4: November | S4: December | T4: Raison / Description
C5: Total | E5: =+SUM(E6:E20) -> 30931.3 | F5: =+SUM(F6:F20) -> 40000 | G5: =+SUM(G6:G20) -> -9068.7 | H5: =+SUM(H6:H20) -> 30931.3 | I5: =+SUM(I6:I20) -> 0 | J5: =+SUM(J6:J20) -> 0 | K5: =+SUM(K6:K20) -> 0 | L5: =+SUM(L6:L20) -> 0 | ... S5: =+SUM(S6:S20) -> 0 | X5: Terrain
A6: =+Parametres!$B$1 -> Ste-Marie Auto | B6: oui | C6: Outils Spécialisés Volks | E6: =+SUM(H6:S6) -> 0 | F6: 40000 | G6: =+E6-F6 -> -40000 | X6: Bâtisse
A7: =+Parametres!$B$1 -> Ste-Marie Auto | B7: non | C7: Équipement informatique | E7: =+SUM(H7:S7) -> 0 | G7: =+E7-F7 -> 0 | X7: Améliorations Locatives
A8: =+Parametres!$B$1 -> Ste-Marie Auto | C8: Nouveau building | E8: =+SUM(H8:S8) -> 30931.3 | G8: =+E8-F8 -> 30931.3 | H8: 30931.3 | X8: Mobilier
A9: =+Parametres!$B$1 -> Ste-Marie Auto | E9: =+SUM(H9:S9) -> 0 | G9: =+E9-F9 -> 0 | X9: Équipements Informatique
A10: =+Parametres!$B$1 -> Ste-Marie Auto | E10: =+SUM(H10:S10) -> 0 | G10: =+E10-F10 -> 0 | X10: Équipements Téléphonique
A11: =+Parametres!$B$1 -> Ste-Marie Auto | E11: =+SUM(H11:S11) -> 0 | G11: =+E11-F11 -> 0 | X11: Enseigne
A12: =+Parametres!$B$1 -> Ste-Marie Auto | E12: =+SUM(H12:S12) -> 0 | G12: =+E12-F12 -> 0
A13: =+Parametres!$B$1 -> Ste-Marie Auto | E13: =+SUM(H13:S13) -> 0 | G13: =+E13-F13 -> 0
A14: =+Parametres!$B$1 -> Ste-Marie Auto | E14: =+SUM(H14:S14) -> 0 | G14: =+E14-F14 -> 0
A15: =+Parametres!$B$1 -> Ste-Marie Auto | E15: =+SUM(H15:S15) -> 0 | G15: =+E15-F15 -> 0
A16: =+Parametres!$B$1 -> Ste-Marie Auto | E16: =+SUM(H16:S16) -> 0 | G16: =+E16-F16 -> 0
A17: =+Parametres!$B$1 -> Ste-Marie Auto | E17: =+SUM(H17:S17) -> 0 | G17: =+E17-F17 -> 0 | X17: non
A18: =+Parametres!$B$1 -> Ste-Marie Auto | E18: =+SUM(H18:S18) -> 0 | G18: =+E18-F18 -> 0
A19: =+Parametres!$B$1 -> Ste-Marie Auto | E19: =+SUM(H19:S19) -> 0 | G19: =+E19-F19 -> 0
A20: =+Parametres!$B$1 -> Ste-Marie Auto | E20: =+SUM(H20:S20) -> 0 | G20: =+E20-F20 -> 0

Sheet Inventaire_Used
A1: #Contrôle | B1: Année | C1: Marque | D1: Modèle | E1: 1416 | F1: 2103 | G1: NIV | H1: Jours en stock | M1: 45169 | N1: $ Inventaire | O1: $ Financé
A2: 5291P | B2: 2020 | C2: VOLKSWAGEN | D2: E-GOLF | E2: 32007.51 | F2: -22494.36 | G2: WVWPR7AU2LW903993 | H2: 423 | M2: CTRL | N2: =+SUM(E:E) -> 2779322.1 | O2: =+SUM(F:F) -> -640715.53
A3: 230251A | B3: 2020 | C3: VOLKSWAGEN | D3: E-GOLF | E3: 24454.46 | G3: WVWPR7AU0LW907198 | H3: 306 | M3: Unités | N3: =COUNT(E:E) -> 111 | O3: =-O2/N2 -> 0.23052943
A4: 230425A | B4: 2021 | C4: VOLKSWAGEN | D4: ATLAS CROSS SPO | E4: 37735.15 | G4: 1V2LC2CAXMC211536 | H4: 188
A5: 230365A | B5: 2018 | C5: VOLKSWAGEN | D5: BEETLE CONVERTI | E5: 29929.55 | G5: 3VW5DAAT2JM518129 | H5: 187 | M5: Moyenne | N5: =+N2/N3 -> 25038.938
A6: 5485P | B6: 2018 | C6: VOLKSWAGEN | D6: ATLAS | E6: 31306.12 | G6: 1V2NR2CA5JC509107 | H6: 131
A7: 230554A | B7: 2014 | C7: SUBARU | D7: WRX | E7: 17680.42 | G7: JF1GR8H60EL238082 | H7: 121 | M7: Plus de 90 Jours | N7: =SUM(E2:E13) -> 337989.36 | O7: =+N7/N2 -> 0.12160856
A8: 230567A | B8: 2021 | C8: VOLKSWAGEN | D8: TIGUAN | E8: 28635.15 | F8: -31332.8 | G8: 3VV2B7AX6MM155874 | H8: 104 | N8: =COUNT(H2:H13) -> 12 | O8: =+N8/(N3) -> 0.10810811
A9: 240013A | B9: 2022 | C9: VOLKSWAGEN | D9: TIGUAN | E9: 38815.25 | G9: 3VV4B7AX3NM051496 | H9: 94
A10: 230392A | B10: 2020 | C10: VOLKSWAGEN | D10: TIGUAN | E10: 31315.25 | F10: -24944.54 | G10: 3VV4B7AX2LM114164 | H10: 94
A11: 230599A | B11: 2019 | C11: VOLKSWAGEN | D11: JETTA | E11: 21280.25 | F11: -10962 | G11: 3VWE57BU6KM254342 | H11: 94
A12: 230606A | B12: 2018 | C12: CHEVROLET | D12: VOLT | E12: 17550 | G12: 1G1RA6S50JU104989 | H12: 93
A13: 240015A | B13: 2019 | C13: VOLKSWAGEN | D13: GOLF GTI | E13: 27280.25 | F13: -17480.23 | G13: 3VW6T7AU5KM024755 | H13: 90
A14: 5511P | B14: 2022 | C14: VOLKSWAGEN | D14: ATLAS CROSS SPO | E14: 44105.05 | F14: -38250 | G14: 1V2BE2CA6NC212111 | H14: 88
A15: 240019A | B15: 2020 | C15: VOLKSWAGEN | D15: ATLAS CROSS SPO | E15: 36415.13 | F15: -26892 | G15: 1V2TE2CA8LC219420 | H15: 82
A16: 230596A | B16: 2020 | C16: VOLKSWAGEN | D16: TIGUAN | E16: 27935.05 | G16: 3VV2B7AX4LM005048 | H16: 76
A17: 5509PA | B17: 2017 | C17: AUDI | D17: A3 E-TRON | E17: 20050 | G17: WAUSPBFF5HA099610 | H17: 74
A18: 230626A | B18: 2018 | C18: VOLKSWAGEN | D18: TIGUAN | E18: 20497.05 | G18: 3VV4B7AX2JM130250 | H18: 72
A19: 5518P | B19: 2020 | C19: VOLKSWAGEN | D19: TIGUAN | E19: 28075.78 | F19: -23850 | G19: 3VV4B7AX0LM106225 | H19: 69
A20: 230593A | B20: 2019 | C20: VOLKSWAGEN | D20: TIGUAN | E20: 26815.25 | G20: 3VV4B7AX3KM183332 | H20: 69
A21: 5519P | B21: 2021 | C21: VOLKSWAGEN | D21: TIGUAN | E21: 28447.25 | F21: -24418.8 | G21: 3VV2B7AX4MM068281 | H21: 68
A22: 240044A | B22: 2019 | C22: VOLKSWAGEN | D22: ATLAS | E22: 29352 | G22: 1V2MR2CA6KC587280 | H22: 66
A23: 240041A | B23: 2018 | C23: VOLKSWAGEN | D23: GOLF | E23: 18787.5 | G23: 3VWG17AU2JM291103 | H23: 66
A24: 240056A | B24: 2020 | C24: VOLKSWAGEN | D24: JETTA | E24: 18043.82 | G24: 3VWN57BU2LM040420 | H24: 65
A25: 240036A | B25: 2021 | C25: VOLKSWAGEN | D25: ATLAS | E25: 40209.65 | G25: 1V2FR2CA8MC595926 | H25: 62
A26: 240079A | B26: 2020 | C26: VOLKSWAGEN | D26: TIGUAN | E26: 30620.3 | G26: 3VV4B7AX5LM110786 | H26: 62
A27: 230564B | B27: 2020 | C27: JEEP | D27: COMPASS | E27: 28211.38 | G27: 3C4NJDDBXLT155667 | H27: 62
A28: 230649A | B28: 2020 | C28: NISSAN | D28: ROGUE | E28: 23550 | G28: 5N1AT2MT7LC775762 | H28: 61
A29: 240086A | B29: 2022 | C29: VOLKSWAGEN | D29: TIGUAN | E29: 36524.6 | G29: 3VV4B7AX9NM096457 | H29: 60
A30: 5522P | B30: 2020 | C30: VOLKSWAGEN | D30: TIGUAN | E30: 24346.21 | F30: -16047.88 | G30: 3VV2B7AX7LM099068 | H30: 60
A31: 5521P | B31: 2019 | C31: VOLKSWAGEN | D31: GOLF | E31: 18530.25 | G31: 3VWG57AU3KM018998 | H31: 60
A32: 5523P | B32: 2021 | C32: VOLKSWAGEN | D32: TIGUAN | E32: 29670.31 | F32: -25505.1 | G32: 3VV2B7AX2MM078047 | H32: 59
A33: 240089A | B33: 2020 | C33: VOLKSWAGEN | D33: JETTA | E33: 22965.2 | G33: 3VWW57BU9LM006236 | H33: 55
A34: 5525P | B34: 2021 | C34: VOLKSWAGEN | D34: TIGUAN | E34: 31666.8 | F34: -33046.59 | G34: 3VV4B7AX1MM155614 | H34: 54
A35: 240059A | B35: 2019 | C35: VOLKSWAGEN | D35: TIGUAN | E35: 24846.26 | G35: 3VV2B7AX7KM049091 | H35: 53
A36: 240099A | B36: 2020 | C36: VOLKSWAGEN | D36: JETTA | E36: 19323.74 | G36: 3VWN57BU9LM077965 | H36: 51
A37: 240098A | B37: 2019 | C37: VOLKSWAGEN | D37: GOLF | E37: 18294.75 | G37: 3VWG57AU0KM034477 | H37: 48
A38: 240038B | B38: 2018 | C38: VOLKSWAGEN | D38: GOLF | E38: 16745.3 | G38: 3VWG17AU9JM275867 | H38: 48
A39: 240091A | B39: 2022 | C39: VOLKSWAGEN | D39: ATLAS | E39: 49927.29 | G39: 1V2FR2CA7NC504226 | H39: 47
A40: 5526P | B40: 2020 | C40: VOLKSWAGEN | D40: TIGUAN | E40: 24483.1 | F40: -18876 | G40: 3VV2B7AX9LM002520 | H40: 47
...

Sheet Inventaire_Neuf
A1: #Contrôle | B1: Année | C1: Marque | D1: Modèle | E1: 1402 | F1: 2101 | G1: NIV | H1: Jours en stock | K1: 45230 | L1: $ Inventaire | M1: $ Financé
A2: 230536 | B2: 2023 | C2: VOLKSWAGEN | D2: JETTA SEDAN | E2: 33666.97 | F2: -31504.85 | G2: 3VW2T7BU7PM053775 | H2: 142 | K2: CTRL | L2: =+SUM(E2:E9963) -> 3059537.1 | M2: =+SUM(F2:F9963) -> -2668372
A3: 240001 | B3: 2024 | C3: VOLKSWAGEN | D3: ATLAS | E3: 56706.1 | F3: -57628.2 | G3: 1V2BR2CA6RC502911 | H3: 142 | K3: Unités | L3: =COUNT(E:E) -> 71 | M3: =-M2/L2 -> 0.8721489
A4: 230574 | B4: 2023 | C4: VOLKSWAGEN | D4: JETTA SEDAN | E4: 31163.98 | F4: -32628.75 | G4: 3VWGM7BU3PM060824 | H4: 116
A5: 230581 | B5: 2023 | C5: VOLKSWAGEN | D5: TAOS | E5: 38081.07 | F5: -39936.75 | G5: 3VV4X7B27PM374246 | H5: 111
A6: 240003 | B6: 2024 | C6: VOLKSWAGEN | D6: ATLAS | E6: 50511.98 | F6: -51427.95 | G6: 1V2LR2CA2RC511786 | H6: 108 | K6: Plus de 90 jrs | L6: =SUM(E2:E12) -> 532950.79 | M6: =SUM(F2:F12) -> -378366.05
A7: 240009 | B7: 2024 | C7: VOLKSWAGEN | D7: ATLAS CROSS SPT | E7: 54659.17 | F7: -57051.75 | G7: 1V2BE2CA7RC206484 | H7: 104 | L7: 2
A8: 240011 | B8: 2024 | C8: VOLKSWAGEN | D8: ATLAS CROSS SPT | E8: 48328.17 | F8: -51136.05 | G8: 1V2LE2CA3RC208611 | H8: 97
A9: 240016 | B9: 2024 | C9: VOLKSWAGEN | D9: ATLAS CROSS SPT | E9: 57229.1 | G9: 1V2BE2CA1RC206996 | H9: 93 | K9: Plus de 180 jrs | L9: 0 | M9: 0
A10: 240022 | B10: 2024 | C10: VOLKSWAGEN | D10: ATLAS | E10: 58141.01 | G10: 1V2BR2CA4RC506228 | H10: 90 | L10: 0
A11: 240021 | B11: 2024 | C11: VOLKSWAGEN | D11: ATLAS | E11: 48171.23 | G11: 1V2LR2CA8RC516197 | H11: 90
A12: 240020 | B12: 2024 | C12: VOLKSWAGEN | D12: ATLAS CROSS SPT | E12: 56292.01 | F12: -57051.75 | G12: 1V2BE2CA5RC210341 | H12: 90
A13: 240027 | B13: 2024 | C13: VOLKSWAGEN | D13: ATLAS | E13: 56073.92 | F13: -58869.3 | G13: 1V2BR2CA1RC517137 | H13: 86
A14: 240026 | B14: 2024 | C14: VOLKSWAGEN | D14: GOLF GTI | E14: 37397 | F14: -39440.1 | G14: WVWGA7CD7RW121198 | H14: 86
A15: 240030 | B15: 2024 | C15: VOLKSWAGEN | D15: ATLAS CROSS SPT | E15: 56197.99 | F15: -58834.65 | G15: 1V2FE2CAXRC211373 | H15: 82
A16: 230639 | B16: 2023 | C16: VOLKSWAGEN | D16: TAOS | E16: 32135.51 | F16: -34034.7 | G16: 3VVEX7B23PM379190 | H16: 80
A17: 240042 | B17: 2024 | C17: VOLKSWAGEN | D17: ATLAS CROSS SPT | E17: 55950.97 | F17: -58834.65 | G17: 1V2FE2CA4RC210672 | H17: 74
A18: 240047 | B18: 2024 | C18: VOLKSWAGEN | D18: ATLAS CROSS SPT | E18: 55950.97 | F18: -58834.65 | G18: 1V2FE2CA0RC211429 | H18: 74
A19: 240045 | B19: 2024 | C19: VOLKSWAGEN | D19: JETTA SEDAN | E19: 26927 | F19: -28367.85 | G19: 3VWWM7BU5RM010702 | H19: 74
A20: 230643 | B20: 2023 | C20: VOLKSWAGEN | D20: TAOS | E20: 37610 | F20: -39461.1 | G20: 3VV4X7B2XPM382549 | H20: 73
A21: 240052 | B21: 2024 | C21: VOLKSWAGEN | D21: ATLAS CROSS SPT | E21: 55950.97 | F21: -58834.65 | G21: 1V2FE2CAXRC211504 | H21: 73
A22: 240050 | B22: 2024 | C22: VOLKSWAGEN | D22: JETTA SEDAN | E22: 29531 | F22: -31102.05 | G22: 3VWSM7BU4RM014707 | H22: 73
A23: 240070 | B23: 2024 | C23: VOLKSWAGEN | D23: ATLAS CROSS SPT | E23: 54250 | F23: -57051.75 | G23: 1V2BE2CA9RC212335 | H23: 68
... A27: 240083 | B27: 2024 | C27: VOLKSWAGEN | D27: JETTA SEDAN | E27: 32017.87 | F27: -33204.15 | G27: 3VWGM7BU7RM015582 | H27: 62
A28: 240125 | B28: 2024 | C28: VOLKSWAGEN | D28: JETTA GLI | E28: 31816.52 | G28: 3VW8T7BU7RM014696 | H28: 52
A29: 240129 | B29: 2024 | C29: VOLKSWAGEN | D29: JETTA GLI | E29: 31513 | G29: 3VW8T7BU8RM016912 | H29: 51
A30: 240137 | B30: 2024 | C30: VOLKSWAGEN | D30: ATLAS | E30: 48894 | F30: -51427.95 | G30: 1V2LR2CA9RC529461 | H30: 48
A31: 240141 | B31: 2024 | C31: VOLKSWAGEN | D31: ATLAS CROSS SPT | E31: 55948 | F31: -58834.65 | G31: 1V2FE2CA6RC216828 | H31: 48
A32: 240139 | B32: 2024 | C32: VOLKSWAGEN | D32: ATLAS CROSS SPT | E32: 54236.5 | G32: 1V2BE2CAXRC212764 | H32: 48
A33: 240138 | B33: 2024 | C33: VOLKSWAGEN | D33: TAOS | E33: 32864 | F33: -34706.7 | G33: 3VVEX7B22RM012347 | H33: 48
A34: 240147 | B34: 2024 | C34: VOLKSWAGEN | D34: ATLAS | E34: 55259.97 | F34: -58109.1 | G34: 1V2BR2CAXRC525513 | H34: 47
A35: 240156 | B35: 2024 | C35: VOLKSWAGEN | D35: ATLAS CROSS SPT | E35: 53794.97 | F35: -56570.85 | G35: 1V2BE2CA8RC216649 | H35: 45
A36: 240171 | B36: 2024 | C36: VOLKSWAGEN | D36: JETTA SEDAN | E36: 28629 | G36: 3VWEM7BU2RM001760 | H36: 44
A37: 240173 | B37: 2024 | C37: VOLKSWAGEN | D37: ATLAS | E37: 54801.97 | F37: -57628.2 | G37: 1V2BR2CA7RC532368 | H37: 41
A38: 240190 | B38: 2024 | C38: VOLKSWAGEN | D38: ATLAS | E38: 58249.97 | G38: 1V2FR2CA7RC531156 | H38: 38
A39: 240197 | B39: 2024 | C39: VOLKSWAGEN | D39: TIGUAN | E39: 45175.95 | F39: -47526.15 | G39: 3VV4B7AX2RM023873 | H39: 37
A40: 240203 | B40: 2024 | C40: VOLKSWAGEN | D40: TIGUAN | E40: 44101 | F40: -46474.05 | G40: 3VV4B7AX6RM025190 | H40: 34
A41: 240207 | B41: 2024 | C41: VOLKSWAGEN | D41: ATLAS | E41: 54806.97 | F41: -57628.2 | G41: 1V2BR2CA4RC531890 | H41: 33
A42: 240206 | B42: 2024 | C42: VOLKSWAGEN | D42: TAOS | E42: 38195 | F42: -40225.5 | G42: 3VV4X7B25RM012063 | H42: 33
A43: 240212 | B43: 2024 | C43: VOLKSWAGEN | D43: ATLAS CROSS SPT | E43: 56348.1 | F43: -58834.65 | G43: 1V2FE2CA5RC219798 | H43: 30
...

Sheet 2pager
B1: =Parametres!$B$1&" "&"2 pager"&" "&Parametres!$B$3&" "&Parametres!$B$4 -> Ste-Marie Auto 2 pager Décembre 2025
B3: New | C3: Actual | D3: Budget | E3: 2023 | F3: ▲ Budget | G3: ▲2023 | H3: % ▲ Budget | I3: % ▲ 2023 | J3: Commentaires
B4: Units | C4: =+Print_Mois!$J$13+Print_Mois!$J$15 -> 54 | D4: =+Print_Mois!$D$13+Print_Mois!$D$15 -> 0 | E4: =+Print_Mois!$O$13+Print_Mois!$O$15 -> 0 | F4: =+IFERROR($C4-D4,"") -> 54 | G4: =+IFERROR($C4-E4,"") -> 54 | H4: =+IFERROR(F4/ABS($D4),"") | I4: =+IFERROR(G4/ABS($E4),"") | J4: L'arrêt des livraisons ID4 a eu un impact significatif sur le mois de septembre. Les profits unitaires au budget n'en tenaient pas tant compte mais la comptétion tant inter-dealers qu'inter-marques a relancé les négociations sur les prix. Notre bureau commercial est encore sous le coup du turnover. Les autres revenus sont la conséquence directe de la baisse de volume d'unités livrées.
B5: Front Margin | C5: =+Print_Mois!$L$13+Print_Mois!$L$15 -> 80534.51 | D5: =+Print_Mois!$F$13+Print_Mois!$F$15 -> 0 | E5: =+Print_Mois!$Q$13+Print_Mois!$Q$15 -> 0 | F5: =+IFERROR($C5-D5,"") -> 80534.51 | G5: =+IFERROR($C5-E5,"") -> 80534.51 | H5: =+IFERROR(F5/ABS($D5),"") | I5: =+IFERROR(G5/ABS($E5),"")
B6: Front margin / unit | C6: =+C5/C4 -> 1491.3798 | D6: =+D5/D4 -> #DIV/0! | E6: =+E5/E4 -> #DIV/0! | F6: =+IFERROR($C6-D6,"") | G6: =+IFERROR($C6-E6,"") | H6: =+IFERROR(F6/ABS($D6),"") | I6: =+IFERROR(G6/ABS($E6),"")
B7: $ Salaires et commission | C7: =+Print_Mois!$L$31 -> 40586.54 | D7: =+Print_Mois!$F$31 -> 0 | E7: =+Print_Mois!$Q$31 -> 0 | F7: =+IFERROR($C7-D7,"") -> 40586.54 | G7: =+IFERROR($C7-E7,"") -> 40586.54 | H7: =+IFERROR(F7/ABS($D7),"") | I7: =+IFERROR(G7/ABS($E7),"")
B8: % Salaires et commission | C8: =+C7/C5 -> 0.50396457 | D8: =+D7/D5 -> #DIV/0! | E8: =+E7/E5 -> #DIV/0! | F8: =+IFERROR($C8-D8,"") | G8: =+IFERROR($C8-E8,"") | H8: =+IFERROR(F8/ABS($D8),"") | I8: =+IFERROR(G8/ABS($E8),"")
B9: Back Margin | C9: =+Print_Mois!$L$24 -> 36941.92 | D9: =+Print_Mois!$F$24 -> 0 | E9: =+Print_Mois!$Q$24 -> 0 | F9: =+IFERROR($C9-D9,"") -> 36941.92 | G9: =+IFERROR($C9-E9,"") -> 36941.92 | H9: =+IFERROR(F9/ABS($D9),"") | I9: =+IFERROR(G9/ABS($E9),"")
B10: Back Margin / unit | C10: =+C9/C4 -> 684.10963 | D10: =+D9/D4 -> #DIV/0! | E10: =+E9/E4 -> #DIV/0! | F10: =+IFERROR($C10-D10,"") | G10: =+IFERROR($C10-E10,"") | H10: =+IFERROR(F10/ABS($D10),"") | I10: =+IFERROR(G10/ABS($E10),"")
B11: $ commission FI | C11: =+Print_Mois!$L$32 -> 12050.59 | D11: =+Print_Mois!$F$32 -> 0 | E11: =+Print_Mois!$Q$32 -> 0 | F11: =+IFERROR($C11-D11,"") -> 12050.59 | G11: =+IFERROR($C11-E11,"") -> 12050.59 | H11: =+IFERROR(F11/ABS($D11),"") | I11: =+IFERROR(G11/ABS($E11),"")
B12: % commission FI | C12: =+C11/C9 -> 0.32620367 | D12: =+D11/D9 -> #DIV/0! | E12: =+E11/E9 -> #DIV/0! | F12: =+IFERROR($C12-D12,"") | G12: =+IFERROR($C12-E12,"") | H12: =+IFERROR(F12/ABS($D12),"") | I12: =+IFERROR(G12/ABS($E12),"")
B13: Variable fees | C13: =+Print_Mois!$L$41-C7-C11 -> -292136.2 | D13: =+Print_Mois!$F$41-D7-D11 -> 0 | E13: =+Print_Mois!$Q$41-E7-E11 -> 0 | F13: =+IFERROR($C13-D13,"") -> -292136.2 | G13: =+IFERROR($C13-E13,"") -> -292136.2 | H13: =+IFERROR(F13/ABS($D13),"") | I13: =+IFERROR(G13/ABS($E13),"")
B14: Variable fees / units | C14: =+C13/C4 -> -5409.9296 | D14: =+D13/D4 -> #DIV/0! | E14: =+E13/E4 -> #DIV/0! | F14: =+IFERROR($C14-D14,"") | G14: =+IFERROR($C14-E14,"") | H14: =+IFERROR(F14/ABS($D14),"") | I14: =+IFERROR(G14/ABS($E14),"")
B15: Other Revenues | C15: =+Print_Mois!$L$83 -> 5621.93 | D15: =+Print_Mois!$F$83 -> 0 | E15: =+Print_Mois!$Q$83 -> 0 | F15: =+IFERROR($C15-D15,"") -> 5621.93 | G15: =+IFERROR($C15-E15,"") -> 5621.93 | H15: =+IFERROR(F15/ABS($D15),"") | I15: =+IFERROR(G15/ABS($E15),"")
B16: Inventory
B17: Units | C17: =Inventaire_Neuf!L3 -> 71 | D17: 61 | E17: 164 | F17: =+IFERROR($C17-D17,"") -> 10 | G17: =+IFERROR($C17-E17,"") -> -93 | H17: =+IFERROR(F17/ABS($D17),"") -> 0.16393443 | I17: =+IFERROR(G17/ABS($E17),"") -> -0.56707317
B18: $ | C18: =Inventaire_Neuf!L2 -> 3059537.1 | D18: 2233570 | E18: 5689693.2 | F18: =+IFERROR($C18-D18,"") -> 825967.15 | G18: =+IFERROR($C18-E18,"") -> -2630156 | H18: =+IFERROR(F18/ABS($D18),"") -> 0.36979685 | I18: =+IFERROR(G18/ABS($E18),"") -> -0.46226676
B20: Used | C20: Actual | D20: Budget | E20: =$E$3 -> 2023 | F20: ▲ Budget | G20: =$G$3 -> ▲2023 | H20: % ▲ Budget | I20: =$I$3 -> % ▲ 2023 | J20: Commentaires
B21: Units | C21: =+Print_Mois!$J$97 -> 15 | D21: =+Print_Mois!$D$97 -> 0 | E21: =+Print_Mois!$O$97 -> 0 | F21: =+IFERROR($C21-D21,"") -> 15 | G21: =+IFERROR($C21-E21,"") -> 15 | H21: =+IFERROR(F21/ABS($D21),"") | I21: =+IFERROR(G21/ABS($E21),"") | J21: Le volume et les résultats du bureau commercial sont maintenant en ligne avec les attentes. Le profit unitaire "front" est le dernier sujet d'ajustement côté chiffre en même temps que la prise de contrôle des leads, du temps de réponse et de ce que l'on en fait ! Invenaire sain, marchandisage optimisé. Il nous reste à être extrèmement vigilants et rigoureux dans le suivi de ces opérations.
B22: Front Margin | C22: =+Print_Mois!$L$97 -> 6927 | D22: =+Print_Mois!$F$97 -> 0 | E22: =+Print_Mois!$Q$97 -> 0 | F22: =+IFERROR($C22-D22,"") -> 6927 | G22: =+IFERROR($C22-E22,"") -> 6927 | H22: =+IFERROR(F22/ABS($D22),"") | I22: =+IFERROR(G22/ABS($E22),"")
B23: Front margin / unit | C23: =+C22/C21 -> 461.8 | D23: =+D22/D21 -> #DIV/0! | E23: =+E22/E21 -> #DIV/0! | F23: =+IFERROR($C23-D23,"") | G23: =+IFERROR($C23-E23,"") | H23: =+IFERROR(F23/ABS($D23),"") | I23: =+IFERROR(G23/ABS($E23),"")
B24: $ Salaires et commission | C24: =+Print_Mois!$L$113 -> 8616.29 | D24: =+Print_Mois!$F$113 -> 0 | E24: =+Print_Mois!$Q$113 -> 0 | F24: =+IFERROR($C24-D24,"") -> 8616.29 | G24: =+IFERROR($C24-E24,"") -> 8616.29 | H24: =+IFERROR(F24/ABS($D24),"") | I24: =+IFERROR(G24/ABS($E24),"")
B25: % Salaires et commission | C25: =+C24/C22 -> 1.2438704 | D25: =+D24/D22 -> #DIV/0! | E25: =+E24/E22 -> #DIV/0! | F25: =+IFERROR($C25-D25,"") | G25: =+IFERROR($C25-E25,"") | H25: =+IFERROR(F25/ABS($D25),"") | I25: =+IFERROR(G25/ABS($E25),"")
B26: Back Margin | C26: =+Print_Mois!$L$106 -> 14861.82 | D26: =+Print_Mois!$F$106 -> 0 | E26: =+Print_Mois!$Q$106 -> 0 | F26: =+IFERROR($C26-D26,"") -> 14861.82 | G26: =+IFERROR($C26-E26,"") -> 14861.82 | H26: =+IFERROR(F26/ABS($D26),"") | I26: =+IFERROR(G26/ABS($E26),"")
B27: Back Margin / unit | C27: =+C26/C21 -> 990.788 | D27: =+D26/D21 -> #DIV/0! | E27: =+E26/E21 -> #DIV/0! | F27: =+IFERROR($C27-D27,"") | G27: =+IFERROR($C27-E27,"") | H27: =+IFERROR(F27/ABS($D27),"") | I27: =+IFERROR(G27/ABS($E27),"")
B28: $ commission FI | C28: =+Print_Mois!$L$114 -> 6835.57 | D28: =+Print_Mois!$F$114 -> 0 | E28: =+Print_Mois!$Q$114 -> 0 | F28: =+IFERROR($C28-D28,"") -> 6835.57 | G28: =+IFERROR($C28-E28,"") -> 6835.57 | H28: =+IFERROR(F28/ABS($D28),"") | I28: =+IFERROR(G28/ABS($E28),"")
B29: % commission FI | C29: =+C28/C26 -> 0.45994165 | D29: =+D28/D26 -> #DIV/0! | E29: =+E28/E26 -> #DIV/0! | F29: =+IFERROR($C29-D29,"") | G29: =+IFERROR($C29-E29,"") | H29: =+IFERROR(F29/ABS($D29),"") | I29: =+IFERROR(G29/ABS($E29),"")
B30: Variable fees | C30: =+Print_Mois!$L$123-C24-C28 -> 58937.18 | D30: =+Print_Mois!$F$123-D24-D28 -> 0 | E30: =+Print_Mois!$Q$123-E24-E28 -> 0 | F30: =+IFERROR($C30-D30,"") -> 58937.18 | G30: =+IFERROR($C30-E30,"") -> 58937.18 | H30: =+IFERROR(F30/ABS($D30),"") | I30: =+IFERROR(G30/ABS($E30),"")
B31: Variable fees / units | C31: =+C30/C21 -> 3929.1453 | D31: =+D30/D21 -> #DIV/0! | E31: =+E30/E21 -> #DIV/0! | F31: =+IFERROR($C31-D31,"") | G31: =+IFERROR($C31-E31,"") | H31: =+IFERROR(F31/ABS($D31),"") | I31: =+IFERROR(G31/ABS($E31),"")
B32: Other Revenues | C32: =+Print_Mois!$L$164 -> 0 | D32: =+Print_Mois!$F$164 -> 0 | E32: =+Print_Mois!$Q$164 -> 0 | F32: =+IFERROR($C32-D32,"") -> 0 | G32: =+IFERROR($C32-E32,"") -> 0 | H32: =+IFERROR(F32/ABS($D32),"") | I32: =+IFERROR(G32/ABS($E32),"")
B33: Inventory
B34: Units | C34: =Inventaire_Used!N3 -> 111 | D34: 68 | E34: 92 | F34: =+IFERROR($C34-D34,"") -> 43 | G34: =+IFERROR($C34-E34,"") -> 19 | H34: =+IFERROR(F34/ABS($D34),"") -> 0.63235294 | I34: =+IFERROR(G34/ABS($E34),"") -> 0.20652174
B35: $ | C35: =Inventaire_Used!N2 -> 2779322.1 | D35: 1072231 | E35: 1510979 | F35: =+IFERROR($C35-D35,"") -> 1707091.1 | G35: =+IFERROR($C35-E35,"") -> 1268343.1 | H35: =+IFERROR(F35/ABS($D35),"") -> 1.5920927 | I35: =+IFERROR(G35/ABS($E35),"") -> 0.83941809
B37: Service | C37: Actual | D37: Budget | E37: =$E$3 -> 2023 | F37: ▲ Budget | G37: =$G$3 -> ▲2023 | H37: % ▲ Budget | I37: =$I$3 -> % ▲ 2023 | J37: Commentaires
B38: Revenus | C38: =+Print_Mois!$K$268 -> 184608.29 | D38: =+Print_Mois!$E$268 -> 0 | E38: =+Print_Mois!$P$268 -> 0 | F38: =+IFERROR($C38-D38,"") -> 184608.29 | G38: =+IFERROR($C38-E38,"") -> 184608.29 | H38: =+IFERROR(F38/ABS($D38),"") | I38: =+IFERROR(G38/ABS($E38),"") | J38: Très belle progression versus 2023, autant sur le fait de voir monter le brut globalement que sur le contrôle des dépenses. Le modèle de fonctionnement de la mixité de véhicules de courtoisies, Uber Pro et chauffeurs fonctionne. Bon mois de Csi à côté de la performance financière.
B39: Gross margin | C39: =+Print_Mois!$L$268 -> 122970.84 | D39: =+Print_Mois!$F$268 -> 0 | E39: =+Print_Mois!$Q$268 -> 0 | F39: =+IFERROR($C39-D39,"") -> 122970.84 | G39: =+IFERROR($C39-E39,"") -> 122970.84 | H39: =+IFERROR(F39/ABS($D39),"") | I39: =+IFERROR(G39/ABS($E39),"")
B40: $ Revenus / #WO client | C40: =+Print_Mois!$K$246/Print_Mois!$J$246 -> 433.76617 | D40: =+IFERROR(Print_Mois!$E$246/Print_Mois!$D$246,"") | E40: =+Print_Mois!$P$246/Print_Mois!$O$246 -> #DIV/0! | F40: =+IFERROR($C40-D40,"") | G40: =+IFERROR($C40-E40,"") | H40: =+IFERROR(F40/ABS($D40),"") | I40: =+IFERROR(G40/ABS($E40),"")
B41: $ Revenus / #WO garantie | C41: =+Print_Mois!$K$249/Print_Mois!$J$249 -> 153.82413 | D41: =+IFERROR(Print_Mois!$E$249/Print_Mois!$D$249,"") | E41: =+Print_Mois!$P$249/Print_Mois!$O$249 -> #DIV/0! | F41: =+IFERROR($C41-D41,"") | G41: =+IFERROR($C41-E41,"") | H41: =+IFERROR(F41/ABS($D41),"") | I41: =+IFERROR(G41/ABS($E41),"")
B42: Lost time | C42: =+Print_Mois!$L$258 -> -3012.8 | D42: =+Print_Mois!$F$258 -> 0 | E42: =+Print_Mois!$Q$258 -> 0 | F42: =+IFERROR($C42-D42,"") -> -3012.8 | G42: =+IFERROR($C42-E42,"") -> -3012.8 | H42: =+IFERROR(F42/ABS($D42),"") | I42: =+IFERROR(G42/ABS($E42),"")
B43: Total salaries | C43: =+Print_Mois!$L$284 -> 139149.86 | D43: =+Print_Mois!$F$284 -> 0 | E43: =+Print_Mois!$Q$284 -> 0 | F43: =+IFERROR($C43-D43,"") -> 139149.86 | G43: =+IFERROR($C43-E43,"") -> 139149.86 | H43: =+IFERROR(F43/ABS($D43),"") | I43: =+IFERROR(G43/ABS($E43),"")
...

Sheet Print_Mois
C1: =Parametres!B1 -> Ste-Marie Auto | K1: Véhicules neufs | S1: =CONCATENATE("Réalisé,"," ",Parametres!B3," ",Parametres!B4) -> Réalisé, Décembre 2025
D2: X | E2: O | F2: U | J2: NB | L2: $ | O2: NB | Q2: $ | V2: *** NE PAS EFFACER / Pour An Précédente ***
D3: BUDGET ORIGINAL | J3: RÉALISATION | M3: ÉCART réel / Budget | O3: ANNÉE PRÉCÉDENTE | R3: ECART (réel/ Ann.Préc.) | V3: NEUF | W3: 0.45
D4: UNITE | E4: $P/UNITÉ | F4: $PROFITS | J4: UNITÉS | K4: $P/UNITE | L4: $PROFITS | M4: UNITÉS | N4: $PROFITS | O4: UNITÉS | P4: $P/UNITE | Q4: $PROFITS | R4: UNITÉS | S4: $PROFITS | V4: USAGE | W4: 0.1
A5: Véhicules neufsVentes nettes | B5: Véhicules neufs | C5: Ventes nettes | F5: =+INDEX('Budget original'!$A$2:$AO$501,MATCH($A5,'Budget original'!$A$2:$A$501,0),MATCH(F$2,'Budget original'!$A$2:$AO$2,0)) -> 0 | L5: =-SUMIFS(BV_Data_An_Cour!$AM:$AM,BV_Data_An_Cour!$AS:$AS,"Oui",BV_Data_An_Cour!$AP:$AP,$B5) -> 7771980 | Q5: =-SUMIFS(BV_Data_An_Prec!$AM:$AM,BV_Data_An_Prec!$AS:$AS,"Oui",BV_Data_An_Prec!$AP:$AP,$B5) -> 0 | V5: SERVICE | W5: 0.225
A6: Véhicules neufsAutos détail | B6: Véhicules neufs | C6: Autos détail | D6: =+INDEX('Budget original'!$A$2:$AO$501,MATCH($A6,'Budget original'!$A$2:$A$501,0),MATCH(D$2,'Budget original'!$A$2:$AO$2,0)) -> 0 | E6: =IF(D6=0,0,F6/D6) -> 0 | F6: =+INDEX('Budget original'!$A$2:$AO$501,MATCH($A6,'Budget original'!$A$2:$A$501,0),MATCH(F$2,'Budget original'!$A$2:$AO$2,0)) -> 0 | J6: =SUMIFS(BV_Data_An_Cour!$AW:$AW,BV_Data_An_Cour!$AP:$AP,$B6,BV_Data_An_Cour!$AQ:$AQ,$C6,BV_Data_An_Cour!$AY:$AY,J$2) -> 0 | K6: =IF(J6=0,0,L6/J6) -> 0 | L6: =-SUMIFS(BV_Data_An_Cour!$AM:$AM,BV_Data_An_Cour!$AP:$AP,$B6,BV_Data_An_Cour!$AQ:$AQ,$C6,BV_Data_An_Cour!$AR:$AR,L$2) -> 0 | M6: =J6-D6 -> 0 | N6: =L6-F6 -> 0 | O6: =SUMIFS(BV_Data_An_Prec!$AW:$AW,BV_Data_An_Prec!$AP:$AP,$B6,BV_Data_An_Prec!$AQ:$AQ,$C6,BV_Data_An_Prec!$AY:$AY,O$2) -> 0 | P6: =IF(O6=0,0,Q6/O6) -> 0 | Q6: =-SUMIFS(BV_Data_An_Prec!$AM:$AM,BV_Data_An_Prec!$AP:$AP,$B6,BV_Data_An_Prec!$AQ:$AQ,$C6,BV_Data_An_Prec!$AR:$AR,Q$2) -> 0 | R6: =J6-O6 -> 0 | S6: =L6-Q6 -> 0 | V6: CARROSSERIE | W6: 0.025
A7: Véhicules neufsCamions détail | B7: Véhicules neufs | C7: Camions détail | D7: =+INDEX('Budget original'!$A$2:$AO$501,MATCH($A7,'Budget original'!$A$2:$A$501,0),MATCH(D$2,'Budget original'!$A$2:$AO$2,0)) -> 0 | E7: =IF(D7=0,0,F7/D7) -> 0 | F7: =+INDEX('Budget original'!$A$2:$AO$501,MATCH($A7,'Budget original'!$A$2:$A$501,0),MATCH(F$2,'Budget original'!$A$2:$AO$2,0)) -> 0 | J7: =SUMIFS(BV_Data_An_Cour!$AW:$AW,BV_Data_An_Cour!$AP:$AP,$B7,BV_Data_An_Cour!$AQ:$AQ,$C7,BV_Data_An_Cour!$AY:$AY,J$2) -> 37 | K7: =IF(J7=0,0,L7/J7) -> 1976.2027 | L7: =-SUMIFS(BV_Data_An_Cour!$AM:$AM,BV_Data_An_Cour!$AP:$AP,$B7,BV_Data_An_Cour!$AQ:$AQ,$C7,BV_Data_An_Cour!$AR:$AR,L$2) -> 73119.5 | M7: =J7-D7 -> 37 | N7: =L7-F7 -> 73119.5 | O7: =SUMIFS(BV_Data_An_Prec!$AW:$AW,BV_Data_An_Prec!$AP:$AP,$B7,BV_Data_An_Prec!$AQ:$AQ,$C7,BV_Data_An_Prec!$AY:$AY,O$2) -> 0 | P7: =IF(O7=0,0,Q7/O7) -> 0 | Q7: =-SUMIFS(BV_Data_An_Prec!$AM:$AM,BV_Data_An_Prec!$AP:$AP,$B7,BV_Data_An_Prec!$AQ:$AQ,$C7,BV_Data_An_Prec!$AR:$AR,Q$2) -> 0 | R7: =J7-O7 -> 37 | S7: =L7-Q7 -> 73119.5 | V7: PIECES | W7: 0.2
A8: Véhicules neufsSprinter | B8: Véhicules neufs | C8: Voitures electriques | D8: =+INDEX('Budget original'!$A$2:$AO$501,MATCH($A8,'Budget original'!$A$2:$A$501,0),MATCH(D$2,'Budget original'!$A$2:$AO$2,0)) -> 0 | E8: =IF(D8=0,0,F8/D8) -> 0 | F8: =+INDEX('Budget original'!$A$2:$AO$501,MATCH($A8,'Budget original'!$A$2:$A$501,0),MATCH(F$2,'Budget original'!$A$2:$AO$2,0)) -> 0 | J8: =SUMIFS(BV_Data_An_Cour!$AW:$AW,BV_Data_An_Cour!$AP:$AP,$B8,BV_Data_An_Cour!$AQ:$AQ,$C8,BV_Data_An_Cour!$AY:$AY,J$2) -> 0 | K8: =IF(J8=0,0,L8/J8) -> 0 | L8: =-SUMIFS(BV_Data_An_Cour!$AM:$AM,BV_Data_An_Cour!$AP:$AP,$B8,BV_Data_An_Cour!$AQ:$AQ,$C8,BV_Data_An_Cour!$AR:$AR,L$2) -> 0 | M8: =J8-D8 -> 0 | N8: =L8-F8 -> 0 | O8: =SUMIFS(BV_Data_An_Prec!$AW:$AW,BV_Data_An_Prec!$AP:$AP,$B8,BV_Data_An_Prec!$AQ:$AQ,$C8,BV_Data_An_Prec!$AY:$AY,O$2) -> 0 | P8: =IF(O8=0,0,Q8/O8) -> 0 | Q8: =-SUMIFS(BV_Data_An_Prec!$AM:$AM,BV_Data_An_Prec!$AP:$AP,$B8,BV_Data_An_Prec!$AQ:$AQ,$C8,BV_Data_An_Prec!$AR:$AR,Q$2) -> 0 | R8: =J8-O8 -> 0 | S8: =L8-Q8 -> 0 | W8: =SUM(W3:W7) -> 1
A9: Véhicules neufsMoto détail | B9: Véhicules neufs | C9: Camions electriques | D9: =+INDEX('Budget original'!$A$2:$AO$501,MATCH($A9,'Budget original'!$A$2:$A$501,0),MATCH(D$2,'Budget original'!$A$2:$AO$2,0)) -> 0 | E9: =IF(D9=0,0,F9/D9) -> 0 | F9: =+INDEX('Budget original'!$A$2:$AO$501,MATCH($A9,'Budget original'!$A$2:$A$501,0),MATCH(F$2,'Budget original'!$A$2:$AO$2,0)) -> 0 | J9: =SUMIFS(BV_Data_An_Cour!$AW:$AW,BV_Data_An_Cour!$AP:$AP,$B9,BV_Data_An_Cour!$AQ:$AQ,$C9,BV_Data_An_Cour!$AY:$AY,J$2) -> 17 | K9: =IF(J9=0,0,L9/J9) -> 436.17706 | L9: =-SUMIFS(BV_Data_An_Cour!$AM:$AM,BV_Data_An_Cour!$AP:$AP,$B9,BV_Data_An_Cour!$AQ:$AQ,$C9,BV_Data_An_Cour!$AR:$AR,L$2) -> 7415.01 | M9: =J9-D9 -> 17 | N9: =L9-F9 -> 7415.01 | O9: =SUMIFS(BV_Data_An_Prec!$AW:$AW,BV_Data_An_Prec!$AP:$AP,$B9,BV_Data_An_Prec!$AQ:$AQ,$C9,BV_Data_An_Prec!$AY:$AY,O$2) -> 0 | P9: =IF(O9=0,0,Q9/O9) -> 0 | Q9: =-SUMIFS(BV_Data_An_Prec!$AM:$AM,BV_Data_An_Prec!$AP:$AP,$B9,BV_Data_An_Prec!$AQ:$AQ,$C9,BV_Data_An_Prec!$AR:$AR,Q$2) -> 0 | R9: =J9-O9 -> 17 | S9: =L9-Q9 -> 7415.01
A10: Véhicules neufs[...] | B10: Véhicules neufs | C10: [...] | D10: =+INDEX('Budget original'!$A$2:$AO$501,MATCH($A10,'Budget original'!$A$2:$A$501,0),MATCH(D$2,'Budget original'!$A$2:$AO$2,0)) -> 0 | E10: =IF(D10=0,0,F10/D10) -> 0 | F10: =+INDEX('Budget original'!$A$2:$AO$501,MATCH($A10,'Budget original'!$A$2:$A$501,0),MATCH(F$2,'Budget original'!$A$2:$AO$2,0)) -> 0 | J10: =-SUMIFS(BV_Data_An_Cour!$AM:$AM,BV_Data_An_Cour!$AP:$AP,$B10,BV_Data_An_Cour!$AQ:$AQ,$C10,BV_Data_An_Cour!$AR:$AR,J$2) -> 0 | K10: =IF(J10=0,0,L10/J10) -> 0 | L10: =-SUMIFS(BV_Data_An_Cour!$AM:$AM,BV_Data_An_Cour!$AP:$AP,$B10,BV_Data_An_Cour!$AQ:$AQ,$C10,BV_Data_An_Cour!$AR:$AR,L$2) -> 0 | M10: =J10-D10 -> 0 | N10: =L10-F10 -> 0 | O10: =-SUMIFS(BV_Data_An_Prec!$AM:$AM,BV_Data_An_Prec!$AP:$AP,$B10,BV_Data_An_Prec!$AQ:$AQ,$C10,BV_Data_An_Prec!$AR:$AR,O$2) -> 0 | P10: =IF(O10=0,0,Q10/O10) -> 0 | Q10: =-SUMIFS(BV_Data_An_Prec!$AM:$AM,BV_Data_An_Prec!$AP:$AP,$B10,BV_Data_An_Prec!$AQ:$AQ,$C10,BV_Data_An_Prec!$AR:$AR,Q$2) -> 0 | R10: =J10-O10 -> 0 | S10: =L10-Q10 -> 0
A11: Véhicules neufs[...] | B11: Véhicules neufs | C11: [...] | D11: =+INDEX('Budget original'!$A$2:$AO$501,MATCH($A11,'Budget original'!$A$2:$A$501,0),MATCH(D$2,'Budget original'!$A$2:$AO$2,0)) -> 0 | E11: =IF(D11=0,0,F11/D11) -> 0 | F11: =+INDEX('Budget original'!$A$2:$AO$501,MATCH($A11,'Budget original'!$A$2:$A$501,0),MATCH(F$2,'Budget original'!$A$2:$AO$2,0)) -> 0 | J11: =-SUMIFS(BV_Data_An_Cour!$AM:$AM,BV_Data_An_Cour!$AP:$AP,$B11,BV_Data_An_Cour!$AQ:$AQ,$C11,BV_Data_An_Cour!$AR:$AR,J$2) -> 0 | K11: =IF(J11=0,0,L11/J11) -> 0 | L11: =-SUMIFS(BV_Data_An_Cour!$AM:$AM,BV_Data_An_Cour!$AP:$AP,$B11,BV_Data_An_Cour!$AQ:$AQ,$C11,BV_Data_An_Cour!$AR:$AR,L$2) -> 0 | M11: =J11-D11 -> 0 | N11: =L11-F11 -> 0 | O11: =-SUMIFS(BV_Data_An_Prec!$AM:$AM,BV_Data_An_Prec!$AP:$AP,$B11,BV_Data_An_Prec!$AQ:$AQ,$C11,BV_Data_An_Prec!$AR:$AR,O$2) -> 0 | P11: =IF(O11=0,0,Q11/O11) -> 0 | Q11: =-SUMIFS(BV_Data_An_Prec!$AM:$AM,BV_Data_An_Prec!$AP:$AP,$B11,BV_Data_An_Prec!$AQ:$AQ,$C11,BV_Data_An_Prec!$AR:$AR,Q$2) -> 0 | R11: =J11-O11 -> 0 | S11: =L11-Q11 -> 0
A12: Véhicules neufs[...] | B12: Véhicules neufs | C12: [...] | D12: =+INDEX('Budget original'!$A$2:$AO$501,MATCH($A12,'Budget original'!$A$2:$A$501,0),MATCH(D$2,'Budget original'!$A$2:$AO$2,0)) -> 0 | E12: =IF(D12=0,0,F12/D12) -> 0 | F12: =+INDEX('Budget original'!$A$2:$AO$501,MATCH($A12,'Budget original'!$A$2:$A$501,0),MATCH(F$2,'Budget original'!$A$2:$AO$2,0)) -> 0 | J12: =-SUMIFS(BV_Data_An_Cour!$AM:$AM,BV_Data_An_Cour!$AP:$AP,$B12,BV_Data_An_Cour!$AQ:$AQ,$C12,BV_Data_An_Cour!$AR:$AR,J$2) -> 0 | K12: =IF(J12=0,0,L12/J12) -> 0 | L12: =-SUMIFS(BV_Data_An_Cour!$AM:$AM,BV_Data_An_Cour!$AP:$AP,$B12,BV_Data_An_Cour!$AQ:$AQ,$C12,BV_Data_An_Cour!$AR:$AR,L$2) -> 0 | M12: =J12-D12 -> 0 | N12: =L12-F12 -> 0 | O12: =-SUMIFS(BV_Data_An_Prec!$AM:$AM,BV_Data_An_Prec!$AP:$AP,$B12,BV_Data_An_Prec!$AQ:$AQ,$C12,BV_Data_An_Prec!$AR:$AR,O$2) -> 0 | P12: =IF(O12=0,0,Q12/O12) -> 0 | Q12: =-SUMIFS(BV_Data_An_Prec!$AM:$AM,BV_Data_An_Prec!$AP:$AP,$B12,BV_Data_An_Prec!$AQ:$AQ,$C12,BV_Data_An_Prec!$AR:$AR,Q$2) -> 0 | R12: =J12-O12 -> 0 | S12: =L12-Q12 -> 0
A13: Véhicules neufsTotal Neufs | B13: Véhicules neufs | C13: Total Neufs | D13: =+SUM(D6:D12) -> 0 | E13: =IF(D13<=0,0,F13/D13) -> 0 | F13: =+SUM(F6:F12) -> 0 | J13: =+SUM(J6:J12) -> 54 | K13: =IF(J13<=0,0,L13/J13) -> 1491.3798 | L13: =+SUM(L6:L12) -> 80534.51 | M13: =+SUM(M6:M12) -> 54 | N13: =+SUM(N6:N12) -> 80534.51 | O13: =+SUM(O6:O12) -> 0 | P13: =IF(O13<=0,0,Q13/O13) -> 0 | Q13: =+SUM(Q6:Q12) -> 0 | R13: =+SUM(R6:R12) -> 54 | S13: =+SUM(S6:S12) -> 80534.51
A14: Véhicules neufs | B14: Véhicules neufs | M14: =IF(D13=0,0,M13/D13) -> 0 | N14: =IF(F13=0,0,N13/F13) -> 0 | R14: =R13/O13 -> #DIV/0! | S14: =IF(Q13=0,0,(S13/Q13)) -> 0 | AD14: 20 | AE14: 1000 | AF14: =AD14*AE14 -> 20000
A15: Véhicules neufsEx-Démos et courtoisies | B15: Véhicules neufs | C15: Ex-Démos et courtoisies | D15: =+INDEX('Budget original'!$A$2:$AO$501,MATCH($A15,'Budget original'!$A$2:$A$501,0),MATCH(D$2,'Budget original'!$A$2:$AO$2,0)) -> 0 | E15: =IF(D15=0,0,F15/D15) -> 0 | F15: =+INDEX('Budget original'!$A$2:$AO$501,MATCH($A15,'Budget original'!$A$2:$A$501,0),MATCH(F$2,'Budget original'!$A$2:$AO$2,0)) -> 0 | J15: =SUMIFS(BV_Data_An_Cour!$AW:$AW,BV_Data_An_Cour!$AP:$AP,$B15,BV_Data_An_Cour!$AQ:$AQ,$C15,BV_Data_An_Cour!$AY:$AY,J$2) -> 0 | K15: =IF(J15=0,0,L15/J15) -> 0 | L15: =-SUMIFS(BV_Data_An_Cour!$AM:$AM,BV_Data_An_Cour!$AP:$AP,$B15,BV_Data_An_Cour!$AQ:$AQ,$C15,BV_Data_An_Cour!$AR:$AR,L$2) -> 0 | M15: =J15-D15 -> 0 | N15: =L15-F15 -> 0 | O15: =SUMIFS(BV_Data_An_Prec!$AW:$AW,BV_Data_An_Prec!$AP:$AP,$B15,BV_Data_An_Prec!$AQ:$AQ,$C15,BV_Data_An_Prec!$AY:$AY,O$2) -> 0 | P15: =IF(O15=0,0,Q15/O15) -> 0 | Q15: =-SUMIFS(BV_Data_An_Prec!$AM:$AM,BV_Data_An_Prec!$AP:$AP,$B15,BV_Data_An_Prec!$AQ:$AQ,$C15,BV_Data_An_Prec!$AR:$AR,Q$2) -> 0 | R15: =J15-O15 -> 0 | S15: =L15-Q15 -> 0 | AD15: 25 | AE15: =AF15/AD15 -> 800 | AF15: =AF14 -> 20000
A16: Véhicules neufs | B16: Véhicules neufs
A17: Véhicules neufsFlottes | B17: Véhicules neufs | C17: Flottes | D17: =+INDEX('Budget original'!$A$2:$AO$501,MATCH($A17,'Budget original'!$A$2:$A$501,0),MATCH(D$2,'Budget original'!$A$2:$AO$2,0)) -> 0 | E17: =IF(D17=0,0,F17/D17) -> 0 | F17: =+INDEX('Budget original'!$A$2:$AO$501,MATCH($A17,'Budget original'!$A$2:$A$501,0),MATCH(F$2,'Budget original'!$A$2:$AO$2,0)) -> 0 | J17: =SUMIFS(BV_Data_An_Cour!$AW:$AW,BV_Data_An_Cour!$AP:$AP,$B17,BV_Data_An_Cour!$AQ:$AQ,$C17,BV_Data_An_Cour!$AY:$AY,J$2) -> 63 | K17: =IF(J17=0,0,L17/J17) -> 79.291587 | L17: =-SUMIFS(BV_Data_An_Cour!$AM:$AM,BV_Data_An_Cour!$AP:$AP,$B17,BV_Data_An_Cour!$AQ:$AQ,$C17,BV_Data_An_Cour!$AR:$AR,L$2) -> 4995.37 | M17: =J17-D17 -> 63 | N17: =L17-F17 -> 4995.37 | O17: =SUMIFS(BV_Data_An_Prec!$AW:$AW,BV_Data_An_Prec!$AP:$AP,$B17,BV_Data_An_Prec!$AQ:$AQ,$C17,BV_Data_An_Prec!$AY:$AY,O$2) -> 0 | P17: =IF(O17=0,0,Q17/O17) -> 0 | Q17: =-SUMIFS(BV_Data_An_Prec!$AM:$AM,BV_Data_An_Prec!$AP:$AP,$B17,BV_Data_An_Prec!$AQ:$AQ,$C17,BV_Data_An_Prec!$AR:$AR,Q$2) -> 0 | R17: =J17-O17 -> 63 | S17: =L17-Q17 -> 4995.37
A18: Véhicules neufs | B18: Véhicules neufs
A19: Véhicules neufsRachat bail | B19: Véhicules neufs
A20: Véhicules neufs | B20: Véhicules neufs
A21: Véhicules neufsRev. Finances | B21: Véhicules neufs | C21: Rev. Finances | D21: =+INDEX('Budget original'!$A$2:$AO$501,MATCH($A21,'Budget original'!$A$2:$A$501,0),MATCH(D$2,'Budget original'!$A$2:$AO$2,0)) -> 0 | E21: =IF(D21=0,0,F21/D21) -> 0 | F21: =+INDEX('Budget original'!$A$2:$AO$501,MATCH($A21,'Budget original'!$A$2:$A$501,0),MATCH(F$2,'Budget original'!$A$2:$AO$2,0)) -> 0 | K21: =IF(J13=0,0,L21/(J13+J15)) -> 22.222222 | L21: =-SUMIFS(BV_Data_An_Cour!$AM:$AM,BV_Data_An_Cour!$AP:$AP,$B21,BV_Data_An_Cour!$AQ:$AQ,$C21,BV_Data_An_Cour!$AR:$AR,L$2) -> 1200 | N21: =L21-F21 -> 1200 | P21: =IF(O13=0,0,Q21/(O13+O15)) -> 0 | Q21: =-SUMIFS(BV_Data_An_Prec!$AM:$AM,BV_Data_An_Prec!$AP:$AP,$B21,BV_Data_An_Prec!$AQ:$AQ,$C21,BV_Data_An_Prec!$AR:$AR,Q$2) -> 0 | R21: =P21-K21 -> -22.222222 | S21: =L21-Q21 -> 1200
