Workbook

Sheet Sommaire
B2: Vehicules neuf | K2: Classement | L2: 121-180
B4: Classement | C4: Unite | D4: % unite | E4: Montant | F4: % Montant | K4: Row Labels | L4: Sum of 1402 | M4: Count of NIV
B5: 301 & + | C5: =COUNTIF(Neuf!G:G,Sommaire!B5) -> 5 | D5: =C5/$C$12 -> 0.04950495 | E5: =SUMIF(Neuf!G:G,Sommaire!B5,Neuf!C:C) -> 203768.72 | F5: =E5/$E$12 -> 0.043257396 | K5: 23 VOLKSWAGEN JETTA SEDAN | L5: 30245.52 | M5: 1
B6: 181-300 | C6: =COUNTIF(Neuf!G:G,Sommaire!B6) -> 22 | D6: =C6/$C$12 -> 0.21782178 | E6: =SUMIF(Neuf!G:G,Sommaire!B6,Neuf!C:C) -> 1151716.4 | F6: =E6/$E$12 -> 0.24449411 | K6: 23 VOLKSWAGEN TAOS | L6: 105746.7 | M6: 3
B7: 121-180 | C7: =COUNTIF(Neuf!G:G,Sommaire!B7) -> 11 | D7: =C7/$C$12 -> 0.10891089 | E7: =SUMIF(Neuf!G:G,Sommaire!B7,Neuf!C:C) -> 573885.46 | F7: =E7/$E$12 -> 0.12182827 | K7: 24 VOLKSWAGEN ATLAS | L7: 210943.85 | M7: 4
B8: 91-120 | C8: =COUNTIF(Neuf!G:G,Sommaire!B8) -> 17 | D8: =C8/$C$12 -> 0.16831683 | E8: =SUMIF(Neuf!G:G,Sommaire!B8,Neuf!C:C) -> 705352.47 | F8: =E8/$E$12 -> 0.14973697 | K8: 24 VOLKSWAGEN ATLAS CROSS SPT | L8: 379166.39 | M8: 7
B9: 61-90 | C9: =COUNTIF(Neuf!G:G,Sommaire!B9) -> 9 | D9: =C9/$C$12 -> 0.089108911 | E9: =SUMIF(Neuf!G:G,Sommaire!B9,Neuf!C:C) -> 354272.06 | F9: =E9/$E$12 -> 0.075207259 | K9: 24 VOLKSWAGEN GOLF GTI | L9: 37506.9 | M9: 1
B10: 31-60 | C10: =COUNTIF(Neuf!G:G,Sommaire!B10) -> 11 | D10: =C10/$C$12 -> 0.10891089 | E10: =SUMIF(Neuf!G:G,Sommaire!B10,Neuf!C:C) -> 539345.45 | F10: =E10/$E$12 -> 0.11449589 | K10: 24 VOLKSWAGEN JETTA GLI | L10: 32637 | M10: 1
B11: 0-30 | C11: =COUNTIF(Neuf!G:G,Sommaire!B11) -> 26 | D11: =C11/$C$12 -> 0.25742574 | E11: =SUMIF(Neuf!G:G,Sommaire!B11,Neuf!C:C) -> 1182269.4 | F11: =E11/$E$12 -> 0.25098011 | K11: 24 VOLKSWAGEN JETTA SEDAN | L11: 60613.97 | M11: 2
B12: Total | C12: =SUM(C5:C11) -> 101 | D12: =SUM(D5:D11) -> 1 | E12: =SUM(E5:E11) -> 4710609.9 | F12: =SUM(F5:F11) -> 1 | K12: Grand Total | L12: 856860.33 | M12: 19
B13: Valeur moyenne reel | E13: =E12/C12 -> 46639.702
B15: Budget | C15: ='Unite budgete'!C7 -> 60.71 | D15: =C12/C15 -> 1.6636468 | E15: ='Unite budgete'!C8 -> 2623173.6 | F15: =E12/E15 -> 1.7957675
B16: Ecart | C16: =C12-C15 -> 40.29 | E16: =E12-E15 -> 2087436.3
B17: Valeur moyenne budgete | E17: =E15/C15 -> 43208.262
B21: Vehicules usages
B23: Classement | C23: Unite | D23: % unite | E23: Montant | F23: % Montant | L23: Sum of 1416 | M23: Count of NIV | N23: Count of Classement
B24: 301 & + | C24: =COUNTIF(Usages!G:G,Sommaire!B24) -> 4 | D24: =C24/$C$31 -> 0.1025641 | E24: =SUMIF(Usages!G:G,Sommaire!B24,Usages!C:C) -> 85414.23 | F24: =E24/$E$31 -> 0.10828751 | K24: 121-180 | L24: 254592.93 | M24: 10 | N24: 10
B25: 181-300 | C25: =COUNTIF(Usages!G:G,Sommaire!B25) -> 0 | D25: =C25/$C$31 -> 0 | E25: =SUMIF(Usages!G:G,Sommaire!B25,Usages!C:C) -> 0 | F25: =E25/$E$31 -> 0 | K25: 17 AUDI A3 E-TRON | L25: 20107 | M25: 1 | N25: 1
B26: 121-180 | C26: =COUNTIF(Usages!G:G,Sommaire!B26) -> 0 | D26: =C26/$C$31 -> 0 | E26: =SUMIF(Usages!G:G,Sommaire!B26,Usages!C:C) -> 0 | F26: =E26/$E$31 -> 0 | K26: 18 CHEVROLET VOLT | L26: 17701.95 | M26: 1 | N26: 1
B27: 91-120 | C27: =COUNTIF(Usages!G:G,Sommaire!B27) -> 1 | D27: =C27/$C$31 -> 0.025641026 | E27: =SUMIF(Usages!G:G,Sommaire!B27,Usages!C:C) -> 1207.5 | F27: =E27/$E$31 -> 0.0015308593 | K27: 19 VOLKSWAGEN TIGUAN | L27: 26815.25 | M27: 1 | N27: 1
B28: 61-90 | C28: =COUNTIF(Usages!G:G,Sommaire!B28) -> 2 | D28: =C28/$C$31 -> 0.051282051 | E28: =SUMIF(Usages!G:G,Sommaire!B28,Usages!C:C) -> 39188.3 | F28: =E28/$E$31 -> 0.049682627 | K28: 20 JEEP COMPASS | L28: 28211.38 | M28: 1 | N28: 1
B29: 31-60 | C29: =COUNTIF(Usages!G:G,Sommaire!B29) -> 7 | D29: =C29/$C$31 -> 0.17948718 | E29: =SUMIF(Usages!G:G,Sommaire!B29,Usages!C:C) -> 183027.53 | F29: =E29/$E$31 -> 0.2320409 | K29: 20 VOLKSWAGEN JETTA | L29: 18043.82 | M29: 1 | N29: 1
B30: 0-30 | C30: =COUNTIF(Usages!G:G,Sommaire!B30) -> 25 | D30: =C30/$C$31 -> 0.64102564 | E30: =SUMIF(Usages!G:G,Sommaire!B30,Usages!C:C) -> 479935.14 | F30: =E30/$E$31 -> 0.6084581 | K30: 20 VOLKSWAGEN TIGUAN | L30: 86631.13 | M30: 3 | N30: 3
B31: Total | C31: =SUM(C24:C30) -> 39 | D31: =SUM(D24:D30) -> 1 | E31: =SUM(E24:E30) -> 788772.7 | F31: =E31/$E$31 -> 1 | K31: 21 VOLKSWAGEN TIGUAN | L31: 57082.4 | M31: 2 | N31: 2
B32: Valeur moyenne reel | E32: =E31/C31 -> 20224.941 | K32: 181-300 | L32: 46931.51 | M32: 2 | N32: 2
K33: 10 VOLKSWAGEN ROUTAN | L33: 11646.62 | M33: 1 | N33: 1 | O33: Homme de cours
B34: Budget | C34: ='Unite budgete'!C14 -> 90.4465 | D34: =C31/C34 -> 0.43119413 | E34: ='Unite budgete'!C15 -> 2101286.3 | F34: =E31/E34 -> 0.37537612 | K34: 19 GMC SAVANA CARGO VA | L34: 35284.89 | M34: 1 | N34: 1 | O34: Homme de cours
B35: Ecart | C35: =C31-C34 -> -51.4465 | E35: =E31-E34 -> -1312513.6 | K35: 301 & + | L35: 64330.07 | M35: 3 | N35: 3
B36: Valeur moyenne budgete | E36: =E34/C34 -> 23232.368 | K36: 11 VOLKSWAGEN JETTA SEDAN | L36: 9140.85 | M36: 1 | N36: 1
K37: 20 VOLKSWAGEN E-GOLF | L37: 55189.22 | M37: 2 | N37: 2
K38: Grand Total | L38: 365854.51 | M38: 15 | N38: 15

Sheet Neuf
A1: #Contrôle | B1: Description | C1: 1402 | D1: 2101 | E1: NIV | F1: Jours en stock | G1: Classement | J1: $ Inventaire | K1: $ Financé
A2: 230639 | B2: 23 VOLKSWAGEN TAOS | C2: 29553.74 | D2: -32332.96 | E2: 3VVEX7B23PM379190 | F2: 477 | G2: =_xlfn.IFS(F2<31,"0-30",F2<61,"31-60",F2<91,"61-90",F2<121,"91-120",F2<181,"121-180",F2<301,"181-300",F2>300,"301 & +") -> 301 & + | I2: CTRL | J2: =SUM(C:C) -> 4710609.9 | K2: =SUM(D:D) -> -4701560.1
A3: 240070 | B3: 24 VOLKSWAGEN ATLAS CROSS SPT | C3: 55895.64 | D3: -57051.75 | E3: 1V2BE2CA9RC212335 | F3: 465 | G3: =_xlfn.IFS(F3<31,"0-30",F3<61,"31-60",F3<91,"61-90",F3<121,"91-120",F3<181,"121-180",F3<301,"181-300",F3>300,"301 & +") -> 301 & + | I3: # unités | J3: =COUNT(C:C) -> 101 | K3: =-K2/J2 -> 0.99807885
A4: 240475 | B4: 24 VOLKSWAGEN ATLAS CROSS SPT | C4: 57448.98 | D4: -57916.95 | E4: 1V2BE2CA8RC234066 | F4: 323 | G4: =_xlfn.IFS(F4<31,"0-30",F4<61,"31-60",F4<91,"61-90",F4<121,"91-120",F4<181,"121-180",F4<301,"181-300",F4>300,"301 & +") -> 301 & +
A5: 240494 | B5: 24 VOLKSWAGEN JETTA SEDAN | C5: 31936.52 | D5: -33502.35 | E5: 3VWGM7BU6RM052560 | F5: 309 | G5: =_xlfn.IFS(F5<31,"0-30",F5<61,"31-60",F5<91,"61-90",F5<121,"91-120",F5<181,"121-180",F5<301,"181-300",F5>300,"301 & +") -> 301 & +
A6: 240506 | B6: 24 VOLKSWAGEN JETTA SEDAN | C6: 28933.84 | D6: -33309.15 | E6: 3VWGM7BU1RM051705 | F6: 304 | G6: =_xlfn.IFS(F6<31,"0-30",F6<61,"31-60",F6<91,"61-90",F6<121,"91-120",F6<181,"121-180",F6<301,"181-300",F6>300,"301 & +") -> 301 & + | N6: Financé | O6: Interet / mois | P6: Interet / auto
A7: 240522 | B7: 24 VOLKSWAGEN ATLAS CROSS SPT | C7: 55225.42 | D7: -57637.65 | E7: 1V2BE2CA0RC236135 | F7: 296 | G7: =_xlfn.IFS(F7<31,"0-30",F7<61,"31-60",F7<91,"61-90",F7<121,"91-120",F7<181,"121-180",F7<301,"181-300",F7>300,"301 & +") -> 181-300 | I7: Plus de 365 jrs | J7: =COUNTIF(F:F,">=365") -> 2 | K7: =SUMIF(F:F,">=365",C:C) -> 85449.38 | M7: =COUNTIFS(F:F,">=365",D:D,"<>"&"") -> 2 | N7: =SUMIF(F:F,">=365",D:D) -> -89384.71 | O7: =N7*0.07/12 -> -521.41081 | P7: =IF(J7=0,0,O7/J7) -> -260.7054
A8: 240576 | B8: 24 VOLKSWAGEN JETTA SEDAN | C8: 27643.39 | D8: -31492.65 | E8: 3VWSM7BU4RM044399 | F8: 287 | G8: =_xlfn.IFS(F8<31,"0-30",F8<61,"31-60",F8<91,"61-90",F8<121,"91-120",F8<181,"121-180",F8<301,"181-300",F8>300,"301 & +") -> 181-300 | I8: Entre 180 et 364 jours | J8: =COUNTIFS(F:F,"<365",F:F,">=180") -> 25 | K8: =SUMIFS(C:C,F:F,"<365",F:F,">=180") -> 1270035.7 | M8: =COUNTIFS(F:F,"<365",F:F,">=180",D:D,"<>"&"") -> 25 | N8: =SUMIFS(D:D,F:F,"<365",F:F,">=180") -> -1338374.1 | O8: =N8*0.07/12 -> -7807.1823 | P8: =IF(J8=0,0,O8/J8) -> -312.28729
A9: 240641 | B9: 24 VOLKSWAGEN ID.4 | C9: 56913.26 | D9: -62208.3 | E9: 1V2WSPE88RC008661 | F9: 273 | G9: =_xlfn.IFS(F9<31,"0-30",F9<61,"31-60",F9<91,"61-90",F9<121,"91-120",F9<181,"121-180",F9<301,"181-300",F9>300,"301 & +") -> 181-300 | I9: Entre 90 et 179 jours | J9: =COUNTIFS(F:F,"<180",F:F,">=90") -> 28 | K9: =SUMIFS(C:C,F:F,"<180",F:F,">=90") -> 1279237.9 | M9: =COUNTIFS(F:F,"<180",F:F,">=90",D:D,"<>"&"") -> 28 | N9: =SUMIFS(D:D,F:F,"<180",F:F,">=90") -> -1336243.6 | O9: =N9*0.07/12 -> -7794.7546 | P9: =IF(M9=0,0,O9/M9) -> -278.38409
A10: 240711 | B10: 24 VOLKSWAGEN ID.4 | C10: 55920 | D10: -61717.95 | E10: 1V27SPE80RC011610 | F10: 247 | G10: =_xlfn.IFS(F10<31,"0-30",F10<61,"31-60",F10<91,"61-90",F10<121,"91-120",F10<181,"121-180",F10<301,"181-300",F10>300,"301 & +") -> 181-300 | I10: Entre 0 et 89 jours | J10: =COUNTIF(F:F,"<90") -> 46 | K10: =SUMIF(F:F,"<90",C:C) -> 2075886.9 | M10: =COUNTIFS(F:F,"<90",D:D,"<>"&"") -> 41 | N10: =SUMIF(F:F,"<90",D:D) -> -1937557.6 | O10: =N10*0.07/12 -> -11302.42 | P10: =IF(M10=0,0,O10/M10) -> -275.66877
A11: 240706 | B11: 24 VOLKSWAGEN TAOS | C11: 38470.52 | D11: -40085.85 | E11: 3VV4X7B23RM081155 | F11: 247 | G11: =_xlfn.IFS(F11<31,"0-30",F11<61,"31-60",F11<91,"61-90",F11<121,"91-120",F11<181,"121-180",F11<301,"181-300",F11>300,"301 & +") -> 181-300
A12: 240710 | B12: 24 VOLKSWAGEN JETTA SEDAN | C12: 30268.13 | D12: -33502.35 | E12: 3VWGM7BU2RM082395 | F12: 247 | G12: =_xlfn.IFS(F12<31,"0-30",F12<61,"31-60",F12<91,"61-90",F12<121,"91-120",F12<181,"121-180",F12<301,"181-300",F12>300,"301 & +") -> 181-300
A13: 240714 | B13: 24 VOLKSWAGEN ATLAS CROSS SPT | C13: 55737.97 | D13: -57156.75 | E13: 1V2BE2CA3RC244875 | F13: 245 | G13: =_xlfn.IFS(F13<31,"0-30",F13<61,"31-60",F13<91,"61-90",F13<121,"91-120",F13<181,"121-180",F13<301,"181-300",F13>300,"301 & +") -> 181-300
A14: 240729 | B14: 24 VOLKSWAGEN ID.4 | C14: 60499.92 | D14: -63190.05 | E14: 1V2WSPE82RC013757 | F14: 240 | G14: =_xlfn.IFS(F14<31,"0-30",F14<61,"31-60",F14<91,"61-90",F14<121,"91-120",F14<181,"121-180",F14<301,"181-300",F14>300,"301 & +") -> 181-300
A15: 240728 | B15: 24 VOLKSWAGEN ID.4 | C15: 59092.92 | D15: -62208.3 | E15: 1V27SPE81RC013009 | F15: 240 | G15: =_xlfn.IFS(F15<31,"0-30",F15<61,"31-60",F15<91,"61-90",F15<121,"91-120",F15<181,"121-180",F15<301,"181-300",F15>300,"301 & +") -> 181-300
A16: 240724 | B16: 24 VOLKSWAGEN JETTA GLI | C16: 33471.57 | D16: -34468.35 | E16: 3VW9T7BU9RM081465 | F16: 240 | G16: =_xlfn.IFS(F16<31,"0-30",F16<61,"31-60",F16<91,"61-90",F16<121,"91-120",F16<181,"121-180",F16<301,"181-300",F16>300,"301 & +") -> 181-300
A17: 240723 | B17: 24 VOLKSWAGEN JETTA GLI | C17: 32912.52 | D17: -34468.35 | E17: 3VW9T7BU0RM081421 | F17: 240 | G17: =_xlfn.IFS(F17<31,"0-30",F17<61,"31-60",F17<91,"61-90",F17<121,"91-120",F17<181,"121-180",F17<301,"181-300",F17>300,"301 & +") -> 181-300
A18: 240762 | B18: 24 VOLKSWAGEN ID.4 | C18: 61188.87 | D18: -63190.05 | E18: 1V2WSPE88RC013357 | F18: 225 | G18: =_xlfn.IFS(F18<31,"0-30",F18<61,"31-60",F18<91,"61-90",F18<121,"91-120",F18<181,"121-180",F18<301,"181-300",F18>300,"301 & +") -> 181-300
A19: 240757 | B19: 24 VOLKSWAGEN ID.4 | C19: 60103.92 | D19: -63190.05 | E19: 1V2WSPE80RC014101 | F19: 225 | G19: =_xlfn.IFS(F19<31,"0-30",F19<61,"31-60",F19<91,"61-90",F19<121,"91-120",F19<181,"121-180",F19<301,"181-300",F19>300,"301 & +") -> 181-300
A20: 240786 | B20: 24 VOLKSWAGEN ID.4 | C20: 60103.92 | D20: -63190.05 | E20: 1V2WSPE81RC015063 | F20: 217 | G20: =_xlfn.IFS(F20<31,"0-30",F20<61,"31-60",F20<91,"61-90",F20<121,"91-120",F20<181,"121-180",F20<301,"181-300",F20>300,"301 & +") -> 181-300
A21: 240793 | B21: 24 VOLKSWAGEN ID.4 | C21: 60103.92 | D21: -63190.05 | E21: 1V2WSPE83RC015517 | F21: 213 | G21: =_xlfn.IFS(F21<31,"0-30",F21<61,"31-60",F21<91,"61-90",F21<121,"91-120",F21<181,"121-180",F21<301,"181-300",F21>300,"301 & +") -> 181-300
A22: 240791 | B22: 24 VOLKSWAGEN ATLAS | C22: 55642.56 | D22: -56772.45 | E22: 1V2CR2CA5RC594288 | F22: 213 | G22: =_xlfn.IFS(F22<31,"0-30",F22<61,"31-60",F22<91,"61-90",F22<121,"91-120",F22<181,"121-180",F22<301,"181-300",F22>300,"301 & +") -> 181-300
... A74: 241119 | B74: 24 VOLKSWAGEN TIGUAN | C74: 41237 | D74: -43886.85 | E74: 3VV8B7AX3RM233710 | F74: 44 | G74: =_xlfn.IFS(F74<31,"0-30",F74<61,"31-60",F74<91,"61-90",F74<121,"91-120",F74<181,"121-180",F74<301,"181-300",F74>300,"301 & +") -> 31-60
A75: 241120 | B75: 24 VOLKSWAGEN TAOS | C75: 39908.6 | E75: 3VV4X7B25RM089712 | F75: 43 | G75: =_xlfn.IFS(F75<31,"0-30",F75<61,"31-60",F75<91,"61-90",F75<121,"91-120",F75<181,"121-180",F75<301,"181-300",F75>300,"301 & +") -> 31-60
A76: 241121 | B76: 24 VOLKSWAGEN GOLF R | C76: 50521.32 | E76: WVWFB7CD9RW229380 | F76: 39 | G76: =_xlfn.IFS(F76<31,"0-30",F76<61,"31-60",F76<91,"61-90",F76<121,"91-120",F76<181,"121-180",F76<301,"181-300",F76>300,"301 & +") -> 31-60
A77: 241123 | B77: 24 VOLKSWAGEN GOLF R | C77: 49169.32 | E77: WVWCB7CD0RW221414 | F77: 24 | G77: =_xlfn.IFS(F77<31,"0-30",F77<61,"31-60",F77<91,"61-90",F77<121,"91-120",F77<181,"121-180",F77<301,"181-300",F77>300,"301 & +") -> 0-30
A78: 241128 | B78: 24 VOLKSWAGEN GOLF GTI | C78: 40306.92 | D78: -42374.85 | E78: WVWWA7CD4RW233274 | F78: 18 | G78: =_xlfn.IFS(F78<31,"0-30",F78<61,"31-60",F78<91,"61-90",F78<121,"91-120",F78<181,"121-180",F78<301,"181-300",F78>300,"301 & +") -> 0-30
A79: 250075 | B79: 25 VOLKSWAGEN ID.BUZZ | C79: 84629.46 | D79: -87242.4 | E79: WVG6YVEB0SH014975 | F79: 17 | G79: =_xlfn.IFS(F79<31,"0-30",F79<61,"31-60",F79<91,"61-90",F79<121,"91-120",F79<181,"121-180",F79<301,"181-300",F79>300,"301 & +") -> 0-30
A80: 241137 | B80: 24 VOLKSWAGEN ID.4 | C80: 60657 | D80: -64183.35 | E80: 1V29SPE81RC023242 | F80: 17 | G80: =_xlfn.IFS(F80<31,"0-30",F80<61,"31-60",F80<91,"61-90",F80<121,"91-120",F80<181,"121-180",F80<301,"181-300",F80>300,"301 & +") -> 0-30
A81: 241131 | B81: 24 VOLKSWAGEN ID.4 | C81: 60652 | D81: -64183.35 | E81: 1V29SPE80RC023409 | F81: 17 | G81: =_xlfn.IFS(F81<31,"0-30",F81<61,"31-60",F81<91,"61-90",F81<121,"91-120",F81<181,"121-180",F81<301,"181-300",F81>300,"301 & +") -> 0-30
A82: 241129 | B82: 24 VOLKSWAGEN ID.4 | C82: 59249 | D82: -62710.2 | E82: 1V29SPE87RC022483 | F82: 17 | G82: =_xlfn.IFS(F82<31,"0-30",F82<61,"31-60",F82<91,"61-90",F82<121,"91-120",F82<181,"121-180",F82<301,"181-300",F82>300,"301 & +") -> 0-30
A83: 241134 | B83: 24 VOLKSWAGEN ID.4 | C83: 59164 | D83: -62710.2 | E83: 1V29SPE88RC023173 | F83: 17 | G83: =_xlfn.IFS(F83<31,"0-30",F83<61,"31-60",F83<91,"61-90",F83<121,"91-120",F83<181,"121-180",F83<301,"181-300",F83>300,"301 & +") -> 0-30
A84: 250076 | B84: 25 VOLKSWAGEN JETTA SEDAN | C84: 29099.92 | D84: -30524.55 | E84: 3VWEX7BU9SM044232 | F84: 17 | G84: =_xlfn.IFS(F84<31,"0-30",F84<61,"31-60",F84<91,"61-90",F84<121,"91-120",F84<181,"121-180",F84<301,"181-300",F84>300,"301 & +") -> 0-30
A85: 250077 | B85: 25 VOLKSWAGEN JETTA SEDAN | C85: 26338 | D85: -28137.9 | E85: 3VWCX7BU2SM041535 | F85: 17 | G85: =_xlfn.IFS(F85<31,"0-30",F85<61,"31-60",F85<91,"61-90",F85<121,"91-120",F85<181,"121-180",F85<301,"181-300",F85>300,"301 & +") -> 0-30
A86: 241138 | B86: 24 VOLKSWAGEN ID.4 | C86: 59164 | D86: -62710.2 | E86: 1V29SPE85RC024037 | F86: 15 | G86: =_xlfn.IFS(F86<31,"0-30",F86<61,"31-60",F86<91,"61-90",F86<121,"91-120",F86<181,"121-180",F86<301,"181-300",F86>300,"301 & +") -> 0-30
A87: 241139 | B87: 24 VOLKSWAGEN ID.4 | C87: 61034 | D87: -64673.7 | E87: 1V29SPE85RC023857 | F87: 14 | G87: =_xlfn.IFS(F87<31,"0-30",F87<61,"31-60",F87<91,"61-90",F87<121,"91-120",F87<181,"121-180",F87<301,"181-300",F87>300,"301 & +") -> 0-30
A88: 250088 | B88: 25 VOLKSWAGEN TAOS | C88: 32482.92 | D88: -34165.95 | E88: 3VV8C7B2XSM008268 | F88: 14 | G88: =_xlfn.IFS(F88<31,"0-30",F88<61,"31-60",F88<91,"61-90",F88<121,"91-120",F88<181,"121-180",F88<301,"181-300",F88>300,"301 & +") -> 0-30
A89: 250089 | B89: 25 VOLKSWAGEN TAOS | C89: 32377.92 | D89: -34165.95 | E89: 3VV8C7B2XSM016497 | F89: 14 | G89: =_xlfn.IFS(F89<31,"0-30",F89<61,"31-60",F89<91,"61-90",F89<121,"91-120",F89<181,"121-180",F89<301,"181-300",F89>300,"301 & +") -> 0-30
... A99: 250096 | B99: 25 VOLKSWAGEN JETTA SEDAN | C99: 26338 | D99: -28137.9 | E99: 3VWCX7BU8SM045038 | F99: 7 | G99: =_xlfn.IFS(F99<31,"0-30",F99<61,"31-60",F99<91,"61-90",F99<121,"91-120",F99<181,"121-180",F99<301,"181-300",F99>300,"301 & +") -> 0-30
A100: 241126 | B100: 24 VOLKSWAGEN TIGUAN | C100: 41463 | E100: 3VV8B7AX8RM130315 | F100: 4 | G100: =_xlfn.IFS(F100<31,"0-30",F100<61,"31-60",F100<91,"61-90",F100<121,"91-120",F100<181,"121-180",F100<301,"181-300",F100>300,"301 & +") -> 0-30
...

Sheet Usages
A1: #Contrôle | B1: Description | C1: 1416 | D1: 2103 | E1: NIV | F1: Jours en stock | G1: Classement | J1: $ Inventaire | K1: $ Financé
A2: 5188P | B2: 11 VOLKSWAGEN JETTA SEDAN | C2: 9085.68 | E2: 3VWLL7AJ3BM097101 | F2: 982 | G2: =_xlfn.IFS(F2<31,"0-30",F2<61,"31-60",F2<91,"61-90",F2<121,"91-120",F2<181,"121-180",F2<301,"181-300",F2>300,"301 & +") -> 301 & + | I2: CTRL | J2: =SUM(C:C) -> 788772.7 | K2: =SUM(D:D) -> -252348.4
A3: 5291P | B3: 20 VOLKSWAGEN E-GOLF | C3: 28977.22 | E3: WVWPR7AU2LW903993 | F3: 820 | G3: =_xlfn.IFS(F3<31,"0-30",F3<61,"31-60",F3<91,"61-90",F3<121,"91-120",F3<181,"121-180",F3<301,"181-300",F3>300,"301 & +") -> 301 & + | I3: # unités | J3: =COUNT(C:C) -> 39 | K3: =-K2/J2 -> 0.31992537
A4: 5407P | B4: 19 GMC SAVANA CARGO VA | C4: 33488.49 | E4: 1GTW7BFP1K1340423 | F4: 637 | G4: =_xlfn.IFS(F4<31,"0-30",F4<61,"31-60",F4<91,"61-90",F4<121,"91-120",F4<181,"121-180",F4<301,"181-300",F4>300,"301 & +") -> 301 & +
A5: 5488P | B5: 10 VOLKSWAGEN ROUTAN | C5: 13862.84 | E5: 2V4RW3DX0AR228009 | F5: 522 | G5: =_xlfn.IFS(F5<31,"0-30",F5<61,"31-60",F5<91,"61-90",F5<121,"91-120",F5<181,"121-180",F5<301,"181-300",F5>300,"301 & +") -> 301 & +
A6: 240901A | B6: 16 VOLKSWAGEN JETTA SEDAN | C6: 1207.5 | E6: 3VW267AJ1GM273220 | F6: 108 | G6: =_xlfn.IFS(F6<31,"0-30",F6<61,"31-60",F6<91,"61-90",F6<121,"91-120",F6<181,"121-180",F6<301,"181-300",F6>300,"301 & +") -> 91-120 | N6: Financé | O6: Interet / mois | P6: Interet / auto
A7: 5693P | B7: 17 AUDI A3 | C7: 10539.83 | E7: WAUB8GFF8H1078356 | F7: 66 | G7: =_xlfn.IFS(F7<31,"0-30",F7<61,"31-60",F7<91,"61-90",F7<121,"91-120",F7<181,"121-180",F7<301,"181-300",F7>300,"301 & +") -> 61-90 | I7: Plus de 365 jrs | J7: =COUNTIF(F:F,">=365") -> 4 | K7: =SUMIF(F:F,">=365",C:C) -> 85414.23 | M7: =COUNTIFS(F:F,">=365",D:D,"<>"&"") -> 0 | N7: =SUMIF(F:F,">=365",D:D) -> 0 | O7: =N7*0.07/12 -> 0 | P7: =IF(J7=0,0,O7/J7) -> 0
A8: 5697P | B8: 22 VOLKSWAGEN GOLF GTI | C8: 28648.47 | D8: -27069 | E8: WVW587CD3NW124581 | F8: 63 | G8: =_xlfn.IFS(F8<31,"0-30",F8<61,"31-60",F8<91,"61-90",F8<121,"91-120",F8<181,"121-180",F8<301,"181-300",F8>300,"301 & +") -> 61-90 | I8: Entre 180 et 364 jours | J8: =COUNTIFS(F:F,"<365",F:F,">=180") -> 0 | K8: =SUMIFS(C:C,F:F,"<365",F:F,">=180") -> 0 | M8: =COUNTIFS(F:F,"<365",F:F,">=180",D:D,"<>"&"") -> 0 | N8: =SUMIFS(D:D,F:F,"<365",F:F,">=180") -> 0 | O8: =N8*0.07/12 -> 0 | P8: =IF(J8=0,0,O8/J8) -> 0
A9: 5700P | B9: 24 VOLKSWAGEN ATLAS | C9: 55699.47 | D9: -48960 | E9: 1V2FR2CA6RC622211 | F9: 60 | G9: =_xlfn.IFS(F9<31,"0-30",F9<61,"31-60",F9<91,"61-90",F9<121,"91-120",F9<181,"121-180",F9<301,"181-300",F9>300,"301 & +") -> 31-60 | I9: Entre 90 et 179 jours | J9: =COUNTIFS(F:F,"<180",F:F,">=90") -> 1 | K9: =SUMIFS(C:C,F:F,"<180",F:F,">=90") -> 1207.5 | M9: =COUNTIFS(F:F,"<180",F:F,">=90",D:D,"<>"&"") -> 0 | N9: =SUMIFS(D:D,F:F,"<180",F:F,">=90") -> 0 | O9: =N9*0.07/12 -> 0 | P9: =IF(M9=0,0,O9/M9) -> 0
A10: 241105A | B10: 23 VOLKSWAGEN TAOS | C10: 26612.45 | D10: -30995.42 | E10: 3VVNX7B20PM323160 | F10: 53 | G10: =_xlfn.IFS(F10<31,"0-30",F10<61,"31-60",F10<91,"61-90",F10<121,"91-120",F10<181,"121-180",F10<301,"181-300",F10>300,"301 & +") -> 31-60 | I10: Entre 0 et 89 jours | J10: =COUNTIF(F:F,"<90") -> 34 | K10: =SUMIF(F:F,"<90",C:C) -> 702150.97 | M10: =COUNTIFS(F:F,"<90",D:D,"<>"&"") -> 10 | N10: =SUMIF(F:F,"<90",D:D) -> -252348.4 | O10: =N10*0.07/12 -> -1472.0323 | P10: =IF(M10=0,0,O10/M10) -> -147.20323
A11: 5707P | B11: 19 VOLKSWAGEN ATLAS | C11: 22661.53 | D11: -19203 | E11: 1V2RR2CA9KC592169 | F11: 42 | G11: =_xlfn.IFS(F11<31,"0-30",F11<61,"31-60",F11<91,"61-90",F11<121,"91-120",F11<181,"121-180",F11<301,"181-300",F11>300,"301 & +") -> 31-60
A12: 241116A | B12: 23 HYUNDAI TUCSON HYBRID | C12: 30101.38 | E12: KM8JCCA12PU097253 | F12: 39 | G12: =_xlfn.IFS(F12<31,"0-30",F12<61,"31-60",F12<91,"61-90",F12<121,"91-120",F12<181,"121-180",F12<301,"181-300",F12>300,"301 & +") -> 31-60
A13: 240979A | B13: 16 VOLKSWAGEN GOLF SPORTWAGON | C13: 6041.43 | E13: 3VWA17AU9GM507916 | F13: 35 | G13: =_xlfn.IFS(F13<31,"0-30",F13<61,"31-60",F13<91,"61-90",F13<121,"91-120",F13<181,"121-180",F13<301,"181-300",F13>300,"301 & +") -> 31-60
A14: 5708P | B14: 24 VOLKSWAGEN JETTA GLI | C14: 31361.27 | D14: -27000 | E14: 3VW2T7BU9RM062240 | F14: 32 | G14: =_xlfn.IFS(F14<31,"0-30",F14<61,"31-60",F14<91,"61-90",F14<121,"91-120",F14<181,"121-180",F14<301,"181-300",F14>300,"301 & +") -> 31-60
A15: 240978A | B15: 19 VOLKSWAGEN E-GOLF | C15: 10550 | E15: WVWPR7AU6KW904224 | F15: 32 | G15: =_xlfn.IFS(F15<31,"0-30",F15<61,"31-60",F15<91,"61-90",F15<121,"91-120",F15<181,"121-180",F15<301,"181-300",F15>300,"301 & +") -> 31-60
A16: 250061A | B16: 19 VOLKSWAGEN JETTA | C16: 11591.68 | D16: -7896 | E16: 3VWC57BU7KM150613 | F16: 18 | G16: =_xlfn.IFS(F16<31,"0-30",F16<61,"31-60",F16<91,"61-90",F16<121,"91-120",F16<181,"121-180",F16<301,"181-300",F16>300,"301 & +") -> 0-30
A17: 5712P | B17: 19 VOLKSWAGEN TIGUAN | C17: 19021.43 | D17: -16200 | E17: 3VV2B7AX4KM193293 | F17: 17 | G17: =_xlfn.IFS(F17<31,"0-30",F17<61,"31-60",F17<91,"61-90",F17<121,"91-120",F17<181,"121-180",F17<301,"181-300",F17>300,"301 & +") -> 0-30
A18: 240577A | B18: 21 VOLKSWAGEN TIGUAN | C18: 18346.32 | D18: -20440 | E18: 3VV4B7AX1MM154947 | F18: 15 | G18: =_xlfn.IFS(F18<31,"0-30",F18<61,"31-60",F18<91,"61-90",F18<121,"91-120",F18<181,"121-180",F18<301,"181-300",F18>300,"301 & +") -> 0-30
A19: 5713P | B19: 22 VOLKSWAGEN GOLF R | C19: 36203.27 | D19: -31275 | E19: WVWFB7CD6NW168452 | F19: 14 | G19: =_xlfn.IFS(F19<31,"0-30",F19<61,"31-60",F19<91,"61-90",F19<121,"91-120",F19<181,"121-180",F19<301,"181-300",F19>300,"301 & +") -> 0-30
A20: 240798A | B20: 21 VOLKSWAGEN TIGUAN | C20: 17311.27 | D20: -23309.98 | E20: 3VV2B7AX6MM049151 | F20: 14 | G20: =_xlfn.IFS(F20<31,"0-30",F20<61,"31-60",F20<91,"61-90",F20<121,"91-120",F20<181,"121-180",F20<301,"181-300",F20>300,"301 & +") -> 0-30
A21: 241124A | B21: 21 VOLKSWAGEN TIGUAN | C21: 23456.72 | E21: 3VV4B7AX5MM085714 | F21: 9 | G21: =_xlfn.IFS(F21<31,"0-30",F21<61,"31-60",F21<91,"61-90",F21<121,"91-120",F21<181,"121-180",F21<301,"181-300",F21>300,"301 & +") -> 0-30
A22: 5715P | B22: 20 VOLKSWAGEN TIGUAN | C22: 20861.27 | E22: 3VV4B7AX9LM079431 | F22: 9 | G22: =_xlfn.IFS(F22<31,"0-30",F22<61,"31-60",F22<91,"61-90",F22<121,"91-120",F22<181,"121-180",F22<301,"181-300",F22>300,"301 & +") -> 0-30
A23: 240991A | B23: 21 VOLKSWAGEN TIGUAN | C23: 22550 | E23: 3VV4B7AX0MM118795 | F23: 8 | G23: =_xlfn.IFS(F23<31,"0-30",F23<61,"31-60",F23<91,"61-90",F23<121,"91-120",F23<181,"121-180",F23<301,"181-300",F23>300,"301 & +") -> 0-30
A24: 250074A | B24: 19 VOLKSWAGEN GOLF SPORTWAGEN | C24: 18050 | E24: 3VW117AU7KM514047 | F24: 8 | G24: =_xlfn.IFS(F24<31,"0-30",F24<61,"31-60",F24<91,"61-90",F24<121,"91-120",F24<181,"121-180",F24<301,"181-300",F24>300,"301 & +") -> 0-30
A25: 5716P | B25: 22 VOLKSWAGEN TIGUAN | C25: 26450 | E25: 3VV4B7AX9NM104069 | F25: 4 | G25: =_xlfn.IFS(F25<31,"0-30",F25<61,"31-60",F25<91,"61-90",F25<121,"91-120",F25<181,"121-180",F25<301,"181-300",F25>300,"301 & +") -> 0-30
A26: 241087A | B26: 22 VOLKSWAGEN TIGUAN | C26: 19550 | E26: 3VV0B7AX2NM030881 | F26: 4 | G26: =_xlfn.IFS(F26<31,"0-30",F26<61,"31-60",F26<91,"61-90",F26<121,"91-120",F26<181,"121-180",F26<301,"181-300",F26>300,"301 & +") -> 0-30
A27: 250014A | B27: 20 VOLKSWAGEN JETTA | C27: 16841.32 | E27: 3VWEB7BU8LM071082 | F27: 4 | G27: =_xlfn.IFS(F27<31,"0-30",F27<61,"31-60",F27<91,"61-90",F27<121,"91-120",F27<181,"121-180",F27<301,"181-300",F27>300,"301 & +") -> 0-30
A28: 240982A | B28: 21 VOLKSWAGEN ATLAS | C28: 20550 | E28: 1V2TR2CA6MC542578 | F28: 3 | G28: =_xlfn.IFS(F28<31,"0-30",F28<61,"31-60",F28<91,"61-90",F28<121,"91-120",F28<181,"121-180",F28<301,"181-300",F28>300,"301 & +") -> 0-30
A29: 250093A | B29: 16 AUDI Q5 | C29: 9801.86 | E29: WA1L2AFP5GA144417 | F29: 2 | G29: =_xlfn.IFS(F29<31,"0-30",F29<61,"31-60",F29<91,"61-90",F29<121,"91-120",F29<181,"121-180",F29<301,"181-300",F29>300,"301 & +") -> 0-30
A30: 5717P | B30: 19 VOLKSWAGEN JETTA | C30: 9450 | E30: 3VWW57BU2KM168255 | F30: 2 | G30: =_xlfn.IFS(F30<31,"0-30",F30<61,"31-60",F30<91,"61-90",F30<121,"91-120",F30<181,"121-180",F30<301,"181-300",F30>300,"301 & +") -> 0-30
A31: 250055A | B31: 21 VOLKSWAGEN GOLF GTI | C31: 23050 | E31: 3VW6T7AU1MM014503 | F31: 1 | G31: =_xlfn.IFS(F31<31,"0-30",F31<61,"31-60",F31<91,"61-90",F31<121,"91-120",F31<181,"121-180",F31<301,"181-300",F31>300,"301 & +") -> 0-30
A32: 241113A | B32: 23 VOLKSWAGEN JETTA | C32: 21350 | E32: 3VWNM7BU2PM021715 | F32: 1 | G32: =_xlfn.IFS(F32<31,"0-30",F32<61,"31-60",F32<91,"61-90",F32<121,"91-120",F32<181,"121-180",F32<301,"181-300",F32>300,"301 & +") -> 0-30
... A40: 250073A | B40: 19 VOLKSWAGEN JETTA | C40: 10050 | E40: 3VWC57BU4KM150665 | F40: 0 | G40: =_xlfn.IFS(F40<31,"0-30",F40<61,"31-60",F40<91,"61-90",F40<121,"91-120",F40<181,"121-180",F40<301,"181-300",F40>300,"301 & +") -> 0-30

Sheet Unite budgete
B5: Neuf
B6: Janvier | C6: Février | D6: Mars | E6: Avril | F6: Mai | G6: juin | H6: Juillet | I6: Août | J6: Septembre | K6: Octobre | L6: Novembre | M6: Décembre
B7: 50 | C7: 60.71 | D7: 76.85 | E7: 84.6125 | F7: 71.3 | G7: 66.065 | H7: 71.57 | I7: 66.125 | J7: 87.125 | K7: 76.67 | L7: 50 | M7: 48.215
B8: 2160413.1 | C8: 2623173.6 | D8: 3320554.9 | E8: 3655959.1 | F8: 3080749.1 | G8: 2854553.8 | H8: 3092415.3 | I8: 2857146.3 | J8: 3764519.8 | K8: 3312777.4 | L8: 2160413.1 | M8: 2083286.4
B13: Janvier | C13: Février | D13: Mars | E13: Avril | F13: Mai | G13: juin | H13: Juillet | I13: Août | J13: Septembre | K13: Octobre | L13: Novembre | M13: Décembre
B14: 71.2255 | C14: 90.4465 | D14: 97.219 | E14: 98.38 | F14: 92.1235 | G14: 88.06 | H14: 91.672 | I14: 90.9625 | J14: 90.253 | K14: 88.7695 | L14: 73.096 | M14: 70
B15: 1654737 | C15: 2101286.3 | D15: 2258627.5 | E15: 2285600.3 | F15: 2140247 | G15: 2045842.3 | H15: 2129757.6 | I15: 2113274.2 | J15: 2096790.9 | K15: 2062325.7 | L15: 1698193.1 | M15: 1626265.7
