Workbook
Name Ticker: #REF!

Sheet Parametres
A1: Compagnie | B1: Volks
G2: 1-Mémo | M2: Mois | N2: YTD
A3: Mois Courant | B3: Juillet | C3: =+VLOOKUP(B3,$K$3:$L$14,2,0) -> 7 | G3: 10-Compte compteur | K3: Janvier | L3: 1 | M3: =+IF($K3=$B$3,"X","") | N3: =+IF(K3=B3,"X",IF(L3<=$C$3,"X","")) -> X
A4: Année | B4: 2026 | K4: Février | L4: 2 | M4: =+IF($K4=$B$3,"X","") | N4: =+IF(K4=B4,"X",IF(L4<=$C$3,"X","")) -> X
K5: Mars | L5: 3 | M5: =+IF($K5=$B$3,"X","") | N5: =+IF(K5=B5,"X",IF(L5<=$C$3,"X","")) -> X
K6: Avril | L6: 4 | M6: =+IF($K6=$B$3,"X","") | N6: =+IF(K6=B6,"X",IF(L6<=$C$3,"X","")) -> X
K7: Mai | L7: 5 | M7: =+IF($K7=$B$3,"X","") | N7: =+IF(K7=B7,"X",IF(L7<=$C$3,"X","")) -> X
K8: Juin | L8: 6 | M8: =+IF($K8=$B$3,"X","") | N8: =+IF(K8=B8,"X",IF(L8<=$C$3,"X","")) -> X
A9: Sélectionner le mois en B3 | K9: Juillet | L9: 7 | M9: =+IF($K9=$B$3,"X","") -> X | N9: =+IF(K9=B9,"X",IF(L9<=$C$3,"X","")) -> X
A10: Coller les balances de vérification respectives en cellule A1 dans les onglets BV_Data_An_Cour et BV_Data_An_Prec | K10: Août | L10: 8 | M10: =+IF($K10=$B$3,"X","") | N10: =+IF(K10=B10,"X",IF(L10<=$C$3,"X",""))
A11: Vérifier s'il y a des #N/A dans les colonnes T à X des onlgets de BV | K11: Septembre | L11: 9 | M11: =+IF($K11=$B$3,"X","") | N11: =+IF(K11=B11,"X",IF(L11<=$C$3,"X",""))
A12: Vérifier les chiffres avec l'état financier et les réalisés an passé pour les résultat net mois et aad | K12: Octobre | L12: 10 | M12: =+IF($K12=$B$3,"X","") | N12: =+IF(K12=B12,"X",IF(L12<=$C$3,"X",""))
K13: Novembre | L13: 11 | M13: =+IF($K13=$B$3,"X","") | N13: =+IF(K13=B13,"X",IF(L13<=$C$3,"X",""))
K14: Décembre | L14: 12 | M14: =+IF($K14=$B$3,"X","") | N14: =+IF(K14=B14,"X",IF(L14<=$C$3,"X",""))

Sheet Bilan
A1: BILAN
A2: =+Parametres!B1 -> Volks
A3: =CONCATENATE("",,Parametres!B3," ",Parametres!B4) -> Juillet 2026
A5: Encaisse | B5: =SUMIFS(BV_Data_An_Cour!$P:$P,BV_Data_An_Cour!$U:$U,$A$1,BV_Data_An_Cour!$V:$V,$A5) -> 169187.98 | D5: Marge de crédit | E5: =-SUMIFS(BV_Data_An_Cour!$P:$P,BV_Data_An_Cour!$U:$U,$A$1,BV_Data_An_Cour!$V:$V,$D5) -> 0
A6: Total Trésorerie et équivalent de Trésorerie | B6: =SUM(B5) -> 169187.98
D7: Portion Court Terme de la Dette Long Terme | E7: =-SUMIFS(BV_Data_An_Cour!$P:$P,BV_Data_An_Cour!$U:$U,$A$1,BV_Data_An_Cour!$V:$V,$D7) -> 0
A8: Recevables Contrats en Transit | B8: =SUMIFS(BV_Data_An_Cour!$P:$P,BV_Data_An_Cour!$U:$U,$A$1,BV_Data_An_Cour!$V:$V,$A8) -> 941192.49
A9: Recevables Véhicules | B9: =SUMIFS(BV_Data_An_Cour!$P:$P,BV_Data_An_Cour!$U:$U,$A$1,BV_Data_An_Cour!$V:$V,$A9) -> 77432.25 | D9: Avances à payer | E9: =-SUMIFS(BV_Data_An_Cour!$P:$P,BV_Data_An_Cour!$U:$U,$A$1,BV_Data_An_Cour!$V:$V,$D9) -> 0
A10: Recevables Manufacturier | B10: =SUMIFS(BV_Data_An_Cour!$P:$P,BV_Data_An_Cour!$U:$U,$A$1,BV_Data_An_Cour!$V:$V,$A10) -> 117828 | D10: Comptes à Payer Fournisseurs | E10: =-SUMIFS(BV_Data_An_Cour!$P:$P,BV_Data_An_Cour!$U:$U,$A$1,BV_Data_An_Cour!$V:$V,$D10) -> 493596.86
A11: Recevables Pièces et Service | B11: =SUMIFS(BV_Data_An_Cour!$P:$P,BV_Data_An_Cour!$U:$U,$A$1,BV_Data_An_Cour!$V:$V,$A11) -> 413501.18 | D11: Taxes de Vente à Payer | E11: =-SUMIFS(BV_Data_An_Cour!$P:$P,BV_Data_An_Cour!$U:$U,$A$1,BV_Data_An_Cour!$V:$V,$D11) -> 196570.42
A12: Recevables Garantie Manufacturier | B12: =SUMIFS(BV_Data_An_Cour!$P:$P,BV_Data_An_Cour!$U:$U,$A$1,BV_Data_An_Cour!$V:$V,$A12) -> 110815.24 | D12: Impôts à payer | E12: =-SUMIFS(BV_Data_An_Cour!$P:$P,BV_Data_An_Cour!$U:$U,$A$1,BV_Data_An_Cour!$V:$V,$D12) -> 0
A13: Recevables Carrosserie | B13: =SUMIFS(BV_Data_An_Cour!$P:$P,BV_Data_An_Cour!$U:$U,$A$1,BV_Data_An_Cour!$V:$V,$A13) -> 15558.32 | D13: Dépôts de Client | E13: =-SUMIFS(BV_Data_An_Cour!$P:$P,BV_Data_An_Cour!$U:$U,$A$1,BV_Data_An_Cour!$V:$V,$D13) -> 7700
A14: Recevables Intercos | B14: =SUMIFS(BV_Data_An_Cour!$P:$P,BV_Data_An_Cour!$U:$U,$A$1,BV_Data_An_Cour!$V:$V,$A14) -> 0 | D14: Payables Intercos | E14: =-SUMIFS(BV_Data_An_Cour!$P:$P,BV_Data_An_Cour!$U:$U,$A$1,BV_Data_An_Cour!$V:$V,$D14) -> 0
A15: Recevables Autres | B15: =SUMIFS(BV_Data_An_Cour!$P:$P,BV_Data_An_Cour!$U:$U,$A$1,BV_Data_An_Cour!$V:$V,$A15) -> -8055.2 | D15: Autres Comptes à Payer | E15: =-SUMIFS(BV_Data_An_Cour!$P:$P,BV_Data_An_Cour!$U:$U,$A$1,BV_Data_An_Cour!$V:$V,$D15) -> 195785.24
A16: Total Comptes à Recevoir | B16: =+SUM(B8:B15) -> 1668272.3 | D16: Total Comptes à Payer | E16: =+SUM(E10:E15) -> 893652.52
A18: Inventaire Véhicules Neufs | B18: =SUMIFS(BV_Data_An_Cour!$P:$P,BV_Data_An_Cour!$U:$U,$A$1,BV_Data_An_Cour!$V:$V,$A18) -> 4932307.3 | D18: Effet à Payer Véhicules Neufs | E18: =-SUMIFS(BV_Data_An_Cour!$P:$P,BV_Data_An_Cour!$U:$U,$A$1,BV_Data_An_Cour!$V:$V,$D18) -> 5425474.2
A19: Inventaire Véhicules Usagés | B19: =SUMIFS(BV_Data_An_Cour!$P:$P,BV_Data_An_Cour!$U:$U,$A$1,BV_Data_An_Cour!$V:$V,$A19) -> 1190697 | D19: Effet à Payer Véhicules Usagés | E19: =-SUMIFS(BV_Data_An_Cour!$P:$P,BV_Data_An_Cour!$U:$U,$A$1,BV_Data_An_Cour!$V:$V,$D19) -> 757839.5
A20: Inventaire Pièces, Pneus, Huile | B20: =SUMIFS(BV_Data_An_Cour!$P:$P,BV_Data_An_Cour!$U:$U,$A$1,BV_Data_An_Cour!$V:$V,$A20) -> 501529.26 | D20: Total Effets à Payer | E20: =+SUM(E18:E19) -> 6183313.7
A21: Total Inventaires | B21: =SUM(B18:B20) -> 6624533.6
D22: Salaires à Payer | E22: =-SUMIFS(BV_Data_An_Cour!$P:$P,BV_Data_An_Cour!$U:$U,$A$1,BV_Data_An_Cour!$V:$V,$D22) -> 332167.77
A23: Avances à recevoir | B23: =SUMIFS(BV_Data_An_Cour!$P:$P,BV_Data_An_Cour!$U:$U,$A$1,BV_Data_An_Cour!$V:$V,$A23) -> 0 | D23: DAS à Payer | E23: =-SUMIFS(BV_Data_An_Cour!$P:$P,BV_Data_An_Cour!$U:$U,$A$1,BV_Data_An_Cour!$V:$V,$D23) -> -21559.97
A24: Travaux en Cours | B24: =SUMIFS(BV_Data_An_Cour!$P:$P,BV_Data_An_Cour!$U:$U,$A$1,BV_Data_An_Cour!$V:$V,$A24) -> 14427.48 | D24: Autres Courus | E24: =-SUMIFS(BV_Data_An_Cour!$P:$P,BV_Data_An_Cour!$U:$U,$A$1,BV_Data_An_Cour!$V:$V,$D24) -> 147184.96
A25: Sous-Traitance | B25: =SUMIFS(BV_Data_An_Cour!$P:$P,BV_Data_An_Cour!$U:$U,$A$1,BV_Data_An_Cour!$V:$V,$A25) -> 7458.29 | D25: [...] | E25: =-SUMIFS(BV_Data_An_Cour!$P:$P,BV_Data_An_Cour!$U:$U,$A$1,BV_Data_An_Cour!$V:$V,$D25) -> 0
A26: Frais Payés d'Avance | B26: =SUMIFS(BV_Data_An_Cour!$P:$P,BV_Data_An_Cour!$U:$U,$A$1,BV_Data_An_Cour!$V:$V,$A26) -> 47980.77 | D26: [...] | E26: =-SUMIFS(BV_Data_An_Cour!$P:$P,BV_Data_An_Cour!$U:$U,$A$1,BV_Data_An_Cour!$V:$V,$D26) -> 0
A27: [...] | B27: =SUMIFS(BV_Data_An_Cour!$P:$P,BV_Data_An_Cour!$U:$U,$A$1,BV_Data_An_Cour!$V:$V,$A27) -> 0 | D27: [...] | E27: =-SUMIFS(BV_Data_An_Cour!$P:$P,BV_Data_An_Cour!$U:$U,$A$1,BV_Data_An_Cour!$V:$V,$D27) -> 0
A28: [...] | B28: =SUMIFS(BV_Data_An_Cour!$P:$P,BV_Data_An_Cour!$U:$U,$A$1,BV_Data_An_Cour!$V:$V,$A28) -> 0 | D28: Total Frais Courus | E28: =SUM(E22:E24) -> 457792.76
A29: [...] | B29: =SUMIFS(BV_Data_An_Cour!$P:$P,BV_Data_An_Cour!$U:$U,$A$1,BV_Data_An_Cour!$V:$V,$A29) -> 0
A30: Total Autres | B30: =SUM(B23:B29) -> 69866.54 | D30: Total Passif Court Terme | E30: =+E5+E7+E16+E20+E28 -> 7534759
A32: Total Actif Court Terme | B32: =+B6+B16+B21+B30 -> 8531860.4
D33: Impôts Futurs à payer | E33: =-SUMIFS(BV_Data_An_Cour!$P:$P,BV_Data_An_Cour!$U:$U,$A$1,BV_Data_An_Cour!$V:$V,$D33) -> 0
A35: Terrain | B35: =SUMIFS(BV_Data_An_Cour!$P:$P,BV_Data_An_Cour!$U:$U,$A$1,BV_Data_An_Cour!$V:$V,$A35) -> 0 | D35: Avances Long Terme à Payer | E35: =-SUMIFS(BV_Data_An_Cour!$P:$P,BV_Data_An_Cour!$U:$U,$A$1,BV_Data_An_Cour!$V:$V,$D35) -> 0
A36: Bâtisse | B36: =SUMIFS(BV_Data_An_Cour!$P:$P,BV_Data_An_Cour!$U:$U,$A$1,BV_Data_An_Cour!$V:$V,$A36) -> 0 | D36: Hypothèque à Payer | E36: =-SUMIFS(BV_Data_An_Cour!$P:$P,BV_Data_An_Cour!$U:$U,$A$1,BV_Data_An_Cour!$V:$V,$D36) -> 0
A37: Améliorations Locatives | B37: =SUMIFS(BV_Data_An_Cour!$P:$P,BV_Data_An_Cour!$U:$U,$A$1,BV_Data_An_Cour!$V:$V,$A37) -> 28358.37 | D37: Dette à Long Terme | E37: =-SUMIFS(BV_Data_An_Cour!$P:$P,BV_Data_An_Cour!$U:$U,$A$1,BV_Data_An_Cour!$V:$V,$D37) -> 5672000
A38: Améliorations Locatives Permanentes | B38: =SUMIFS(BV_Data_An_Cour!$P:$P,BV_Data_An_Cour!$U:$U,$A$1,BV_Data_An_Cour!$V:$V,$A38) -> 0 | D38: Autres Dettes à Long Terme | E38: =-SUMIFS(BV_Data_An_Cour!$P:$P,BV_Data_An_Cour!$U:$U,$A$1,BV_Data_An_Cour!$V:$V,$D38) -> 0
A39: Équipements Service | B39: =SUMIFS(BV_Data_An_Cour!$P:$P,BV_Data_An_Cour!$U:$U,$A$1,BV_Data_An_Cour!$V:$V,$A39) -> 268497.39 | D39: [...] | E39: =-SUMIFS(BV_Data_An_Cour!$P:$P,BV_Data_An_Cour!$U:$U,$A$1,BV_Data_An_Cour!$V:$V,$D39) -> 0
A40: Mobilier | B40: =SUMIFS(BV_Data_An_Cour!$P:$P,BV_Data_An_Cour!$U:$U,$A$1,BV_Data_An_Cour!$V:$V,$A40) -> 28979.22 | D40: [...] | E40: =-SUMIFS(BV_Data_An_Cour!$P:$P,BV_Data_An_Cour!$U:$U,$A$1,BV_Data_An_Cour!$V:$V,$D40) -> 0
A41: Équipements Informatique | B41: =SUMIFS(BV_Data_An_Cour!$P:$P,BV_Data_An_Cour!$U:$U,$A$1,BV_Data_An_Cour!$V:$V,$A41) -> 28511.21 | D41: [...] | E41: =-SUMIFS(BV_Data_An_Cour!$P:$P,BV_Data_An_Cour!$U:$U,$A$1,BV_Data_An_Cour!$V:$V,$D41) -> 0
A42: Équipements Téléphonique | B42: =SUMIFS(BV_Data_An_Cour!$P:$P,BV_Data_An_Cour!$U:$U,$A$1,BV_Data_An_Cour!$V:$V,$A42) -> 0 | D42: Total Passif long terme | E42: =+SUM(E33:E38) -> 5672000
A43: Enseigne | B43: =SUMIFS(BV_Data_An_Cour!$P:$P,BV_Data_An_Cour!$U:$U,$A$1,BV_Data_An_Cour!$V:$V,$A43) -> 137120.13
A44: Total Immobilisations Nettes | B44: =SUM(B35:B43) -> 491466.32
...

Sheet Budget original
B1: ="Budget 2024 Mensuel Révisé"&" "&Parametres!$B$1 -> Budget 2024 Mensuel Révisé Volks
B2: Mois | F2: =+IF(Parametres!$B$3=F$6,"X","") | G2: =+IF(Parametres!$B$3=F$6,"O","") | H2: =+IF(Parametres!$B$3=F$6,"U","") | I2: =+IF(Parametres!$B$3=I$6,"X","") | J2: =+IF(Parametres!$B$3=I$6,"O","") | K2: =+IF(Parametres!$B$3=I$6,"U","") | L2: =+IF(Parametres!$B$3=L$6,"X","") | M2: =+IF(Parametres!$B$3=L$6,"O","") | N2: =+IF(Parametres!$B$3=L$6,"U","") | O2: =+IF(Parametres!$B$3=O$6,"X","") | P2: =+IF(Parametres!$B$3=O$6,"O","") | Q2: =+IF(Parametres!$B$3=O$6,"U","") | R2: =+IF(Parametres!$B$3=R$6,"X","") | S2: =+IF(Parametres!$B$3=R$6,"O","") | T2: =+IF(Parametres!$B$3=R$6,"U","") | U2: =+IF(Parametres!$B$3=U$6,"X","") | V2: =+IF(Parametres!$B$3=U$6,"O","") | W2: =+IF(Parametres!$B$3=U$6,"U","") | X2: =+IF(Parametres!$B$3=X$6,"X","") -> X | Y2: =+IF(Parametres!$B$3=X$6,"O","") -> O | Z2: =+IF(Parametres!$B$3=X$6,"U","") -> U | AA2: =+IF(Parametres!$B$3=AA$6,"X","") | AB2: =+IF(Parametres!$B$3=AA$6,"O","") | AC2: =+IF(Parametres!$B$3=AA$6,"U","") | AD2: =+IF(Parametres!$B$3=AD$6,"X","") | AE2: =+IF(Parametres!$B$3=AD$6,"O","") | AF2: =+IF(Parametres!$B$3=AD$6,"U","") | AG2: =+IF(Parametres!$B$3=AG$6,"X","") | AH2: =+IF(Parametres!$B$3=AG$6,"O","") | AI2: =+IF(Parametres!$B$3=AG$6,"U","") | AJ2: =+IF(Parametres!$B$3=AJ$6,"X","") | AK2: =+IF(Parametres!$B$3=AJ$6,"O","") | AL2: =+IF(Parametres!$B$3=AJ$6,"U","") | AM2: =+IF(Parametres!$B$3=AM$6,"X","") | AN2: =+IF(Parametres!$B$3=AM$6,"O","") | AO2: =+IF(Parametres!$B$3=AM$6,"U","")
B3: YTD | F3: =+IF(VLOOKUP(F$6,Parametres!$K$3:$N$14,4,0)="X","X","") -> X | G3: =+IF(VLOOKUP(F$6,Parametres!$K$3:$N$14,4,0)="X","O","") -> O | H3: =+IF(VLOOKUP(F$6,Parametres!$K$3:$N$14,4,0)="X","U","") -> U | I3: =+IF(VLOOKUP(I$6,Parametres!$K$3:$N$14,4,0)="X","X","") -> X | J3: =+IF(VLOOKUP(I$6,Parametres!$K$3:$N$14,4,0)="X","O","") -> O | K3: =+IF(VLOOKUP(I$6,Parametres!$K$3:$N$14,4,0)="X","U","") -> U | L3: =+IF(VLOOKUP(L$6,Parametres!$K$3:$N$14,4,0)="X","X","") -> X | M3: =+IF(VLOOKUP(L$6,Parametres!$K$3:$N$14,4,0)="X","O","") -> O | N3: =+IF(VLOOKUP(L$6,Parametres!$K$3:$N$14,4,0)="X","U","") -> U | O3: =+IF(VLOOKUP(O$6,Parametres!$K$3:$N$14,4,0)="X","X","") -> X | P3: =+IF(VLOOKUP(O$6,Parametres!$K$3:$N$14,4,0)="X","O","") -> O | Q3: =+IF(VLOOKUP(O$6,Parametres!$K$3:$N$14,4,0)="X","U","") -> U | R3: =+IF(VLOOKUP(R$6,Parametres!$K$3:$N$14,4,0)="X","X","") -> X | S3: =+IF(VLOOKUP(R$6,Parametres!$K$3:$N$14,4,0)="X","O","") -> O | T3: =+IF(VLOOKUP(R$6,Parametres!$K$3:$N$14,4,0)="X","U","") -> U | U3: =+IF(VLOOKUP(U$6,Parametres!$K$3:$N$14,4,0)="X","X","") -> X | V3: =+IF(VLOOKUP(U$6,Parametres!$K$3:$N$14,4,0)="X","O","") -> O | W3: =+IF(VLOOKUP(U$6,Parametres!$K$3:$N$14,4,0)="X","U","") -> U | X3: =+IF(VLOOKUP(X$6,Parametres!$K$3:$N$14,4,0)="X","X","") -> X | Y3: =+IF(VLOOKUP(X$6,Parametres!$K$3:$N$14,4,0)="X","O","") -> O | Z3: =+IF(VLOOKUP(X$6,Parametres!$K$3:$N$14,4,0)="X","U","") -> U | AA3: =+IF(VLOOKUP(AA$6,Parametres!$K$3:$N$14,4,0)="X","X","") | AB3: =+IF(VLOOKUP(AA$6,Parametres!$K$3:$N$14,4,0)="X","O","") | AC3: =+IF(VLOOKUP(AA$6,Parametres!$K$3:$N$14,4,0)="X","U","") | AD3: =+IF(VLOOKUP(AD$6,Parametres!$K$3:$N$14,4,0)="X","X","") | AE3: =+IF(VLOOKUP(AD$6,Parametres!$K$3:$N$14,4,0)="X","O","") | AF3: =+IF(VLOOKUP(AD$6,Parametres!$K$3:$N$14,4,0)="X","U","") | AG3: =+IF(VLOOKUP(AG$6,Parametres!$K$3:$N$14,4,0)="X","X","") | AH3: =+IF(VLOOKUP(AG$6,Parametres!$K$3:$N$14,4,0)="X","O","") | AI3: =+IF(VLOOKUP(AG$6,Parametres!$K$3:$N$14,4,0)="X","U","") | AJ3: =+IF(VLOOKUP(AJ$6,Parametres!$K$3:$N$14,4,0)="X","X","") | AK3: =+IF(VLOOKUP(AJ$6,Parametres!$K$3:$N$14,4,0)="X","O","") | AL3: =+IF(VLOOKUP(AJ$6,Parametres!$K$3:$N$14,4,0)="X","U","") | AM3: =+IF(VLOOKUP(AM$6,Parametres!$K$3:$N$14,4,0)="X","X","") | AN3: =+IF(VLOOKUP(AM$6,Parametres!$K$3:$N$14,4,0)="X","O","") | AO3: =+IF(VLOOKUP(AM$6,Parametres!$K$3:$N$14,4,0)="X","U","")
B4: Budget 2025 | C4: Véhicules neufs
B6: Mois | C6: TOTAL | F6: Janvier | I6: Février | L6: Mars | O6: Avril | R6: Mai | U6: Juin | X6: Juillet | AA6: Août | AD6: Septembre | AG6: Octobre | AJ6: Novembre | AM6: Décembre
C7: UNITE | D7: $P/UNITE | E7: $PROFITS | F7: UNITE | G7: $P/UNITE | H7: $PROFITS | I7: UNITE | J7: $P/UNITE | K7: $PROFITS | L7: UNITE | M7: $P/UNITE | N7: $PROFITS | O7: UNITE | P7: $P/UNITE | Q7: $PROFITS | R7: UNITE | S7: $P/UNITE | T7: $PROFITS | U7: UNITE | V7: $P/UNITE | W7: $PROFITS | X7: UNITE | Y7: $P/UNITE | Z7: $PROFITS | AA7: UNITE | AB7: $P/UNITE | AC7: $PROFITS | AD7: UNITE | AE7: $P/UNITE | AF7: $PROFITS | AG7: UNITE | AH7: $P/UNITE | AI7: $PROFITS | AJ7: UNITE | AK7: $P/UNITE | AL7: $PROFITS | AM7: UNITE | AN7: $P/UNITE | AO7: $PROFITS
A8: =+$C$4&B8 -> Véhicules neufsVentes nettes | B8: Ventes nettes | E8: =+SUM(H8,K8,N8,Q8,T8,W8,Z8,AC8,AF8,AI8,AL8,AO8) -> 35986167 | H8: ='[1]Vehicules neuf 2026'!E60 -> 2377394.8 | K8: ='[1]Vehicules neuf 2026'!F60 -> 2560324.4 | N8: ='[1]Vehicules neuf 2026'!G60 -> 3684432.8 | Q8: ='[1]Vehicules neuf 2026'!H60 -> 3774495.5 | T8: ='[1]Vehicules neuf 2026'!I60 -> 3914068.9 | W8: ='[1]Vehicules neuf 2026'!J60 -> 3544859.4 | Z8: ='[1]Vehicules neuf 2026'!K60 -> 3172845.9 | AC8: ='[1]Vehicules neuf 2026'!L60 -> 2888981.7 | AF8: ='[1]Vehicules neuf 2026'!M60 -> 2798918.9 | AI8: ='[1]Vehicules neuf 2026'!N60 -> 2749408.3 | AL8: ='[1]Vehicules neuf 2026'!O60 -> 2426905.4 | AO8: ='[1]Vehicules neuf 2026'!P60 -> 2093530.6
A9: =+$C$4&B9 -> Véhicules neufsAutos détail | B9: Autos détail | C9: =+SUM(F9,I9,L9,O9,R9,U9,X9,AA9,AD9,AG9,AJ9,AM9) -> 197 | D9: =IF(C9=0,0,E9/C9) -> 1839.3979 | E9: =+SUM(H9,K9,N9,Q9,T9,W9,Z9,AC9,AF9,AI9,AL9,AO9) -> 362361.39 | F9: ='[1]Vehicules neuf 2026'!E35 -> 13 | G9: =IF(F9=0,0,H9/F9) -> 1839.3979 | H9: ='[1]Vehicules neuf 2026'!E53 -> 23912.173 | I9: ='[1]Vehicules neuf 2026'!F35 -> 14 | J9: =IF(I9=0,0,K9/I9) -> 1839.3979 | K9: ='[1]Vehicules neuf 2026'!F53 -> 25751.571 | L9: ='[1]Vehicules neuf 2026'!G35 -> 20 | M9: =IF(L9=0,0,N9/L9) -> 1839.3979 | N9: ='[1]Vehicules neuf 2026'!G53 -> 36787.958 | O9: ='[1]Vehicules neuf 2026'!H35 -> 21 | P9: =IF(O9=0,0,Q9/O9) -> 1839.3979 | Q9: ='[1]Vehicules neuf 2026'!H53 -> 38627.356 | R9: ='[1]Vehicules neuf 2026'!I35 -> 22 | S9: =IF(R9=0,0,T9/R9) -> 1839.3979 | T9: ='[1]Vehicules neuf 2026'!I53 -> 40466.754 | U9: ='[1]Vehicules neuf 2026'!J35 -> 19 | V9: =IF(U9=0,0,W9/U9) -> 1839.3979 | W9: ='[1]Vehicules neuf 2026'!J53 -> 34948.56 | X9: ='[1]Vehicules neuf 2026'!K35 -> 17 | Y9: =IF(X9=0,0,Z9/X9) -> 1839.3979 | Z9: ='[1]Vehicules neuf 2026'!K53 -> 31269.764 | AA9: ='[1]Vehicules neuf 2026'!L35 -> 16 | AB9: =IF(AA9=0,0,AC9/AA9) -> 1839.3979 | AC9: ='[1]Vehicules neuf 2026'!L53 -> 29430.366 | AD9: ='[1]Vehicules neuf 2026'!M35 -> 15 | AE9: =IF(AD9=0,0,AF9/AD9) -> 1839.3979 | AF9: ='[1]Vehicules neuf 2026'!M53 -> 27590.968 | AG9: ='[1]Vehicules neuf 2026'!N35 -> 15 | AH9: =IF(AG9=0,0,AI9/AG9) -> 1839.3979 | AI9: ='[1]Vehicules neuf 2026'!N53 -> 27590.968 | AJ9: ='[1]Vehicules neuf 2026'!O35 -> 13 | AK9: =IF(AJ9=0,0,AL9/AJ9) -> 1839.3979 | AL9: ='[1]Vehicules neuf 2026'!O53 -> 23912.173 | AM9: ='[1]Vehicules neuf 2026'!P35 -> 12 | AN9: =IF(AM9=0,0,AO9/AM9) -> 1839.3979 | AO9: ='[1]Vehicules neuf 2026'!P53 -> 22072.775
A10: =+$C$4&B10 -> Véhicules neufsCamions détail | B10: Camions détail | C10: =+SUM(F10,I10,L10,O10,R10,U10,X10,AA10,AD10,AG10,AJ10,AM10) -> 486 | D10: =IF(C10=0,0,E10/C10) -> 2490.3911 | E10: =+SUM(H10,K10,N10,Q10,T10,W10,Z10,AC10,AF10,AI10,AL10,AO10) -> 1210330.1 | F10: ='[1]Vehicules neuf 2026'!E36 -> 32 | G10: =IF(F10=0,0,H10/F10) -> 2490.3911 | H10: ='[1]Vehicules neuf 2026'!E54 -> 79692.514 | I10: ='[1]Vehicules neuf 2026'!F36 -> 34 | J10: =IF(I10=0,0,K10/I10) -> 2490.3911 | K10: ='[1]Vehicules neuf 2026'!F54 -> 84673.296 | L10: ='[1]Vehicules neuf 2026'!G36 -> 50 | M10: =IF(L10=0,0,N10/L10) -> 2490.3911 | N10: ='[1]Vehicules neuf 2026'!G54 -> 124519.55 | O10: ='[1]Vehicules neuf 2026'!H36 -> 51 | P10: =IF(O10=0,0,Q10/O10) -> 2490.3911 | Q10: ='[1]Vehicules neuf 2026'!H54 -> 127009.94 | R10: ='[1]Vehicules neuf 2026'!I36 -> 53 | S10: =IF(R10=0,0,T10/R10) -> 2490.3911 | T10: ='[1]Vehicules neuf 2026'!I54 -> 131990.73 | U10: ='[1]Vehicules neuf 2026'!J36 -> 48 | V10: =IF(U10=0,0,W10/U10) -> 2490.3911 | W10: ='[1]Vehicules neuf 2026'!J54 -> 119538.77 | X10: ='[1]Vehicules neuf 2026'!K36 -> 43 | Y10: =IF(X10=0,0,Z10/X10) -> 2490.3911 | Z10: ='[1]Vehicules neuf 2026'!K54 -> 107086.82 | AA10: ='[1]Vehicules neuf 2026'!L36 -> 39 | AB10: =IF(AA10=0,0,AC10/AA10) -> 2490.3911 | AC10: ='[1]Vehicules neuf 2026'!L54 -> 97125.251 | AD10: ='[1]Vehicules neuf 2026'!M36 -> 38 | AE10: =IF(AD10=0,0,AF10/AD10) -> 2490.3911 | AF10: ='[1]Vehicules neuf 2026'!M54 -> 94634.86 | AG10: ='[1]Vehicules neuf 2026'!N36 -> 37 | AH10: =IF(AG10=0,0,AI10/AG10) -> 2490.3911 | AI10: ='[1]Vehicules neuf 2026'!N54 -> 92144.469 | AJ10: ='[1]Vehicules neuf 2026'!O36 -> 33 | AK10: =IF(AJ10=0,0,AL10/AJ10) -> 2490.3911 | AL10: ='[1]Vehicules neuf 2026'!O54 -> 82182.905 | AM10: ='[1]Vehicules neuf 2026'!P36 -> 28 | AN10: =IF(AM10=0,0,AO10/AM10) -> 2490.3911 | AO10: ='[1]Vehicules neuf 2026'!P54 -> 69730.95
A11: =+$C$4&B11 -> Véhicules neufsSprinter | B11: Sprinter | C11: =+SUM(F11,I11,L11,O11,R11,U11,X11,AA11,AD11,AG11,AJ11,AM11) -> 0 | D11: =IF(C11=0,0,E11/C11) -> 0 | E11: =+SUM(H11,K11,N11,Q11,T11,W11,Z11,AC11,AF11,AI11,AL11,AO11) -> 0 | G11: =IF(F11=0,0,H11/F11) -> 0 | J11: =IF(I11=0,0,K11/I11) -> 0 | M11: =IF(L11=0,0,N11/L11) -> 0 | P11: =IF(O11=0,0,Q11/O11) -> 0 | S11: =IF(R11=0,0,T11/R11) -> 0 | V11: =IF(U11=0,0,W11/U11) -> 0 | Y11: =IF(X11=0,0,Z11/X11) -> 0 | AB11: =IF(AA11=0,0,AC11/AA11) -> 0 | AE11: =IF(AD11=0,0,AF11/AD11) -> 0 | AH11: =IF(AG11=0,0,AI11/AG11) -> 0 | AK11: =IF(AJ11=0,0,AL11/AJ11) -> 0 | AN11: =IF(AM11=0,0,AO11/AM11) -> 0
A12: =+$C$4&B12 -> Véhicules neufsMoto détail | B12: Moto détail | C12: =+SUM(F12,I12,L12,O12,R12,U12,X12,AA12,AD12,AG12,AJ12,AM12) -> 0 | D12: =IF(C12=0,0,E12/C12) -> 0 | E12: =+SUM(H12,K12,N12,Q12,T12,W12,Z12,AC12,AF12,AI12,AL12,AO12) -> 0 | G12: =IF(F12=0,0,H12/F12) -> 0 | J12: =IF(I12=0,0,K12/I12) -> 0 | M12: =IF(L12=0,0,N12/L12) -> 0 | P12: =IF(O12=0,0,Q12/O12) -> 0 | S12: =IF(R12=0,0,T12/R12) -> 0 | V12: =IF(U12=0,0,W12/U12) -> 0 | Y12: =IF(X12=0,0,Z12/X12) -> 0 | AB12: =IF(AA12=0,0,AC12/AA12) -> 0 | AE12: =IF(AD12=0,0,AF12/AD12) -> 0 | AH12: =IF(AG12=0,0,AI12/AG12) -> 0 | AK12: =IF(AJ12=0,0,AL12/AJ12) -> 0 | AN12: =IF(AM12=0,0,AO12/AM12) -> 0
A13: =+$C$4&B13 -> Véhicules neufs[...] | B13: [...] | C13: =+SUM(F13,I13,L13,O13,R13,U13,X13,AA13,AD13,AG13,AJ13,AM13) -> 0 | D13: =IF(C13=0,0,E13/C13) -> 0 | E13: =+SUM(H13,K13,N13,Q13,T13,W13,Z13,AC13,AF13,AI13,AL13,AO13) -> 0 | G13: =IF(F13=0,0,H13/F13) -> 0 | J13: =IF(I13=0,0,K13/I13) -> 0 | M13: =IF(L13=0,0,N13/L13) -> 0 | P13: =IF(O13=0,0,Q13/O13) -> 0 | S13: =IF(R13=0,0,T13/R13) -> 0 | V13: =IF(U13=0,0,W13/U13) -> 0 | Y13: =IF(X13=0,0,Z13/X13) -> 0 | AB13: =IF(AA13=0,0,AC13/AA13) -> 0 | AE13: =IF(AD13=0,0,AF13/AD13) -> 0 | AH13: =IF(AG13=0,0,AI13/AG13) -> 0 | AK13: =IF(AJ13=0,0,AL13/AJ13) -> 0 | AN13: =IF(AM13=0,0,AO13/AM13) -> 0
A14: =+$C$4&B14 -> Véhicules neufs[...] | B14: [...] | C14: =+SUM(F14,I14,L14,O14,R14,U14,X14,AA14,AD14,AG14,AJ14,AM14) -> 0 | D14: =IF(C14=0,0,E14/C14) -> 0 | E14: =+SUM(H14,K14,N14,Q14,T14,W14,Z14,AC14,AF14,AI14,AL14,AO14) -> 0 | G14: =IF(F14=0,0,H14/F14) -> 0 | J14: =IF(I14=0,0,K14/I14) -> 0 | M14: =IF(L14=0,0,N14/L14) -> 0 | P14: =IF(O14=0,0,Q14/O14) -> 0 | S14: =IF(R14=0,0,T14/R14) -> 0 | V14: =IF(U14=0,0,W14/U14) -> 0 | Y14: =IF(X14=0,0,Z14/X14) -> 0 | AB14: =IF(AA14=0,0,AC14/AA14) -> 0 | AE14: =IF(AD14=0,0,AF14/AD14) -> 0 | AH14: =IF(AG14=0,0,AI14/AG14) -> 0 | AK14: =IF(AJ14=0,0,AL14/AJ14) -> 0 | AN14: =IF(AM14=0,0,AO14/AM14) -> 0
A15: =+$C$4&B15 -> Véhicules neufs[...] | B15: [...] | C15: =+SUM(F15,I15,L15,O15,R15,U15,X15,AA15,AD15,AG15,AJ15,AM15) -> 0 | D15: =IF(C15=0,0,E15/C15) -> 0 | E15: =+SUM(H15,K15,N15,Q15,T15,W15,Z15,AC15,AF15,AI15,AL15,AO15) -> 0 | G15: =IF(F15=0,0,H15/F15) -> 0 | J15: =IF(I15=0,0,K15/I15) -> 0 | M15: =IF(L15=0,0,N15/L15) -> 0 | P15: =IF(O15=0,0,Q15/O15) -> 0 | S15: =IF(R15=0,0,T15/R15) -> 0 | V15: =IF(U15=0,0,W15/U15) -> 0 | Y15: =IF(X15=0,0,Z15/X15) -> 0 | AB15: =IF(AA15=0,0,AC15/AA15) -> 0 | AE15: =IF(AD15=0,0,AF15/AD15) -> 0 | AH15: =IF(AG15=0,0,AI15/AG15) -> 0 | AK15: =IF(AJ15=0,0,AL15/AJ15) -> 0 | AN15: =IF(AM15=0,0,AO15/AM15) -> 0
A16: =+$C$4&B16 -> Véhicules neufsTotal Neufs | B16: Total Neufs | C16: =+SUM(C9:C15) -> 683 | D16: =IF(C16<=0,0,E16/C16) -> 2302.6229 | E16: =+SUM(E9:E15) -> 1572691.4 | F16: =+SUM(F9:F15) -> 45 | G16: =IF(F16<=0,0,H16/F16) -> 2302.3264 | H16: =+SUM(H9:H15) -> 103604.69 | I16: =+SUM(I9:I15) -> 48 | J16: =IF(I16<=0,0,K16/I16) -> 2300.5181 | K16: =+SUM(K9:K15) -> 110424.87 | L16: =+SUM(L9:L15) -> 70 | M16: =IF(L16<=0,0,N16/L16) -> 2304.393 | N16: =+SUM(N9:N15) -> 161307.51 | O16: =+SUM(O9:O15) -> 72 | P16: =IF(O16<=0,0,Q16/O16) -> 2300.5181 | Q16: =+SUM(Q9:Q15) -> 165637.3 | R16: =+SUM(R9:R15) -> 75 | S16: =IF(R16<=0,0,T16/R16) -> 2299.4331 | T16: =+SUM(T9:T15) -> 172457.48 | U16: =+SUM(U9:U15) -> 67 | V16: =IF(U16<=0,0,W16/U16) -> 2305.7811 | W16: =+SUM(W9:W15) -> 154487.33 | X16: =+SUM(X9:X15) -> 60 | Y16: =IF(X16<=0,0,Z16/X16) -> 2305.943 | Z16: =+SUM(Z9:Z15) -> 138356.58 | AA16: =+SUM(AA9:AA15) -> 55 | AB16: =IF(AA16<=0,0,AC16/AA16) -> 2301.0112 | AC16: =+SUM(AC9:AC15) -> 126555.62 | AD16: =+SUM(AD9:AD15) -> 53 | AE16: =IF(AD16<=0,0,AF16/AD16) -> 2306.1477 | AF16: =+SUM(AF9:AF15) -> 122225.83 | AG16: =+SUM(AG9:AG15) -> 52 | AH16: =IF(AG16<=0,0,AI16/AG16) -> 2302.6046 | AI16: =+SUM(AI9:AI15) -> 119735.44 | AJ16: =+SUM(AJ9:AJ15) -> 46 | AK16: =IF(AJ16<=0,0,AL16/AJ16) -> 2306.4147 | AL16: =+SUM(AL9:AL15) -> 106095.08 | AM16: =+SUM(AM9:AM15) -> 40 | AN16: =IF(AM16<=0,0,AO16/AM16) -> 2295.0931 | AO16: =+SUM(AO9:AO15) -> 91803.725
A17: =+$C$4&B17 -> Véhicules neufs
A18: =+$C$4&B18 -> Véhicules neufsEx-Démos et courtoisies | B18: Ex-Démos et courtoisies | C18: =+SUM(F18,I18,L18,O18,R18,U18,X18,AA18,AD18,AG18,AJ18,AM18) -> 40 | D18: =IF(C18=0,0,E18/C18) -> 1524.8245 | E18: =+SUM(H18,K18,N18,Q18,T18,W18,Z18,AC18,AF18,AI18,AL18,AO18) -> 60992.981 | F18: ='[1]Vehicules neuf 2026'!E37 -> 3 | G18: =IF(F18=0,0,H18/F18) -> 1524.8245 | H18: ='[1]Vehicules neuf 2026'!E55 -> 4574.4736 | I18: ='[1]Vehicules neuf 2026'!F37 -> 3 | J18: =IF(I18=0,0,K18/I18) -> 1524.8245 | K18: ='[1]Vehicules neuf 2026'!F55 -> 4574.4736 | L18: ='[1]Vehicules neuf 2026'!G37 -> 4 | M18: =IF(L18=0,0,N18/L18) -> 1524.8245 | N18: ='[1]Vehicules neuf 2026'!G55 -> 6099.2981 | O18: ='[1]Vehicules neuf 2026'!H37 -> 4 | P18: =IF(O18=0,0,Q18/O18) -> 1524.8245 | Q18: ='[1]Vehicules neuf 2026'!H55 -> 6099.2981 | R18: ='[1]Vehicules neuf 2026'!I37 -> 4 | S18: =IF(R18=0,0,T18/R18) -> 1524.8245 | T18: ='[1]Vehicules neuf 2026'!I55 -> 6099.2981 | U18: ='[1]Vehicules neuf 2026'!J37 -> 4 | V18: =IF(U18=0,0,W18/U18) -> 1524.8245 | W18: ='[1]Vehicules neuf 2026'!J55 -> 6099.2981 | X18: ='[1]Vehicules neuf 2026'!K37 -> 4 | Y18: =IF(X18=0,0,Z18/X18) -> 1524.8245 | Z18: ='[1]Vehicules neuf 2026'!K55 -> 6099.2981 | AA18: ='[1]Vehicules neuf 2026'!L37 -> 3 | AB18: =IF(AA18=0,0,AC18/AA18) -> 1524.8245 | AC18: ='[1]Vehicules neuf 2026'!L55 -> 4574.4736 | AD18: ='[1]Vehicules neuf 2026'!M37 -> 3 | AE18: =IF(AD18=0,0,AF18/AD18) -> 1524.8245 | AF18: ='[1]Vehicules neuf 2026'!M55 -> 4574.4736 | AG18: ='[1]Vehicules neuf 2026'!N37 -> 3 | AH18: =IF(AG18=0,0,AI18/AG18) -> 1524.8245 | AI18: ='[1]Vehicules neuf 2026'!N55 -> 4574.4736 | AJ18: ='[1]Vehicules neuf 2026'!O37 -> 3 | AK18: =IF(AJ18=0,0,AL18/AJ18) -> 1524.8245 | AL18: ='[1]Vehicules neuf 2026'!O55 -> 4574.4736 | AM18: ='[1]Vehicules neuf 2026'!P37 -> 2 | AN18: =IF(AM18=0,0,AO18/AM18) -> 1524.8245 | AO18: ='[1]Vehicules neuf 2026'!P55 -> 3049.6491
A19: =+$C$4&B19 -> Véhicules neufs
A20: =+$C$4&B20 -> Véhicules neufsFlottes | B20: Flottes | C20: =+SUM(F20,I20,L20,O20,R20,U20,X20,AA20,AD20,AG20,AJ20,AM20) -> 49 | D20: =IF(C20=0,0,E20/C20) -> 1300.6851 | E20: =+SUM(H20,K20,N20,Q20,T20,W20,Z20,AC20,AF20,AI20,AL20,AO20) -> 63733.571 | F20: ='[1]Vehicules neuf 2026'!E38 -> 3 | G20: =IF(F20=0,0,H20/F20) -> 1300.6851 | H20: ='[1]Vehicules neuf 2026'!E56 -> 3902.0554 | I20: ='[1]Vehicules neuf 2026'!F38 -> 4 | J20: =IF(I20=0,0,K20/I20) -> 1300.6851 | K20: ='[1]Vehicules neuf 2026'!F56 -> 5202.7405 | L20: ='[1]Vehicules neuf 2026'!G38 -> 5 | M20: =IF(L20=0,0,N20/L20) -> 1300.6851 | N20: ='[1]Vehicules neuf 2026'!G56 -> 6503.4257 | O20: ='[1]Vehicules neuf 2026'!H38 -> 5 | P20: =IF(O20=0,0,Q20/O20) -> 1300.6851 | Q20: ='[1]Vehicules neuf 2026'!H56 -> 6503.4257 | R20: ='[1]Vehicules neuf 2026'!I38 -> 5 | S20: =IF(R20=0,0,T20/R20) -> 1300.6851 | T20: ='[1]Vehicules neuf 2026'!I56 -> 6503.4257 | U20: ='[1]Vehicules neuf 2026'!J38 -> 5 | V20: =IF(U20=0,0,W20/U20) -> 1300.6851 | W20: ='[1]Vehicules neuf 2026'!J56 -> 6503.4257 | X20: ='[1]Vehicules neuf 2026'!K38 -> 4 | Y20: =IF(X20=0,0,Z20/X20) -> 1300.6851 | Z20: ='[1]Vehicules neuf 2026'!K56 -> 5202.7405 | AA20: ='[1]Vehicules neuf 2026'!L38 -> 4 | AB20: =IF(AA20=0,0,AC20/AA20) -> 1300.6851 | AC20: ='[1]Vehicules neuf 2026'!L56 -> 5202.7405 | AD20: ='[1]Vehicules neuf 2026'!M38 -> 4 | AE20: =IF(AD20=0,0,AF20/AD20) -> 1300.6851 | AF20: ='[1]Vehicules neuf 2026'!M56 -> 5202.7405 | AG20: ='[1]Vehicules neuf 2026'!N38 -> 4 | AH20: =IF(AG20=0,0,AI20/AG20) -> 1300.6851 | AI20: ='[1]Vehicules neuf 2026'!N56 -> 5202.7405 | AJ20: ='[1]Vehicules neuf 2026'!O38 -> 3 | AK20: =IF(AJ20=0,0,AL20/AJ20) -> 1300.6851 | AL20: ='[1]Vehicules neuf 2026'!O56 -> 3902.0554 | AM20: ='[1]Vehicules neuf 2026'!P38 -> 3 | AN20: =IF(AM20=0,0,AO20/AM20) -> 1300.6851 | AO20: ='[1]Vehicules neuf 2026'!P56 -> 3902.0554
A21: =+$C$4&B21 -> Véhicules neufs
A22: =+$C$4&B22 -> Véhicules neufs
A23: =+$C$4&B23 -> Véhicules neufs
A24: =+$C$4&B24 -> Véhicules neufsRev. Finances | B24: Rev. Finances | D24: =IF(C16=0,0,E24/(C16+C18)) -> 50 | E24: =+SUM(H24,K24,N24,Q24,T24,W24,Z24,AC24,AF24,AI24,AL24,AO24) -> 36150 | G24: =IF(F16=0,0,H24/(F16+F18)) -> 50 | H24: ='[1]Vehicules neuf 2026'!E79 -> 2400 | J24: =IF(I16=0,0,K24/(I16+I18)) -> 50 | K24: ='[1]Vehicules neuf 2026'!F79 -> 2550 | M24: =IF(L16=0,0,N24/(L16+L18)) -> 50 | N24: ='[1]Vehicules neuf 2026'!G79 -> 3700 | P24: =IF(O16=0,0,Q24/(O16+O18)) -> 50 | Q24: ='[1]Vehicules neuf 2026'!H79 -> 3800 | S24: =IF(R16=0,0,T24/(R16+R18)) -> 50 | T24: ='[1]Vehicules neuf 2026'!I79 -> 3950 | V24: =IF(U16=0,0,W24/(U16+U18)) -> 50 | W24: ='[1]Vehicules neuf 2026'!J79 -> 3550 | Y24: =IF(X16=0,0,Z24/(X16+X18)) -> 50 | Z24: ='[1]Vehicules neuf 2026'!K79 -> 3200 | AB24: =IF(AA16=0,0,AC24/(AA16+AA18)) -> 50 | AC24: ='[1]Vehicules neuf 2026'!L79 -> 2900 | AE24: =IF(AD16=0,0,AF24/(AD16+AD18)) -> 50 | AF24: ='[1]Vehicules neuf 2026'!M79 -> 2800 | AH24: =IF(AG16=0,0,AI24/(AG16+AG18)) -> 50 | AI24: ='[1]Vehicules neuf 2026'!N79 -> 2750 | AK24: =IF(AJ16=0,0,AL24/(AJ16+AJ18)) -> 50 | AL24: ='[1]Vehicules neuf 2026'!O79 -> 2450 | AN24: =IF(AM16=0,0,AO24/(AM16+AM18)) -> 50 | AO24: ='[1]Vehicules neuf 2026'!P79 -> 2100
A25: =+$C$4&B25 -> Véhicules neufsRev. Protections | B25: Rev. Protections | D25: =IF(C16=0,0,E25/(C16+C18)) -> 1130 | E25: =+SUM(H25,K25,N25,Q25,T25,W25,Z25,AC25,AF25,AI25,AL25,AO25) -> 816990 | G25: =IF(F16=0,0,H25/(F16+F18)) -> 1130 | H25: ='[1]Vehicules neuf 2026'!E80 -> 54240 | J25: =IF(I16=0,0,K25/(I16+I18)) -> 1130 | K25: ='[1]Vehicules neuf 2026'!F80 -> 57630 | M25: =IF(L16=0,0,N25/(L16+L18)) -> 1130 | N25: ='[1]Vehicules neuf 2026'!G80 -> 83620 | P25: =IF(O16=0,0,Q25/(O16+O18)) -> 1130 | Q25: ='[1]Vehicules neuf 2026'!H80 -> 85880 | S25: =IF(R16=0,0,T25/(R16+R18)) -> 1130 | T25: ='[1]Vehicules neuf 2026'!I80 -> 89270 | V25: =IF(U16=0,0,W25/(U16+U18)) -> 1130 | W25: ='[1]Vehicules neuf 2026'!J80 -> 80230 | Y25: =IF(X16=0,0,Z25/(X16+X18)) -> 1130 | Z25: ='[1]Vehicules neuf 2026'!K80 -> 72320 | AB25: =IF(AA16=0,0,AC25/(AA16+AA18)) -> 1130 | AC25: ='[1]Vehicules neuf 2026'!L80 -> 65540 | AE25: =IF(AD16=0,0,AF25/(AD16+AD18)) -> 1130 | AF25: ='[1]Vehicules neuf 2026'!M80 -> 63280 | AH25: =IF(AG16=0,0,AI25/(AG16+AG18)) -> 1130 | AI25: ='[1]Vehicules neuf 2026'!N80 -> 62150 | AK25: =IF(AJ16=0,0,AL25/(AJ16+AJ18)) -> 1130 | AL25: ='[1]Vehicules neuf 2026'!O80 -> 55370 | AN25: =IF(AM16=0,0,AO25/(AM16+AM18)) -> 1130 | AO25: ='[1]Vehicules neuf 2026'!P80 -> 47460
A26: =+$C$4&B26 -> Véhicules neufsRev. Autres | B26: Rev. Autres | D26: =IF(C16=0,0,E26/(C16+C18)) -> 20 | E26: =+SUM(H26,K26,N26,Q26,T26,W26,Z26,AC26,AF26,AI26,AL26,AO26) -> 14460 | G26: =IF(F16=0,0,H26/(F16+F18)) -> 20 | H26: ='[1]Vehicules neuf 2026'!E81 -> 960 | J26: =IF(I16=0,0,K26/(I16+I18)) -> 20 | K26: ='[1]Vehicules neuf 2026'!F81 -> 1020 | M26: =IF(L16=0,0,N26/(L16+L18)) -> 20 | N26: ='[1]Vehicules neuf 2026'!G81 -> 1480 | P26: =IF(O16=0,0,Q26/(O16+O18)) -> 20 | Q26: ='[1]Vehicules neuf 2026'!H81 -> 1520 | S26: =IF(R16=0,0,T26/(R16+R18)) -> 20 | T26: ='[1]Vehicules neuf 2026'!I81 -> 1580 | V26: =IF(U16=0,0,W26/(U16+U18)) -> 20 | W26: ='[1]Vehicules neuf 2026'!J81 -> 1420 | Y26: =IF(X16=0,0,Z26/(X16+X18)) -> 20 | Z26: ='[1]Vehicules neuf 2026'!K81 -> 1280 | AB26: =IF(AA16=0,0,AC26/(AA16+AA18)) -> 20 | AC26: ='[1]Vehicules neuf 2026'!L81 -> 1160 | AE26: =IF(AD16=0,0,AF26/(AD16+AD18)) -> 20 | AF26: ='[1]Vehicules neuf 2026'!M81 -> 1120 | AH26: =IF(AG16=0,0,AI26/(AG16+AG18)) -> 20 | AI26: ='[1]Vehicules neuf 2026'!N81 -> 1100 | AK26: =IF(AJ16=0,0,AL26/(AJ16+AJ18)) -> 20 | AL26: ='[1]Vehicules neuf 2026'!O81 -> 980 | AN26: =IF(AM16=0,0,AO26/(AM16+AM18)) -> 20 | AO26: ='[1]Vehicules neuf 2026'!P81 -> 840
A27: =+$C$4&B27 -> Véhicules neufsTotal F&I | B27: Total F&I | C27: =+C18+C16 -> 723 | D27: =IF(C27<=0,0,E27/C27) -> 1200 | E27: =E24+E25+E26 -> 867600 | F27: =+F18+F16 -> 48 | G27: =IF(F27<=0,0,H27/F27) -> 1200 | H27: =H24+H25+H26 -> 57600 | I27: =+I18+I16 -> 51 | J27: =IF(I27<=0,0,K27/I27) -> 1200 | K27: =K24+K25+K26 -> 61200 | L27: =+L18+L16 -> 74 | M27: =IF(L27<=0,0,N27/L27) -> 1200 | N27: =N24+N25+N26 -> 88800 | O27: =+O18+O16 -> 76 | P27: =IF(O27<=0,0,Q27/O27) -> 1200 | Q27: =Q24+Q25+Q26 -> 91200 | R27: =+R18+R16 -> 79 | S27: =IF(R27<=0,0,T27/R27) -> 1200 | T27: =T24+T25+T26 -> 94800 | U27: =+U18+U16 -> 71 | V27: =IF(U27<=0,0,W27/U27) -> 1200 | W27: =W24+W25+W26 -> 85200 | X27: =+X18+X16 -> 64 | Y27: =IF(X27<=0,0,Z27/X27) -> 1200 | Z27: =Z24+Z25+Z26 -> 76800 | AA27: =+AA18+AA16 -> 58 | AB27: =IF(AA27<=0,0,AC27/AA27) -> 1200 | AC27: =AC24+AC25+AC26 -> 69600 | AD27: =+AD18+AD16 -> 56 | AE27: =IF(AD27<=0,0,AF27/AD27) -> 1200 | AF27: =AF24+AF25+AF26 -> 67200 | AG27: =+AG18+AG16 -> 55 | AH27: =IF(AG27<=0,0,AI27/AG27) -> 1200 | AI27: =AI24+AI25+AI26 -> 66000 | AJ27: =+AJ18+AJ16 -> 49 | AK27: =IF(AJ27<=0,0,AL27/AJ27) -> 1200 | AL27: =AL24+AL25+AL26 -> 58800 | AM27: =+AM18+AM16 -> 42 | AN27: =IF(AM27<=0,0,AO27/AM27) -> 1200 | AO27: =AO24+AO25+AO26 -> 50400
A28: =+$C$4&B28 -> Véhicules neufs
A29: =+$C$4&B29 -> Véhicules neufs
A30: =+$C$4&B30 -> Véhicules neufsTotal Dépt. Neufs | B30: Total Dépt. Neufs | C30: =+C16+C18+C20 -> 772 | D30: =IF(C30<=0,0,E30/C30) -> 3322.5622 | E30: =E16+E20+E27+E22+E18 -> 2565018 | F30: =+F16+F18+F20 -> 51 | G30: =IF(F30<=0,0,H30/F30) -> 3327.0827 | H30: =H16+H20+H27+H22+H18 -> 169681.22 | I30: =+I16+I18+I20 -> 55 | J30: =IF(I30<=0,0,K30/I30) -> 3298.2197 | K30: =K16+K20+K27+K22+K18 -> 181402.08 | L30: =+L16+L18+L20 -> 79 | M30: =IF(L30<=0,0,N30/L30) -> 3325.446 | N30: =N16+N20+N27+N22+N18 -> 262710.23 | O30: =+O16+O18+O20 -> 81 | P30: =IF(O30<=0,0,Q30/O30) -> 3326.42 | Q30: =Q16+Q20+Q27+Q22+Q18 -> 269440.02 | R30: =+R16+R18+R20 -> 84 | S30: =IF(R30<=0,0,T30/R30) -> 3331.6691 | T30: =T16+T20+T27+T22+T18 -> 279860.2 | U30: =+U16+U18+U20 -> 76 | V30: =IF(U30<=0,0,W30/U30) -> 3319.606 | W30: =W16+W20+W27+W22+W18 -> 252290.05 | X30: =+X16+X18+X20 -> 68 | Y30: =IF(X30<=0,0,Z30/X30) -> 3330.2738 | Z30: =Z16+Z20+Z27+Z22+Z18 -> 226458.62 | AA30: =+AA16+AA18+AA20 -> 62 | AB30: =IF(AA30<=0,0,AC30/AA30) -> 3321.4973 | AC30: =AC16+AC20+AC27+AC22+AC18 -> 205932.83 | AD30: =+AD16+AD18+AD20 -> 60 | AE30: =IF(AD30<=0,0,AF30/AD30) -> 3320.0507 | AF30: =AF16+AF20+AF27+AF22+AF18 -> 199203.04 | AG30: =+AG16+AG18+AG20 -> 59 | AH30: =IF(AG30<=0,0,AI30/AG30) -> 3313.7738 | AI30: =AI16+AI20+AI27+AI22+AI18 -> 195512.65 | AJ30: =+AJ16+AJ18+AJ20 -> 52 | AK30: =IF(AJ30<=0,0,AL30/AJ30) -> 3334.0694 | AL30: =AL16+AL20+AL27+AL22+AL18 -> 173371.61 | AM30: =+AM16+AM18+AM20 -> 45 | AN30: =IF(AM30<=0,0,AO30/AM30) -> 3314.5651 | AO30: =AO16+AO20+AO27+AO22+AO18 -> 149155.43
A31: =+$C$4&B31 -> Véhicules neufs
A32: =+$C$4&B32 -> Véhicules neufs
A33: =+$C$4&B33 -> Véhicules neufsDEPENSES | B33: DEPENSES
A34: =+$C$4&B34 -> Véhicules neufsComm. vendeurs | B34: Comm. vendeurs | C34: =E34/(E16+E18) -> 0.32350364 | D34: =IF(E34=0,0,E34/C$27) -> 730.98597 | E34: =+SUM(H34,K34,N34,Q34,T34,W34,Z34,AC34,AF34,AI34,AL34,AO34) -> 528502.86 | F34: =H34/(H16+H18) -> 0.32965618 | G34: =IF(H34=0,0,H34/F$27) -> 742.95684 | H34: ='[1]Vehicules neuf 2026'!E74 -> 35661.928 | I34: =K34/(K16+K18) -> 0.32917199 | J34: =IF(K34=0,0,K34/I$27) -> 742.24631 | K34: ='[1]Vehicules neuf 2026'!F74 -> 37854.562 | L34: =N34/(N16+N18) -> 0.31274572 | M34: =IF(N34=0,0,N34/L$27) -> 707.51032 | N34: ='[1]Vehicules neuf 2026'!G74 -> 52355.763 | O34: =Q34/(Q16+Q18) -> 0.31166803 | P34: =IF(Q34=0,0,Q34/O$27) -> 704.27377 | Q34: ='[1]Vehicules neuf 2026'!H74 -> 53524.806 | R34: =T34/(T16+T18) -> 0.31763709 | S34: =IF(T34=0,0,T34/R$27) -> 717.92728 | T34: ='[1]Vehicules neuf 2026'!I74 -> 56716.255 | U34: =W34/(W16+W18) -> 0.31456115 | V34: =IF(W34=0,0,W34/U$27) -> 711.46922 | W34: ='[1]Vehicules neuf 2026'!J74 -> 50514.315 | X34: =Z34/(Z16+Z18) -> 0.32645142 | Y34: =IF(Z34=0,0,Z34/X$27) -> 736.84105 | Z34: ='[1]Vehicules neuf 2026'!K74 -> 47157.827 | AA34: =AC34/(AC16+AC18) -> 0.32189305 | AB34: =IF(AC34=0,0,AC34/AA$27) -> 727.75629 | AC34: ='[1]Vehicules neuf 2026'!L74 -> 42209.865 | AD34: =AF34/(AF16+AF18) -> 0.32366501 | AE34: =IF(AF34=0,0,AF34/AD$27) -> 732.87181 | AF34: ='[1]Vehicules neuf 2026'!M74 -> 41040.822 | AG34: =AI34/(AI16+AI18) -> 0.33560008 | AH34: =IF(AI34=0,0,AI34/AG$27) -> 758.51665 | AI34: ='[1]Vehicules neuf 2026'!N74 -> 41718.416 | AJ34: =AL34/(AL16+AL18) -> 0.32831374 | AK34: =IF(AL34=0,0,AL34/AJ$27) -> 741.51702 | AL34: ='[1]Vehicules neuf 2026'!O74 -> 36334.334 | AM34: =AO34/(AO16+AO18) -> 0.35226966 | AN34: =IF(AO34=0,0,AO34/AM$27) -> 795.57061 | AO34: ='[1]Vehicules neuf 2026'!P74 -> 33413.966
A35: =+$C$4&B35 -> Véhicules neufsComm. F&I | B35: Comm. F&I | C35: =E35/E27 -> 0.2 | D35: =IF(E35=0,0,E35/C$27) -> 240 | E35: =+SUM(H35,K35,N35,Q35,T35,W35,Z35,AC35,AF35,AI35,AL35,AO35) -> 173520 | F35: =H35/H27 -> 0.2 | G35: =IF(H35=0,0,H35/F$27) -> 240 | H35: ='[1]Vehicules neuf 2026'!E85 -> 11520 | I35: =K35/K27 -> 0.2 | J35: =IF(K35=0,0,K35/I$27) -> 240 | K35: ='[1]Vehicules neuf 2026'!F85 -> 12240 | L35: =N35/N27 -> 0.2 | M35: =IF(N35=0,0,N35/L$27) -> 240 | N35: ='[1]Vehicules neuf 2026'!G85 -> 17760 | O35: =Q35/Q27 -> 0.2 | P35: =IF(Q35=0,0,Q35/O$27) -> 240 | Q35: ='[1]Vehicules neuf 2026'!H85 -> 18240 | R35: =T35/T27 -> 0.2 | S35: =IF(T35=0,0,T35/R$27) -> 240 | T35: ='[1]Vehicules neuf 2026'!I85 -> 18960 | U35: =W35/W27 -> 0.2 | V35: =IF(W35=0,0,W35/U$27) -> 240 | W35: ='[1]Vehicules neuf 2026'!J85 -> 17040 | X35: =Z35/Z27 -> 0.2 | Y35: =IF(Z35=0,0,Z35/X$27) -> 240 | Z35: ='[1]Vehicules neuf 2026'!K85 -> 15360 | AA35: =AC35/AC27 -> 0.2 | AB35: =IF(AC35=0,0,AC35/AA$27) -> 240 | AC35: ='[1]Vehicules neuf 2026'!L85 -> 13920 | AD35: =AF35/AF27 -> 0.2 | AE35: =IF(AF35=0,0,AF35/AD$27) -> 240 | AF35: ='[1]Vehicules neuf 2026'!M85 -> 13440 | AG35: =AI35/AI27 -> 0.2 | AH35: =IF(AI35=0,0,AI35/AG$27) -> 240 | AI35: ='[1]Vehicules neuf 2026'!N85 -> 13200 | AJ35: =AL35/AL27 -> 0.2 | AK35: =IF(AL35=0,0,AL35/AJ$27) -> 240 | AL35: ='[1]Vehicules neuf 2026'!O85 -> 11760 | AM35: =AO35/AO27 -> 0.2 | AN35: =IF(AO35=0,0,AO35/AM$27) -> 240 | AO35: ='[1]Vehicules neuf 2026'!P85 -> 10080
A36: =+$C$4&B36 -> Véhicules neufsFrais de livraison | B36: Frais de livraison | D36: =IF(E36=0,0,E36/C$27) -> 115 | E36: =+SUM(H36,K36,N36,Q36,T36,W36,Z36,AC36,AF36,AI36,AL36,AO36) -> 83145 | G36: =IF(H36=0,0,H36/F$27) -> 115 | H36: ='[1]Vehicules neuf 2026'!E91 -> 5520 | J36: =IF(K36=0,0,K36/I$27) -> 115 | K36: ='[1]Vehicules neuf 2026'!F91 -> 5865 | M36: =IF(N36=0,0,N36/L$27) -> 115 | N36: ='[1]Vehicules neuf 2026'!G91 -> 8510 | P36: =IF(Q36=0,0,Q36/O$27) -> 115 | Q36: ='[1]Vehicules neuf 2026'!H91 -> 8740 | S36: =IF(T36=0,0,T36/R$27) -> 115 | T36: ='[1]Vehicules neuf 2026'!I91 -> 9085 | V36: =IF(W36=0,0,W36/U$27) -> 115 | W36: ='[1]Vehicules neuf 2026'!J91 -> 8165 | Y36: =IF(Z36=0,0,Z36/X$27) -> 115 | Z36: ='[1]Vehicules neuf 2026'!K91 -> 7360 | AB36: =IF(AC36=0,0,AC36/AA$27) -> 115 | AC36: ='[1]Vehicules neuf 2026'!L91 -> 6670 | AE36: =IF(AF36=0,0,AF36/AD$27) -> 115 | AF36: ='[1]Vehicules neuf 2026'!M91 -> 6440 | AH36: =IF(AI36=0,0,AI36/AG$27) -> 115 | AI36: ='[1]Vehicules neuf 2026'!N91 -> 6325 | AK36: =IF(AL36=0,0,AL36/AJ$27) -> 115 | AL36: ='[1]Vehicules neuf 2026'!O91 -> 5635 | AN36: =IF(AO36=0,0,AO36/AM$27) -> 115 | AO36: ='[1]Vehicules neuf 2026'!P91 -> 4830
A37: =+$C$4&B37 -> Véhicules neufsService gratuit 1 | B37: Service gratuit 1 | D37: =IF(E37=0,0,E37/C$27) -> 10 | E37: =+SUM(H37,K37,N37,Q37,T37,W37,Z37,AC37,AF37,AI37,AL37,AO37) -> 7230 | G37: =IF(H37=0,0,H37/F$27) -> 10 | H37: ='[1]Vehicules neuf 2026'!E97 -> 480 | J37: =IF(K37=0,0,K37/I$27) -> 10 | K37: ='[1]Vehicules neuf 2026'!F97 -> 510 | M37: =IF(N37=0,0,N37/L$27) -> 10 | N37: ='[1]Vehicules neuf 2026'!G97 -> 740 | P37: =IF(Q37=0,0,Q37/O$27) -> 10 | Q37: ='[1]Vehicules neuf 2026'!H97 -> 760 | S37: =IF(T37=0,0,T37/R$27) -> 10 | T37: ='[1]Vehicules neuf 2026'!I97 -> 790 | V37: =IF(W37=0,0,W37/U$27) -> 10 | W37: ='[1]Vehicules neuf 2026'!J97 -> 710 | Y37: =IF(Z37=0,0,Z37/X$27) -> 10 | Z37: ='[1]Vehicules neuf 2026'!K97 -> 640 | AB37: =IF(AC37=0,0,AC37/AA$27) -> 10 | AC37: ='[1]Vehicules neuf 2026'!L97 -> 580 | AE37: =IF(AF37=0,0,AF37/AD$27) -> 10 | AF37: ='[1]Vehicules neuf 2026'!M97 -> 560 | AH37: =IF(AI37=0,0,AI37/AG$27) -> 10 | AI37: ='[1]Vehicules neuf 2026'!N97 -> 550 | AK37: =IF(AL37=0,0,AL37/AJ$27) -> 10 | AL37: ='[1]Vehicules neuf 2026'!O97 -> 490 | AN37: =IF(AO37=0,0,AO37/AM$27) -> 10 | AO37: ='[1]Vehicules neuf 2026'!P97 -> 420
A38: =+$C$4&B38 -> Véhicules neufsEntretien stock | B38: Entretien stock | D38: =IF(E38=0,0,E38/C$27) -> 120 | E38: =+SUM(H38,K38,N38,Q38,T38,W38,Z38,AC38,AF38,AI38,AL38,AO38) -> 86760 | G38: =IF(H38=0,0,H38/F$27) -> 120 | H38: ='[1]Vehicules neuf 2026'!E103 -> 5760 | J38: =IF(K38=0,0,K38/I$27) -> 120 | K38: ='[1]Vehicules neuf 2026'!F103 -> 6120 | M38: =IF(N38=0,0,N38/L$27) -> 120 | N38: ='[1]Vehicules neuf 2026'!G103 -> 8880 | P38: =IF(Q38=0,0,Q38/O$27) -> 120 | Q38: ='[1]Vehicules neuf 2026'!H103 -> 9120 | S38: =IF(T38=0,0,T38/R$27) -> 120 | T38: ='[1]Vehicules neuf 2026'!I103 -> 9480 | V38: =IF(W38=0,0,W38/U$27) -> 120 | W38: ='[1]Vehicules neuf 2026'!J103 -> 8520 | Y38: =IF(Z38=0,0,Z38/X$27) -> 120 | Z38: ='[1]Vehicules neuf 2026'!K103 -> 7680 | AB38: =IF(AC38=0,0,AC38/AA$27) -> 120 | AC38: ='[1]Vehicules neuf 2026'!L103 -> 6960 | AE38: =IF(AF38=0,0,AF38/AD$27) -> 120 | AF38: ='[1]Vehicules neuf 2026'!M103 -> 6720 | AH38: =IF(AI38=0,0,AI38/AG$27) -> 120 | AI38: ='[1]Vehicules neuf 2026'!N103 -> 6600 | AK38: =IF(AL38=0,0,AL38/AJ$27) -> 120 | AL38: ='[1]Vehicules neuf 2026'!O103 -> 5880 | AN38: =IF(AO38=0,0,AO38/AM$27) -> 120 | AO38: ='[1]Vehicules neuf 2026'!P103 -> 5040
A39: =+$C$4&B39 -> Véhicules neufsPublicité 1 | B39: Publicité 1 | D39: =IF(E39=0,0,E39/C$27) -> 68.48686 | E39: =+SUM(H39,K39,N39,Q39,T39,W39,Z39,AC39,AF39,AI39,AL39,AO39) -> 49516 | G39: =IF(H39=0,0,H39/F$27) -> 169.96875 | H39: ='[1]Vehicules neuf 2026'!E111 -> 8158.5 | J39: =IF(K39=0,0,K39/I$27) -> 61.421569 | K39: ='[1]Vehicules neuf 2026'!F111 -> 3132.5 | M39: =IF(N39=0,0,N39/L$27) -> -4.2905405 | N39: ='[1]Vehicules neuf 2026'!G111 -> -317.5 | P39: =IF(Q39=0,0,Q39/O$27) -> 149.76974 | Q39: ='[1]Vehicules neuf 2026'!H111 -> 11382.5 | S39: =IF(T39=0,0,T39/R$27) -> -13.512658 | T39: ='[1]Vehicules neuf 2026'!I111 -> -1067.5 | V39: =IF(W39=0,0,W39/U$27) -> 1.8661972 | W39: ='[1]Vehicules neuf 2026'!J111 -> 132.5 | Y39: =IF(Z39=0,0,Z39/X$27) -> 18.476562 | Z39: ='[1]Vehicules neuf 2026'!K111 -> 1182.5 | AB39: =IF(AC39=0,0,AC39/AA$27) -> 35.905172 | AC39: ='[1]Vehicules neuf 2026'!L111 -> 2082.5 | AE39: =IF(AF39=0,0,AF39/AD$27) -> 42.544643 | AF39: ='[1]Vehicules neuf 2026'!M111 -> 2382.5 | AH39: =IF(AI39=0,0,AI39/AG$27) -> 46.045455 | AI39: ='[1]Vehicules neuf 2026'!N111 -> 2532.5 | AK39: =IF(AL39=0,0,AL39/AJ$27) -> 314.94898 | AL39: ='[1]Vehicules neuf 2026'!O111 -> 15432.5 | AN39: =IF(AO39=0,0,AO39/AM$27) -> 106.72619 | AO39: ='[1]Vehicules neuf 2026'!P111 -> 4482.5
A40: =+$C$4&B40 -> Véhicules neufsIntérêt de gros | B40: Intérêt de gros | D40: =IF(E40=0,0,E40/C$27) -> 352.41067 | E40: =+SUM(H40,K40,N40,Q40,T40,W40,Z40,AC40,AF40,AI40,AL40,AO40) -> 254792.91 | G40: =IF(H40=0,0,H40/F$27) -> 402.63618 | H40: ='[1]Vehicules neuf 2026'!E49 -> 19326.537 | J40: =IF(K40=0,0,K40/I$27) -> 419.81904 | K40: ='[1]Vehicules neuf 2026'!F49 -> 21410.771 | M40: =IF(N40=0,0,N40/L$27) -> 321.98092 | N40: ='[1]Vehicules neuf 2026'!G49 -> 23826.588 | P40: =IF(Q40=0,0,Q40/O$27) -> 318.80558 | Q40: ='[1]Vehicules neuf 2026'!H49 -> 24229.224 | S40: =IF(T40=0,0,T40/R$27) -> 303.1014 | T40: ='[1]Vehicules neuf 2026'!I49 -> 23945.011 | V40: =IF(W40=0,0,W40/U$27) -> 318.57295 | W40: ='[1]Vehicules neuf 2026'!J49 -> 22618.68 | Y40: =IF(Z40=0,0,Z40/X$27) -> 334.91337 | Z40: ='[1]Vehicules neuf 2026'!K49 -> 21434.456 | AB40: =IF(AC40=0,0,AC40/AA$27) -> 357.30899 | AC40: ='[1]Vehicules neuf 2026'!L49 -> 20723.921 | AE40: =IF(AF40=0,0,AF40/AD$27) -> 365.41771 | AF40: ='[1]Vehicules neuf 2026'!M49 -> 20463.392 | AH40: =IF(AI40=0,0,AI40/AG$27) -> 361.296 | AI40: ='[1]Vehicules neuf 2026'!N49 -> 19871.28 | AK40: =IF(AL40=0,0,AL40/AJ$27) -> 381.85184 | AL40: ='[1]Vehicules neuf 2026'!O49 -> 18710.74 | AN40: =IF(AO40=0,0,AO40/AM$27) -> 434.10271 | AO40: ='[1]Vehicules neuf 2026'!P49 -> 18232.314
A41: =+$C$4&B41 -> Véhicules neufs[...] | B41: [...] | D41: =IF(E41=0,0,E41/C$27) -> 0 | E41: =+SUM(H41,K41,N41,Q41,T41,W41,Z41,AC41,AF41,AI41,AL41,AO41) -> 0 | G41: =IF(H41=0,0,H41/F$27) -> 0 | J41: =IF(K41=0,0,K41/I$27) -> 0 | M41: =IF(N41=0,0,N41/L$27) -> 0 | P41: =IF(Q41=0,0,Q41/O$27) -> 0 | S41: =IF(T41=0,0,T41/R$27) -> 0 | V41: =IF(W41=0,0,W41/U$27) -> 0 | Y41: =IF(Z41=0,0,Z41/X$27) -> 0 | AB41: =IF(AC41=0,0,AC41/AA$27) -> 0 | AE41: =IF(AF41=0,0,AF41/AD$27) -> 0 | AH41: =IF(AI41=0,0,AI41/AG$27) -> 0 | AK41: =IF(AL41=0,0,AL41/AJ$27) -> 0 | AN41: =IF(AO41=0,0,AO41/AM$27) -> 0
...

Sheet Réel 2024
B1: ="Réel 2023 Mensuel Révisé"&" "&Parametres!$B$1 -> Réel 2023 Mensuel Révisé Volks
B2: Mois | F2: =+IF(Parametres!$B$3=F$6,"X","") | G2: =+IF(Parametres!$B$3=F$6,"O","") | H2: =+IF(Parametres!$B$3=F$6,"U","") | I2: =+IF(Parametres!$B$3=I$6,"X","") | J2: =+IF(Parametres!$B$3=I$6,"O","") | K2: =+IF(Parametres!$B$3=I$6,"U","") | L2: =+IF(Parametres!$B$3=L$6,"X","") | M2: =+IF(Parametres!$B$3=L$6,"O","") | N2: =+IF(Parametres!$B$3=L$6,"U","") | O2: =+IF(Parametres!$B$3=O$6,"X","") | P2: =+IF(Parametres!$B$3=O$6,"O","") | Q2: =+IF(Parametres!$B$3=O$6,"U","") | R2: =+IF(Parametres!$B$3=R$6,"X","") | S2: =+IF(Parametres!$B$3=R$6,"O","") | T2: =+IF(Parametres!$B$3=R$6,"U","") | U2: =+IF(Parametres!$B$3=U$6,"X","") | V2: =+IF(Parametres!$B$3=U$6,"O","") | W2: =+IF(Parametres!$B$3=U$6,"U","") | X2: =+IF(Parametres!$B$3=X$6,"X","") -> X | Y2: =+IF(Parametres!$B$3=X$6,"O","") -> O | Z2: =+IF(Parametres!$B$3=X$6,"U","") -> U | AA2: =+IF(Parametres!$B$3=AA$6,"X","") | AB2: =+IF(Parametres!$B$3=AA$6,"O","") | AC2: =+IF(Parametres!$B$3=AA$6,"U","") | AD2: =+IF(Parametres!$B$3=AD$6,"X","") | AE2: =+IF(Parametres!$B$3=AD$6,"O","") | AF2: =+IF(Parametres!$B$3=AD$6,"U","") | AG2: =+IF(Parametres!$B$3=AG$6,"X","") | AH2: =+IF(Parametres!$B$3=AG$6,"O","") | AI2: =+IF(Parametres!$B$3=AG$6,"U","") | AJ2: =+IF(Parametres!$B$3=AJ$6,"X","") | AK2: =+IF(Parametres!$B$3=AJ$6,"O","") | AL2: =+IF(Parametres!$B$3=AJ$6,"U","") | AM2: =+IF(Parametres!$B$3=AM$6,"X","") | AN2: =+IF(Parametres!$B$3=AM$6,"O","") | AO2: =+IF(Parametres!$B$3=AM$6,"U","")
B3: YTD | F3: =+IF(VLOOKUP(F$6,Parametres!$K$3:$N$14,4,0)="X","X","") -> X | G3: =+IF(VLOOKUP(F$6,Parametres!$K$3:$N$14,4,0)="X","O","") -> O | H3: =+IF(VLOOKUP(F$6,Parametres!$K$3:$N$14,4,0)="X","U","") -> U | I3: =+IF(VLOOKUP(I$6,Parametres!$K$3:$N$14,4,0)="X","X","") -> X | J3: =+IF(VLOOKUP(I$6,Parametres!$K$3:$N$14,4,0)="X","O","") -> O | K3: =+IF(VLOOKUP(I$6,Parametres!$K$3:$N$14,4,0)="X","U","") -> U | L3: =+IF(VLOOKUP(L$6,Parametres!$K$3:$N$14,4,0)="X","X","") -> X | M3: =+IF(VLOOKUP(L$6,Parametres!$K$3:$N$14,4,0)="X","O","") -> O | N3: =+IF(VLOOKUP(L$6,Parametres!$K$3:$N$14,4,0)="X","U","") -> U | O3: =+IF(VLOOKUP(O$6,Parametres!$K$3:$N$14,4,0)="X","X","") -> X | P3: =+IF(VLOOKUP(O$6,Parametres!$K$3:$N$14,4,0)="X","O","") -> O | Q3: =+IF(VLOOKUP(O$6,Parametres!$K$3:$N$14,4,0)="X","U","") -> U | R3: =+IF(VLOOKUP(R$6,Parametres!$K$3:$N$14,4,0)="X","X","") -> X | S3: =+IF(VLOOKUP(R$6,Parametres!$K$3:$N$14,4,0)="X","O","") -> O | T3: =+IF(VLOOKUP(R$6,Parametres!$K$3:$N$14,4,0)="X","U","") -> U | U3: =+IF(VLOOKUP(U$6,Parametres!$K$3:$N$14,4,0)="X","X","") -> X | V3: =+IF(VLOOKUP(U$6,Parametres!$K$3:$N$14,4,0)="X","O","") -> O | W3: =+IF(VLOOKUP(U$6,Parametres!$K$3:$N$14,4,0)="X","U","") -> U | X3: =+IF(VLOOKUP(X$6,Parametres!$K$3:$N$14,4,0)="X","X","") -> X | Y3: =+IF(VLOOKUP(X$6,Parametres!$K$3:$N$14,4,0)="X","O","") -> O | Z3: =+IF(VLOOKUP(X$6,Parametres!$K$3:$N$14,4,0)="X","U","") -> U | AA3: =+IF(VLOOKUP(AA$6,Parametres!$K$3:$N$14,4,0)="X","X","") | AB3: =+IF(VLOOKUP(AA$6,Parametres!$K$3:$N$14,4,0)="X","O","") | AC3: =+IF(VLOOKUP(AA$6,Parametres!$K$3:$N$14,4,0)="X","U","") | AD3: =+IF(VLOOKUP(AD$6,Parametres!$K$3:$N$14,4,0)="X","X","") | AE3: =+IF(VLOOKUP(AD$6,Parametres!$K$3:$N$14,4,0)="X","O","") | AF3: =+IF(VLOOKUP(AD$6,Parametres!$K$3:$N$14,4,0)="X","U","") | AG3: =+IF(VLOOKUP(AG$6,Parametres!$K$3:$N$14,4,0)="X","X","") | AH3: =+IF(VLOOKUP(AG$6,Parametres!$K$3:$N$14,4,0)="X","O","") | AI3: =+IF(VLOOKUP(AG$6,Parametres!$K$3:$N$14,4,0)="X","U","") | AJ3: =+IF(VLOOKUP(AJ$6,Parametres!$K$3:$N$14,4,0)="X","X","") | AK3: =+IF(VLOOKUP(AJ$6,Parametres!$K$3:$N$14,4,0)="X","O","") | AL3: =+IF(VLOOKUP(AJ$6,Parametres!$K$3:$N$14,4,0)="X","U","") | AM3: =+IF(VLOOKUP(AM$6,Parametres!$K$3:$N$14,4,0)="X","X","") | AN3: =+IF(VLOOKUP(AM$6,Parametres!$K$3:$N$14,4,0)="X","O","") | AO3: =+IF(VLOOKUP(AM$6,Parametres!$K$3:$N$14,4,0)="X","U","")
B4: Réel 2024 | C4: Véhicules neufs
B6: Mois | C6: 2024 | F6: Janvier | I6: Février | L6: Mars | O6: Avril | R6: Mai | U6: Juin | X6: Juillet | AA6: Août | AD6: Septembre | AG6: Octobre | AJ6: Novembre | AM6: Décembre
C7: UNITE | D7: $P/UNITE | E7: $PROFITS | F7: UNITE | G7: $P/UNITE | H7: $PROFITS | I7: UNITE | J7: $P/UNITE | K7: $PROFITS | L7: UNITE | M7: $P/UNITE | N7: $PROFITS | O7: UNITE | P7: $P/UNITE | Q7: $PROFITS | R7: UNITE | S7: $P/UNITE | T7: $PROFITS | U7: UNITE | V7: $P/UNITE | W7: $PROFITS | X7: UNITE | Y7: $P/UNITE | Z7: $PROFITS | AA7: UNITE | AB7: $P/UNITE | AC7: $PROFITS | AD7: UNITE | AE7: $P/UNITE | AF7: $PROFITS | AG7: UNITE | AH7: $P/UNITE | AI7: $PROFITS | AJ7: UNITE | AK7: $P/UNITE | AL7: $PROFITS | AM7: UNITE | AN7: $P/UNITE | AO7: $PROFITS
A8: =+$C$4&B8 -> Véhicules neufsVentes nettes | B8: Ventes nettes | E8: 36609711 | H8: 2918214.9 | K8: 2075892.1 | N8: 2855728.6 | Q8: 2860821 | T8: 3181778.8 | W8: 2263467 | Z8: 4089468.3 | AC8: 3610810.1 | AF8: 3303841.7 | AI8: 2861489.8 | AL8: 4142859.5 | AO8: 2445339.6
A9: =+$C$4&B9 -> Véhicules neufsAutos détail | B9: Autos détail | C9: 127 | D9: 1912.2985 | E9: 242861.91 | F9: 8 | G9: 1716.8587 | H9: 13734.87 | I9: 4 | J9: 1345.9625 | K9: 5383.85 | L9: 11 | M9: 1848.9036 | N9: 20337.94 | O9: 24 | P9: 1996.3658 | Q9: 47912.78 | R9: 10 | S9: 2530.125 | T9: 25301.25 | U9: 12 | V9: 2183.5042 | W9: 26202.05 | X9: 13 | Y9: 1905.2108 | Z9: 24767.74 | AA9: 15 | AB9: 2442.5653 | AC9: 36638.48 | AD9: 7 | AE9: 688.43143 | AF9: 4819.02 | AG9: 11 | AH9: 1392.1182 | AI9: 15313.3 | AJ9: 10 | AK9: 1542.296 | AL9: 15422.96 | AM9: 2 | AN9: 3513.835 | AO9: 7027.67
A10: =+$C$4&B10 -> Véhicules neufsCamions détail | B10: Camions détail | C10: 511 | D10: 2254.2629 | E10: 1151928.3 | F10: 40 | G10: 2500.5232 | H10: 100020.93 | I10: 26 | J10: 2574.7485 | K10: 66943.46 | L10: 40 | M10: 2175.1205 | N10: 87004.82 | O10: 32 | P10: 2603.3337 | Q10: 83306.68 | R10: 42 | S10: 2234.159 | T10: 93834.68 | U10: 29 | V10: 1971.4128 | W10: 57170.97 | X10: 63 | Y10: 2276.0851 | Z10: 143393.36 | AA10: 49 | AB10: 2254.3873 | AC10: 110464.98 | AD10: 56 | AE10: 2636.2429 | AF10: 147629.6 | AG10: 37 | AH10: 2420.7516 | AI10: 89567.81 | AJ10: 60 | AK10: 1856.0265 | AL10: 111361.59 | AM10: 37 | AN10: 1654.85 | AO10: 61229.45
A11: =+$C$4&B11 -> Véhicules neufsSprinter | B11: Sprinter | C11: 0 | D11: 0 | E11: 0 | F11: 0 | G11: 0 | H11: 0 | I11: 0 | J11: 0 | K11: 0 | L11: 0 | M11: 0 | N11: 0 | O11: 0 | P11: 0 | Q11: 0 | R11: 0 | S11: 0 | T11: 0 | U11: 0 | V11: 0 | W11: 0 | X11: 0 | Y11: 0 | Z11: 0 | AA11: 0 | AB11: 0 | AC11: 0 | AD11: 0 | AE11: 0 | AF11: 0 | AG11: 0 | AH11: 0 | AI11: 0 | AJ11: 0 | AK11: 0 | AL11: 0 | AM11: 0 | AN11: 0 | AO11: 0
A12: =+$C$4&B12 -> Véhicules neufsMoto détail | B12: Moto détail | C12: 0 | D12: 0 | E12: 0 | F12: 0 | G12: 0 | H12: 0 | I12: 0 | J12: 0 | K12: 0 | L12: 0 | M12: 0 | N12: 0 | O12: 0 | P12: 0 | Q12: 0 | R12: 0 | S12: 0 | T12: 0 | U12: 0 | V12: 0 | W12: 0 | X12: 0 | Y12: 0 | Z12: 0 | AA12: 0 | AB12: 0 | AC12: 0 | AD12: 0 | AE12: 0 | AF12: 0 | AG12: 0 | AH12: 0 | AI12: 0 | AJ12: 0 | AK12: 0 | AL12: 0 | AM12: 0 | AN12: 0 | AO12: 0
A13: =+$C$4&B13 -> Véhicules neufs[...] | B13: [...]
A14: =+$C$4&B14 -> Véhicules neufs[...] | B14: [...]
A15: =+$C$4&B15 -> Véhicules neufs[...] | B15: [...]
A16: =+$C$4&B16 -> Véhicules neufsTotal Neufs | B16: Total Neufs | C16: 638 | D16: 2186.1916 | E16: 1394790.2 | F16: 48 | G16: 2369.9125 | H16: 113755.8 | I16: 30 | J16: 2410.9103 | K16: 72327.31 | L16: 51 | M16: 2104.76 | N16: 107342.76 | O16: 56 | P16: 2343.2046 | Q16: 131219.46 | R16: 52 | S16: 2291.0756 | T16: 119135.93 | U16: 41 | V16: 2033.4883 | W16: 83373.02 | X16: 76 | Y16: 2212.6461 | Z16: 168161.1 | AA16: 64 | AB16: 2298.4916 | AC16: 147103.46 | AD16: 63 | AE16: 2419.8194 | AF16: 152448.62 | AG16: 48 | AH16: 2185.0231 | AI16: 104881.11 | AJ16: 70 | AK16: 1811.2079 | AL16: 126784.55 | AM16: 39 | AN16: 1750.1826 | AO16: 68257.12
A17: =+$C$4&B17 -> Véhicules neufs
A18: =+$C$4&B18 -> Véhicules neufsEx-Démos et courtoisies | B18: Ex-Démos et courtoisies | C18: 38 | D18: 1468.0958 | E18: 55787.64 | F18: 2 | G18: 2429.645 | H18: 4859.29 | I18: 2 | J18: 1540.7 | K18: 3081.4 | L18: 4 | M18: 370.87 | N18: 1483.48 | O18: 2 | P18: 495.505 | Q18: 991.01 | R18: 5 | S18: 2015.852 | T18: 10079.26 | U18: 6 | V18: 1300.1783 | W18: 7801.07 | X18: 5 | Y18: 1374.508 | Z18: 6872.54 | AA18: 3 | AB18: 942.82667 | AC18: 2828.48 | AD18: 1 | AE18: 1212.34 | AF18: 1212.34 | AG18: 3 | AH18: 1277.7867 | AI18: 3833.36 | AJ18: 2 | AK18: 2386.71 | AL18: 4773.42 | AM18: 3 | AN18: 2657.33 | AO18: 7971.99
A19: =+$C$4&B19 -> Véhicules neufs
A20: =+$C$4&B20 -> Véhicules neufsFlottes | B20: Flottes | C20: 22 | D20: 2142.7155 | E20: 47139.74 | F20: 4 | G20: 2065.4675 | H20: 8261.87 | I20: 8 | J20: 2662.095 | K20: 21296.76 | L20: 0 | M20: 0 | N20: 0 | O20: 0 | P20: 0 | Q20: 0 | R20: 0 | S20: 0 | T20: 0 | U20: 0 | V20: 0 | W20: 0 | X20: 0 | Y20: 0 | Z20: 0 | AA20: 2 | AB20: 905.915 | AC20: 1811.83 | AD20: 3 | AE20: 626.18667 | AF20: 1878.56 | AG20: 3 | AH20: 2106.1833 | AI20: 6318.55 | AJ20: 2 | AK20: 3786.085 | AL20: 7572.17 | AM20: 0 | AN20: 0 | AO20: 0
A21: =+$C$4&B21 -> Véhicules neufs
A22: =+$C$4&B22 -> Véhicules neufs
A23: =+$C$4&B23 -> Véhicules neufs
A24: =+$C$4&B24 -> Véhicules neufsRev. Finances | B24: Rev. Finances | D24: 14.756686 | E24: 9975.52 | G24: 0 | H24: 0 | J24: 19.229688 | K24: 615.35 | M24: 0 | N24: 0 | P24: 0 | Q24: 0 | S24: 11.182281 | T24: 637.39 | V24: 14.402128 | W24: 676.9 | Y24: 7.4635802 | Z24: 604.55 | AB24: 25.274776 | AC24: 1693.41 | AE24: 0 | AF24: 0 | AH24: 38.216863 | AI24: 1949.06 | AK24: 0 | AL24: 0 | AN24: 90.449048 | AO24: 3798.86
A25: =+$C$4&B25 -> Véhicules neufsRev. Protections | B25: Rev. Protections | D25: 956.66136 | E25: 646703.08 | G25: 1179.3872 | H25: 58969.36 | J25: 984.25156 | K25: 31496.05 | M25: 606.02891 | N25: 33331.59 | P25: 931.86034 | Q25: 54047.9 | S25: 1090.3154 | T25: 62147.98 | V25: 1023.1253 | W25: 48086.89 | Y25: 985.36333 | Z25: 79814.43 | AB25: 940.25194 | AC25: 62996.88 | AE25: 952.71766 | AF25: 60973.93 | AH25: 968.15549 | AI25: 49375.93 | AK25: 995.15556 | AL25: 71651.2 | AN25: 805.02238 | AO25: 33810.94
A26: =+$C$4&B26 -> Véhicules neufsRev. Autres | B26: Rev. Autres | D26: 5.3130325 | E26: 3591.61 | G26: 0 | H26: 0 | J26: 13.8625 | K26: 443.6 | M26: 5.7529091 | N26: 316.41 | P26: 0 | Q26: 0 | S26: 4.6777193 | T26: 266.63 | V26: 0 | W26: 0 | Y26: 2.302963 | Z26: 186.54 | AB26: 5.9568657 | AC26: 399.11 | AE26: 0 | AF26: 0 | AH26: 0 | AI26: 0 | AK26: 13.881806 | AL26: 999.49 | AN26: 23.329286 | AO26: 979.83
A27: =+$C$4&B27 -> Véhicules neufsTotal F&I | B27: Total F&I | C27: 676 | D27: 976.73108 | E27: 660270.21 | F27: 50 | G27: 1179.3872 | H27: 58969.36 | I27: 32 | J27: 1017.3437 | K27: 32555 | L27: 55 | M27: 611.78182 | N27: 33648 | O27: 58 | P27: 931.86034 | Q27: 54047.9 | R27: 57 | S27: 1106.1754 | T27: 63052 | U27: 47 | V27: 1037.5274 | W27: 48763.79 | X27: 81 | Y27: 995.12988 | Z27: 80605.52 | AA27: 67 | AB27: 971.48358 | AC27: 65089.4 | AD27: 64 | AE27: 952.71766 | AF27: 60973.93 | AG27: 51 | AH27: 1006.3724 | AI27: 51324.99 | AJ27: 72 | AK27: 1009.0374 | AL27: 72650.69 | AM27: 42 | AN27: 918.80071 | AO27: 38589.63
A28: =+$C$4&B28 -> Véhicules neufs
A29: =+$C$4&B29 -> Véhicules neufs
A30: =+$C$4&B30 -> Véhicules neufsTotal Dépt. Neufs | B30: Total Dépt. Neufs | C30: 698 | D30: 3249.0204 | E30: 2267816.2 | F30: 54 | G30: 3533.3763 | H30: 190802.32 | I30: 40 | J30: 3400.273 | K30: 136010.92 | L30: 55 | M30: 2826.8116 | N30: 155474.64 | O30: 58 | P30: 3313.1321 | Q30: 192161.66 | R30: 57 | S30: 3579.5528 | T30: 204034.51 | U30: 47 | V30: 3108.0315 | W30: 146077.48 | X30: 81 | Y30: 3311.6236 | Z30: 268241.51 | AA30: 69 | AB30: 3279.6362 | AC30: 226294.9 | AD30: 67 | AE30: 3405.2369 | AF30: 228150.87 | AG30: 54 | AH30: 3257.7409 | AI30: 175918.01 | AJ30: 74 | AK30: 3005.8222 | AL30: 222430.84 | AM30: 42 | AN30: 2909.9662 | AO30: 122218.58
A31: =+$C$4&B31 -> Véhicules neufs
A32: =+$C$4&B32 -> Véhicules neufs
A33: =+$C$4&B33 -> Véhicules neufsDEPENSES | B33: DEPENSES
A34: =+$C$4&B34 -> Véhicules neufsComm. vendeurs | B34: Comm. vendeurs | C34: 0.32111322 | D34: 689.05286 | E34: 465799.73 | F34: 0.36865267 | G34: 874.5554 | H34: 43727.77 | I34: 0.35924126 | J34: 846.56 | K34: 27089.92 | L34: 0.28209805 | M34: 558.17582 | N34: 30699.67 | O34: 0.30815298 | P34: 702.4319 | Q34: 40741.05 | R34: 0.33936869 | S34: 769.32614 | T34: 43851.59 | U34: 0.34423486 | V34: 667.77234 | W34: 31385.3 | X34: 0.29871778 | Y34: 645.50198 | Z34: 52285.66 | AA34: 0.31853546 | AB34: 712.81552 | AC34: 47758.64 | AD34: 0.27814436 | AE34: 667.81141 | AF34: 42739.93 | AG34: 0.37945869 | AH34: 808.87549 | AI34: 41252.65 | AJ34: 0.2766924 | AK34: 505.57069 | AL34: 36401.09 | AM34: 0.36556192 | AN34: 663.48714 | AO34: 27866.46
A35: =+$C$4&B35 -> Véhicules neufsComm. F&I | B35: Comm. F&I | C35: 0.25728074 | D35: 251.2941 | E35: 169874.81 | F35: 0.30000105 | G35: 353.8174 | H35: 17690.87 | I35: 0.24998526 | J35: 254.32094 | K35: 8138.27 | L35: 0.30698942 | M35: 187.81055 | N35: 10329.58 | O35: 0.2000087 | P35: 186.38017 | Q35: 10810.05 | R35: 0.29999762 | S35: 331.85 | T35: 18915.45 | U35: 0.29928478 | V35: 310.51617 | W35: 14594.26 | X35: 0.25000198 | Y35: 248.78444 | Z35: 20151.54 | AA35: 0.24999478 | AB35: 242.86582 | AC35: 16272.01 | AD35: 0.26000358 | AE35: 247.71 | AF35: 15853.44 | AG35: 0.26999966 | AH35: 271.7202 | AI35: 13857.73 | AJ35: 0.26999661 | AK35: 272.43667 | AL35: 19615.44 | AM35: 0.094485747 | AN35: 86.813571 | AO35: 3646.17
A36: =+$C$4&B36 -> Véhicules neufsFrais de livraison | B36: Frais de livraison | D36: 105.38633 | E36: 71241.16 | G36: 88.6484 | H36: 4432.42 | J36: 98.328438 | K36: 3146.51 | M36: 35.175818 | N36: 1934.67 | P36: 166.21517 | Q36: 9640.48 | S36: 138.49439 | T36: 7894.18 | V36: 111.73617 | W36: 5251.6 | Y36: 112.60815 | Z36: 9121.26 | AB36: 78.424925 | AC36: 5254.47 | AE36: 130.02187 | AF36: 8321.4 | AH36: 127.63843 | AI36: 6509.56 | AK36: 73.22125 | AL36: 5271.93 | AN36: 106.25429 | AO36: 4462.68
A37: =+$C$4&B37 -> Véhicules neufsService gratuit 1 | B37: Service gratuit 1 | D37: 4.9730325 | E37: 3361.77 | G37: 1.8594 | H37: 92.97 | J37: 30.533125 | K37: 977.06 | M37: 10.110182 | N37: 556.06 | P37: 6.017069 | Q37: 348.99 | S37: 0.066315789 | T37: 3.78 | V37: 5.4995745 | W37: 258.48 | Y37: 0 | Z37: 0 | AB37: 8.5468657 | AC37: 572.64 | AE37: 0 | AF37: 0 | AH37: 4.0194118 | AI37: 204.99 | AK37: 3.7194444 | AL37: 267.8 | AN37: 1.8809524 | AO37: 79
A38: =+$C$4&B38 -> Véhicules neufsEntretien stock | B38: Entretien stock | D38: 119.19737 | E38: 80577.42 | G38: 115.9442 | H38: 5797.21 | J38: 268.93781 | K38: 8606.01 | M38: 117.53782 | N38: 6464.58 | P38: 133.99603 | Q38: 7771.77 | S38: 167.94544 | T38: 9572.89 | V38: 168.73936 | W38: 7930.75 | Y38: 43.995185 | Z38: 3563.61 | AB38: 50.172239 | AC38: 3361.54 | AE38: 121.18812 | AF38: 7756.04 | AH38: 94.619412 | AI38: 4825.59 | AK38: 109.28875 | AL38: 7868.79 | AN38: 168.06286 | AO38: 7058.64
A39: =+$C$4&B39 -> Véhicules neufsPublicité 1 | B39: Publicité 1 | D39: 152.67334 | E39: 103207.18 | G39: 91.2874 | H39: 4564.37 | J39: 137.47656 | K39: 4399.25 | M39: 367.98564 | N39: 20239.21 | P39: 245.72724 | Q39: 14252.18 | S39: 171.58053 | T39: 9780.09 | V39: 108.28021 | W39: 5089.17 | Y39: 45.389259 | Z39: 3676.53 | AB39: 86.991045 | AC39: 5828.4 | AE39: 124.21734 | AF39: 7949.91 | AH39: 233.87333 | AI39: 11927.54 | AK39: 53.550417 | AL39: 3855.63 | AN39: 277.25952 | AO39: 11644.9
A40: =+$C$4&B40 -> Véhicules neufsIntérêt de gros | B40: Intérêt de gros | D40: 224.57978 | E40: 151815.93 | G40: 538.3934 | H40: 26919.67 | J40: -353.66 | K40: -11317.12 | M40: 437.246 | N40: 24048.53 | P40: -85.485517 | Q40: -4958.16 | S40: 227.21439 | T40: 12951.22 | V40: 280.19213 | W40: 13169.03 | Y40: 273.39222 | Z40: 22144.77 | AB40: 22.367313 | AC40: 1498.61 | AE40: 37.670469 | AF40: 2410.91 | AH40: 425.86784 | AI40: 21719.26 | AK40: 337.88694 | AL40: 24327.86 | AN40: 450.03214 | AO40: 18901.35
A41: =+$C$4&B41 -> Véhicules neufs[...] | B41: [...]
...

Sheet Capex
A1: PARK AVENUE VOLKSWAGEN | B1: PARK AVENUE VOLKSWAGEN
