Workbook

Sheet Sommaire
B2: Vehicules neuf
B4: Classement | C4: Unite | D4: % unite | E4: Montant | F4: % Montant
B5: 301 & + | C5: =COUNTIF(Neuf!G:G,Sommaire!B5) -> 4 | D5: =C5/$C$12 -> 0.021052632 | E5: =SUMIF(Neuf!G:G,Sommaire!B5,Neuf!C:C) -> 272374.27 | F5: =E5/$E$12 -> 0.033450044
B6: 181-300 | C6: =COUNTIF(Neuf!G:G,Sommaire!B6) -> 28 | D6: =C6/$C$12 -> 0.14736842 | E6: =SUMIF(Neuf!G:G,Sommaire!B6,Neuf!C:C) -> 1338198.9 | F6: =E6/$E$12 -> 0.16434303
B7: 121-180 | C7: =COUNTIF(Neuf!G:G,Sommaire!B7) -> 16 | D7: =C7/$C$12 -> 0.084210526 | E7: =SUMIF(Neuf!G:G,Sommaire!B7,Neuf!C:C) -> 624737.1 | F7: =E7/$E$12 -> 0.076723412
B8: 91-120 | C8: =COUNTIF(Neuf!G:G,Sommaire!B8) -> 12 | D8: =C8/$C$12 -> 0.063157895 | E8: =SUMIF(Neuf!G:G,Sommaire!B8,Neuf!C:C) -> 485613.87 | F8: =E8/$E$12 -> 0.059637811
B9: 61-90 | C9: =COUNTIF(Neuf!G:G,Sommaire!B9) -> 14 | D9: =C9/$C$12 -> 0.073684211 | E9: =SUMIF(Neuf!G:G,Sommaire!B9,Neuf!C:C) -> 584908.93 | F9: =E9/$E$12 -> 0.071832149
B10: 31-60 | C10: =COUNTIF(Neuf!G:G,Sommaire!B10) -> 32 | D10: =C10/$C$12 -> 0.16842105 | E10: =SUMIF(Neuf!G:G,Sommaire!B10,Neuf!C:C) -> 1339745.1 | F10: =E10/$E$12 -> 0.16453291
B11: 0-30 | C11: =COUNTIF(Neuf!G:G,Sommaire!B11) -> 84 | D11: =C11/$C$12 -> 0.44210526 | E11: =SUMIF(Neuf!G:G,Sommaire!B11,Neuf!C:C) -> 3497139.8 | F11: =E11/$E$12 -> 0.42948065
B12: Total | C12: =SUM(C5:C11) -> 190 | D12: =SUM(D5:D11) -> 1 | E12: =SUM(E5:E11) -> 8142717.9 | F12: =SUM(F5:F11) -> 1
B13: Valeur moyenne reel | E13: =E12/C12 -> 42856.41
B15: Budget | C15: =#REF! -> #REF! | D15: =C12/C15 -> #REF! | E15: =#REF! -> #REF! | F15: =E12/E15 -> #REF!
B16: Ecart | C16: =C12-C15 -> #REF! | E16: =E12-E15 -> #REF!
B17: Valeur moyenne budgete | E17: =E15/C15 -> #REF!
B21: Vehicules usages
B23: Classement | C23: Unite | D23: % unite | E23: Montant | F23: % Montant
B24: 301 & + | C24: =COUNTIF(Usages!G:G,Sommaire!B24) -> 3 | D24: =C24/$C$31 -> 0.06 | E24: =SUMIF(Usages!G:G,Sommaire!B24,Usages!C:C) -> 63278.29 | F24: =E24/$E$31 -> 0.058296791
B25: 181-300 | C25: =COUNTIF(Usages!G:G,Sommaire!B25) -> 0 | D25: =C25/$C$31 -> 0 | E25: =SUMIF(Usages!G:G,Sommaire!B25,Usages!C:C) -> 0 | F25: =E25/$E$31 -> 0
B26: 121-180 | C26: =COUNTIF(Usages!G:G,Sommaire!B26) -> 0 | D26: =C26/$C$31 -> 0 | E26: =SUMIF(Usages!G:G,Sommaire!B26,Usages!C:C) -> 0 | F26: =E26/$E$31 -> 0
B27: 91-120 | C27: =COUNTIF(Usages!G:G,Sommaire!B27) -> 2 | D27: =C27/$C$31 -> 0.04 | E27: =SUMIF(Usages!G:G,Sommaire!B27,Usages!C:C) -> 54067.19 | F27: =E27/$E$31 -> 0.049810823
B28: 61-90 | C28: =COUNTIF(Usages!G:G,Sommaire!B28) -> 3 | D28: =C28/$C$31 -> 0.06 | E28: =SUMIF(Usages!G:G,Sommaire!B28,Usages!C:C) -> 57776.87 | F28: =E28/$E$31 -> 0.053228463
B29: 31-60 | C29: =COUNTIF(Usages!G:G,Sommaire!B29) -> 13 | D29: =C29/$C$31 -> 0.26 | E29: =SUMIF(Usages!G:G,Sommaire!B29,Usages!C:C) -> 317063.17 | F29: =E29/$E$31 -> 0.2921028
B30: 0-30 | C30: =COUNTIF(Usages!G:G,Sommaire!B30) -> 29 | D30: =C30/$C$31 -> 0.58 | E30: =SUMIF(Usages!G:G,Sommaire!B30,Usages!C:C) -> 593265.13 | F30: =E30/$E$31 -> 0.54656113
B31: Total | C31: =SUM(C24:C30) -> 50 | D31: =SUM(D24:D30) -> 1 | E31: =SUM(E24:E30) -> 1085450.6 | F31: =E31/$E$31 -> 1
B32: Valeur moyenne reel | E32: =E31/C31 -> 21709.013
O33: Homme de cours
B34: Budget | C34: =#REF! -> #REF! | D34: =C31/C34 -> #REF! | E34: =#REF! -> #REF! | F34: =E31/E34 -> #REF! | O34: Homme de cours
B35: Ecart | C35: =C31-C34 -> #REF! | E35: =E31-E34 -> #REF!
B36: Valeur moyenne budgete | E36: =E34/C34 -> #REF!

Sheet Neuf
A1: #Contrôle | B1: Description | C1: 1402 | D1: 2101 | E1: NIV | F1: Jours en stock | G1: Classement | J1: $ Inventaire | K1: $ Financé
A2: 250187 | B2: 25 VOLKSWAGEN ID.BUZZ | C2: 85586.87 | D2: -88722.9 | E2: WVG6YVEB1SH027640 | F2: 376 | G2: =IFS(F2<31,"0-30",F2<61,"31-60",F2<91,"61-90",F2<121,"91-120",F2<181,"121-180",F2<301,"181-300",F2>300,"301 & +") -> 301 & + | I2: CTRL | J2: =SUM(C:C) -> 8142717.9 | K2: =SUM(D:D) -> -8073099.3
A3: 250228 | B3: 25 VOLKSWAGEN ID.4 | C3: 61456.86 | E3: 1V2JSPE84SC001030 | F3: 349 | G3: =IFS(F3<31,"0-30",F3<61,"31-60",F3<91,"61-90",F3<121,"91-120",F3<181,"121-180",F3<301,"181-300",F3>300,"301 & +") -> 301 & + | I3: # unités | J3: =COUNT(C:C) -> 190 | K3: =-K2/J2 -> 0.9914502
A4: 250281 | B4: 25 VOLKSWAGEN ID.4 | C4: 63600.32 | D4: -65270.1 | E4: 1V29SPE85SC003730 | F4: 307 | G4: =IFS(F4<31,"0-30",F4<61,"31-60",F4<91,"61-90",F4<121,"91-120",F4<181,"121-180",F4<301,"181-300",F4>300,"301 & +") -> 301 & +
A5: 250277 | B5: 25 VOLKSWAGEN ID.4 | C5: 61730.22 | D5: -64778.7 | E5: 1V2ASPE80SC003373 | F5: 307 | G5: =IFS(F5<31,"0-30",F5<61,"31-60",F5<91,"61-90",F5<121,"91-120",F5<181,"121-180",F5<301,"181-300",F5>300,"301 & +") -> 301 & +
A6: 250294 | B6: 25 VOLKSWAGEN JETTA SEDAN | C6: 30839.96 | E6: 3VWEX7BU7SM074572 | F6: 299 | G6: =IFS(F6<31,"0-30",F6<61,"31-60",F6<91,"61-90",F6<121,"91-120",F6<181,"121-180",F6<301,"181-300",F6>300,"301 & +") -> 181-300 | N6: Financé | O6: Interet / mois | P6: Interet / auto
A7: 250301 | B7: 25 VOLKSWAGEN ID.4 | C7: 62928.32 | D7: -66251.85 | E7: 1V29SPE81SC002638 | F7: 295 | G7: =IFS(F7<31,"0-30",F7<61,"31-60",F7<91,"61-90",F7<121,"91-120",F7<181,"121-180",F7<301,"181-300",F7>300,"301 & +") -> 181-300 | I7: Plus de 365 jrs | J7: =COUNTIF(F:F,">=365") -> 1 | K7: =SUMIF(F:F,">=365",C:C) -> 85586.87 | M7: =COUNTIFS(F:F,">=365",D:D,"<>"&"") -> 1 | N7: =SUMIF(F:F,">=365",D:D) -> -88722.9 | O7: =N7*0.07/12 -> -517.55025 | P7: =IF(J7=0,0,O7/J7) -> -517.55025
A8: 250302 | B8: 25 VOLKSWAGEN JETTA SEDAN | C8: 33727.2 | D8: -33332.25 | E8: 3VWGX7BU2SM087917 | F8: 295 | G8: =IFS(F8<31,"0-30",F8<61,"31-60",F8<91,"61-90",F8<121,"91-120",F8<181,"121-180",F8<301,"181-300",F8>300,"301 & +") -> 181-300 | I8: Entre 180 et 364 jours | J8: =COUNTIFS(F:F,"<365",F:F,">=180") -> 33 | K8: =SUMIFS(C:C,F:F,"<365",F:F,">=180") -> 1602534 | M8: =COUNTIFS(F:F,"<365",F:F,">=180",D:D,"<>"&"") -> 31 | N8: =SUMIFS(D:D,F:F,"<365",F:F,">=180") -> -1559211.1 | O8: =N8*0.07/12 -> -9095.3984 | P8: =IF(J8=0,0,O8/J8) -> -275.61813
A9: 250341 | B9: 25 VOLKSWAGEN ID.4 | C9: 62577.9 | D9: -65760.45 | E9: 1V29SPE80SC004168 | F9: 281 | G9: =IFS(F9<31,"0-30",F9<61,"31-60",F9<91,"61-90",F9<121,"91-120",F9<181,"121-180",F9<301,"181-300",F9>300,"301 & +") -> 181-300 | I9: Entre 90 et 179 jours | J9: =COUNTIFS(F:F,"<180",F:F,">=90") -> 26 | K9: =SUMIFS(C:C,F:F,"<180",F:F,">=90") -> 1032803.3 | M9: =COUNTIFS(F:F,"<180",F:F,">=90",D:D,"<>"&"") -> 25 | N9: =SUMIFS(D:D,F:F,"<180",F:F,">=90") -> -1029738.2 | O9: =N9*0.07/12 -> -6006.8059 | P9: =IF(M9=0,0,O9/M9) -> -240.27223
A10: 250350 | B10: 25 VOLKSWAGEN ID.4 | C10: 59277.15 | D10: -60545.1 | E10: 1V2XRPE86SC000287 | F10: 281 | G10: =IFS(F10<31,"0-30",F10<61,"31-60",F10<91,"61-90",F10<121,"91-120",F10<181,"121-180",F10<301,"181-300",F10>300,"301 & +") -> 181-300 | I10: Entre 0 et 89 jours | J10: =COUNTIF(F:F,"<90") -> 130 | K10: =SUMIF(F:F,"<90",C:C) -> 5421793.8 | M10: =COUNTIFS(F:F,"<90",D:D,"<>"&"") -> 123 | N10: =SUMIF(F:F,"<90",D:D) -> -5395427.1 | O10: =N10*0.07/12 -> -31473.325 | P10: =IF(M10=0,0,O10/M10) -> -255.88069
A11: 250361 | B11: 25 VOLKSWAGEN ID.4 | C11: 62373.22 | D11: -65270.1 | E11: 1V29SPE89SC003827 | F11: 279 | G11: =IFS(F11<31,"0-30",F11<61,"31-60",F11<91,"61-90",F11<121,"91-120",F11<181,"121-180",F11<301,"181-300",F11>300,"301 & +") -> 181-300
A12: 250357 | B12: 25 VOLKSWAGEN ID.4 | C12: 62119.22 | D12: -65270.1 | E12: 1V29SPE81SC004731 | F12: 279 | G12: =IFS(F12<31,"0-30",F12<61,"31-60",F12<91,"61-90",F12<121,"91-120",F12<181,"121-180",F12<301,"181-300",F12>300,"301 & +") -> 181-300
A13: 250360 | B13: 25 VOLKSWAGEN ID.4 | C13: 58058.22 | D13: -61035.45 | E13: 1V2XRPE86SC004372 | F13: 279 | G13: =IFS(F13<31,"0-30",F13<61,"31-60",F13<91,"61-90",F13<121,"91-120",F13<181,"121-180",F13<301,"181-300",F13>300,"301 & +") -> 181-300
A14: 250366 | B14: 25 VOLKSWAGEN ID.4 | C14: 67741.99 | D14: -67233.6 | E14: 1V2ASPE80SC004913 | F14: 278 | G14: =IFS(F14<31,"0-30",F14<61,"31-60",F14<91,"61-90",F14<121,"91-120",F14<181,"121-180",F14<301,"181-300",F14>300,"301 & +") -> 181-300
A15: 250377 | B15: 25 VOLKSWAGEN ID.4 | C15: 63054.22 | D15: -66251.85 | E15: 1V29SPE87SC003812 | F15: 277 | G15: =IFS(F15<31,"0-30",F15<61,"31-60",F15<91,"61-90",F15<121,"91-120",F15<181,"121-180",F15<301,"181-300",F15>300,"301 & +") -> 181-300
A16: 250399 | B16: 25 VOLKSWAGEN ID.4 | C16: 62198.22 | D16: -65270.1 | E16: 1V29SPE80SC005255 | F16: 270 | G16: =IFS(F16<31,"0-30",F16<61,"31-60",F16<91,"61-90",F16<121,"91-120",F16<181,"121-180",F16<301,"181-300",F16>300,"301 & +") -> 181-300
A17: 250400 | B17: 25 VOLKSWAGEN ID.4 | C17: 62119.22 | D17: -65270.1 | E17: 1V29SPE80SC004882 | F17: 270 | G17: =IFS(F17<31,"0-30",F17<61,"31-60",F17<91,"61-90",F17<121,"91-120",F17<181,"121-180",F17<301,"181-300",F17>300,"301 & +") -> 181-300
A18: 250397 | B18: 25 VOLKSWAGEN ID.4 | C18: 61730.22 | D18: -64778.7 | E18: 1V29SPE89SC004007 | F18: 270 | G18: =IFS(F18<31,"0-30",F18<61,"31-60",F18<91,"61-90",F18<121,"91-120",F18<181,"121-180",F18<301,"181-300",F18>300,"301 & +") -> 181-300
A19: 250412 | B19: 25 VOLKSWAGEN ID.4 | C19: 58545.9 | D19: -61526.85 | E19: 1V2XRPE84SC004046 | F19: 266 | G19: =IFS(F19<31,"0-30",F19<61,"31-60",F19<91,"61-90",F19<121,"91-120",F19<181,"121-180",F19<301,"181-300",F19>300,"301 & +") -> 181-300
A20: 250429 | B20: 25 VOLKSWAGEN ID.4 | C20: 63054.22 | D20: -66251.85 | E20: 1V29SPE88SC004595 | F20: 264 | G20: =IFS(F20<31,"0-30",F20<61,"31-60",F20<91,"61-90",F20<121,"91-120",F20<181,"121-180",F20<301,"181-300",F20>300,"301 & +") -> 181-300
A21: 250431 | B21: 25 VOLKSWAGEN ID.4 | C21: 63026.22 | D21: -66251.85 | E21: 1V29SPE86SC002697 | F21: 264 | G21: =IFS(F21<31,"0-30",F21<61,"31-60",F21<91,"61-90",F21<121,"91-120",F21<181,"121-180",F21<301,"181-300",F21>300,"301 & +") -> 181-300
A22: 250422 | B22: 25 VOLKSWAGEN JETTA SEDAN | C22: 28609.55 | D22: -28242.9 | E22: 3VWCX7BU6SM096375 | F22: 264 | G22: =IFS(F22<31,"0-30",F22<61,"31-60",F22<91,"61-90",F22<121,"91-120",F22<181,"121-180",F22<301,"181-300",F22>300,"301 & +") -> 181-300
... A35: 260048 | B35: 26 VOLKSWAGEN TAOS | C35: 38045.82 | D35: -39744.6 | E35: 3VV2C7B24TM009052 | F35: 180 | G35: =IFS(F35<31,"0-30",F35<61,"31-60",F35<91,"61-90",F35<121,"91-120",F35<181,"121-180",F35<301,"181-300",F35>300,"301 & +") -> 121-180
A36: 260054 | B36: 26 VOLKSWAGEN TAOS | C36: 37968.87 | E36: 3VV2C7B29TM009564 | F36: 173 | G36: =IFS(F36<31,"0-30",F36<61,"31-60",F36<91,"61-90",F36<121,"91-120",F36<181,"121-180",F36<301,"181-300",F36>300,"301 & +") -> 121-180
A37: 260064 | B37: 26 VOLKSWAGEN TAOS | C37: 34786.68 | D37: -34633.2 | E37: 3VV8C7B2XTM002438 | F37: 168 | G37: =IFS(F37<31,"0-30",F37<61,"31-60",F37<91,"61-90",F37<121,"91-120",F37<181,"121-180",F37<301,"181-300",F37>300,"301 & +") -> 121-180
A38: 260059 | B38: 26 VOLKSWAGEN JETTA SEDAN | C38: 27907.82 | D38: -28977.9 | E38: 3VWCW7BU1TM009499 | F38: 168 | G38: =IFS(F38<31,"0-30",F38<61,"31-60",F38<91,"61-90",F38<121,"91-120",F38<181,"121-180",F38<301,"181-300",F38>300,"301 & +") -> 121-180
A39: 260080 | B39: 26 VOLKSWAGEN TAOS | C39: 39043.82 | D39: -40792.5 | E39: 3VV4C7B2XTM011946 | F39: 161 | G39: =IFS(F39<31,"0-30",F39<61,"31-60",F39<91,"61-90",F39<121,"91-120",F39<181,"121-180",F39<301,"181-300",F39>300,"301 & +") -> 121-180
A40: 260094 | B40: 26 VOLKSWAGEN TIGUAN | C40: 40219.9 | D40: -41778.45 | E40: 3VVER7RM7TM009520 | F40: 160 | G40: =IFS(F40<31,"0-30",F40<61,"31-60",F40<91,"61-90",F40<121,"91-120",F40<181,"121-180",F40<301,"181-300",F40>300,"301 & +") -> 121-180
A41: 260089 | B41: 26 VOLKSWAGEN TAOS | C41: 37582.82 | D41: -39258.45 | E41: 3VV2C7B24TM012663 | F41: 160 | G41: =IFS(F41<31,"0-30",F41<61,"31-60",F41<91,"61-90",F41<121,"91-120",F41<181,"121-180",F41<301,"181-300",F41>300,"301 & +") -> 121-180
A42: 260092 | B42: 26 VOLKSWAGEN TAOS | C42: 37582.82 | D42: -39258.45 | E42: 3VV2C7B2XTM012683 | F42: 160 | G42: =IFS(F42<31,"0-30",F42<61,"31-60",F42<91,"61-90",F42<121,"91-120",F42<181,"121-180",F42<301,"181-300",F42>300,"301 & +") -> 121-180
A43: 260101 | B43: 26 VOLKSWAGEN TAOS | C43: 39043.82 | D43: -40792.5 | E43: 3VV4C7B21TM010734 | F43: 159 | G43: =IFS(F43<31,"0-30",F43<61,"31-60",F43<91,"61-90",F43<121,"91-120",F43<181,"121-180",F43<301,"181-300",F43>300,"301 & +") -> 121-180
A44: 260105 | B44: 26 VOLKSWAGEN TIGUAN | C44: 38299.09 | D44: -38935.05 | E44: 3VVBR7RM7TM008743 | F44: 159 | G44: =IFS(F44<31,"0-30",F44<61,"31-60",F44<91,"61-90",F44<121,"91-120",F44<181,"121-180",F44<301,"181-300",F44>300,"301 & +") -> 121-180
A45: 260099 | B45: 26 VOLKSWAGEN JETTA SEDAN | C45: 28697.22 | D45: -28977.9 | E45: 3VWCW7BU6TM011300 | F45: 159 | G45: =IFS(F45<31,"0-30",F45<61,"31-60",F45<91,"61-90",F45<121,"91-120",F45<181,"121-180",F45<301,"181-300",F45>300,"301 & +") -> 121-180
A46: 260110 | B46: 26 VOLKSWAGEN JETTA SEDAN | C46: 28643.22 | D46: -28977.9 | E46: 3VWCW7BU7TM011449 | F46: 159 | G46: =IFS(F46<31,"0-30",F46<61,"31-60",F46<91,"61-90",F46<121,"91-120",F46<181,"121-180",F46<301,"181-300",F46>300,"301 & +") -> 121-180
A47: 260168 | B47: 25 VOLKSWAGEN ID.BUZZ | C47: 84885.22 | D47: -88722.9 | E47: WVG6YVEB5SH041704 | F47: 145 | G47: =IFS(F47<31,"0-30",F47<61,"31-60",F47<91,"61-90",F47<121,"91-120",F47<181,"121-180",F47<301,"181-300",F47>300,"301 & +") -> 121-180
A48: 260194 | B48: 26 VOLKSWAGEN TIGUAN | C48: 37941.99 | D48: -38935.05 | E48: 3VVBR7RM4TM025189 | F48: 127 | G48: =IFS(F48<31,"0-30",F48<61,"31-60",F48<91,"61-90",F48<121,"91-120",F48<181,"121-180",F48<301,"181-300",F48>300,"301 & +") -> 121-180
... A73: 260340 | B73: 26 VOLKSWAGEN TIGUAN | C73: 39679.82 | D73: -41783.7 | E73: 3VVER7RM4TM053961 | F73: 75 | G73: =IFS(F73<31,"0-30",F73<61,"31-60",F73<91,"61-90",F73<121,"91-120",F73<181,"121-180",F73<301,"181-300",F73>300,"301 & +") -> 61-90
A74: 260343 | B74: 26 VOLKSWAGEN TIGUAN | C74: 44159.27 | E74: 3VVGR7RM8TM052854 | F74: 69 | G74: =IFS(F74<31,"0-30",F74<61,"31-60",F74<91,"61-90",F74<121,"91-120",F74<181,"121-180",F74<301,"181-300",F74>300,"301 & +") -> 61-90
A75: 260349 | B75: 26 VOLKSWAGEN TAOS | C75: 37268.82 | D75: -39263.7 | E75: 3VV2C7B21TM038332 | F75: 61 | G75: =IFS(F75<31,"0-30",F75<61,"31-60",F75<91,"61-90",F75<121,"91-120",F75<181,"121-180",F75<301,"181-300",F75>300,"301 & +") -> 61-90
A76: 260359 | B76: 26 VOLKSWAGEN TAOS | C76: 37268.82 | D76: -39263.7 | E76: 3VV2C7B29TM040393 | F76: 54 | G76: =IFS(F76<31,"0-30",F76<61,"31-60",F76<91,"61-90",F76<121,"91-120",F76<181,"121-180",F76<301,"181-300",F76>300,"301 & +") -> 31-60
...

Sheet Usages
A1: #Contrôle | B1: Description | C1: 1416 | D1: 2103 | E1: NIV | F1: Jours en stock | G1: Classement | J1: $ Inventaire | K1: $ Financé
A2: 5188P | B2: 11 VOLKSWAGEN JETTA SEDAN | C2: 8407.04 | E2: 3VWLL7AJ3BM097101 | F2: 1406 | G2: =IFS(F2<31,"0-30",F2<61,"31-60",F2<91,"61-90",F2<121,"91-120",F2<181,"121-180",F2<301,"181-300",F2>300,"301 & +") -> 301 & + | I2: CTRL | J2: =SUM(C:C) -> 1085450.6 | K2: =SUM(D:D) -> -630898.37
A3: 5291P | B3: 20 VOLKSWAGEN E-GOLF | C3: 20835.53 | E3: WVWPR7AU2LW903993 | F3: 1244 | G3: =IFS(F3<31,"0-30",F3<61,"31-60",F3<91,"61-90",F3<121,"91-120",F3<181,"121-180",F3<301,"181-300",F3>300,"301 & +") -> 301 & + | I3: # unités | J3: =COUNT(C:C) -> 50 | K3: =-K2/J2 -> 0.58123174
A4: 5407P | B4: 19 GMC SAVANA CARGO VA | C4: 34035.72 | E4: 1GTW7BFP1K1340423 | F4: 1061 | G4: =IFS(F4<31,"0-30",F4<61,"31-60",F4<91,"61-90",F4<121,"91-120",F4<181,"121-180",F4<301,"181-300",F4>300,"301 & +") -> 301 & +
A5: 260266A | B5: 19 VOLKSWAGEN JETTA | C5: 10550 | E5: 3VWC57BU1KM057327 | F5: 102 | G5: =IFS(F5<31,"0-30",F5<61,"31-60",F5<91,"61-90",F5<121,"91-120",F5<181,"121-180",F5<301,"181-300",F5>300,"301 & +") -> 91-120
A6: 260227A | B6: 24 VOLKSWAGEN ATLAS CROSS SPO | C6: 43517.19 | D6: -44625 | E6: 1V2FE2CAXRC210319 | F6: 92 | G6: =IFS(F6<31,"0-30",F6<61,"31-60",F6<91,"61-90",F6<121,"91-120",F6<181,"121-180",F6<301,"181-300",F6>300,"301 & +") -> 91-120 | N6: Financé | O6: Interet / mois | P6: Interet / auto
A7: 260067A | B7: 22 VOLKSWAGEN TAOS | C7: 16932.29 | D7: -17528.7 | E7: 3VVAX7B24NM045018 | F7: 77 | G7: =IFS(F7<31,"0-30",F7<61,"31-60",F7<91,"61-90",F7<121,"91-120",F7<181,"121-180",F7<301,"181-300",F7>300,"301 & +") -> 61-90 | I7: Plus de 365 jrs | J7: =COUNTIF(F:F,">=365") -> 3 | K7: =SUMIF(F:F,">=365",C:C) -> 63278.29 | M7: =COUNTIFS(F:F,">=365",D:D,"<>"&"") -> 0 | N7: =SUMIF(F:F,">=365",D:D) -> 0 | O7: =N7*0.07/12 -> 0 | P7: =IF(J7=0,0,O7/J7) -> 0
A8: 5916P | B8: 22 VOLKSWAGEN TAOS | C8: 19432.29 | E8: 3VVLX7B27NM077731 | F8: 68 | G8: =IFS(F8<31,"0-30",F8<61,"31-60",F8<91,"61-90",F8<121,"91-120",F8<181,"121-180",F8<301,"181-300",F8>300,"301 & +") -> 61-90 | I8: Entre 180 et 364 jours | J8: =COUNTIFS(F:F,"<365",F:F,">=180") -> 0 | K8: =SUMIFS(C:C,F:F,"<365",F:F,">=180") -> 0 | M8: =COUNTIFS(F:F,"<365",F:F,">=180",D:D,"<>"&"") -> 0 | N8: =SUMIFS(D:D,F:F,"<365",F:F,">=180") -> 0 | O8: =N8*0.07/12 -> 0 | P8: =IF(J8=0,0,O8/J8) -> 0
A9: 260274A | B9: 22 VOLKSWAGEN TAOS | C9: 21412.29 | E9: 3VV2X7B2XNM074396 | F9: 63 | G9: =IFS(F9<31,"0-30",F9<61,"31-60",F9<91,"61-90",F9<121,"91-120",F9<181,"121-180",F9<301,"181-300",F9>300,"301 & +") -> 61-90 | I9: Entre 90 et 179 jours | J9: =COUNTIFS(F:F,"<180",F:F,">=90") -> 2 | K9: =SUMIFS(C:C,F:F,"<180",F:F,">=90") -> 54067.19 | M9: =COUNTIFS(F:F,"<180",F:F,">=90",D:D,"<>"&"") -> 1 | N9: =SUMIFS(D:D,F:F,"<180",F:F,">=90") -> -44625 | O9: =N9*0.07/12 -> -260.3125 | P9: =IF(M9=0,0,O9/M9) -> -260.3125
A10: 260155A | B10: 24 VOLKSWAGEN TIGUAN | C10: 29432.29 | E10: 3VV8B7AX0RM019399 | F10: 60 | G10: =IFS(F10<31,"0-30",F10<61,"31-60",F10<91,"61-90",F10<121,"91-120",F10<181,"121-180",F10<301,"181-300",F10>300,"301 & +") -> 31-60 | I10: Entre 0 et 89 jours | J10: =COUNTIF(F:F,"<90") -> 45 | K10: =SUMIF(F:F,"<90",C:C) -> 968105.17 | M10: =COUNTIFS(F:F,"<90",D:D,"<>"&"") -> 24 | N10: =SUMIF(F:F,"<90",D:D) -> -586273.37 | O10: =N10*0.07/12 -> -3419.928 | P10: =IF(M10=0,0,O10/M10) -> -142.497
A11: 260249A | B11: 22 VOLKSWAGEN TAOS | C11: 22033.99 | D11: -20549 | E11: 3VV3X7B22NM045639 | F11: 60 | G11: =IFS(F11<31,"0-30",F11<61,"31-60",F11<91,"61-90",F11<121,"91-120",F11<181,"121-180",F11<301,"181-300",F11>300,"301 & +") -> 31-60
A12: 260344A | B12: 22 VOLKSWAGEN TIGUAN | C12: 26522.19 | D12: -24927.02 | E12: 3VV4B7AX3NM143448 | F12: 54 | G12: =IFS(F12<31,"0-30",F12<61,"31-60",F12<91,"61-90",F12<121,"91-120",F12<181,"121-180",F12<301,"181-300",F12>300,"301 & +") -> 31-60
A13: 5921P | B13: 22 VOLKSWAGEN TAOS | C13: 19117.48 | D13: -19985.19 | E13: 3VVLX7B2XNM070191 | F13: 54 | G13: =IFS(F13<31,"0-30",F13<61,"31-60",F13<91,"61-90",F13<121,"91-120",F13<181,"121-180",F13<301,"181-300",F13>300,"301 & +") -> 31-60
A14: 260339A | B14: 24 VOLKSWAGEN GOLF GTI | C14: 36407.24 | D14: -36875 | E14: WVWWA7CD7RW232734 | F14: 53 | G14: =IFS(F14<31,"0-30",F14<61,"31-60",F14<91,"61-90",F14<121,"91-120",F14<181,"121-180",F14<301,"181-300",F14>300,"301 & +") -> 31-60
A15: 5923P | B15: 23 VOLKSWAGEN TAOS | C15: 26776.29 | D15: -22899.6 | E15: 3VV2X7B2XPM335318 | F15: 49 | G15: =IFS(F15<31,"0-30",F15<61,"31-60",F15<91,"61-90",F15<121,"91-120",F15<181,"121-180",F15<301,"181-300",F15>300,"301 & +") -> 31-60
A16: 260123A | B16: 22 VOLKSWAGEN TAOS | C16: 17150 | D16: -17473.05 | E16: 3VVAX7B26NM043965 | F16: 46 | G16: =IFS(F16<31,"0-30",F16<61,"31-60",F16<91,"61-90",F16<121,"91-120",F16<181,"121-180",F16<301,"181-300",F16>300,"301 & +") -> 31-60
A17: 5925P | B17: 22 VOLKSWAGEN ATLAS | C17: 27857.29 | D17: -24629.85 | E17: 1V2BP2CA8NC519029 | F17: 42 | G17: =IFS(F17<31,"0-30",F17<61,"31-60",F17<91,"61-90",F17<121,"91-120",F17<181,"121-180",F17<301,"181-300",F17>300,"301 & +") -> 31-60
A18: 5926P | B18: 22 VOLKSWAGEN TIGUAN | C18: 24357.29 | D18: -22131 | E18: 3VV4B7AX4NM052527 | F18: 41 | G18: =IFS(F18<31,"0-30",F18<61,"31-60",F18<91,"61-90",F18<121,"91-120",F18<181,"121-180",F18<301,"181-300",F18>300,"301 & +") -> 31-60
A19: 260400A | B19: 22 VOLKSWAGEN ATLAS | C19: 27332.29 | D19: -24580.1 | E19: 1V2LR2CA1NC546457 | F19: 34 | G19: =IFS(F19<31,"0-30",F19<61,"31-60",F19<91,"61-90",F19<121,"91-120",F19<181,"121-180",F19<301,"181-300",F19>300,"301 & +") -> 31-60
A20: 260367A | B20: 23 VOLKSWAGEN TAOS | C20: 20332.29 | E20: 3VVNX7B24PM333190 | F20: 34 | G20: =IFS(F20<31,"0-30",F20<61,"31-60",F20<91,"61-90",F20<121,"91-120",F20<181,"121-180",F20<301,"181-300",F20>300,"301 & +") -> 31-60
A21: 260371A | B21: 22 VOLKSWAGEN TIGUAN | C21: 22332.29 | D21: -19852 | E21: 3VV2B7AXXNM073812 | F21: 33 | G21: =IFS(F21<31,"0-30",F21<61,"31-60",F21<91,"61-90",F21<121,"91-120",F21<181,"121-180",F21<301,"181-300",F21>300,"301 & +") -> 31-60
A22: 260076B | B22: 20 VOLKSWAGEN GOLF | C22: 17412.24 | E22: 3VWG57AU7LM007441 | F22: 32 | G22: =IFS(F22<31,"0-30",F22<61,"31-60",F22<91,"61-90",F22<121,"91-120",F22<181,"121-180",F22<301,"181-300",F22>300,"301 & +") -> 31-60
A23: 5928P | B23: 22 VOLKSWAGEN ATLAS | C23: 27031.29 | D23: -25189 | E23: 1V2BR2CA7NC524006 | F23: 28 | G23: =IFS(F23<31,"0-30",F23<61,"31-60",F23<91,"61-90",F23<121,"91-120",F23<181,"121-180",F23<301,"181-300",F23>300,"301 & +") -> 0-30
A24: 5929P | B24: 23 VOLKSWAGEN ATLAS CROSS SPO | C24: 31450.34 | D24: -36846.85 | E24: 1V2SE2CA6PC205971 | F24: 27 | G24: =IFS(F24<31,"0-30",F24<61,"31-60",F24<91,"61-90",F24<121,"91-120",F24<181,"121-180",F24<301,"181-300",F24>300,"301 & +") -> 0-30
A25: 260235A | B25: 21 VOLKSWAGEN JETTA | C25: 15332.29 | D25: -11778.79 | E25: 3VWE57BU5MM036962 | F25: 25 | G25: =IFS(F25<31,"0-30",F25<61,"31-60",F25<91,"61-90",F25<121,"91-120",F25<181,"121-180",F25<301,"181-300",F25>300,"301 & +") -> 0-30
A26: 260363A | B26: 24 VOLKSWAGEN ATLAS | C26: 43425.59 | D26: -45484.42 | E26: 1V2FR2CA5RC522746 | F26: 22 | G26: =IFS(F26<31,"0-30",F26<61,"31-60",F26<91,"61-90",F26<121,"91-120",F26<181,"121-180",F26<301,"181-300",F26>300,"301 & +") -> 0-30
A27: 260431A | B27: 22 VOLKSWAGEN ATLAS | C27: 35320.69 | E27: 1V2FR2CA1NC542986 | F27: 22 | G27: =IFS(F27<31,"0-30",F27<61,"31-60",F27<91,"61-90",F27<121,"91-120",F27<181,"121-180",F27<301,"181-300",F27>300,"301 & +") -> 0-30
A28: 260404A | B28: 22 VOLKSWAGEN ATLAS | C28: 31177.59 | D28: -28614.25 | E28: 1V2BR2CA7NC553103 | F28: 22 | G28: =IFS(F28<31,"0-30",F28<61,"31-60",F28<91,"61-90",F28<121,"91-120",F28<181,"121-180",F28<301,"181-300",F28>300,"301 & +") -> 0-30
A29: 260414A | B29: 22 VOLKSWAGEN TAOS | C29: 21632.29 | D29: -21594.66 | E29: 3VV2X7B28NM078172 | F29: 21 | G29: =IFS(F29<31,"0-30",F29<61,"31-60",F29<91,"61-90",F29<121,"91-120",F29<181,"121-180",F29<301,"181-300",F29>300,"301 & +") -> 0-30
A30: 260397A | B30: 18 MERCEDES LIGHT TRUCK GLC | C30: 23152.38 | E30: WDC0G4KB8JV111587 | F30: 19 | G30: =IFS(F30<31,"0-30",F30<61,"31-60",F30<91,"61-90",F30<121,"91-120",F30<181,"121-180",F30<301,"181-300",F30>300,"301 & +") -> 0-30
A31: 5934P | B31: 22 VOLKSWAGEN TIGUAN | C31: 22218.24 | D31: -20754 | E31: 3VV8B7AX0NM067821 | F31: 14 | G31: =IFS(F31<31,"0-30",F31<61,"31-60",F31<91,"61-90",F31<121,"91-120",F31<181,"121-180",F31<301,"181-300",F31>300,"301 & +") -> 0-30
A32: 5933P | B32: 21 VOLKSWAGEN ATLAS | C32: 21650 | D32: -21200 | E32: 1V2FR2CA4MC545959 | F32: 14 | G32: =IFS(F32<31,"0-30",F32<61,"31-60",F32<91,"61-90",F32<121,"91-120",F32<181,"121-180",F32<301,"181-300",F32>300,"301 & +") -> 0-30
A33: 5935P | B33: 22 VOLKSWAGEN GOLF R | C33: 36950 | D33: -29343 | E33: WVWEB7CD9NW160664 | F33: 13 | G33: =IFS(F33<31,"0-30",F33<61,"31-60",F33<91,"61-90",F33<121,"91-120",F33<181,"121-180",F33<301,"181-300",F33>300,"301 & +") -> 0-30
A34: 260358A | B34: 21 VOLKSWAGEN TIGUAN | C34: 16649.85 | E34: 3VV2B7AX1MM129019 | F34: 12 | G34: =IFS(F34<31,"0-30",F34<61,"31-60",F34<91,"61-90",F34<121,"91-120",F34<181,"121-180",F34<301,"181-300",F34>300,"301 & +") -> 0-30
A35: 260477A | B35: 22 VOLKSWAGEN TIGUAN | C35: 26334.29 | D35: -24063 | E35: 3VV4B7AXXNM096385 | F35: 11 | G35: =IFS(F35<31,"0-30",F35<61,"31-60",F35<91,"61-90",F35<121,"91-120",F35<181,"121-180",F35<301,"181-300",F35>300,"301 & +") -> 0-30
A36: 260217A | B36: 22 VOLKSWAGEN TAOS | C36: 22584.29 | D36: -20518 | E36: 3VV3X7B26NM065182 | F36: 11 | G36: =IFS(F36<31,"0-30",F36<61,"31-60",F36<91,"61-90",F36<121,"91-120",F36<181,"121-180",F36<301,"181-300",F36>300,"301 & +") -> 0-30
A37: 5938P | B37: 21 VOLKSWAGEN ATLAS CROSS SPO | C37: 24150.55 | E37: 1V2BC2CAXMC221804 | F37: 8 | G37: =IFS(F37<31,"0-30",F37<61,"31-60",F37<91,"61-90",F37<121,"91-120",F37<181,"121-180",F37<301,"181-300",F37>300,"301 & +") -> 0-30
A38: 260452A | B38: 24 VOLKSWAGEN TIGUAN | C38: 26656.16 | D38: -30109.89 | E38: 3VVMB7AX5RM088409 | F38: 7 | G38: =IFS(F38<31,"0-30",F38<61,"31-60",F38<91,"61-90",F38<121,"91-120",F38<181,"121-180",F38<301,"181-300",F38>300,"301 & +") -> 0-30
A39: 260476A | B39: 23 VOLKSWAGEN TAOS | C39: 16950 | E39: 3VVAX7B22PM330481 | F39: 6 | G39: =IFS(F39<31,"0-30",F39<61,"31-60",F39<91,"61-90",F39<121,"91-120",F39<181,"121-180",F39<301,"181-300",F39>300,"301 & +") -> 0-30
A40: 260463A | B40: 22 VOLKSWAGEN TIGUAN | C40: 20834.29 | D40: -19347 | E40: 3VV2B7AX4NM053314 | F40: 5 | G40: =IFS(F40<31,"0-30",F40<61,"31-60",F40<91,"61-90",F40<121,"91-120",F40<181,"121-180",F40<301,"181-300",F40>300,"301 & +") -> 0-30
...
