Workbook
Name _Dates_Conc: [1]Dealers!$BF$37:$KA$63
Name _scen: '[1]Scen & Sens'!$E$26
Name _scen1: '[1]Scen & Sens'!$E$27
Name _scen2: '[1]Scen & Sens'!$E$28
Name _SCenarios: '[1]Scen & Sens'!$J$26:$O$26
Name _Sens1: '[1]Scen & Sens'!$F$9
Name _Sens2: '[1]Scen & Sens'!$F$10
Name _sensRes1: '[1]Scen & Sens'!$E$15
Name _sensRes2: '[1]Scen & Sens'!$E$16
Name _sensRes3: '[1]Scen & Sens'!$E$17
Name _sensRes4: '[1]Scen & Sens'!$E$18
Name _sensRes5: '[1]Scen & Sens'!$E$19
Name _sensRes6: '[1]Scen & Sens'!$E$20
Name _sensRes7: '[1]Scen & Sens'!$E$21
Name DateRange: [1]Volkswagen!$BF$6:$DY$6
Name Monetary_Unit: [1]Parameters!$B$15
Name Months: [1]Parameters!$E$9:$E$20
Name Rng_Dealers_Names: [1]!Tbl_Dealers[Dealer Name]
Name Rng_Dlr_Dates: [1]!Tbl_V_Dlr_Dates[Date]
Name Titre: [1]Front!$A$9

Sheet Parametres
A1: Compagnie | B1: Volks
G2: 1-Mémo | M2: Mois | N2: YTD
A3: Mois Courant | B3: Novembre | C3: =+VLOOKUP(B3,$K$3:$L$14,2,0) -> 11 | G3: 10-Compte compteur | K3: Janvier | L3: 1 | M3: =+IF($K3=$B$3,"X","") | N3: =+IF(K3=B3,"X",IF(L3<=$C$3,"X","")) -> X
A4: Année | B4: 2022 | K4: Février | L4: 2 | M4: =+IF($K4=$B$3,"X","") | N4: =+IF(K4=B4,"X",IF(L4<=$C$3,"X","")) -> X
K5: Mars | L5: 3 | M5: =+IF($K5=$B$3,"X","") | N5: =+IF(K5=B5,"X",IF(L5<=$C$3,"X","")) -> X
K6: Avril | L6: 4 | M6: =+IF($K6=$B$3,"X","") | N6: =+IF(K6=B6,"X",IF(L6<=$C$3,"X","")) -> X
K7: Mai | L7: 5 | M7: =+IF($K7=$B$3,"X","") | N7: =+IF(K7=B7,"X",IF(L7<=$C$3,"X","")) -> X
K8: Juin | L8: 6 | M8: =+IF($K8=$B$3,"X","") | N8: =+IF(K8=B8,"X",IF(L8<=$C$3,"X","")) -> X
A9: Sélectionner le mois en B3 | K9: Juillet | L9: 7 | M9: =+IF($K9=$B$3,"X","") | N9: =+IF(K9=B9,"X",IF(L9<=$C$3,"X","")) -> X
A10: Coller les balances de vérification respectives en cellule A1 dans les onglets BV_Data_An_Cour et BV_Data_An_Prec | K10: Août | L10: 8 | M10: =+IF($K10=$B$3,"X","") | N10: =+IF(K10=B10,"X",IF(L10<=$C$3,"X","")) -> X
A11: Vérifier s'il y a des #N/A dans les colonnes T à X des onlgets de BV | K11: Septembre | L11: 9 | M11: =+IF($K11=$B$3,"X","") | N11: =+IF(K11=B11,"X",IF(L11<=$C$3,"X","")) -> X
A12: Vérifier les chiffres avec l'état financier et les réalisés an passé pour les résultat net mois et aad | K12: Octobre | L12: 10 | M12: =+IF($K12=$B$3,"X","") | N12: =+IF(K12=B12,"X",IF(L12<=$C$3,"X","")) -> X
K13: Novembre | L13: 11 | M13: =+IF($K13=$B$3,"X","") -> X | N13: =+IF(K13=B13,"X",IF(L13<=$C$3,"X","")) -> X
K14: Décembre | L14: 12 | M14: =+IF($K14=$B$3,"X","") | N14: =+IF(K14=B14,"X",IF(L14<=$C$3,"X",""))

Sheet Bilan
A1: BILAN
A2: =+Parametres!B1 -> Volks
A3: =CONCATENATE("",,Parametres!B3," ",Parametres!B4) -> Novembre 2022
A5: Encaisse | B5: =SUMIFS(BV_Data_An_Cour!$Q:$Q,BV_Data_An_Cour!$V:$V,$A$1,BV_Data_An_Cour!$W:$W,$A5) -> 0 | D5: Marge de crédit | E5: =-SUMIFS(BV_Data_An_Cour!$Q:$Q,BV_Data_An_Cour!$V:$V,$A$1,BV_Data_An_Cour!$W:$W,$D5) -> 0
A6: Total Trésorerie et équivalent de Trésorerie | B6: =SUM(B5) -> 0
D7: Portion Court Terme de la Dette Long Terme | E7: =-SUMIFS(BV_Data_An_Cour!$Q:$Q,BV_Data_An_Cour!$V:$V,$A$1,BV_Data_An_Cour!$W:$W,$D7) -> 0
A8: Recevables Contrats en Transit | B8: =SUMIFS(BV_Data_An_Cour!$Q:$Q,BV_Data_An_Cour!$V:$V,$A$1,BV_Data_An_Cour!$W:$W,$A8) -> 0
A9: Recevables Véhicules | B9: =SUMIFS(BV_Data_An_Cour!$Q:$Q,BV_Data_An_Cour!$V:$V,$A$1,BV_Data_An_Cour!$W:$W,$A9) -> 0 | D9: Avances à payer | E9: =-SUMIFS(BV_Data_An_Cour!$Q:$Q,BV_Data_An_Cour!$V:$V,$A$1,BV_Data_An_Cour!$W:$W,$D9) -> 0
A10: Recevables Manufacturier | B10: =SUMIFS(BV_Data_An_Cour!$Q:$Q,BV_Data_An_Cour!$V:$V,$A$1,BV_Data_An_Cour!$W:$W,$A10) -> 0 | D10: Comptes à Payer Fournisseurs | E10: =-SUMIFS(BV_Data_An_Cour!$Q:$Q,BV_Data_An_Cour!$V:$V,$A$1,BV_Data_An_Cour!$W:$W,$D10) -> 0
A11: Recevables Pièces et Service | B11: =SUMIFS(BV_Data_An_Cour!$Q:$Q,BV_Data_An_Cour!$V:$V,$A$1,BV_Data_An_Cour!$W:$W,$A11) -> 0 | D11: Taxes de Vente à Payer | E11: =-SUMIFS(BV_Data_An_Cour!$Q:$Q,BV_Data_An_Cour!$V:$V,$A$1,BV_Data_An_Cour!$W:$W,$D11) -> 0
A12: Recevables Garantie Manufacturier | B12: =SUMIFS(BV_Data_An_Cour!$Q:$Q,BV_Data_An_Cour!$V:$V,$A$1,BV_Data_An_Cour!$W:$W,$A12) -> 0 | D12: Impôts à payer | E12: =-SUMIFS(BV_Data_An_Cour!$Q:$Q,BV_Data_An_Cour!$V:$V,$A$1,BV_Data_An_Cour!$W:$W,$D12) -> 0
A13: Recevables Carrosserie | B13: =SUMIFS(BV_Data_An_Cour!$Q:$Q,BV_Data_An_Cour!$V:$V,$A$1,BV_Data_An_Cour!$W:$W,$A13) -> 0 | D13: Dépôts de Client | E13: =-SUMIFS(BV_Data_An_Cour!$Q:$Q,BV_Data_An_Cour!$V:$V,$A$1,BV_Data_An_Cour!$W:$W,$D13) -> 0
A14: Recevables Intercos | B14: =SUMIFS(BV_Data_An_Cour!$Q:$Q,BV_Data_An_Cour!$V:$V,$A$1,BV_Data_An_Cour!$W:$W,$A14) -> 0 | D14: Payables Intercos | E14: =-SUMIFS(BV_Data_An_Cour!$Q:$Q,BV_Data_An_Cour!$V:$V,$A$1,BV_Data_An_Cour!$W:$W,$D14) -> 0
A15: Recevables Autres | B15: =SUMIFS(BV_Data_An_Cour!$Q:$Q,BV_Data_An_Cour!$V:$V,$A$1,BV_Data_An_Cour!$W:$W,$A15) -> 0 | D15: Autres Comptes à Payer | E15: =-SUMIFS(BV_Data_An_Cour!$Q:$Q,BV_Data_An_Cour!$V:$V,$A$1,BV_Data_An_Cour!$W:$W,$D15) -> 0
A16: Total Comptes à Recevoir | B16: =+SUM(B8:B15) -> 0 | D16: Total Comptes à Payer | E16: =+SUM(E10:E15) -> 0
A18: Inventaire Véhicules Neufs | B18: =SUMIFS(BV_Data_An_Cour!$Q:$Q,BV_Data_An_Cour!$V:$V,$A$1,BV_Data_An_Cour!$W:$W,$A18) -> 0 | D18: Effet à Payer Véhicules Neufs | E18: =-SUMIFS(BV_Data_An_Cour!$Q:$Q,BV_Data_An_Cour!$V:$V,$A$1,BV_Data_An_Cour!$W:$W,$D18) -> 0
A19: Inventaire Véhicules Usagés | B19: =SUMIFS(BV_Data_An_Cour!$Q:$Q,BV_Data_An_Cour!$V:$V,$A$1,BV_Data_An_Cour!$W:$W,$A19) -> 0 | D19: Effet à Payer Véhicules Usagés | E19: =-SUMIFS(BV_Data_An_Cour!$Q:$Q,BV_Data_An_Cour!$V:$V,$A$1,BV_Data_An_Cour!$W:$W,$D19) -> 0
A20: Inventaire Pièces, Pneus, Huile | B20: =SUMIFS(BV_Data_An_Cour!$Q:$Q,BV_Data_An_Cour!$V:$V,$A$1,BV_Data_An_Cour!$W:$W,$A20) -> 0 | D20: Total Effets à Payer | E20: =+SUM(E18:E19) -> 0
A21: Total Inventaires | B21: =SUM(B18:B20) -> 0
D22: Salaires à Payer | E22: =-SUMIFS(BV_Data_An_Cour!$Q:$Q,BV_Data_An_Cour!$V:$V,$A$1,BV_Data_An_Cour!$W:$W,$D22) -> 0
A23: Avances à recevoir | B23: =SUMIFS(BV_Data_An_Cour!$Q:$Q,BV_Data_An_Cour!$V:$V,$A$1,BV_Data_An_Cour!$W:$W,$A23) -> 0 | D23: DAS à Payer | E23: =-SUMIFS(BV_Data_An_Cour!$Q:$Q,BV_Data_An_Cour!$V:$V,$A$1,BV_Data_An_Cour!$W:$W,$D23) -> 0
A24: Travaux en Cours | B24: =SUMIFS(BV_Data_An_Cour!$Q:$Q,BV_Data_An_Cour!$V:$V,$A$1,BV_Data_An_Cour!$W:$W,$A24) -> 0 | D24: Autres Courus | E24: =-SUMIFS(BV_Data_An_Cour!$Q:$Q,BV_Data_An_Cour!$V:$V,$A$1,BV_Data_An_Cour!$W:$W,$D24) -> 0
A25: Sous-Traitance | B25: =SUMIFS(BV_Data_An_Cour!$Q:$Q,BV_Data_An_Cour!$V:$V,$A$1,BV_Data_An_Cour!$W:$W,$A25) -> 0 | D25: [...] | E25: =-SUMIFS(BV_Data_An_Cour!$Q:$Q,BV_Data_An_Cour!$V:$V,$A$1,BV_Data_An_Cour!$W:$W,$D25) -> 0
A26: Frais Payés d'Avance | B26: =SUMIFS(BV_Data_An_Cour!$Q:$Q,BV_Data_An_Cour!$V:$V,$A$1,BV_Data_An_Cour!$W:$W,$A26) -> 0 | D26: [...] | E26: =-SUMIFS(BV_Data_An_Cour!$Q:$Q,BV_Data_An_Cour!$V:$V,$A$1,BV_Data_An_Cour!$W:$W,$D26) -> 0
A27: [...] | B27: =SUMIFS(BV_Data_An_Cour!$Q:$Q,BV_Data_An_Cour!$V:$V,$A$1,BV_Data_An_Cour!$W:$W,$A27) -> 0 | D27: [...] | E27: =-SUMIFS(BV_Data_An_Cour!$Q:$Q,BV_Data_An_Cour!$V:$V,$A$1,BV_Data_An_Cour!$W:$W,$D27) -> 0
A28: [...] | B28: =SUMIFS(BV_Data_An_Cour!$Q:$Q,BV_Data_An_Cour!$V:$V,$A$1,BV_Data_An_Cour!$W:$W,$A28) -> 0 | D28: Total Frais Courus | E28: =SUM(E22:E24) -> 0
A29: [...] | B29: =SUMIFS(BV_Data_An_Cour!$Q:$Q,BV_Data_An_Cour!$V:$V,$A$1,BV_Data_An_Cour!$W:$W,$A29) -> 0
A30: Total Autres | B30: =SUM(B23:B29) -> 0 | D30: Total Passif Court Terme | E30: =+E5+E7+E16+E20+E28 -> 0
A32: Total Actif Court Terme | B32: =+B6+B16+B21+B30 -> 0
D33: Impôts Futurs à payer | E33: =-SUMIFS(BV_Data_An_Cour!$Q:$Q,BV_Data_An_Cour!$V:$V,$A$1,BV_Data_An_Cour!$W:$W,$D33) -> 0
A35: Terrain | B35: =SUMIFS(BV_Data_An_Cour!$Q:$Q,BV_Data_An_Cour!$V:$V,$A$1,BV_Data_An_Cour!$W:$W,$A35) -> 0 | D35: Avances Long Terme à Payer | E35: =-SUMIFS(BV_Data_An_Cour!$Q:$Q,BV_Data_An_Cour!$V:$V,$A$1,BV_Data_An_Cour!$W:$W,$D35) -> 0
A36: Bâtisse | B36: =SUMIFS(BV_Data_An_Cour!$Q:$Q,BV_Data_An_Cour!$V:$V,$A$1,BV_Data_An_Cour!$W:$W,$A36) -> 0 | D36: Hypothèque à Payer | E36: =-SUMIFS(BV_Data_An_Cour!$Q:$Q,BV_Data_An_Cour!$V:$V,$A$1,BV_Data_An_Cour!$W:$W,$D36) -> 0
A37: Améliorations Locatives | B37: =SUMIFS(BV_Data_An_Cour!$Q:$Q,BV_Data_An_Cour!$V:$V,$A$1,BV_Data_An_Cour!$W:$W,$A37) -> 0 | D37: Dette à Long Terme | E37: =-SUMIFS(BV_Data_An_Cour!$Q:$Q,BV_Data_An_Cour!$V:$V,$A$1,BV_Data_An_Cour!$W:$W,$D37) -> 0
A38: Améliorations Locatives Permanentes | B38: =SUMIFS(BV_Data_An_Cour!$Q:$Q,BV_Data_An_Cour!$V:$V,$A$1,BV_Data_An_Cour!$W:$W,$A38) -> 0 | D38: Autres Dettes à Long Terme | E38: =-SUMIFS(BV_Data_An_Cour!$Q:$Q,BV_Data_An_Cour!$V:$V,$A$1,BV_Data_An_Cour!$W:$W,$D38) -> 0
A39: Équipements Service | B39: =SUMIFS(BV_Data_An_Cour!$Q:$Q,BV_Data_An_Cour!$V:$V,$A$1,BV_Data_An_Cour!$W:$W,$A39) -> 0 | D39: [...] | E39: =-SUMIFS(BV_Data_An_Cour!$Q:$Q,BV_Data_An_Cour!$V:$V,$A$1,BV_Data_An_Cour!$W:$W,$D39) -> 0
A40: Mobilier | B40: =SUMIFS(BV_Data_An_Cour!$Q:$Q,BV_Data_An_Cour!$V:$V,$A$1,BV_Data_An_Cour!$W:$W,$A40) -> 0 | D40: [...] | E40: =-SUMIFS(BV_Data_An_Cour!$Q:$Q,BV_Data_An_Cour!$V:$V,$A$1,BV_Data_An_Cour!$W:$W,$D40) -> 0
A41: Équipements Informatique | B41: =SUMIFS(BV_Data_An_Cour!$Q:$Q,BV_Data_An_Cour!$V:$V,$A$1,BV_Data_An_Cour!$W:$W,$A41) -> 0 | D41: [...] | E41: =-SUMIFS(BV_Data_An_Cour!$Q:$Q,BV_Data_An_Cour!$V:$V,$A$1,BV_Data_An_Cour!$W:$W,$D41) -> 0
A42: Équipements Téléphonique | B42: =SUMIFS(BV_Data_An_Cour!$Q:$Q,BV_Data_An_Cour!$V:$V,$A$1,BV_Data_An_Cour!$W:$W,$A42) -> 0 | D42: Total Passif long terme | E42: =+SUM(E33:E38) -> 0
A43: Enseigne | B43: =SUMIFS(BV_Data_An_Cour!$Q:$Q,BV_Data_An_Cour!$V:$V,$A$1,BV_Data_An_Cour!$W:$W,$A43) -> 0
A44: Total Immobilisations Nettes | B44: =SUM(B35:B43) -> 0
...

Sheet Budget original
B1: ="Budget 2022 Mensuel Révisé"&" "&Parametres!$B$1 -> Budget 2022 Mensuel Révisé Volks
B2: Mois | F2: =+IF(Parametres!$B$3=F$6,"X","") | G2: =+IF(Parametres!$B$3=F$6,"O","") | H2: =+IF(Parametres!$B$3=F$6,"U","") | I2: =+IF(Parametres!$B$3=I$6,"X","") | J2: =+IF(Parametres!$B$3=I$6,"O","") | K2: =+IF(Parametres!$B$3=I$6,"U","") | L2: =+IF(Parametres!$B$3=L$6,"X","") | M2: =+IF(Parametres!$B$3=L$6,"O","") | N2: =+IF(Parametres!$B$3=L$6,"U","") | O2: =+IF(Parametres!$B$3=O$6,"X","") | P2: =+IF(Parametres!$B$3=O$6,"O","") | Q2: =+IF(Parametres!$B$3=O$6,"U","") | R2: =+IF(Parametres!$B$3=R$6,"X","") | S2: =+IF(Parametres!$B$3=R$6,"O","") | T2: =+IF(Parametres!$B$3=R$6,"U","") | U2: =+IF(Parametres!$B$3=U$6,"X","") | V2: =+IF(Parametres!$B$3=U$6,"O","") | W2: =+IF(Parametres!$B$3=U$6,"U","") | X2: =+IF(Parametres!$B$3=X$6,"X","") | Y2: =+IF(Parametres!$B$3=X$6,"O","") | Z2: =+IF(Parametres!$B$3=X$6,"U","") | AA2: =+IF(Parametres!$B$3=AA$6,"X","") | AB2: =+IF(Parametres!$B$3=AA$6,"O","") | AC2: =+IF(Parametres!$B$3=AA$6,"U","") | AD2: =+IF(Parametres!$B$3=AD$6,"X","") | AE2: =+IF(Parametres!$B$3=AD$6,"O","") | AF2: =+IF(Parametres!$B$3=AD$6,"U","") | AG2: =+IF(Parametres!$B$3=AG$6,"X","") | AH2: =+IF(Parametres!$B$3=AG$6,"O","") | AI2: =+IF(Parametres!$B$3=AG$6,"U","") | AJ2: =+IF(Parametres!$B$3=AJ$6,"X","") -> X | AK2: =+IF(Parametres!$B$3=AJ$6,"O","") -> O | AL2: =+IF(Parametres!$B$3=AJ$6,"U","") -> U | AM2: =+IF(Parametres!$B$3=AM$6,"X","") | AN2: =+IF(Parametres!$B$3=AM$6,"O","") | AO2: =+IF(Parametres!$B$3=AM$6,"U","")
B3: YTD | F3: =+IF(VLOOKUP(F$6,Parametres!$K$3:$N$14,4,0)="X","X","") -> X | G3: =+IF(VLOOKUP(F$6,Parametres!$K$3:$N$14,4,0)="X","O","") -> O | H3: =+IF(VLOOKUP(F$6,Parametres!$K$3:$N$14,4,0)="X","U","") -> U | I3: =+IF(VLOOKUP(I$6,Parametres!$K$3:$N$14,4,0)="X","X","") -> X | J3: =+IF(VLOOKUP(I$6,Parametres!$K$3:$N$14,4,0)="X","O","") -> O | K3: =+IF(VLOOKUP(I$6,Parametres!$K$3:$N$14,4,0)="X","U","") -> U | L3: =+IF(VLOOKUP(L$6,Parametres!$K$3:$N$14,4,0)="X","X","") -> X | M3: =+IF(VLOOKUP(L$6,Parametres!$K$3:$N$14,4,0)="X","O","") -> O | N3: =+IF(VLOOKUP(L$6,Parametres!$K$3:$N$14,4,0)="X","U","") -> U | O3: =+IF(VLOOKUP(O$6,Parametres!$K$3:$N$14,4,0)="X","X","") -> X | P3: =+IF(VLOOKUP(O$6,Parametres!$K$3:$N$14,4,0)="X","O","") -> O | Q3: =+IF(VLOOKUP(O$6,Parametres!$K$3:$N$14,4,0)="X","U","") -> U | R3: =+IF(VLOOKUP(R$6,Parametres!$K$3:$N$14,4,0)="X","X","") -> X | S3: =+IF(VLOOKUP(R$6,Parametres!$K$3:$N$14,4,0)="X","O","") -> O | T3: =+IF(VLOOKUP(R$6,Parametres!$K$3:$N$14,4,0)="X","U","") -> U | U3: =+IF(VLOOKUP(U$6,Parametres!$K$3:$N$14,4,0)="X","X","") -> X | V3: =+IF(VLOOKUP(U$6,Parametres!$K$3:$N$14,4,0)="X","O","") -> O | W3: =+IF(VLOOKUP(U$6,Parametres!$K$3:$N$14,4,0)="X","U","") -> U | X3: =+IF(VLOOKUP(X$6,Parametres!$K$3:$N$14,4,0)="X","X","") -> X | Y3: =+IF(VLOOKUP(X$6,Parametres!$K$3:$N$14,4,0)="X","O","") -> O | Z3: =+IF(VLOOKUP(X$6,Parametres!$K$3:$N$14,4,0)="X","U","") -> U | AA3: =+IF(VLOOKUP(AA$6,Parametres!$K$3:$N$14,4,0)="X","X","") -> X | AB3: =+IF(VLOOKUP(AA$6,Parametres!$K$3:$N$14,4,0)="X","O","") -> O | AC3: =+IF(VLOOKUP(AA$6,Parametres!$K$3:$N$14,4,0)="X","U","") -> U | AD3: =+IF(VLOOKUP(AD$6,Parametres!$K$3:$N$14,4,0)="X","X","") -> X | AE3: =+IF(VLOOKUP(AD$6,Parametres!$K$3:$N$14,4,0)="X","O","") -> O | AF3: =+IF(VLOOKUP(AD$6,Parametres!$K$3:$N$14,4,0)="X","U","") -> U | AG3: =+IF(VLOOKUP(AG$6,Parametres!$K$3:$N$14,4,0)="X","X","") -> X | AH3: =+IF(VLOOKUP(AG$6,Parametres!$K$3:$N$14,4,0)="X","O","") -> O | AI3: =+IF(VLOOKUP(AG$6,Parametres!$K$3:$N$14,4,0)="X","U","") -> U | AJ3: =+IF(VLOOKUP(AJ$6,Parametres!$K$3:$N$14,4,0)="X","X","") -> X | AK3: =+IF(VLOOKUP(AJ$6,Parametres!$K$3:$N$14,4,0)="X","O","") -> O | AL3: =+IF(VLOOKUP(AJ$6,Parametres!$K$3:$N$14,4,0)="X","U","") -> U | AM3: =+IF(VLOOKUP(AM$6,Parametres!$K$3:$N$14,4,0)="X","X","") | AN3: =+IF(VLOOKUP(AM$6,Parametres!$K$3:$N$14,4,0)="X","O","") | AO3: =+IF(VLOOKUP(AM$6,Parametres!$K$3:$N$14,4,0)="X","U","")
B4: Budget 2022 | C4: Véhicules neufs
B6: Mois | C6: 2022 | F6: Janvier | I6: Février | L6: Mars | O6: Avril | R6: Mai | U6: Juin | X6: Juillet | AA6: Août | AD6: Septembre | AG6: Octobre | AJ6: Novembre | AM6: Décembre
C7: UNITE | D7: $P/UNITE | E7: $PROFITS | F7: UNITE | G7: $P/UNITE | H7: $PROFITS | I7: UNITE | J7: $P/UNITE | K7: $PROFITS | L7: UNITE | M7: $P/UNITE | N7: $PROFITS | O7: UNITE | P7: $P/UNITE | Q7: $PROFITS | R7: UNITE | S7: $P/UNITE | T7: $PROFITS | U7: UNITE | V7: $P/UNITE | W7: $PROFITS | X7: UNITE | Y7: $P/UNITE | Z7: $PROFITS | AA7: UNITE | AB7: $P/UNITE | AC7: $PROFITS | AD7: UNITE | AE7: $P/UNITE | AF7: $PROFITS | AG7: UNITE | AH7: $P/UNITE | AI7: $PROFITS | AJ7: UNITE | AK7: $P/UNITE | AL7: $PROFITS | AM7: UNITE | AN7: $P/UNITE | AO7: $PROFITS
A8: =+$C$4&B8 -> Véhicules neufsVentes nettes | B8: Ventes nettes | E8: =+SUM(H8,K8,N8,Q8,T8,W8,Z8,AC8,AF8,AI8,AL8,AO8) -> 32920311 | H8: 1528310.4 | K8: 1587458.9 | N8: 2936799 | Q8: 3254290.8 | T8: 3809901.5 | W8: 2936799 | Z8: 3373350.3 | AC8: 3254290.8 | AF8: 2857426.1 | AI8: 3055858.5 | AL8: 2738366.7 | AO8: 1587458.9
A9: =+$C$4&B9 -> Véhicules neufsAutos détail | B9: Autos détail | C9: =+SUM(F9,I9,L9,O9,R9,U9,X9,AA9,AD9,AG9,AJ9,AM9) -> 168 | D9: =IF(C9=0,0,E9/C9) -> 1450.6298 | E9: =+SUM(H9,K9,N9,Q9,T9,W9,Z9,AC9,AF9,AI9,AL9,AO9) -> 243705.8 | F9: 7.8939759 | G9: =IF(F9=0,0,H9/F9) -> 1450.6298 | H9: 11451.236 | I9: 8.0963855 | J9: =IF(I9=0,0,K9/I9) -> 1450.6298 | K9: 11744.858 | L9: 14.978313 | M9: =IF(L9=0,0,N9/L9) -> 1450.6298 | N9: 21727.987 | O9: 16.59759 | P9: =IF(O9=0,0,Q9/O9) -> 1450.6298 | Q9: 24076.959 | R9: 19.431325 | S9: =IF(R9=0,0,T9/R9) -> 1450.6298 | T9: 28187.659 | U9: 14.978313 | V9: =IF(U9=0,0,W9/U9) -> 1450.6298 | W9: 21727.987 | X9: 17.204819 | Y9: =IF(X9=0,0,Z9/X9) -> 1450.6298 | Z9: 24957.823 | AA9: 16.59759 | AB9: =IF(AA9=0,0,AC9/AA9) -> 1450.6298 | AC9: 24076.959 | AD9: 14.573494 | AE9: =IF(AD9=0,0,AF9/AD9) -> 1450.6298 | AF9: 21140.744 | AG9: 15.585542 | AH9: =IF(AG9=0,0,AI9/AG9) -> 1450.6298 | AI9: 22608.851 | AJ9: 13.966265 | AK9: =IF(AJ9=0,0,AL9/AJ9) -> 1450.6298 | AL9: 20259.88 | AM9: 8.0963855 | AN9: =IF(AM9=0,0,AO9/AM9) -> 1450.6298 | AO9: 11744.858
A10: =+$C$4&B10 -> Véhicules neufsCamions détail | B10: Camions détail | C10: =+SUM(F10,I10,L10,O10,R10,U10,X10,AA10,AD10,AG10,AJ10,AM10) -> 580 | D10: =IF(C10=0,0,E10/C10) -> 2081.8276 | E10: =+SUM(H10,K10,N10,Q10,T10,W10,Z10,AC10,AF10,AI10,AL10,AO10) -> 1207460 | F10: 27.253012 | G10: =IF(F10=0,0,H10/F10) -> 2081.8276 | H10: 56736.072 | I10: 27.951807 | J10: =IF(I10=0,0,K10/I10) -> 2081.8276 | K10: 58190.843 | L10: 51.710843 | M10: =IF(L10=0,0,N10/L10) -> 2081.8276 | N10: 107653.06 | O10: 57.301205 | P10: =IF(O10=0,0,Q10/O10) -> 2081.8276 | Q10: 119291.23 | R10: 67.084337 | S10: =IF(R10=0,0,T10/R10) -> 2081.8276 | T10: 139658.02 | U10: 51.710843 | V10: =IF(U10=0,0,W10/U10) -> 2081.8276 | W10: 107653.06 | X10: 59.39759 | Y10: =IF(X10=0,0,Z10/X10) -> 2081.8276 | Z10: 123655.54 | AA10: 57.301205 | AB10: =IF(AA10=0,0,AC10/AA10) -> 2081.8276 | AC10: 119291.23 | AD10: 50.313253 | AE10: =IF(AD10=0,0,AF10/AD10) -> 2081.8276 | AF10: 104743.52 | AG10: 53.807229 | AH10: =IF(AG10=0,0,AI10/AG10) -> 2081.8276 | AI10: 112017.37 | AJ10: 48.216867 | AK10: =IF(AJ10=0,0,AL10/AJ10) -> 2081.8276 | AL10: 100379.2 | AM10: 27.951807 | AN10: =IF(AM10=0,0,AO10/AM10) -> 2081.8276 | AO10: 58190.843
A11: =+$C$4&B11 -> Véhicules neufsSprinter | B11: Sprinter | C11: =+SUM(F11,I11,L11,O11,R11,U11,X11,AA11,AD11,AG11,AJ11,AM11) -> 0 | D11: =IF(C11=0,0,E11/C11) -> 0 | E11: =+SUM(H11,K11,N11,Q11,T11,W11,Z11,AC11,AF11,AI11,AL11,AO11) -> 0 | F11: 0 | G11: =IF(F11=0,0,H11/F11) -> 0 | H11: 0 | I11: 0 | J11: =IF(I11=0,0,K11/I11) -> 0 | K11: 0 | L11: 0 | M11: =IF(L11=0,0,N11/L11) -> 0 | N11: 0 | O11: 0 | P11: =IF(O11=0,0,Q11/O11) -> 0 | Q11: 0 | R11: 0 | S11: =IF(R11=0,0,T11/R11) -> 0 | T11: 0 | U11: 0 | V11: =IF(U11=0,0,W11/U11) -> 0 | W11: 0 | X11: 0 | Y11: =IF(X11=0,0,Z11/X11) -> 0 | Z11: 0 | AA11: 0 | AB11: =IF(AA11=0,0,AC11/AA11) -> 0 | AC11: 0 | AD11: 0 | AE11: =IF(AD11=0,0,AF11/AD11) -> 0 | AF11: 0 | AG11: 0 | AH11: =IF(AG11=0,0,AI11/AG11) -> 0 | AI11: 0 | AJ11: 0 | AK11: =IF(AJ11=0,0,AL11/AJ11) -> 0 | AL11: 0 | AM11: 0 | AN11: =IF(AM11=0,0,AO11/AM11) -> 0 | AO11: 0
A12: =+$C$4&B12 -> Véhicules neufsMoto détail | B12: Moto détail | C12: =+SUM(F12,I12,L12,O12,R12,U12,X12,AA12,AD12,AG12,AJ12,AM12) -> 0 | D12: =IF(C12=0,0,E12/C12) -> 0 | E12: =+SUM(H12,K12,N12,Q12,T12,W12,Z12,AC12,AF12,AI12,AL12,AO12) -> 0 | F12: 0 | G12: =IF(F12=0,0,H12/F12) -> 0 | H12: 0 | I12: 0 | J12: =IF(I12=0,0,K12/I12) -> 0 | K12: 0 | L12: 0 | M12: =IF(L12=0,0,N12/L12) -> 0 | N12: 0 | O12: 0 | P12: =IF(O12=0,0,Q12/O12) -> 0 | Q12: 0 | R12: 0 | S12: =IF(R12=0,0,T12/R12) -> 0 | T12: 0 | U12: 0 | V12: =IF(U12=0,0,W12/U12) -> 0 | W12: 0 | X12: 0 | Y12: =IF(X12=0,0,Z12/X12) -> 0 | Z12: 0 | AA12: 0 | AB12: =IF(AA12=0,0,AC12/AA12) -> 0 | AC12: 0 | AD12: 0 | AE12: =IF(AD12=0,0,AF12/AD12) -> 0 | AF12: 0 | AG12: 0 | AH12: =IF(AG12=0,0,AI12/AG12) -> 0 | AI12: 0 | AJ12: 0 | AK12: =IF(AJ12=0,0,AL12/AJ12) -> 0 | AL12: 0 | AM12: 0 | AN12: =IF(AM12=0,0,AO12/AM12) -> 0 | AO12: 0
A13: =+$C$4&B13 -> Véhicules neufs[...] | B13: [...] | C13: =+SUM(F13,I13,L13,O13,R13,U13,X13,AA13,AD13,AG13,AJ13,AM13) -> 0 | D13: =IF(C13=0,0,E13/C13) -> 0 | E13: =+SUM(H13,K13,N13,Q13,T13,W13,Z13,AC13,AF13,AI13,AL13,AO13) -> 0 | G13: =IF(F13=0,0,H13/F13) -> 0 | J13: =IF(I13=0,0,K13/I13) -> 0 | M13: =IF(L13=0,0,N13/L13) -> 0 | P13: =IF(O13=0,0,Q13/O13) -> 0 | S13: =IF(R13=0,0,T13/R13) -> 0 | V13: =IF(U13=0,0,W13/U13) -> 0 | Y13: =IF(X13=0,0,Z13/X13) -> 0 | AB13: =IF(AA13=0,0,AC13/AA13) -> 0 | AE13: =IF(AD13=0,0,AF13/AD13) -> 0 | AH13: =IF(AG13=0,0,AI13/AG13) -> 0 | AK13: =IF(AJ13=0,0,AL13/AJ13) -> 0 | AN13: =IF(AM13=0,0,AO13/AM13) -> 0
A14: =+$C$4&B14 -> Véhicules neufs[...] | B14: [...] | C14: =+SUM(F14,I14,L14,O14,R14,U14,X14,AA14,AD14,AG14,AJ14,AM14) -> 0 | D14: =IF(C14=0,0,E14/C14) -> 0 | E14: =+SUM(H14,K14,N14,Q14,T14,W14,Z14,AC14,AF14,AI14,AL14,AO14) -> 0 | G14: =IF(F14=0,0,H14/F14) -> 0 | J14: =IF(I14=0,0,K14/I14) -> 0 | M14: =IF(L14=0,0,N14/L14) -> 0 | P14: =IF(O14=0,0,Q14/O14) -> 0 | S14: =IF(R14=0,0,T14/R14) -> 0 | V14: =IF(U14=0,0,W14/U14) -> 0 | Y14: =IF(X14=0,0,Z14/X14) -> 0 | AB14: =IF(AA14=0,0,AC14/AA14) -> 0 | AE14: =IF(AD14=0,0,AF14/AD14) -> 0 | AH14: =IF(AG14=0,0,AI14/AG14) -> 0 | AK14: =IF(AJ14=0,0,AL14/AJ14) -> 0 | AN14: =IF(AM14=0,0,AO14/AM14) -> 0
A15: =+$C$4&B15 -> Véhicules neufs[...] | B15: [...] | C15: =+SUM(F15,I15,L15,O15,R15,U15,X15,AA15,AD15,AG15,AJ15,AM15) -> 0 | D15: =IF(C15=0,0,E15/C15) -> 0 | E15: =+SUM(H15,K15,N15,Q15,T15,W15,Z15,AC15,AF15,AI15,AL15,AO15) -> 0 | G15: =IF(F15=0,0,H15/F15) -> 0 | J15: =IF(I15=0,0,K15/I15) -> 0 | M15: =IF(L15=0,0,N15/L15) -> 0 | P15: =IF(O15=0,0,Q15/O15) -> 0 | S15: =IF(R15=0,0,T15/R15) -> 0 | V15: =IF(U15=0,0,W15/U15) -> 0 | Y15: =IF(X15=0,0,Z15/X15) -> 0 | AB15: =IF(AA15=0,0,AC15/AA15) -> 0 | AE15: =IF(AD15=0,0,AF15/AD15) -> 0 | AH15: =IF(AG15=0,0,AI15/AG15) -> 0 | AK15: =IF(AJ15=0,0,AL15/AJ15) -> 0 | AN15: =IF(AM15=0,0,AO15/AM15) -> 0
A16: =+$C$4&B16 -> Véhicules neufsTotal Neufs | B16: Total Neufs | C16: =+SUM(C9:C15) -> 748 | D16: =IF(C16<=0,0,E16/C16) -> 1940.0612 | E16: =+SUM(E9:E15) -> 1451165.8 | F16: =+SUM(F9:F15) -> 35.146988 | G16: =IF(F16<=0,0,H16/F16) -> 1940.0612 | H16: =+SUM(H9:H15) -> 68187.309 | I16: =+SUM(I9:I15) -> 36.048193 | J16: =IF(I16<=0,0,K16/I16) -> 1940.0612 | K16: =+SUM(K9:K15) -> 69935.701 | L16: =+SUM(L9:L15) -> 66.689157 | M16: =IF(L16<=0,0,N16/L16) -> 1940.0612 | N16: =+SUM(N9:N15) -> 129381.05 | O16: =+SUM(O9:O15) -> 73.898795 | P16: =IF(O16<=0,0,Q16/O16) -> 1940.0612 | Q16: =+SUM(Q9:Q15) -> 143368.19 | R16: =+SUM(R9:R15) -> 86.515663 | S16: =IF(R16<=0,0,T16/R16) -> 1940.0612 | T16: =+SUM(T9:T15) -> 167845.68 | U16: =+SUM(U9:U15) -> 66.689157 | V16: =IF(U16<=0,0,W16/U16) -> 1940.0612 | W16: =+SUM(W9:W15) -> 129381.05 | X16: =+SUM(X9:X15) -> 76.60241 | Y16: =IF(X16<=0,0,Z16/X16) -> 1940.0612 | Z16: =+SUM(Z9:Z15) -> 148613.37 | AA16: =+SUM(AA9:AA15) -> 73.898795 | AB16: =IF(AA16<=0,0,AC16/AA16) -> 1940.0612 | AC16: =+SUM(AC9:AC15) -> 143368.19 | AD16: =+SUM(AD9:AD15) -> 64.886747 | AE16: =IF(AD16<=0,0,AF16/AD16) -> 1940.0612 | AF16: =+SUM(AF9:AF15) -> 125884.26 | AG16: =+SUM(AG9:AG15) -> 69.392771 | AH16: =IF(AG16<=0,0,AI16/AG16) -> 1940.0612 | AI16: =+SUM(AI9:AI15) -> 134626.22 | AJ16: =+SUM(AJ9:AJ15) -> 62.183133 | AK16: =IF(AJ16<=0,0,AL16/AJ16) -> 1940.0612 | AL16: =+SUM(AL9:AL15) -> 120639.08 | AM16: =+SUM(AM9:AM15) -> 36.048193 | AN16: =IF(AM16<=0,0,AO16/AM16) -> 1940.0612 | AO16: =+SUM(AO9:AO15) -> 69935.701
A17: =+$C$4&B17 -> Véhicules neufs
A18: =+$C$4&B18 -> Véhicules neufsEx-Démos et courtoisies | B18: Ex-Démos et courtoisies | C18: =+SUM(F18,I18,L18,O18,R18,U18,X18,AA18,AD18,AG18,AJ18,AM18) -> 70 | D18: =IF(C18=0,0,E18/C18) -> 1386.1016 | E18: =+SUM(H18,K18,N18,Q18,T18,W18,Z18,AC18,AF18,AI18,AL18,AO18) -> 97027.113 | F18: 3.2891566 | G18: =IF(F18=0,0,H18/F18) -> 1386.1016 | H18: 4559.1053 | I18: 3.373494 | J18: =IF(I18=0,0,K18/I18) -> 1386.1016 | K18: 4676.0055 | L18: 6.2409639 | M18: =IF(L18=0,0,N18/L18) -> 1386.1016 | N18: 8650.6101 | O18: 6.9156627 | P18: =IF(O18=0,0,Q18/O18) -> 1386.1016 | Q18: 9585.8112 | R18: 8.0963855 | S18: =IF(R18=0,0,T18/R18) -> 1386.1016 | T18: 11222.413 | U18: 6.2409639 | V18: =IF(U18=0,0,W18/U18) -> 1386.1016 | W18: 8650.6101 | X18: 7.1686747 | Y18: =IF(X18=0,0,Z18/X18) -> 1386.1016 | Z18: 9936.5116 | AA18: 6.9156627 | AB18: =IF(AA18=0,0,AC18/AA18) -> 1386.1016 | AC18: 9585.8112 | AD18: 6.0722892 | AE18: =IF(AD18=0,0,AF18/AD18) -> 1386.1016 | AF18: 8416.8098 | AG18: 6.4939759 | AH18: =IF(AG18=0,0,AI18/AG18) -> 1386.1016 | AI18: 9001.3105 | AJ18: 5.8192771 | AK18: =IF(AJ18=0,0,AL18/AJ18) -> 1386.1016 | AL18: 8066.1094 | AM18: 3.373494 | AN18: =IF(AM18=0,0,AO18/AM18) -> 1386.1016 | AO18: 4676.0055
A19: =+$C$4&B19 -> Véhicules neufs
A20: =+$C$4&B20 -> Véhicules neufsFlottes | B20: Flottes | C20: =+SUM(F20,I20,L20,O20,R20,U20,X20,AA20,AD20,AG20,AJ20,AM20) -> 12 | D20: =IF(C20=0,0,E20/C20) -> 1938.8732 | E20: =+SUM(H20,K20,N20,Q20,T20,W20,Z20,AC20,AF20,AI20,AL20,AO20) -> 23266.478 | F20: 0 | G20: =IF(F20=0,0,H20/F20) -> 0 | H20: 0 | I20: 0.6068268 | J20: =IF(I20=0,0,K20/I20) -> 1938.8732 | K20: 1176.5602 | L20: 1.1226296 | M20: =IF(L20=0,0,N20/L20) -> 1938.8732 | N20: 2176.6364 | O20: 1.2439949 | P20: =IF(O20=0,0,Q20/O20) -> 1938.8732 | Q20: 2411.9484 | R20: 1.4563843 | S20: =IF(R20=0,0,T20/R20) -> 1938.8732 | T20: 2823.7445 | U20: 1.1226296 | V20: =IF(U20=0,0,W20/U20) -> 1938.8732 | W20: 2176.6364 | X20: 1.289507 | Y20: =IF(X20=0,0,Z20/X20) -> 1938.8732 | Z20: 2500.1904 | AA20: 1.2439949 | AB20: =IF(AA20=0,0,AC20/AA20) -> 1938.8732 | AC20: 2411.9484 | AD20: 1.0922882 | AE20: =IF(AD20=0,0,AF20/AD20) -> 1938.8732 | AF20: 2117.8084 | AG20: 1.1681416 | AH20: =IF(AG20=0,0,AI20/AG20) -> 1938.8732 | AI20: 2264.8784 | AJ20: 1.0467762 | AK20: =IF(AJ20=0,0,AL20/AJ20) -> 1938.8732 | AL20: 2029.5663 | AM20: 0.6068268 | AN20: =IF(AM20=0,0,AO20/AM20) -> 1938.8732 | AO20: 1176.5602
A21: =+$C$4&B21 -> Véhicules neufs
A22: =+$C$4&B22 -> Véhicules neufsRachat bail | B22: Rachat bail | E22: =+SUM(H22,K22,N22,Q22,T22,W22,Z22,AC22,AF22,AI22,AL22,AO22) -> 70133.658 | H22: 3506.6829 | K22: 3506.6829 | N22: 8416.039 | Q22: 8416.039 | T22: 8416.039 | W22: 8416.039 | Z22: 7013.3658 | AC22: 4909.3561 | AF22: 4909.3561 | AI22: 4208.0195 | AL22: 4208.0195 | AO22: 4208.0195
A23: =+$C$4&B23 -> Véhicules neufs
A24: =+$C$4&B24 -> Véhicules neufsRev. Finances | B24: Rev. Finances | D24: =IF(C16=0,0,E24/(C16+C18)) -> 29.923763 | E24: =+SUM(H24,K24,N24,Q24,T24,W24,Z24,AC24,AF24,AI24,AL24,AO24) -> 24477.638 | G24: =IF(F16=0,0,H24/(F16+F18)) -> 29.923763 | H24: 1150.1541 | J24: =IF(I16=0,0,K24/(I16+I18)) -> 29.923763 | K24: 1179.6452 | M24: =IF(L16=0,0,N24/(L16+L18)) -> 29.923763 | N24: 2182.3436 | P24: =IF(O16=0,0,Q24/(O16+O18)) -> 29.923763 | Q24: 2418.2727 | S24: =IF(R16=0,0,T24/(R16+R18)) -> 29.923763 | T24: 2831.1485 | V24: =IF(U16=0,0,W24/(U16+U18)) -> 29.923763 | W24: 2182.3436 | Y24: =IF(X16=0,0,Z24/(X16+X18)) -> 29.923763 | Z24: 2506.7461 | AB24: =IF(AA16=0,0,AC24/(AA16+AA18)) -> 29.923763 | AC24: 2418.2727 | AE24: =IF(AD16=0,0,AF24/(AD16+AD18)) -> 29.923763 | AF24: 2123.3614 | AH24: =IF(AG16=0,0,AI24/(AG16+AG18)) -> 29.923763 | AI24: 2270.817 | AK24: =IF(AJ16=0,0,AL24/(AJ16+AJ18)) -> 29.923763 | AL24: 2034.888 | AN24: =IF(AM16=0,0,AO24/(AM16+AM18)) -> 29.923763 | AO24: 1179.6452
A25: =+$C$4&B25 -> Véhicules neufsRev. Protections | B25: Rev. Protections | D25: =IF(C16=0,0,E25/(C16+C18)) -> 800.26939 | E25: =+SUM(H25,K25,N25,Q25,T25,W25,Z25,AC25,AF25,AI25,AL25,AO25) -> 654620.36 | G25: =IF(F16=0,0,H25/(F16+F18)) -> 800.26939 | H25: 30759.27 | J25: =IF(I16=0,0,K25/(I16+I18)) -> 800.26939 | K25: 31547.969 | M25: =IF(L16=0,0,N25/(L16+L18)) -> 800.26939 | N25: 58363.743 | P25: =IF(O16=0,0,Q25/(O16+O18)) -> 800.26939 | Q25: 64673.337 | S25: =IF(R16=0,0,T25/(R16+R18)) -> 800.26939 | T25: 75715.126 | V25: =IF(U16=0,0,W25/(U16+U18)) -> 800.26939 | W25: 58363.743 | Y25: =IF(X16=0,0,Z25/(X16+X18)) -> 800.26939 | Z25: 67039.434 | AB25: =IF(AA16=0,0,AC25/(AA16+AA18)) -> 800.26939 | AC25: 64673.337 | AE25: =IF(AD16=0,0,AF25/(AD16+AD18)) -> 800.26939 | AF25: 56786.344 | AH25: =IF(AG16=0,0,AI25/(AG16+AG18)) -> 800.26939 | AI25: 60729.841 | AK25: =IF(AJ16=0,0,AL25/(AJ16+AJ18)) -> 800.26939 | AL25: 54420.247 | AN25: =IF(AM16=0,0,AO25/(AM16+AM18)) -> 800.26939 | AO25: 31547.969
A26: =+$C$4&B26 -> Véhicules neufsRev. Autres | B26: Rev. Autres | D26: =IF(C16=0,0,E26/(C16+C18)) -> 19.806849 | E26: =+SUM(H26,K26,N26,Q26,T26,W26,Z26,AC26,AF26,AI26,AL26,AO26) -> 16202.003 | G26: =IF(F16=0,0,H26/(F16+F18)) -> 19.806849 | H26: 761.29892 | J26: =IF(I16=0,0,K26/(I16+I18)) -> 19.806849 | K26: 780.8194 | M26: =IF(L16=0,0,N26/(L16+L18)) -> 19.806849 | N26: 1444.5159 | P26: =IF(O16=0,0,Q26/(O16+O18)) -> 19.806849 | Q26: 1600.6798 | S26: =IF(R16=0,0,T26/(R16+R18)) -> 19.806849 | T26: 1873.9666 | V26: =IF(U16=0,0,W26/(U16+U18)) -> 19.806849 | W26: 1444.5159 | Y26: =IF(X16=0,0,Z26/(X16+X18)) -> 19.806849 | Z26: 1659.2412 | AB26: =IF(AA16=0,0,AC26/(AA16+AA18)) -> 19.806849 | AC26: 1600.6798 | AE26: =IF(AD16=0,0,AF26/(AD16+AD18)) -> 19.806849 | AF26: 1405.4749 | AH26: =IF(AG16=0,0,AI26/(AG16+AG18)) -> 19.806849 | AI26: 1503.0774 | AK26: =IF(AJ16=0,0,AL26/(AJ16+AJ18)) -> 19.806849 | AL26: 1346.9135 | AN26: =IF(AM16=0,0,AO26/(AM16+AM18)) -> 19.806849 | AO26: 780.8194
A27: =+$C$4&B27 -> Véhicules neufsTotal F&I | B27: Total F&I | C27: =+C18+C16 -> 818 | D27: =IF(C27<=0,0,E27/C27) -> 850 | E27: =E24+E25+E26 -> 695300 | F27: =+F18+F16 -> 38.436145 | G27: =IF(F27<=0,0,H27/F27) -> 850 | H27: =H24+H25+H26 -> 32670.723 | I27: =+I18+I16 -> 39.421687 | J27: =IF(I27<=0,0,K27/I27) -> 850 | K27: =K24+K25+K26 -> 33508.434 | L27: =+L18+L16 -> 72.93012 | M27: =IF(L27<=0,0,N27/L27) -> 850 | N27: =N24+N25+N26 -> 61990.602 | O27: =+O18+O16 -> 80.814458 | P27: =IF(O27<=0,0,Q27/O27) -> 850 | Q27: =Q24+Q25+Q26 -> 68692.289 | R27: =+R18+R16 -> 94.612048 | S27: =IF(R27<=0,0,T27/R27) -> 850 | T27: =T24+T25+T26 -> 80420.241 | U27: =+U18+U16 -> 72.93012 | V27: =IF(U27<=0,0,W27/U27) -> 850 | W27: =W24+W25+W26 -> 61990.602 | X27: =+X18+X16 -> 83.771084 | Y27: =IF(X27<=0,0,Z27/X27) -> 850 | Z27: =Z24+Z25+Z26 -> 71205.422 | AA27: =+AA18+AA16 -> 80.814458 | AB27: =IF(AA27<=0,0,AC27/AA27) -> 850 | AC27: =AC24+AC25+AC26 -> 68692.289 | AD27: =+AD18+AD16 -> 70.959036 | AE27: =IF(AD27<=0,0,AF27/AD27) -> 850 | AF27: =AF24+AF25+AF26 -> 60315.181 | AG27: =+AG18+AG16 -> 75.886747 | AH27: =IF(AG27<=0,0,AI27/AG27) -> 850 | AI27: =AI24+AI25+AI26 -> 64503.735 | AJ27: =+AJ18+AJ16 -> 68.00241 | AK27: =IF(AJ27<=0,0,AL27/AJ27) -> 850 | AL27: =AL24+AL25+AL26 -> 57802.048 | AM27: =+AM18+AM16 -> 39.421687 | AN27: =IF(AM27<=0,0,AO27/AM27) -> 850 | AO27: =AO24+AO25+AO26 -> 33508.434
A28: =+$C$4&B28 -> Véhicules neufs
A29: =+$C$4&B29 -> Véhicules neufs
A30: =+$C$4&B30 -> Véhicules neufsTotal Dépt. Neufs | B30: Total Dépt. Neufs | C30: =+C16+C18+C20 -> 830 | D30: =IF(C30<=0,0,E30/C30) -> 2815.5338 | E30: =E16+E20+E27+E22+E18 -> 2336893 | F30: =+F16+F18+F20 -> 38.436145 | G30: =IF(F30<=0,0,H30/F30) -> 2833.8904 | H30: =H16+H20+H27+H22+H18 -> 108923.82 | I30: =+I16+I18+I20 -> 40.028514 | J30: =IF(I30<=0,0,K30/I30) -> 2818.0758 | K30: =K16+K20+K27+K22+K18 -> 112803.38 | L30: =+L16+L18+L20 -> 74.05275 | M30: =IF(L30<=0,0,N30/L30) -> 2844.1204 | N30: =N16+N20+N27+N22+N18 -> 210614.94 | O30: =+O16+O18+O20 -> 82.058453 | P30: =IF(O30<=0,0,Q30/O30) -> 2833.0326 | Q30: =Q16+Q20+Q27+Q22+Q18 -> 232474.28 | R30: =+R16+R18+R20 -> 96.068433 | S30: =IF(R30<=0,0,T30/R30) -> 2818.0758 | T30: =T16+T20+T27+T22+T18 -> 270728.12 | U30: =+U16+U18+U20 -> 74.05275 | V30: =IF(U30<=0,0,W30/U30) -> 2844.1204 | W30: =W16+W20+W27+W22+W18 -> 210614.94 | X30: =+X16+X18+X20 -> 85.060591 | Y30: =IF(X30<=0,0,Z30/X30) -> 2812.9225 | Z30: =Z16+Z20+Z27+Z22+Z18 -> 239268.85 | AA30: =+AA16+AA18+AA20 -> 82.058453 | AB30: =IF(AA30<=0,0,AC30/AA30) -> 2790.2987 | AC30: =AC16+AC20+AC27+AC22+AC18 -> 228967.59 | AD30: =+AD16+AD18+AD20 -> 72.051324 | AE30: =IF(AD30<=0,0,AF30/AD30) -> 2798.6081 | AF30: =AF16+AF20+AF27+AF22+AF18 -> 201643.42 | AG30: =+AG16+AG18+AG20 -> 77.054889 | AH30: =IF(AG30<=0,0,AI30/AG30) -> 2785.0818 | AI30: =AI16+AI20+AI27+AI22+AI18 -> 214604.17 | AJ30: =+AJ16+AJ18+AJ20 -> 69.049186 | AK30: =IF(AJ30<=0,0,AL30/AJ30) -> 2791.4135 | AL30: =AL16+AL20+AL27+AL22+AL18 -> 192744.83 | AM30: =+AM16+AM18+AM20 -> 40.028514 | AN30: =IF(AM30<=0,0,AO30/AM30) -> 2835.5967 | AO30: =AO16+AO20+AO27+AO22+AO18 -> 113504.72
A31: =+$C$4&B31 -> Véhicules neufs
A32: =+$C$4&B32 -> Véhicules neufs
A33: =+$C$4&B33 -> Véhicules neufsDEPENSES | B33: DEPENSES
A34: =+$C$4&B34 -> Véhicules neufsComm. vendeurs | B34: Comm. vendeurs | C34: =E34/(E16+E18) -> 0.33115355 | D34: =IF(E34=0,0,E34/C$27) -> 626.75987 | E34: =+SUM(H34,K34,N34,Q34,T34,W34,Z34,AC34,AF34,AI34,AL34,AO34) -> 512689.57 | F34: =H34/(H16+H18) -> 0.37878062 | G34: =IF(H34=0,0,H34/F$27) -> 716.90156 | H34: 27554.932 | I34: =K34/(K16+K18) -> 0.37507774 | J34: =IF(K34=0,0,K34/I$27) -> 709.89328 | K34: 27985.19 | L34: =N34/(N16+N18) -> 0.32918247 | M34: =IF(N34=0,0,N34/L$27) -> 623.02931 | N34: 45437.602 | O34: =Q34/(Q16+Q18) -> 0.31966893 | P34: =IF(Q34=0,0,Q34/O$27) -> 605.02343 | Q34: 48894.64 | R34: =T34/(T16+T18) -> 0.31286677 | S34: =IF(T34=0,0,T34/R$27) -> 592.14929 | T34: 56024.457 | U34: =W34/(W16+W18) -> 0.32744374 | V34: =IF(W34=0,0,W34/U$27) -> 619.73848 | W34: 45197.602 | X34: =Z34/(Z16+Z18) -> 0.31769832 | Y34: =IF(Z34=0,0,Z34/X$27) -> 601.29375 | Z34: 50371.03 | AA34: =AC34/(AC16+AC18) -> 0.32280712 | AB34: =IF(AC34=0,0,AC34/AA$27) -> 610.96296 | AC34: 49374.64 | AD34: =AF34/(AF16+AF18) -> 0.32921065 | AE34: =IF(AF34=0,0,AF34/AD$27) -> 623.08263 | AF34: 44213.343 | AG34: =AI34/(AI16+AI18) -> 0.3232945 | AH34: =IF(AI34=0,0,AI34/AG$27) -> 611.88539 | AI34: 46433.992 | AJ34: =AL34/(AL16+AL18) -> 0.33205306 | AK34: =IF(AL34=0,0,AL34/AJ$27) -> 628.46234 | AL34: 42736.954 | AM34: =AO34/(AO16+AO18) -> 0.38151105 | AN34: =IF(AO34=0,0,AO34/AM$27) -> 722.06932 | AO34: 28465.19
A35: =+$C$4&B35 -> Véhicules neufsComm. F&I | B35: Comm. F&I | C35: =E35/E27 -> 0.3 | D35: =IF(E35=0,0,E35/C$27) -> 255 | E35: =+SUM(H35,K35,N35,Q35,T35,W35,Z35,AC35,AF35,AI35,AL35,AO35) -> 208590 | F35: =H35/H27 -> 0.3 | G35: =IF(H35=0,0,H35/F$27) -> 255 | H35: 9801.2169 | I35: =K35/K27 -> 0.3 | J35: =IF(K35=0,0,K35/I$27) -> 255 | K35: 10052.53 | L35: =N35/N27 -> 0.3 | M35: =IF(N35=0,0,N35/L$27) -> 255 | N35: 18597.181 | O35: =Q35/Q27 -> 0.3 | P35: =IF(Q35=0,0,Q35/O$27) -> 255 | Q35: 20607.687 | R35: =T35/T27 -> 0.3 | S35: =IF(T35=0,0,T35/R$27) -> 255 | T35: 24126.072 | U35: =W35/W27 -> 0.3 | V35: =IF(W35=0,0,W35/U$27) -> 255 | W35: 18597.181 | X35: =Z35/Z27 -> 0.3 | Y35: =IF(Z35=0,0,Z35/X$27) -> 255 | Z35: 21361.627 | AA35: =AC35/AC27 -> 0.3 | AB35: =IF(AC35=0,0,AC35/AA$27) -> 255 | AC35: 20607.687 | AD35: =AF35/AF27 -> 0.3 | AE35: =IF(AF35=0,0,AF35/AD$27) -> 255 | AF35: 18094.554 | AG35: =AI35/AI27 -> 0.3 | AH35: =IF(AI35=0,0,AI35/AG$27) -> 255 | AI35: 19351.12 | AJ35: =AL35/AL27 -> 0.3 | AK35: =IF(AL35=0,0,AL35/AJ$27) -> 255 | AL35: 17340.614 | AM35: =AO35/AO27 -> 0.3 | AN35: =IF(AO35=0,0,AO35/AM$27) -> 255 | AO35: 10052.53
A36: =+$C$4&B36 -> Véhicules neufsFrais de livraison | B36: Frais de livraison | D36: =IF(E36=0,0,E36/C$27) -> 167.8493 | E36: =+SUM(H36,K36,N36,Q36,T36,W36,Z36,AC36,AF36,AI36,AL36,AO36) -> 137300.73 | G36: =IF(H36=0,0,H36/F$27) -> 167.8493 | H36: 6451.48 | J36: =IF(K36=0,0,K36/I$27) -> 167.8493 | K36: 6616.9026 | M36: =IF(N36=0,0,N36/L$27) -> 167.8493 | N36: 12241.27 | P36: =IF(Q36=0,0,Q36/O$27) -> 167.8493 | Q36: 13564.65 | S36: =IF(T36=0,0,T36/R$27) -> 167.8493 | T36: 15880.566 | V36: =IF(W36=0,0,W36/U$27) -> 167.8493 | W36: 12241.27 | Y36: =IF(Z36=0,0,Z36/X$27) -> 167.8493 | Z36: 14060.918 | AB36: =IF(AC36=0,0,AC36/AA$27) -> 167.8493 | AC36: 13564.65 | AE36: =IF(AF36=0,0,AF36/AD$27) -> 167.8493 | AF36: 11910.425 | AH36: =IF(AI36=0,0,AI36/AG$27) -> 167.8493 | AI36: 12737.538 | AK36: =IF(AL36=0,0,AL36/AJ$27) -> 167.8493 | AL36: 11414.157 | AN36: =IF(AO36=0,0,AO36/AM$27) -> 167.8493 | AO36: 6616.9026
A37: =+$C$4&B37 -> Véhicules neufsService gratuit 1 | B37: Service gratuit 1 | D37: =IF(E37=0,0,E37/C$27) -> 7.3548076 | E37: =+SUM(H37,K37,N37,Q37,T37,W37,Z37,AC37,AF37,AI37,AL37,AO37) -> 6016.2326 | G37: =IF(H37=0,0,H37/F$27) -> 7.3548076 | H37: 282.69045 | J37: =IF(K37=0,0,K37/I$27) -> 7.3548076 | K37: 289.93892 | M37: =IF(N37=0,0,N37/L$27) -> 7.3548076 | N37: 536.38701 | P37: =IF(Q37=0,0,Q37/O$27) -> 7.3548076 | Q37: 594.37479 | S37: =IF(T37=0,0,T37/R$27) -> 7.3548076 | T37: 695.85341 | V37: =IF(W37=0,0,W37/U$27) -> 7.3548076 | W37: 536.38701 | Y37: =IF(Z37=0,0,Z37/X$27) -> 7.3548076 | Z37: 616.12021 | AB37: =IF(AC37=0,0,AC37/AA$27) -> 7.3548076 | AC37: 594.37479 | AE37: =IF(AF37=0,0,AF37/AD$27) -> 7.3548076 | AF37: 521.89006 | AH37: =IF(AI37=0,0,AI37/AG$27) -> 7.3548076 | AI37: 558.13243 | AK37: =IF(AL37=0,0,AL37/AJ$27) -> 7.3548076 | AL37: 500.14464 | AN37: =IF(AO37=0,0,AO37/AM$27) -> 7.3548076 | AO37: 289.93892
A38: =+$C$4&B38 -> Véhicules neufsEntretien stock | B38: Entretien stock | D38: =IF(E38=0,0,E38/C$27) -> 17.733118 | E38: =+SUM(H38,K38,N38,Q38,T38,W38,Z38,AC38,AF38,AI38,AL38,AO38) -> 14505.691 | G38: =IF(H38=0,0,H38/F$27) -> 17.733118 | H38: 681.5927 | J38: =IF(K38=0,0,K38/I$27) -> 17.733118 | K38: 699.06943 | M38: =IF(N38=0,0,N38/L$27) -> 17.733118 | N38: 1293.2784 | P38: =IF(Q38=0,0,Q38/O$27) -> 17.733118 | Q38: 1433.0923 | S38: =IF(T38=0,0,T38/R$27) -> 17.733118 | T38: 1677.7666 | V38: =IF(W38=0,0,W38/U$27) -> 17.733118 | W38: 1293.2784 | Y38: =IF(Z38=0,0,Z38/X$27) -> 17.733118 | Z38: 1485.5225 | AB38: =IF(AC38=0,0,AC38/AA$27) -> 17.733118 | AC38: 1433.0923 | AE38: =IF(AF38=0,0,AF38/AD$27) -> 17.733118 | AF38: 1258.325 | AH38: =IF(AI38=0,0,AI38/AG$27) -> 17.733118 | AI38: 1345.7087 | AK38: =IF(AL38=0,0,AL38/AJ$27) -> 17.733118 | AL38: 1205.8948 | AN38: =IF(AO38=0,0,AO38/AM$27) -> 17.733118 | AO38: 699.06943
A39: =+$C$4&B39 -> Véhicules neufsPublicité 1 | B39: Publicité 1 | D39: =IF(E39=0,0,E39/C$27) -> 195.93765 | E39: =+SUM(H39,K39,N39,Q39,T39,W39,Z39,AC39,AF39,AI39,AL39,AO39) -> 160277 | G39: =IF(H39=0,0,H39/F$27) -> 195.93765 | H39: 7531.088 | J39: =IF(K39=0,0,K39/I$27) -> 195.93765 | K39: 7724.1928 | M39: =IF(N39=0,0,N39/L$27) -> 195.93765 | N39: 14289.757 | P39: =IF(Q39=0,0,Q39/O$27) -> 195.93765 | Q39: 15834.595 | S39: =IF(T39=0,0,T39/R$27) -> 195.93765 | T39: 18538.063 | V39: =IF(W39=0,0,W39/U$27) -> 195.93765 | W39: 14289.757 | Y39: =IF(Z39=0,0,Z39/X$27) -> 195.93765 | Z39: 16413.91 | AB39: =IF(AC39=0,0,AC39/AA$27) -> 195.93765 | AC39: 15834.595 | AE39: =IF(AF39=0,0,AF39/AD$27) -> 195.93765 | AF39: 13903.547 | AH39: =IF(AI39=0,0,AI39/AG$27) -> 195.93765 | AI39: 14869.071 | AK39: =IF(AL39=0,0,AL39/AJ$27) -> 195.93765 | AL39: 13324.233 | AN39: =IF(AO39=0,0,AO39/AM$27) -> 195.93765 | AO39: 7724.1928
A40: =+$C$4&B40 -> Véhicules neufsIntérêt de gros | B40: Intérêt de gros | D40: =IF(E40=0,0,E40/C$27) -> 102.42004 | E40: =+SUM(H40,K40,N40,Q40,T40,W40,Z40,AC40,AF40,AI40,AL40,AO40) -> 83779.589 | G40: =IF(H40=0,0,H40/F$27) -> 146.62809 | H40: 5635.8184 | J40: =IF(K40=0,0,K40/I$27) -> 162.72861 | K40: 6415.0362 | M40: =IF(N40=0,0,N40/L$27) -> 100.885 | N40: 7357.5552 | P40: =IF(Q40=0,0,Q40/O$27) -> 101.02946 | Q40: 8164.6412 | S40: =IF(T40=0,0,T40/R$27) -> 83.856314 | T40: 7933.8176 | V40: =IF(W40=0,0,W40/U$27) -> 95.743292 | W40: 6982.5698 | Y40: =IF(Z40=0,0,Z40/X$27) -> 86.224826 | Z40: 7223.1472 | AB40: =IF(AC40=0,0,AC40/AA$27) -> 96.0289 | AC40: 7760.5235 | AE40: =IF(AF40=0,0,AF40/AD$27) -> 117.38963 | AF40: 8329.8552 | AH40: =IF(AI40=0,0,AI40/AG$27) -> 97.587388 | AI40: 7405.5894 | AK40: =IF(AL40=0,0,AL40/AJ$27) -> 79.550134 | AL40: 5409.6008 | AN40: =IF(AO40=0,0,AO40/AM$27) -> 130.92881 | AO40: 5161.4344
A41: =+$C$4&B41 -> Véhicules neufs[...] | B41: [...] | D41: =IF(E41=0,0,E41/C$27) -> 0 | E41: =+SUM(H41,K41,N41,Q41,T41,W41,Z41,AC41,AF41,AI41,AL41,AO41) -> 0 | G41: =IF(H41=0,0,H41/F$27) -> 0 | J41: =IF(K41=0,0,K41/I$27) -> 0 | M41: =IF(N41=0,0,N41/L$27) -> 0 | P41: =IF(Q41=0,0,Q41/O$27) -> 0 | S41: =IF(T41=0,0,T41/R$27) -> 0 | V41: =IF(W41=0,0,W41/U$27) -> 0 | Y41: =IF(Z41=0,0,Z41/X$27) -> 0 | AB41: =IF(AC41=0,0,AC41/AA$27) -> 0 | AE41: =IF(AF41=0,0,AF41/AD$27) -> 0 | AH41: =IF(AI41=0,0,AI41/AG$27) -> 0 | AK41: =IF(AL41=0,0,AL41/AJ$27) -> 0 | AN41: =IF(AO41=0,0,AO41/AM$27) -> 0
...

Sheet Budget révisé
B1: ="Budget 2022 Mensuel Révisé"&" "&Parametres!$B$1 -> Budget 2022 Mensuel Révisé Volks
B2: Mois | F2: =+IF(Parametres!$B$3=F$6,"X","") | G2: =+IF(Parametres!$B$3=F$6,"O","") | H2: =+IF(Parametres!$B$3=F$6,"U","") | I2: =+IF(Parametres!$B$3=I$6,"X","") | J2: =+IF(Parametres!$B$3=I$6,"O","") | K2: =+IF(Parametres!$B$3=I$6,"U","") | L2: =+IF(Parametres!$B$3=L$6,"X","") | M2: =+IF(Parametres!$B$3=L$6,"O","") | N2: =+IF(Parametres!$B$3=L$6,"U","") | O2: =+IF(Parametres!$B$3=O$6,"X","") | P2: =+IF(Parametres!$B$3=O$6,"O","") | Q2: =+IF(Parametres!$B$3=O$6,"U","") | R2: =+IF(Parametres!$B$3=R$6,"X","") | S2: =+IF(Parametres!$B$3=R$6,"O","") | T2: =+IF(Parametres!$B$3=R$6,"U","") | U2: =+IF(Parametres!$B$3=U$6,"X","") | V2: =+IF(Parametres!$B$3=U$6,"O","") | W2: =+IF(Parametres!$B$3=U$6,"U","") | X2: =+IF(Parametres!$B$3=X$6,"X","") | Y2: =+IF(Parametres!$B$3=X$6,"O","") | Z2: =+IF(Parametres!$B$3=X$6,"U","") | AA2: =+IF(Parametres!$B$3=AA$6,"X","") | AB2: =+IF(Parametres!$B$3=AA$6,"O","") | AC2: =+IF(Parametres!$B$3=AA$6,"U","") | AD2: =+IF(Parametres!$B$3=AD$6,"X","") | AE2: =+IF(Parametres!$B$3=AD$6,"O","") | AF2: =+IF(Parametres!$B$3=AD$6,"U","") | AG2: =+IF(Parametres!$B$3=AG$6,"X","") | AH2: =+IF(Parametres!$B$3=AG$6,"O","") | AI2: =+IF(Parametres!$B$3=AG$6,"U","") | AJ2: =+IF(Parametres!$B$3=AJ$6,"X","") -> X | AK2: =+IF(Parametres!$B$3=AJ$6,"O","") -> O | AL2: =+IF(Parametres!$B$3=AJ$6,"U","") -> U | AM2: =+IF(Parametres!$B$3=AM$6,"X","") | AN2: =+IF(Parametres!$B$3=AM$6,"O","") | AO2: =+IF(Parametres!$B$3=AM$6,"U","")
B3: YTD | F3: =+IF(VLOOKUP(F$6,Parametres!$K$3:$N$14,4,0)="X","X","") -> X | G3: =+IF(VLOOKUP(F$6,Parametres!$K$3:$N$14,4,0)="X","O","") -> O | H3: =+IF(VLOOKUP(F$6,Parametres!$K$3:$N$14,4,0)="X","U","") -> U | I3: =+IF(VLOOKUP(I$6,Parametres!$K$3:$N$14,4,0)="X","X","") -> X | J3: =+IF(VLOOKUP(I$6,Parametres!$K$3:$N$14,4,0)="X","O","") -> O | K3: =+IF(VLOOKUP(I$6,Parametres!$K$3:$N$14,4,0)="X","U","") -> U | L3: =+IF(VLOOKUP(L$6,Parametres!$K$3:$N$14,4,0)="X","X","") -> X | M3: =+IF(VLOOKUP(L$6,Parametres!$K$3:$N$14,4,0)="X","O","") -> O | N3: =+IF(VLOOKUP(L$6,Parametres!$K$3:$N$14,4,0)="X","U","") -> U | O3: =+IF(VLOOKUP(O$6,Parametres!$K$3:$N$14,4,0)="X","X","") -> X | P3: =+IF(VLOOKUP(O$6,Parametres!$K$3:$N$14,4,0)="X","O","") -> O | Q3: =+IF(VLOOKUP(O$6,Parametres!$K$3:$N$14,4,0)="X","U","") -> U | R3: =+IF(VLOOKUP(R$6,Parametres!$K$3:$N$14,4,0)="X","X","") -> X | S3: =+IF(VLOOKUP(R$6,Parametres!$K$3:$N$14,4,0)="X","O","") -> O | T3: =+IF(VLOOKUP(R$6,Parametres!$K$3:$N$14,4,0)="X","U","") -> U | U3: =+IF(VLOOKUP(U$6,Parametres!$K$3:$N$14,4,0)="X","X","") -> X | V3: =+IF(VLOOKUP(U$6,Parametres!$K$3:$N$14,4,0)="X","O","") -> O | W3: =+IF(VLOOKUP(U$6,Parametres!$K$3:$N$14,4,0)="X","U","") -> U | X3: =+IF(VLOOKUP(X$6,Parametres!$K$3:$N$14,4,0)="X","X","") -> X | Y3: =+IF(VLOOKUP(X$6,Parametres!$K$3:$N$14,4,0)="X","O","") -> O | Z3: =+IF(VLOOKUP(X$6,Parametres!$K$3:$N$14,4,0)="X","U","") -> U | AA3: =+IF(VLOOKUP(AA$6,Parametres!$K$3:$N$14,4,0)="X","X","") -> X | AB3: =+IF(VLOOKUP(AA$6,Parametres!$K$3:$N$14,4,0)="X","O","") -> O | AC3: =+IF(VLOOKUP(AA$6,Parametres!$K$3:$N$14,4,0)="X","U","") -> U | AD3: =+IF(VLOOKUP(AD$6,Parametres!$K$3:$N$14,4,0)="X","X","") -> X | AE3: =+IF(VLOOKUP(AD$6,Parametres!$K$3:$N$14,4,0)="X","O","") -> O | AF3: =+IF(VLOOKUP(AD$6,Parametres!$K$3:$N$14,4,0)="X","U","") -> U | AG3: =+IF(VLOOKUP(AG$6,Parametres!$K$3:$N$14,4,0)="X","X","") -> X | AH3: =+IF(VLOOKUP(AG$6,Parametres!$K$3:$N$14,4,0)="X","O","") -> O | AI3: =+IF(VLOOKUP(AG$6,Parametres!$K$3:$N$14,4,0)="X","U","") -> U | AJ3: =+IF(VLOOKUP(AJ$6,Parametres!$K$3:$N$14,4,0)="X","X","") -> X | AK3: =+IF(VLOOKUP(AJ$6,Parametres!$K$3:$N$14,4,0)="X","O","") -> O | AL3: =+IF(VLOOKUP(AJ$6,Parametres!$K$3:$N$14,4,0)="X","U","") -> U | AM3: =+IF(VLOOKUP(AM$6,Parametres!$K$3:$N$14,4,0)="X","X","") | AN3: =+IF(VLOOKUP(AM$6,Parametres!$K$3:$N$14,4,0)="X","O","") | AO3: =+IF(VLOOKUP(AM$6,Parametres!$K$3:$N$14,4,0)="X","U","")
B4: Budget 2022 | C4: Véhicules neufs
B6: Mois | C6: 2022 | F6: Janvier | I6: Février | L6: Mars | O6: Avril | R6: Mai | U6: Juin | X6: Juillet | AA6: Août | AD6: Septembre | AG6: Octobre | AJ6: Novembre | AM6: Décembre
C7: UNITE | D7: $P/UNITE | E7: $PROFITS | F7: UNITE | G7: $P/UNITE | H7: $PROFITS | I7: UNITE | J7: $P/UNITE | K7: $PROFITS | L7: UNITE | M7: $P/UNITE | N7: $PROFITS | O7: UNITE | P7: $P/UNITE | Q7: $PROFITS | R7: UNITE | S7: $P/UNITE | T7: $PROFITS | U7: UNITE | V7: $P/UNITE | W7: $PROFITS | X7: UNITE | Y7: $P/UNITE | Z7: $PROFITS | AA7: UNITE | AB7: $P/UNITE | AC7: $PROFITS | AD7: UNITE | AE7: $P/UNITE | AF7: $PROFITS | AG7: UNITE | AH7: $P/UNITE | AI7: $PROFITS | AJ7: UNITE | AK7: $P/UNITE | AL7: $PROFITS | AM7: UNITE | AN7: $P/UNITE | AO7: $PROFITS
A8: =+$C$4&B8 -> Véhicules neufsVentes nettes | B8: Ventes nettes | E8: =+SUM(H8,K8,N8,Q8,T8,W8,Z8,AC8,AF8,AI8,AL8,AO8) -> 32920311 | H8: 1528310.4 | K8: 1587458.9 | N8: 2936799 | Q8: 3254290.8 | T8: 3809901.5 | W8: 2936799 | Z8: 3373350.3 | AC8: 3254290.8 | AF8: 2857426.1 | AI8: 3055858.5 | AL8: 2738366.7 | AO8: 1587458.9
A9: =+$C$4&B9 -> Véhicules neufsAutos détail | B9: Autos détail | C9: =+SUM(F9,I9,L9,O9,R9,U9,X9,AA9,AD9,AG9,AJ9,AM9) -> 168 | D9: =IF(C9=0,0,E9/C9) -> 1450.6298 | E9: =+SUM(H9,K9,N9,Q9,T9,W9,Z9,AC9,AF9,AI9,AL9,AO9) -> 243705.8 | F9: 7.8939759 | G9: =IF(F9=0,0,H9/F9) -> 1450.6298 | H9: 11451.236 | I9: 8.0963855 | J9: =IF(I9=0,0,K9/I9) -> 1450.6298 | K9: 11744.858 | L9: 14.978313 | M9: =IF(L9=0,0,N9/L9) -> 1450.6298 | N9: 21727.987 | O9: 16.59759 | P9: =IF(O9=0,0,Q9/O9) -> 1450.6298 | Q9: 24076.959 | R9: 19.431325 | S9: =IF(R9=0,0,T9/R9) -> 1450.6298 | T9: 28187.659 | U9: 14.978313 | V9: =IF(U9=0,0,W9/U9) -> 1450.6298 | W9: 21727.987 | X9: 17.204819 | Y9: =IF(X9=0,0,Z9/X9) -> 1450.6298 | Z9: 24957.823 | AA9: 16.59759 | AB9: =IF(AA9=0,0,AC9/AA9) -> 1450.6298 | AC9: 24076.959 | AD9: 14.573494 | AE9: =IF(AD9=0,0,AF9/AD9) -> 1450.6298 | AF9: 21140.744 | AG9: 15.585542 | AH9: =IF(AG9=0,0,AI9/AG9) -> 1450.6298 | AI9: 22608.851 | AJ9: 13.966265 | AK9: =IF(AJ9=0,0,AL9/AJ9) -> 1450.6298 | AL9: 20259.88 | AM9: 8.0963855 | AN9: =IF(AM9=0,0,AO9/AM9) -> 1450.6298 | AO9: 11744.858
A10: =+$C$4&B10 -> Véhicules neufsCamions détail | B10: Camions détail | C10: =+SUM(F10,I10,L10,O10,R10,U10,X10,AA10,AD10,AG10,AJ10,AM10) -> 580 | D10: =IF(C10=0,0,E10/C10) -> 2081.8276 | E10: =+SUM(H10,K10,N10,Q10,T10,W10,Z10,AC10,AF10,AI10,AL10,AO10) -> 1207460 | F10: 27.253012 | G10: =IF(F10=0,0,H10/F10) -> 2081.8276 | H10: 56736.072 | I10: 27.951807 | J10: =IF(I10=0,0,K10/I10) -> 2081.8276 | K10: 58190.843 | L10: 51.710843 | M10: =IF(L10=0,0,N10/L10) -> 2081.8276 | N10: 107653.06 | O10: 57.301205 | P10: =IF(O10=0,0,Q10/O10) -> 2081.8276 | Q10: 119291.23 | R10: 67.084337 | S10: =IF(R10=0,0,T10/R10) -> 2081.8276 | T10: 139658.02 | U10: 51.710843 | V10: =IF(U10=0,0,W10/U10) -> 2081.8276 | W10: 107653.06 | X10: 59.39759 | Y10: =IF(X10=0,0,Z10/X10) -> 2081.8276 | Z10: 123655.54 | AA10: 57.301205 | AB10: =IF(AA10=0,0,AC10/AA10) -> 2081.8276 | AC10: 119291.23 | AD10: 50.313253 | AE10: =IF(AD10=0,0,AF10/AD10) -> 2081.8276 | AF10: 104743.52 | AG10: 53.807229 | AH10: =IF(AG10=0,0,AI10/AG10) -> 2081.8276 | AI10: 112017.37 | AJ10: 48.216867 | AK10: =IF(AJ10=0,0,AL10/AJ10) -> 2081.8276 | AL10: 100379.2 | AM10: 27.951807 | AN10: =IF(AM10=0,0,AO10/AM10) -> 2081.8276 | AO10: 58190.843
A11: =+$C$4&B11 -> Véhicules neufsSprinter | B11: Sprinter | C11: =+SUM(F11,I11,L11,O11,R11,U11,X11,AA11,AD11,AG11,AJ11,AM11) -> 0 | D11: =IF(C11=0,0,E11/C11) -> 0 | E11: =+SUM(H11,K11,N11,Q11,T11,W11,Z11,AC11,AF11,AI11,AL11,AO11) -> 0 | F11: 0 | G11: =IF(F11=0,0,H11/F11) -> 0 | H11: 0 | I11: 0 | J11: =IF(I11=0,0,K11/I11) -> 0 | K11: 0 | L11: 0 | M11: =IF(L11=0,0,N11/L11) -> 0 | N11: 0 | O11: 0 | P11: =IF(O11=0,0,Q11/O11) -> 0 | Q11: 0 | R11: 0 | S11: =IF(R11=0,0,T11/R11) -> 0 | T11: 0 | U11: 0 | V11: =IF(U11=0,0,W11/U11) -> 0 | W11: 0 | X11: 0 | Y11: =IF(X11=0,0,Z11/X11) -> 0 | Z11: 0 | AA11: 0 | AB11: =IF(AA11=0,0,AC11/AA11) -> 0 | AC11: 0 | AD11: 0 | AE11: =IF(AD11=0,0,AF11/AD11) -> 0 | AF11: 0 | AG11: 0 | AH11: =IF(AG11=0,0,AI11/AG11) -> 0 | AI11: 0 | AJ11: 0 | AK11: =IF(AJ11=0,0,AL11/AJ11) -> 0 | AL11: 0 | AM11: 0 | AN11: =IF(AM11=0,0,AO11/AM11) -> 0 | AO11: 0
A12: =+$C$4&B12 -> Véhicules neufsMoto détail | B12: Moto détail | C12: =+SUM(F12,I12,L12,O12,R12,U12,X12,AA12,AD12,AG12,AJ12,AM12) -> 0 | D12: =IF(C12=0,0,E12/C12) -> 0 | E12: =+SUM(H12,K12,N12,Q12,T12,W12,Z12,AC12,AF12,AI12,AL12,AO12) -> 0 | F12: 0 | G12: =IF(F12=0,0,H12/F12) -> 0 | H12: 0 | I12: 0 | J12: =IF(I12=0,0,K12/I12) -> 0 | K12: 0 | L12: 0 | M12: =IF(L12=0,0,N12/L12) -> 0 | N12: 0 | O12: 0 | P12: =IF(O12=0,0,Q12/O12) -> 0 | Q12: 0 | R12: 0 | S12: =IF(R12=0,0,T12/R12) -> 0 | T12: 0 | U12: 0 | V12: =IF(U12=0,0,W12/U12) -> 0 | W12: 0 | X12: 0 | Y12: =IF(X12=0,0,Z12/X12) -> 0 | Z12: 0 | AA12: 0 | AB12: =IF(AA12=0,0,AC12/AA12) -> 0 | AC12: 0 | AD12: 0 | AE12: =IF(AD12=0,0,AF12/AD12) -> 0 | AF12: 0 | AG12: 0 | AH12: =IF(AG12=0,0,AI12/AG12) -> 0 | AI12: 0 | AJ12: 0 | AK12: =IF(AJ12=0,0,AL12/AJ12) -> 0 | AL12: 0 | AM12: 0 | AN12: =IF(AM12=0,0,AO12/AM12) -> 0 | AO12: 0
A13: =+$C$4&B13 -> Véhicules neufs[...] | B13: [...] | C13: =+SUM(F13,I13,L13,O13,R13,U13,X13,AA13,AD13,AG13,AJ13,AM13) -> 0 | D13: =IF(C13=0,0,E13/C13) -> 0 | E13: =+SUM(H13,K13,N13,Q13,T13,W13,Z13,AC13,AF13,AI13,AL13,AO13) -> 0 | G13: =IF(F13=0,0,H13/F13) -> 0 | J13: =IF(I13=0,0,K13/I13) -> 0 | M13: =IF(L13=0,0,N13/L13) -> 0 | P13: =IF(O13=0,0,Q13/O13) -> 0 | S13: =IF(R13=0,0,T13/R13) -> 0 | V13: =IF(U13=0,0,W13/U13) -> 0 | Y13: =IF(X13=0,0,Z13/X13) -> 0 | AB13: =IF(AA13=0,0,AC13/AA13) -> 0 | AE13: =IF(AD13=0,0,AF13/AD13) -> 0 | AH13: =IF(AG13=0,0,AI13/AG13) -> 0 | AK13: =IF(AJ13=0,0,AL13/AJ13) -> 0 | AN13: =IF(AM13=0,0,AO13/AM13) -> 0
A14: =+$C$4&B14 -> Véhicules neufs[...] | B14: [...] | C14: =+SUM(F14,I14,L14,O14,R14,U14,X14,AA14,AD14,AG14,AJ14,AM14) -> 0 | D14: =IF(C14=0,0,E14/C14) -> 0 | E14: =+SUM(H14,K14,N14,Q14,T14,W14,Z14,AC14,AF14,AI14,AL14,AO14) -> 0 | G14: =IF(F14=0,0,H14/F14) -> 0 | J14: =IF(I14=0,0,K14/I14) -> 0 | M14: =IF(L14=0,0,N14/L14) -> 0 | P14: =IF(O14=0,0,Q14/O14) -> 0 | S14: =IF(R14=0,0,T14/R14) -> 0 | V14: =IF(U14=0,0,W14/U14) -> 0 | Y14: =IF(X14=0,0,Z14/X14) -> 0 | AB14: =IF(AA14=0,0,AC14/AA14) -> 0 | AE14: =IF(AD14=0,0,AF14/AD14) -> 0 | AH14: =IF(AG14=0,0,AI14/AG14) -> 0 | AK14: =IF(AJ14=0,0,AL14/AJ14) -> 0 | AN14: =IF(AM14=0,0,AO14/AM14) -> 0
A15: =+$C$4&B15 -> Véhicules neufs[...] | B15: [...] | C15: =+SUM(F15,I15,L15,O15,R15,U15,X15,AA15,AD15,AG15,AJ15,AM15) -> 0 | D15: =IF(C15=0,0,E15/C15) -> 0 | E15: =+SUM(H15,K15,N15,Q15,T15,W15,Z15,AC15,AF15,AI15,AL15,AO15) -> 0 | G15: =IF(F15=0,0,H15/F15) -> 0 | J15: =IF(I15=0,0,K15/I15) -> 0 | M15: =IF(L15=0,0,N15/L15) -> 0 | P15: =IF(O15=0,0,Q15/O15) -> 0 | S15: =IF(R15=0,0,T15/R15) -> 0 | V15: =IF(U15=0,0,W15/U15) -> 0 | Y15: =IF(X15=0,0,Z15/X15) -> 0 | AB15: =IF(AA15=0,0,AC15/AA15) -> 0 | AE15: =IF(AD15=0,0,AF15/AD15) -> 0 | AH15: =IF(AG15=0,0,AI15/AG15) -> 0 | AK15: =IF(AJ15=0,0,AL15/AJ15) -> 0 | AN15: =IF(AM15=0,0,AO15/AM15) -> 0
A16: =+$C$4&B16 -> Véhicules neufsTotal Neufs | B16: Total Neufs | C16: =+SUM(C9:C15) -> 748 | D16: =IF(C16<=0,0,E16/C16) -> 1940.0612 | E16: =+SUM(E9:E15) -> 1451165.8 | F16: =+SUM(F9:F15) -> 35.146988 | G16: =IF(F16<=0,0,H16/F16) -> 1940.0612 | H16: =+SUM(H9:H15) -> 68187.309 | I16: =+SUM(I9:I15) -> 36.048193 | J16: =IF(I16<=0,0,K16/I16) -> 1940.0612 | K16: =+SUM(K9:K15) -> 69935.701 | L16: =+SUM(L9:L15) -> 66.689157 | M16: =IF(L16<=0,0,N16/L16) -> 1940.0612 | N16: =+SUM(N9:N15) -> 129381.05 | O16: =+SUM(O9:O15) -> 73.898795 | P16: =IF(O16<=0,0,Q16/O16) -> 1940.0612 | Q16: =+SUM(Q9:Q15) -> 143368.19 | R16: =+SUM(R9:R15) -> 86.515663 | S16: =IF(R16<=0,0,T16/R16) -> 1940.0612 | T16: =+SUM(T9:T15) -> 167845.68 | U16: =+SUM(U9:U15) -> 66.689157 | V16: =IF(U16<=0,0,W16/U16) -> 1940.0612 | W16: =+SUM(W9:W15) -> 129381.05 | X16: =+SUM(X9:X15) -> 76.60241 | Y16: =IF(X16<=0,0,Z16/X16) -> 1940.0612 | Z16: =+SUM(Z9:Z15) -> 148613.37 | AA16: =+SUM(AA9:AA15) -> 73.898795 | AB16: =IF(AA16<=0,0,AC16/AA16) -> 1940.0612 | AC16: =+SUM(AC9:AC15) -> 143368.19 | AD16: =+SUM(AD9:AD15) -> 64.886747 | AE16: =IF(AD16<=0,0,AF16/AD16) -> 1940.0612 | AF16: =+SUM(AF9:AF15) -> 125884.26 | AG16: =+SUM(AG9:AG15) -> 69.392771 | AH16: =IF(AG16<=0,0,AI16/AG16) -> 1940.0612 | AI16: =+SUM(AI9:AI15) -> 134626.22 | AJ16: =+SUM(AJ9:AJ15) -> 62.183133 | AK16: =IF(AJ16<=0,0,AL16/AJ16) -> 1940.0612 | AL16: =+SUM(AL9:AL15) -> 120639.08 | AM16: =+SUM(AM9:AM15) -> 36.048193 | AN16: =IF(AM16<=0,0,AO16/AM16) -> 1940.0612 | AO16: =+SUM(AO9:AO15) -> 69935.701
A17: =+$C$4&B17 -> Véhicules neufs
A18: =+$C$4&B18 -> Véhicules neufsEx-Démos et courtoisies | B18: Ex-Démos et courtoisies | C18: =+SUM(F18,I18,L18,O18,R18,U18,X18,AA18,AD18,AG18,AJ18,AM18) -> 70 | D18: =IF(C18=0,0,E18/C18) -> 1386.1016 | E18: =+SUM(H18,K18,N18,Q18,T18,W18,Z18,AC18,AF18,AI18,AL18,AO18) -> 97027.113 | F18: 3.2891566 | G18: =IF(F18=0,0,H18/F18) -> 1386.1016 | H18: 4559.1053 | I18: 3.373494 | J18: =IF(I18=0,0,K18/I18) -> 1386.1016 | K18: 4676.0055 | L18: 6.2409639 | M18: =IF(L18=0,0,N18/L18) -> 1386.1016 | N18: 8650.6101 | O18: 6.9156627 | P18: =IF(O18=0,0,Q18/O18) -> 1386.1016 | Q18: 9585.8112 | R18: 8.0963855 | S18: =IF(R18=0,0,T18/R18) -> 1386.1016 | T18: 11222.413 | U18: 6.2409639 | V18: =IF(U18=0,0,W18/U18) -> 1386.1016 | W18: 8650.6101 | X18: 7.1686747 | Y18: =IF(X18=0,0,Z18/X18) -> 1386.1016 | Z18: 9936.5116 | AA18: 6.9156627 | AB18: =IF(AA18=0,0,AC18/AA18) -> 1386.1016 | AC18: 9585.8112 | AD18: 6.0722892 | AE18: =IF(AD18=0,0,AF18/AD18) -> 1386.1016 | AF18: 8416.8098 | AG18: 6.4939759 | AH18: =IF(AG18=0,0,AI18/AG18) -> 1386.1016 | AI18: 9001.3105 | AJ18: 5.8192771 | AK18: =IF(AJ18=0,0,AL18/AJ18) -> 1386.1016 | AL18: 8066.1094 | AM18: 3.373494 | AN18: =IF(AM18=0,0,AO18/AM18) -> 1386.1016 | AO18: 4676.0055
A19: =+$C$4&B19 -> Véhicules neufs
A20: =+$C$4&B20 -> Véhicules neufsFlottes | B20: Flottes | C20: =+SUM(F20,I20,L20,O20,R20,U20,X20,AA20,AD20,AG20,AJ20,AM20) -> 12 | D20: =IF(C20=0,0,E20/C20) -> 1938.8732 | E20: =+SUM(H20,K20,N20,Q20,T20,W20,Z20,AC20,AF20,AI20,AL20,AO20) -> 23266.478 | F20: 0 | G20: =IF(F20=0,0,H20/F20) -> 0 | H20: 0 | I20: 0.6068268 | J20: =IF(I20=0,0,K20/I20) -> 1938.8732 | K20: 1176.5602 | L20: 1.1226296 | M20: =IF(L20=0,0,N20/L20) -> 1938.8732 | N20: 2176.6364 | O20: 1.2439949 | P20: =IF(O20=0,0,Q20/O20) -> 1938.8732 | Q20: 2411.9484 | R20: 1.4563843 | S20: =IF(R20=0,0,T20/R20) -> 1938.8732 | T20: 2823.7445 | U20: 1.1226296 | V20: =IF(U20=0,0,W20/U20) -> 1938.8732 | W20: 2176.6364 | X20: 1.289507 | Y20: =IF(X20=0,0,Z20/X20) -> 1938.8732 | Z20: 2500.1904 | AA20: 1.2439949 | AB20: =IF(AA20=0,0,AC20/AA20) -> 1938.8732 | AC20: 2411.9484 | AD20: 1.0922882 | AE20: =IF(AD20=0,0,AF20/AD20) -> 1938.8732 | AF20: 2117.8084 | AG20: 1.1681416 | AH20: =IF(AG20=0,0,AI20/AG20) -> 1938.8732 | AI20: 2264.8784 | AJ20: 1.0467762 | AK20: =IF(AJ20=0,0,AL20/AJ20) -> 1938.8732 | AL20: 2029.5663 | AM20: 0.6068268 | AN20: =IF(AM20=0,0,AO20/AM20) -> 1938.8732 | AO20: 1176.5602
A21: =+$C$4&B21 -> Véhicules neufs
A22: =+$C$4&B22 -> Véhicules neufsRachat bail | B22: Rachat bail | E22: =+SUM(H22,K22,N22,Q22,T22,W22,Z22,AC22,AF22,AI22,AL22,AO22) -> 70133.658 | H22: 3506.6829 | K22: 3506.6829 | N22: 8416.039 | Q22: 8416.039 | T22: 8416.039 | W22: 8416.039 | Z22: 7013.3658 | AC22: 4909.3561 | AF22: 4909.3561 | AI22: 4208.0195 | AL22: 4208.0195 | AO22: 4208.0195
A23: =+$C$4&B23 -> Véhicules neufs
A24: =+$C$4&B24 -> Véhicules neufsRev. Finances | B24: Rev. Finances | D24: =IF(C16=0,0,E24/(C16+C18)) -> 29.923763 | E24: =+SUM(H24,K24,N24,Q24,T24,W24,Z24,AC24,AF24,AI24,AL24,AO24) -> 24477.638 | G24: =IF(F16=0,0,H24/(F16+F18)) -> 29.923763 | H24: 1150.1541 | J24: =IF(I16=0,0,K24/(I16+I18)) -> 29.923763 | K24: 1179.6452 | M24: =IF(L16=0,0,N24/(L16+L18)) -> 29.923763 | N24: 2182.3436 | P24: =IF(O16=0,0,Q24/(O16+O18)) -> 29.923763 | Q24: 2418.2727 | S24: =IF(R16=0,0,T24/(R16+R18)) -> 29.923763 | T24: 2831.1485 | V24: =IF(U16=0,0,W24/(U16+U18)) -> 29.923763 | W24: 2182.3436 | Y24: =IF(X16=0,0,Z24/(X16+X18)) -> 29.923763 | Z24: 2506.7461 | AB24: =IF(AA16=0,0,AC24/(AA16+AA18)) -> 29.923763 | AC24: 2418.2727 | AE24: =IF(AD16=0,0,AF24/(AD16+AD18)) -> 29.923763 | AF24: 2123.3614 | AH24: =IF(AG16=0,0,AI24/(AG16+AG18)) -> 29.923763 | AI24: 2270.817 | AK24: =IF(AJ16=0,0,AL24/(AJ16+AJ18)) -> 29.923763 | AL24: 2034.888 | AN24: =IF(AM16=0,0,AO24/(AM16+AM18)) -> 29.923763 | AO24: 1179.6452
A25: =+$C$4&B25 -> Véhicules neufsRev. Protections | B25: Rev. Protections | D25: =IF(C16=0,0,E25/(C16+C18)) -> 800.26939 | E25: =+SUM(H25,K25,N25,Q25,T25,W25,Z25,AC25,AF25,AI25,AL25,AO25) -> 654620.36 | G25: =IF(F16=0,0,H25/(F16+F18)) -> 800.26939 | H25: 30759.27 | J25: =IF(I16=0,0,K25/(I16+I18)) -> 800.26939 | K25: 31547.969 | M25: =IF(L16=0,0,N25/(L16+L18)) -> 800.26939 | N25: 58363.743 | P25: =IF(O16=0,0,Q25/(O16+O18)) -> 800.26939 | Q25: 64673.337 | S25: =IF(R16=0,0,T25/(R16+R18)) -> 800.26939 | T25: 75715.126 | V25: =IF(U16=0,0,W25/(U16+U18)) -> 800.26939 | W25: 58363.743 | Y25: =IF(X16=0,0,Z25/(X16+X18)) -> 800.26939 | Z25: 67039.434 | AB25: =IF(AA16=0,0,AC25/(AA16+AA18)) -> 800.26939 | AC25: 64673.337 | AE25: =IF(AD16=0,0,AF25/(AD16+AD18)) -> 800.26939 | AF25: 56786.344 | AH25: =IF(AG16=0,0,AI25/(AG16+AG18)) -> 800.26939 | AI25: 60729.841 | AK25: =IF(AJ16=0,0,AL25/(AJ16+AJ18)) -> 800.26939 | AL25: 54420.247 | AN25: =IF(AM16=0,0,AO25/(AM16+AM18)) -> 800.26939 | AO25: 31547.969
A26: =+$C$4&B26 -> Véhicules neufsRev. Autres | B26: Rev. Autres | D26: =IF(C16=0,0,E26/(C16+C18)) -> 19.806849 | E26: =+SUM(H26,K26,N26,Q26,T26,W26,Z26,AC26,AF26,AI26,AL26,AO26) -> 16202.003 | G26: =IF(F16=0,0,H26/(F16+F18)) -> 19.806849 | H26: 761.29892 | J26: =IF(I16=0,0,K26/(I16+I18)) -> 19.806849 | K26: 780.8194 | M26: =IF(L16=0,0,N26/(L16+L18)) -> 19.806849 | N26: 1444.5159 | P26: =IF(O16=0,0,Q26/(O16+O18)) -> 19.806849 | Q26: 1600.6798 | S26: =IF(R16=0,0,T26/(R16+R18)) -> 19.806849 | T26: 1873.9666 | V26: =IF(U16=0,0,W26/(U16+U18)) -> 19.806849 | W26: 1444.5159 | Y26: =IF(X16=0,0,Z26/(X16+X18)) -> 19.806849 | Z26: 1659.2412 | AB26: =IF(AA16=0,0,AC26/(AA16+AA18)) -> 19.806849 | AC26: 1600.6798 | AE26: =IF(AD16=0,0,AF26/(AD16+AD18)) -> 19.806849 | AF26: 1405.4749 | AH26: =IF(AG16=0,0,AI26/(AG16+AG18)) -> 19.806849 | AI26: 1503.0774 | AK26: =IF(AJ16=0,0,AL26/(AJ16+AJ18)) -> 19.806849 | AL26: 1346.9135 | AN26: =IF(AM16=0,0,AO26/(AM16+AM18)) -> 19.806849 | AO26: 780.8194
A27: =+$C$4&B27 -> Véhicules neufsTotal F&I | B27: Total F&I | C27: =+C18+C16 -> 818 | D27: =IF(C27<=0,0,E27/C27) -> 850 | E27: =E24+E25+E26 -> 695300 | F27: =+F18+F16 -> 38.436145 | G27: =IF(F27<=0,0,H27/F27) -> 850 | H27: =H24+H25+H26 -> 32670.723 | I27: =+I18+I16 -> 39.421687 | J27: =IF(I27<=0,0,K27/I27) -> 850 | K27: =K24+K25+K26 -> 33508.434 | L27: =+L18+L16 -> 72.93012 | M27: =IF(L27<=0,0,N27/L27) -> 850 | N27: =N24+N25+N26 -> 61990.602 | O27: =+O18+O16 -> 80.814458 | P27: =IF(O27<=0,0,Q27/O27) -> 850 | Q27: =Q24+Q25+Q26 -> 68692.289 | R27: =+R18+R16 -> 94.612048 | S27: =IF(R27<=0,0,T27/R27) -> 850 | T27: =T24+T25+T26 -> 80420.241 | U27: =+U18+U16 -> 72.93012 | V27: =IF(U27<=0,0,W27/U27) -> 850 | W27: =W24+W25+W26 -> 61990.602 | X27: =+X18+X16 -> 83.771084 | Y27: =IF(X27<=0,0,Z27/X27) -> 850 | Z27: =Z24+Z25+Z26 -> 71205.422 | AA27: =+AA18+AA16 -> 80.814458 | AB27: =IF(AA27<=0,0,AC27/AA27) -> 850 | AC27: =AC24+AC25+AC26 -> 68692.289 | AD27: =+AD18+AD16 -> 70.959036 | AE27: =IF(AD27<=0,0,AF27/AD27) -> 850 | AF27: =AF24+AF25+AF26 -> 60315.181 | AG27: =+AG18+AG16 -> 75.886747 | AH27: =IF(AG27<=0,0,AI27/AG27) -> 850 | AI27: =AI24+AI25+AI26 -> 64503.735 | AJ27: =+AJ18+AJ16 -> 68.00241 | AK27: =IF(AJ27<=0,0,AL27/AJ27) -> 850 | AL27: =AL24+AL25+AL26 -> 57802.048 | AM27: =+AM18+AM16 -> 39.421687 | AN27: =IF(AM27<=0,0,AO27/AM27) -> 850 | AO27: =AO24+AO25+AO26 -> 33508.434
A28: =+$C$4&B28 -> Véhicules neufs
A29: =+$C$4&B29 -> Véhicules neufs
