Workbook
Name Ticker: #REF!

Sheet Parametres
A1: Compagnie | B1: Volks
G2: 1-Mémo | M2: Mois | N2: YTD
A3: Mois Courant | B3: Novembre | C3: =+VLOOKUP(B3,$K$3:$L$14,2,0) -> 11 | G3: 10-Compte compteur | K3: Janvier | L3: 1 | M3: =+IF($K3=$B$3,"X","") | N3: =+IF(K3=B3,"X",IF(L3<=$C$3,"X","")) -> X
A4: Année | B4: 2023 | K4: Février | L4: 2 | M4: =+IF($K4=$B$3,"X","") | N4: =+IF(K4=B4,"X",IF(L4<=$C$3,"X","")) -> X
K5: Mars | L5: 3 | M5: =+IF($K5=$B$3,"X","") | N5: =+IF(K5=B5,"X",IF(L5<=$C$3,"X","")) -> X
K6: Avril | L6: 4 | M6: =+IF($K6=$B$3,"X","") | N6: =+IF(K6=B6,"X",IF(L6<=$C$3,"X","")) -> X
K7: Mai | L7: 5 | M7: =+IF($K7=$B$3,"X","") | N7: =+IF(K7=B7,"X",IF(L7<=$C$3,"X","")) -> X
K8: Juin | L8: 6 | M8: =+IF($K8=$B$3,"X","") | N8: =+IF(K8=B8,"X",IF(L8<=$C$3,"X","")) -> X
A9: Sélectionner le mois en B3 | K9: Juillet | L9: 7 | M9: =+IF($K9=$B$3,"X","") | N9: =+IF(K9=B9,"X",IF(L9<=$C$3,"X","")) -> X
A10: Coller les balances de vérification respectives en cellule A1 dans les onglets BV_Data_An_Cour et BV_Data_An_Prec | K10: Août | L10: 8 | M10: =+IF($K10=$B$3,"X","") | N10: =+IF(K10=B10,"X",IF(L10<=$C$3,"X","")) -> X
A11: Vérifier s'il y a des #N/A dans les colonnes T à X des onlgets de BV | K11: Septembre | L11: 9 | M11: =+IF($K11=$B$3,"X","") | N11: =+IF(K11=B11,"X",IF(L11<=$C$3,"X","")) -> X
A12: Vérifier les chiffres avec l'état financier et les réalisés an passé pour les résultat net mois et aad | K12: Octobre | L12: 10 | M12: =+IF($K12=$B$3,"X","") | N12: =+IF(K12=B12,"X",IF(L12<=$C$3,"X","")) -> X
K13: Novembre | L13: 11 | M13: =+IF($K13=$B$3,"X","") -> X | N13: =+IF(K13=B13,"X",IF(L13<=$C$3,"X","")) -> X
K14: Décembre | L14: 12 | M14: =+IF($K14=$B$3,"X","") | N14: =+IF(K14=B14,"X",IF(L14<=$C$3,"X",""))

Sheet Bilan
A1: BILAN
A2: =+Parametres!B1 -> Volks
A3: =CONCATENATE("",,Parametres!B3," ",Parametres!B4) -> Novembre 2023
A5: Encaisse | B5: =SUMIFS(BV_Data_An_Cour!$P:$P,BV_Data_An_Cour!$U:$U,$A$1,BV_Data_An_Cour!$V:$V,$A5) -> -200594.14 | D5: Marge de crédit | E5: =-SUMIFS(BV_Data_An_Cour!$P:$P,BV_Data_An_Cour!$U:$U,$A$1,BV_Data_An_Cour!$V:$V,$D5) -> 0
A6: Total Trésorerie et équivalent de Trésorerie | B6: =SUM(B5) -> -200594.14
D7: Portion Court Terme de la Dette Long Terme | E7: =-SUMIFS(BV_Data_An_Cour!$P:$P,BV_Data_An_Cour!$U:$U,$A$1,BV_Data_An_Cour!$V:$V,$D7) -> 0
A8: Recevables Contrats en Transit | B8: =SUMIFS(BV_Data_An_Cour!$P:$P,BV_Data_An_Cour!$U:$U,$A$1,BV_Data_An_Cour!$V:$V,$A8) -> 2274657.7
A9: Recevables Véhicules | B9: =SUMIFS(BV_Data_An_Cour!$P:$P,BV_Data_An_Cour!$U:$U,$A$1,BV_Data_An_Cour!$V:$V,$A9) -> 369958.83 | D9: Avances à payer | E9: =-SUMIFS(BV_Data_An_Cour!$P:$P,BV_Data_An_Cour!$U:$U,$A$1,BV_Data_An_Cour!$V:$V,$D9) -> 0
A10: Recevables Manufacturier | B10: =SUMIFS(BV_Data_An_Cour!$P:$P,BV_Data_An_Cour!$U:$U,$A$1,BV_Data_An_Cour!$V:$V,$A10) -> 130525.34 | D10: Comptes à Payer Fournisseurs | E10: =-SUMIFS(BV_Data_An_Cour!$P:$P,BV_Data_An_Cour!$U:$U,$A$1,BV_Data_An_Cour!$V:$V,$D10) -> 890962.02
A11: Recevables Pièces et Service | B11: =SUMIFS(BV_Data_An_Cour!$P:$P,BV_Data_An_Cour!$U:$U,$A$1,BV_Data_An_Cour!$V:$V,$A11) -> 161189.93 | D11: Taxes de Vente à Payer | E11: =-SUMIFS(BV_Data_An_Cour!$P:$P,BV_Data_An_Cour!$U:$U,$A$1,BV_Data_An_Cour!$V:$V,$D11) -> -60578.39
A12: Recevables Garantie Manufacturier | B12: =SUMIFS(BV_Data_An_Cour!$P:$P,BV_Data_An_Cour!$U:$U,$A$1,BV_Data_An_Cour!$V:$V,$A12) -> 31356.42 | D12: Impôts à payer | E12: =-SUMIFS(BV_Data_An_Cour!$P:$P,BV_Data_An_Cour!$U:$U,$A$1,BV_Data_An_Cour!$V:$V,$D12) -> 0
A13: Recevables Carrosserie | B13: =SUMIFS(BV_Data_An_Cour!$P:$P,BV_Data_An_Cour!$U:$U,$A$1,BV_Data_An_Cour!$V:$V,$A13) -> 37776.63 | D13: Dépôts de Client | E13: =-SUMIFS(BV_Data_An_Cour!$P:$P,BV_Data_An_Cour!$U:$U,$A$1,BV_Data_An_Cour!$V:$V,$D13) -> 24850
A14: Recevables Intercos | B14: =SUMIFS(BV_Data_An_Cour!$P:$P,BV_Data_An_Cour!$U:$U,$A$1,BV_Data_An_Cour!$V:$V,$A14) -> 42752.14 | D14: Payables Intercos | E14: =-SUMIFS(BV_Data_An_Cour!$P:$P,BV_Data_An_Cour!$U:$U,$A$1,BV_Data_An_Cour!$V:$V,$D14) -> 84906.93
A15: Recevables Autres | B15: =SUMIFS(BV_Data_An_Cour!$P:$P,BV_Data_An_Cour!$U:$U,$A$1,BV_Data_An_Cour!$V:$V,$A15) -> 49133 | D15: Autres Comptes à Payer | E15: =-SUMIFS(BV_Data_An_Cour!$P:$P,BV_Data_An_Cour!$U:$U,$A$1,BV_Data_An_Cour!$V:$V,$D15) -> 414000.94
A16: Total Comptes à Recevoir | B16: =+SUM(B8:B15) -> 3097350 | D16: Total Comptes à Payer | E16: =+SUM(E10:E15) -> 1354141.5
A18: Inventaire Véhicules Neufs | B18: =SUMIFS(BV_Data_An_Cour!$P:$P,BV_Data_An_Cour!$U:$U,$A$1,BV_Data_An_Cour!$V:$V,$A18) -> 3242138.3 | D18: Effet à Payer Véhicules Neufs | E18: =-SUMIFS(BV_Data_An_Cour!$P:$P,BV_Data_An_Cour!$U:$U,$A$1,BV_Data_An_Cour!$V:$V,$D18) -> 4472488.5
A19: Inventaire Véhicules Usagés | B19: =SUMIFS(BV_Data_An_Cour!$P:$P,BV_Data_An_Cour!$U:$U,$A$1,BV_Data_An_Cour!$V:$V,$A19) -> 2176291.1 | D19: Effet à Payer Véhicules Usagés | E19: =-SUMIFS(BV_Data_An_Cour!$P:$P,BV_Data_An_Cour!$U:$U,$A$1,BV_Data_An_Cour!$V:$V,$D19) -> 362813.1
A20: Inventaire Pièces, Pneus, Huile | B20: =SUMIFS(BV_Data_An_Cour!$P:$P,BV_Data_An_Cour!$U:$U,$A$1,BV_Data_An_Cour!$V:$V,$A20) -> 518591.98 | D20: Total Effets à Payer | E20: =+SUM(E18:E19) -> 4835301.6
A21: Total Inventaires | B21: =SUM(B18:B20) -> 5937021.4
D22: Salaires à Payer | E22: =-SUMIFS(BV_Data_An_Cour!$P:$P,BV_Data_An_Cour!$U:$U,$A$1,BV_Data_An_Cour!$V:$V,$D22) -> 404245.67
A23: Avances à recevoir | B23: =SUMIFS(BV_Data_An_Cour!$P:$P,BV_Data_An_Cour!$U:$U,$A$1,BV_Data_An_Cour!$V:$V,$A23) -> 0 | D23: DAS à Payer | E23: =-SUMIFS(BV_Data_An_Cour!$P:$P,BV_Data_An_Cour!$U:$U,$A$1,BV_Data_An_Cour!$V:$V,$D23) -> 5096.64
A24: Travaux en Cours | B24: =SUMIFS(BV_Data_An_Cour!$P:$P,BV_Data_An_Cour!$U:$U,$A$1,BV_Data_An_Cour!$V:$V,$A24) -> 9673.17 | D24: Autres Courus | E24: =-SUMIFS(BV_Data_An_Cour!$P:$P,BV_Data_An_Cour!$U:$U,$A$1,BV_Data_An_Cour!$V:$V,$D24) -> 360677.37
A25: Sous-Traitance | B25: =SUMIFS(BV_Data_An_Cour!$P:$P,BV_Data_An_Cour!$U:$U,$A$1,BV_Data_An_Cour!$V:$V,$A25) -> -21051.46 | D25: [...] | E25: =-SUMIFS(BV_Data_An_Cour!$P:$P,BV_Data_An_Cour!$U:$U,$A$1,BV_Data_An_Cour!$V:$V,$D25) -> 0
A26: Frais Payés d'Avance | B26: =SUMIFS(BV_Data_An_Cour!$P:$P,BV_Data_An_Cour!$U:$U,$A$1,BV_Data_An_Cour!$V:$V,$A26) -> 84938.62 | D26: [...] | E26: =-SUMIFS(BV_Data_An_Cour!$P:$P,BV_Data_An_Cour!$U:$U,$A$1,BV_Data_An_Cour!$V:$V,$D26) -> 0
A27: [...] | B27: =SUMIFS(BV_Data_An_Cour!$P:$P,BV_Data_An_Cour!$U:$U,$A$1,BV_Data_An_Cour!$V:$V,$A27) -> 0 | D27: [...] | E27: =-SUMIFS(BV_Data_An_Cour!$P:$P,BV_Data_An_Cour!$U:$U,$A$1,BV_Data_An_Cour!$V:$V,$D27) -> 0
A28: [...] | B28: =SUMIFS(BV_Data_An_Cour!$P:$P,BV_Data_An_Cour!$U:$U,$A$1,BV_Data_An_Cour!$V:$V,$A28) -> 0 | D28: Total Frais Courus | E28: =SUM(E22:E24) -> 770019.68
A29: [...] | B29: =SUMIFS(BV_Data_An_Cour!$P:$P,BV_Data_An_Cour!$U:$U,$A$1,BV_Data_An_Cour!$V:$V,$A29) -> 0
A30: Total Autres | B30: =SUM(B23:B29) -> 73560.33 | D30: Total Passif Court Terme | E30: =+E5+E7+E16+E20+E28 -> 6959462.8
A32: Total Actif Court Terme | B32: =+B6+B16+B21+B30 -> 8907337.6
D33: Impôts Futurs à payer | E33: =-SUMIFS(BV_Data_An_Cour!$P:$P,BV_Data_An_Cour!$U:$U,$A$1,BV_Data_An_Cour!$V:$V,$D33) -> 0
A35: Terrain | B35: =SUMIFS(BV_Data_An_Cour!$P:$P,BV_Data_An_Cour!$U:$U,$A$1,BV_Data_An_Cour!$V:$V,$A35) -> 0 | D35: Avances Long Terme à Payer | E35: =-SUMIFS(BV_Data_An_Cour!$P:$P,BV_Data_An_Cour!$U:$U,$A$1,BV_Data_An_Cour!$V:$V,$D35) -> 0
A36: Bâtisse | B36: =SUMIFS(BV_Data_An_Cour!$P:$P,BV_Data_An_Cour!$U:$U,$A$1,BV_Data_An_Cour!$V:$V,$A36) -> 0 | D36: Hypothèque à Payer | E36: =-SUMIFS(BV_Data_An_Cour!$P:$P,BV_Data_An_Cour!$U:$U,$A$1,BV_Data_An_Cour!$V:$V,$D36) -> 0
A37: Améliorations Locatives | B37: =SUMIFS(BV_Data_An_Cour!$P:$P,BV_Data_An_Cour!$U:$U,$A$1,BV_Data_An_Cour!$V:$V,$A37) -> 609212.17 | D37: Dette à Long Terme | E37: =-SUMIFS(BV_Data_An_Cour!$P:$P,BV_Data_An_Cour!$U:$U,$A$1,BV_Data_An_Cour!$V:$V,$D37) -> 0
A38: Améliorations Locatives Permanentes | B38: =SUMIFS(BV_Data_An_Cour!$P:$P,BV_Data_An_Cour!$U:$U,$A$1,BV_Data_An_Cour!$V:$V,$A38) -> 0 | D38: Autres Dettes à Long Terme | E38: =-SUMIFS(BV_Data_An_Cour!$P:$P,BV_Data_An_Cour!$U:$U,$A$1,BV_Data_An_Cour!$V:$V,$D38) -> 0
A39: Équipements Service | B39: =SUMIFS(BV_Data_An_Cour!$P:$P,BV_Data_An_Cour!$U:$U,$A$1,BV_Data_An_Cour!$V:$V,$A39) -> 272626.94 | D39: [...] | E39: =-SUMIFS(BV_Data_An_Cour!$P:$P,BV_Data_An_Cour!$U:$U,$A$1,BV_Data_An_Cour!$V:$V,$D39) -> 0
A40: Mobilier | B40: =SUMIFS(BV_Data_An_Cour!$P:$P,BV_Data_An_Cour!$U:$U,$A$1,BV_Data_An_Cour!$V:$V,$A40) -> 26298.79 | D40: [...] | E40: =-SUMIFS(BV_Data_An_Cour!$P:$P,BV_Data_An_Cour!$U:$U,$A$1,BV_Data_An_Cour!$V:$V,$D40) -> 0
A41: Équipements Informatique | B41: =SUMIFS(BV_Data_An_Cour!$P:$P,BV_Data_An_Cour!$U:$U,$A$1,BV_Data_An_Cour!$V:$V,$A41) -> 17785.24 | D41: [...] | E41: =-SUMIFS(BV_Data_An_Cour!$P:$P,BV_Data_An_Cour!$U:$U,$A$1,BV_Data_An_Cour!$V:$V,$D41) -> 0
A42: Équipements Téléphonique | B42: =SUMIFS(BV_Data_An_Cour!$P:$P,BV_Data_An_Cour!$U:$U,$A$1,BV_Data_An_Cour!$V:$V,$A42) -> 0 | D42: Total Passif long terme | E42: =+SUM(E33:E38) -> 0
A43: Enseigne | B43: =SUMIFS(BV_Data_An_Cour!$P:$P,BV_Data_An_Cour!$U:$U,$A$1,BV_Data_An_Cour!$V:$V,$A43) -> 0.01
A44: Total Immobilisations Nettes | B44: =SUM(B35:B43) -> 925923.15
...

Sheet Budget original
B1: ="Budget 2023 Mensuel Révisé"&" "&Parametres!$B$1 -> Budget 2023 Mensuel Révisé Volks
B2: Mois | F2: =+IF(Parametres!$B$3=F$6,"X","") | G2: =+IF(Parametres!$B$3=F$6,"O","") | H2: =+IF(Parametres!$B$3=F$6,"U","") | I2: =+IF(Parametres!$B$3=I$6,"X","") | J2: =+IF(Parametres!$B$3=I$6,"O","") | K2: =+IF(Parametres!$B$3=I$6,"U","") | L2: =+IF(Parametres!$B$3=L$6,"X","") | M2: =+IF(Parametres!$B$3=L$6,"O","") | N2: =+IF(Parametres!$B$3=L$6,"U","") | O2: =+IF(Parametres!$B$3=O$6,"X","") | P2: =+IF(Parametres!$B$3=O$6,"O","") | Q2: =+IF(Parametres!$B$3=O$6,"U","") | R2: =+IF(Parametres!$B$3=R$6,"X","") | S2: =+IF(Parametres!$B$3=R$6,"O","") | T2: =+IF(Parametres!$B$3=R$6,"U","") | U2: =+IF(Parametres!$B$3=U$6,"X","") | V2: =+IF(Parametres!$B$3=U$6,"O","") | W2: =+IF(Parametres!$B$3=U$6,"U","") | X2: =+IF(Parametres!$B$3=X$6,"X","") | Y2: =+IF(Parametres!$B$3=X$6,"O","") | Z2: =+IF(Parametres!$B$3=X$6,"U","") | AA2: =+IF(Parametres!$B$3=AA$6,"X","") | AB2: =+IF(Parametres!$B$3=AA$6,"O","") | AC2: =+IF(Parametres!$B$3=AA$6,"U","") | AD2: =+IF(Parametres!$B$3=AD$6,"X","") | AE2: =+IF(Parametres!$B$3=AD$6,"O","") | AF2: =+IF(Parametres!$B$3=AD$6,"U","") | AG2: =+IF(Parametres!$B$3=AG$6,"X","") | AH2: =+IF(Parametres!$B$3=AG$6,"O","") | AI2: =+IF(Parametres!$B$3=AG$6,"U","") | AJ2: =+IF(Parametres!$B$3=AJ$6,"X","") -> X | AK2: =+IF(Parametres!$B$3=AJ$6,"O","") -> O | AL2: =+IF(Parametres!$B$3=AJ$6,"U","") -> U | AM2: =+IF(Parametres!$B$3=AM$6,"X","") | AN2: =+IF(Parametres!$B$3=AM$6,"O","") | AO2: =+IF(Parametres!$B$3=AM$6,"U","")
B3: YTD | F3: =+IF(VLOOKUP(F$6,Parametres!$K$3:$N$14,4,0)="X","X","") -> X | G3: =+IF(VLOOKUP(F$6,Parametres!$K$3:$N$14,4,0)="X","O","") -> O | H3: =+IF(VLOOKUP(F$6,Parametres!$K$3:$N$14,4,0)="X","U","") -> U | I3: =+IF(VLOOKUP(I$6,Parametres!$K$3:$N$14,4,0)="X","X","") -> X | J3: =+IF(VLOOKUP(I$6,Parametres!$K$3:$N$14,4,0)="X","O","") -> O | K3: =+IF(VLOOKUP(I$6,Parametres!$K$3:$N$14,4,0)="X","U","") -> U | L3: =+IF(VLOOKUP(L$6,Parametres!$K$3:$N$14,4,0)="X","X","") -> X | M3: =+IF(VLOOKUP(L$6,Parametres!$K$3:$N$14,4,0)="X","O","") -> O | N3: =+IF(VLOOKUP(L$6,Parametres!$K$3:$N$14,4,0)="X","U","") -> U | O3: =+IF(VLOOKUP(O$6,Parametres!$K$3:$N$14,4,0)="X","X","") -> X | P3: =+IF(VLOOKUP(O$6,Parametres!$K$3:$N$14,4,0)="X","O","") -> O | Q3: =+IF(VLOOKUP(O$6,Parametres!$K$3:$N$14,4,0)="X","U","") -> U | R3: =+IF(VLOOKUP(R$6,Parametres!$K$3:$N$14,4,0)="X","X","") -> X | S3: =+IF(VLOOKUP(R$6,Parametres!$K$3:$N$14,4,0)="X","O","") -> O | T3: =+IF(VLOOKUP(R$6,Parametres!$K$3:$N$14,4,0)="X","U","") -> U | U3: =+IF(VLOOKUP(U$6,Parametres!$K$3:$N$14,4,0)="X","X","") -> X | V3: =+IF(VLOOKUP(U$6,Parametres!$K$3:$N$14,4,0)="X","O","") -> O | W3: =+IF(VLOOKUP(U$6,Parametres!$K$3:$N$14,4,0)="X","U","") -> U | X3: =+IF(VLOOKUP(X$6,Parametres!$K$3:$N$14,4,0)="X","X","") -> X | Y3: =+IF(VLOOKUP(X$6,Parametres!$K$3:$N$14,4,0)="X","O","") -> O | Z3: =+IF(VLOOKUP(X$6,Parametres!$K$3:$N$14,4,0)="X","U","") -> U | AA3: =+IF(VLOOKUP(AA$6,Parametres!$K$3:$N$14,4,0)="X","X","") -> X | AB3: =+IF(VLOOKUP(AA$6,Parametres!$K$3:$N$14,4,0)="X","O","") -> O | AC3: =+IF(VLOOKUP(AA$6,Parametres!$K$3:$N$14,4,0)="X","U","") -> U | AD3: =+IF(VLOOKUP(AD$6,Parametres!$K$3:$N$14,4,0)="X","X","") -> X | AE3: =+IF(VLOOKUP(AD$6,Parametres!$K$3:$N$14,4,0)="X","O","") -> O | AF3: =+IF(VLOOKUP(AD$6,Parametres!$K$3:$N$14,4,0)="X","U","") -> U | AG3: =+IF(VLOOKUP(AG$6,Parametres!$K$3:$N$14,4,0)="X","X","") -> X | AH3: =+IF(VLOOKUP(AG$6,Parametres!$K$3:$N$14,4,0)="X","O","") -> O | AI3: =+IF(VLOOKUP(AG$6,Parametres!$K$3:$N$14,4,0)="X","U","") -> U | AJ3: =+IF(VLOOKUP(AJ$6,Parametres!$K$3:$N$14,4,0)="X","X","") -> X | AK3: =+IF(VLOOKUP(AJ$6,Parametres!$K$3:$N$14,4,0)="X","O","") -> O | AL3: =+IF(VLOOKUP(AJ$6,Parametres!$K$3:$N$14,4,0)="X","U","") -> U | AM3: =+IF(VLOOKUP(AM$6,Parametres!$K$3:$N$14,4,0)="X","X","") | AN3: =+IF(VLOOKUP(AM$6,Parametres!$K$3:$N$14,4,0)="X","O","") | AO3: =+IF(VLOOKUP(AM$6,Parametres!$K$3:$N$14,4,0)="X","U","")
B4: Budget 2023 | C4: Véhicules neufs
B6: Mois | C6: TOTAL | F6: Janvier | I6: Février | L6: Mars | O6: Avril | R6: Mai | U6: Juin | X6: Juillet | AA6: Août | AD6: Septembre | AG6: Octobre | AJ6: Novembre | AM6: Décembre
C7: UNITE | D7: $P/UNITE | E7: $PROFITS | F7: UNITE | G7: $P/UNITE | H7: $PROFITS | I7: UNITE | J7: $P/UNITE | K7: $PROFITS | L7: UNITE | M7: $P/UNITE | N7: $PROFITS | O7: UNITE | P7: $P/UNITE | Q7: $PROFITS | R7: UNITE | S7: $P/UNITE | T7: $PROFITS | U7: UNITE | V7: $P/UNITE | W7: $PROFITS | X7: UNITE | Y7: $P/UNITE | Z7: $PROFITS | AA7: UNITE | AB7: $P/UNITE | AC7: $PROFITS | AD7: UNITE | AE7: $P/UNITE | AF7: $PROFITS | AG7: UNITE | AH7: $P/UNITE | AI7: $PROFITS | AJ7: UNITE | AK7: $P/UNITE | AL7: $PROFITS | AM7: UNITE | AN7: $P/UNITE | AO7: $PROFITS
A8: =+$C$4&B8 -> Véhicules neufsVentes nettes | B8: Ventes nettes | E8: 29441341 | H8: 2058973.9 | K8: 1513989 | N8: 2694522.6 | Q8: 2946054.1 | T8: 3239507.5 | W8: 2275303.5 | Z8: 2357227.3 | AC8: 2438191.1 | AF8: 2522034.9 | AI8: 2898372.2 | AL8: 3024137.9 | AO8: 1473027.1
A9: =+$C$4&B9 -> Véhicules neufsAutos détail | B9: Autos détail | C9: 125.6 | D9: 1988.434 | E9: 249747.31 | F9: 8.792 | G9: 1988.434 | H9: 17482.312 | I9: 6.4594286 | J9: 1988.434 | K9: 12844.147 | L9: 11.483429 | M9: 1988.434 | N9: 22834.04 | O9: 12.56 | P9: 1988.434 | Q9: 24974.731 | R9: 13.816 | S9: 1988.434 | T9: 27472.204 | U9: 9.6891429 | V9: 1988.434 | W9: 19266.221 | X9: 10.048 | Y9: 1988.434 | Z9: 19979.785 | AA9: 10.406857 | AB9: 1988.434 | AC9: 20693.349 | AD9: 10.765714 | AE9: 1988.434 | AF9: 21406.912 | AG9: 12.380571 | AH9: 1988.434 | AI9: 24617.949 | AJ9: 12.918857 | AK9: 1988.434 | AL9: 25688.295 | AM9: 6.28 | AN9: 1988.434 | AO9: 12487.366
A10: =+$C$4&B10 -> Véhicules neufsCamions détail | B10: Camions détail | C10: 502.34976 | D10: 2556.3336 | E10: 1284173.6 | F10: 35.164483 | G10: 2556.3336 | H10: 89892.151 | I10: 25.835131 | J10: 2556.3336 | K10: 66043.213 | L10: 45.929121 | M10: 2556.3336 | N10: 117410.16 | O10: 50.234976 | P10: 2556.3336 | Q10: 128417.36 | R10: 55.258474 | S10: 2556.3336 | T10: 141259.09 | U10: 38.752696 | V10: 2556.3336 | W10: 99064.82 | X10: 40.187981 | Y10: 2556.3336 | Z10: 102733.89 | AA10: 41.623266 | AB10: 2556.3336 | AC10: 106402.95 | AD10: 43.058551 | AE10: 2556.3336 | AF10: 110072.02 | AG10: 49.517333 | AH10: 2556.3336 | AI10: 126582.83 | AJ10: 51.670261 | AK10: 2556.3336 | AL10: 132086.43 | AM10: 25.117488 | AN10: 2556.3336 | AO10: 64208.679
A11: =+$C$4&B11 -> Véhicules neufsSprinter | B11: Sprinter | C11: 0 | D11: 0 | E11: 0 | G11: 0 | J11: 0 | M11: 0 | P11: 0 | S11: 0 | V11: 0 | Y11: 0 | AB11: 0 | AE11: 0 | AH11: 0 | AK11: 0 | AN11: 0
A12: =+$C$4&B12 -> Véhicules neufsMoto détail | B12: Moto détail | C12: 0 | D12: 0 | E12: 0 | G12: 0 | J12: 0 | M12: 0 | P12: 0 | S12: 0 | V12: 0 | Y12: 0 | AB12: 0 | AE12: 0 | AH12: 0 | AK12: 0 | AN12: 0
A13: =+$C$4&B13 -> Véhicules neufs[...] | B13: [...] | C13: 0 | D13: 0 | E13: 0 | G13: 0 | J13: 0 | M13: 0 | P13: 0 | S13: 0 | V13: 0 | Y13: 0 | AB13: 0 | AE13: 0 | AH13: 0 | AK13: 0 | AN13: 0
A14: =+$C$4&B14 -> Véhicules neufs[...] | B14: [...] | C14: 0 | D14: 0 | E14: 0 | G14: 0 | J14: 0 | M14: 0 | P14: 0 | S14: 0 | V14: 0 | Y14: 0 | AB14: 0 | AE14: 0 | AH14: 0 | AK14: 0 | AN14: 0
A15: =+$C$4&B15 -> Véhicules neufs[...] | B15: [...] | C15: 0 | D15: 0 | E15: 0 | G15: 0 | J15: 0 | M15: 0 | P15: 0 | S15: 0 | V15: 0 | Y15: 0 | AB15: 0 | AE15: 0 | AH15: 0 | AK15: 0 | AN15: 0
A16: =+$C$4&B16 -> Véhicules neufsTotal Neufs | B16: Total Neufs | C16: 627.94976 | D16: 2442.7446 | E16: 1533920.9 | F16: 43.956483 | G16: 2442.7446 | H16: 107374.46 | I16: 32.294559 | J16: 2442.7446 | K16: 78887.36 | L16: 57.412549 | M16: 2442.7446 | N16: 140244.2 | O16: 62.794976 | P16: 2442.7446 | Q16: 153392.09 | R16: 69.074474 | S16: 2442.7446 | T16: 168731.3 | U16: 48.441839 | V16: 2442.7446 | W16: 118331.04 | X16: 50.235981 | Y16: 2442.7446 | Z16: 122713.67 | AA16: 52.030123 | AB16: 2442.7446 | AC16: 127096.3 | AD16: 53.824265 | AE16: 2442.7446 | AF16: 131478.93 | AG16: 61.897905 | AH16: 2442.7446 | AI16: 151200.77 | AJ16: 64.589118 | AK16: 2442.7446 | AL16: 157774.72 | AM16: 31.397488 | AN16: 2442.7446 | AO16: 76696.045
A17: =+$C$4&B17 -> Véhicules neufs
A18: =+$C$4&B18 -> Véhicules neufsEx-Démos et courtoisies | B18: Ex-Démos et courtoisies | C18: 30 | D18: 2442.5492 | E18: 73276.476 | F18: 2.1 | G18: 2442.5492 | H18: 5129.3533 | I18: 1.5428571 | J18: 2442.5492 | K18: 3768.5045 | L18: 2.7428571 | M18: 2442.5492 | N18: 6699.5635 | O18: 3 | P18: 2442.5492 | Q18: 7327.6476 | R18: 3.3 | S18: 2442.5492 | T18: 8060.4124 | U18: 2.3142857 | V18: 2442.5492 | W18: 5652.7567 | X18: 2.4 | Y18: 2442.5492 | Z18: 5862.1181 | AA18: 2.4857143 | AB18: 2442.5492 | AC18: 6071.4794 | AD18: 2.5714286 | AE18: 2442.5492 | AF18: 6280.8408 | AG18: 2.9571429 | AH18: 2442.5492 | AI18: 7222.9669 | AJ18: 3.0857143 | AK18: 2442.5492 | AL18: 7537.009 | AM18: 1.5 | AN18: 2442.5492 | AO18: 3663.8238
A19: =+$C$4&B19 -> Véhicules neufs
A20: =+$C$4&B20 -> Véhicules neufsFlottes | B20: Flottes | C20: 24 | D20: 2442.5492 | E20: 58621.181 | F20: 1.68 | G20: 2442.5492 | H20: 4103.4827 | I20: 1.2342857 | J20: 2442.5492 | K20: 3014.8036 | L20: 2.1942857 | M20: 2442.5492 | N20: 5359.6508 | O20: 2.4 | P20: 2442.5492 | Q20: 5862.1181 | R20: 2.64 | S20: 2442.5492 | T20: 6448.3299 | U20: 1.8514286 | V20: 2442.5492 | W20: 4522.2054 | X20: 1.92 | Y20: 2442.5492 | Z20: 4689.6945 | AA20: 1.9885714 | AB20: 2442.5492 | AC20: 4857.1836 | AD20: 2.0571429 | AE20: 2442.5492 | AF20: 5024.6726 | AG20: 2.3657143 | AH20: 2442.5492 | AI20: 5778.3735 | AJ20: 2.4685714 | AK20: 2442.5492 | AL20: 6029.6072 | AM20: 1.2 | AN20: 2442.5492 | AO20: 2931.059
A21: =+$C$4&B21 -> Véhicules neufs
A22: =+$C$4&B22 -> Véhicules neufsRachat bail | B22: Rachat bail | E22: 96000 | H22: 4800 | K22: 4800 | N22: 11520 | Q22: 11520 | T22: 11520 | W22: 11520 | Z22: 9600 | AC22: 6720 | AF22: 6720 | AI22: 5760 | AL22: 5760 | AO22: 5760
A23: =+$C$4&B23 -> Véhicules neufs
A24: =+$C$4&B24 -> Véhicules neufsRev. Finances | B24: Rev. Finances | D24: 172 | E24: 113167.36 | G24: 172 | H24: 7921.7151 | J24: 172 | K24: 5820.0356 | M24: 172 | N24: 10346.73 | P24: 172 | Q24: 11316.736 | S24: 172 | T24: 12448.409 | V24: 172 | W24: 8730.0534 | Y24: 172 | Z24: 9053.3887 | AB24: 172 | AC24: 9376.724 | AE24: 172 | AF24: 9700.0593 | AH24: 172 | AI24: 11155.068 | AK24: 172 | AL24: 11640.071 | AN24: 172 | AO24: 5658.3679
A25: =+$C$4&B25 -> Véhicules neufsRev. Protections | B25: Rev. Protections | D25: 946 | E25: 622420.47 | G25: 946 | H25: 43569.433 | J25: 946 | K25: 32010.196 | M25: 946 | N25: 56907.015 | P25: 946 | Q25: 62242.047 | S25: 946 | T25: 68466.252 | V25: 946 | W25: 48015.294 | Y25: 946 | Z25: 49793.638 | AB25: 946 | AC25: 51571.982 | AE25: 946 | AF25: 53350.326 | AH25: 946 | AI25: 61352.875 | AK25: 946 | AL25: 64020.392 | AN25: 946 | AO25: 31121.024
A26: =+$C$4&B26 -> Véhicules neufsRev. Autres | B26: Rev. Autres | D26: 29 | E26: 19080.543 | G26: 29 | H26: 1335.638 | J26: 29 | K26: 981.28507 | M26: 29 | N26: 1744.5068 | P26: 29 | Q26: 1908.0543 | S26: 29 | T26: 2098.8597 | V26: 29 | W26: 1471.9276 | Y26: 29 | Z26: 1526.4434 | AB26: 29 | AC26: 1580.9593 | AE26: 29 | AF26: 1635.4751 | AH26: 29 | AI26: 1880.7964 | AK26: 29 | AL26: 1962.5701 | AN26: 29 | AO26: 954.02715
A27: =+$C$4&B27 -> Véhicules neufsTotal F&I | B27: Total F&I | C27: 657.94976 | D27: 1147 | E27: 754668.37 | F27: 46.056483 | G27: 1147 | H27: 52826.786 | I27: 33.837416 | J27: 1147 | K27: 38811.516 | L27: 60.155407 | M27: 1147 | N27: 68998.251 | O27: 65.794976 | P27: 1147 | Q27: 75466.837 | R27: 72.374474 | S27: 1147 | T27: 83013.521 | U27: 50.756124 | V27: 1147 | W27: 58217.275 | X27: 52.635981 | Y27: 1147 | Z27: 60373.47 | AA27: 54.515837 | AB27: 1147 | AC27: 62529.665 | AD27: 56.395694 | AE27: 1147 | AF27: 64685.861 | AG27: 64.855048 | AH27: 1147 | AI27: 74388.74 | AJ27: 67.674832 | AK27: 1147 | AL27: 77623.033 | AM27: 32.897488 | AN27: 1147 | AO27: 37733.419
A28: =+$C$4&B28 -> Véhicules neufs
A29: =+$C$4&B29 -> Véhicules neufs
A30: =+$C$4&B30 -> Véhicules neufsTotal Dépt. Neufs | B30: Total Dépt. Neufs | C30: 681.94976 | D30: 3690.1354 | E30: 2516486.9 | F30: 47.736483 | G30: 3649.9146 | H30: 174234.09 | I30: 35.071702 | J30: 3686.225 | K30: 129282.18 | L30: 62.349692 | M30: 3734.1269 | N30: 232821.66 | O30: 68.194976 | P30: 3718.2899 | Q30: 253568.69 | R30: 75.014474 | S30: 3702.9329 | T30: 277773.56 | U30: 52.607553 | V30: 3768.3425 | W30: 198243.28 | X30: 54.555981 | Y30: 3725.3286 | Z30: 203238.95 | AA30: 56.504409 | AB30: 3668.2913 | AC30: 207274.63 | AD30: 58.452837 | AE30: 3664.327 | AF30: 214190.31 | AG30: 67.220762 | AH30: 3635.0503 | AI30: 244350.85 | AJ30: 70.143404 | AK30: 3631.48 | AL30: 254724.37 | AM30: 34.097488 | AN30: 3718.2899 | AO30: 126784.35
A31: =+$C$4&B31 -> Véhicules neufs
A32: =+$C$4&B32 -> Véhicules neufs
A33: =+$C$4&B33 -> Véhicules neufsDEPENSES | B33: DEPENSES
A34: =+$C$4&B34 -> Véhicules neufsComm. vendeurs | B34: Comm. vendeurs | C34: 0.3141475 | D34: 767.37931 | E34: 504897.03 | F34: 0.32509824 | G34: 794.12907 | H34: 36574.792 | I34: 0.34960605 | J34: 853.99518 | K34: 28896.99 | L34: 0.31057373 | M34: 758.64954 | N34: 45636.872 | O34: 0.30232568 | P34: 738.50173 | Q34: 48589.703 | R34: 0.29885266 | S34: 730.01807 | T34: 52834.674 | U34: 0.32000541 | V34: 781.68863 | W34: 39675.485 | X34: 0.31560967 | Y34: 770.95101 | Z34: 40579.763 | AA34: 0.3169238 | AB34: 774.16109 | AC34: 42204.04 | AD34: 0.31292384 | AE34: 764.39023 | AF34: 43108.317 | AG34: 0.30309576 | AH34: 740.38284 | AI34: 48017.565 | AJ34: 0.30230148 | AK34: 738.44262 | AL34: 49973.981 | AM34: 0.35844822 | AN34: 875.59426 | AO34: 28804.852
A35: =+$C$4&B35 -> Véhicules neufsComm. F&I | B35: Comm. F&I | C35: 0.3 | D35: 344.1 | E35: 226400.51 | F35: 0.3 | G35: 344.1 | H35: 15848.036 | I35: 0.3 | J35: 344.1 | K35: 11643.455 | L35: 0.3 | M35: 344.1 | N35: 20699.475 | O35: 0.3 | P35: 344.1 | Q35: 22640.051 | R35: 0.3 | S35: 344.1 | T35: 24904.056 | U35: 0.3 | V35: 344.1 | W35: 17465.182 | X35: 0.3 | Y35: 344.1 | Z35: 18112.041 | AA35: 0.3 | AB35: 344.1 | AC35: 18758.9 | AD35: 0.3 | AE35: 344.1 | AF35: 19405.758 | AG35: 0.3 | AH35: 344.1 | AI35: 22316.622 | AJ35: 0.3 | AK35: 344.1 | AL35: 23286.91 | AM35: 0.3 | AN35: 344.1 | AO35: 11320.026
A36: =+$C$4&B36 -> Véhicules neufsFrais de livraison | B36: Frais de livraison | D36: 113.25898 | E36: 74518.717 | G36: 113.25898 | H36: 5216.3102 | J36: 113.25898 | K36: 3832.3911 | M36: 113.25898 | N36: 6813.1398 | P36: 113.25898 | Q36: 7451.8717 | S36: 113.25898 | T36: 8197.0588 | V36: 113.25898 | W36: 5748.5867 | Y36: 113.25898 | Z36: 5961.4973 | AB36: 113.25898 | AC36: 6174.4079 | AE36: 113.25898 | AF36: 6387.3186 | AH36: 113.25898 | AI36: 7345.4163 | AK36: 113.25898 | AL36: 7664.7823 | AN36: 113.25898 | AO36: 3725.9358
A37: =+$C$4&B37 -> Véhicules neufsService gratuit 1 | B37: Service gratuit 1 | D37: 5.1177856 | E37: 3367.2458 | G37: 5.1177856 | H37: 235.70721 | J37: 5.1177856 | K37: 173.17264 | M37: 5.1177856 | N37: 307.86248 | P37: 5.1177856 | Q37: 336.72458 | S37: 5.1177856 | T37: 370.39704 | V37: 5.1177856 | W37: 259.75896 | Y37: 5.1177856 | Z37: 269.37967 | AB37: 5.1177856 | AC37: 279.00037 | AE37: 5.1177856 | AF37: 288.62107 | AH37: 5.1177856 | AI37: 331.91423 | AK37: 5.1177856 | AL37: 346.34529 | AN37: 5.1177856 | AO37: 168.36229
A38: =+$C$4&B38 -> Véhicules neufsEntretien stock | B38: Entretien stock | D38: 105.01044 | E38: 69091.596 | G38: 105.01044 | H38: 4836.4117 | J38: 105.01044 | K38: 3553.2821 | M38: 105.01044 | N38: 6316.9459 | P38: 105.01044 | Q38: 6909.1596 | S38: 105.01044 | T38: 7600.0756 | V38: 105.01044 | W38: 5329.9231 | Y38: 105.01044 | Z38: 5527.3277 | AB38: 105.01044 | AC38: 5724.7322 | AE38: 105.01044 | AF38: 5922.1368 | AH38: 105.01044 | AI38: 6810.4573 | AK38: 105.01044 | AL38: 7106.5642 | AN38: 105.01044 | AO38: 3454.5798
A39: =+$C$4&B39 -> Véhicules neufsPublicité 1 | B39: Publicité 1 | D39: 300.75552 | E39: 197882.02 | G39: 300.75552 | H39: 13851.742 | J39: 300.75552 | K39: 10176.79 | M39: 300.75552 | N39: 18092.071 | P39: 300.75552 | Q39: 19788.202 | S39: 300.75552 | T39: 21767.023 | V39: 300.75552 | W39: 15265.185 | Y39: 300.75552 | Z39: 15830.562 | AB39: 300.75552 | AC39: 16395.939 | AE39: 300.75552 | AF39: 16961.316 | AH39: 300.75552 | AI39: 19505.514 | AK39: 300.75552 | AL39: 20353.58 | AN39: 300.75552 | AO39: 9894.1012
A40: =+$C$4&B40 -> Véhicules neufsIntérêt de gros | B40: Intérêt de gros | D40: 52.641607 | E40: 34635.533 | G40: 37.116022 | H40: 1709.4334 | J40: 45.756141 | K40: 1548.2696 | M40: 67.038107 | N40: 4032.7046 | P40: 72.303115 | Q40: 4757.1817 | S40: 52.849132 | T40: 3824.9281 | V40: 45.737234 | W40: 2321.4447 | Y40: 50.687592 | Z40: 2667.9911 | AB40: 53.963736 | AC40: 2941.8783 | AE40: 63.366313 | AF40: 3573.5872 | AH40: 69.534232 | AI40: 4509.6459 | AK40: 31.332422 | AL40: 2120.4164 | AN40: 19.091169 | AO40: 628.05151
A41: =+$C$4&B41 -> Véhicules neufs[...] | B41: [...] | D41: 0 | E41: 0 | G41: 0 | J41: 0 | M41: 0 | P41: 0 | S41: 0 | V41: 0 | Y41: 0 | AB41: 0 | AE41: 0 | AH41: 0 | AK41: 0 | AN41: 0
...

Sheet Capex
A1: PARK AVENUE VOLKSWAGEN | B1: PARK AVENUE VOLKSWAGEN
A2: Forecast Immobilisation 2022 | B2: Forecast Immobilisation 2023 | H2: 1 | I2: 2 | J2: 3 | K2: 4 | L2: 5 | M2: 6 | N2: 7 | O2: 8 | P2: 9 | Q2: 10 | R2: 11 | S2: 12
H3: =+IF(VLOOKUP(H2,Parametres!$L$3:$N$14,3,0)="X","REEL","FORECAST") -> REEL | I3: =+IF(VLOOKUP(I2,Parametres!$L$3:$N$14,3,0)="X","REEL","FORECAST") -> REEL | J3: =+IF(VLOOKUP(J2,Parametres!$L$3:$N$14,3,0)="X","REEL","FORECAST") -> REEL | K3: =+IF(VLOOKUP(K2,Parametres!$L$3:$N$14,3,0)="X","REEL","FORECAST") -> REEL | L3: =+IF(VLOOKUP(L2,Parametres!$L$3:$N$14,3,0)="X","REEL","FORECAST") -> REEL | M3: =+IF(VLOOKUP(M2,Parametres!$L$3:$N$14,3,0)="X","REEL","FORECAST") -> REEL | N3: =+IF(VLOOKUP(N2,Parametres!$L$3:$N$14,3,0)="X","REEL","FORECAST") -> REEL | O3: =+IF(VLOOKUP(O2,Parametres!$L$3:$N$14,3,0)="X","REEL","FORECAST") -> REEL | ... S3: =+IF(VLOOKUP(S2,Parametres!$L$3:$N$14,3,0)="X","REEL","FORECAST") -> FORECAST
A4: Concession | B4: Budgété / Non budgété | C4: Projet | D4: Catégorie Immo | E4: Total forecast | F4: Budget Annuel | G4: Écart vs budget | H4: January | I4: February | J4: March | K4: April | L4: May | M4: June | N4: July | O4: August | P4: September | Q4: October | R4: November | S4: December | T4: Raison / Description
C5: Total | E5: =+SUM(E6:E20) -> 178764.31 | F5: =+SUM(F6:F20) -> 10000 | G5: =+SUM(G6:G20) -> 168764.31 | H5: =+SUM(H6:H20) -> 759.98 | I5: =+SUM(I6:I20) -> 0 | J5: =+SUM(J6:J20) -> 30333.84 | K5: =+SUM(K6:K20) -> 4403.25 | L5: =+SUM(L6:L20) -> 2714.93 | ... S5: =+SUM(S6:S20) -> 0 | X5: Terrain
A6: =+Parametres!$B$1 -> Volks | B6: oui | C6: Outils Spécialisés Volks | D6: Mobilier | E6: =+SUM(H6:S6) -> 48837.92 | F6: 10000 | G6: =+E6-F6 -> 38837.92 | J6: 19223.83 | P6: 3049.1 | R6: 26564.99 | X6: Bâtisse
A7: =+Parametres!$B$1 -> Volks | B7: non | C7: Reparation immeuble | D7: Améliorations Locatives | E7: =+SUM(H7:S7) -> 10527.65 | G7: =+E7-F7 -> 10527.65 | J7: 8802.13 | K7: 1725.52 | X7: Améliorations Locatives
A8: =+Parametres!$B$1 -> Volks | B8: non | C8: Equipement informatique | D8: Équipements Informatique | E8: =+SUM(H8:S8) -> 12960.52 | G8: =+E8-F8 -> 12960.52 | H8: 759.98 | J8: 2307.88 | K8: 2677.73 | L8: 2714.93 | O8: 4500 | X8: Mobilier
A9: =+Parametres!$B$1 -> Volks | B9: non | C9: Machine a pneus et balanceur | D9: Équipements Service | E9: =+SUM(H9:S9) -> 106438.22 | G9: =+E9-F9 -> 106438.22 | Q9: 106438.22 | X9: Équipements Informatique
A10: =+Parametres!$B$1 -> Volks | B10: non | E10: =+SUM(H10:S10) -> 0 | G10: =+E10-F10 -> 0 | X10: Équipements Téléphonique
A11: =+Parametres!$B$1 -> Volks | B11: non | E11: =+SUM(H11:S11) -> 0 | G11: =+E11-F11 -> 0 | X11: Enseigne
A12: =+Parametres!$B$1 -> Volks | B12: non | E12: =+SUM(H12:S12) -> 0 | G12: =+E12-F12 -> 0
A13: =+Parametres!$B$1 -> Volks | B13: non | E13: =+SUM(H13:S13) -> 0 | G13: =+E13-F13 -> 0
A14: =+Parametres!$B$1 -> Volks | B14: non | E14: =+SUM(H14:S14) -> 0 | G14: =+E14-F14 -> 0
A15: =+Parametres!$B$1 -> Volks | B15: non | E15: =+SUM(H15:S15) -> 0 | G15: =+E15-F15 -> 0
A16: =+Parametres!$B$1 -> Volks | B16: non | E16: =+SUM(H16:S16) -> 0 | G16: =+E16-F16 -> 0
A17: =+Parametres!$B$1 -> Volks | B17: non | E17: =+SUM(H17:S17) -> 0 | G17: =+E17-F17 -> 0 | X17: non
A18: =+Parametres!$B$1 -> Volks | B18: non | E18: =+SUM(H18:S18) -> 0 | G18: =+E18-F18 -> 0
A19: =+Parametres!$B$1 -> Volks | B19: non | E19: =+SUM(H19:S19) -> 0 | G19: =+E19-F19 -> 0
A20: =+Parametres!$B$1 -> Volks | B20: non | E20: =+SUM(H20:S20) -> 0 | G20: =+E20-F20 -> 0

Sheet Inventaire_Used
A1: #Contrôle | B1: Année | C1: Marque | D1: Modèle | E1: 1416 | F1: 2103 | G1: NIV | H1: Jours en stock | M1: 45169 | N1: $ Inventaire | O1: $ Financé
A2: 5291P | B2: 2020 | C2: VOLKSWAGEN | D2: E-GOLF | E2: 32409.56 | F2: -22494.36 | G2: WVWPR7AU2LW903993 | H2: 392 | M2: CTRL | N2: =+SUM(E:E) -> 2199909.3 | O2: =+SUM(F:F) -> -296870.95
A3: 230251A | B3: 2020 | C3: VOLKSWAGEN | D3: E-GOLF | E3: 24845.21 | G3: WVWPR7AU0LW907198 | H3: 275 | M3: Unités | N3: =COUNT(E:E) -> 93 | O3: =-O2/N2 -> 0.1349469
A4: 230425A | B4: 2021 | C4: VOLKSWAGEN | D4: ATLAS CROSS SPO | E4: 37735.15 | G4: 1V2LC2CAXMC211536 | H4: 157
A5: 230365A | B5: 2018 | C5: VOLKSWAGEN | D5: BEETLE CONVERTI | E5: 29929.55 | G5: 3VW5DAAT2JM518129 | H5: 156 | M5: Moyenne | N5: =+N2/N3 -> 23654.939
A6: 5449PA | B6: 2018 | C6: VOLKSWAGEN | D6: GOLF | E6: 19715.63 | G6: 3VWB17AU0JM271989 | H6: 111
A7: 230544A | B7: 2019 | C7: VOLKSWAGEN | D7: JETTA | E7: 22879.9 | F7: -12635 | G7: 3VWG57BUXKM094345 | H7: 100 | M7: Plus de 90 Jours | N7: =SUM(E2:E10) -> 241858.49 | O7: =+N7/N2 -> 0.10994021
A8: 5485P | B8: 2018 | C8: VOLKSWAGEN | D8: ATLAS | E8: 31306.12 | G8: 1V2NR2CA5JC509107 | H8: 100 | N8: =COUNT(H2:H10) -> 9 | O8: =+N8/(N3) -> 0.096774194
A9: 5487P | B9: 2018 | C9: VOLKSWAGEN | D9: GOLF GTI | E9: 25356.95 | F9: -21600 | G9: 3VW547AU8JM271761 | H9: 97
A10: 230554A | B10: 2014 | C10: SUBARU | D10: WRX | E10: 17680.42 | G10: JF1GR8H60EL238082 | H10: 90
A11: 5496P | B11: 2019 | C11: VOLKSWAGEN | D11: GOLF | E11: 19201.82 | F11: -11233 | G11: 3VWG57AU0KM026959 | H11: 85
A12: 5500P | B12: 2019 | C12: VOLKSWAGEN | D12: JETTA | E12: 20375.85 | F12: -10707 | G12: 3VWE57BU6KM024333 | H12: 79
A13: 240008A | B13: 2020 | C13: MAZDA | D13: CX-5 | E13: 25169.95 | G13: JM3KFBCM9L0736240 | H13: 77
A14: 230567A | B14: 2021 | C14: VOLKSWAGEN | D14: TIGUAN | E14: 28635.15 | F14: -31332.8 | G14: 3VV2B7AX6MM155874 | H14: 73
A15: 5503P | B15: 2022 | C15: VOLKSWAGEN | D15: JETTA | E15: 26374.85 | G15: 3VWGM7BU3NM007957 | H15: 70
A16: 5505P | B16: 2023 | C16: VOLKSWAGEN | D16: JETTA GLI | E16: 34475.25 | F16: -32366.59 | G16: 3VW2T7BU0PM002098 | H16: 69
A17: 240013A | B17: 2022 | C17: VOLKSWAGEN | D17: TIGUAN | E17: 38815.25 | G17: 3VV4B7AX3NM051496 | H17: 63
A18: 230392A | B18: 2020 | C18: VOLKSWAGEN | D18: TIGUAN | E18: 31315.25 | F18: -24944.54 | G18: 3VV4B7AX2LM114164 | H18: 63
A19: 230599A | B19: 2019 | C19: VOLKSWAGEN | D19: JETTA | E19: 21280.25 | F19: -10962 | G19: 3VWE57BU6KM254342 | H19: 63
A20: 230606A | B20: 2018 | C20: CHEVROLET | D20: VOLT | E20: 17550 | G20: 1G1RA6S50JU104989 | H20: 62
A21: 240015A | B21: 2019 | C21: VOLKSWAGEN | D21: GOLF GTI | E21: 27280.25 | F21: -17480.23 | G21: 3VW6T7AU5KM024755 | H21: 59
A22: 5511P | B22: 2022 | C22: VOLKSWAGEN | D22: ATLAS CROSS SPO | E22: 44105.05 | F22: -38250 | G22: 1V2BE2CA6NC212111 | H22: 57
A23: 230619A | B23: 2020 | C23: NISSAN | D23: QASHQAI | E23: 26890.95 | G23: JN1BJ1CWXLW362448 | H23: 56
A24: 230622A | B24: 2020 | C24: VOLKSWAGEN | D24: JETTA | E24: 24417.5 | G24: 3VWEB7BU2LM004638 | H24: 51
A25: 240019A | B25: 2020 | C25: VOLKSWAGEN | D25: ATLAS CROSS SPO | E25: 36415.13 | F25: -26892 | G25: 1V2TE2CA8LC219420 | H25: 51
A26: 230628A | B26: 2019 | C26: VOLKSWAGEN | D26: JETTA | E26: 18251.25 | F26: -12123.43 | G26: 3VWC57BU8KM150071 | H26: 48
A27: 230596A | B27: 2020 | C27: VOLKSWAGEN | D27: TIGUAN | E27: 27935.05 | G27: 3VV2B7AX4LM005048 | H27: 45
A28: 5509PA | B28: 2017 | C28: AUDI | D28: A3 E-TRON | E28: 20050 | G28: WAUSPBFF5HA099610 | H28: 43
A29: 230626A | B29: 2018 | C29: VOLKSWAGEN | D29: TIGUAN | E29: 20497.05 | G29: 3VV4B7AX2JM130250 | H29: 41
A30: 5518P | B30: 2020 | C30: VOLKSWAGEN | D30: TIGUAN | E30: 28075.78 | F30: -23850 | G30: 3VV4B7AX0LM106225 | H30: 38
A31: 230593A | B31: 2019 | C31: VOLKSWAGEN | D31: TIGUAN | E31: 26815.25 | G31: 3VV4B7AX3KM183332 | H31: 38
A32: 5519P | B32: 2021 | C32: VOLKSWAGEN | D32: TIGUAN | E32: 28447.25 | G32: 3VV2B7AX4MM068281 | H32: 37
A33: 240044A | B33: 2019 | C33: VOLKSWAGEN | D33: ATLAS | E33: 29352 | G33: 1V2MR2CA6KC587280 | H33: 35
A34: 240041A | B34: 2018 | C34: VOLKSWAGEN | D34: GOLF | E34: 18787.5 | G34: 3VWG17AU2JM291103 | H34: 35
A35: 230625B | B35: 2015 | C35: TOYOTA | D35: RAV4 | E35: 14735.77 | G35: 2T3DFREV2FW373974 | H35: 35
A36: 240056A | B36: 2020 | C36: VOLKSWAGEN | D36: JETTA | E36: 18043.82 | G36: 3VWN57BU2LM040420 | H36: 34
A37: 240036A | B37: 2021 | C37: VOLKSWAGEN | D37: ATLAS | E37: 40209.65 | G37: 1V2FR2CA8MC595926 | H37: 31
A38: 240079A | B38: 2020 | C38: VOLKSWAGEN | D38: TIGUAN | E38: 30620.3 | G38: 3VV4B7AX5LM110786 | H38: 31
A39: 230564B | B39: 2020 | C39: JEEP | D39: COMPASS | E39: 27550 | G39: 3C4NJDDBXLT155667 | H39: 31
A40: 230649A | B40: 2020 | C40: NISSAN | D40: ROGUE | E40: 23550 | G40: 5N1AT2MT7LC775762 | H40: 30
...

Sheet Inventaire_Neuf
A1: #Contrôle | B1: Année | C1: Marque | D1: Modèle | E1: 1402 | F1: 2101 | G1: NIV | H1: Jours en stock | K1: 45230 | L1: $ Inventaire | M1: $ Financé
A2: 240187 | B2: 2024 | C2: VOLKSWAGEN | D2: ATLAS | E2: 56440.18 | F2: -57628.2 | G2: 1V2BR2CA6RC502911 | H2: 111 | K2: CTRL | L2: =+SUM(E2:E9974) -> 3304520.1 | M2: =+SUM(F2:F9974) -> -2708634.5
A3: 230650 | B3: 2023 | C3: VOLKSWAGEN | D3: JETTA SEDAN | E3: 34174.44 | F3: -32404.99 | G3: 3VW2T7BU7PM053775 | H3: 111 | K3: Unités | L3: =COUNT(E:E) -> 74 | M3: =-M2/L2 -> 0.8196756
A4: 240060 | B4: 2023 | C4: VOLKSWAGEN | D4: JETTA SEDAN | E4: 31533.26 | F4: -32628.75 | G4: 3VWGM7BU3PM060824 | H4: 85
A5: 240150 | B5: 2023 | C5: VOLKSWAGEN | D5: TAOS | E5: 38553.25 | F5: -39936.75 | G5: 3VV4X7B27PM374246 | H5: 80
A6: 240083 | B6: 2024 | C6: VOLKSWAGEN | D6: ATLAS | E6: 50422.03 | F6: -51427.95 | G6: 1V2LR2CA2RC511786 | H6: 77 | K6: Plus de 90 jrs | L6: =SUM(E2:E3) -> 90614.62 | M6: =SUM(F2:F3) -> -90033.19
A7: 240191 | B7: 2024 | C7: VOLKSWAGEN | D7: ATLAS CROSS SPT | E7: 55153.85 | F7: -57051.75 | G7: 1V2BE2CA7RC206484 | H7: 73 | L7: 2
A8: 230643 | B8: 2024 | C8: VOLKSWAGEN | D8: ATLAS | E8: 58887.12 | F8: -60546.15 | G8: 1V2FR2CA6RC509911 | H8: 73
A9: 240182 | B9: 2024 | C9: VOLKSWAGEN | D9: ATLAS CROSS SPT | E9: 49045.79 | F9: -51136.05 | G9: 1V2LE2CA3RC208611 | H9: 66 | K9: Plus de 180 jrs | L9: 0 | M9: 0
A10: 240197 | B10: 2024 | C10: VOLKSWAGEN | D10: ATLAS CROSS SPT | E10: 57630.1 | G10: 1V2BE2CA1RC206996 | H10: 62 | L10: 0
A11: 240204 | B11: 2024 | C11: VOLKSWAGEN | D11: ATLAS CROSS SPT | E11: 56202.06 | F11: -57051.75 | G11: 1V2BE2CA5RC210341 | H11: 59
A12: 240026 | B12: 2024 | C12: VOLKSWAGEN | D12: ATLAS | E12: 58051.06 | G12: 1V2BR2CA4RC506228 | H12: 59
A13: 240125 | B13: 2024 | C13: VOLKSWAGEN | D13: ATLAS | E13: 48902.32 | G13: 1V2LR2CA8RC516197 | H13: 59
A14: 240035 | B14: 2024 | C14: VOLKSWAGEN | D14: GOLF GTI | E14: 37397 | F14: -39440.1 | G14: WVWGA7CD7RW121198 | H14: 55
A15: 240102 | B15: 2024 | C15: VOLKSWAGEN | D15: ATLAS | E15: 55983.97 | F15: -58869.3 | G15: 1V2BR2CA1RC517137 | H15: 55
A16: 240168 | B16: 2024 | C16: VOLKSWAGEN | D16: ATLAS CROSS SPT | E16: 56815.09 | F16: -58834.65 | G16: 1V2FE2CAXRC211373 | H16: 51
A17: 240172 | B17: 2024 | C17: VOLKSWAGEN | D17: ATLAS CROSS SPT | E17: 56057.95 | F17: -58834.65 | G17: 1V2FE2CAXRC210840 | H17: 51
A18: 240210 | B18: 2024 | C18: VOLKSWAGEN | D18: ATLAS CROSS SPT | E18: 55948 | F18: -58834.65 | G18: 1V2FE2CA7RC210827 | H18: 49
A19: 230574 | B19: 2024 | C19: VOLKSWAGEN | D19: ATLAS | E19: 48889 | F19: -51427.95 | G19: 1V2LR2CAXRC520316 | H19: 49
A20: 240050 | B20: 2023 | C20: VOLKSWAGEN | D20: TAOS | E20: 32613.32 | F20: -34034.7 | G20: 3VVEX7B23PM379190 | H20: 49
A21: 240045 | B21: 2023 | C21: VOLKSWAGEN | D21: JETTA GLI | E21: 34545.5 | G21: 3VW2T7BU5PM062118 | H21: 49
A22: 240070 | B22: 2024 | C22: VOLKSWAGEN | D22: JETTA SEDAN | E22: 26927 | F22: -28367.85 | G22: 3VWWM7BU5RM010702 | H22: 43
A23: 240203 | B23: 2024 | C23: VOLKSWAGEN | D23: ATLAS CROSS SPT | E23: 55950.97 | F23: -58834.65 | G23: 1V2FE2CA4RC210672 | H23: 43
A24: 240192 | B24: 2024 | C24: VOLKSWAGEN | D24: ATLAS CROSS SPT | E24: 55950.97 | F24: -58834.65 | G24: 1V2FE2CA0RC211429 | H24: 43
A25: 240173 | B25: 2024 | C25: VOLKSWAGEN | D25: JETTA SEDAN | E25: 29531 | F25: -31102.05 | G25: 3VWSM7BU4RM014707 | H25: 42
A26: 240188 | B26: 2024 | C26: VOLKSWAGEN | D26: ATLAS CROSS SPT | E26: 55950.97 | F26: -58834.65 | G26: 1V2FE2CAXRC211504 | H26: 42
A27: 240176 | B27: 2023 | C27: VOLKSWAGEN | D27: TAOS | E27: 37610 | F27: -39461.1 | G27: 3VV4X7B2XPM382549 | H27: 42
A28: 240156 | B28: 2024 | C28: VOLKSWAGEN | D28: JETTA GLI | E28: 34477 | F28: -36295.35 | G28: 3VW2T7BU5RM004870 | H28: 38
A29: 240132 | B29: 2024 | C29: VOLKSWAGEN | D29: JETTA SEDAN | E29: 28309 | F29: -29734.95 | G29: 3VWFM7BU8RM015148 | H29: 37
A30: 240003 | B30: 2024 | C30: VOLKSWAGEN | D30: JETTA GLI | E30: 32637 | F30: -34363.35 | G30: 3VW9T7BUXRM015328 | H30: 37
A31: 240021 | B31: 2024 | C31: VOLKSWAGEN | D31: GOLF GTI | E31: 38101 | F31: -40179.3 | G31: WVWRA7CD3RW124950 | H31: 37
A32: 240137 | B32: 2024 | C32: VOLKSWAGEN | D32: GOLF GTI | E32: 37506.9 | F32: -39440.1 | G32: WVWGA7CD1RW121181 | H32: 37
A33: 240206 | B33: 2024 | C33: VOLKSWAGEN | D33: ATLAS CROSS SPT | E33: 54250 | F33: -57051.75 | G33: 1V2BE2CA9RC212335 | H33: 37
... A37: 240052 | B37: 2024 | C37: VOLKSWAGEN | D37: TAOS | E37: 32679.42 | F37: -33257.7 | G37: 3VVSX7B29RM011974 | H37: 28
A38: 240178 | B38: 2024 | C38: VOLKSWAGEN | D38: JETTA GLI | E38: 31816.52 | G38: 3VW8T7BU7RM014696 | H38: 21
A39: 240030 | B39: 2024 | C39: VOLKSWAGEN | D39: TIGUAN | E39: 39108 | G39: 3VVMB7AX2RM018480 | H39: 20
A40: 230581 | B40: 2024 | C40: VOLKSWAGEN | D40: ATLAS CROSS SPT | E40: 54516 | F40: -57331.05 | G40: 1V2BE2CA7RC216397 | H40: 20
A41: 240067 | B41: 2024 | C41: VOLKSWAGEN | D41: ATLAS | E41: 58735.8 | G41: 1V2FR2CA3RC523474 | H41: 20
A42: 240042 | B42: 2024 | C42: VOLKSWAGEN | D42: TAOS | E42: 32864 | F42: -34706.7 | G42: 3VVEX7B22RM012347 | H42: 17
A43: 240160 | B43: 2024 | C43: VOLKSWAGEN | D43: ATLAS CROSS SPT | E43: 55948 | F43: -58834.65 | G43: 1V2FE2CA6RC216828 | H43: 17
...

Sheet 2pager
B1: =Parametres!$B$1&" "&"2 pager"&" "&Parametres!$B$3&" "&Parametres!$B$4 -> Volks 2 pager Novembre 2023
B3: New | C3: Actual | D3: Budget | E3: 2022 | F3: ▲ Budget | G3: ▲2022 | H3: % ▲ Budget | I3: % ▲ 2022 | J3: Commentaires
B4: Units | C4: =+Print_Mois!$J$13+Print_Mois!$J$15 -> 90 | D4: =+Print_Mois!$D$13+Print_Mois!$D$15 -> 67.674832 | E4: =+Print_Mois!$O$13+Print_Mois!$O$15 -> 38 | F4: =+IFERROR($C4-D4,"") -> 22.325168 | G4: =+IFERROR($C4-E4,"") -> 52 | H4: =+IFERROR(F4/ABS($D4),"") -> 0.32988877 | I4: =+IFERROR(G4/ABS($E4),"") -> 1.3684211 | J4: Les volumes sont maintenant en ligne avec nos budgets. Les inventaires restent bas et le pipeline prévendu monte maintenant autour de 77%. Il faut améliorer le profit par unité tant front que back. Les holdabcks suivent, les frais d'admin sont là.
B5: Front Margin | C5: =+Print_Mois!$L$13+Print_Mois!$L$15 -> 204399.78 | D5: =+Print_Mois!$F$13+Print_Mois!$F$15 -> 165311.73 | E5: =+Print_Mois!$Q$13+Print_Mois!$Q$15 -> 92855.84 | F5: =+IFERROR($C5-D5,"") -> 39088.05 | G5: =+IFERROR($C5-E5,"") -> 111543.94 | H5: =+IFERROR(F5/ABS($D5),"") -> 0.23645055 | I5: =+IFERROR(G5/ABS($E5),"") -> 1.2012593
B6: Front margin / unit | C6: =+C5/C4 -> 2271.1087 | D6: =+D5/D4 -> 2442.7357 | E6: =+E5/E4 -> 2443.5747 | F6: =+IFERROR($C6-D6,"") -> -171.62704 | G6: =+IFERROR($C6-E6,"") -> -172.46607 | H6: =+IFERROR(F6/ABS($D6),"") -> -0.070260177 | I6: =+IFERROR(G6/ABS($E6),"") -> -0.070579413
B7: $ Salaires et commission | C7: =+Print_Mois!$L$31 -> 45012.79 | D7: =+Print_Mois!$F$31 -> 49973.981 | E7: =+Print_Mois!$Q$31 -> 27121.04 | F7: =+IFERROR($C7-D7,"") -> -4961.1905 | G7: =+IFERROR($C7-E7,"") -> 17891.75 | H7: =+IFERROR(F7/ABS($D7),"") -> -0.099275472 | I7: =+IFERROR(G7/ABS($E7),"") -> 0.6597
B8: % Salaires et commission | C8: =+C7/C5 -> 0.22021937 | D8: =+D7/D5 -> 0.30230148 | E8: =+E7/E5 -> 0.29207684 | F8: =+IFERROR($C8-D8,"") -> -0.082082113 | G8: =+IFERROR($C8-E8,"") -> -0.07185747 | H8: =+IFERROR(F8/ABS($D8),"") -> -0.27152402 | I8: =+IFERROR(G8/ABS($E8),"") -> -0.24602249
B9: Back Margin | C9: =+Print_Mois!$L$24 -> 95059.78 | D9: =+Print_Mois!$F$24 -> 77623.033 | E9: =+Print_Mois!$Q$24 -> 51064.45 | F9: =+IFERROR($C9-D9,"") -> 17436.747 | G9: =+IFERROR($C9-E9,"") -> 43995.33 | H9: =+IFERROR(F9/ABS($D9),"") -> 0.22463368 | I9: =+IFERROR(G9/ABS($E9),"") -> 0.86156475
B10: Back Margin / unit | C10: =+C9/C4 -> 1056.2198 | D10: =+D9/D4 -> 1147 | E10: =+E9/E4 -> 1343.8013 | F10: =+IFERROR($C10-D10,"") -> -90.780222 | G10: =+IFERROR($C10-E10,"") -> -287.58154 | H10: =+IFERROR(F10/ABS($D10),"") -> -0.079145791 | I10: =+IFERROR(G10/ABS($E10),"") -> -0.214006
B11: $ commission FI | C11: =+Print_Mois!$L$32 -> 28480.86 | D11: =+Print_Mois!$F$32 -> 23286.91 | E11: =+Print_Mois!$Q$32 -> 17558.83 | F11: =+IFERROR($C11-D11,"") -> 5193.9502 | G11: =+IFERROR($C11-E11,"") -> 10922.03 | H11: =+IFERROR(F11/ABS($D11),"") -> 0.22304162 | I11: =+IFERROR(G11/ABS($E11),"") -> 0.62202493
B12: % commission FI | C12: =+C11/C9 -> 0.29960999 | D12: =+D11/D9 -> 0.3 | E12: =+E11/E9 -> 0.34385624 | F12: =+IFERROR($C12-D12,"") -> -0.00039000721 | G12: =+IFERROR($C12-E12,"") -> -0.044246252 | H12: =+IFERROR(F12/ABS($D12),"") -> -0.001300024 | I12: =+IFERROR(G12/ABS($E12),"") -> -0.1286766
B13: Variable fees | C13: =+Print_Mois!$L$41-C7-C11 -> 48777.8 | D13: =+Print_Mois!$F$41-D7-D11 -> 37591.688 | E13: =+Print_Mois!$Q$41-E7-E11 -> 11808.58 | F13: =+IFERROR($C13-D13,"") -> 11186.112 | G13: =+IFERROR($C13-E13,"") -> 36969.22 | H13: =+IFERROR(F13/ABS($D13),"") -> 0.29756877 | I13: =+IFERROR(G13/ABS($E13),"") -> 3.1307083
B14: Variable fees / units | C14: =+C13/C4 -> 541.97556 | D14: =+D13/D4 -> 555.47515 | E14: =+E13/E4 -> 310.75211 | F14: =+IFERROR($C14-D14,"") -> -13.499595 | G14: =+IFERROR($C14-E14,"") -> 231.22345 | H14: =+IFERROR(F14/ABS($D14),"") -> -0.024302789 | I14: =+IFERROR(G14/ABS($E14),"") -> 0.74407686
B15: Other Revenues | C15: =+Print_Mois!$L$83 -> 142300.9 | D15: =+Print_Mois!$F$83 -> 105135.6 | E15: =+Print_Mois!$Q$83 -> 102324 | F15: =+IFERROR($C15-D15,"") -> 37165.301 | G15: =+IFERROR($C15-E15,"") -> 39976.9 | H15: =+IFERROR(F15/ABS($D15),"") -> 0.35349873 | I15: =+IFERROR(G15/ABS($E15),"") -> 0.39068938
B16: Inventory
B17: Units | C17: =Inventaire_Neuf!L3 -> 74 | D17: 61 | E17: 164 | F17: =+IFERROR($C17-D17,"") -> 13 | G17: =+IFERROR($C17-E17,"") -> -90 | H17: =+IFERROR(F17/ABS($D17),"") -> 0.21311475 | I17: =+IFERROR(G17/ABS($E17),"") -> -0.54878049
B18: $ | C18: =Inventaire_Neuf!L2 -> 3304520.1 | D18: 2233570 | E18: 5689693.2 | F18: =+IFERROR($C18-D18,"") -> 1070950.1 | G18: =+IFERROR($C18-E18,"") -> -2385173.1 | H18: =+IFERROR(F18/ABS($D18),"") -> 0.47947909 | I18: =+IFERROR(G18/ABS($E18),"") -> -0.41920944
C19: =C18/C17 -> 44655.677 | D19: =D18/D17 -> 36615.902 | E19: =E18/E17 -> 34693.251
B20: Used | C20: Actual | D20: Budget | E20: =$E$3 -> 2022 | F20: ▲ Budget | G20: =$G$3 -> ▲2022 | H20: % ▲ Budget | I20: =$I$3 -> % ▲ 2022 | J20: Commentaires
B21: Units | C21: =+Print_Mois!$J$96 -> 20 | D21: =+Print_Mois!$D$96 -> 39 | E21: =+Print_Mois!$O$96 -> 27 | F21: =+IFERROR($C21-D21,"") -> -19 | G21: =+IFERROR($C21-E21,"") -> -7 | H21: =+IFERROR(F21/ABS($D21),"") -> -0.48717949 | I21: =+IFERROR(G21/ABS($E21),"") -> -0.25925926 | J21: Les volumes sont la clé. Notre profit unitaire rejoint et dépasse même notre cible. Le F&i subit encore la contre performance du changement récent d'employé Nous visons être à niveau fin octobre. L'inventaire est absolument sous contrôle et notre marchandisage comme notre niveau de réponse web est dans les top 3 du groupe. On peut encore améliorer ça avec la mise en place du 2ème agent BDC mixte entre Audi et VW pour couvrir les heures de fin de semaine, accélérer les réponses et augmenter nos ventes.
B22: Front Margin | C22: =+Print_Mois!$L$96 -> 25020.67 | D22: =+Print_Mois!$F$96 -> 72462 | E22: =+Print_Mois!$Q$96 -> 23423.91 | F22: =+IFERROR($C22-D22,"") -> -47441.33 | G22: =+IFERROR($C22-E22,"") -> 1596.76 | H22: =+IFERROR(F22/ABS($D22),"") -> -0.65470633 | I22: =+IFERROR(G22/ABS($E22),"") -> 0.068167953
B23: Front margin / unit | C23: =+C22/C21 -> 1251.0335 | D23: =+D22/D21 -> 1858 | E23: =+E22/E21 -> 867.55222 | F23: =+IFERROR($C23-D23,"") -> -606.9665 | G23: =+IFERROR($C23-E23,"") -> 383.48128 | H23: =+IFERROR(F23/ABS($D23),"") -> -0.32667734 | I23: =+IFERROR(G23/ABS($E23),"") -> 0.44202674
B24: $ Salaires et commission | C24: =+Print_Mois!$L$111 -> 8239.93 | D24: =+Print_Mois!$F$111 -> 22726.5 | E24: =+Print_Mois!$Q$111 -> 14976.51 | F24: =+IFERROR($C24-D24,"") -> -14486.57 | G24: =+IFERROR($C24-E24,"") -> -6736.58 | H24: =+IFERROR(F24/ABS($D24),"") -> -0.63743075 | I24: =+IFERROR(G24/ABS($E24),"") -> -0.44980974
B25: % Salaires et commission | C25: =+C24/C22 -> 0.32932491 | D25: =+D24/D22 -> 0.31363335 | E25: =+E24/E22 -> 0.63936849 | F25: =+IFERROR($C25-D25,"") -> 0.015691562 | G25: =+IFERROR($C25-E25,"") -> -0.31004358 | H25: =+IFERROR(F25/ABS($D25),"") -> 0.050031546 | I25: =+IFERROR(G25/ABS($E25),"") -> -0.48492158
B26: Back Margin | C26: =+Print_Mois!$L$104 -> 26546.7 | D26: =+Print_Mois!$F$104 -> 81900 | E26: =+Print_Mois!$Q$104 -> 51221.51 | F26: =+IFERROR($C26-D26,"") -> -55353.3 | G26: =+IFERROR($C26-E26,"") -> -24674.81 | H26: =+IFERROR(F26/ABS($D26),"") -> -0.67586447 | I26: =+IFERROR(G26/ABS($E26),"") -> -0.4817275
B27: Back Margin / unit | C27: =+C26/C21 -> 1327.335 | D27: =+D26/D21 -> 2100 | E27: =+E26/E21 -> 1897.093 | F27: =+IFERROR($C27-D27,"") -> -772.665 | G27: =+IFERROR($C27-E27,"") -> -569.75796 | H27: =+IFERROR(F27/ABS($D27),"") -> -0.36793571 | I27: =+IFERROR(G27/ABS($E27),"") -> -0.30033213
B28: $ commission FI | C28: =+Print_Mois!$L$112 -> 7995.8 | D28: =+Print_Mois!$F$112 -> 24570 | E28: =+Print_Mois!$Q$112 -> 15310.99 | F28: =+IFERROR($C28-D28,"") -> -16574.2 | G28: =+IFERROR($C28-E28,"") -> -7315.19 | H28: =+IFERROR(F28/ABS($D28),"") -> -0.67457061 | I28: =+IFERROR(G28/ABS($E28),"") -> -0.47777381
B29: % commission FI | C29: =+C28/C26 -> 0.30119751 | D29: =+D28/D26 -> 0.3 | E29: =+E28/E26 -> 0.29891719 | F29: =+IFERROR($C29-D29,"") -> 0.0011975123 | G29: =+IFERROR($C29-E29,"") -> 0.0022803191 | H29: =+IFERROR(F29/ABS($D29),"") -> 0.0039917077 | I29: =+IFERROR(G29/ABS($E29),"") -> 0.0076285981
B30: Variable fees | C30: =+Print_Mois!$L$121-C24-C28 -> 19821.35 | D30: =+Print_Mois!$F$121-D24-D28 -> 16049.265 | E30: =+Print_Mois!$Q$121-E24-E28 -> 21441.66 | F30: =+IFERROR($C30-D30,"") -> 3772.0846 | G30: =+IFERROR($C30-E30,"") -> -1620.31 | H30: =+IFERROR(F30/ABS($D30),"") -> 0.23503161 | I30: =+IFERROR(G30/ABS($E30),"") -> -0.07556831
B31: Variable fees / units | C31: =+C30/C21 -> 991.0675 | D31: =+D30/D21 -> 411.51962 | E31: =+E30/E21 -> 794.13556 | F31: =+IFERROR($C31-D31,"") -> 579.54788 | G31: =+IFERROR($C31-E31,"") -> 196.93194 | H31: =+IFERROR(F31/ABS($D31),"") -> 1.4083116 | I31: =+IFERROR(G31/ABS($E31),"") -> 0.24798278
B32: Other Revenues | C32: =+Print_Mois!$L$162 -> 7749 | D32: =+Print_Mois!$F$162 -> 14004.9 | E32: =+Print_Mois!$Q$162 -> 10323 | F32: =+IFERROR($C32-D32,"") -> -6255.9 | G32: =+IFERROR($C32-E32,"") -> -2574 | H32: =+IFERROR(F32/ABS($D32),"") -> -0.44669366 | I32: =+IFERROR(G32/ABS($E32),"") -> -0.24934612
B33: Inventory
B34: Units | C34: =Inventaire_Used!N3 -> 93 | D34: 68 | E34: 92 | F34: =+IFERROR($C34-D34,"") -> 25 | G34: =+IFERROR($C34-E34,"") -> 1 | H34: =+IFERROR(F34/ABS($D34),"") -> 0.36764706 | I34: =+IFERROR(G34/ABS($E34),"") -> 0.010869565
B35: $ | C35: =Inventaire_Used!N2 -> 2199909.3 | D35: 1072231 | E35: 1510979 | F35: =+IFERROR($C35-D35,"") -> 1127678.3 | G35: =+IFERROR($C35-E35,"") -> 688930.3 | H35: =+IFERROR(F35/ABS($D35),"") -> 1.0517121 | I35: =+IFERROR(G35/ABS($E35),"") -> 0.45594962
C36: =C35/C34 -> 23654.939 | D36: =D35/D34 -> 15768.103 | E36: =E35/E34 -> 16423.685
B37: Service | C37: Actual | D37: Budget | E37: =$E$3 -> 2022 | F37: ▲ Budget | G37: =$G$3 -> ▲2022 | H37: % ▲ Budget | I37: =$I$3 -> % ▲ 2022 | J37: Commentaires
B38: Revenus | C38: =+Print_Mois!$K$193 -> 408560.41 | D38: =+Print_Mois!$E$193 -> 431214.32 | E38: =+Print_Mois!$P$193 -> 391200.46 | F38: =+IFERROR($C38-D38,"") -> -22653.915 | G38: =+IFERROR($C38-E38,"") -> 17359.95 | H38: =+IFERROR(F38/ABS($D38),"") -> -0.052535163 | I38: =+IFERROR(G38/ABS($E38),"") -> 0.044376098 | J38: Nous atteignons pour la première fois les chiffres au brut que nous visions avec notre augmentation de capacité. Dépenses sous contrôle malgré le déménagement et un lost time légèrement plus haut que le budget. Les économies sur les véhicules de compagnie ont été faites et les chiffres parlent. Notre nouveau directeur des opérations fixes démarre le 6 novembre prochain.
B39: Gross margin | C39: =+Print_Mois!$L$193 -> 290276.32 | D39: =+Print_Mois!$F$193 -> 308610.32 | E39: =+Print_Mois!$Q$193 -> 277195.32 | F39: =+IFERROR($C39-D39,"") -> -18334.002 | G39: =+IFERROR($C39-E39,"") -> 13081 | H39: =+IFERROR(F39/ABS($D39),"") -> -0.059408259 | I39: =+IFERROR(G39/ABS($E39),"") -> 0.047190551
B40: $ Revenus / #WO client | C40: =+Print_Mois!$K$171/Print_Mois!$J$171 -> 245.00563 | D40: =+IFERROR(Print_Mois!$E$171/Print_Mois!$D$171,"") -> 295 | E40: =+Print_Mois!$P$171/Print_Mois!$O$171 -> 265.65314 | F40: =+IFERROR($C40-D40,"") -> -49.994367 | G40: =+IFERROR($C40-E40,"") -> -20.647505 | H40: =+IFERROR(F40/ABS($D40),"") -> -0.16947243 | I40: =+IFERROR(G40/ABS($E40),"") -> -0.077723552
B41: $ Revenus / #WO garantie | C41: =+Print_Mois!$K$174/Print_Mois!$J$174 -> 196.97871 | D41: =+IFERROR(Print_Mois!$E$174/Print_Mois!$D$174,"") -> 170 | E41: =+Print_Mois!$P$174/Print_Mois!$O$174 -> 188.81694 | F41: =+IFERROR($C41-D41,"") -> 26.978707 | G41: =+IFERROR($C41-E41,"") -> 8.1617714 | H41: =+IFERROR(F41/ABS($D41),"") -> 0.15869828 | I41: =+IFERROR(G41/ABS($E41),"") -> 0.043225844
...

Sheet Print_Mois
C1: =Parametres!B1 -> Volks | K1: Véhicules neufs | S1: =CONCATENATE("Réalisé,"," ",Parametres!B3," ",Parametres!B4) -> Réalisé, Novembre 2023
D2: X | E2: O | F2: U | J2: NB | L2: $ | O2: NB | Q2: $ | V2: *** NE PAS EFFACER / Pour An Précédente ***
D3: BUDGET ORIGINAL | J3: RÉALISATION | M3: ÉCART réel / Budget | O3: ANNÉE PRÉCÉDENTE | R3: ECART (réel/ Ann.Préc.) | V3: NEUF | W3: 0.45
D4: UNITÉS | E4: $P/UNITÉ | F4: $PROFITS | J4: UNITÉS | K4: $P/UNITE | L4: $PROFITS | M4: UNITÉS | N4: $PROFITS | O4: UNITÉS | P4: $P/UNITE | Q4: $PROFITS | R4: UNITÉS | S4: $PROFITS | V4: USAGE | W4: 0.1
A5: Véhicules neufsVentes nettes | B5: Véhicules neufs | C5: Ventes nettes | F5: {=+INDEX('Budget original'!$A$2:$AO$500,MATCH($A5,'Budget original'!$A$2:$A$500,0),MATCH(F$2,'Budget original'!$A$2:$AO$2,0))} -> 3024137.9 | L5: =-SUMIFS(BV_Data_An_Cour!$O:$O,BV_Data_An_Cour!$X:$X,"Oui",BV_Data_An_Cour!$U:$U,$B5) -> 4112838.4 | Q5: =-SUMIFS(BV_Data_An_Prec!$O:$O,BV_Data_An_Prec!$X:$X,"Oui",BV_Data_An_Prec!$U:$U,$B5) -> 2056128.2 | V5: SERVICE | W5: 0.225
A6: Véhicules neufsAutos détail | B6: Véhicules neufs | C6: Autos détail | D6: {=+INDEX('Budget original'!$A$2:$AO$500,MATCH($A6,'Budget original'!$A$2:$A$500,0),MATCH(D$2,'Budget original'!$A$2:$AO$2,0))} -> 12.918857 | E6: =IF(D6=0,0,F6/D6) -> 1988.434 | F6: {=+INDEX('Budget original'!$A$2:$AO$500,MATCH($A6,'Budget original'!$A$2:$A$500,0),MATCH(F$2,'Budget original'!$A$2:$AO$2,0))} -> 25688.295 | J6: =-SUMIFS(BV_Data_An_Cour!$O:$O,BV_Data_An_Cour!$U:$U,$B6,BV_Data_An_Cour!$V:$V,$C6,BV_Data_An_Cour!$W:$W,J$2) -> 18 | K6: =IF(J6=0,0,L6/J6) -> 2139.7994 | L6: =-SUMIFS(BV_Data_An_Cour!$O:$O,BV_Data_An_Cour!$U:$U,$B6,BV_Data_An_Cour!$V:$V,$C6,BV_Data_An_Cour!$W:$W,L$2) -> 38516.39 | M6: =J6-D6 -> 5.0811429 | N6: =L6-F6 -> 12828.095 | O6: =-SUMIFS(BV_Data_An_Prec!$O:$O,BV_Data_An_Prec!$U:$U,$B6,BV_Data_An_Prec!$V:$V,$C6,BV_Data_An_Prec!$W:$W,O$2) -> 2 | P6: =IF(O6=0,0,Q6/O6) -> 1595.39 | Q6: =-SUMIFS(BV_Data_An_Prec!$O:$O,BV_Data_An_Prec!$U:$U,$B6,BV_Data_An_Prec!$V:$V,$C6,BV_Data_An_Prec!$W:$W,Q$2) -> 3190.78 | R6: =J6-O6 -> 16 | S6: =L6-Q6 -> 35325.61 | V6: CARROSSERIE | W6: 0.025
A7: Véhicules neufsCamions détail | B7: Véhicules neufs | C7: Camions détail | D7: {=+INDEX('Budget original'!$A$2:$AO$500,MATCH($A7,'Budget original'!$A$2:$A$500,0),MATCH(D$2,'Budget original'!$A$2:$AO$2,0))} -> 51.670261 | E7: =IF(D7=0,0,F7/D7) -> 2556.3336 | F7: {=+INDEX('Budget original'!$A$2:$AO$500,MATCH($A7,'Budget original'!$A$2:$A$500,0),MATCH(F$2,'Budget original'!$A$2:$AO$2,0))} -> 132086.43 | J7: =-SUMIFS(BV_Data_An_Cour!$O:$O,BV_Data_An_Cour!$U:$U,$B7,BV_Data_An_Cour!$V:$V,$C7,BV_Data_An_Cour!$W:$W,J$2) -> 71 | K7: =IF(J7=0,0,L7/J7) -> 2320.119 | L7: =-SUMIFS(BV_Data_An_Cour!$O:$O,BV_Data_An_Cour!$U:$U,$B7,BV_Data_An_Cour!$V:$V,$C7,BV_Data_An_Cour!$W:$W,L$2) -> 164728.45 | M7: =J7-D7 -> 19.329739 | N7: =L7-F7 -> 32642.024 | O7: =-SUMIFS(BV_Data_An_Prec!$O:$O,BV_Data_An_Prec!$U:$U,$B7,BV_Data_An_Prec!$V:$V,$C7,BV_Data_An_Prec!$W:$W,O$2) -> 32 | P7: =IF(O7=0,0,Q7/O7) -> 2121.0544 | Q7: =-SUMIFS(BV_Data_An_Prec!$O:$O,BV_Data_An_Prec!$U:$U,$B7,BV_Data_An_Prec!$V:$V,$C7,BV_Data_An_Prec!$W:$W,Q$2) -> 67873.74 | R7: =J7-O7 -> 39 | S7: =L7-Q7 -> 96854.71 | V7: PIECES | W7: 0.2
A8: Véhicules neufsSprinter | B8: Véhicules neufs | C8: Sprinter | D8: {=+INDEX('Budget original'!$A$2:$AO$500,MATCH($A8,'Budget original'!$A$2:$A$500,0),MATCH(D$2,'Budget original'!$A$2:$AO$2,0))} -> 0 | E8: =IF(D8=0,0,F8/D8) -> 0 | F8: {=+INDEX('Budget original'!$A$2:$AO$500,MATCH($A8,'Budget original'!$A$2:$A$500,0),MATCH(F$2,'Budget original'!$A$2:$AO$2,0))} -> 0 | J8: =-SUMIFS(BV_Data_An_Cour!$O:$O,BV_Data_An_Cour!$U:$U,$B8,BV_Data_An_Cour!$V:$V,$C8,BV_Data_An_Cour!$W:$W,J$2) -> 0 | K8: =IF(J8=0,0,L8/J8) -> 0 | L8: =-SUMIFS(BV_Data_An_Cour!$O:$O,BV_Data_An_Cour!$U:$U,$B8,BV_Data_An_Cour!$V:$V,$C8,BV_Data_An_Cour!$W:$W,L$2) -> 0 | M8: =J8-D8 -> 0 | N8: =L8-F8 -> 0 | O8: =-SUMIFS(BV_Data_An_Prec!$O:$O,BV_Data_An_Prec!$U:$U,$B8,BV_Data_An_Prec!$V:$V,$C8,BV_Data_An_Prec!$W:$W,O$2) -> 0 | P8: =IF(O8=0,0,Q8/O8) -> 0 | Q8: =-SUMIFS(BV_Data_An_Prec!$O:$O,BV_Data_An_Prec!$U:$U,$B8,BV_Data_An_Prec!$V:$V,$C8,BV_Data_An_Prec!$W:$W,Q$2) -> 0 | R8: =J8-O8 -> 0 | S8: =L8-Q8 -> 0 | W8: =SUM(W3:W7) -> 1
A9: Véhicules neufsMoto détail | B9: Véhicules neufs | C9: Moto détail | D9: {=+INDEX('Budget original'!$A$2:$AO$500,MATCH($A9,'Budget original'!$A$2:$A$500,0),MATCH(D$2,'Budget original'!$A$2:$AO$2,0))} -> 0 | E9: =IF(D9=0,0,F9/D9) -> 0 | F9: {=+INDEX('Budget original'!$A$2:$AO$500,MATCH($A9,'Budget original'!$A$2:$A$500,0),MATCH(F$2,'Budget original'!$A$2:$AO$2,0))} -> 0 | J9: =-SUMIFS(BV_Data_An_Cour!$O:$O,BV_Data_An_Cour!$U:$U,$B9,BV_Data_An_Cour!$V:$V,$C9,BV_Data_An_Cour!$W:$W,J$2) -> 0 | K9: =IF(J9=0,0,L9/J9) -> 0 | L9: =-SUMIFS(BV_Data_An_Cour!$O:$O,BV_Data_An_Cour!$U:$U,$B9,BV_Data_An_Cour!$V:$V,$C9,BV_Data_An_Cour!$W:$W,L$2) -> 0 | M9: =J9-D9 -> 0 | N9: =L9-F9 -> 0 | O9: =-SUMIFS(BV_Data_An_Prec!$O:$O,BV_Data_An_Prec!$U:$U,$B9,BV_Data_An_Prec!$V:$V,$C9,BV_Data_An_Prec!$W:$W,O$2) -> 0 | P9: =IF(O9=0,0,Q9/O9) -> 0 | Q9: =-SUMIFS(BV_Data_An_Prec!$O:$O,BV_Data_An_Prec!$U:$U,$B9,BV_Data_An_Prec!$V:$V,$C9,BV_Data_An_Prec!$W:$W,Q$2) -> 0 | R9: =J9-O9 -> 0 | S9: =L9-Q9 -> 0
A10: Véhicules neufs[...] | B10: Véhicules neufs | C10: [...] | D10: 0 | E10: =IF(D10=0,0,F10/D10) -> 0 | F10: {=+INDEX('Budget original'!$A$2:$AO$500,MATCH($A10,'Budget original'!$A$2:$A$500,0),MATCH(F$2,'Budget original'!$A$2:$AO$2,0))} -> 0 | J10: =-SUMIFS(BV_Data_An_Cour!$O:$O,BV_Data_An_Cour!$U:$U,$B10,BV_Data_An_Cour!$V:$V,$C10,BV_Data_An_Cour!$W:$W,J$2) -> 0 | K10: =IF(J10=0,0,L10/J10) -> 0 | L10: =-SUMIFS(BV_Data_An_Cour!$O:$O,BV_Data_An_Cour!$U:$U,$B10,BV_Data_An_Cour!$V:$V,$C10,BV_Data_An_Cour!$W:$W,L$2) -> 0 | M10: =J10-D10 -> 0 | N10: =L10-F10 -> 0 | O10: =-SUMIFS(BV_Data_An_Prec!$O:$O,BV_Data_An_Prec!$U:$U,$B10,BV_Data_An_Prec!$V:$V,$C10,BV_Data_An_Prec!$W:$W,O$2) -> 0 | P10: =IF(O10=0,0,Q10/O10) -> 0 | Q10: =-SUMIFS(BV_Data_An_Prec!$O:$O,BV_Data_An_Prec!$U:$U,$B10,BV_Data_An_Prec!$V:$V,$C10,BV_Data_An_Prec!$W:$W,Q$2) -> 0 | R10: =J10-O10 -> 0 | S10: =L10-Q10 -> 0
A11: Véhicules neufs[...] | B11: Véhicules neufs | C11: [...] | D11: 0 | E11: =IF(D11=0,0,F11/D11) -> 0 | F11: {=+INDEX('Budget original'!$A$2:$AO$500,MATCH($A11,'Budget original'!$A$2:$A$500,0),MATCH(F$2,'Budget original'!$A$2:$AO$2,0))} -> 0 | J11: =-SUMIFS(BV_Data_An_Cour!$O:$O,BV_Data_An_Cour!$U:$U,$B11,BV_Data_An_Cour!$V:$V,$C11,BV_Data_An_Cour!$W:$W,J$2) -> 0 | K11: =IF(J11=0,0,L11/J11) -> 0 | L11: =-SUMIFS(BV_Data_An_Cour!$O:$O,BV_Data_An_Cour!$U:$U,$B11,BV_Data_An_Cour!$V:$V,$C11,BV_Data_An_Cour!$W:$W,L$2) -> 0 | M11: =J11-D11 -> 0 | N11: =L11-F11 -> 0 | O11: =-SUMIFS(BV_Data_An_Prec!$O:$O,BV_Data_An_Prec!$U:$U,$B11,BV_Data_An_Prec!$V:$V,$C11,BV_Data_An_Prec!$W:$W,O$2) -> 0 | P11: =IF(O11=0,0,Q11/O11) -> 0 | Q11: =-SUMIFS(BV_Data_An_Prec!$O:$O,BV_Data_An_Prec!$U:$U,$B11,BV_Data_An_Prec!$V:$V,$C11,BV_Data_An_Prec!$W:$W,Q$2) -> 0 | R11: =J11-O11 -> 0 | S11: =L11-Q11 -> 0
A12: Véhicules neufs[...] | B12: Véhicules neufs | C12: [...] | D12: 0 | E12: =IF(D12=0,0,F12/D12) -> 0 | F12: {=+INDEX('Budget original'!$A$2:$AO$500,MATCH($A12,'Budget original'!$A$2:$A$500,0),MATCH(F$2,'Budget original'!$A$2:$AO$2,0))} -> 0 | J12: =-SUMIFS(BV_Data_An_Cour!$O:$O,BV_Data_An_Cour!$U:$U,$B12,BV_Data_An_Cour!$V:$V,$C12,BV_Data_An_Cour!$W:$W,J$2) -> 0 | K12: =IF(J12=0,0,L12/J12) -> 0 | L12: =-SUMIFS(BV_Data_An_Cour!$O:$O,BV_Data_An_Cour!$U:$U,$B12,BV_Data_An_Cour!$V:$V,$C12,BV_Data_An_Cour!$W:$W,L$2) -> 0 | M12: =J12-D12 -> 0 | N12: =L12-F12 -> 0 | O12: =-SUMIFS(BV_Data_An_Prec!$O:$O,BV_Data_An_Prec!$U:$U,$B12,BV_Data_An_Prec!$V:$V,$C12,BV_Data_An_Prec!$W:$W,O$2) -> 0 | P12: =IF(O12=0,0,Q12/O12) -> 0 | Q12: =-SUMIFS(BV_Data_An_Prec!$O:$O,BV_Data_An_Prec!$U:$U,$B12,BV_Data_An_Prec!$V:$V,$C12,BV_Data_An_Prec!$W:$W,Q$2) -> 0 | R12: =J12-O12 -> 0 | S12: =L12-Q12 -> 0
