Workbook
Name Ticker: #REF!
Name Ticker: #REF!

Sheet Parametres
A1: Compagnie | B1: Volks
G2: 1-Mémo | M2: Mois | N2: YTD
A3: Mois Courant | B3: Juillet | C3: =+VLOOKUP(B3,$K$3:$L$14,2,0) -> 7 | G3: 10-Compte compteur | K3: Janvier | L3: 1 | M3: =+IF($K3=$B$3,"X","") | N3: =+IF(K3=B3,"X",IF(L3<=$C$3,"X","")) -> X
A4: Année | B4: 2025 | K4: Février | L4: 2 | M4: =+IF($K4=$B$3,"X","") | N4: =+IF(K4=B4,"X",IF(L4<=$C$3,"X","")) -> X
K5: Mars | L5: 3 | M5: =+IF($K5=$B$3,"X","") | N5: =+IF(K5=B5,"X",IF(L5<=$C$3,"X","")) -> X
K6: Avril | L6: 4 | M6: =+IF($K6=$B$3,"X","") | N6: =+IF(K6=B6,"X",IF(L6<=$C$3,"X","")) -> X
K7: Mai | L7: 5 | M7: =+IF($K7=$B$3,"X","") | N7: =+IF(K7=B7,"X",IF(L7<=$C$3,"X","")) -> X
K8: Juin | L8: 6 | M8: =+IF($K8=$B$3,"X","") | N8: =+IF(K8=B8,"X",IF(L8<=$C$3,"X","")) -> X
A9: Sélectionner le mois en B3 | K9: Juillet | L9: 7 | M9: =+IF($K9=$B$3,"X","") -> X | N9: =+IF(K9=B9,"X",IF(L9<=$C$3,"X","")) -> X
A10: Coller les balances de vérification respectives en cellule A1 dans les onglets BV_Data_An_Cour et BV_Data_An_Prec | K10: Août | L10: 8 | M10: =+IF($K10=$B$3,"X","") | N10: =+IF(K10=B10,"X",IF(L10<=$C$3,"X",""))
A11: Vérifier s'il y a des #N/A dans les colonnes T à X des onlgets de BV | K11: Septembre | L11: 9 | M11: =+IF($K11=$B$3,"X","") | N11: =+IF(K11=B11,"X",IF(L11<=$C$3,"X",""))
A12: Vérifier les chiffres avec l'état financier et les réalisés an passé pour les résultat net mois et aad | K12: Octobre | L12: 10 | M12: =+IF($K12=$B$3,"X","") | N12: =+IF(K12=B12,"X",IF(L12<=$C$3,"X",""))
K13: Novembre | L13: 11 | M13: =+IF($K13=$B$3,"X","") | N13: =+IF(K13=B13,"X",IF(L13<=$C$3,"X",""))
K14: Décembre | L14: 12 | M14: =+IF($K14=$B$3,"X","") | N14: =+IF(K14=B14,"X",IF(L14<=$C$3,"X",""))

Sheet Bilan
A1: BILAN
A2: =+Parametres!B1 -> Volks
A3: =CONCATENATE("",,Parametres!B3," ",Parametres!B4) -> Juillet 2025
A5: Encaisse | B5: =SUMIFS(BV_Data_An_Cour!$P:$P,BV_Data_An_Cour!$U:$U,$A$1,BV_Data_An_Cour!$V:$V,$A5) -> 104754.7 | D5: Marge de crédit | E5: =-SUMIFS(BV_Data_An_Cour!$P:$P,BV_Data_An_Cour!$U:$U,$A$1,BV_Data_An_Cour!$V:$V,$D5) -> 0
A6: Total Trésorerie et équivalent de Trésorerie | B6: =SUM(B5) -> 104754.7
D7: Portion Court Terme de la Dette Long Terme | E7: =-SUMIFS(BV_Data_An_Cour!$P:$P,BV_Data_An_Cour!$U:$U,$A$1,BV_Data_An_Cour!$V:$V,$D7) -> 0
A8: Recevables Contrats en Transit | B8: =SUMIFS(BV_Data_An_Cour!$P:$P,BV_Data_An_Cour!$U:$U,$A$1,BV_Data_An_Cour!$V:$V,$A8) -> 991942.07
A9: Recevables Véhicules | B9: =SUMIFS(BV_Data_An_Cour!$P:$P,BV_Data_An_Cour!$U:$U,$A$1,BV_Data_An_Cour!$V:$V,$A9) -> 491754.35 | D9: Avances à payer | E9: =-SUMIFS(BV_Data_An_Cour!$P:$P,BV_Data_An_Cour!$U:$U,$A$1,BV_Data_An_Cour!$V:$V,$D9) -> 0
A10: Recevables Manufacturier | B10: =SUMIFS(BV_Data_An_Cour!$P:$P,BV_Data_An_Cour!$U:$U,$A$1,BV_Data_An_Cour!$V:$V,$A10) -> 229390 | D10: Comptes à Payer Fournisseurs | E10: =-SUMIFS(BV_Data_An_Cour!$P:$P,BV_Data_An_Cour!$U:$U,$A$1,BV_Data_An_Cour!$V:$V,$D10) -> 404715.46
A11: Recevables Pièces et Service | B11: =SUMIFS(BV_Data_An_Cour!$P:$P,BV_Data_An_Cour!$U:$U,$A$1,BV_Data_An_Cour!$V:$V,$A11) -> 196011.14 | D11: Taxes de Vente à Payer | E11: =-SUMIFS(BV_Data_An_Cour!$P:$P,BV_Data_An_Cour!$U:$U,$A$1,BV_Data_An_Cour!$V:$V,$D11) -> 72856.79
A12: Recevables Garantie Manufacturier | B12: =SUMIFS(BV_Data_An_Cour!$P:$P,BV_Data_An_Cour!$U:$U,$A$1,BV_Data_An_Cour!$V:$V,$A12) -> 113753.84 | D12: Impôts à payer | E12: =-SUMIFS(BV_Data_An_Cour!$P:$P,BV_Data_An_Cour!$U:$U,$A$1,BV_Data_An_Cour!$V:$V,$D12) -> 0
A13: Recevables Carrosserie | B13: =SUMIFS(BV_Data_An_Cour!$P:$P,BV_Data_An_Cour!$U:$U,$A$1,BV_Data_An_Cour!$V:$V,$A13) -> 10686.27 | D13: Dépôts de Client | E13: =-SUMIFS(BV_Data_An_Cour!$P:$P,BV_Data_An_Cour!$U:$U,$A$1,BV_Data_An_Cour!$V:$V,$D13) -> 28850
A14: Recevables Intercos | B14: =SUMIFS(BV_Data_An_Cour!$P:$P,BV_Data_An_Cour!$U:$U,$A$1,BV_Data_An_Cour!$V:$V,$A14) -> 117631.28 | D14: Payables Intercos | E14: =-SUMIFS(BV_Data_An_Cour!$P:$P,BV_Data_An_Cour!$U:$U,$A$1,BV_Data_An_Cour!$V:$V,$D14) -> 98608.04
A15: Recevables Autres | B15: =SUMIFS(BV_Data_An_Cour!$P:$P,BV_Data_An_Cour!$U:$U,$A$1,BV_Data_An_Cour!$V:$V,$A15) -> -1665.65 | D15: Autres Comptes à Payer | E15: =-SUMIFS(BV_Data_An_Cour!$P:$P,BV_Data_An_Cour!$U:$U,$A$1,BV_Data_An_Cour!$V:$V,$D15) -> 521616
A16: Total Comptes à Recevoir | B16: =+SUM(B8:B15) -> 2149503.3 | D16: Total Comptes à Payer | E16: =+SUM(E10:E15) -> 1126646.3
A18: Inventaire Véhicules Neufs | B18: =SUMIFS(BV_Data_An_Cour!$P:$P,BV_Data_An_Cour!$U:$U,$A$1,BV_Data_An_Cour!$V:$V,$A18) -> 4980838 | D18: Effet à Payer Véhicules Neufs | E18: =-SUMIFS(BV_Data_An_Cour!$P:$P,BV_Data_An_Cour!$U:$U,$A$1,BV_Data_An_Cour!$V:$V,$D18) -> 6607400.1
A19: Inventaire Véhicules Usagés | B19: =SUMIFS(BV_Data_An_Cour!$P:$P,BV_Data_An_Cour!$U:$U,$A$1,BV_Data_An_Cour!$V:$V,$A19) -> 1775371.1 | D19: Effet à Payer Véhicules Usagés | E19: =-SUMIFS(BV_Data_An_Cour!$P:$P,BV_Data_An_Cour!$U:$U,$A$1,BV_Data_An_Cour!$V:$V,$D19) -> 614115.28
A20: Inventaire Pièces, Pneus, Huile | B20: =SUMIFS(BV_Data_An_Cour!$P:$P,BV_Data_An_Cour!$U:$U,$A$1,BV_Data_An_Cour!$V:$V,$A20) -> 573866.21 | D20: Total Effets à Payer | E20: =+SUM(E18:E19) -> 7221515.4
A21: Total Inventaires | B21: =SUM(B18:B20) -> 7330075.3
D22: Salaires à Payer | E22: =-SUMIFS(BV_Data_An_Cour!$P:$P,BV_Data_An_Cour!$U:$U,$A$1,BV_Data_An_Cour!$V:$V,$D22) -> 473403.06
A23: Avances à recevoir | B23: =SUMIFS(BV_Data_An_Cour!$P:$P,BV_Data_An_Cour!$U:$U,$A$1,BV_Data_An_Cour!$V:$V,$A23) -> 0 | D23: DAS à Payer | E23: =-SUMIFS(BV_Data_An_Cour!$P:$P,BV_Data_An_Cour!$U:$U,$A$1,BV_Data_An_Cour!$V:$V,$D23) -> -10796.08
A24: Travaux en Cours | B24: =SUMIFS(BV_Data_An_Cour!$P:$P,BV_Data_An_Cour!$U:$U,$A$1,BV_Data_An_Cour!$V:$V,$A24) -> 12303.47 | D24: Autres Courus | E24: =-SUMIFS(BV_Data_An_Cour!$P:$P,BV_Data_An_Cour!$U:$U,$A$1,BV_Data_An_Cour!$V:$V,$D24) -> 446733.66
A25: Sous-Traitance | B25: =SUMIFS(BV_Data_An_Cour!$P:$P,BV_Data_An_Cour!$U:$U,$A$1,BV_Data_An_Cour!$V:$V,$A25) -> -28170.96 | D25: [...] | E25: =-SUMIFS(BV_Data_An_Cour!$P:$P,BV_Data_An_Cour!$U:$U,$A$1,BV_Data_An_Cour!$V:$V,$D25) -> 0
A26: Frais Payés d'Avance | B26: =SUMIFS(BV_Data_An_Cour!$P:$P,BV_Data_An_Cour!$U:$U,$A$1,BV_Data_An_Cour!$V:$V,$A26) -> -7604.54 | D26: [...] | E26: =-SUMIFS(BV_Data_An_Cour!$P:$P,BV_Data_An_Cour!$U:$U,$A$1,BV_Data_An_Cour!$V:$V,$D26) -> 0
A27: [...] | B27: =SUMIFS(BV_Data_An_Cour!$P:$P,BV_Data_An_Cour!$U:$U,$A$1,BV_Data_An_Cour!$V:$V,$A27) -> 0 | D27: [...] | E27: =-SUMIFS(BV_Data_An_Cour!$P:$P,BV_Data_An_Cour!$U:$U,$A$1,BV_Data_An_Cour!$V:$V,$D27) -> 0
A28: [...] | B28: =SUMIFS(BV_Data_An_Cour!$P:$P,BV_Data_An_Cour!$U:$U,$A$1,BV_Data_An_Cour!$V:$V,$A28) -> 0 | D28: Total Frais Courus | E28: =SUM(E22:E24) -> 909340.64
A29: [...] | B29: =SUMIFS(BV_Data_An_Cour!$P:$P,BV_Data_An_Cour!$U:$U,$A$1,BV_Data_An_Cour!$V:$V,$A29) -> 0
A30: Total Autres | B30: =SUM(B23:B29) -> -23472.03 | D30: Total Passif Court Terme | E30: =+E5+E7+E16+E20+E28 -> 9257502.3
A32: Total Actif Court Terme | B32: =+B6+B16+B21+B30 -> 9560861.3
D33: Impôts Futurs à payer | E33: =-SUMIFS(BV_Data_An_Cour!$P:$P,BV_Data_An_Cour!$U:$U,$A$1,BV_Data_An_Cour!$V:$V,$D33) -> 0
A35: Terrain | B35: =SUMIFS(BV_Data_An_Cour!$P:$P,BV_Data_An_Cour!$U:$U,$A$1,BV_Data_An_Cour!$V:$V,$A35) -> 0 | D35: Avances Long Terme à Payer | E35: =-SUMIFS(BV_Data_An_Cour!$P:$P,BV_Data_An_Cour!$U:$U,$A$1,BV_Data_An_Cour!$V:$V,$D35) -> 0
A36: Bâtisse | B36: =SUMIFS(BV_Data_An_Cour!$P:$P,BV_Data_An_Cour!$U:$U,$A$1,BV_Data_An_Cour!$V:$V,$A36) -> 0 | D36: Hypothèque à Payer | E36: =-SUMIFS(BV_Data_An_Cour!$P:$P,BV_Data_An_Cour!$U:$U,$A$1,BV_Data_An_Cour!$V:$V,$D36) -> 0
A37: Améliorations Locatives | B37: =SUMIFS(BV_Data_An_Cour!$P:$P,BV_Data_An_Cour!$U:$U,$A$1,BV_Data_An_Cour!$V:$V,$A37) -> -8394.37 | D37: Dette à Long Terme | E37: =-SUMIFS(BV_Data_An_Cour!$P:$P,BV_Data_An_Cour!$U:$U,$A$1,BV_Data_An_Cour!$V:$V,$D37) -> 0
A38: Améliorations Locatives Permanentes | B38: =SUMIFS(BV_Data_An_Cour!$P:$P,BV_Data_An_Cour!$U:$U,$A$1,BV_Data_An_Cour!$V:$V,$A38) -> 0 | D38: Autres Dettes à Long Terme | E38: =-SUMIFS(BV_Data_An_Cour!$P:$P,BV_Data_An_Cour!$U:$U,$A$1,BV_Data_An_Cour!$V:$V,$D38) -> 0
A39: Équipements Service | B39: =SUMIFS(BV_Data_An_Cour!$P:$P,BV_Data_An_Cour!$U:$U,$A$1,BV_Data_An_Cour!$V:$V,$A39) -> 385618.82 | D39: [...] | E39: =-SUMIFS(BV_Data_An_Cour!$P:$P,BV_Data_An_Cour!$U:$U,$A$1,BV_Data_An_Cour!$V:$V,$D39) -> 0
A40: Mobilier | B40: =SUMIFS(BV_Data_An_Cour!$P:$P,BV_Data_An_Cour!$U:$U,$A$1,BV_Data_An_Cour!$V:$V,$A40) -> 30124.81 | D40: [...] | E40: =-SUMIFS(BV_Data_An_Cour!$P:$P,BV_Data_An_Cour!$U:$U,$A$1,BV_Data_An_Cour!$V:$V,$D40) -> 0
A41: Équipements Informatique | B41: =SUMIFS(BV_Data_An_Cour!$P:$P,BV_Data_An_Cour!$U:$U,$A$1,BV_Data_An_Cour!$V:$V,$A41) -> 60720.81 | D41: [...] | E41: =-SUMIFS(BV_Data_An_Cour!$P:$P,BV_Data_An_Cour!$U:$U,$A$1,BV_Data_An_Cour!$V:$V,$D41) -> 0
A42: Équipements Téléphonique | B42: =SUMIFS(BV_Data_An_Cour!$P:$P,BV_Data_An_Cour!$U:$U,$A$1,BV_Data_An_Cour!$V:$V,$A42) -> 0 | D42: Total Passif long terme | E42: =+SUM(E33:E38) -> 0
A43: Enseigne | B43: =SUMIFS(BV_Data_An_Cour!$P:$P,BV_Data_An_Cour!$U:$U,$A$1,BV_Data_An_Cour!$V:$V,$A43) -> 6327.01
A44: Total Immobilisations Nettes | B44: =SUM(B35:B43) -> 474397.08
...

Sheet Budget original
B1: ="Budget 2024 Mensuel Révisé"&" "&Parametres!$B$1 -> Budget 2024 Mensuel Révisé Volks
B2: Mois | F2: =+IF(Parametres!$B$3=F$6,"X","") | G2: =+IF(Parametres!$B$3=F$6,"O","") | H2: =+IF(Parametres!$B$3=F$6,"U","") | I2: =+IF(Parametres!$B$3=I$6,"X","") | J2: =+IF(Parametres!$B$3=I$6,"O","") | K2: =+IF(Parametres!$B$3=I$6,"U","") | L2: =+IF(Parametres!$B$3=L$6,"X","") | M2: =+IF(Parametres!$B$3=L$6,"O","") | N2: =+IF(Parametres!$B$3=L$6,"U","") | O2: =+IF(Parametres!$B$3=O$6,"X","") | P2: =+IF(Parametres!$B$3=O$6,"O","") | Q2: =+IF(Parametres!$B$3=O$6,"U","") | R2: =+IF(Parametres!$B$3=R$6,"X","") | S2: =+IF(Parametres!$B$3=R$6,"O","") | T2: =+IF(Parametres!$B$3=R$6,"U","") | U2: =+IF(Parametres!$B$3=U$6,"X","") | V2: =+IF(Parametres!$B$3=U$6,"O","") | W2: =+IF(Parametres!$B$3=U$6,"U","") | X2: =+IF(Parametres!$B$3=X$6,"X","") -> X | Y2: =+IF(Parametres!$B$3=X$6,"O","") -> O | Z2: =+IF(Parametres!$B$3=X$6,"U","") -> U | AA2: =+IF(Parametres!$B$3=AA$6,"X","") | AB2: =+IF(Parametres!$B$3=AA$6,"O","") | AC2: =+IF(Parametres!$B$3=AA$6,"U","") | AD2: =+IF(Parametres!$B$3=AD$6,"X","") | AE2: =+IF(Parametres!$B$3=AD$6,"O","") | AF2: =+IF(Parametres!$B$3=AD$6,"U","") | AG2: =+IF(Parametres!$B$3=AG$6,"X","") | AH2: =+IF(Parametres!$B$3=AG$6,"O","") | AI2: =+IF(Parametres!$B$3=AG$6,"U","") | AJ2: =+IF(Parametres!$B$3=AJ$6,"X","") | AK2: =+IF(Parametres!$B$3=AJ$6,"O","") | AL2: =+IF(Parametres!$B$3=AJ$6,"U","") | AM2: =+IF(Parametres!$B$3=AM$6,"X","") | AN2: =+IF(Parametres!$B$3=AM$6,"O","") | AO2: =+IF(Parametres!$B$3=AM$6,"U","")
B3: YTD | F3: =+IF(VLOOKUP(F$6,Parametres!$K$3:$N$14,4,0)="X","X","") -> X | G3: =+IF(VLOOKUP(F$6,Parametres!$K$3:$N$14,4,0)="X","O","") -> O | H3: =+IF(VLOOKUP(F$6,Parametres!$K$3:$N$14,4,0)="X","U","") -> U | I3: =+IF(VLOOKUP(I$6,Parametres!$K$3:$N$14,4,0)="X","X","") -> X | J3: =+IF(VLOOKUP(I$6,Parametres!$K$3:$N$14,4,0)="X","O","") -> O | K3: =+IF(VLOOKUP(I$6,Parametres!$K$3:$N$14,4,0)="X","U","") -> U | L3: =+IF(VLOOKUP(L$6,Parametres!$K$3:$N$14,4,0)="X","X","") -> X | M3: =+IF(VLOOKUP(L$6,Parametres!$K$3:$N$14,4,0)="X","O","") -> O | N3: =+IF(VLOOKUP(L$6,Parametres!$K$3:$N$14,4,0)="X","U","") -> U | O3: =+IF(VLOOKUP(O$6,Parametres!$K$3:$N$14,4,0)="X","X","") -> X | P3: =+IF(VLOOKUP(O$6,Parametres!$K$3:$N$14,4,0)="X","O","") -> O | Q3: =+IF(VLOOKUP(O$6,Parametres!$K$3:$N$14,4,0)="X","U","") -> U | R3: =+IF(VLOOKUP(R$6,Parametres!$K$3:$N$14,4,0)="X","X","") -> X | S3: =+IF(VLOOKUP(R$6,Parametres!$K$3:$N$14,4,0)="X","O","") -> O | T3: =+IF(VLOOKUP(R$6,Parametres!$K$3:$N$14,4,0)="X","U","") -> U | U3: =+IF(VLOOKUP(U$6,Parametres!$K$3:$N$14,4,0)="X","X","") -> X | V3: =+IF(VLOOKUP(U$6,Parametres!$K$3:$N$14,4,0)="X","O","") -> O | W3: =+IF(VLOOKUP(U$6,Parametres!$K$3:$N$14,4,0)="X","U","") -> U | X3: =+IF(VLOOKUP(X$6,Parametres!$K$3:$N$14,4,0)="X","X","") -> X | Y3: =+IF(VLOOKUP(X$6,Parametres!$K$3:$N$14,4,0)="X","O","") -> O | Z3: =+IF(VLOOKUP(X$6,Parametres!$K$3:$N$14,4,0)="X","U","") -> U | AA3: =+IF(VLOOKUP(AA$6,Parametres!$K$3:$N$14,4,0)="X","X","") | AB3: =+IF(VLOOKUP(AA$6,Parametres!$K$3:$N$14,4,0)="X","O","") | AC3: =+IF(VLOOKUP(AA$6,Parametres!$K$3:$N$14,4,0)="X","U","") | AD3: =+IF(VLOOKUP(AD$6,Parametres!$K$3:$N$14,4,0)="X","X","") | AE3: =+IF(VLOOKUP(AD$6,Parametres!$K$3:$N$14,4,0)="X","O","") | AF3: =+IF(VLOOKUP(AD$6,Parametres!$K$3:$N$14,4,0)="X","U","") | AG3: =+IF(VLOOKUP(AG$6,Parametres!$K$3:$N$14,4,0)="X","X","") | AH3: =+IF(VLOOKUP(AG$6,Parametres!$K$3:$N$14,4,0)="X","O","") | AI3: =+IF(VLOOKUP(AG$6,Parametres!$K$3:$N$14,4,0)="X","U","") | AJ3: =+IF(VLOOKUP(AJ$6,Parametres!$K$3:$N$14,4,0)="X","X","") | AK3: =+IF(VLOOKUP(AJ$6,Parametres!$K$3:$N$14,4,0)="X","O","") | AL3: =+IF(VLOOKUP(AJ$6,Parametres!$K$3:$N$14,4,0)="X","U","") | AM3: =+IF(VLOOKUP(AM$6,Parametres!$K$3:$N$14,4,0)="X","X","") | AN3: =+IF(VLOOKUP(AM$6,Parametres!$K$3:$N$14,4,0)="X","O","") | AO3: =+IF(VLOOKUP(AM$6,Parametres!$K$3:$N$14,4,0)="X","U","")
B4: Budget 2025 | C4: Véhicules neufs
B6: Mois | C6: 2025 | F6: Janvier | I6: Février | L6: Mars | O6: Avril | R6: Mai | U6: Juin | X6: Juillet | AA6: Août | AD6: Septembre | AG6: Octobre | AJ6: Novembre | AM6: Décembre
C7: UNITE | D7: $P/UNITE | E7: $PROFITS | F7: UNITE | G7: $P/UNITE | H7: $PROFITS | I7: UNITE | J7: $P/UNITE | K7: $PROFITS | L7: UNITE | M7: $P/UNITE | N7: $PROFITS | O7: UNITE | P7: $P/UNITE | Q7: $PROFITS | R7: UNITE | S7: $P/UNITE | T7: $PROFITS | U7: UNITE | V7: $P/UNITE | W7: $PROFITS | X7: UNITE | Y7: $P/UNITE | Z7: $PROFITS | AA7: UNITE | AB7: $P/UNITE | AC7: $PROFITS | AD7: UNITE | AE7: $P/UNITE | AF7: $PROFITS | AG7: UNITE | AH7: $P/UNITE | AI7: $PROFITS | AJ7: UNITE | AK7: $P/UNITE | AL7: $PROFITS | AM7: UNITE | AN7: $P/UNITE | AO7: $PROFITS
A8: =+$C$4&B8 -> Véhicules neufsVentes nettes | B8: Ventes nettes | E8: 42012202 | H8: 2738793.1 | K8: 2857429.7 | N8: 3142915.1 | Q8: 3150915.1 | T8: 3234339.5 | W8: 3782098.2 | Z8: 3782098.2 | AC8: 4621342.2 | AF8: 3359976.1 | AI8: 3781098.2 | AL8: 4620342.2 | AO8: 2940854.1
A9: =+$C$4&B9 -> Véhicules neufsAutos détail | B9: Autos détail | C9: 206 | D9: 1953.6492 | E9: 402451.73 | F9: 15 | G9: 1953.6492 | H9: 29304.738 | I9: 14 | J9: 1953.6492 | K9: 27351.088 | L9: 13 | M9: 1953.6492 | N9: 25397.439 | O9: 15 | P9: 1953.6492 | Q9: 29304.738 | R9: 16 | S9: 1953.6492 | T9: 31258.387 | U9: 19 | V9: 1953.6492 | W9: 37119.334 | X9: 19 | Y9: 1953.6492 | Z9: 37119.334 | AA9: 23 | AB9: 1953.6492 | AC9: 44933.931 | AD9: 16 | AE9: 1953.6492 | AF9: 31258.387 | AG9: 19 | AH9: 1953.6492 | AI9: 37119.334 | AJ9: 23 | AK9: 1953.6492 | AL9: 44933.931 | AM9: 14 | AN9: 1953.6492 | AO9: 27351.088
A10: =+$C$4&B10 -> Véhicules neufsCamions détail | B10: Camions détail | C10: 555 | D10: 2435.9047 | E10: 1351927.1 | F10: 42 | G10: 2435.9047 | H10: 102308 | I10: 38 | J10: 2435.9047 | K10: 92564.378 | L10: 36 | M10: 2435.9047 | N10: 87692.568 | O10: 42 | P10: 2435.9047 | Q10: 102308 | R10: 43 | S10: 2435.9047 | T10: 104743.9 | U10: 50 | V10: 2435.9047 | W10: 121795.23 | X10: 50 | Y10: 2435.9047 | Z10: 121795.23 | AA10: 61 | AB10: 2435.9047 | AC10: 148590.19 | AD10: 44 | AE10: 2435.9047 | AF10: 107179.81 | AG10: 50 | AH10: 2435.9047 | AI10: 121795.23 | AJ10: 60 | AK10: 2435.9047 | AL10: 146154.28 | AM10: 39 | AN10: 2435.9047 | AO10: 95000.282
A11: =+$C$4&B11 -> Véhicules neufsSprinter | B11: Sprinter | C11: 0 | D11: 0 | E11: 0 | F11: 0 | G11: 0 | H11: 0 | I11: 0 | J11: 0 | K11: 0 | L11: 0 | M11: 0 | N11: 0 | O11: 0 | P11: 0 | Q11: 0 | R11: 0 | S11: 0 | T11: 0 | U11: 0 | V11: 0 | W11: 0 | X11: 0 | Y11: 0 | Z11: 0 | AA11: 0 | AB11: 0 | AC11: 0 | AD11: 0 | AE11: 0 | AF11: 0 | AG11: 0 | AH11: 0 | AI11: 0 | AJ11: 0 | AK11: 0 | AL11: 0 | AM11: 0 | AN11: 0 | AO11: 0
A12: =+$C$4&B12 -> Véhicules neufsMoto détail | B12: Moto détail | C12: 0 | D12: 0 | E12: 0 | F12: 0 | G12: 0 | H12: 0 | I12: 0 | J12: 0 | K12: 0 | L12: 0 | M12: 0 | N12: 0 | O12: 0 | P12: 0 | Q12: 0 | R12: 0 | S12: 0 | T12: 0 | U12: 0 | V12: 0 | W12: 0 | X12: 0 | Y12: 0 | Z12: 0 | AA12: 0 | AB12: 0 | AC12: 0 | AD12: 0 | AE12: 0 | AF12: 0 | AG12: 0 | AH12: 0 | AI12: 0 | AJ12: 0 | AK12: 0 | AL12: 0 | AM12: 0 | AN12: 0 | AO12: 0
A13: =+$C$4&B13 -> Véhicules neufs[...] | B13: [...] | C13: 0 | D13: 0 | E13: 0 | G13: 0 | J13: 0 | M13: 0 | P13: 0 | S13: 0 | V13: 0 | Y13: 0 | AB13: 0 | AE13: 0 | AH13: 0 | AK13: 0 | AN13: 0
A14: =+$C$4&B14 -> Véhicules neufs[...] | B14: [...] | C14: 0 | D14: 0 | E14: 0 | G14: 0 | J14: 0 | M14: 0 | P14: 0 | S14: 0 | V14: 0 | Y14: 0 | AB14: 0 | AE14: 0 | AH14: 0 | AK14: 0 | AN14: 0
A15: =+$C$4&B15 -> Véhicules neufs[...] | B15: [...] | C15: 0 | D15: 0 | E15: 0 | G15: 0 | J15: 0 | M15: 0 | P15: 0 | S15: 0 | V15: 0 | Y15: 0 | AB15: 0 | AE15: 0 | AH15: 0 | AK15: 0 | AN15: 0
A16: =+$C$4&B16 -> Véhicules neufsTotal Neufs | B16: Total Neufs | C16: 761 | D16: 2305.3598 | E16: 1754378.8 | F16: 57 | G16: 2308.9953 | H16: 131612.73 | I16: 52 | J16: 2306.0667 | K16: 119915.47 | L16: 49 | M16: 2307.9593 | N16: 113090.01 | O16: 57 | P16: 2308.9953 | Q16: 131612.73 | R16: 59 | S16: 2305.1235 | T16: 136002.29 | U16: 69 | V16: 2303.1097 | W16: 158914.57 | X16: 69 | Y16: 2303.1097 | Z16: 158914.57 | AA16: 84 | AB16: 2303.8585 | AC16: 193524.12 | AD16: 60 | AE16: 2307.3032 | AF16: 138438.19 | AG16: 69 | AH16: 2303.1097 | AI16: 158914.57 | AJ16: 83 | AK16: 2302.2676 | AL16: 191088.21 | AM16: 53 | AN16: 2308.5164 | AO16: 122351.37
A17: =+$C$4&B17 -> Véhicules neufs
A18: =+$C$4&B18 -> Véhicules neufsEx-Démos et courtoisies | B18: Ex-Démos et courtoisies | C18: 39 | D18: 1534.7521 | E18: 59855.334 | F18: 3 | G18: 1534.7521 | H18: 4604.2564 | I18: 3 | J18: 1534.7521 | K18: 4604.2564 | L18: 3 | M18: 1534.7521 | N18: 4604.2564 | O18: 3 | P18: 1534.7521 | Q18: 4604.2564 | R18: 2 | S18: 1534.7521 | T18: 3069.5043 | U18: 4 | V18: 1534.7521 | W18: 6139.0086 | X18: 4 | Y18: 1534.7521 | Z18: 6139.0086 | AA18: 4 | AB18: 1534.7521 | AC18: 6139.0086 | AD18: 3 | AE18: 1534.7521 | AF18: 4604.2564 | AG18: 3 | AH18: 1534.7521 | AI18: 4604.2564 | AJ18: 4 | AK18: 1534.7521 | AL18: 6139.0086 | AM18: 3 | AN18: 1534.7521 | AO18: 4604.2564
A19: =+$C$4&B19 -> Véhicules neufs
A20: =+$C$4&B20 -> Véhicules neufsFlottes | B20: Flottes | C20: 20 | D20: 2393.8521 | E20: 47877.042 | F20: 1 | G20: 2393.8521 | H20: 2393.8521 | I20: 1 | J20: 2393.8521 | K20: 2393.8521 | L20: 1 | M20: 2393.8521 | N20: 2393.8521 | O20: 2 | P20: 2393.8521 | Q20: 4787.7042 | R20: 2 | S20: 2393.8521 | T20: 4787.7042 | U20: 2 | V20: 2393.8521 | W20: 4787.7042 | X20: 2 | Y20: 2393.8521 | Z20: 4787.7042 | AA20: 2 | AB20: 2393.8521 | AC20: 4787.7042 | AD20: 2 | AE20: 2393.8521 | AF20: 4787.7042 | AG20: 2 | AH20: 2393.8521 | AI20: 4787.7042 | AJ20: 2 | AK20: 2393.8521 | AL20: 4787.7042 | AM20: 1 | AN20: 2393.8521 | AO20: 2393.8521
A21: =+$C$4&B21 -> Véhicules neufs
A22: =+$C$4&B22 -> Véhicules neufsRachat bail | B22: Rachat bail | E22: 85000 | H22: 5525 | K22: 5780 | N22: 6375 | Q22: 6375 | T22: 6545 | W22: 7650 | Z22: 7650 | AC22: 9350 | AF22: 6800 | AI22: 7650 | AL22: 9350 | AO22: 5950
A23: =+$C$4&B23 -> Véhicules neufs
A24: =+$C$4&B24 -> Véhicules neufsRev. Finances | B24: Rev. Finances | D24: 50 | E24: 40000 | G24: 50 | H24: 3000 | J24: 50 | K24: 2750 | M24: 50 | N24: 2600 | P24: 50 | Q24: 3000 | S24: 50 | T24: 3050 | V24: 50 | W24: 3650 | Y24: 50 | Z24: 3650 | AB24: 50 | AC24: 4400 | AE24: 50 | AF24: 3150 | AH24: 50 | AI24: 3600 | AK24: 50 | AL24: 4350 | AN24: 50 | AO24: 2800
A25: =+$C$4&B25 -> Véhicules neufsRev. Protections | B25: Rev. Protections | D25: 930 | E25: 744000 | G25: 930 | H25: 55800 | J25: 930 | K25: 51150 | M25: 930 | N25: 48360 | P25: 930 | Q25: 55800 | S25: 930 | T25: 56730 | V25: 930 | W25: 67890 | Y25: 930 | Z25: 67890 | AB25: 930 | AC25: 81840 | AE25: 930 | AF25: 58590 | AH25: 930 | AI25: 66960 | AK25: 930 | AL25: 80910 | AN25: 930 | AO25: 52080
A26: =+$C$4&B26 -> Véhicules neufsRev. Autres | B26: Rev. Autres | D26: 20 | E26: 16000 | G26: 20 | H26: 1200 | J26: 20 | K26: 1100 | M26: 20 | N26: 1040 | P26: 20 | Q26: 1200 | S26: 20 | T26: 1220 | V26: 20 | W26: 1460 | Y26: 20 | Z26: 1460 | AB26: 20 | AC26: 1760 | AE26: 20 | AF26: 1260 | AH26: 20 | AI26: 1440 | AK26: 20 | AL26: 1740 | AN26: 20 | AO26: 1120
A27: =+$C$4&B27 -> Véhicules neufsTotal F&I | B27: Total F&I | C27: 800 | D27: 1000 | E27: 800000 | F27: 60 | G27: 1000 | H27: 60000 | I27: 55 | J27: 1000 | K27: 55000 | L27: 52 | M27: 1000 | N27: 52000 | O27: 60 | P27: 1000 | Q27: 60000 | R27: 61 | S27: 1000 | T27: 61000 | U27: 73 | V27: 1000 | W27: 73000 | X27: 73 | Y27: 1000 | Z27: 73000 | AA27: 88 | AB27: 1000 | AC27: 88000 | AD27: 63 | AE27: 1000 | AF27: 63000 | AG27: 72 | AH27: 1000 | AI27: 72000 | AJ27: 87 | AK27: 1000 | AL27: 87000 | AM27: 56 | AN27: 1000 | AO27: 56000
A28: =+$C$4&B28 -> Véhicules neufs
A29: =+$C$4&B29 -> Véhicules neufs
A30: =+$C$4&B30 -> Véhicules neufsTotal Dépt. Neufs | B30: Total Dépt. Neufs | C30: 820 | D30: 3350.1356 | E30: 2747111.2 | F30: 61 | G30: 3346.4892 | H30: 204135.84 | I30: 56 | J30: 3351.671 | K30: 187693.57 | L30: 53 | M30: 3367.2286 | N30: 178463.12 | O30: 62 | P30: 3344.8338 | Q30: 207379.69 | R30: 63 | S30: 3355.6269 | T30: 211404.5 | U30: 75 | V30: 3339.8837 | W30: 250491.28 | X30: 75 | Y30: 3339.8837 | Z30: 250491.28 | AA30: 90 | AB30: 3353.3425 | AC30: 301800.83 | AD30: 65 | AE30: 3348.1562 | AF30: 217630.15 | AG30: 74 | AH30: 3350.7639 | AI30: 247956.53 | AJ30: 89 | AK30: 3352.4149 | AL30: 298364.92 | AM30: 57 | AN30: 3356.1312 | AO30: 191299.48
A31: =+$C$4&B31 -> Véhicules neufs
A32: =+$C$4&B32 -> Véhicules neufs
A33: =+$C$4&B33 -> Véhicules neufsDEPENSES | B33: DEPENSES
A34: =+$C$4&B34 -> Véhicules neufsComm. vendeurs | B34: Comm. vendeurs | C34: 0.33 | D34: 748.37159 | E34: 598697.27 | F34: 0.33900479 | G34: 769.63686 | H34: 46178.212 | I34: 0.33358069 | J34: 755.22499 | K34: 41537.375 | L34: 0.33665933 | M34: 761.97832 | N34: 39622.872 | O34: 0.33304494 | P34: 756.10632 | Q34: 45366.379 | R34: 0.34122338 | S34: 777.94339 | T34: 47454.547 | U34: 0.32512204 | V34: 735.1035 | W34: 53662.555 | X34: 0.32512204 | Y34: 735.1035 | Z34: 53662.555 | AA34: 0.32397102 | AB34: 735.05757 | AC34: 64685.066 | AD34: 0.33053742 | AE34: 750.49018 | AF34: 47280.881 | AG34: 0.33313833 | AH34: 756.58872 | AI34: 54474.388 | AJ34: 0.31738468 | AK34: 719.50459 | AL34: 62596.899 | AM34: 0.33220695 | AN34: 753.13468 | AO34: 42175.542
A35: =+$C$4&B35 -> Véhicules neufsComm. F&I | B35: Comm. F&I | C35: 0.28 | D35: 280 | E35: 224000 | F35: 0.28 | G35: 280 | H35: 16800 | I35: 0.28 | J35: 280 | K35: 15400 | L35: 0.28 | M35: 280 | N35: 14560 | O35: 0.28 | P35: 280 | Q35: 16800 | R35: 0.28 | S35: 280 | T35: 17080 | U35: 0.28 | V35: 280 | W35: 20440 | X35: 0.28 | Y35: 280 | Z35: 20440 | AA35: 0.28 | AB35: 280 | AC35: 24640 | AD35: 0.28 | AE35: 280 | AF35: 17640 | AG35: 0.28 | AH35: 280 | AI35: 20160 | AJ35: 0.28 | AK35: 280 | AL35: 24360 | AM35: 0.28 | AN35: 280 | AO35: 15680
A36: =+$C$4&B36 -> Véhicules neufsFrais de livraison | B36: Frais de livraison | D36: 115 | E36: 92000 | G36: 115 | H36: 6900 | J36: 115 | K36: 6325 | M36: 115 | N36: 5980 | P36: 115 | Q36: 6900 | S36: 115 | T36: 7015 | V36: 115 | W36: 8395 | Y36: 115 | Z36: 8395 | AB36: 115 | AC36: 10120 | AE36: 115 | AF36: 7245 | AH36: 115 | AI36: 8280 | AK36: 115 | AL36: 10005 | AN36: 115 | AO36: 6440
A37: =+$C$4&B37 -> Véhicules neufsService gratuit 1 | B37: Service gratuit 1 | D37: 10 | E37: 8000 | G37: 10 | H37: 600 | J37: 10 | K37: 550 | M37: 10 | N37: 520 | P37: 10 | Q37: 600 | S37: 10 | T37: 610 | V37: 10 | W37: 730 | Y37: 10 | Z37: 730 | AB37: 10 | AC37: 880 | AE37: 10 | AF37: 630 | AH37: 10 | AI37: 720 | AK37: 10 | AL37: 870 | AN37: 10 | AO37: 560
A38: =+$C$4&B38 -> Véhicules neufsEntretien stock | B38: Entretien stock | D38: 120.75 | E38: 96600 | G38: 120.75 | H38: 7245 | J38: 120.75 | K38: 6641.25 | M38: 120.75 | N38: 6279 | P38: 120.75 | Q38: 7245 | S38: 120.75 | T38: 7365.75 | V38: 120.75 | W38: 8814.75 | Y38: 120.75 | Z38: 8814.75 | AB38: 120.75 | AC38: 10626 | AE38: 120.75 | AF38: 7607.25 | AH38: 120.75 | AI38: 8694 | AK38: 120.75 | AL38: 10505.25 | AN38: 120.75 | AO38: 6762
A39: =+$C$4&B39 -> Véhicules neufsPublicité 1 | B39: Publicité 1 | D39: 101.93 | E39: 81544 | G39: 91.033333 | H39: 5462 | J39: 108.4 | K39: 5962 | M39: 351.19231 | N39: 18262 | P39: 91.033333 | Q39: 5462 | S39: 87.901639 | T39: 5362 | V39: 57.013699 | W39: 4162 | Y39: 57.013699 | Z39: 4162 | AB39: 30.25 | AC39: 2662 | AE39: 81.936508 | AF39: 5162 | AH39: 225.86111 | AI39: 16262 | AK39: 31.747126 | AL39: 2762 | AN39: 104.67857 | AO39: 5862
A40: =+$C$4&B40 -> Véhicules neufsIntérêt de gros | B40: Intérêt de gros | D40: 554.295 | E40: 443436 | G40: 580.19552 | H40: 34811.731 | J40: 623.20302 | K40: 34276.166 | M40: 690.05503 | N40: 35882.862 | P40: 601.02305 | Q40: 36061.383 | S40: 626.28924 | T40: 38203.644 | V40: 523.33758 | W40: 38203.644 | Y40: 560.02013 | Z40: 40881.469 | AB40: 413.84576 | AC40: 36418.427 | AE40: 603.57336 | AF40: 38025.122 | AH40: 565.31871 | AI40: 40702.947 | AK40: 402.18682 | AL40: 34990.253 | AN40: 624.61342 | AO40: 34978.352
A41: =+$C$4&B41 -> Véhicules neufs[...] | B41: [...] | D41: 0 | E41: 0 | G41: 0 | J41: 0 | M41: 0 | P41: 0 | S41: 0 | V41: 0 | Y41: 0 | AB41: 0 | AE41: 0 | AH41: 0 | AK41: 0 | AN41: 0
...

Sheet Réel 2024
B1: ="Réel 2023 Mensuel Révisé"&" "&Parametres!$B$1 -> Réel 2023 Mensuel Révisé Volks
B2: Mois | F2: =+IF(Parametres!$B$3=F$6,"X","") | G2: =+IF(Parametres!$B$3=F$6,"O","") | H2: =+IF(Parametres!$B$3=F$6,"U","") | I2: =+IF(Parametres!$B$3=I$6,"X","") | J2: =+IF(Parametres!$B$3=I$6,"O","") | K2: =+IF(Parametres!$B$3=I$6,"U","") | L2: =+IF(Parametres!$B$3=L$6,"X","") | M2: =+IF(Parametres!$B$3=L$6,"O","") | N2: =+IF(Parametres!$B$3=L$6,"U","") | O2: =+IF(Parametres!$B$3=O$6,"X","") | P2: =+IF(Parametres!$B$3=O$6,"O","") | Q2: =+IF(Parametres!$B$3=O$6,"U","") | R2: =+IF(Parametres!$B$3=R$6,"X","") | S2: =+IF(Parametres!$B$3=R$6,"O","") | T2: =+IF(Parametres!$B$3=R$6,"U","") | U2: =+IF(Parametres!$B$3=U$6,"X","") | V2: =+IF(Parametres!$B$3=U$6,"O","") | W2: =+IF(Parametres!$B$3=U$6,"U","") | X2: =+IF(Parametres!$B$3=X$6,"X","") -> X | Y2: =+IF(Parametres!$B$3=X$6,"O","") -> O | Z2: =+IF(Parametres!$B$3=X$6,"U","") -> U | AA2: =+IF(Parametres!$B$3=AA$6,"X","") | AB2: =+IF(Parametres!$B$3=AA$6,"O","") | AC2: =+IF(Parametres!$B$3=AA$6,"U","") | AD2: =+IF(Parametres!$B$3=AD$6,"X","") | AE2: =+IF(Parametres!$B$3=AD$6,"O","") | AF2: =+IF(Parametres!$B$3=AD$6,"U","") | AG2: =+IF(Parametres!$B$3=AG$6,"X","") | AH2: =+IF(Parametres!$B$3=AG$6,"O","") | AI2: =+IF(Parametres!$B$3=AG$6,"U","") | AJ2: =+IF(Parametres!$B$3=AJ$6,"X","") | AK2: =+IF(Parametres!$B$3=AJ$6,"O","") | AL2: =+IF(Parametres!$B$3=AJ$6,"U","") | AM2: =+IF(Parametres!$B$3=AM$6,"X","") | AN2: =+IF(Parametres!$B$3=AM$6,"O","") | AO2: =+IF(Parametres!$B$3=AM$6,"U","")
B3: YTD | F3: =+IF(VLOOKUP(F$6,Parametres!$K$3:$N$14,4,0)="X","X","") -> X | G3: =+IF(VLOOKUP(F$6,Parametres!$K$3:$N$14,4,0)="X","O","") -> O | H3: =+IF(VLOOKUP(F$6,Parametres!$K$3:$N$14,4,0)="X","U","") -> U | I3: =+IF(VLOOKUP(I$6,Parametres!$K$3:$N$14,4,0)="X","X","") -> X | J3: =+IF(VLOOKUP(I$6,Parametres!$K$3:$N$14,4,0)="X","O","") -> O | K3: =+IF(VLOOKUP(I$6,Parametres!$K$3:$N$14,4,0)="X","U","") -> U | L3: =+IF(VLOOKUP(L$6,Parametres!$K$3:$N$14,4,0)="X","X","") -> X | M3: =+IF(VLOOKUP(L$6,Parametres!$K$3:$N$14,4,0)="X","O","") -> O | N3: =+IF(VLOOKUP(L$6,Parametres!$K$3:$N$14,4,0)="X","U","") -> U | O3: =+IF(VLOOKUP(O$6,Parametres!$K$3:$N$14,4,0)="X","X","") -> X | P3: =+IF(VLOOKUP(O$6,Parametres!$K$3:$N$14,4,0)="X","O","") -> O | Q3: =+IF(VLOOKUP(O$6,Parametres!$K$3:$N$14,4,0)="X","U","") -> U | R3: =+IF(VLOOKUP(R$6,Parametres!$K$3:$N$14,4,0)="X","X","") -> X | S3: =+IF(VLOOKUP(R$6,Parametres!$K$3:$N$14,4,0)="X","O","") -> O | T3: =+IF(VLOOKUP(R$6,Parametres!$K$3:$N$14,4,0)="X","U","") -> U | U3: =+IF(VLOOKUP(U$6,Parametres!$K$3:$N$14,4,0)="X","X","") -> X | V3: =+IF(VLOOKUP(U$6,Parametres!$K$3:$N$14,4,0)="X","O","") -> O | W3: =+IF(VLOOKUP(U$6,Parametres!$K$3:$N$14,4,0)="X","U","") -> U | X3: =+IF(VLOOKUP(X$6,Parametres!$K$3:$N$14,4,0)="X","X","") -> X | Y3: =+IF(VLOOKUP(X$6,Parametres!$K$3:$N$14,4,0)="X","O","") -> O | Z3: =+IF(VLOOKUP(X$6,Parametres!$K$3:$N$14,4,0)="X","U","") -> U | AA3: =+IF(VLOOKUP(AA$6,Parametres!$K$3:$N$14,4,0)="X","X","") | AB3: =+IF(VLOOKUP(AA$6,Parametres!$K$3:$N$14,4,0)="X","O","") | AC3: =+IF(VLOOKUP(AA$6,Parametres!$K$3:$N$14,4,0)="X","U","") | AD3: =+IF(VLOOKUP(AD$6,Parametres!$K$3:$N$14,4,0)="X","X","") | AE3: =+IF(VLOOKUP(AD$6,Parametres!$K$3:$N$14,4,0)="X","O","") | AF3: =+IF(VLOOKUP(AD$6,Parametres!$K$3:$N$14,4,0)="X","U","") | AG3: =+IF(VLOOKUP(AG$6,Parametres!$K$3:$N$14,4,0)="X","X","") | AH3: =+IF(VLOOKUP(AG$6,Parametres!$K$3:$N$14,4,0)="X","O","") | AI3: =+IF(VLOOKUP(AG$6,Parametres!$K$3:$N$14,4,0)="X","U","") | AJ3: =+IF(VLOOKUP(AJ$6,Parametres!$K$3:$N$14,4,0)="X","X","") | AK3: =+IF(VLOOKUP(AJ$6,Parametres!$K$3:$N$14,4,0)="X","O","") | AL3: =+IF(VLOOKUP(AJ$6,Parametres!$K$3:$N$14,4,0)="X","U","") | AM3: =+IF(VLOOKUP(AM$6,Parametres!$K$3:$N$14,4,0)="X","X","") | AN3: =+IF(VLOOKUP(AM$6,Parametres!$K$3:$N$14,4,0)="X","O","") | AO3: =+IF(VLOOKUP(AM$6,Parametres!$K$3:$N$14,4,0)="X","U","")
B4: Réel 2024 | C4: Véhicules neufs
B6: Mois | C6: 2024 | F6: Janvier | I6: Février | L6: Mars | O6: Avril | R6: Mai | U6: Juin | X6: Juillet | AA6: Août | AD6: Septembre | AG6: Octobre | AJ6: Novembre | AM6: Décembre
C7: UNITE | D7: $P/UNITE | E7: $PROFITS | F7: UNITE | G7: $P/UNITE | H7: $PROFITS | I7: UNITE | J7: $P/UNITE | K7: $PROFITS | L7: UNITE | M7: $P/UNITE | N7: $PROFITS | O7: UNITE | P7: $P/UNITE | Q7: $PROFITS | R7: UNITE | S7: $P/UNITE | T7: $PROFITS | U7: UNITE | V7: $P/UNITE | W7: $PROFITS | X7: UNITE | Y7: $P/UNITE | Z7: $PROFITS | AA7: UNITE | AB7: $P/UNITE | AC7: $PROFITS | AD7: UNITE | AE7: $P/UNITE | AF7: $PROFITS | AG7: UNITE | AH7: $P/UNITE | AI7: $PROFITS | AJ7: UNITE | AK7: $P/UNITE | AL7: $PROFITS | AM7: UNITE | AN7: $P/UNITE | AO7: $PROFITS
A8: =+$C$4&B8 -> Véhicules neufsVentes nettes | B8: Ventes nettes | E8: 38196011 | H8: 2179097.8 | K8: 3708952.5 | N8: 4089927.9 | Q8: 3890022.9 | T8: 3906259.8 | W8: 2093787.4 | Z8: 4524162.1 | AC8: 4621444.5 | AF8: 2442838.5 | AI8: 2470114 | AL8: 2101403.3 | AO8: 2168000.1
A9: =+$C$4&B9 -> Véhicules neufsAutos détail | B9: Autos détail | C9: 183 | D9: 1942.5738 | E9: 355491 | F9: 10 | G9: 1336.532 | H9: 13365.32 | I9: 24 | J9: 2210.4767 | K9: 53051.44 | L9: 14 | M9: 2832.1014 | N9: 39649.42 | O9: 18 | P9: 2168.0939 | Q9: 39025.69 | R9: 18 | S9: 1997.7756 | T9: 35959.96 | U9: 15 | V9: 1651.894 | W9: 24778.41 | X9: 23 | Y9: 1942.4757 | Z9: 44676.94 | AA9: 19 | AB9: 1667.12 | AC9: 31675.28 | AD9: 16 | AE9: 1640.0056 | AF9: 26240.09 | AG9: 12 | AH9: 1802.2583 | AI9: 21627.1 | AJ9: 8 | AK9: 2031.0612 | AL9: 16248.49 | AM9: 6 | AN9: 1532.1433 | AO9: 9192.86
A10: =+$C$4&B10 -> Véhicules neufsCamions détail | B10: Camions détail | C10: 489 | D10: 2368.9078 | E10: 1158395.9 | F10: 34 | G10: 2268.3159 | H10: 77122.74 | I10: 47 | J10: 2454.7581 | K10: 115373.63 | L10: 56 | M10: 2919.9218 | N10: 163515.62 | O10: 51 | P10: 2906.2869 | Q10: 148220.63 | R10: 51 | S10: 2441.8604 | T10: 124534.88 | U10: 25 | V10: 2415.8504 | W10: 60396.26 | X10: 54 | Y10: 2267.4683 | Z10: 122443.29 | AA10: 62 | AB10: 2284.2913 | AC10: 141626.06 | AD10: 26 | AE10: 2080.4762 | AF10: 54092.38 | AG10: 32 | AH10: 1508.5388 | AI10: 48273.24 | AJ10: 27 | AK10: 2114.5019 | AL10: 57091.55 | AM10: 24 | AN10: 1904.4017 | AO10: 45705.64
A11: =+$C$4&B11 -> Véhicules neufsSprinter | B11: Sprinter | C11: 0 | D11: 0 | E11: 0 | F11: 0 | G11: 0 | H11: 0 | I11: 0 | J11: 0 | K11: 0 | L11: 0 | M11: 0 | N11: 0 | O11: 0 | P11: 0 | Q11: 0 | R11: 0 | S11: 0 | T11: 0 | U11: 0 | V11: 0 | W11: 0 | X11: 0 | Y11: 0 | Z11: 0 | AA11: 0 | AB11: 0 | AC11: 0 | AD11: 0 | AE11: 0 | AF11: 0 | AG11: 0 | AH11: 0 | AI11: 0 | AJ11: 0 | AK11: 0 | AL11: 0 | AM11: 0 | AN11: 0 | AO11: 0
A12: =+$C$4&B12 -> Véhicules neufsMoto détail | B12: Moto détail | C12: 0 | D12: 0 | E12: 0 | F12: 0 | G12: 0 | H12: 0 | I12: 0 | J12: 0 | K12: 0 | L12: 0 | M12: 0 | N12: 0 | O12: 0 | P12: 0 | Q12: 0 | R12: 0 | S12: 0 | T12: 0 | U12: 0 | V12: 0 | W12: 0 | X12: 0 | Y12: 0 | Z12: 0 | AA12: 0 | AB12: 0 | AC12: 0 | AD12: 0 | AE12: 0 | AF12: 0 | AG12: 0 | AH12: 0 | AI12: 0 | AJ12: 0 | AK12: 0 | AL12: 0 | AM12: 0 | AN12: 0 | AO12: 0
A13: =+$C$4&B13 -> Véhicules neufs[...] | B13: [...] | C13: 0 | D13: 0 | E13: 0 | G13: 0 | J13: 0 | M13: 0 | P13: 0 | S13: 0 | V13: 0 | Y13: 0 | AB13: 0 | AE13: 0 | AH13: 0 | AK13: 0 | AN13: 0
A14: =+$C$4&B14 -> Véhicules neufs[...] | B14: [...] | C14: 0 | D14: 0 | E14: 0 | G14: 0 | J14: 0 | M14: 0 | P14: 0 | S14: 0 | V14: 0 | Y14: 0 | AB14: 0 | AE14: 0 | AH14: 0 | AK14: 0 | AN14: 0
A15: =+$C$4&B15 -> Véhicules neufs[...] | B15: [...] | C15: 0 | D15: 0 | E15: 0 | G15: 0 | J15: 0 | M15: 0 | P15: 0 | S15: 0 | V15: 0 | Y15: 0 | AB15: 0 | AE15: 0 | AH15: 0 | AK15: 0 | AN15: 0
A16: =+$C$4&B16 -> Véhicules neufsTotal Neufs | B16: Total Neufs | C16: 672 | D16: 2252.8079 | E16: 1513886.9 | F16: 44 | G16: 2056.5468 | H16: 90488.06 | I16: 71 | J16: 2372.1841 | K16: 168425.07 | L16: 70 | M16: 2902.3577 | N16: 203165.04 | O16: 69 | P16: 2713.7148 | Q16: 187246.32 | R16: 69 | S16: 2326.0122 | T16: 160494.84 | U16: 40 | V16: 2129.3667 | W16: 85174.67 | X16: 77 | Y16: 2170.3926 | Z16: 167120.23 | AA16: 81 | AB16: 2139.5227 | AC16: 173301.34 | AD16: 42 | AE16: 1912.6779 | AF16: 80332.47 | AG16: 44 | AH16: 1588.6441 | AI16: 69900.34 | AJ16: 35 | AK16: 2095.4297 | AL16: 73340.04 | AM16: 30 | AN16: 1829.95 | AO16: 54898.5
A17: =+$C$4&B17 -> Véhicules neufs
A18: =+$C$4&B18 -> Véhicules neufsEx-Démos et courtoisies | B18: Ex-Démos et courtoisies | C18: 41 | D18: 1567.3937 | E18: 64263.14 | F18: 2 | G18: 2875.985 | H18: 5751.97 | I18: 2 | J18: 1741.325 | K18: 3482.65 | L18: 4 | M18: 590.49 | N18: 2361.96 | O18: 4 | P18: 2264.375 | Q18: 9057.5 | R18: 5 | S18: 1165.582 | T18: 5827.91 | U18: 0 | V18: 0 | W18: 0 | X18: 3 | Y18: 913.29 | Z18: 2739.87 | AA18: 6 | AB18: 1521.5767 | AC18: 9129.46 | AD18: 3 | AE18: 2567.51 | AF18: 7702.53 | AG18: 6 | AH18: 1038.8833 | AI18: 6233.3 | AJ18: 2 | AK18: 1396.23 | AL18: 2792.46 | AM18: 4 | AN18: 2295.8825 | AO18: 9183.53
A19: =+$C$4&B19 -> Véhicules neufs
A20: =+$C$4&B20 -> Véhicules neufsFlottes | B20: Flottes | C20: 20 | D20: 1710.9615 | E20: 34219.23 | F20: 0 | G20: 0 | H20: 0 | I20: 2 | J20: 1747.28 | K20: 3494.56 | L20: 0 | M20: 0 | N20: 0 | O20: 0 | P20: 0 | Q20: 0 | R20: 0 | S20: 0 | T20: 0 | U20: 0 | V20: 0 | W20: 0 | X20: 5 | Y20: 2550.916 | Z20: 12754.58 | AA20: 1 | AB20: 1402.08 | AC20: 1402.08 | AD20: 1 | AE20: 4920.64 | AF20: 4920.64 | AG20: 2 | AH20: 383.48 | AI20: 766.96 | AJ20: 3 | AK20: 1478.8733 | AL20: 4436.62 | AM20: 6 | AN20: 1073.965 | AO20: 6443.79
A21: =+$C$4&B21 -> Véhicules neufs
A22: =+$C$4&B22 -> Véhicules neufsRachat bail | B22: Rachat bail | E22: 91424.37 | H22: 5000 | K22: 4000 | N22: 7500 | Q22: 6030.37 | T22: 9930 | W22: 6100 | Z22: 10000 | AC22: 4315 | AF22: 14800 | AI22: 10100 | AL22: 7700 | AO22: 5949
A23: =+$C$4&B23 -> Véhicules neufs
A24: =+$C$4&B24 -> Véhicules neufsRev. Finances | B24: Rev. Finances | D24: 15.171052 | E24: 10816.96 | G24: 6.5217391 | H24: 300 | J24: 115.4537 | K24: 8428.12 | M24: 0 | N24: 0 | P24: 0 | Q24: 0 | S24: 10.810811 | T24: 800 | V24: 0 | W24: 0 | Y24: 0 | Z24: 0 | AB24: 0 | AC24: 0 | AE24: 0 | AF24: 0 | AH24: 0 | AI24: 0 | AK24: 0 | AL24: 0 | AN24: 37.907059 | AO24: 1288.84
A25: =+$C$4&B25 -> Véhicules neufsRev. Protections | B25: Rev. Protections | D25: 882.44753 | E25: 629185.09 | G25: 883.63217 | H25: 40647.08 | J25: 899.34425 | K25: 65652.13 | M25: 926.11297 | N25: 68532.36 | P25: 765.92219 | Q25: 55912.32 | S25: 791.51257 | T25: 58571.93 | V25: 775.005 | W25: 31000.2 | Y25: 762.336 | Z25: 60986.88 | AB25: 880.21138 | AC25: 76578.39 | AE25: 1020.234 | AF25: 45910.53 | AH25: 844.5266 | AI25: 42226.33 | AK25: 1044.0162 | AL25: 38628.6 | AN25: 1309.9512 | AO25: 44538.34
A26: =+$C$4&B26 -> Véhicules neufsRev. Autres | B26: Rev. Autres | D26: 10.581304 | E26: 7544.47 | G26: 0 | H26: 0 | J26: 0 | K26: 0 | M26: 0 | N26: 0 | P26: 18.60589 | Q26: 1358.23 | S26: 0 | T26: 0 | V26: 67.475 | W26: 2699 | Y26: 7.12275 | Z26: 569.82 | AB26: 0 | AC26: 0 | AE26: 36.183111 | AF26: 1628.24 | AH26: 12.8804 | AI26: 644.02 | AK26: 17.436757 | AL26: 645.16 | AN26: 0 | AO26: 0
A27: =+$C$4&B27 -> Véhicules neufsTotal F&I | B27: Total F&I | C27: 713 | D27: 908.19989 | E27: 647546.52 | F27: 46 | G27: 890.15391 | H27: 40947.08 | I27: 73 | J27: 1014.7979 | K27: 74080.25 | L27: 74 | M27: 926.11297 | N27: 68532.36 | O27: 73 | P27: 784.52808 | Q27: 57270.55 | R27: 74 | S27: 802.32338 | T27: 59371.93 | U27: 40 | V27: 842.48 | W27: 33699.2 | X27: 80 | Y27: 769.45875 | Z27: 61556.7 | AA27: 87 | AB27: 880.21138 | AC27: 76578.39 | AD27: 45 | AE27: 1056.4171 | AF27: 47538.77 | AG27: 50 | AH27: 857.407 | AI27: 42870.35 | AJ27: 37 | AK27: 1061.453 | AL27: 39273.76 | AM27: 34 | AN27: 1347.8582 | AO27: 45827.18
A28: =+$C$4&B28 -> Véhicules neufs
A29: =+$C$4&B29 -> Véhicules neufs
A30: =+$C$4&B30 -> Véhicules neufsTotal Dépt. Neufs | B30: Total Dépt. Neufs | C30: 733 | D30: 3207.8311 | E30: 2351340.2 | F30: 46 | G30: 3091.0241 | H30: 142187.11 | I30: 75 | J30: 3379.7671 | K30: 253482.53 | L30: 74 | M30: 3804.8562 | N30: 281559.36 | O30: 73 | P30: 3556.2293 | Q30: 259604.74 | R30: 74 | S30: 3184.1173 | T30: 235624.68 | U30: 40 | V30: 3124.3467 | W30: 124973.87 | X30: 85 | Y30: 2990.2515 | Z30: 254171.38 | AA30: 88 | AB30: 3008.2531 | AC30: 264726.27 | AD30: 46 | AE30: 3375.9654 | AF30: 155294.41 | AG30: 52 | AH30: 2497.5183 | AI30: 129870.95 | AJ30: 40 | AK30: 3188.572 | AL30: 127542.88 | AM30: 40 | AN30: 3057.55 | AO30: 122302
A31: =+$C$4&B31 -> Véhicules neufs
A32: =+$C$4&B32 -> Véhicules neufs
A33: =+$C$4&B33 -> Véhicules neufsDEPENSES | B33: DEPENSES
A34: =+$C$4&B34 -> Véhicules neufsComm. vendeurs | B34: Comm. vendeurs | C34: 0.30428588 | D34: 673.5046 | E34: 480208.78 | F34: 0.35900508 | G34: 751.1013 | H34: 34550.66 | I34: 0.27013796 | J34: 636.14795 | K34: 46438.8 | L34: 0.3078577 | M34: 855.04149 | N34: 63273.07 | O34: 0.24820205 | P34: 667.43849 | Q34: 48723.01 | R34: 0.21053999 | S34: 473.21068 | T34: 35017.59 | U34: 0.30022752 | V34: 639.2945 | W34: 25571.78 | X34: 0.33547025 | Y34: 712.28763 | Z34: 56983.01 | AA34: 0.34952376 | AB34: 732.91839 | AC34: 63763.9 | AD34: 0.34726234 | AE34: 679.36089 | AF34: 30571.24 | AG34: 0.36906117 | AH34: 561.9594 | AI34: 28097.97 | AJ34: 0.31392099 | AK34: 645.93486 | AL34: 23899.59 | AM34: 0.36387986 | AN34: 685.82824 | AO34: 23318.16
A35: =+$C$4&B35 -> Véhicules neufsComm. F&I | B35: Comm. F&I | C35: 0.27412176 | D35: 248.95735 | E35: 177506.59 | F35: 0.29998818 | G35: 267.03565 | H35: 12283.64 | I35: 0.30043055 | J35: 304.8763 | K35: 22255.97 | L35: 0.29634424 | M35: 274.44824 | N35: 20309.17 | O35: 0.29711868 | P35: 233.09795 | Q35: 17016.15 | R35: 0.29999833 | S35: 240.69568 | T35: 17811.48 | U35: 0.0032629855 | V35: 2.749 | W35: 109.96 | X35: 0.26999709 | Y35: 207.75163 | Z35: 16620.13 | AA35: 0.26932885 | AB35: 237.06632 | AC35: 20624.77 | AD35: 0.2977738 | AE35: 314.57333 | AF35: 14155.8 | AG35: 0.26999336 | AH35: 231.4942 | AI35: 11574.71 | AJ35: 0.27998974 | AK35: 297.19595 | AL35: 10996.25 | AM35: 0.30000886 | AN35: 404.36941 | AO35: 13748.56
A36: =+$C$4&B36 -> Véhicules neufsFrais de livraison | B36: Frais de livraison | D36: 122.99884 | E36: 87698.17 | G36: 164.2663 | H36: 7556.25 | J36: 117.11219 | K36: 8549.19 | M36: 115.96514 | N36: 8581.42 | P36: 51.42137 | Q36: 3753.76 | S36: 153.52486 | T36: 11360.84 | V36: 130.5265 | W36: 5221.06 | Y36: 95.093 | Z36: 7607.44 | AB36: 120.29333 | AC36: 10465.52 | AE36: 123.12511 | AF36: 5540.63 | AH36: 156.3466 | AI36: 7817.33 | AK36: 233.92757 | AL36: 8655.32 | AN36: 76.159118 | AO36: 2589.41
A37: =+$C$4&B37 -> Véhicules neufsService gratuit 1 | B37: Service gratuit 1 | D37: 21.524348 | E37: 15346.86 | G37: 8.3769565 | H37: 385.34 | J37: 17.555205 | K37: 1281.53 | M37: 4.4041892 | N37: 325.91 | P37: 1.5160274 | Q37: 110.67 | S37: 13.206486 | T37: 977.28 | V37: 4.62375 | W37: 184.95 | Y37: 33.065625 | Z37: 2645.25 | AB37: 23.456092 | AC37: 2040.68 | AE37: 36.238889 | AF37: 1630.75 | AH37: 16.8636 | AI37: 843.18 | AK37: 108.85892 | AL37: 4027.78 | AN37: 26.280588 | AO37: 893.54
A38: =+$C$4&B38 -> Véhicules neufsEntretien stock | B38: Entretien stock | D38: 122.40062 | E38: 87271.64 | G38: 127.07739 | H38: 5845.56 | J38: 32.798493 | K38: 2394.29 | M38: 142.67541 | N38: 10557.98 | P38: 164.94 | Q38: 12040.62 | S38: 132.78284 | T38: 9825.93 | V38: 185.7815 | W38: 7431.26 | Y38: 79.675375 | Z38: 6374.03 | AB38: 65.982069 | AC38: 5740.44 | AE38: 174.15711 | AF38: 7837.07 | AH38: 159.8588 | AI38: 7992.94 | AK38: 212.08676 | AL38: 7847.21 | AN38: 99.538529 | AO38: 3384.31
A39: =+$C$4&B39 -> Véhicules neufsPublicité 1 | B39: Publicité 1 | D39: 144.03689 | E39: 102698.3 | G39: 158.61696 | H39: 7296.38 | J39: -25.284384 | K39: -1845.76 | M39: 152.39 | N39: 11276.86 | P39: 131.05397 | Q39: 9566.94 | S39: 164.58405 | T39: 12179.22 | V39: 266.85925 | W39: 10674.37 | Y39: 39.7595 | Z39: 3180.76 | AB39: 8.5896552 | AC39: 747.3 | AE39: 180.94756 | AF39: 8142.64 | AH39: 224.6836 | AI39: 11234.18 | AK39: 527.05568 | AL39: 19501.06 | AN39: 316.01029 | AO39: 10744.35
A40: =+$C$4&B40 -> Véhicules neufsIntérêt de gros | B40: Intérêt de gros | D40: 430.43816 | E40: 306902.41 | G40: 488.54978 | H40: 22473.29 | J40: 418.82699 | K40: 30574.37 | M40: 473.94432 | N40: 35071.88 | P40: 474.72863 | Q40: 34655.19 | S40: 644.70649 | T40: 47708.28 | V40: 1001.4042 | W40: 40056.17 | Y40: 565.70337 | Z40: 45256.27 | AB40: 400.05483 | AC40: 34804.77 | AE40: 678.81778 | AF40: 30546.8 | AH40: 530.407 | AI40: 26520.35 | AK40: -1003.7751 | AL40: -37139.68 | AN40: -106.62588 | AO40: -3625.28
A41: =+$C$4&B41 -> Véhicules neufs[...] | B41: [...] | D41: 0 | E41: 0 | G41: 0 | J41: 0 | M41: 0 | P41: 0 | S41: 0 | V41: 0 | Y41: 0 | AB41: 0 | AE41: 0 | AH41: 0 | AK41: 0 | AN41: 0
...

Sheet Capex
A1: PARK AVENUE VOLKSWAGEN | B1: PARK AVENUE VOLKSWAGEN
A2: Forecast Immobilisation 2022 | B2: Forecast Immobilisation 2025 | H2: 1 | I2: 2 | J2: 3 | K2: 4 | L2: 5 | M2: 6 | N2: 7 | O2: 8 | P2: 9 | Q2: 10 | R2: 11 | S2: 12
H3: =+IF(VLOOKUP(H2,Parametres!$L$3:$N$14,3,0)="X","REEL","FORECAST") -> REEL | I3: =+IF(VLOOKUP(I2,Parametres!$L$3:$N$14,3,0)="X","REEL","FORECAST") -> REEL | J3: =+IF(VLOOKUP(J2,Parametres!$L$3:$N$14,3,0)="X","REEL","FORECAST") -> REEL | K3: =+IF(VLOOKUP(K2,Parametres!$L$3:$N$14,3,0)="X","REEL","FORECAST") -> REEL | L3: =+IF(VLOOKUP(L2,Parametres!$L$3:$N$14,3,0)="X","REEL","FORECAST") -> REEL | M3: =+IF(VLOOKUP(M2,Parametres!$L$3:$N$14,3,0)="X","REEL","FORECAST") -> REEL | N3: =+IF(VLOOKUP(N2,Parametres!$L$3:$N$14,3,0)="X","REEL","FORECAST") -> REEL | O3: =+IF(VLOOKUP(O2,Parametres!$L$3:$N$14,3,0)="X","REEL","FORECAST") -> FORECAST | ... S3: =+IF(VLOOKUP(S2,Parametres!$L$3:$N$14,3,0)="X","REEL","FORECAST") -> FORECAST
A4: Concession | B4: Budgété / Non budgété | C4: Projet | D4: Catégorie Immo | E4: Total forecast | F4: Budget Annuel | G4: Écart vs budget | H4: January | I4: February | J4: March | K4: April | L4: May | M4: June | N4: July | O4: August | P4: September | Q4: October | R4: November | S4: December | T4: Raison / Description
C5: Total | E5: =+SUM(E6:E20) -> 90029.98 | F5: =+SUM(F6:F20) -> 40000 | G5: =+SUM(G6:G20) -> 50029.98 | H5: =+SUM(H6:H20) -> 30931.3 | I5: =+SUM(I6:I20) -> 5073.24 | J5: =+SUM(J6:J20) -> 0 | K5: =+SUM(K6:K20) -> 0 | L5: =+SUM(L6:L20) -> 33385.44 | ... S5: =+SUM(S6:S20) -> 0 | X5: Terrain
A6: =+Parametres!$B$1 -> Volks | B6: oui | C6: Outils Spécialisés Volks | E6: =+SUM(H6:S6) -> 40000.46 | F6: 40000 | G6: =+E6-F6 -> 0.46 | I6: 2000 | L6: 17360.46 | P6: 10000 | R6: 10640 | X6: Bâtisse
A7: =+Parametres!$B$1 -> Volks | B7: non | C7: Équipement informatique | E7: =+SUM(H7:S7) -> 5924.22 | G7: =+E7-F7 -> 5924.22 | I7: 3073.24 | L7: 2850.98 | X7: Améliorations Locatives
A8: =+Parametres!$B$1 -> Volks | C8: Nouveau building | E8: =+SUM(H8:S8) -> 44105.3 | G8: =+E8-F8 -> 44105.3 | H8: 30931.3 | L8: =1012+1690+10472 -> 13174 | X8: Mobilier
A9: =+Parametres!$B$1 -> Volks | E9: =+SUM(H9:S9) -> 0 | G9: =+E9-F9 -> 0 | X9: Équipements Informatique
A10: =+Parametres!$B$1 -> Volks | E10: =+SUM(H10:S10) -> 0 | G10: =+E10-F10 -> 0 | X10: Équipements Téléphonique
A11: =+Parametres!$B$1 -> Volks | E11: =+SUM(H11:S11) -> 0 | G11: =+E11-F11 -> 0 | X11: Enseigne
A12: =+Parametres!$B$1 -> Volks | E12: =+SUM(H12:S12) -> 0 | G12: =+E12-F12 -> 0
A13: =+Parametres!$B$1 -> Volks | E13: =+SUM(H13:S13) -> 0 | G13: =+E13-F13 -> 0
A14: =+Parametres!$B$1 -> Volks | E14: =+SUM(H14:S14) -> 0 | G14: =+E14-F14 -> 0
A15: =+Parametres!$B$1 -> Volks | E15: =+SUM(H15:S15) -> 0 | G15: =+E15-F15 -> 0
A16: =+Parametres!$B$1 -> Volks | E16: =+SUM(H16:S16) -> 0 | G16: =+E16-F16 -> 0
A17: =+Parametres!$B$1 -> Volks | E17: =+SUM(H17:S17) -> 0 | G17: =+E17-F17 -> 0 | X17: non
A18: =+Parametres!$B$1 -> Volks | E18: =+SUM(H18:S18) -> 0 | G18: =+E18-F18 -> 0
A19: =+Parametres!$B$1 -> Volks | E19: =+SUM(H19:S19) -> 0 | G19: =+E19-F19 -> 0
A20: =+Parametres!$B$1 -> Volks | E20: =+SUM(H20:S20) -> 0 | G20: =+E20-F20 -> 0

Sheet Inventaire_Used
A1: #Contrôle | B1: Année | C1: Marque | D1: Modèle | E1: 1416 | F1: 2103 | G1: NIV | H1: Jours en stock | M1: 45169 | N1: $ Inventaire | O1: $ Financé
A2: 5291P | B2: 2020 | C2: VOLKSWAGEN | D2: E-GOLF | E2: 32007.51 | F2: -22494.36 | G2: WVWPR7AU2LW903993 | H2: 423 | M2: CTRL | N2: =+SUM(E:E) -> 2779322.1 | O2: =+SUM(F:F) -> -640715.53
A3: 230251A | B3: 2020 | C3: VOLKSWAGEN | D3: E-GOLF | E3: 24454.46 | G3: WVWPR7AU0LW907198 | H3: 306 | M3: Unités | N3: =COUNT(E:E) -> 111 | O3: =-O2/N2 -> 0.23052943
A4: 230425A | B4: 2021 | C4: VOLKSWAGEN | D4: ATLAS CROSS SPO | E4: 37735.15 | G4: 1V2LC2CAXMC211536 | H4: 188
A5: 230365A | B5: 2018 | C5: VOLKSWAGEN | D5: BEETLE CONVERTI | E5: 29929.55 | G5: 3VW5DAAT2JM518129 | H5: 187 | M5: Moyenne | N5: =+N2/N3 -> 25038.938
A6: 5485P | B6: 2018 | C6: VOLKSWAGEN | D6: ATLAS | E6: 31306.12 | G6: 1V2NR2CA5JC509107 | H6: 131
A7: 230554A | B7: 2014 | C7: SUBARU | D7: WRX | E7: 17680.42 | G7: JF1GR8H60EL238082 | H7: 121 | M7: Plus de 90 Jours | N7: =SUM(E2:E13) -> 337989.36 | O7: =+N7/N2 -> 0.12160856
A8: 230567A | B8: 2021 | C8: VOLKSWAGEN | D8: TIGUAN | E8: 28635.15 | F8: -31332.8 | G8: 3VV2B7AX6MM155874 | H8: 104 | N8: =COUNT(H2:H13) -> 12 | O8: =+N8/(N3) -> 0.10810811
A9: 240013A | B9: 2022 | C9: VOLKSWAGEN | D9: TIGUAN | E9: 38815.25 | G9: 3VV4B7AX3NM051496 | H9: 94
A10: 230392A | B10: 2020 | C10: VOLKSWAGEN | D10: TIGUAN | E10: 31315.25 | F10: -24944.54 | G10: 3VV4B7AX2LM114164 | H10: 94
A11: 230599A | B11: 2019 | C11: VOLKSWAGEN | D11: JETTA | E11: 21280.25 | F11: -10962 | G11: 3VWE57BU6KM254342 | H11: 94
A12: 230606A | B12: 2018 | C12: CHEVROLET | D12: VOLT | E12: 17550 | G12: 1G1RA6S50JU104989 | H12: 93
A13: 240015A | B13: 2019 | C13: VOLKSWAGEN | D13: GOLF GTI | E13: 27280.25 | F13: -17480.23 | G13: 3VW6T7AU5KM024755 | H13: 90
A14: 5511P | B14: 2022 | C14: VOLKSWAGEN | D14: ATLAS CROSS SPO | E14: 44105.05 | F14: -38250 | G14: 1V2BE2CA6NC212111 | H14: 88
A15: 240019A | B15: 2020 | C15: VOLKSWAGEN | D15: ATLAS CROSS SPO | E15: 36415.13 | F15: -26892 | G15: 1V2TE2CA8LC219420 | H15: 82
A16: 230596A | B16: 2020 | C16: VOLKSWAGEN | D16: TIGUAN | E16: 27935.05 | G16: 3VV2B7AX4LM005048 | H16: 76
A17: 5509PA | B17: 2017 | C17: AUDI | D17: A3 E-TRON | E17: 20050 | G17: WAUSPBFF5HA099610 | H17: 74
A18: 230626A | B18: 2018 | C18: VOLKSWAGEN | D18: TIGUAN | E18: 20497.05 | G18: 3VV4B7AX2JM130250 | H18: 72
A19: 5518P | B19: 2020 | C19: VOLKSWAGEN | D19: TIGUAN | E19: 28075.78 | F19: -23850 | G19: 3VV4B7AX0LM106225 | H19: 69
A20: 230593A | B20: 2019 | C20: VOLKSWAGEN | D20: TIGUAN | E20: 26815.25 | G20: 3VV4B7AX3KM183332 | H20: 69
A21: 5519P | B21: 2021 | C21: VOLKSWAGEN | D21: TIGUAN | E21: 28447.25 | F21: -24418.8 | G21: 3VV2B7AX4MM068281 | H21: 68
A22: 240044A | B22: 2019 | C22: VOLKSWAGEN | D22: ATLAS | E22: 29352 | G22: 1V2MR2CA6KC587280 | H22: 66
A23: 240041A | B23: 2018 | C23: VOLKSWAGEN | D23: GOLF | E23: 18787.5 | G23: 3VWG17AU2JM291103 | H23: 66
A24: 240056A | B24: 2020 | C24: VOLKSWAGEN | D24: JETTA | E24: 18043.82 | G24: 3VWN57BU2LM040420 | H24: 65
A25: 240036A | B25: 2021 | C25: VOLKSWAGEN | D25: ATLAS | E25: 40209.65 | G25: 1V2FR2CA8MC595926 | H25: 62
A26: 240079A | B26: 2020 | C26: VOLKSWAGEN | D26: TIGUAN | E26: 30620.3 | G26: 3VV4B7AX5LM110786 | H26: 62
A27: 230564B | B27: 2020 | C27: JEEP | D27: COMPASS | E27: 28211.38 | G27: 3C4NJDDBXLT155667 | H27: 62
A28: 230649A | B28: 2020 | C28: NISSAN | D28: ROGUE | E28: 23550 | G28: 5N1AT2MT7LC775762 | H28: 61
A29: 240086A | B29: 2022 | C29: VOLKSWAGEN | D29: TIGUAN | E29: 36524.6 | G29: 3VV4B7AX9NM096457 | H29: 60
A30: 5522P | B30: 2020 | C30: VOLKSWAGEN | D30: TIGUAN | E30: 24346.21 | F30: -16047.88 | G30: 3VV2B7AX7LM099068 | H30: 60
A31: 5521P | B31: 2019 | C31: VOLKSWAGEN | D31: GOLF | E31: 18530.25 | G31: 3VWG57AU3KM018998 | H31: 60
A32: 5523P | B32: 2021 | C32: VOLKSWAGEN | D32: TIGUAN | E32: 29670.31 | F32: -25505.1 | G32: 3VV2B7AX2MM078047 | H32: 59
A33: 240089A | B33: 2020 | C33: VOLKSWAGEN | D33: JETTA | E33: 22965.2 | G33: 3VWW57BU9LM006236 | H33: 55
A34: 5525P | B34: 2021 | C34: VOLKSWAGEN | D34: TIGUAN | E34: 31666.8 | F34: -33046.59 | G34: 3VV4B7AX1MM155614 | H34: 54
A35: 240059A | B35: 2019 | C35: VOLKSWAGEN | D35: TIGUAN | E35: 24846.26 | G35: 3VV2B7AX7KM049091 | H35: 53
A36: 240099A | B36: 2020 | C36: VOLKSWAGEN | D36: JETTA | E36: 19323.74 | G36: 3VWN57BU9LM077965 | H36: 51
A37: 240098A | B37: 2019 | C37: VOLKSWAGEN | D37: GOLF | E37: 18294.75 | G37: 3VWG57AU0KM034477 | H37: 48
A38: 240038B | B38: 2018 | C38: VOLKSWAGEN | D38: GOLF | E38: 16745.3 | G38: 3VWG17AU9JM275867 | H38: 48
A39: 240091A | B39: 2022 | C39: VOLKSWAGEN | D39: ATLAS | E39: 49927.29 | G39: 1V2FR2CA7NC504226 | H39: 47
A40: 5526P | B40: 2020 | C40: VOLKSWAGEN | D40: TIGUAN | E40: 24483.1 | F40: -18876 | G40: 3VV2B7AX9LM002520 | H40: 47
...

Sheet Inventaire_Neuf
A1: #Contrôle | B1: Année | C1: Marque | D1: Modèle | E1: 1402 | F1: 2101 | G1: NIV | H1: Jours en stock | K1: 45230 | L1: $ Inventaire | M1: $ Financé
A2: 230536 | B2: 2023 | C2: VOLKSWAGEN | D2: JETTA SEDAN | E2: 33666.97 | F2: -31504.85 | G2: 3VW2T7BU7PM053775 | H2: 142 | K2: CTRL | L2: =+SUM(E2:E9963) -> 3059537.1 | M2: =+SUM(F2:F9963) -> -2668372
A3: 240001 | B3: 2024 | C3: VOLKSWAGEN | D3: ATLAS | E3: 56706.1 | F3: -57628.2 | G3: 1V2BR2CA6RC502911 | H3: 142 | K3: Unités | L3: =COUNT(E:E) -> 71 | M3: =-M2/L2 -> 0.8721489
A4: 230574 | B4: 2023 | C4: VOLKSWAGEN | D4: JETTA SEDAN | E4: 31163.98 | F4: -32628.75 | G4: 3VWGM7BU3PM060824 | H4: 116
A5: 230581 | B5: 2023 | C5: VOLKSWAGEN | D5: TAOS | E5: 38081.07 | F5: -39936.75 | G5: 3VV4X7B27PM374246 | H5: 111
A6: 240003 | B6: 2024 | C6: VOLKSWAGEN | D6: ATLAS | E6: 50511.98 | F6: -51427.95 | G6: 1V2LR2CA2RC511786 | H6: 108 | K6: Plus de 90 jrs | L6: =SUM(E2:E12) -> 532950.79 | M6: =SUM(F2:F12) -> -378366.05
A7: 240009 | B7: 2024 | C7: VOLKSWAGEN | D7: ATLAS CROSS SPT | E7: 54659.17 | F7: -57051.75 | G7: 1V2BE2CA7RC206484 | H7: 104 | L7: 2
A8: 240011 | B8: 2024 | C8: VOLKSWAGEN | D8: ATLAS CROSS SPT | E8: 48328.17 | F8: -51136.05 | G8: 1V2LE2CA3RC208611 | H8: 97
A9: 240016 | B9: 2024 | C9: VOLKSWAGEN | D9: ATLAS CROSS SPT | E9: 57229.1 | G9: 1V2BE2CA1RC206996 | H9: 93 | K9: Plus de 180 jrs | L9: 0 | M9: 0
A10: 240022 | B10: 2024 | C10: VOLKSWAGEN | D10: ATLAS | E10: 58141.01 | G10: 1V2BR2CA4RC506228 | H10: 90 | L10: 0
A11: 240021 | B11: 2024 | C11: VOLKSWAGEN | D11: ATLAS | E11: 48171.23 | G11: 1V2LR2CA8RC516197 | H11: 90
A12: 240020 | B12: 2024 | C12: VOLKSWAGEN | D12: ATLAS CROSS SPT | E12: 56292.01 | F12: -57051.75 | G12: 1V2BE2CA5RC210341 | H12: 90
A13: 240027 | B13: 2024 | C13: VOLKSWAGEN | D13: ATLAS | E13: 56073.92 | F13: -58869.3 | G13: 1V2BR2CA1RC517137 | H13: 86
A14: 240026 | B14: 2024 | C14: VOLKSWAGEN | D14: GOLF GTI | E14: 37397 | F14: -39440.1 | G14: WVWGA7CD7RW121198 | H14: 86
A15: 240030 | B15: 2024 | C15: VOLKSWAGEN | D15: ATLAS CROSS SPT | E15: 56197.99 | F15: -58834.65 | G15: 1V2FE2CAXRC211373 | H15: 82
A16: 230639 | B16: 2023 | C16: VOLKSWAGEN | D16: TAOS | E16: 32135.51 | F16: -34034.7 | G16: 3VVEX7B23PM379190 | H16: 80
A17: 240042 | B17: 2024 | C17: VOLKSWAGEN | D17: ATLAS CROSS SPT | E17: 55950.97 | F17: -58834.65 | G17: 1V2FE2CA4RC210672 | H17: 74
A18: 240047 | B18: 2024 | C18: VOLKSWAGEN | D18: ATLAS CROSS SPT | E18: 55950.97 | F18: -58834.65 | G18: 1V2FE2CA0RC211429 | H18: 74
A19: 240045 | B19: 2024 | C19: VOLKSWAGEN | D19: JETTA SEDAN | E19: 26927 | F19: -28367.85 | G19: 3VWWM7BU5RM010702 | H19: 74
A20: 230643 | B20: 2023 | C20: VOLKSWAGEN | D20: TAOS | E20: 37610 | F20: -39461.1 | G20: 3VV4X7B2XPM382549 | H20: 73
A21: 240052 | B21: 2024 | C21: VOLKSWAGEN | D21: ATLAS CROSS SPT | E21: 55950.97 | F21: -58834.65 | G21: 1V2FE2CAXRC211504 | H21: 73
A22: 240050 | B22: 2024 | C22: VOLKSWAGEN | D22: JETTA SEDAN | E22: 29531 | F22: -31102.05 | G22: 3VWSM7BU4RM014707 | H22: 73
A23: 240070 | B23: 2024 | C23: VOLKSWAGEN | D23: ATLAS CROSS SPT | E23: 54250 | F23: -57051.75 | G23: 1V2BE2CA9RC212335 | H23: 68
... A27: 240083 | B27: 2024 | C27: VOLKSWAGEN | D27: JETTA SEDAN | E27: 32017.87 | F27: -33204.15 | G27: 3VWGM7BU7RM015582 | H27: 62
A28: 240125 | B28: 2024 | C28: VOLKSWAGEN | D28: JETTA GLI | E28: 31816.52 | G28: 3VW8T7BU7RM014696 | H28: 52
A29: 240129 | B29: 2024 | C29: VOLKSWAGEN | D29: JETTA GLI | E29: 31513 | G29: 3VW8T7BU8RM016912 | H29: 51
A30: 240137 | B30: 2024 | C30: VOLKSWAGEN | D30: ATLAS | E30: 48894 | F30: -51427.95 | G30: 1V2LR2CA9RC529461 | H30: 48
A31: 240141 | B31: 2024 | C31: VOLKSWAGEN | D31: ATLAS CROSS SPT | E31: 55948 | F31: -58834.65 | G31: 1V2FE2CA6RC216828 | H31: 48
A32: 240139 | B32: 2024 | C32: VOLKSWAGEN | D32: ATLAS CROSS SPT | E32: 54236.5 | G32: 1V2BE2CAXRC212764 | H32: 48
A33: 240138 | B33: 2024 | C33: VOLKSWAGEN | D33: TAOS | E33: 32864 | F33: -34706.7 | G33: 3VVEX7B22RM012347 | H33: 48
A34: 240147 | B34: 2024 | C34: VOLKSWAGEN | D34: ATLAS | E34: 55259.97 | F34: -58109.1 | G34: 1V2BR2CAXRC525513 | H34: 47
A35: 240156 | B35: 2024 | C35: VOLKSWAGEN | D35: ATLAS CROSS SPT | E35: 53794.97 | F35: -56570.85 | G35: 1V2BE2CA8RC216649 | H35: 45
A36: 240171 | B36: 2024 | C36: VOLKSWAGEN | D36: JETTA SEDAN | E36: 28629 | G36: 3VWEM7BU2RM001760 | H36: 44
A37: 240173 | B37: 2024 | C37: VOLKSWAGEN | D37: ATLAS | E37: 54801.97 | F37: -57628.2 | G37: 1V2BR2CA7RC532368 | H37: 41
A38: 240190 | B38: 2024 | C38: VOLKSWAGEN | D38: ATLAS | E38: 58249.97 | G38: 1V2FR2CA7RC531156 | H38: 38
A39: 240197 | B39: 2024 | C39: VOLKSWAGEN | D39: TIGUAN | E39: 45175.95 | F39: -47526.15 | G39: 3VV4B7AX2RM023873 | H39: 37
A40: 240203 | B40: 2024 | C40: VOLKSWAGEN | D40: TIGUAN | E40: 44101 | F40: -46474.05 | G40: 3VV4B7AX6RM025190 | H40: 34
A41: 240207 | B41: 2024 | C41: VOLKSWAGEN | D41: ATLAS | E41: 54806.97 | F41: -57628.2 | G41: 1V2BR2CA4RC531890 | H41: 33
A42: 240206 | B42: 2024 | C42: VOLKSWAGEN | D42: TAOS | E42: 38195 | F42: -40225.5 | G42: 3VV4X7B25RM012063 | H42: 33
A43: 240212 | B43: 2024 | C43: VOLKSWAGEN | D43: ATLAS CROSS SPT | E43: 56348.1 | F43: -58834.65 | G43: 1V2FE2CA5RC219798 | H43: 30
...

Sheet Print_Mois
C1: =Parametres!B1 -> Volks | K1: Véhicules neufs | S1: =CONCATENATE("Réalisé,"," ",Parametres!B3," ",Parametres!B4) -> Réalisé, Juillet 2025
D2: X | E2: O | F2: U | J2: NB | L2: $ | O2: X | P2: O | Q2: U | V2: *** NE PAS EFFACER / Pour An Précédente ***
D3: BUDGET ORIGINAL | J3: RÉALISATION | M3: ÉCART réel / Budget | O3: ANNÉE PRÉCÉDENTE | R3: ECART (réel/ Ann.Préc.) | V3: NEUF | W3: 0.45
D4: UNITE | E4: $P/UNITÉ | F4: $PROFITS | J4: UNITÉS | K4: $P/UNITE | L4: $PROFITS | M4: UNITÉS | N4: $PROFITS | O4: UNITE | P4: $P/UNITÉ | Q4: $PROFITS | R4: UNITÉS | S4: $PROFITS | V4: USAGE | W4: 0.1
A5: Véhicules neufsVentes nettes | B5: Véhicules neufs | C5: Ventes nettes | F5: =+INDEX('Budget original'!$A$2:$AO$501,MATCH($A5,'Budget original'!$A$2:$A$501,0),MATCH(F$2,'Budget original'!$A$2:$AO$2,0)) -> 3782098.2 | L5: =-SUMIFS(BV_Data_An_Cour!$O:$O,BV_Data_An_Cour!$X:$X,"Oui",BV_Data_An_Cour!$U:$U,$B5) -> 4089468.3 | Q5: {=+INDEX('Réel 2024'!$A$2:$AO$501,MATCH($A5,'Réel 2024'!$A$2:$A$501,0),MATCH(Q$2,'Réel 2024'!$A$2:$AO$2,0))} -> 4524162.1 | V5: SERVICE | W5: 0.225
A6: Véhicules neufsAutos détail | B6: Véhicules neufs | C6: Autos détail | D6: =+INDEX('Budget original'!$A$2:$AO$501,MATCH($A6,'Budget original'!$A$2:$A$501,0),MATCH(D$2,'Budget original'!$A$2:$AO$2,0)) -> 19 | E6: =IF(D6=0,0,F6/D6) -> 1953.6492 | F6: =+INDEX('Budget original'!$A$2:$AO$501,MATCH($A6,'Budget original'!$A$2:$A$501,0),MATCH(F$2,'Budget original'!$A$2:$AO$2,0)) -> 37119.334 | J6: =-SUMIFS(BV_Data_An_Cour!$O:$O,BV_Data_An_Cour!$U:$U,$B6,BV_Data_An_Cour!$V:$V,$C6,BV_Data_An_Cour!$W:$W,J$2) -> 13 | K6: =IF(J6=0,0,L6/J6) -> 1905.2108 | L6: =-SUMIFS(BV_Data_An_Cour!$O:$O,BV_Data_An_Cour!$U:$U,$B6,BV_Data_An_Cour!$V:$V,$C6,BV_Data_An_Cour!$W:$W,L$2) -> 24767.74 | M6: =J6-D6 -> -6 | N6: =L6-F6 -> -12351.594 | O6: =+INDEX('Réel 2024'!$A$2:$AO$501,MATCH($A6,'Réel 2024'!$A$2:$A$501,0),MATCH(O$2,'Réel 2024'!$A$2:$AO$2,0)) -> 23 | P6: =IF(O6=0,0,Q6/O6) -> 1942.4757 | Q6: {=+INDEX('Réel 2024'!$A$2:$AO$501,MATCH($A6,'Réel 2024'!$A$2:$A$501,0),MATCH(Q$2,'Réel 2024'!$A$2:$AO$2,0))} -> 44676.94 | R6: =J6-O6 -> -10 | S6: =L6-Q6 -> -19909.2 | V6: CARROSSERIE | W6: 0.025
A7: Véhicules neufsCamions détail | B7: Véhicules neufs | C7: Camions détail | D7: =+INDEX('Budget original'!$A$2:$AO$501,MATCH($A7,'Budget original'!$A$2:$A$501,0),MATCH(D$2,'Budget original'!$A$2:$AO$2,0)) -> 50 | E7: =IF(D7=0,0,F7/D7) -> 2435.9047 | F7: =+INDEX('Budget original'!$A$2:$AO$501,MATCH($A7,'Budget original'!$A$2:$A$501,0),MATCH(F$2,'Budget original'!$A$2:$AO$2,0)) -> 121795.23 | J7: =-SUMIFS(BV_Data_An_Cour!$O:$O,BV_Data_An_Cour!$U:$U,$B7,BV_Data_An_Cour!$V:$V,$C7,BV_Data_An_Cour!$W:$W,J$2) -> 63 | K7: =IF(J7=0,0,L7/J7) -> 2276.0851 | L7: =-SUMIFS(BV_Data_An_Cour!$O:$O,BV_Data_An_Cour!$U:$U,$B7,BV_Data_An_Cour!$V:$V,$C7,BV_Data_An_Cour!$W:$W,L$2) -> 143393.36 | M7: =J7-D7 -> 13 | N7: =L7-F7 -> 21598.126 | O7: {=+INDEX('Réel 2024'!$A$2:$AO$501,MATCH($A7,'Réel 2024'!$A$2:$A$501,0),MATCH(O$2,'Réel 2024'!$A$2:$AO$2,0))} -> 54 | P7: =IF(O7=0,0,Q7/O7) -> 2267.4683 | Q7: {=+INDEX('Réel 2024'!$A$2:$AO$501,MATCH($A7,'Réel 2024'!$A$2:$A$501,0),MATCH(Q$2,'Réel 2024'!$A$2:$AO$2,0))} -> 122443.29 | R7: =J7-O7 -> 9 | S7: =L7-Q7 -> 20950.07 | V7: PIECES | W7: 0.2
A8: Véhicules neufsSprinter | B8: Véhicules neufs | C8: Sprinter | D8: =+INDEX('Budget original'!$A$2:$AO$501,MATCH($A8,'Budget original'!$A$2:$A$501,0),MATCH(D$2,'Budget original'!$A$2:$AO$2,0)) -> 0 | E8: =IF(D8=0,0,F8/D8) -> 0 | F8: =+INDEX('Budget original'!$A$2:$AO$501,MATCH($A8,'Budget original'!$A$2:$A$501,0),MATCH(F$2,'Budget original'!$A$2:$AO$2,0)) -> 0 | J8: =-SUMIFS(BV_Data_An_Cour!$O:$O,BV_Data_An_Cour!$U:$U,$B8,BV_Data_An_Cour!$V:$V,$C8,BV_Data_An_Cour!$W:$W,J$2) -> 0 | K8: =IF(J8=0,0,L8/J8) -> 0 | L8: =-SUMIFS(BV_Data_An_Cour!$O:$O,BV_Data_An_Cour!$U:$U,$B8,BV_Data_An_Cour!$V:$V,$C8,BV_Data_An_Cour!$W:$W,L$2) -> 0 | M8: =J8-D8 -> 0 | N8: =L8-F8 -> 0 | O8: {=+INDEX('Réel 2024'!$A$2:$AO$501,MATCH($A8,'Réel 2024'!$A$2:$A$501,0),MATCH(O$2,'Réel 2024'!$A$2:$AO$2,0))} -> 0 | P8: =IF(O8=0,0,Q8/O8) -> 0 | Q8: {=+INDEX('Réel 2024'!$A$2:$AO$501,MATCH($A8,'Réel 2024'!$A$2:$A$501,0),MATCH(Q$2,'Réel 2024'!$A$2:$AO$2,0))} -> 0 | R8: =J8-O8 -> 0 | S8: =L8-Q8 -> 0 | W8: =SUM(W3:W7) -> 1
