Workbook
Name Ticker: #REF!
Name Ticker: #REF!

Sheet Parametres
A1: Compagnie | B1: Volks
G2: 1-Mémo | M2: Mois | N2: YTD
A3: Mois Courant | B3: Avril | C3: =+VLOOKUP(B3,$K$3:$L$14,2,0) -> 4 | G3: 10-Compte compteur | K3: Janvier | L3: 1 | M3: =+IF($K3=$B$3,"X","") | N3: =+IF(K3=B3,"X",IF(L3<=$C$3,"X","")) -> X
A4: Année | B4: 2024 | K4: Février | L4: 2 | M4: =+IF($K4=$B$3,"X","") | N4: =+IF(K4=B4,"X",IF(L4<=$C$3,"X","")) -> X
K5: Mars | L5: 3 | M5: =+IF($K5=$B$3,"X","") | N5: =+IF(K5=B5,"X",IF(L5<=$C$3,"X","")) -> X
K6: Avril | L6: 4 | M6: =+IF($K6=$B$3,"X","") -> X | N6: =+IF(K6=B6,"X",IF(L6<=$C$3,"X","")) -> X
K7: Mai | L7: 5 | M7: =+IF($K7=$B$3,"X","") | N7: =+IF(K7=B7,"X",IF(L7<=$C$3,"X",""))
K8: Juin | L8: 6 | M8: =+IF($K8=$B$3,"X","") | N8: =+IF(K8=B8,"X",IF(L8<=$C$3,"X",""))
A9: Sélectionner le mois en B3 | K9: Juillet | L9: 7 | M9: =+IF($K9=$B$3,"X","") | N9: =+IF(K9=B9,"X",IF(L9<=$C$3,"X",""))
A10: Coller les balances de vérification respectives en cellule A1 dans les onglets BV_Data_An_Cour et BV_Data_An_Prec | K10: Août | L10: 8 | M10: =+IF($K10=$B$3,"X","") | N10: =+IF(K10=B10,"X",IF(L10<=$C$3,"X",""))
A11: Vérifier s'il y a des #N/A dans les colonnes T à X des onlgets de BV | K11: Septembre | L11: 9 | M11: =+IF($K11=$B$3,"X","") | N11: =+IF(K11=B11,"X",IF(L11<=$C$3,"X",""))
A12: Vérifier les chiffres avec l'état financier et les réalisés an passé pour les résultat net mois et aad | K12: Octobre | L12: 10 | M12: =+IF($K12=$B$3,"X","") | N12: =+IF(K12=B12,"X",IF(L12<=$C$3,"X",""))
K13: Novembre | L13: 11 | M13: =+IF($K13=$B$3,"X","") | N13: =+IF(K13=B13,"X",IF(L13<=$C$3,"X",""))
K14: Décembre | L14: 12 | M14: =+IF($K14=$B$3,"X","") | N14: =+IF(K14=B14,"X",IF(L14<=$C$3,"X",""))

Sheet Bilan
A1: BILAN
A2: =+Parametres!B1 -> Volks
A3: =CONCATENATE("",,Parametres!B3," ",Parametres!B4) -> Avril 2024
A5: Encaisse | B5: =SUMIFS(BV_Data_An_Cour!$P:$P,BV_Data_An_Cour!$U:$U,$A$1,BV_Data_An_Cour!$V:$V,$A5) -> 1570613.7 | D5: Marge de crédit | E5: =-SUMIFS(BV_Data_An_Cour!$P:$P,BV_Data_An_Cour!$U:$U,$A$1,BV_Data_An_Cour!$V:$V,$D5) -> 0
A6: Total Trésorerie et équivalent de Trésorerie | B6: =SUM(B5) -> 1570613.7
D7: Portion Court Terme de la Dette Long Terme | E7: =-SUMIFS(BV_Data_An_Cour!$P:$P,BV_Data_An_Cour!$U:$U,$A$1,BV_Data_An_Cour!$V:$V,$D7) -> 0
A8: Recevables Contrats en Transit | B8: =SUMIFS(BV_Data_An_Cour!$P:$P,BV_Data_An_Cour!$U:$U,$A$1,BV_Data_An_Cour!$V:$V,$A8) -> 1903267.8
A9: Recevables Véhicules | B9: =SUMIFS(BV_Data_An_Cour!$P:$P,BV_Data_An_Cour!$U:$U,$A$1,BV_Data_An_Cour!$V:$V,$A9) -> 386143.73 | D9: Avances à payer | E9: =-SUMIFS(BV_Data_An_Cour!$P:$P,BV_Data_An_Cour!$U:$U,$A$1,BV_Data_An_Cour!$V:$V,$D9) -> 0
A10: Recevables Manufacturier | B10: =SUMIFS(BV_Data_An_Cour!$P:$P,BV_Data_An_Cour!$U:$U,$A$1,BV_Data_An_Cour!$V:$V,$A10) -> 601016 | D10: Comptes à Payer Fournisseurs | E10: =-SUMIFS(BV_Data_An_Cour!$P:$P,BV_Data_An_Cour!$U:$U,$A$1,BV_Data_An_Cour!$V:$V,$D10) -> 225405.73
A11: Recevables Pièces et Service | B11: =SUMIFS(BV_Data_An_Cour!$P:$P,BV_Data_An_Cour!$U:$U,$A$1,BV_Data_An_Cour!$V:$V,$A11) -> 244017.37 | D11: Taxes de Vente à Payer | E11: =-SUMIFS(BV_Data_An_Cour!$P:$P,BV_Data_An_Cour!$U:$U,$A$1,BV_Data_An_Cour!$V:$V,$D11) -> -230223.21
A12: Recevables Garantie Manufacturier | B12: =SUMIFS(BV_Data_An_Cour!$P:$P,BV_Data_An_Cour!$U:$U,$A$1,BV_Data_An_Cour!$V:$V,$A12) -> 38141.16 | D12: Impôts à payer | E12: =-SUMIFS(BV_Data_An_Cour!$P:$P,BV_Data_An_Cour!$U:$U,$A$1,BV_Data_An_Cour!$V:$V,$D12) -> 0
A13: Recevables Carrosserie | B13: =SUMIFS(BV_Data_An_Cour!$P:$P,BV_Data_An_Cour!$U:$U,$A$1,BV_Data_An_Cour!$V:$V,$A13) -> 29228.72 | D13: Dépôts de Client | E13: =-SUMIFS(BV_Data_An_Cour!$P:$P,BV_Data_An_Cour!$U:$U,$A$1,BV_Data_An_Cour!$V:$V,$D13) -> 33050
A14: Recevables Intercos | B14: =SUMIFS(BV_Data_An_Cour!$P:$P,BV_Data_An_Cour!$U:$U,$A$1,BV_Data_An_Cour!$V:$V,$A14) -> 46289.36 | D14: Payables Intercos | E14: =-SUMIFS(BV_Data_An_Cour!$P:$P,BV_Data_An_Cour!$U:$U,$A$1,BV_Data_An_Cour!$V:$V,$D14) -> 104241.45
A15: Recevables Autres | B15: =SUMIFS(BV_Data_An_Cour!$P:$P,BV_Data_An_Cour!$U:$U,$A$1,BV_Data_An_Cour!$V:$V,$A15) -> 5547.23 | D15: Autres Comptes à Payer | E15: =-SUMIFS(BV_Data_An_Cour!$P:$P,BV_Data_An_Cour!$U:$U,$A$1,BV_Data_An_Cour!$V:$V,$D15) -> 604967.78
A16: Total Comptes à Recevoir | B16: =+SUM(B8:B15) -> 3253651.4 | D16: Total Comptes à Payer | E16: =+SUM(E10:E15) -> 737441.75
A18: Inventaire Véhicules Neufs | B18: =SUMIFS(BV_Data_An_Cour!$P:$P,BV_Data_An_Cour!$U:$U,$A$1,BV_Data_An_Cour!$V:$V,$A18) -> 6603791.7 | D18: Effet à Payer Véhicules Neufs | E18: =-SUMIFS(BV_Data_An_Cour!$P:$P,BV_Data_An_Cour!$U:$U,$A$1,BV_Data_An_Cour!$V:$V,$D18) -> 9510585.8
A19: Inventaire Véhicules Usagés | B19: =SUMIFS(BV_Data_An_Cour!$P:$P,BV_Data_An_Cour!$U:$U,$A$1,BV_Data_An_Cour!$V:$V,$A19) -> 2675437.9 | D19: Effet à Payer Véhicules Usagés | E19: =-SUMIFS(BV_Data_An_Cour!$P:$P,BV_Data_An_Cour!$U:$U,$A$1,BV_Data_An_Cour!$V:$V,$D19) -> 1161904
A20: Inventaire Pièces, Pneus, Huile | B20: =SUMIFS(BV_Data_An_Cour!$P:$P,BV_Data_An_Cour!$U:$U,$A$1,BV_Data_An_Cour!$V:$V,$A20) -> 686479 | D20: Total Effets à Payer | E20: =+SUM(E18:E19) -> 10672490
A21: Total Inventaires | B21: =SUM(B18:B20) -> 9965708.6
D22: Salaires à Payer | E22: =-SUMIFS(BV_Data_An_Cour!$P:$P,BV_Data_An_Cour!$U:$U,$A$1,BV_Data_An_Cour!$V:$V,$D22) -> 437444.62
A23: Avances à recevoir | B23: =SUMIFS(BV_Data_An_Cour!$P:$P,BV_Data_An_Cour!$U:$U,$A$1,BV_Data_An_Cour!$V:$V,$A23) -> 0 | D23: DAS à Payer | E23: =-SUMIFS(BV_Data_An_Cour!$P:$P,BV_Data_An_Cour!$U:$U,$A$1,BV_Data_An_Cour!$V:$V,$D23) -> -319.2
A24: Travaux en Cours | B24: =SUMIFS(BV_Data_An_Cour!$P:$P,BV_Data_An_Cour!$U:$U,$A$1,BV_Data_An_Cour!$V:$V,$A24) -> 11951.17 | D24: Autres Courus | E24: =-SUMIFS(BV_Data_An_Cour!$P:$P,BV_Data_An_Cour!$U:$U,$A$1,BV_Data_An_Cour!$V:$V,$D24) -> 487103.16
A25: Sous-Traitance | B25: =SUMIFS(BV_Data_An_Cour!$P:$P,BV_Data_An_Cour!$U:$U,$A$1,BV_Data_An_Cour!$V:$V,$A25) -> -22753.58 | D25: [...] | E25: =-SUMIFS(BV_Data_An_Cour!$P:$P,BV_Data_An_Cour!$U:$U,$A$1,BV_Data_An_Cour!$V:$V,$D25) -> 0
A26: Frais Payés d'Avance | B26: =SUMIFS(BV_Data_An_Cour!$P:$P,BV_Data_An_Cour!$U:$U,$A$1,BV_Data_An_Cour!$V:$V,$A26) -> 126296.98 | D26: [...] | E26: =-SUMIFS(BV_Data_An_Cour!$P:$P,BV_Data_An_Cour!$U:$U,$A$1,BV_Data_An_Cour!$V:$V,$D26) -> 0
A27: [...] | B27: =SUMIFS(BV_Data_An_Cour!$P:$P,BV_Data_An_Cour!$U:$U,$A$1,BV_Data_An_Cour!$V:$V,$A27) -> 0 | D27: [...] | E27: =-SUMIFS(BV_Data_An_Cour!$P:$P,BV_Data_An_Cour!$U:$U,$A$1,BV_Data_An_Cour!$V:$V,$D27) -> 0
A28: [...] | B28: =SUMIFS(BV_Data_An_Cour!$P:$P,BV_Data_An_Cour!$U:$U,$A$1,BV_Data_An_Cour!$V:$V,$A28) -> 0 | D28: Total Frais Courus | E28: =SUM(E22:E24) -> 924228.58
A29: [...] | B29: =SUMIFS(BV_Data_An_Cour!$P:$P,BV_Data_An_Cour!$U:$U,$A$1,BV_Data_An_Cour!$V:$V,$A29) -> 0
A30: Total Autres | B30: =SUM(B23:B29) -> 115494.57 | D30: Total Passif Court Terme | E30: =+E5+E7+E16+E20+E28 -> 12334160
A32: Total Actif Court Terme | B32: =+B6+B16+B21+B30 -> 14905468
D33: Impôts Futurs à payer | E33: =-SUMIFS(BV_Data_An_Cour!$P:$P,BV_Data_An_Cour!$U:$U,$A$1,BV_Data_An_Cour!$V:$V,$D33) -> 0
A35: Terrain | B35: =SUMIFS(BV_Data_An_Cour!$P:$P,BV_Data_An_Cour!$U:$U,$A$1,BV_Data_An_Cour!$V:$V,$A35) -> 0 | D35: Avances Long Terme à Payer | E35: =-SUMIFS(BV_Data_An_Cour!$P:$P,BV_Data_An_Cour!$U:$U,$A$1,BV_Data_An_Cour!$V:$V,$D35) -> 0
A36: Bâtisse | B36: =SUMIFS(BV_Data_An_Cour!$P:$P,BV_Data_An_Cour!$U:$U,$A$1,BV_Data_An_Cour!$V:$V,$A36) -> 0 | D36: Hypothèque à Payer | E36: =-SUMIFS(BV_Data_An_Cour!$P:$P,BV_Data_An_Cour!$U:$U,$A$1,BV_Data_An_Cour!$V:$V,$D36) -> 0
A37: Améliorations Locatives | B37: =SUMIFS(BV_Data_An_Cour!$P:$P,BV_Data_An_Cour!$U:$U,$A$1,BV_Data_An_Cour!$V:$V,$A37) -> 4334085.7 | D37: Dette à Long Terme | E37: =-SUMIFS(BV_Data_An_Cour!$P:$P,BV_Data_An_Cour!$U:$U,$A$1,BV_Data_An_Cour!$V:$V,$D37) -> 0
A38: Améliorations Locatives Permanentes | B38: =SUMIFS(BV_Data_An_Cour!$P:$P,BV_Data_An_Cour!$U:$U,$A$1,BV_Data_An_Cour!$V:$V,$A38) -> 0 | D38: Autres Dettes à Long Terme | E38: =-SUMIFS(BV_Data_An_Cour!$P:$P,BV_Data_An_Cour!$U:$U,$A$1,BV_Data_An_Cour!$V:$V,$D38) -> 0
A39: Équipements Service | B39: =SUMIFS(BV_Data_An_Cour!$P:$P,BV_Data_An_Cour!$U:$U,$A$1,BV_Data_An_Cour!$V:$V,$A39) -> 378067.54 | D39: [...] | E39: =-SUMIFS(BV_Data_An_Cour!$P:$P,BV_Data_An_Cour!$U:$U,$A$1,BV_Data_An_Cour!$V:$V,$D39) -> 0
A40: Mobilier | B40: =SUMIFS(BV_Data_An_Cour!$P:$P,BV_Data_An_Cour!$U:$U,$A$1,BV_Data_An_Cour!$V:$V,$A40) -> 23119.27 | D40: [...] | E40: =-SUMIFS(BV_Data_An_Cour!$P:$P,BV_Data_An_Cour!$U:$U,$A$1,BV_Data_An_Cour!$V:$V,$D40) -> 0
A41: Équipements Informatique | B41: =SUMIFS(BV_Data_An_Cour!$P:$P,BV_Data_An_Cour!$U:$U,$A$1,BV_Data_An_Cour!$V:$V,$A41) -> 19665.21 | D41: [...] | E41: =-SUMIFS(BV_Data_An_Cour!$P:$P,BV_Data_An_Cour!$U:$U,$A$1,BV_Data_An_Cour!$V:$V,$D41) -> 0
A42: Équipements Téléphonique | B42: =SUMIFS(BV_Data_An_Cour!$P:$P,BV_Data_An_Cour!$U:$U,$A$1,BV_Data_An_Cour!$V:$V,$A42) -> 0 | D42: Total Passif long terme | E42: =+SUM(E33:E38) -> 0
A43: Enseigne | B43: =SUMIFS(BV_Data_An_Cour!$P:$P,BV_Data_An_Cour!$U:$U,$A$1,BV_Data_An_Cour!$V:$V,$A43) -> 0.01
A44: Total Immobilisations Nettes | B44: =SUM(B35:B43) -> 4754937.7
...

Sheet Budget original
B1: ="Budget 2024 Mensuel Révisé"&" "&Parametres!$B$1 -> Budget 2024 Mensuel Révisé Volks
B2: Mois | F2: =+IF(Parametres!$B$3=F$6,"X","") | G2: =+IF(Parametres!$B$3=F$6,"O","") | H2: =+IF(Parametres!$B$3=F$6,"U","") | I2: =+IF(Parametres!$B$3=I$6,"X","") | J2: =+IF(Parametres!$B$3=I$6,"O","") | K2: =+IF(Parametres!$B$3=I$6,"U","") | L2: =+IF(Parametres!$B$3=L$6,"X","") | M2: =+IF(Parametres!$B$3=L$6,"O","") | N2: =+IF(Parametres!$B$3=L$6,"U","") | O2: =+IF(Parametres!$B$3=O$6,"X","") -> X | P2: =+IF(Parametres!$B$3=O$6,"O","") -> O | Q2: =+IF(Parametres!$B$3=O$6,"U","") -> U | R2: =+IF(Parametres!$B$3=R$6,"X","") | S2: =+IF(Parametres!$B$3=R$6,"O","") | T2: =+IF(Parametres!$B$3=R$6,"U","") | U2: =+IF(Parametres!$B$3=U$6,"X","") | V2: =+IF(Parametres!$B$3=U$6,"O","") | W2: =+IF(Parametres!$B$3=U$6,"U","") | X2: =+IF(Parametres!$B$3=X$6,"X","") | Y2: =+IF(Parametres!$B$3=X$6,"O","") | Z2: =+IF(Parametres!$B$3=X$6,"U","") | AA2: =+IF(Parametres!$B$3=AA$6,"X","") | AB2: =+IF(Parametres!$B$3=AA$6,"O","") | AC2: =+IF(Parametres!$B$3=AA$6,"U","") | AD2: =+IF(Parametres!$B$3=AD$6,"X","") | AE2: =+IF(Parametres!$B$3=AD$6,"O","") | AF2: =+IF(Parametres!$B$3=AD$6,"U","") | AG2: =+IF(Parametres!$B$3=AG$6,"X","") | AH2: =+IF(Parametres!$B$3=AG$6,"O","") | AI2: =+IF(Parametres!$B$3=AG$6,"U","") | AJ2: =+IF(Parametres!$B$3=AJ$6,"X","") | AK2: =+IF(Parametres!$B$3=AJ$6,"O","") | AL2: =+IF(Parametres!$B$3=AJ$6,"U","") | AM2: =+IF(Parametres!$B$3=AM$6,"X","") | AN2: =+IF(Parametres!$B$3=AM$6,"O","") | AO2: =+IF(Parametres!$B$3=AM$6,"U","")
B3: YTD | F3: =+IF(VLOOKUP(F$6,Parametres!$K$3:$N$14,4,0)="X","X","") -> X | G3: =+IF(VLOOKUP(F$6,Parametres!$K$3:$N$14,4,0)="X","O","") -> O | H3: =+IF(VLOOKUP(F$6,Parametres!$K$3:$N$14,4,0)="X","U","") -> U | I3: =+IF(VLOOKUP(I$6,Parametres!$K$3:$N$14,4,0)="X","X","") -> X | J3: =+IF(VLOOKUP(I$6,Parametres!$K$3:$N$14,4,0)="X","O","") -> O | K3: =+IF(VLOOKUP(I$6,Parametres!$K$3:$N$14,4,0)="X","U","") -> U | L3: =+IF(VLOOKUP(L$6,Parametres!$K$3:$N$14,4,0)="X","X","") -> X | M3: =+IF(VLOOKUP(L$6,Parametres!$K$3:$N$14,4,0)="X","O","") -> O | N3: =+IF(VLOOKUP(L$6,Parametres!$K$3:$N$14,4,0)="X","U","") -> U | O3: =+IF(VLOOKUP(O$6,Parametres!$K$3:$N$14,4,0)="X","X","") -> X | P3: =+IF(VLOOKUP(O$6,Parametres!$K$3:$N$14,4,0)="X","O","") -> O | Q3: =+IF(VLOOKUP(O$6,Parametres!$K$3:$N$14,4,0)="X","U","") -> U | R3: =+IF(VLOOKUP(R$6,Parametres!$K$3:$N$14,4,0)="X","X","") | S3: =+IF(VLOOKUP(R$6,Parametres!$K$3:$N$14,4,0)="X","O","") | T3: =+IF(VLOOKUP(R$6,Parametres!$K$3:$N$14,4,0)="X","U","") | U3: =+IF(VLOOKUP(U$6,Parametres!$K$3:$N$14,4,0)="X","X","") | V3: =+IF(VLOOKUP(U$6,Parametres!$K$3:$N$14,4,0)="X","O","") | W3: =+IF(VLOOKUP(U$6,Parametres!$K$3:$N$14,4,0)="X","U","") | X3: =+IF(VLOOKUP(X$6,Parametres!$K$3:$N$14,4,0)="X","X","") | Y3: =+IF(VLOOKUP(X$6,Parametres!$K$3:$N$14,4,0)="X","O","") | Z3: =+IF(VLOOKUP(X$6,Parametres!$K$3:$N$14,4,0)="X","U","") | AA3: =+IF(VLOOKUP(AA$6,Parametres!$K$3:$N$14,4,0)="X","X","") | AB3: =+IF(VLOOKUP(AA$6,Parametres!$K$3:$N$14,4,0)="X","O","") | AC3: =+IF(VLOOKUP(AA$6,Parametres!$K$3:$N$14,4,0)="X","U","") | AD3: =+IF(VLOOKUP(AD$6,Parametres!$K$3:$N$14,4,0)="X","X","") | AE3: =+IF(VLOOKUP(AD$6,Parametres!$K$3:$N$14,4,0)="X","O","") | AF3: =+IF(VLOOKUP(AD$6,Parametres!$K$3:$N$14,4,0)="X","U","") | AG3: =+IF(VLOOKUP(AG$6,Parametres!$K$3:$N$14,4,0)="X","X","") | AH3: =+IF(VLOOKUP(AG$6,Parametres!$K$3:$N$14,4,0)="X","O","") | AI3: =+IF(VLOOKUP(AG$6,Parametres!$K$3:$N$14,4,0)="X","U","") | AJ3: =+IF(VLOOKUP(AJ$6,Parametres!$K$3:$N$14,4,0)="X","X","") | AK3: =+IF(VLOOKUP(AJ$6,Parametres!$K$3:$N$14,4,0)="X","O","") | AL3: =+IF(VLOOKUP(AJ$6,Parametres!$K$3:$N$14,4,0)="X","U","") | AM3: =+IF(VLOOKUP(AM$6,Parametres!$K$3:$N$14,4,0)="X","X","") | AN3: =+IF(VLOOKUP(AM$6,Parametres!$K$3:$N$14,4,0)="X","O","") | AO3: =+IF(VLOOKUP(AM$6,Parametres!$K$3:$N$14,4,0)="X","U","")
B4: Budget 2024 | C4: Véhicules neufs
B6: Mois | C6: 2024 | F6: Janvier | I6: Février | L6: Mars | O6: Avril | R6: Mai | U6: Juin | X6: Juillet | AA6: Août | AD6: Septembre | AG6: Octobre | AJ6: Novembre | AM6: Décembre
C7: UNITE | D7: $P/UNITE | E7: $PROFITS | F7: UNITE | G7: $P/UNITE | H7: $PROFITS | I7: UNITE | J7: $P/UNITE | K7: $PROFITS | L7: UNITE | M7: $P/UNITE | N7: $PROFITS | O7: UNITE | P7: $P/UNITE | Q7: $PROFITS | R7: UNITE | S7: $P/UNITE | T7: $PROFITS | U7: UNITE | V7: $P/UNITE | W7: $PROFITS | X7: UNITE | Y7: $P/UNITE | Z7: $PROFITS | AA7: UNITE | AB7: $P/UNITE | AC7: $PROFITS | AD7: UNITE | AE7: $P/UNITE | AF7: $PROFITS | AG7: UNITE | AH7: $P/UNITE | AI7: $PROFITS | AJ7: UNITE | AK7: $P/UNITE | AL7: $PROFITS | AM7: UNITE | AN7: $P/UNITE | AO7: $PROFITS
A8: =+$C$4&B8 -> Véhicules neufsVentes nettes | B8: Ventes nettes | E8: 32266637 | H8: 1621482.2 | K8: 1621482.2 | N8: 2270075 | Q8: 3243094.3 | T8: 3729071 | W8: 2918459.9 | Z8: 2594371.5 | AC8: 2918927.9 | AF8: 2594475.5 | AI8: 3890933.2 | AL8: 3242782.3 | AO8: 1621482.2
A9: =+$C$4&B9 -> Véhicules neufsAutos détail | B9: Autos détail | C9: 120 | D9: 2187.1313 | E9: 262455.76 | F9: 6 | G9: 2198.1219 | H9: 13188.732 | I9: 6 | J9: 2198.1219 | K9: 13188.732 | L9: 8.4 | M9: 2198.1219 | N9: 18464.224 | O9: 12 | P9: 2198.1219 | Q9: 26377.463 | R9: 14 | S9: 2166.7202 | T9: 30334.083 | U9: 11 | V9: 2158.1561 | W9: 23739.717 | X9: 9.6 | Y9: 2198.1219 | Z9: 21101.971 | AA9: 11 | AB9: 2158.1561 | AC9: 23739.717 | AD9: 9.6 | AE9: 2198.1219 | AF9: 21101.971 | AG9: 14.4 | AH9: 2198.1219 | AI9: 31652.956 | AJ9: 12 | AK9: 2198.1219 | AL9: 26377.463 | AM9: 6 | AN9: 2198.1219 | AO9: 13188.732
A10: =+$C$4&B10 -> Véhicules neufsCamions détail | B10: Camions détail | C10: 496 | D10: 2858.8784 | E10: 1418003.7 | F10: 25 | G10: 2850.2587 | H10: 71256.467 | I10: 25 | J10: 2850.2587 | K10: 71256.467 | L10: 35 | M10: 2850.2587 | N10: 99759.054 | O10: 50 | P10: 2850.2587 | Q10: 142512.93 | R10: 57.04 | S10: 2873.2447 | T10: 163889.88 | U10: 44.64 | V10: 2873.2447 | W10: 128261.64 | X10: 40 | Y10: 2850.2587 | Z10: 114010.35 | AA10: 45 | AB10: 2850.2587 | AC10: 128261.64 | AD10: 40 | AE10: 2850.2587 | AF10: 114010.35 | AG10: 59.52 | AH10: 2873.2447 | AI10: 171015.52 | AJ10: 49.8 | AK10: 2861.7055 | AL10: 142512.93 | AM10: 25 | AN10: 2850.2587 | AO10: 71256.467
A11: =+$C$4&B11 -> Véhicules neufsSprinter | B11: Sprinter | C11: 0 | D11: 0 | E11: 0 | F11: 0 | G11: 0 | H11: 0 | I11: 0 | J11: 0 | K11: 0 | L11: 0 | M11: 0 | N11: 0 | O11: 0 | P11: 0 | Q11: 0 | R11: 0 | S11: 0 | T11: 0 | U11: 0 | V11: 0 | W11: 0 | X11: 0 | Y11: 0 | Z11: 0 | AA11: 0 | AB11: 0 | AC11: 0 | AD11: 0 | AE11: 0 | AF11: 0 | AG11: 0 | AH11: 0 | AI11: 0 | AJ11: 0 | AK11: 0 | AL11: 0 | AM11: 0 | AN11: 0 | AO11: 0
A12: =+$C$4&B12 -> Véhicules neufsMoto détail | B12: Moto détail | C12: 0 | D12: 0 | E12: 0 | F12: 0 | G12: 0 | H12: 0 | I12: 0 | J12: 0 | K12: 0 | L12: 0 | M12: 0 | N12: 0 | O12: 0 | P12: 0 | Q12: 0 | R12: 0 | S12: 0 | T12: 0 | U12: 0 | V12: 0 | W12: 0 | X12: 0 | Y12: 0 | Z12: 0 | AA12: 0 | AB12: 0 | AC12: 0 | AD12: 0 | AE12: 0 | AF12: 0 | AG12: 0 | AH12: 0 | AI12: 0 | AJ12: 0 | AK12: 0 | AL12: 0 | AM12: 0 | AN12: 0 | AO12: 0
A13: =+$C$4&B13 -> Véhicules neufs[...] | B13: [...] | C13: 0 | D13: 0 | E13: 0 | G13: 0 | J13: 0 | M13: 0 | P13: 0 | S13: 0 | V13: 0 | Y13: 0 | AB13: 0 | AE13: 0 | AH13: 0 | AK13: 0 | AN13: 0
A14: =+$C$4&B14 -> Véhicules neufs[...] | B14: [...] | C14: 0 | D14: 0 | E14: 0 | G14: 0 | J14: 0 | M14: 0 | P14: 0 | S14: 0 | V14: 0 | Y14: 0 | AB14: 0 | AE14: 0 | AH14: 0 | AK14: 0 | AN14: 0
A15: =+$C$4&B15 -> Véhicules neufs[...] | B15: [...] | C15: 0 | D15: 0 | E15: 0 | G15: 0 | J15: 0 | M15: 0 | P15: 0 | S15: 0 | V15: 0 | Y15: 0 | AB15: 0 | AE15: 0 | AH15: 0 | AK15: 0 | AN15: 0
A16: =+$C$4&B16 -> Véhicules neufsTotal Neufs | B16: Total Neufs | C16: 616 | D16: 2728.0186 | E16: 1680459.5 | F16: 31 | G16: 2724.0387 | H16: 84445.199 | I16: 31 | J16: 2724.0387 | K16: 84445.199 | L16: 43.4 | M16: 2724.0387 | N16: 118223.28 | O16: 62 | P16: 2724.0387 | Q16: 168890.4 | R16: 71.04 | S16: 2734.0084 | T16: 194223.96 | U16: 55.64 | V16: 2731.872 | W16: 152001.36 | X16: 49.6 | Y16: 2724.0387 | Z16: 135112.32 | AA16: 56 | AB16: 2714.31 | AC16: 152001.36 | AD16: 49.6 | AE16: 2724.0387 | AF16: 135112.32 | AG16: 73.92 | AH16: 2741.7272 | AI16: 202668.48 | AJ16: 61.8 | AK16: 2732.8543 | AL16: 168890.4 | AM16: 31 | AN16: 2724.0387 | AO16: 84445.199
A17: =+$C$4&B17 -> Véhicules neufs
A18: =+$C$4&B18 -> Véhicules neufsEx-Démos et courtoisies | B18: Ex-Démos et courtoisies | C18: 48.995 | D18: 2522.7034 | E18: 123599.85 | F18: 2.45 | G18: 2535.1216 | H18: 6211.0479 | I18: 2.45 | J18: 2535.1216 | K18: 6211.0479 | L18: 3.43 | M18: 2535.1216 | N18: 8695.467 | O18: 5 | P18: 2484.4192 | Q18: 12422.096 | R18: 5.635 | S18: 2535.1216 | T18: 14285.41 | U18: 4.41 | V18: 2535.1216 | W18: 11179.886 | X18: 3.92 | Y18: 2535.1216 | Z18: 9937.6766 | AA18: 4.41 | AB18: 2535.1216 | AC18: 11179.886 | AD18: 4 | AE18: 2484.4192 | AF18: 9937.6766 | AG18: 5.88 | AH18: 2535.1216 | AI18: 14906.515 | AJ18: 4.96 | AK18: 2504.4548 | AL18: 12422.096 | AM18: 2.45 | AN18: 2535.1216 | AO18: 6211.0479
A19: =+$C$4&B19 -> Véhicules neufs
A20: =+$C$4&B20 -> Véhicules neufsFlottes | B20: Flottes | C20: 44.775 | D20: 2664.4641 | E20: 119301.38 | F20: 2.25 | G20: 2664.4641 | H20: 5995.0442 | I20: 2.25 | J20: 2664.4641 | K20: 5995.0442 | L20: 3.15 | M20: 2664.4641 | N20: 8393.0618 | O20: 4.5 | P20: 2664.4641 | Q20: 11990.088 | R20: 5.175 | S20: 2664.4641 | T20: 13788.602 | U20: 4.05 | V20: 2664.4641 | W20: 10791.079 | X20: 3.6 | Y20: 2664.4641 | Z20: 9592.0706 | AA20: 4.05 | AB20: 2664.4641 | AC20: 10791.079 | AD20: 3.6 | AE20: 2664.4641 | AF20: 9592.0706 | AG20: 5.4 | AH20: 2664.4641 | AI20: 14388.106 | AJ20: 4.5 | AK20: 2664.4641 | AL20: 11990.088 | AM20: 2.25 | AN20: 2664.4641 | AO20: 5995.0442
A21: =+$C$4&B21 -> Véhicules neufs
A22: =+$C$4&B22 -> Véhicules neufsRachat bail | B22: Rachat bail | E22: 84575 | H22: 4250 | K22: 4250 | N22: 5950 | Q22: 8500 | T22: 9775 | W22: 7650 | Z22: 6800 | AC22: 7650 | AF22: 6800 | AI22: 10200 | AL22: 8500 | AO22: 4250
A23: =+$C$4&B23 -> Véhicules neufs
A24: =+$C$4&B24 -> Véhicules neufsRev. Finances | B24: Rev. Finances | D24: 200 | E24: 132999 | G24: 200 | H24: 6690 | J24: 200 | K24: 6690 | M24: 200 | N24: 9366 | P24: 200 | Q24: 13400 | S24: 200 | T24: 15335 | V24: 200 | W24: 12010 | Y24: 200 | Z24: 10704 | AB24: 200 | AC24: 12082 | AE24: 200 | AF24: 10720 | AH24: 200 | AI24: 15960 | AK24: 200 | AL24: 13352 | AN24: 200 | AO24: 6690
A25: =+$C$4&B25 -> Véhicules neufsRev. Protections | B25: Rev. Protections | D25: 1080 | E25: 718194.6 | G25: 1080 | H25: 36126 | J25: 1080 | K25: 36126 | M25: 1080 | N25: 50576.4 | P25: 1080 | Q25: 72360 | S25: 1080 | T25: 82809 | V25: 1080 | W25: 64854 | Y25: 1080 | Z25: 57801.6 | AB25: 1080 | AC25: 65242.8 | AE25: 1080 | AF25: 57888 | AH25: 1080 | AI25: 86184 | AK25: 1080 | AL25: 72100.8 | AN25: 1080 | AO25: 36126
A26: =+$C$4&B26 -> Véhicules neufsRev. Autres | B26: Rev. Autres | D26: 20 | E26: 13299.9 | G26: 20 | H26: 669 | J26: 20 | K26: 669 | M26: 20 | N26: 936.6 | P26: 20 | Q26: 1340 | S26: 20 | T26: 1533.5 | V26: 20 | W26: 1201 | Y26: 20 | Z26: 1070.4 | AB26: 20 | AC26: 1208.2 | AE26: 20 | AF26: 1072 | AH26: 20 | AI26: 1596 | AK26: 20 | AL26: 1335.2 | AN26: 20 | AO26: 669
A27: =+$C$4&B27 -> Véhicules neufsTotal F&I | B27: Total F&I | C27: 664.995 | D27: 1300 | E27: 864493.5 | F27: 33.45 | G27: 1300 | H27: 43485 | I27: 33.45 | J27: 1300 | K27: 43485 | L27: 46.83 | M27: 1300 | N27: 60879 | O27: 67 | P27: 1300 | Q27: 87100 | R27: 76.675 | S27: 1300 | T27: 99677.5 | U27: 60.05 | V27: 1300 | W27: 78065 | X27: 53.52 | Y27: 1300 | Z27: 69576 | AA27: 60.41 | AB27: 1300 | AC27: 78533 | AD27: 53.6 | AE27: 1300 | AF27: 69680 | AG27: 79.8 | AH27: 1300 | AI27: 103740 | AJ27: 66.76 | AK27: 1300 | AL27: 86788 | AM27: 33.45 | AN27: 1300 | AO27: 43485
A28: =+$C$4&B28 -> Véhicules neufs
A29: =+$C$4&B29 -> Véhicules neufs
A30: =+$C$4&B30 -> Véhicules neufsTotal Dépt. Neufs | B30: Total Dépt. Neufs | C30: 709.77 | D30: 4046.9859 | E30: 2872429.2 | F30: 35.7 | G30: 4044.4339 | H30: 144386.29 | I30: 35.7 | J30: 4044.4339 | K30: 144386.29 | L30: 49.98 | M30: 4044.4339 | N30: 202140.81 | O30: 71.5 | P30: 4040.5956 | Q30: 288902.58 | R30: 81.85 | S30: 4053.1517 | T30: 331750.47 | U30: 64.1 | V30: 4051.2843 | W30: 259687.32 | X30: 57.12 | Y30: 4044.4339 | Z30: 231018.07 | AA30: 64.46 | AB30: 4035.9188 | AC30: 260155.32 | AD30: 57.2 | AE30: 4040.5956 | AF30: 231122.07 | AG30: 85.2 | AH30: 4059.8955 | AI30: 345903.1 | AJ30: 71.26 | AK30: 4049.8257 | AL30: 288590.58 | AM30: 35.7 | AN30: 4044.4339 | AO30: 144386.29
A31: =+$C$4&B31 -> Véhicules neufs
A32: =+$C$4&B32 -> Véhicules neufs
A33: =+$C$4&B33 -> Véhicules neufsDEPENSES | B33: DEPENSES
A34: =+$C$4&B34 -> Véhicules neufsComm. vendeurs | B34: Comm. vendeurs | C34: 0.34 | D34: 922.38313 | E34: 613380.17 | F34: 0.34 | G34: 921.46858 | H34: 30823.124 | I34: 0.34 | J34: 921.46858 | K34: 30823.124 | L34: 0.34 | M34: 921.46858 | N34: 43152.374 | O34: 0.34 | P34: 920.09325 | Q34: 61646.248 | R34: 0.34 | S34: 924.59322 | T34: 70893.185 | U34: 0.34 | V34: 923.92378 | W34: 55481.623 | X34: 0.34 | Y34: 921.46858 | Z34: 49316.998 | AA34: 0.34 | AB34: 918.41786 | AC34: 55481.623 | AD34: 0.34 | AE34: 920.09325 | AF34: 49316.998 | AG34: 0.34 | AH34: 927.01125 | AI34: 73975.497 | AJ34: 0.34 | AK34: 923.40096 | AL34: 61646.248 | AM34: 0.34 | AN34: 921.46858 | AO34: 30823.124
A35: =+$C$4&B35 -> Véhicules neufsComm. F&I | B35: Comm. F&I | C35: 0.3 | D35: 390 | E35: 259348.05 | F35: 0.3 | G35: 390 | H35: 13045.5 | I35: 0.3 | J35: 390 | K35: 13045.5 | L35: 0.3 | M35: 390 | N35: 18263.7 | O35: 0.3 | P35: 390 | Q35: 26130 | R35: 0.3 | S35: 390 | T35: 29903.25 | U35: 0.3 | V35: 390 | W35: 23419.5 | X35: 0.3 | Y35: 390 | Z35: 20872.8 | AA35: 0.3 | AB35: 390 | AC35: 23559.9 | AD35: 0.3 | AE35: 390 | AF35: 20904 | AG35: 0.3 | AH35: 390 | AI35: 31122 | AJ35: 0.3 | AK35: 390 | AL35: 26036.4 | AM35: 0.3 | AN35: 390 | AO35: 13045.5
A36: =+$C$4&B36 -> Véhicules neufsFrais de livraison | B36: Frais de livraison | D36: 115 | E36: 76474.425 | G36: 115 | H36: 3846.75 | J36: 115 | K36: 3846.75 | M36: 115 | N36: 5385.45 | P36: 115 | Q36: 7705 | S36: 115 | T36: 8817.625 | V36: 115 | W36: 6905.75 | Y36: 115 | Z36: 6154.8 | AB36: 115 | AC36: 6947.15 | AE36: 115 | AF36: 6164 | AH36: 115 | AI36: 9177 | AK36: 115 | AL36: 7677.4 | AN36: 115 | AO36: 3846.75
A37: =+$C$4&B37 -> Véhicules neufsService gratuit 1 | B37: Service gratuit 1 | D37: 3 | E37: 1994.985 | G37: 3 | H37: 100.35 | J37: 3 | K37: 100.35 | M37: 3 | N37: 140.49 | P37: 3 | Q37: 201 | S37: 3 | T37: 230.025 | V37: 3 | W37: 180.15 | Y37: 3 | Z37: 160.56 | AB37: 3 | AC37: 181.23 | AE37: 3 | AF37: 160.8 | AH37: 3 | AI37: 239.4 | AK37: 3 | AL37: 200.28 | AN37: 3 | AO37: 100.35
A38: =+$C$4&B38 -> Véhicules neufsEntretien stock | B38: Entretien stock | D38: 85.05 | E38: 56557.825 | G38: 85.05 | H38: 2844.9225 | J38: 85.05 | K38: 2844.9225 | M38: 85.05 | N38: 3982.8915 | P38: 85.05 | Q38: 5698.35 | S38: 85.05 | T38: 6521.2087 | V38: 85.05 | W38: 5107.2525 | Y38: 85.05 | Z38: 4551.876 | AB38: 85.05 | AC38: 5137.8705 | AE38: 85.05 | AF38: 4558.68 | AH38: 85.05 | AI38: 6786.99 | AK38: 85.05 | AL38: 5677.938 | AN38: 85.05 | AO38: 2844.9225
A39: =+$C$4&B39 -> Véhicules neufsPublicité 1 | B39: Publicité 1 | D39: 116.29035 | E39: 77332.5 | G39: 191.06129 | H39: 6391 | J39: 191.06129 | K39: 6391 | M39: 203.99317 | N39: 9553 | P39: 112.47761 | Q39: 7536 | S39: 26.977502 | T39: 2068.5 | V39: 137.06911 | W39: 8231 | Y39: 165.99402 | Z39: 8884 | AB39: 61.16537 | AC39: 3695 | AE39: 81.641791 | AF39: 4376 | AH39: 78.39599 | AI39: 6256 | AK39: 113.24146 | AL39: 7560 | AN39: 191.06129 | AO39: 6391
A40: =+$C$4&B40 -> Véhicules neufsIntérêt de gros | B40: Intérêt de gros | D40: 306.72127 | E40: 203968.11 | G40: 376.75365 | H40: 12602.41 | J40: 457.45429 | K40: 15301.846 | M40: 413.62169 | N40: 19369.904 | P40: 318.30489 | Q40: 21326.428 | S40: 234.37935 | T40: 17971.036 | V40: 277.29499 | W40: 16651.564 | Y40: 337.05324 | Z40: 18039.089 | AB40: 275.89285 | AC40: 16666.687 | AE40: 409.69588 | AF40: 21959.699 | AH40: 242.16209 | AI40: 19324.535 | AK40: 188.77187 | AL40: 12602.41 | AN40: 363.30355 | AO40: 12152.504
A41: =+$C$4&B41 -> Véhicules neufs[...] | B41: [...] | D41: 0 | E41: 0 | G41: 0 | J41: 0 | M41: 0 | P41: 0 | S41: 0 | V41: 0 | Y41: 0 | AB41: 0 | AE41: 0 | AH41: 0 | AK41: 0 | AN41: 0
...

Sheet Réel 2023
B1: ="Réel 2023 Mensuel Révisé"&" "&Parametres!$B$1 -> Réel 2023 Mensuel Révisé Volks
B2: Mois | F2: =+IF(Parametres!$B$3=F$6,"X","") | G2: =+IF(Parametres!$B$3=F$6,"O","") | H2: =+IF(Parametres!$B$3=F$6,"U","") | I2: =+IF(Parametres!$B$3=I$6,"X","") | J2: =+IF(Parametres!$B$3=I$6,"O","") | K2: =+IF(Parametres!$B$3=I$6,"U","") | L2: =+IF(Parametres!$B$3=L$6,"X","") | M2: =+IF(Parametres!$B$3=L$6,"O","") | N2: =+IF(Parametres!$B$3=L$6,"U","") | O2: =+IF(Parametres!$B$3=O$6,"X","") -> X | P2: =+IF(Parametres!$B$3=O$6,"O","") -> O | Q2: =+IF(Parametres!$B$3=O$6,"U","") -> U | R2: =+IF(Parametres!$B$3=R$6,"X","") | S2: =+IF(Parametres!$B$3=R$6,"O","") | T2: =+IF(Parametres!$B$3=R$6,"U","") | U2: =+IF(Parametres!$B$3=U$6,"X","") | V2: =+IF(Parametres!$B$3=U$6,"O","") | W2: =+IF(Parametres!$B$3=U$6,"U","") | X2: =+IF(Parametres!$B$3=X$6,"X","") | Y2: =+IF(Parametres!$B$3=X$6,"O","") | Z2: =+IF(Parametres!$B$3=X$6,"U","") | AA2: =+IF(Parametres!$B$3=AA$6,"X","") | AB2: =+IF(Parametres!$B$3=AA$6,"O","") | AC2: =+IF(Parametres!$B$3=AA$6,"U","") | AD2: =+IF(Parametres!$B$3=AD$6,"X","") | AE2: =+IF(Parametres!$B$3=AD$6,"O","") | AF2: =+IF(Parametres!$B$3=AD$6,"U","") | AG2: =+IF(Parametres!$B$3=AG$6,"X","") | AH2: =+IF(Parametres!$B$3=AG$6,"O","") | AI2: =+IF(Parametres!$B$3=AG$6,"U","") | AJ2: =+IF(Parametres!$B$3=AJ$6,"X","") | AK2: =+IF(Parametres!$B$3=AJ$6,"O","") | AL2: =+IF(Parametres!$B$3=AJ$6,"U","") | AM2: =+IF(Parametres!$B$3=AM$6,"X","") | AN2: =+IF(Parametres!$B$3=AM$6,"O","") | AO2: =+IF(Parametres!$B$3=AM$6,"U","")
B3: YTD | F3: =+IF(VLOOKUP(F$6,Parametres!$K$3:$N$14,4,0)="X","X","") -> X | G3: =+IF(VLOOKUP(F$6,Parametres!$K$3:$N$14,4,0)="X","O","") -> O | H3: =+IF(VLOOKUP(F$6,Parametres!$K$3:$N$14,4,0)="X","U","") -> U | I3: =+IF(VLOOKUP(I$6,Parametres!$K$3:$N$14,4,0)="X","X","") -> X | J3: =+IF(VLOOKUP(I$6,Parametres!$K$3:$N$14,4,0)="X","O","") -> O | K3: =+IF(VLOOKUP(I$6,Parametres!$K$3:$N$14,4,0)="X","U","") -> U | L3: =+IF(VLOOKUP(L$6,Parametres!$K$3:$N$14,4,0)="X","X","") -> X | M3: =+IF(VLOOKUP(L$6,Parametres!$K$3:$N$14,4,0)="X","O","") -> O | N3: =+IF(VLOOKUP(L$6,Parametres!$K$3:$N$14,4,0)="X","U","") -> U | O3: =+IF(VLOOKUP(O$6,Parametres!$K$3:$N$14,4,0)="X","X","") -> X | P3: =+IF(VLOOKUP(O$6,Parametres!$K$3:$N$14,4,0)="X","O","") -> O | Q3: =+IF(VLOOKUP(O$6,Parametres!$K$3:$N$14,4,0)="X","U","") -> U | R3: =+IF(VLOOKUP(R$6,Parametres!$K$3:$N$14,4,0)="X","X","") | S3: =+IF(VLOOKUP(R$6,Parametres!$K$3:$N$14,4,0)="X","O","") | T3: =+IF(VLOOKUP(R$6,Parametres!$K$3:$N$14,4,0)="X","U","") | U3: =+IF(VLOOKUP(U$6,Parametres!$K$3:$N$14,4,0)="X","X","") | V3: =+IF(VLOOKUP(U$6,Parametres!$K$3:$N$14,4,0)="X","O","") | W3: =+IF(VLOOKUP(U$6,Parametres!$K$3:$N$14,4,0)="X","U","") | X3: =+IF(VLOOKUP(X$6,Parametres!$K$3:$N$14,4,0)="X","X","") | Y3: =+IF(VLOOKUP(X$6,Parametres!$K$3:$N$14,4,0)="X","O","") | Z3: =+IF(VLOOKUP(X$6,Parametres!$K$3:$N$14,4,0)="X","U","") | AA3: =+IF(VLOOKUP(AA$6,Parametres!$K$3:$N$14,4,0)="X","X","") | AB3: =+IF(VLOOKUP(AA$6,Parametres!$K$3:$N$14,4,0)="X","O","") | AC3: =+IF(VLOOKUP(AA$6,Parametres!$K$3:$N$14,4,0)="X","U","") | AD3: =+IF(VLOOKUP(AD$6,Parametres!$K$3:$N$14,4,0)="X","X","") | AE3: =+IF(VLOOKUP(AD$6,Parametres!$K$3:$N$14,4,0)="X","O","") | AF3: =+IF(VLOOKUP(AD$6,Parametres!$K$3:$N$14,4,0)="X","U","") | AG3: =+IF(VLOOKUP(AG$6,Parametres!$K$3:$N$14,4,0)="X","X","") | AH3: =+IF(VLOOKUP(AG$6,Parametres!$K$3:$N$14,4,0)="X","O","") | AI3: =+IF(VLOOKUP(AG$6,Parametres!$K$3:$N$14,4,0)="X","U","") | AJ3: =+IF(VLOOKUP(AJ$6,Parametres!$K$3:$N$14,4,0)="X","X","") | AK3: =+IF(VLOOKUP(AJ$6,Parametres!$K$3:$N$14,4,0)="X","O","") | AL3: =+IF(VLOOKUP(AJ$6,Parametres!$K$3:$N$14,4,0)="X","U","") | AM3: =+IF(VLOOKUP(AM$6,Parametres!$K$3:$N$14,4,0)="X","X","") | AN3: =+IF(VLOOKUP(AM$6,Parametres!$K$3:$N$14,4,0)="X","O","") | AO3: =+IF(VLOOKUP(AM$6,Parametres!$K$3:$N$14,4,0)="X","U","")
B4: Réel 2023 | C4: Véhicules neufs
B6: Mois | C6: 2023 | F6: Janvier | I6: Février | L6: Mars | O6: Avril | R6: Mai | U6: Juin | X6: Juillet | AA6: Août | AD6: Septembre | AG6: Octobre | AJ6: Novembre | AM6: Décembre
C7: UNITE | D7: $P/UNITE | E7: $PROFITS | F7: UNITE | G7: $P/UNITE | H7: $PROFITS | I7: UNITE | J7: $P/UNITE | K7: $PROFITS | L7: UNITE | M7: $P/UNITE | N7: $PROFITS | O7: UNITE | P7: $P/UNITE | Q7: $PROFITS | R7: UNITE | S7: $P/UNITE | T7: $PROFITS | U7: UNITE | V7: $P/UNITE | W7: $PROFITS | X7: UNITE | Y7: $P/UNITE | Z7: $PROFITS | AA7: UNITE | AB7: $P/UNITE | AC7: $PROFITS | AD7: UNITE | AE7: $P/UNITE | AF7: $PROFITS | AG7: UNITE | AH7: $P/UNITE | AI7: $PROFITS | AJ7: UNITE | AK7: $P/UNITE | AL7: $PROFITS | AM7: UNITE | AN7: $P/UNITE | AO7: $PROFITS
A8: =+$C$4&B8 -> Véhicules neufsVentes nettes | B8: Ventes nettes | E8: 46883614 | H8: 2000310.4 | K8: 1303139.6 | N8: 2316528.3 | Q8: 1765867 | T8: 2808157.7 | W8: 2851329.3 | Z8: 2122186.9 | AC8: 2567524.5 | AF8: 2612584.6 | AI8: 8285274.9 | AL8: 10151414 | AO8: 8099296.2
A9: =+$C$4&B9 -> Véhicules neufsAutos détail | B9: Autos détail | C9: 160 | D9: 2077.4209 | E9: 332387.34 | F9: 14 | G9: 1585.0143 | H9: 22190.2 | I9: 3 | J9: 908.03333 | K9: 2724.1 | L9: 9 | M9: 2223.0811 | N9: 20007.73 | O9: 12 | P9: 2975.6025 | Q9: 35707.23 | R9: 12 | S9: 2048.03 | T9: 24576.36 | U9: 16 | V9: 2103.4488 | W9: 33655.18 | X9: 12 | Y9: 1882.1942 | Z9: 22586.33 | AA9: 21 | AB9: 2336.3824 | AC9: 49064.03 | AD9: 17 | AE9: 1804.1035 | AF9: 30669.76 | AG9: 14 | AH9: 2125.1657 | AI9: 29752.32 | AJ9: 18 | AK9: 2139.7994 | AL9: 38516.39 | AM9: 12 | AN9: 1911.4758 | AO9: 22937.71
A10: =+$C$4&B10 -> Véhicules neufsCamions détail | B10: Camions détail | C10: 402 | D10: 2485.11 | E10: 999014.21 | F10: 28 | G10: 2112.1561 | H10: 59140.37 | I10: 19 | J10: 2501.8716 | K10: 47535.56 | L10: 29 | M10: 2831.0634 | N10: 82100.84 | O10: 16 | P10: 2481.2725 | Q10: 39700.36 | R10: 34 | S10: 2504.1768 | T10: 85142.01 | U10: 39 | V10: 2445.2556 | W10: 95364.97 | X10: 24 | Y10: 2577.0196 | Z10: 61848.47 | AA10: 22 | AB10: 2712.29 | AC10: 59670.38 | AD10: 36 | AE10: 2493.9233 | AF10: 89781.24 | AG10: 45 | AH10: 2647.1667 | AI10: 119122.5 | AJ10: 71 | AK10: 2320.119 | AL10: 164728.45 | AM10: 39 | AN10: 2432.7964 | AO10: 94879.06
A11: =+$C$4&B11 -> Véhicules neufsSprinter | B11: Sprinter | C11: 0 | D11: 0 | E11: 0 | F11: 0 | G11: 0 | H11: 0 | I11: 0 | J11: 0 | K11: 0 | L11: 0 | M11: 0 | N11: 0 | O11: 0 | P11: 0 | Q11: 0 | R11: 0 | S11: 0 | T11: 0 | U11: 0 | V11: 0 | W11: 0 | X11: 0 | Y11: 0 | Z11: 0 | AA11: 0 | AB11: 0 | AC11: 0 | AD11: 0 | AE11: 0 | AF11: 0 | AG11: 0 | AH11: 0 | AI11: 0 | AJ11: 0 | AK11: 0 | AL11: 0 | AM11: 0 | AN11: 0 | AO11: 0
A12: =+$C$4&B12 -> Véhicules neufsMoto détail | B12: Moto détail | C12: 0 | D12: 0 | E12: 0 | F12: 0 | G12: 0 | H12: 0 | I12: 0 | J12: 0 | K12: 0 | L12: 0 | M12: 0 | N12: 0 | O12: 0 | P12: 0 | Q12: 0 | R12: 0 | S12: 0 | T12: 0 | U12: 0 | V12: 0 | W12: 0 | X12: 0 | Y12: 0 | Z12: 0 | AA12: 0 | AB12: 0 | AC12: 0 | AD12: 0 | AE12: 0 | AF12: 0 | AG12: 0 | AH12: 0 | AI12: 0 | AJ12: 0 | AK12: 0 | AL12: 0 | AM12: 0 | AN12: 0 | AO12: 0
A13: =+$C$4&B13 -> Véhicules neufs[...] | B13: [...] | C13: 0 | D13: 0 | E13: 0 | G13: 0 | J13: 0 | M13: 0 | P13: 0 | S13: 0 | V13: 0 | Y13: 0 | AB13: 0 | AE13: 0 | AH13: 0 | AK13: 0 | AN13: 0
A14: =+$C$4&B14 -> Véhicules neufs[...] | B14: [...] | C14: 0 | D14: 0 | E14: 0 | G14: 0 | J14: 0 | M14: 0 | P14: 0 | S14: 0 | V14: 0 | Y14: 0 | AB14: 0 | AE14: 0 | AH14: 0 | AK14: 0 | AN14: 0
A15: =+$C$4&B15 -> Véhicules neufs[...] | B15: [...] | C15: 0 | D15: 0 | E15: 0 | G15: 0 | J15: 0 | M15: 0 | P15: 0 | S15: 0 | V15: 0 | Y15: 0 | AB15: 0 | AE15: 0 | AH15: 0 | AK15: 0 | AN15: 0
A16: =+$C$4&B16 -> Véhicules neufsTotal Neufs | B16: Total Neufs | C16: 562 | D16: 2369.0419 | E16: 1331401.5 | F16: 42 | G16: 1936.4421 | H16: 81330.57 | I16: 22 | J16: 2284.53 | K16: 50259.66 | L16: 38 | M16: 2687.0676 | N16: 102108.57 | O16: 28 | P16: 2693.1282 | Q16: 75407.59 | R16: 46 | S16: 2385.182 | T16: 109718.37 | U16: 55 | V16: 2345.8209 | W16: 129020.15 | X16: 36 | Y16: 2345.4111 | Z16: 84434.8 | AA16: 43 | AB16: 2528.7072 | AC16: 108734.41 | AD16: 53 | AE16: 2272.6604 | AF16: 120451 | AG16: 59 | AH16: 2523.302 | AI16: 148874.82 | AJ16: 89 | AK16: 2283.6499 | AL16: 203244.84 | AM16: 51 | AN16: 2310.1327 | AO16: 117816.77
A17: =+$C$4&B17 -> Véhicules neufs
A18: =+$C$4&B18 -> Véhicules neufsEx-Démos et courtoisies | B18: Ex-Démos et courtoisies | C18: 42 | D18: 2481.1169 | E18: 104206.91 | F18: 3 | G18: 6274.7467 | H18: 18824.24 | I18: 2 | J18: 5044.27 | K18: 10088.54 | L18: 8 | M18: 3142.5462 | N18: 25140.37 | O18: 6 | P18: 1717.8083 | Q18: 10306.85 | R18: 7 | S18: 2567.5443 | T18: 17972.81 | U18: 2 | V18: 1486.73 | W18: 2973.46 | X18: 3 | Y18: 851.18 | Z18: 2553.54 | AA18: 8 | AB18: 1186.9175 | AC18: 9495.34 | AD18: 1 | AE18: 975.83 | AF18: 975.83 | AG18: 0 | AH18: 0 | AI18: 3550 | AJ18: 1 | AK18: 1154.94 | AL18: 1154.94 | AM18: 1 | AN18: 1170.99 | AO18: 1170.99
A19: =+$C$4&B19 -> Véhicules neufs
A20: =+$C$4&B20 -> Véhicules neufsFlottes | B20: Flottes | C20: 26 | D20: 2968.9 | E20: 77191.4 | F20: 1 | G20: 2144.83 | H20: 2144.83 | I20: 1 | J20: 2919.37 | K20: 2919.37 | L20: 0 | M20: 0 | N20: 0 | O20: 3 | P20: 3228.9067 | Q20: 9686.72 | R20: 3 | S20: 1222.9133 | T20: 3668.74 | U20: 2 | V20: 2962.945 | W20: 5925.89 | X20: 1 | Y20: 4279.05 | Z20: 4279.05 | AA20: 4 | AB20: 3473.7725 | AC20: 13895.09 | AD20: 1 | AE20: 3198 | AF20: 3198 | AG20: 8 | AH20: 3193.38 | AI20: 25547.04 | AJ20: 2 | AK20: 3324.41 | AL20: 6648.82 | AM20: 0 | AN20: 0 | AO20: -722.15
A21: =+$C$4&B21 -> Véhicules neufs
A22: =+$C$4&B22 -> Véhicules neufsRachat bail | B22: Rachat bail | E22: 99141.1 | H22: 5000.4 | K22: 6807.17 | N22: 11489.37 | Q22: 7229.27 | T22: 12671.61 | W22: 12900.75 | Z22: 9971 | AC22: 7757.94 | AF22: 7932.08 | AI22: 8229.71 | AL22: 3732.16 | AO22: 5419.64
A23: =+$C$4&B23 -> Véhicules neufs
A24: =+$C$4&B24 -> Véhicules neufsRev. Finances | B24: Rev. Finances | D24: 138.28978 | E24: 83527.03 | G24: 214.11533 | H24: 9635.19 | J24: 516.52875 | K24: 12396.69 | M24: 256.81543 | N24: 11813.51 | P24: 71.606765 | Q24: 2434.63 | S24: 136.53245 | T24: 7236.22 | V24: 89.401579 | W24: 5095.89 | Y24: 247.8859 | Z24: 9667.55 | AB24: 175.29412 | AC24: 8940 | AE24: 92.308148 | AF24: 4984.64 | AH24: 59.010339 | AI24: 3481.61 | AK24: 48.026889 | AL24: 4322.42 | AN24: 67.666923 | AO24: 3518.68
A25: =+$C$4&B25 -> Véhicules neufsRev. Protections | B25: Rev. Protections | D25: 972.14964 | E25: 587178.38 | G25: 653.30889 | H25: 29398.9 | J25: 943.50875 | K25: 22644.21 | M25: 1021.8824 | N25: 47006.59 | P25: 913.24941 | Q25: 31050.48 | S25: 1002.9296 | T25: 53155.27 | V25: 868.40772 | W25: 49499.24 | Y25: 1110.4236 | Z25: 43306.52 | AB25: 1030.0339 | AC25: 52531.73 | AE25: 1111.505 | AF25: 60021.27 | AH25: 942.08305 | AI25: 55582.9 | AK25: 993.18356 | AL25: 89386.52 | AN25: 1030.6683 | AO25: 53594.75
A26: =+$C$4&B26 -> Véhicules neufsRev. Autres | B26: Rev. Autres | D26: 12.821325 | E26: 7744.08 | G26: 0 | H26: 0 | J26: 0 | K26: 0 | M26: 13.392826 | N26: 616.07 | P26: 0 | Q26: 0 | S26: 32.927736 | T26: 1745.17 | V26: 0 | W26: 0 | Y26: 0 | Z26: 0 | AB26: 12.943529 | AC26: 660.12 | AE26: 9.5077778 | AF26: 513.42 | AH26: 6.749322 | AI26: 398.21 | AK26: 15.009333 | AL26: 1350.84 | AN26: 47.3125 | AO26: 2460.25
A27: =+$C$4&B27 -> Véhicules neufsTotal F&I | B27: Total F&I | C27: 604 | D27: 1123.2607 | E27: 678449.49 | F27: 45 | G27: 867.42422 | H27: 39034.09 | I27: 24 | J27: 1460.0375 | K27: 35040.9 | L27: 46 | M27: 1292.0907 | N27: 59436.17 | O27: 34 | P27: 984.85618 | Q27: 33485.11 | R27: 53 | S27: 1172.3898 | T27: 62136.66 | U27: 57 | V27: 957.8093 | W27: 54595.13 | X27: 39 | Y27: 1358.3095 | Z27: 52974.07 | AA27: 51 | AB27: 1218.2716 | AC27: 62131.85 | AD27: 54 | AE27: 1213.3209 | AF27: 65519.33 | AG27: 59 | AH27: 1007.8427 | AI27: 59462.72 | AJ27: 90 | AK27: 1056.2198 | AL27: 95059.78 | AM27: 52 | AN27: 1145.6477 | AO27: 59573.68
A28: =+$C$4&B28 -> Véhicules neufs
A29: =+$C$4&B29 -> Véhicules neufs
A30: =+$C$4&B30 -> Véhicules neufsTotal Dépt. Neufs | B30: Total Dépt. Neufs | C30: 630 | D30: 3635.5404 | E30: 2290390.4 | F30: 46 | G30: 3181.1767 | H30: 146334.13 | I30: 25 | J30: 4204.6256 | K30: 105115.64 | L30: 46 | M30: 4308.1409 | N30: 198174.48 | O30: 37 | P30: 3678.7984 | Q30: 136115.54 | R30: 56 | S30: 3681.5748 | T30: 206168.19 | U30: 59 | V30: 3481.6166 | W30: 205415.38 | X30: 40 | Y30: 3855.3115 | Z30: 154212.46 | AA30: 55 | AB30: 3672.9933 | AC30: 202014.63 | AD30: 55 | AE30: 3601.3862 | AF30: 198076.24 | AG30: 67 | AH30: 3666.6312 | AI30: 245664.29 | AJ30: 92 | AK30: 3367.832 | AL30: 309840.54 | AM30: 52 | AN30: 3524.2102 | AO30: 183258.93
A31: =+$C$4&B31 -> Véhicules neufs
A32: =+$C$4&B32 -> Véhicules neufs
A33: =+$C$4&B33 -> Véhicules neufsDEPENSES | B33: DEPENSES
A34: =+$C$4&B34 -> Véhicules neufsComm. vendeurs | B34: Comm. vendeurs | C34: 0.29849572 | D34: 709.47513 | E34: 428522.98 | F34: 0.20080094 | G34: 446.91511 | H34: 20111.18 | I34: 0.37480389 | J34: 942.4475 | K34: 22618.74 | L34: 0.34224819 | M34: 946.75478 | N34: 43550.72 | O34: 0.43277959 | P34: 1091.0429 | Q34: 37095.46 | R34: 0.32730601 | S34: 788.56774 | T34: 41794.09 | U34: 0.33310605 | V34: 771.36614 | W34: 43967.87 | X34: 0.37701685 | Y34: 840.92487 | Z34: 32796.07 | AA34: 0.35356676 | AB34: 819.64922 | AC34: 41802.11 | AD34: 0.19647832 | AE34: 441.81 | AF34: 23857.74 | AG34: 0.27493521 | AH34: 710.28729 | AI34: 41906.95 | AJ34: 0.22021937 | AK34: 500.14211 | AL34: 45012.79 | AM34: 0.2858215 | AN34: 654.02423 | AO34: 34009.26
A35: =+$C$4&B35 -> Véhicules neufsComm. F&I | B35: Comm. F&I | C35: 0.30598639 | D35: 343.7025 | E35: 207596.31 | F35: 0.42056546 | G35: 364.80867 | H35: 16416.39 | I35: 0.28643557 | J35: 418.20667 | K35: 10036.96 | L35: 0.29836781 | M35: 385.51826 | N35: 17733.84 | O35: 0.2997816 | P35: 295.24176 | Q35: 10038.22 | R35: 0.29997187 | S35: 351.68396 | T35: 18639.25 | U35: 0.30010864 | V35: 287.44684 | W35: 16384.47 | X35: 0.30073846 | Y35: 408.4959 | Z35: 15931.34 | AA35: 0.2998974 | AB35: 365.35647 | AC35: 18633.18 | AD35: 0.30030542 | AE35: 364.36685 | AF35: 19675.81 | AG35: 0.29873305 | AH35: 301.07593 | AI35: 17763.48 | AJ35: 0.29960999 | AK35: 316.454 | AL35: 28480.86 | AM35: 0.29983896 | AN35: 343.50981 | AO35: 17862.51
A36: =+$C$4&B36 -> Véhicules neufsFrais de livraison | B36: Frais de livraison | D36: 122.55435 | E36: 74022.83 | G36: 58.516222 | H36: 2633.23 | J36: 245.49917 | K36: 5891.98 | M36: 64.906087 | N36: 2985.68 | P36: 99.448824 | Q36: 3381.26 | S36: 112.82151 | T36: 5979.54 | V36: 98.259649 | W36: 5600.8 | Y36: 168.41974 | Z36: 6568.37 | AB36: 121.67235 | AC36: 6205.29 | AE36: 85.562222 | AF36: 4620.36 | AH36: 131.92102 | AI36: 7783.34 | AK36: 138.78767 | AL36: 12490.89 | AN36: 190.04019 | AO36: 9882.09
A37: =+$C$4&B37 -> Véhicules neufsService gratuit 1 | B37: Service gratuit 1 | D37: 13.843328 | E37: 8361.37 | G37: 0 | H37: 0 | J37: 0 | K37: 0 | M37: 4.5619565 | N37: 209.85 | P37: 2.3529412 | Q37: 80 | S37: 0 | T37: 0 | V37: 0 | W37: 0 | Y37: 1.025641 | Z37: 40 | AB37: 1.8039216 | AC37: 92 | AE37: 3.9803704 | AF37: 214.94 | AH37: 9.4247458 | AI37: 556.06 | AK37: 63.110222 | AL37: 5679.92 | AN37: 28.626923 | AO37: 1488.6
A38: =+$C$4&B38 -> Véhicules neufsEntretien stock | B38: Entretien stock | D38: 79.81144 | E38: 48206.11 | G38: 59.264222 | H38: 2666.89 | J38: 125.22542 | K38: 3005.41 | M38: 48.714348 | N38: 2240.86 | P38: 88.82 | Q38: 3019.88 | S38: 66.649057 | T38: 3532.4 | V38: 70.210526 | W38: 4002 | Y38: 118.07769 | Z38: 4605.03 | AB38: 78.708235 | AC38: 4014.12 | AE38: 80.216481 | AF38: 4331.69 | AH38: 92.110169 | AI38: 5434.5 | AK38: 83.834222 | AL38: 7545.08 | AN38: 73.235577 | AO38: 3808.25
A39: =+$C$4&B39 -> Véhicules neufsPublicité 1 | B39: Publicité 1 | D39: 100.76803 | E39: 60863.89 | G39: 7.4604444 | H39: 335.72 | J39: 300.07 | K39: 7201.68 | M39: 87.100652 | N39: 4006.63 | P39: 159.71529 | Q39: 5430.32 | S39: 56.458679 | T39: 2992.31 | V39: 122.48649 | W39: 6981.73 | Y39: 154.58692 | Z39: 6028.89 | AB39: 40.121961 | AC39: 2046.22 | AE39: 102.55352 | AF39: 5537.89 | AH39: 155.86983 | AI39: 9196.32 | AK39: 38.481889 | AL39: 3463.37 | AN39: 146.97712 | AO39: 7642.81
A40: =+$C$4&B40 -> Véhicules neufsIntérêt de gros | B40: Intérêt de gros | D40: 121.38026 | E40: 73313.68 | G40: 153.29867 | H40: 6898.44 | J40: 187.08333 | K40: 4490 | M40: 86.143043 | N40: 3962.58 | P40: 54.914412 | Q40: 1867.09 | S40: 110.78396 | T40: 5871.55 | V40: 83.072632 | W40: 4735.14 | Y40: 90.482564 | Z40: 3528.82 | AB40: 0 | AC40: 0 | AE40: 95.057593 | AF40: 5133.11 | AH40: 0 | AI40: 0 | AK40: 217.76156 | AL40: 19598.54 | AN40: 331.31558 | AO40: 17228.41
A41: =+$C$4&B41 -> Véhicules neufs[...] | B41: [...] | D41: 0 | E41: 0 | G41: 0 | J41: 0 | M41: 0 | P41: 0 | S41: 0 | V41: 0 | Y41: 0 | AB41: 0 | AE41: 0 | AH41: 0 | AK41: 0 | AN41: 0
...

Sheet Capex
A1: PARK AVENUE VOLKSWAGEN | B1: PARK AVENUE VOLKSWAGEN
A2: Forecast Immobilisation 2022 | B2: Forecast Immobilisation 2024 | H2: 1 | I2: 2 | J2: 3 | K2: 4 | L2: 5 | M2: 6 | N2: 7 | O2: 8 | P2: 9 | Q2: 10 | R2: 11 | S2: 12
H3: =+IF(VLOOKUP(H2,Parametres!$L$3:$N$14,3,0)="X","REEL","FORECAST") -> REEL | I3: =+IF(VLOOKUP(I2,Parametres!$L$3:$N$14,3,0)="X","REEL","FORECAST") -> REEL | J3: =+IF(VLOOKUP(J2,Parametres!$L$3:$N$14,3,0)="X","REEL","FORECAST") -> REEL | K3: =+IF(VLOOKUP(K2,Parametres!$L$3:$N$14,3,0)="X","REEL","FORECAST") -> REEL | L3: =+IF(VLOOKUP(L2,Parametres!$L$3:$N$14,3,0)="X","REEL","FORECAST") -> FORECAST | M3: =+IF(VLOOKUP(M2,Parametres!$L$3:$N$14,3,0)="X","REEL","FORECAST") -> FORECAST | N3: =+IF(VLOOKUP(N2,Parametres!$L$3:$N$14,3,0)="X","REEL","FORECAST") -> FORECAST | O3: =+IF(VLOOKUP(O2,Parametres!$L$3:$N$14,3,0)="X","REEL","FORECAST") -> FORECAST | ... S3: =+IF(VLOOKUP(S2,Parametres!$L$3:$N$14,3,0)="X","REEL","FORECAST") -> FORECAST
A4: Concession | B4: Budgété / Non budgété | C4: Projet | D4: Catégorie Immo | E4: Total forecast | F4: Budget Annuel | G4: Écart vs budget | H4: January | I4: February | J4: March | K4: April | L4: May | M4: June | N4: July | O4: August | P4: September | Q4: October | R4: November | S4: December | T4: Raison / Description
C5: Total | E5: =+SUM(E6:E20) -> 96462.09 | F5: =+SUM(F6:F20) -> 83000 | G5: =+SUM(G6:G20) -> 13462.09 | H5: =+SUM(H6:H20) -> 4849.87 | I5: =+SUM(I6:I20) -> 11606.23 | J5: =+SUM(J6:J20) -> 10913 | K5: =+SUM(K6:K20) -> 12548.99 | L5: =+SUM(L6:L20) -> 16097 | ... S5: =+SUM(S6:S20) -> 5000 | X5: Terrain
A6: =+Parametres!$B$1 -> Volks | B6: oui | C6: Outillage ID4 | E6: =+SUM(H6:S6) -> 51000.09 | F6: 51000 | G6: =+E6-F6 -> 0.09 | I6: 9903.09 | L6: 16097 | N6: 25000 | X6: Bâtisse
A7: =+Parametres!$B$1 -> Volks | B7: non | C7: Outils Spécialisés Volks | E7: =+SUM(H7:S7) -> 22000.01 | F7: 22000 | G7: =+E7-F7 -> 0.01 | H7: 4849.87 | I7: 1703.14 | M7: 5447 | P7: 5000 | S7: 5000 | X7: Améliorations Locatives
A8: =+Parametres!$B$1 -> Volks | B8: non | C8: Porte de garage CPO | E8: =+SUM(H8:S8) -> 10000 | F8: 10000 | G8: =+E8-F8 -> 0 | K8: 10000 | X8: Mobilier
A9: =+Parametres!$B$1 -> Volks | B9: non | C9: Lift (ex-Volvo) | E9: =+SUM(H9:S9) -> 10415 | G9: =+E9-F9 -> 10415 | J9: 10415 | X9: Équipements Informatique
A10: =+Parametres!$B$1 -> Volks | B10: non | C10: Equipement informatiques | E10: =+SUM(H10:S10) -> 3046.99 | G10: =+E10-F10 -> 3046.99 | J10: 498 | K10: 2548.99 | X10: Équipements Téléphonique
A11: =+Parametres!$B$1 -> Volks | B11: non | E11: =+SUM(H11:S11) -> 0 | G11: =+E11-F11 -> 0 | X11: Enseigne
A12: =+Parametres!$B$1 -> Volks | B12: non | E12: =+SUM(H12:S12) -> 0 | G12: =+E12-F12 -> 0
A13: =+Parametres!$B$1 -> Volks | B13: non | E13: =+SUM(H13:S13) -> 0 | G13: =+E13-F13 -> 0
A14: =+Parametres!$B$1 -> Volks | B14: non | E14: =+SUM(H14:S14) -> 0 | G14: =+E14-F14 -> 0
A15: =+Parametres!$B$1 -> Volks | B15: non | E15: =+SUM(H15:S15) -> 0 | G15: =+E15-F15 -> 0
A16: =+Parametres!$B$1 -> Volks | B16: non | E16: =+SUM(H16:S16) -> 0 | G16: =+E16-F16 -> 0
A17: =+Parametres!$B$1 -> Volks | B17: non | E17: =+SUM(H17:S17) -> 0 | G17: =+E17-F17 -> 0 | X17: non
A18: =+Parametres!$B$1 -> Volks | B18: non | E18: =+SUM(H18:S18) -> 0 | G18: =+E18-F18 -> 0
A19: =+Parametres!$B$1 -> Volks | B19: non | E19: =+SUM(H19:S19) -> 0 | G19: =+E19-F19 -> 0
A20: =+Parametres!$B$1 -> Volks | B20: non | E20: =+SUM(H20:S20) -> 0 | G20: =+E20-F20 -> 0

Sheet Inventaire_Used
A1: #Contrôle | B1: Année | C1: Marque | D1: Modèle | E1: 1416 | F1: 2103 | G1: NIV | H1: Jours en stock | M1: 45169 | N1: $ Inventaire | O1: $ Financé
A2: 5291P | B2: 2020 | C2: VOLKSWAGEN | D2: E-GOLF | E2: 32007.51 | F2: -22494.36 | G2: WVWPR7AU2LW903993 | H2: 423 | M2: CTRL | N2: =+SUM(E:E) -> 2779322.1 | O2: =+SUM(F:F) -> -640715.53
A3: 230251A | B3: 2020 | C3: VOLKSWAGEN | D3: E-GOLF | E3: 24454.46 | G3: WVWPR7AU0LW907198 | H3: 306 | M3: Unités | N3: =COUNT(E:E) -> 111 | O3: =-O2/N2 -> 0.23052943
A4: 230425A | B4: 2021 | C4: VOLKSWAGEN | D4: ATLAS CROSS SPO | E4: 37735.15 | G4: 1V2LC2CAXMC211536 | H4: 188
A5: 230365A | B5: 2018 | C5: VOLKSWAGEN | D5: BEETLE CONVERTI | E5: 29929.55 | G5: 3VW5DAAT2JM518129 | H5: 187 | M5: Moyenne | N5: =+N2/N3 -> 25038.938
A6: 5485P | B6: 2018 | C6: VOLKSWAGEN | D6: ATLAS | E6: 31306.12 | G6: 1V2NR2CA5JC509107 | H6: 131
A7: 230554A | B7: 2014 | C7: SUBARU | D7: WRX | E7: 17680.42 | G7: JF1GR8H60EL238082 | H7: 121 | M7: Plus de 90 Jours | N7: =SUM(E2:E13) -> 337989.36 | O7: =+N7/N2 -> 0.12160856
A8: 230567A | B8: 2021 | C8: VOLKSWAGEN | D8: TIGUAN | E8: 28635.15 | F8: -31332.8 | G8: 3VV2B7AX6MM155874 | H8: 104 | N8: =COUNT(H2:H13) -> 12 | O8: =+N8/(N3) -> 0.10810811
A9: 240013A | B9: 2022 | C9: VOLKSWAGEN | D9: TIGUAN | E9: 38815.25 | G9: 3VV4B7AX3NM051496 | H9: 94
A10: 230392A | B10: 2020 | C10: VOLKSWAGEN | D10: TIGUAN | E10: 31315.25 | F10: -24944.54 | G10: 3VV4B7AX2LM114164 | H10: 94
A11: 230599A | B11: 2019 | C11: VOLKSWAGEN | D11: JETTA | E11: 21280.25 | F11: -10962 | G11: 3VWE57BU6KM254342 | H11: 94
A12: 230606A | B12: 2018 | C12: CHEVROLET | D12: VOLT | E12: 17550 | G12: 1G1RA6S50JU104989 | H12: 93
A13: 240015A | B13: 2019 | C13: VOLKSWAGEN | D13: GOLF GTI | E13: 27280.25 | F13: -17480.23 | G13: 3VW6T7AU5KM024755 | H13: 90
A14: 5511P | B14: 2022 | C14: VOLKSWAGEN | D14: ATLAS CROSS SPO | E14: 44105.05 | F14: -38250 | G14: 1V2BE2CA6NC212111 | H14: 88
A15: 240019A | B15: 2020 | C15: VOLKSWAGEN | D15: ATLAS CROSS SPO | E15: 36415.13 | F15: -26892 | G15: 1V2TE2CA8LC219420 | H15: 82
A16: 230596A | B16: 2020 | C16: VOLKSWAGEN | D16: TIGUAN | E16: 27935.05 | G16: 3VV2B7AX4LM005048 | H16: 76
A17: 5509PA | B17: 2017 | C17: AUDI | D17: A3 E-TRON | E17: 20050 | G17: WAUSPBFF5HA099610 | H17: 74
A18: 230626A | B18: 2018 | C18: VOLKSWAGEN | D18: TIGUAN | E18: 20497.05 | G18: 3VV4B7AX2JM130250 | H18: 72
A19: 5518P | B19: 2020 | C19: VOLKSWAGEN | D19: TIGUAN | E19: 28075.78 | F19: -23850 | G19: 3VV4B7AX0LM106225 | H19: 69
A20: 230593A | B20: 2019 | C20: VOLKSWAGEN | D20: TIGUAN | E20: 26815.25 | G20: 3VV4B7AX3KM183332 | H20: 69
A21: 5519P | B21: 2021 | C21: VOLKSWAGEN | D21: TIGUAN | E21: 28447.25 | F21: -24418.8 | G21: 3VV2B7AX4MM068281 | H21: 68
A22: 240044A | B22: 2019 | C22: VOLKSWAGEN | D22: ATLAS | E22: 29352 | G22: 1V2MR2CA6KC587280 | H22: 66
A23: 240041A | B23: 2018 | C23: VOLKSWAGEN | D23: GOLF | E23: 18787.5 | G23: 3VWG17AU2JM291103 | H23: 66
A24: 240056A | B24: 2020 | C24: VOLKSWAGEN | D24: JETTA | E24: 18043.82 | G24: 3VWN57BU2LM040420 | H24: 65
A25: 240036A | B25: 2021 | C25: VOLKSWAGEN | D25: ATLAS | E25: 40209.65 | G25: 1V2FR2CA8MC595926 | H25: 62
A26: 240079A | B26: 2020 | C26: VOLKSWAGEN | D26: TIGUAN | E26: 30620.3 | G26: 3VV4B7AX5LM110786 | H26: 62
A27: 230564B | B27: 2020 | C27: JEEP | D27: COMPASS | E27: 28211.38 | G27: 3C4NJDDBXLT155667 | H27: 62
A28: 230649A | B28: 2020 | C28: NISSAN | D28: ROGUE | E28: 23550 | G28: 5N1AT2MT7LC775762 | H28: 61
A29: 240086A | B29: 2022 | C29: VOLKSWAGEN | D29: TIGUAN | E29: 36524.6 | G29: 3VV4B7AX9NM096457 | H29: 60
A30: 5522P | B30: 2020 | C30: VOLKSWAGEN | D30: TIGUAN | E30: 24346.21 | F30: -16047.88 | G30: 3VV2B7AX7LM099068 | H30: 60
A31: 5521P | B31: 2019 | C31: VOLKSWAGEN | D31: GOLF | E31: 18530.25 | G31: 3VWG57AU3KM018998 | H31: 60
A32: 5523P | B32: 2021 | C32: VOLKSWAGEN | D32: TIGUAN | E32: 29670.31 | F32: -25505.1 | G32: 3VV2B7AX2MM078047 | H32: 59
A33: 240089A | B33: 2020 | C33: VOLKSWAGEN | D33: JETTA | E33: 22965.2 | G33: 3VWW57BU9LM006236 | H33: 55
A34: 5525P | B34: 2021 | C34: VOLKSWAGEN | D34: TIGUAN | E34: 31666.8 | F34: -33046.59 | G34: 3VV4B7AX1MM155614 | H34: 54
A35: 240059A | B35: 2019 | C35: VOLKSWAGEN | D35: TIGUAN | E35: 24846.26 | G35: 3VV2B7AX7KM049091 | H35: 53
A36: 240099A | B36: 2020 | C36: VOLKSWAGEN | D36: JETTA | E36: 19323.74 | G36: 3VWN57BU9LM077965 | H36: 51
A37: 240098A | B37: 2019 | C37: VOLKSWAGEN | D37: GOLF | E37: 18294.75 | G37: 3VWG57AU0KM034477 | H37: 48
A38: 240038B | B38: 2018 | C38: VOLKSWAGEN | D38: GOLF | E38: 16745.3 | G38: 3VWG17AU9JM275867 | H38: 48
A39: 240091A | B39: 2022 | C39: VOLKSWAGEN | D39: ATLAS | E39: 49927.29 | G39: 1V2FR2CA7NC504226 | H39: 47
A40: 5526P | B40: 2020 | C40: VOLKSWAGEN | D40: TIGUAN | E40: 24483.1 | F40: -18876 | G40: 3VV2B7AX9LM002520 | H40: 47
...

Sheet Inventaire_Neuf
A1: #Contrôle | B1: Année | C1: Marque | D1: Modèle | E1: 1402 | F1: 2101 | G1: NIV | H1: Jours en stock | K1: 45230 | L1: $ Inventaire | M1: $ Financé
A2: 230536 | B2: 2023 | C2: VOLKSWAGEN | D2: JETTA SEDAN | E2: 33666.97 | F2: -31504.85 | G2: 3VW2T7BU7PM053775 | H2: 142 | K2: CTRL | L2: =+SUM(E2:E9963) -> 3059537.1 | M2: =+SUM(F2:F9963) -> -2668372
A3: 240001 | B3: 2024 | C3: VOLKSWAGEN | D3: ATLAS | E3: 56706.1 | F3: -57628.2 | G3: 1V2BR2CA6RC502911 | H3: 142 | K3: Unités | L3: =COUNT(E:E) -> 71 | M3: =-M2/L2 -> 0.8721489
A4: 230574 | B4: 2023 | C4: VOLKSWAGEN | D4: JETTA SEDAN | E4: 31163.98 | F4: -32628.75 | G4: 3VWGM7BU3PM060824 | H4: 116
A5: 230581 | B5: 2023 | C5: VOLKSWAGEN | D5: TAOS | E5: 38081.07 | F5: -39936.75 | G5: 3VV4X7B27PM374246 | H5: 111
A6: 240003 | B6: 2024 | C6: VOLKSWAGEN | D6: ATLAS | E6: 50511.98 | F6: -51427.95 | G6: 1V2LR2CA2RC511786 | H6: 108 | K6: Plus de 90 jrs | L6: =SUM(E2:E12) -> 532950.79 | M6: =SUM(F2:F12) -> -378366.05
A7: 240009 | B7: 2024 | C7: VOLKSWAGEN | D7: ATLAS CROSS SPT | E7: 54659.17 | F7: -57051.75 | G7: 1V2BE2CA7RC206484 | H7: 104 | L7: 2
A8: 240011 | B8: 2024 | C8: VOLKSWAGEN | D8: ATLAS CROSS SPT | E8: 48328.17 | F8: -51136.05 | G8: 1V2LE2CA3RC208611 | H8: 97
A9: 240016 | B9: 2024 | C9: VOLKSWAGEN | D9: ATLAS CROSS SPT | E9: 57229.1 | G9: 1V2BE2CA1RC206996 | H9: 93 | K9: Plus de 180 jrs | L9: 0 | M9: 0
A10: 240022 | B10: 2024 | C10: VOLKSWAGEN | D10: ATLAS | E10: 58141.01 | G10: 1V2BR2CA4RC506228 | H10: 90 | L10: 0
A11: 240021 | B11: 2024 | C11: VOLKSWAGEN | D11: ATLAS | E11: 48171.23 | G11: 1V2LR2CA8RC516197 | H11: 90
A12: 240020 | B12: 2024 | C12: VOLKSWAGEN | D12: ATLAS CROSS SPT | E12: 56292.01 | F12: -57051.75 | G12: 1V2BE2CA5RC210341 | H12: 90
A13: 240027 | B13: 2024 | C13: VOLKSWAGEN | D13: ATLAS | E13: 56073.92 | F13: -58869.3 | G13: 1V2BR2CA1RC517137 | H13: 86
A14: 240026 | B14: 2024 | C14: VOLKSWAGEN | D14: GOLF GTI | E14: 37397 | F14: -39440.1 | G14: WVWGA7CD7RW121198 | H14: 86
A15: 240030 | B15: 2024 | C15: VOLKSWAGEN | D15: ATLAS CROSS SPT | E15: 56197.99 | F15: -58834.65 | G15: 1V2FE2CAXRC211373 | H15: 82
A16: 230639 | B16: 2023 | C16: VOLKSWAGEN | D16: TAOS | E16: 32135.51 | F16: -34034.7 | G16: 3VVEX7B23PM379190 | H16: 80
A17: 240042 | B17: 2024 | C17: VOLKSWAGEN | D17: ATLAS CROSS SPT | E17: 55950.97 | F17: -58834.65 | G17: 1V2FE2CA4RC210672 | H17: 74
A18: 240047 | B18: 2024 | C18: VOLKSWAGEN | D18: ATLAS CROSS SPT | E18: 55950.97 | F18: -58834.65 | G18: 1V2FE2CA0RC211429 | H18: 74
A19: 240045 | B19: 2024 | C19: VOLKSWAGEN | D19: JETTA SEDAN | E19: 26927 | F19: -28367.85 | G19: 3VWWM7BU5RM010702 | H19: 74
A20: 230643 | B20: 2023 | C20: VOLKSWAGEN | D20: TAOS | E20: 37610 | F20: -39461.1 | G20: 3VV4X7B2XPM382549 | H20: 73
A21: 240052 | B21: 2024 | C21: VOLKSWAGEN | D21: ATLAS CROSS SPT | E21: 55950.97 | F21: -58834.65 | G21: 1V2FE2CAXRC211504 | H21: 73
A22: 240050 | B22: 2024 | C22: VOLKSWAGEN | D22: JETTA SEDAN | E22: 29531 | F22: -31102.05 | G22: 3VWSM7BU4RM014707 | H22: 73
A23: 240070 | B23: 2024 | C23: VOLKSWAGEN | D23: ATLAS CROSS SPT | E23: 54250 | F23: -57051.75 | G23: 1V2BE2CA9RC212335 | H23: 68
... A27: 240083 | B27: 2024 | C27: VOLKSWAGEN | D27: JETTA SEDAN | E27: 32017.87 | F27: -33204.15 | G27: 3VWGM7BU7RM015582 | H27: 62
A28: 240125 | B28: 2024 | C28: VOLKSWAGEN | D28: JETTA GLI | E28: 31816.52 | G28: 3VW8T7BU7RM014696 | H28: 52
A29: 240129 | B29: 2024 | C29: VOLKSWAGEN | D29: JETTA GLI | E29: 31513 | G29: 3VW8T7BU8RM016912 | H29: 51
A30: 240137 | B30: 2024 | C30: VOLKSWAGEN | D30: ATLAS | E30: 48894 | F30: -51427.95 | G30: 1V2LR2CA9RC529461 | H30: 48
A31: 240141 | B31: 2024 | C31: VOLKSWAGEN | D31: ATLAS CROSS SPT | E31: 55948 | F31: -58834.65 | G31: 1V2FE2CA6RC216828 | H31: 48
A32: 240139 | B32: 2024 | C32: VOLKSWAGEN | D32: ATLAS CROSS SPT | E32: 54236.5 | G32: 1V2BE2CAXRC212764 | H32: 48
A33: 240138 | B33: 2024 | C33: VOLKSWAGEN | D33: TAOS | E33: 32864 | F33: -34706.7 | G33: 3VVEX7B22RM012347 | H33: 48
A34: 240147 | B34: 2024 | C34: VOLKSWAGEN | D34: ATLAS | E34: 55259.97 | F34: -58109.1 | G34: 1V2BR2CAXRC525513 | H34: 47
A35: 240156 | B35: 2024 | C35: VOLKSWAGEN | D35: ATLAS CROSS SPT | E35: 53794.97 | F35: -56570.85 | G35: 1V2BE2CA8RC216649 | H35: 45
A36: 240171 | B36: 2024 | C36: VOLKSWAGEN | D36: JETTA SEDAN | E36: 28629 | G36: 3VWEM7BU2RM001760 | H36: 44
A37: 240173 | B37: 2024 | C37: VOLKSWAGEN | D37: ATLAS | E37: 54801.97 | F37: -57628.2 | G37: 1V2BR2CA7RC532368 | H37: 41
A38: 240190 | B38: 2024 | C38: VOLKSWAGEN | D38: ATLAS | E38: 58249.97 | G38: 1V2FR2CA7RC531156 | H38: 38
A39: 240197 | B39: 2024 | C39: VOLKSWAGEN | D39: TIGUAN | E39: 45175.95 | F39: -47526.15 | G39: 3VV4B7AX2RM023873 | H39: 37
A40: 240203 | B40: 2024 | C40: VOLKSWAGEN | D40: TIGUAN | E40: 44101 | F40: -46474.05 | G40: 3VV4B7AX6RM025190 | H40: 34
A41: 240207 | B41: 2024 | C41: VOLKSWAGEN | D41: ATLAS | E41: 54806.97 | F41: -57628.2 | G41: 1V2BR2CA4RC531890 | H41: 33
A42: 240206 | B42: 2024 | C42: VOLKSWAGEN | D42: TAOS | E42: 38195 | F42: -40225.5 | G42: 3VV4X7B25RM012063 | H42: 33
A43: 240212 | B43: 2024 | C43: VOLKSWAGEN | D43: ATLAS CROSS SPT | E43: 56348.1 | F43: -58834.65 | G43: 1V2FE2CA5RC219798 | H43: 30
...

Sheet 2pager
B1: =Parametres!$B$1&" "&"2 pager"&" "&Parametres!$B$3&" "&Parametres!$B$4 -> Volks 2 pager Avril 2024
B3: New | C3: Actual | D3: Budget | E3: 2023 | F3: ▲ Budget | G3: ▲2023 | H3: % ▲ Budget | I3: % ▲ 2023 | J3: Commentaires
B4: Units | C4: =+Print_Mois!$J$13+Print_Mois!$J$15 -> 73 | D4: =+Print_Mois!$D$13+Print_Mois!$D$15 -> 67 | E4: =+Print_Mois!$O$13+Print_Mois!$O$15 -> 34 | F4: =+IFERROR($C4-D4,"") -> 6 | G4: =+IFERROR($C4-E4,"") -> 39 | H4: =+IFERROR(F4/ABS($D4),"") -> 0.089552239 | I4: =+IFERROR(G4/ABS($E4),"") -> 1.1470588 | J4: Volume over budget mais moyennes front & back plus difficiles, F&i en transition avec les nouvelles embauches. Des frais de livraisons en hausse avec le nombre de locates et un impact aussi sur le hodback. Dépenses sous contrôle mais on doit être plus vigilants sur la rotation de l'inventaire de neuf et privilégier absolument le stock. Le plan de paye à effet au 1er février aura un impact sur ce point.
B5: Front Margin | C5: =+Print_Mois!$L$13+Print_Mois!$L$15 -> 196303.82 | D5: =+Print_Mois!$F$13+Print_Mois!$F$15 -> 181312.49 | E5: =+Print_Mois!$Q$13+Print_Mois!$Q$15 -> 85714.44 | F5: =+IFERROR($C5-D5,"") -> 14991.326 | G5: =+IFERROR($C5-E5,"") -> 110589.38 | H5: =+IFERROR(F5/ABS($D5),"") -> 0.082682257 | I5: =+IFERROR(G5/ABS($E5),"") -> 1.2902071
B6: Front margin / unit | C6: =+C5/C4 -> 2689.0934 | D6: =+D5/D4 -> 2706.1566 | E6: =+E5/E4 -> 2521.0129 | F6: =+IFERROR($C6-D6,"") -> -17.063198 | G6: =+IFERROR($C6-E6,"") -> 168.08048 | H6: =+IFERROR(F6/ABS($D6),"") -> -0.0063053255 | I6: =+IFERROR(G6/ABS($E6),"") -> 0.066671805
B7: $ Salaires et commission | C7: =+Print_Mois!$L$31 -> 48723.01 | D7: =+Print_Mois!$F$31 -> 61646.248 | E7: =+Print_Mois!$Q$31 -> 37095.46 | F7: =+IFERROR($C7-D7,"") -> -12923.238 | G7: =+IFERROR($C7-E7,"") -> 11627.55 | H7: =+IFERROR(F7/ABS($D7),"") -> -0.20963543 | I7: =+IFERROR(G7/ABS($E7),"") -> 0.31344941
B8: % Salaires et commission | C8: =+C7/C5 -> 0.24820205 | D8: =+D7/D5 -> 0.34 | E8: =+E7/E5 -> 0.43277959 | F8: =+IFERROR($C8-D8,"") -> -0.091797953 | G8: =+IFERROR($C8-E8,"") -> -0.18457754 | H8: =+IFERROR(F8/ABS($D8),"") -> -0.26999398 | I8: =+IFERROR(G8/ABS($E8),"") -> -0.42649318
B9: Back Margin | C9: =+Print_Mois!$L$24 -> 57270.55 | D9: =+Print_Mois!$F$24 -> 87100 | E9: =+Print_Mois!$Q$24 -> 33485.11 | F9: =+IFERROR($C9-D9,"") -> -29829.45 | G9: =+IFERROR($C9-E9,"") -> 23785.44 | H9: =+IFERROR(F9/ABS($D9),"") -> -0.34247359 | I9: =+IFERROR(G9/ABS($E9),"") -> 0.71032886
B10: Back Margin / unit | C10: =+C9/C4 -> 784.52808 | D10: =+D9/D4 -> 1300 | E10: =+E9/E4 -> 984.85618 | F10: =+IFERROR($C10-D10,"") -> -515.47192 | G10: =+IFERROR($C10-E10,"") -> -200.32809 | H10: =+IFERROR(F10/ABS($D10),"") -> -0.39651686 | I10: =+IFERROR(G10/ABS($E10),"") -> -0.20340848
B11: $ commission FI | C11: =+Print_Mois!$L$32 -> 17016.15 | D11: =+Print_Mois!$F$32 -> 26130 | E11: =+Print_Mois!$Q$32 -> 10038.22 | F11: =+IFERROR($C11-D11,"") -> -9113.85 | G11: =+IFERROR($C11-E11,"") -> 6977.93 | H11: =+IFERROR(F11/ABS($D11),"") -> -0.34878875 | I11: =+IFERROR(G11/ABS($E11),"") -> 0.69513619
B12: % commission FI | C12: =+C11/C9 -> 0.29711868 | D12: =+D11/D9 -> 0.3 | E12: =+E11/E9 -> 0.2997816 | F12: =+IFERROR($C12-D12,"") -> -0.0028813238 | G12: =+IFERROR($C12-E12,"") -> -0.0026629282 | H12: =+IFERROR(F12/ABS($D12),"") -> -0.0096044127 | I12: =+IFERROR(G12/ABS($E12),"") -> -0.0088828941
B13: Variable fees | C13: =+Print_Mois!$L$41-C7-C11 -> 60127.18 | D13: =+Print_Mois!$F$41-D7-D11 -> 42466.778 | E13: =+Print_Mois!$Q$41-E7-E11 -> 13778.55 | F13: =+IFERROR($C13-D13,"") -> 17660.402 | G13: =+IFERROR($C13-E13,"") -> 46348.63 | H13: =+IFERROR(F13/ABS($D13),"") -> 0.41586395 | I13: =+IFERROR(G13/ABS($E13),"") -> 3.3638249
B14: Variable fees / units | C14: =+C13/C4 -> 823.66 | D14: =+D13/D4 -> 633.83251 | E14: =+E13/E4 -> 405.25147 | F14: =+IFERROR($C14-D14,"") -> 189.82749 | G14: =+IFERROR($C14-E14,"") -> 418.40853 | H14: =+IFERROR(F14/ABS($D14),"") -> 0.29949157 | I14: =+IFERROR(G14/ABS($E14),"") -> 1.0324664
