Workbook
Name Ticker: #REF!

Sheet SOMMAIRE
A1: Bonis Cadre
A3: VW | B3: 45688 | C3: GL
A4: Tommy Martel | B4: ='Tommy Martel Diotte 2024'!K30 -> 3058 | D4: =B4*0.6 -> 1834.8 | E4: =B4*0.4 -> 1223.2
A5: Tommy Martel - Trim | B5: ='Tommy Martel Diotte 2024'!K47 -> 0 | D5: =B5*0.6 -> 0 | E5: =B5*0.4 -> 0
A6: Marc-Olivier Poulin | B6: ='Marc-Olivier Poulin 2025'!K34 -> 4250 | C6: 6222
A7: Sebastien Fleury | B7: ='Sebastien Fleury 2025'!K36 -> 4250
A8: Alexandre Paradis | B8: ='Alexandre Paradis 2025 v2'!K44 -> 4500 | C8: 6122
A9: Rémi Dubreuil | B9: ='Rémi Dubreuil 2025'!K36 -> 864.59221 | C9: 6722
A10: Total VW | B10: =SUM(B4:B9) -> 16922.592
B12: Final | C12: Prov. É/F | D12: Écart
A13: 6122 | B13: =B7+B8 -> 8750 | D13: =+B13-C13 -> 8750 | E13: Neuf
A14: 6222 | B14: =B6 -> 4250 | D14: =+B14-C14 -> 4250 | E14: Usagé
A15: 6422 | B15: =D4+D5 -> 1834.8 | D15: =+B15-C15 -> 1834.8 | E15: Service
A16: 6722 | B16: =E4+E5+B9 -> 2087.7922 | D16: =+B16-C16 -> 2087.7922 | E16: Pièces | J16: 6445 | K16: 100
B17: =SUM(B13:B16) -> 16922.592 | C17: =SUM(C13:C16) -> 0 | D17: =SUM(D13:D16) -> 16922.592

Sheet Kaven Bonneau v2 2024
B1: Kaven Bonneau - Directeur des Ventes
B3: Bonis Mensuels | H3: 45321 | I3: 45350 | J3: 45379 | K3: 45408 | L3: 45437 | M3: 45466 | N3: 45495 | O3: 45524 | P3: 45553 | Q3: 45582 | R3: 45611 | S3: 45640
B4: Profit brut départemental NEUF | G4: Réalisé | M4: 124974 | N4: 254171 | O4: 260155
B5: vs BUDGET 2024 | G5: Cible | M5: 259687 | N5: 231018 | O5: 260155
C6: de | D6: à | E6: Boni | G6: % | M6: =IFERROR(ROUND(M4/M5,3)," - - -") -> 0.481 | N6: =IFERROR(ROUND(N4/N5,3)," - - -") -> 1.1 | O6: =IFERROR(ROUND(O4/O5,3)," - - -") -> 1 | P6: =IFERROR(ROUND(P4/P5,3)," - - -") -> - - - | Q6: =IFERROR(ROUND(Q4/Q5,3)," - - -") -> - - - | R6: =IFERROR(ROUND(R4/R5,3)," - - -") -> - - - | S6: =IFERROR(ROUND(S4/S5,3)," - - -") -> - - -
C7: 0.9 | D7: 0.9999 | E7: 500 | M7: =IF(AND(M$6>=$C7,M$6<=$D7),$E7,0) -> 0 | N7: =IF(AND(N$6>=$C7,N$6<=$D7),$E7,0) -> 0 | O7: =IF(AND(O$6>=$C7,O$6<=$D7),$E7,0) -> 0 | P7: =IF(AND(P$6>=$C7,P$6<=$D7),$E7,0) -> 0 | Q7: =IF(AND(Q$6>=$C7,Q$6<=$D7),$E7,0) -> 0 | R7: =IF(AND(R$6>=$C7,R$6<=$D7),$E7,0) -> 0 | S7: =IF(AND(S$6>=$C7,S$6<=$D7),$E7,0) -> 0
C8: 1 | D8: 1.049 | E8: 800 | M8: =IF(AND(M$6>=$C8,M$6<=$D8),$E8,0) -> 0 | N8: =IF(AND(N$6>=$C8,N$6<=$D8),$E8,0) -> 0 | O8: =IF(AND(O$6>=$C8,O$6<=$D8),$E8,0) -> 800 | P8: =IF(AND(P$6>=$C8,P$6<=$D8),$E8,0) -> 0 | Q8: =IF(AND(Q$6>=$C8,Q$6<=$D8),$E8,0) -> 0 | R8: =IF(AND(R$6>=$C8,R$6<=$D8),$E8,0) -> 0 | S8: =IF(AND(S$6>=$C8,S$6<=$D8),$E8,0) -> 0
C9: 1.05 | D9: et plus | E9: 1250 | M9: =IF(AND(M$6>=$C9,M$6<=$D9),$E9,0) -> 0 | N9: =IF(AND(N$6>=$C9,N$6<=$D9),$E9,0) -> 1250 | O9: =IF(AND(O$6>=$C9,O$6<=$D9),$E9,0) -> 0 | P9: =IF(AND(P$6>=$C9,P$6<=$D9),$E9,0) -> 1250 | Q9: =IF(AND(Q$6>=$C9,Q$6<=$D9),$E9,0) -> 1250 | R9: =IF(AND(R$6>=$C9,R$6<=$D9),$E9,0) -> 1250 | S9: =IF(AND(S$6>=$C9,S$6<=$D9),$E9,0) -> 1250
G10: Payable | M10: =SUM(M7:M9) -> 0 | N10: =SUM(N7:N9) -> 1250 | O10: =SUM(O7:O9) -> 800 | P10: =SUM(P7:P9) -> 1250 | Q10: =SUM(Q7:Q9) -> 1250 | R10: =SUM(R7:R9) -> 1250 | S10: =SUM(S7:S9) -> 1250
B11: Objectifs de volume vehicules neufs | G11: Réalisé | M11: 40 | N11: 85 | O11: 88
B12: vs objectif mensuel du manufacturier | G12: Cible | M12: 87 | N12: 80 | O12: 81
C13: de | D13: à | E13: Boni | G13: % | M13: =IFERROR(ROUND(M11/M12,3)," - - -") -> 0.46 | N13: =IFERROR(ROUND(N11/N12,3)," - - -") -> 1.063 | O13: =IFERROR(ROUND(O11/O12,3)," - - -") -> 1.086 | P13: =IFERROR(ROUND(P11/P12,3)," - - -") -> - - - | Q13: =IFERROR(ROUND(Q11/Q12,3)," - - -") -> - - - | R13: =IFERROR(ROUND(R11/R12,3)," - - -") -> - - - | S13: =IFERROR(ROUND(S11/S12,3)," - - -") -> - - -
C14: 0.9 | D14: 0.9999 | E14: 500 | M14: =IF(AND(M$6>=$C14,M$6<=$D14),$E14,0) -> 0 | N14: =IF(AND(N$13>=$C14,N$13<=$D14),$E14,0) -> 0 | O14: =IF(AND(O$13>=$C14,O$13<=$D14),$E14,0) -> 0 | P14: =IF(AND(P$13>=$C14,P$13<=$D14),$E14,0) -> 0 | Q14: =IF(AND(Q$13>=$C14,Q$13<=$D14),$E14,0) -> 0 | R14: =IF(AND(R$13>=$C14,R$13<=$D14),$E14,0) -> 0 | S14: =IF(AND(S$13>=$C14,S$13<=$D14),$E14,0) -> 0
C15: 1 | D15: 1.049 | E15: 800 | M15: =IF(AND(M$6>=$C15,M$6<=$D15),$E15,0) -> 0 | N15: =IF(AND(N$13>=$C15,N$13<=$D15),$E15,0) -> 0 | O15: =IF(AND(O$13>=$C15,O$13<=$D15),$E15,0) -> 0 | P15: =IF(AND(P$13>=$C15,P$13<=$D15),$E15,0) -> 0 | Q15: =IF(AND(Q$13>=$C15,Q$13<=$D15),$E15,0) -> 0 | R15: =IF(AND(R$13>=$C15,R$13<=$D15),$E15,0) -> 0 | S15: =IF(AND(S$13>=$C15,S$13<=$D15),$E15,0) -> 0
C16: 1.05 | D16: et plus | E16: 1250 | M16: =IF(AND(M$6>=$C16,M$6<=$D16),$E16,0) -> 0 | N16: =IF(AND(N$13>=$C16,N$13<=$D16),$E16,0) -> 1250 | O16: =IF(AND(O$13>=$C16,O$13<=$D16),$E16,0) -> 1250 | P16: =IF(AND(P$13>=$C16,P$13<=$D16),$E16,0) -> 1250 | Q16: =IF(AND(Q$13>=$C16,Q$13<=$D16),$E16,0) -> 1250 | R16: =IF(AND(R$13>=$C16,R$13<=$D16),$E16,0) -> 1250 | S16: =IF(AND(S$13>=$C16,S$13<=$D16),$E16,0) -> 1250
G17: Payable | M17: =SUM(M14:M16) -> 0 | N17: =SUM(N14:N16) -> 1250 | O17: =SUM(O14:O16) -> 1250 | P17: =SUM(P14:P16) -> 1250 | Q17: =SUM(Q14:Q16) -> 1250 | R17: =SUM(R14:R16) -> 1250 | S17: =SUM(S14:S16) -> 1250
B18: CSI vehicules neuf, 3 indicateurs strategiques | G18: Réalisé
B19: Doit avoir 80% sur les 3 questions | C19: de | D19: à | E19: Boni | G19: % | M19: 0 | N19: 0 | O19: 1 | P19: =IFERROR(ROUND(P18/#REF!,3)," - - -") -> - - - | Q19: =IFERROR(ROUND(Q18/#REF!,3)," - - -") -> - - - | R19: =IFERROR(ROUND(R18/#REF!,3)," - - -") -> - - - | S19: =IFERROR(ROUND(S18/#REF!,3)," - - -") -> - - -
B20: 2,4,5 | C20: 0 | D20: 0.799 | E20: 0 | M20: =IF(AND(M$6>=$C20,M$6<=$D20),$E20,0) -> 0 | N20: =IF(AND(N$19>=$C20,N$19<=$D20),$E20,0) -> 0 | O20: =IF(AND(O$19>=$C20,O$19<=$D20),$E20,0) -> 0 | P20: =IF(AND(P$19>=$C20,P$19<=$D20),$E20,0) -> 0 | Q20: =IF(AND(Q$19>=$C20,Q$19<=$D20),$E20,0) -> 0 | R20: =IF(AND(R$19>=$C20,R$19<=$D20),$E20,0) -> 0 | S20: =IF(AND(S$19>=$C20,S$19<=$D20),$E20,0) -> 0
C21: 0.8 | D21: 0.83 | E21: 500 | M21: =IF(AND(M$6>=$C21,M$6<=$D21),$E21,0) -> 0 | N21: =IF(AND(N$19>=$C21,N$19<=$D21),$E21,0) -> 0 | O21: =IF(AND(O$19>=$C21,O$19<=$D21),$E21,0) -> 0 | P21: =IF(AND(P$19>=$C21,P$19<=$D21),$E21,0) -> 0 | Q21: =IF(AND(Q$19>=$C21,Q$19<=$D21),$E21,0) -> 0 | R21: =IF(AND(R$19>=$C21,R$19<=$D21),$E21,0) -> 0 | S21: =IF(AND(S$19>=$C21,S$19<=$D21),$E21,0) -> 0
C22: 0.8301 | D22: et plus | E22: 750 | M22: =IF(AND(M$6>=$C22,M$6<=$D22),$E22,0) -> 0 | N22: =IF(AND(N$19>=$C22,N$19<=$D22),$E22,0) -> 0 | O22: =IF(AND(O$19>=$C22,O$19<=$D22),$E22,0) -> 750 | P22: =IF(AND(P$19>=$C22,P$19<=$D22),$E22,0) -> 750 | Q22: =IF(AND(Q$19>=$C22,Q$19<=$D22),$E22,0) -> 750 | R22: =IF(AND(R$19>=$C22,R$19<=$D22),$E22,0) -> 750 | S22: =IF(AND(S$19>=$C22,S$19<=$D22),$E22,0) -> 750
G23: Payable | M23: =SUM(M20:M22) -> 0 | N23: =SUM(N20:N22) -> 0 | O23: =SUM(O20:O22) -> 750 | P23: =SUM(P20:P22) -> 750 | Q23: =SUM(Q20:Q22) -> 750 | R23: =SUM(R20:R22) -> 750 | S23: =SUM(S20:S22) -> 750
B24: Profit brut départemental USAGÉ | G24: Réalisé | M24: 84900 | N24: 100043 | O24: 42434
B25: vs BUDGET 2024 | G25: Cible | M25: 171471 | N25: 159665 | O25: 170159
C26: de | D26: à | E26: Boni | G26: % | M26: =IFERROR(ROUND(M24/M25,3)," - - -") -> 0.495 | N26: =IFERROR(ROUND(N24/N25,3)," - - -") -> 0.627 | O26: =IFERROR(ROUND(O24/O25,3)," - - -") -> 0.249 | P26: =IFERROR(ROUND(P24/P25,3)," - - -") -> - - - | Q26: =IFERROR(ROUND(Q24/Q25,3)," - - -") -> - - - | R26: =IFERROR(ROUND(R24/R25,3)," - - -") -> - - - | S26: =IFERROR(ROUND(S24/S25,3)," - - -") -> - - -
C27: 0.9 | D27: 0.9999 | E27: 500 | M27: =IF(AND(M$26>=$C27,M$26<=$D27),$E27,0) -> 0 | N27: =IF(AND(N$26>=$C27,N$26<=$D27),$E27,0) -> 0 | O27: =IF(AND(O$26>=$C27,O$26<=$D27),$E27,0) -> 0 | P27: =IF(AND(P$26>=$C27,P$26<=$D27),$E27,0) -> 0 | Q27: =IF(AND(Q$26>=$C27,Q$26<=$D27),$E27,0) -> 0 | R27: =IF(AND(R$26>=$C27,R$26<=$D27),$E27,0) -> 0 | S27: =IF(AND(S$26>=$C27,S$26<=$D27),$E27,0) -> 0
C28: 1 | D28: 1.0999 | E28: 800 | M28: =IF(AND(M$26>=$C28,M$26<=$D28),$E28,0) -> 0 | N28: =IF(AND(N$26>=$C28,N$26<=$D28),$E28,0) -> 0 | O28: =IF(AND(O$26>=$C28,O$26<=$D28),$E28,0) -> 0 | P28: =IF(AND(P$26>=$C28,P$26<=$D28),$E28,0) -> 0 | Q28: =IF(AND(Q$26>=$C28,Q$26<=$D28),$E28,0) -> 0 | R28: =IF(AND(R$26>=$C28,R$26<=$D28),$E28,0) -> 0 | S28: =IF(AND(S$26>=$C28,S$26<=$D28),$E28,0) -> 0
C29: 1.1 | D29: et plus | E29: 1250 | M29: =IF(AND(M$26>=$C29,M$26<=$D29),$E29,0) -> 0 | N29: =IF(AND(N$26>=$C29,N$26<=$D29),$E29,0) -> 0 | O29: =IF(AND(O$26>=$C29,O$26<=$D29),$E29,0) -> 0 | P29: =IF(AND(P$26>=$C29,P$26<=$D29),$E29,0) -> 1250 | Q29: =IF(AND(Q$26>=$C29,Q$26<=$D29),$E29,0) -> 1250 | R29: =IF(AND(R$26>=$C29,R$26<=$D29),$E29,0) -> 1250 | S29: =IF(AND(S$26>=$C29,S$26<=$D29),$E29,0) -> 1250
G30: Payable | M30: =SUM(M27:M29) -> 0 | N30: =SUM(N27:N29) -> 0 | O30: =SUM(O27:O29) -> 0 | P30: =SUM(P27:P29) -> 1250 | Q30: =SUM(Q27:Q29) -> 1250 | R30: =SUM(R27:R29) -> 1250 | S30: =SUM(S27:S29) -> 1250
B31: CSI vehicules d'occasion, 3 indicateurs strategiques | G31: Réalisé
B32: Doit avoir 80% sur les 4 questions | C32: de | D32: à | E32: Boni | G32: % | M32: 0 | N32: 0 | O32: 0 | P32: =IFERROR(ROUND(P31/#REF!,3)," - - -") -> - - - | Q32: =IFERROR(ROUND(Q31/#REF!,3)," - - -") -> - - - | R32: =IFERROR(ROUND(R31/#REF!,3)," - - -") -> - - - | S32: =IFERROR(ROUND(S31/#REF!,3)," - - -") -> - - -
B33: 2,3,4,5 | C33: 0 | D33: 0.799 | E33: 0 | M33: =IF(AND(M$32>=$C33,M$32<=$D33),$E33,0) -> 0 | N33: =IF(AND(N$32>=$C33,N$32<=$D33),$E33,0) -> 0 | O33: =IF(AND(O$32>=$C33,O$32<=$D33),$E33,0) -> 0 | P33: =IF(AND(P$32>=$C33,P$32<=$D33),$E33,0) -> 0 | Q33: =IF(AND(Q$32>=$C33,Q$32<=$D33),$E33,0) -> 0 | R33: =IF(AND(R$32>=$C33,R$32<=$D33),$E33,0) -> 0 | S33: =IF(AND(S$32>=$C33,S$32<=$D33),$E33,0) -> 0
C34: 0.8 | D34: 0.83 | E34: 500 | M34: =IF(AND(M$32>=$C34,M$32<=$D34),$E34,0) -> 0 | N34: =IF(AND(N$32>=$C34,N$32<=$D34),$E34,0) -> 0 | O34: =IF(AND(O$32>=$C34,O$32<=$D34),$E34,0) -> 0 | P34: =IF(AND(P$32>=$C34,P$32<=$D34),$E34,0) -> 0 | Q34: =IF(AND(Q$32>=$C34,Q$32<=$D34),$E34,0) -> 0 | R34: =IF(AND(R$32>=$C34,R$32<=$D34),$E34,0) -> 0 | S34: =IF(AND(S$32>=$C34,S$32<=$D34),$E34,0) -> 0
C35: 0.8301 | D35: et plus | E35: 750 | M35: =IF(AND(M$32>=$C35,M$32<=$D35),$E35,0) -> 0 | N35: =IF(AND(N$32>=$C35,N$32<=$D35),$E35,0) -> 0 | O35: =IF(AND(O$32>=$C35,O$32<=$D35),$E35,0) -> 0 | P35: =IF(AND(P$32>=$C35,P$32<=$D35),$E35,0) -> 750 | Q35: =IF(AND(Q$32>=$C35,Q$32<=$D35),$E35,0) -> 750 | R35: =IF(AND(R$32>=$C35,R$32<=$D35),$E35,0) -> 750 | S35: =IF(AND(S$32>=$C35,S$32<=$D35),$E35,0) -> 750
G36: Payable | M36: =SUM(M33:M35) -> 0 | N36: =SUM(N33:N35) -> 0 | O36: =SUM(O33:O35) -> 0 | P36: =SUM(P33:P35) -> 750 | Q36: =SUM(Q33:Q35) -> 750 | R36: =SUM(R33:R35) -> 750 | S36: =SUM(S33:S35) -> 750
G38: Ajustement | O38: 1250
G40: Total Mensuel | M40: =+M10+M30+M36+M17+M23 -> 0 | N40: =+N10+N30+N36+N17+N23 -> 2500 | O40: =+O10+O30+O36+O17+O23+O38 -> 4050 | P40: =+P10+P30+P36+P17+P23 -> 5250 | Q40: =+Q10+Q30+Q36+Q17+Q23 -> 5250 | R40: =+R10+R30+R36+R17+R23 -> 5250 | S40: =+S10+S30+S36+S17+S23 -> 5250
B41: Bonis Trimestriels
B42: Profit NET cumule des 2 departements des ventes | G42: Réalisé | M42: 268536
G43: Cible | M43: 762586
...

Sheet Guillaume Raymond v2 2024 
B1: Guillaume Raymond - Directeur Adjoint Ventes Usagé
B3: Bonis Mensuels | H3: 45321 | I3: 45350 | J3: 45379 | K3: 45408 | L3: 45437 | M3: 45466 | N3: 45495 | O3: 45524 | P3: 45553 | Q3: 45582 | R3: 45611 | S3: 45640
B4: Profit brut départemental USAGÉ | G4: Réalisé | M4: 84900 | N4: ='Kaven Bonneau v2 2024'!N24 -> 100043 | O4: ='Kaven Bonneau v2 2024'!O24 -> 42434 | P4: ='Kaven Bonneau v2 2024'!P24 -> 0 | Q4: ='Kaven Bonneau v2 2024'!Q24 -> 0 | R4: ='Kaven Bonneau v2 2024'!R24 -> 0 | S4: ='Kaven Bonneau v2 2024'!S24 -> 0
B5: vs le Budget 2024 | G5: Cible | M5: 171471 | N5: ='Kaven Bonneau v2 2024'!N25 -> 159665 | O5: ='Kaven Bonneau v2 2024'!O25 -> 170159 | P5: ='Kaven Bonneau v2 2024'!P25 -> 0 | Q5: ='Kaven Bonneau v2 2024'!Q25 -> 0 | R5: ='Kaven Bonneau v2 2024'!R25 -> 0 | S5: ='Kaven Bonneau v2 2024'!S25 -> 0
C6: de | D6: à | E6: Boni | G6: % | M6: =IFERROR(ROUND(M4/M5,3)," - - -") -> 0.495 | N6: =IFERROR(ROUND(N4/N5,3)," - - -") -> 0.627 | O6: =IFERROR(ROUND(O4/O5,3)," - - -") -> 0.249 | P6: =IFERROR(ROUND(P4/P5,3)," - - -") -> - - - | Q6: =IFERROR(ROUND(Q4/Q5,3)," - - -") -> - - - | R6: =IFERROR(ROUND(R4/R5,3)," - - -") -> - - - | S6: =IFERROR(ROUND(S4/S5,3)," - - -") -> - - -
C7: 0.9 | D7: 0.9999 | E7: 500 | M7: =IF(AND(M$6>=$C7,M$6<=$D7),$E7,0) -> 0 | N7: =IF(AND(N$6>=$C7,N$6<=$D7),$E7,0) -> 0 | O7: =IF(AND(O$6>=$C7,O$6<=$D7),$E7,0) -> 0 | P7: =IF(AND(P$6>=$C7,P$6<=$D7),$E7,0) -> 0 | Q7: =IF(AND(Q$6>=$C7,Q$6<=$D7),$E7,0) -> 0 | R7: =IF(AND(R$6>=$C7,R$6<=$D7),$E7,0) -> 0 | S7: =IF(AND(S$6>=$C7,S$6<=$D7),$E7,0) -> 0
C8: 1 | D8: 1.0999 | E8: 850 | M8: =IF(AND(M$6>=$C8,M$6<=$D8),$E8,0) -> 0 | N8: =IF(AND(N$6>=$C8,N$6<=$D8),$E8,0) -> 0 | O8: =IF(AND(O$6>=$C8,O$6<=$D8),$E8,0) -> 0 | P8: =IF(AND(P$6>=$C8,P$6<=$D8),$E8,0) -> 0 | Q8: =IF(AND(Q$6>=$C8,Q$6<=$D8),$E8,0) -> 0 | R8: =IF(AND(R$6>=$C8,R$6<=$D8),$E8,0) -> 0 | S8: =IF(AND(S$6>=$C8,S$6<=$D8),$E8,0) -> 0
C9: 1.1 | D9: et plus | E9: 1500 | M9: =IF(AND(M$6>=$C9,M$6<=$D9),$E9,0) -> 0 | N9: =IF(AND(N$6>=$C9,N$6<=$D9),$E9,0) -> 0 | O9: =IF(AND(O$6>=$C9,O$6<=$D9),$E9,0) -> 0 | P9: =IF(AND(P$6>=$C9,P$6<=$D9),$E9,0) -> 1500 | Q9: =IF(AND(Q$6>=$C9,Q$6<=$D9),$E9,0) -> 1500 | R9: =IF(AND(R$6>=$C9,R$6<=$D9),$E9,0) -> 1500 | S9: =IF(AND(S$6>=$C9,S$6<=$D9),$E9,0) -> 1500
G10: Payable | M10: =SUM(M7:M9) -> 0 | N10: =SUM(N7:N9) -> 0 | O10: =SUM(O7:O9) -> 0 | P10: =SUM(P7:P9) -> 1500 | Q10: =SUM(Q7:Q9) -> 1500 | R10: =SUM(R7:R9) -> 1500 | S10: =SUM(S7:S9) -> 1500
B12: Atteinte Volume Ventes Usagés - DÉTAILS | G12: Réalisé | M12: 33 | N12: 30 | O12: 25
B13: vs le Budget 2024 | G13: Cible | M13: 39 | N13: 36 | O13: 39
C14: de | D14: à | E14: Boni | G14: % | M14: =IFERROR(ROUND(M12/M13,3)," - - -") -> 0.846 | N14: =IFERROR(ROUND(N12/N13,3)," - - -") -> 0.833 | O14: =IFERROR(ROUND(O12/O13,3)," - - -") -> 0.641 | P14: =IFERROR(ROUND(P12/P13,3)," - - -") -> - - - | Q14: =IFERROR(ROUND(Q12/Q13,3)," - - -") -> - - - | R14: =IFERROR(ROUND(R12/R13,3)," - - -") -> - - - | S14: =IFERROR(ROUND(S12/S13,3)," - - -") -> - - -
C15: 0.9 | D15: 0.9999 | E15: 500 | M15: =IF(AND(M$14>=$C15,M$14<=$D15),$E15,0) -> 0 | N15: =IF(AND(N$14>=$C15,N$14<=$D15),$E15,0) -> 0 | O15: =IF(AND(O$14>=$C15,O$14<=$D15),$E15,0) -> 0 | P15: =IF(AND(P$14>=$C15,P$14<=$D15),$E15,0) -> 0 | Q15: =IF(AND(Q$14>=$C15,Q$14<=$D15),$E15,0) -> 0 | R15: =IF(AND(R$14>=$C15,R$14<=$D15),$E15,0) -> 0 | S15: =IF(AND(S$14>=$C15,S$14<=$D15),$E15,0) -> 0
C16: 1 | D16: 1.0999 | E16: 750 | M16: =IF(AND(M$14>=$C16,M$14<=$D16),$E16,0) -> 0 | N16: =IF(AND(N$14>=$C16,N$14<=$D16),$E16,0) -> 0 | O16: =IF(AND(O$14>=$C16,O$14<=$D16),$E16,0) -> 0 | P16: =IF(AND(P$14>=$C16,P$14<=$D16),$E16,0) -> 0 | Q16: =IF(AND(Q$14>=$C16,Q$14<=$D16),$E16,0) -> 0 | R16: =IF(AND(R$14>=$C16,R$14<=$D16),$E16,0) -> 0 | S16: =IF(AND(S$14>=$C16,S$14<=$D16),$E16,0) -> 0
C17: 1.1 | D17: et plus | E17: 1500 | M17: =IF(AND(M$14>=$C17,M$14<=$D17),$E17,0) -> 0 | N17: =IF(AND(N$14>=$C17,N$14<=$D17),$E17,0) -> 0 | O17: =IF(AND(O$14>=$C17,O$14<=$D17),$E17,0) -> 0 | P17: =IF(AND(P$14>=$C17,P$14<=$D17),$E17,0) -> 1500 | Q17: =IF(AND(Q$14>=$C17,Q$14<=$D17),$E17,0) -> 1500 | R17: =IF(AND(R$14>=$C17,R$14<=$D17),$E17,0) -> 1500 | S17: =IF(AND(S$14>=$C17,S$14<=$D17),$E17,0) -> 1500
G18: Payable | M18: =SUM(M15:M17) -> 0 | N18: =SUM(N15:N17) -> 0 | O18: =SUM(O15:O17) -> 0 | P18: =SUM(P15:P17) -> 1500 | Q18: =SUM(Q15:Q17) -> 1500 | R18: =SUM(R15:R17) -> 1500 | S18: =SUM(S15:S17) -> 1500
B20: Atteinte des Indicateurs de Performance ( X de 3 ) | M20: 1 | N20: 1 | O20: 1
C21: de | D21: à | E21: Boni
C22: 0 | D22: 1 | E22: 0 | M22: =IF(AND(M20>=$C22,M20<=$D22),$E22,0) -> 0 | N22: =IF(AND(N20>=$C22,N20<=$D22),$E22,0) -> 0 | O22: =IF(AND(O20>=$C22,O20<=$D22),$E22,0) -> 0 | P22: =IF(AND(P20>=$C22,P20<=$D22),$E22,0) -> 0 | Q22: =IF(AND(Q20>=$C22,Q20<=$D22),$E22,0) -> 0 | R22: =IF(AND(R20>=$C22,R20<=$D22),$E22,0) -> 0 | S22: =IF(AND(S20>=$C22,S20<=$D22),$E22,0) -> 0
C23: 2 | D23: 2 | E23: 750 | M23: =IF(AND(M20>=$C23,M20<=$D23),$E23,0) -> 0 | N23: =IF(AND(N20>=$C23,N20<=$D23),$E23,0) -> 0 | O23: =IF(AND(O20>=$C23,O20<=$D23),$E23,0) -> 0 | P23: =IF(AND(P20>=$C23,P20<=$D23),$E23,0) -> 0 | Q23: =IF(AND(Q20>=$C23,Q20<=$D23),$E23,0) -> 0 | R23: =IF(AND(R20>=$C23,R20<=$D23),$E23,0) -> 0 | S23: =IF(AND(S20>=$C23,S20<=$D23),$E23,0) -> 0
C24: 3 | D24: 3 | E24: 1250 | M24: =IF(AND(M20>=$C24,M20<=$D24),$E24,0) -> 0 | N24: =IF(AND(N20>=$C24,N20<=$D24),$E24,0) -> 0 | O24: =IF(AND(O20>=$C24,O20<=$D24),$E24,0) -> 0 | P24: =IF(AND(P20>=$C24,P20<=$D24),$E24,0) -> 0 | Q24: =IF(AND(Q20>=$C24,Q20<=$D24),$E24,0) -> 0 | R24: =IF(AND(R20>=$C24,R20<=$D24),$E24,0) -> 0 | S24: =IF(AND(S20>=$C24,S20<=$D24),$E24,0) -> 0
G25: Payable | M25: =SUM(M22:M24) -> 0 | N25: =SUM(N22:N24) -> 0 | O25: =SUM(O22:O24) -> 0 | P25: =SUM(P22:P24) -> 0 | Q25: =SUM(Q22:Q24) -> 0 | R25: =SUM(R22:R24) -> 0 | S25: =SUM(S22:S24) -> 0
B27: CSI ( X de 4 ) | M27: 1 | N27: 0 | O27: 0
C28: de | D28: à | E28: Boni
C29: 0 | D29: 0.7999 | E29: 0 | M29: =IF(AND(M27>=$C29,M27<=$D29),$E29,0) -> 0 | N29: =IF(AND(N27>=$C29,N27<=$D29),$E29,0) -> 0 | O29: =IF(AND(O27>=$C29,O27<=$D29),$E29,0) -> 0 | P29: =IF(AND(P27>=$C29,P27<=$D29),$E29,0) -> 0 | Q29: =IF(AND(Q27>=$C29,Q27<=$D29),$E29,0) -> 0 | R29: =IF(AND(R27>=$C29,R27<=$D29),$E29,0) -> 0 | S29: =IF(AND(S27>=$C29,S27<=$D29),$E29,0) -> 0
C30: 0.8 | D30: 0.85 | E30: 1000 | M30: =IF(AND(M27>=$C30,M27<=$D30),$E30,0) -> 0 | N30: =IF(AND(N27>=$C30,N27<=$D30),$E30,0) -> 0 | O30: =IF(AND(O27>=$C30,O27<=$D30),$E30,0) -> 0 | P30: =IF(AND(P27>=$C30,P27<=$D30),$E30,0) -> 0 | Q30: =IF(AND(Q27>=$C30,Q27<=$D30),$E30,0) -> 0 | R30: =IF(AND(R27>=$C30,R27<=$D30),$E30,0) -> 0 | S30: =IF(AND(S27>=$C30,S27<=$D30),$E30,0) -> 0
C31: 0.8501 | D31: et plus | E31: 2000 | M31: =IF(AND(M27>=$C31,M27<=$D31),$E31,0) -> 2000 | N31: =IF(AND(N27>=$C31,N27<=$D31),$E31,0) -> 0 | O31: =IF(AND(O27>=$C31,O27<=$D31),$E31,0) -> 0 | P31: =IF(AND(P27>=$C31,P27<=$D31),$E31,0) -> 0 | Q31: =IF(AND(Q27>=$C31,Q27<=$D31),$E31,0) -> 0 | R31: =IF(AND(R27>=$C31,R27<=$D31),$E31,0) -> 0 | S31: =IF(AND(S27>=$C31,S27<=$D31),$E31,0) -> 0
G32: Payable | M32: =SUM(M29:M31) -> 2000 | N32: =SUM(N29:N31) -> 0 | O32: =SUM(O29:O31) -> 0 | P32: =SUM(P29:P31) -> 0 | Q32: =SUM(Q29:Q31) -> 0 | R32: =SUM(R29:R31) -> 0 | S32: =SUM(S29:S31) -> 0
E34: Vente de véhicule en inventaire / Produit F&I | M34: 280 | N34: 60
G36: Total Mensuel | H36: =H10+H18+H25+H32+H34 -> 0 | I36: =I10+I18+I25+I32+I34 -> 0 | J36: =J10+J18+J25+J32+J34 -> 0 | K36: =K10+K18+K25+K32+K34 -> 0 | L36: =L10+L18+L25+L32+L34 -> 0 | M36: =M10+M18+M25+M32+M34 -> 2280 | N36: =N10+N18+N25+N32+N34 -> 60 | O36: =O10+O18+O25+O32+O34 -> 0 | ... S36: =S10+S18+S25+S32+S34 -> 3000

Sheet Guillaume Raymond 2024
B1: Guillaume Raymond - Directeur Adjoint Ventes Usagé
B3: Bonis Mensuels | H3: 45321 | I3: 45350 | J3: 45379 | K3: 45408 | L3: 45437 | M3: 45466 | N3: 45495 | O3: 45524 | P3: 45553 | Q3: 45582 | R3: 45611 | S3: 45640
B4: Profit brut départemental USAGÉ | G4: Réalisé | I4: 12562 | J4: 77150.61 | K4: ='Kaven Bonneau 2024'!K12 -> 62515 | L4: 49484 | M4: 84900
B5: vs le Budget 2024 | G5: Cible | I5: 110753 | J5: 166598.6 | K5: ='Kaven Bonneau 2024'!K13 -> 186276 | L5: 189649 | M5: 171471
C6: de | D6: à | E6: Boni | G6: % | I6: =IFERROR(ROUND(I4/I5,3)," - - -") -> 0.113 | J6: =IFERROR(ROUND(J4/J5,3)," - - -") -> 0.463 | K6: =IFERROR(ROUND(K4/K5,3)," - - -") -> 0.336 | L6: =IFERROR(ROUND(L4/L5,3)," - - -") -> 0.261 | M6: =IFERROR(ROUND(M4/M5,3)," - - -") -> 0.495 | N6: =IFERROR(ROUND(N4/N5,3)," - - -") -> - - - | O6: =IFERROR(ROUND(O4/O5,3)," - - -") -> - - - | P6: =IFERROR(ROUND(P4/P5,3)," - - -") -> - - - | ... S6: =IFERROR(ROUND(S4/S5,3)," - - -") -> - - -
C7: 0.9 | D7: 0.9999 | E7: 750 | H7: =IF(AND(H$6>=$C7,H$6<=$D7),$E7,0) -> 0 | I7: =IF(AND(I$6>=$C7,I$6<=$D7),$E7,0) -> 0 | J7: =IF(AND(J$6>=$C7,J$6<=$D7),$E7,0) -> 0 | K7: =IF(AND(K$6>=$C7,K$6<=$D7),$E7,0) -> 0 | L7: =IF(AND(L$6>=$C7,L$6<=$D7),$E7,0) -> 0 | M7: =IF(AND(M$6>=$C7,M$6<=$D7),$E7,0) -> 0 | N7: =IF(AND(N$6>=$C7,N$6<=$D7),$E7,0) -> 0 | O7: =IF(AND(O$6>=$C7,O$6<=$D7),$E7,0) -> 0 | ... S7: =IF(AND(S$6>=$C7,S$6<=$D7),$E7,0) -> 0
C8: 1 | D8: 1.0999 | E8: 1250 | H8: =IF(AND(H$6>=$C8,H$6<=$D8),$E8,0) -> 0 | I8: =IF(AND(I$6>=$C8,I$6<=$D8),$E8,0) -> 0 | J8: =IF(AND(J$6>=$C8,J$6<=$D8),$E8,0) -> 0 | K8: =IF(AND(K$6>=$C8,K$6<=$D8),$E8,0) -> 0 | L8: =IF(AND(L$6>=$C8,L$6<=$D8),$E8,0) -> 0 | M8: =IF(AND(M$6>=$C8,M$6<=$D8),$E8,0) -> 0 | N8: =IF(AND(N$6>=$C8,N$6<=$D8),$E8,0) -> 0 | O8: =IF(AND(O$6>=$C8,O$6<=$D8),$E8,0) -> 0 | ... S8: =IF(AND(S$6>=$C8,S$6<=$D8),$E8,0) -> 0
C9: 1.1 | D9: et plus | E9: 1750 | H9: =IF(AND(H$6>=$C9,H$6<=$D9),$E9,0) -> 0 | I9: =IF(AND(I$6>=$C9,I$6<=$D9),$E9,0) -> 0 | J9: =IF(AND(J$6>=$C9,J$6<=$D9),$E9,0) -> 0 | K9: =IF(AND(K$6>=$C9,K$6<=$D9),$E9,0) -> 0 | L9: =IF(AND(L$6>=$C9,L$6<=$D9),$E9,0) -> 0 | M9: =IF(AND(M$6>=$C9,M$6<=$D9),$E9,0) -> 0 | N9: =IF(AND(N$6>=$C9,N$6<=$D9),$E9,0) -> 1750 | O9: =IF(AND(O$6>=$C9,O$6<=$D9),$E9,0) -> 1750 | ... S9: =IF(AND(S$6>=$C9,S$6<=$D9),$E9,0) -> 1750
G10: Payable | H10: =SUM(H7:H9) -> 0 | I10: =SUM(I7:I9) -> 0 | J10: =SUM(J7:J9) -> 0 | K10: =SUM(K7:K9) -> 0 | L10: =SUM(L7:L9) -> 0 | M10: =SUM(M7:M9) -> 0 | N10: =SUM(N7:N9) -> 1750 | O10: =SUM(O7:O9) -> 1750 | ... S10: =SUM(S7:S9) -> 1750
B12: Atteinte Volume Ventes Usagés - DÉTAILS | G12: Réalisé | I12: 27 | J12: 22 | K12: 23 | L12: 40 | M12: 33
B13: vs le Budget 2024 | G13: Cible | I13: 25 | J13: 37.7825 | K13: 42 | L13: 43 | M13: 39
C14: de | D14: à | E14: Boni | G14: % | I14: =IFERROR(ROUND(I12/I13,3)," - - -") -> 1.08 | J14: =IFERROR(ROUND(J12/J13,3)," - - -") -> 0.582 | K14: =IFERROR(ROUND(K12/K13,3)," - - -") -> 0.548 | L14: =IFERROR(ROUND(L12/L13,3)," - - -") -> 0.93 | M14: =IFERROR(ROUND(M12/M13,3)," - - -") -> 0.846 | N14: =IFERROR(ROUND(N12/N13,3)," - - -") -> - - - | O14: =IFERROR(ROUND(O12/O13,3)," - - -") -> - - - | P14: =IFERROR(ROUND(P12/P13,3)," - - -") -> - - - | ... S14: =IFERROR(ROUND(S12/S13,3)," - - -") -> - - -
C15: 0.9 | D15: 0.9999 | E15: 750 | H15: =IF(AND(H$14>=$C15,H$14<=$D15),$E15,0) -> 0 | I15: =IF(AND(I$14>=$C15,I$14<=$D15),$E15,0) -> 0 | J15: =IF(AND(J$14>=$C15,J$14<=$D15),$E15,0) -> 0 | K15: =IF(AND(K$14>=$C15,K$14<=$D15),$E15,0) -> 0 | L15: =IF(AND(L$14>=$C15,L$14<=$D15),$E15,0) -> 750 | M15: =IF(AND(M$14>=$C15,M$14<=$D15),$E15,0) -> 0 | N15: =IF(AND(N$14>=$C15,N$14<=$D15),$E15,0) -> 0 | O15: =IF(AND(O$14>=$C15,O$14<=$D15),$E15,0) -> 0 | ... S15: =IF(AND(S$14>=$C15,S$14<=$D15),$E15,0) -> 0
C16: 1 | D16: 1.0999 | E16: 1250 | H16: =IF(AND(H$14>=$C16,H$14<=$D16),$E16,0) -> 0 | I16: =IF(AND(I$14>=$C16,I$14<=$D16),$E16,0) -> 1250 | J16: =IF(AND(J$14>=$C16,J$14<=$D16),$E16,0) -> 0 | K16: =IF(AND(K$14>=$C16,K$14<=$D16),$E16,0) -> 0 | L16: =IF(AND(L$14>=$C16,L$14<=$D16),$E16,0) -> 0 | M16: =IF(AND(M$14>=$C16,M$14<=$D16),$E16,0) -> 0 | N16: =IF(AND(N$14>=$C16,N$14<=$D16),$E16,0) -> 0 | O16: =IF(AND(O$14>=$C16,O$14<=$D16),$E16,0) -> 0 | ... S16: =IF(AND(S$14>=$C16,S$14<=$D16),$E16,0) -> 0
C17: 1.1 | D17: et plus | E17: 1750 | H17: =IF(AND(H$14>=$C17,H$14<=$D17),$E17,0) -> 0 | I17: =IF(AND(I$14>=$C17,I$14<=$D17),$E17,0) -> 0 | J17: =IF(AND(J$14>=$C17,J$14<=$D17),$E17,0) -> 0 | K17: =IF(AND(K$14>=$C17,K$14<=$D17),$E17,0) -> 0 | L17: =IF(AND(L$14>=$C17,L$14<=$D17),$E17,0) -> 0 | M17: =IF(AND(M$14>=$C17,M$14<=$D17),$E17,0) -> 0 | N17: =IF(AND(N$14>=$C17,N$14<=$D17),$E17,0) -> 1750 | O17: =IF(AND(O$14>=$C17,O$14<=$D17),$E17,0) -> 1750 | ... S17: =IF(AND(S$14>=$C17,S$14<=$D17),$E17,0) -> 1750
G18: Payable | H18: =SUM(H15:H17) -> 0 | I18: =SUM(I15:I17) -> 1250 | J18: =SUM(J15:J17) -> 0 | K18: =SUM(K15:K17) -> 0 | L18: =SUM(L15:L17) -> 750 | M18: =SUM(M15:M17) -> 0 | N18: =SUM(N15:N17) -> 1750 | O18: =SUM(O15:O17) -> 1750 | ... S18: =SUM(S15:S17) -> 1750
B20: Atteinte de la Cible CSI CPO (VOC) | G20: Réalisé | I20: 5 | J20: 5 | K20: 4 | L20: 4.04
C21: de | D21: à | E21: Boni
C22: 0 | D22: 4.8 | E22: 0 | H22: =IF(AND(H$20>=$C22,H$20<=$D22),$E22,0) -> 0 | I22: =IF(AND(I$20>=$C22,I$20<=$D22),$E22,0) -> 0 | J22: =IF(AND(J$20>=$C22,J$20<=$D22),$E22,0) -> 0 | K22: =IF(AND(K$20>=$C22,K$20<=$D22),$E22,0) -> 0 | L22: =IF(AND(L$20>=$C22,L$20<=$D22),$E22,0) -> 0 | M22: =IF(AND(M$20>=$C22,M$20<=$D22),$E22,0) -> 0 | N22: =IF(AND(N$20>=$C22,N$20<=$D22),$E22,0) -> 0 | O22: =IF(AND(O$20>=$C22,O$20<=$D22),$E22,0) -> 0 | ... S22: =IF(AND(S$20>=$C22,S$20<=$D22),$E22,0) -> 0
C23: 4.81 | D23: 4.89 | E23: 500 | H23: =IF(AND(H$20>=$C23,H$20<=$D23),$E23,0) -> 0 | I23: =IF(AND(I$20>=$C23,I$20<=$D23),$E23,0) -> 0 | J23: =IF(AND(J$20>=$C23,J$20<=$D23),$E23,0) -> 0 | K23: =IF(AND(K$20>=$C23,K$20<=$D23),$E23,0) -> 0 | L23: =IF(AND(L$20>=$C23,L$20<=$D23),$E23,0) -> 0 | M23: =IF(AND(M$20>=$C23,M$20<=$D23),$E23,0) -> 0 | N23: =IF(AND(N$20>=$C23,N$20<=$D23),$E23,0) -> 0 | O23: =IF(AND(O$20>=$C23,O$20<=$D23),$E23,0) -> 0 | ... S23: =IF(AND(S$20>=$C23,S$20<=$D23),$E23,0) -> 0
C24: 4.9 | D24: et plus | E24: 1000 | H24: =IF(AND(H$20>=$C24,H$20<=$D24),$E24,0) -> 0 | I24: =IF(AND(I$20>=$C24,I$20<=$D24),$E24,0) -> 1000 | J24: =IF(AND(J$20>=$C24,J$20<=$D24),$E24,0) -> 1000 | K24: =IF(AND(K$20>=$C24,K$20<=$D24),$E24,0) -> 0 | L24: =IF(AND(L$20>=$C24,L$20<=$D24),$E24,0) -> 0 | M24: =IF(AND(M$20>=$C24,M$20<=$D24),$E24,0) -> 0 | N24: =IF(AND(N$20>=$C24,N$20<=$D24),$E24,0) -> 0 | O24: =IF(AND(O$20>=$C24,O$20<=$D24),$E24,0) -> 0 | ... S24: =IF(AND(S$20>=$C24,S$20<=$D24),$E24,0) -> 0
G25: Payable | H25: =SUM(H22:H24) -> 0 | I25: =SUM(I22:I24) -> 1000 | J25: =SUM(J22:J24) -> 1000 | K25: =SUM(K22:K24) -> 0 | L25: =SUM(L22:L24) -> 0 | M25: =SUM(M22:M24) -> 0 | N25: =SUM(N22:N24) -> 0 | O25: =SUM(O22:O24) -> 0 | ... S25: =SUM(S22:S24) -> 0
B27: Atteinte des Indiicateurs de Performance ( X de 4 )
B28: (Inventaire > 90 jours en bas de 15% ou de Nov à février 25% / Marchandisage moyen dans le mois >95% / Taux de closing web >15% / Taux de closing Phone ups > 30% | G28: Réalisé | I28: 3 | J28: 2 | K28: 3 | L28: 2
C29: de | D29: à | E29: Boni
C30: 2 | D30: 2 | E30: 500 | H30: =IF(AND(H$28>=$C30,H$28<=$D30),$E30,0) -> 0 | I30: =IF(AND(I$28>=$C30,I$28<=$D30),$E30,0) -> 0 | J30: =IF(AND(J$28>=$C30,J$28<=$D30),$E30,0) -> 500 | K30: =IF(AND(K$28>=$C30,K$28<=$D30),$E30,0) -> 0 | L30: =IF(AND(L$28>=$C30,L$28<=$D30),$E30,0) -> 500 | M30: =IF(AND(M$28>=$C30,M$28<=$D30),$E30,0) -> 0 | N30: =IF(AND(N$28>=$C30,N$28<=$D30),$E30,0) -> 0 | O30: =IF(AND(O$28>=$C30,O$28<=$D30),$E30,0) -> 0 | ... S30: =IF(AND(S$28>=$C30,S$28<=$D30),$E30,0) -> 0
C31: 3 | D31: 3 | E31: 1000 | H31: =IF(AND(H$28>=$C31,H$28<=$D31),$E31,0) -> 0 | I31: =IF(AND(I$28>=$C31,I$28<=$D31),$E31,0) -> 1000 | J31: =IF(AND(J$28>=$C31,J$28<=$D31),$E31,0) -> 0 | K31: =IF(AND(K$28>=$C31,K$28<=$D31),$E31,0) -> 1000 | L31: =IF(AND(L$28>=$C31,L$28<=$D31),$E31,0) -> 0 | M31: =IF(AND(M$28>=$C31,M$28<=$D31),$E31,0) -> 0 | N31: =IF(AND(N$28>=$C31,N$28<=$D31),$E31,0) -> 0 | O31: =IF(AND(O$28>=$C31,O$28<=$D31),$E31,0) -> 0 | ... S31: =IF(AND(S$28>=$C31,S$28<=$D31),$E31,0) -> 0
C32: 4 | D32: 4 | E32: 1500 | H32: =IF(AND(H$28>=$C32,H$28<=$D32),$E32,0) -> 0 | I32: =IF(AND(I$28>=$C32,I$28<=$D32),$E32,0) -> 0 | J32: =IF(AND(J$28>=$C32,J$28<=$D32),$E32,0) -> 0 | K32: =IF(AND(K$28>=$C32,K$28<=$D32),$E32,0) -> 0 | L32: =IF(AND(L$28>=$C32,L$28<=$D32),$E32,0) -> 0 | M32: =IF(AND(M$28>=$C32,M$28<=$D32),$E32,0) -> 0 | N32: =IF(AND(N$28>=$C32,N$28<=$D32),$E32,0) -> 0 | O32: =IF(AND(O$28>=$C32,O$28<=$D32),$E32,0) -> 0 | ... S32: =IF(AND(S$28>=$C32,S$28<=$D32),$E32,0) -> 0
G33: Payable | H33: =SUM(H30:H32) -> 0 | I33: =SUM(I30:I32) -> 1000 | J33: =SUM(J30:J32) -> 500 | K33: =SUM(K30:K32) -> 1000 | L33: =SUM(L30:L32) -> 500 | M33: =SUM(M30:M32) -> 0 | N33: =SUM(N30:N32) -> 0 | O33: =SUM(O30:O32) -> 0 | ... S33: =SUM(S30:S32) -> 0
E35: Vente de véhicule en inventaire / Produit F&I | J35: 200 | K35: 200 | L35: 120
G37: Total Mensuel | H37: =+H10+H18+H25+H33 -> 0 | I37: =+I10+I18+I25+I33 -> 3250 | J37: =+J10+J18+J25+J33+J35 -> 1700 | K37: =+K10+K18+K25+K33+K35 -> 1200 | L37: =+L10+L18+L25+L33+L35 -> 1370 | M37: =+M10+M18+M25+M33+M35 -> 0 | N37: =+N10+N18+N25+N33+N35 -> 3500 | O37: =+O10+O18+O25+O33+O35 -> 3500 | P37: =+P10+P18+P25+P33+P35 -> 3500 | Q37: =+Q10+Q18+Q25+Q33+Q35 -> 3500 | ... S37: =+S10+S18+S25+S33+S35 -> 3500

Sheet Sebastien Fleury 2025
B1: Sebastien Fleury - Directeur General des ventes
B3: Bonis Mensuels | H3: 45688 | I3: 45716 | J3: 45747 | K3: 45777 | L3: 45808 | M3: 45838 | N3: 45869 | O3: 45900 | P3: 45930 | Q3: 45961 | R3: 45991 | S3: 46022
B4: Profit net départemental NEUF | G4: Réalisé | H4: 110350 | I4: 63627 | J4: 55508 | K4: =115596-21449.7-15600 -> 78546.3 | L4: 0 | M4: 0 | N4: 0 | O4: 0 | P4: 0 | Q4: 0 | R4: 0 | S4: 0 | U4: L27 | V4: =SUM(I4:J4) -> 119135
B5: vs le Budget 2025 | G5: Cible | H5: 83820 | I5: 79399 | J5: =69531-25000 -> 44531 | K5: 90870 | L5: 0 | M5: 0 | N5: 0 | O5: 0 | P5: 0 | Q5: 0 | R5: 0 | S5: 0 | U5: F27 | V5: =SUM(I5:J5) -> 123930
C6: de | D6: à | E6: Boni | G6: % | H6: =IFERROR(ROUND(H4/H5,3)," - - -") -> 1.317 | I6: 0.9 | J6: =IFERROR(ROUND(J4/J5,3)," - - -") -> 1.247 | K6: =IFERROR(ROUND(K4/K5,3)," - - -") -> 0.864 | L6: =IFERROR(ROUND(L4/L5,3)," - - -") -> - - - | M6: =IFERROR(ROUND(M4/M5,3)," - - -") -> - - - | N6: =IFERROR(ROUND(N4/N5,3)," - - -") -> - - - | O6: =IFERROR(ROUND(O4/O5,3)," - - -") -> - - - | P6: =IFERROR(ROUND(P4/P5,3)," - - -") -> - - - | Q6: =IFERROR(ROUND(Q4/Q5,3)," - - -") -> - - - | ... S6: =IFERROR(ROUND(S4/S5,3)," - - -") -> - - - | V6: =IFERROR(ROUND(V4/V5,3)," - - -") -> 0.961
C7: 0.9 | D7: 0.9999 | E7: 750 | H7: =IF(AND(H$6>=$C7,H$6<=$D7),$E7,0) -> 0 | I7: =IF(AND(I$6>=$C7,I$6<=$D7),$E7,0) -> 750 | J7: =IF(AND(J$6>=$C7,J$6<=$D7),$E7,0) -> 0 | K7: =IF(AND(K$6>=$C7,K$6<=$D7),$E7,0) -> 0 | L7: =IF(AND(L$6>=$C7,L$6<=$D7),$E7,0) -> 0 | M7: =IF(AND(M$6>=$C7,M$6<=$D7),$E7,0) -> 0 | N7: =IF(AND(N$6>=$C7,N$6<=$D7),$E7,0) -> 0 | O7: =IF(AND(O$6>=$C7,O$6<=$D7),$E7,0) -> 0 | ... S7: =IF(AND(S$6>=$C7,S$6<=$D7),$E7,0) -> 0
C8: 1 | D8: 1.1999 | E8: 1500 | H8: =IF(AND(H$6>=$C8,H$6<=$D8),$E8,0) -> 0 | I8: =IF(AND(I$6>=$C8,I$6<=$D8),$E8,0) -> 0 | J8: =IF(AND(J$6>=$C8,J$6<=$D8),$E8,0) -> 0 | K8: =IF(AND(K$6>=$C8,K$6<=$D8),$E8,0) -> 0 | L8: =IF(AND(L$6>=$C8,L$6<=$D8),$E8,0) -> 0 | M8: =IF(AND(M$6>=$C8,M$6<=$D8),$E8,0) -> 0 | N8: =IF(AND(N$6>=$C8,N$6<=$D8),$E8,0) -> 0 | O8: =IF(AND(O$6>=$C8,O$6<=$D8),$E8,0) -> 0 | ... S8: =IF(AND(S$6>=$C8,S$6<=$D8),$E8,0) -> 0
C9: 1.2 | D9: et plus | E9: 2500 | H9: =IF(AND(H$6>=$C9,H$6<=$D9),$E9,0) -> 2500 | I9: =IF(AND(I$6>=$C9,I$6<=$D9),$E9,0) -> 0 | J9: =IF(AND(J$6>=$C9,J$6<=$D9),$E9,0) -> 2500 | K9: =IF(AND(K$6>=$C9,K$6<=$D9),$E9,0) -> 0 | L9: =IF(AND(L$6>=$C9,L$6<=$D9),$E9,0) -> 2500 | M9: =IF(AND(M$6>=$C9,M$6<=$D9),$E9,0) -> 2500 | N9: =IF(AND(N$6>=$C9,N$6<=$D9),$E9,0) -> 2500 | O9: =IF(AND(O$6>=$C9,O$6<=$D9),$E9,0) -> 2500 | ... S9: =IF(AND(S$6>=$C9,S$6<=$D9),$E9,0) -> 2500
G10: Payable | H10: =SUM(H7:H9) -> 2500 | I10: =SUM(I7:I9) -> 750 | J10: =SUM(J7:J9) -> 2500 | K10: =SUM(K7:K9) -> 0 | L10: =SUM(L7:L9) -> 2500 | M10: =SUM(M7:M9) -> 2500 | N10: =SUM(N7:N9) -> 2500 | O10: =SUM(O7:O9) -> 2500 | ... S10: =SUM(S7:S9) -> 2500
B12: Profit net départemental USED | G12: Réalisé | H12: 1151 | I12: -9236 | J12: 27817 | K12: 30976 | L12: 0 | M12: 0 | N12: 0 | O12: 0 | P12: 0 | Q12: 0 | R12: 0 | S12: 0 | U12: L27 | V12: =SUM(I12:J12) -> 18581
B13: vs le Budget 2025 | G13: Cible | H13: -19027 | I13: 516 | J13: 3636 | K13: 2935 | L13: 0 | M13: 0 | N13: 0 | O13: 0 | P13: 0 | Q13: 0 | R13: 0 | S13: 0 | U13: F27 | V13: =SUM(I13:J13) -> 4152
C14: de | D14: à | E14: Boni | G14: % | H14: 1.2 | I14: 0.9 | J14: =IFERROR(ROUND(J12/J13,3)," - - -") -> 7.65 | K14: =IFERROR(ROUND(K12/K13,3)," - - -") -> 10.554 | L14: =IFERROR(ROUND(L12/L13,3)," - - -") -> - - - | M14: =IFERROR(ROUND(M12/M13,3)," - - -") -> - - - | N14: =IFERROR(ROUND(N12/N13,3)," - - -") -> - - - | O14: =IFERROR(ROUND(O12/O13,3)," - - -") -> - - - | P14: =IFERROR(ROUND(P12/P13,3)," - - -") -> - - - | Q14: =IFERROR(ROUND(Q12/Q13,3)," - - -") -> - - - | ... S14: =IFERROR(ROUND(S12/S13,3)," - - -") -> - - - | V14: =IFERROR(ROUND(V12/V13,3)," - - -") -> 4.475
C15: 0.9 | D15: 0.9999 | E15: 750 | H15: =IF(AND(H$14>=$C15,H$14<=$D15),$E15,0) -> 0 | I15: =IF(AND(I$14>=$C15,I$14<=$D15),$E15,0) -> 750 | J15: =IF(AND(J$14>=$C15,J$14<=$D15),$E15,0) -> 0 | K15: =IF(AND(K$14>=$C15,K$14<=$D15),$E15,0) -> 0 | L15: =IF(AND(L$14>=$C15,L$14<=$D15),$E15,0) -> 0 | M15: =IF(AND(M$14>=$C15,M$14<=$D15),$E15,0) -> 0 | N15: =IF(AND(N$14>=$C15,N$14<=$D15),$E15,0) -> 0 | O15: =IF(AND(O$14>=$C15,O$14<=$D15),$E15,0) -> 0 | ... S15: =IF(AND(S$14>=$C15,S$14<=$D15),$E15,0) -> 0
C16: 1 | D16: 1.1999 | E16: 1500 | H16: =IF(AND(H$14>=$C16,H$14<=$D16),$E16,0) -> 0 | I16: =IF(AND(I$14>=$C16,I$14<=$D16),$E16,0) -> 0 | J16: =IF(AND(J$14>=$C16,J$14<=$D16),$E16,0) -> 0 | K16: =IF(AND(K$14>=$C16,K$14<=$D16),$E16,0) -> 0 | L16: =IF(AND(L$14>=$C16,L$14<=$D16),$E16,0) -> 0 | M16: =IF(AND(M$14>=$C16,M$14<=$D16),$E16,0) -> 0 | N16: =IF(AND(N$14>=$C16,N$14<=$D16),$E16,0) -> 0 | O16: =IF(AND(O$14>=$C16,O$14<=$D16),$E16,0) -> 0 | ... S16: =IF(AND(S$14>=$C16,S$14<=$D16),$E16,0) -> 0
C17: 1.2 | D17: et plus | E17: 2500 | H17: =IF(AND(H$14>=$C17,H$14<=$D17),$E17,0) -> 2500 | I17: =IF(AND(I$14>=$C17,I$14<=$D17),$E17,0) -> 0 | J17: =IF(AND(J$14>=$C17,J$14<=$D17),$E17,0) -> 2500 | K17: =IF(AND(K$14>=$C17,K$14<=$D17),$E17,0) -> 2500 | L17: =IF(AND(L$14>=$C17,L$14<=$D17),$E17,0) -> 2500 | M17: =IF(AND(M$14>=$C17,M$14<=$D17),$E17,0) -> 2500 | N17: =IF(AND(N$14>=$C17,N$14<=$D17),$E17,0) -> 2500 | O17: =IF(AND(O$14>=$C17,O$14<=$D17),$E17,0) -> 2500 | ... S17: =IF(AND(S$14>=$C17,S$14<=$D17),$E17,0) -> 2500
G18: Payable | H18: =SUM(H15:H17) -> 2500 | I18: =SUM(I15:I17) -> 750 | J18: =SUM(J15:J17) -> 2500 | K18: =SUM(K15:K17) -> 2500 | L18: =SUM(L15:L17) -> 2500 | M18: =SUM(M15:M17) -> 2500 | N18: =SUM(N15:N17) -> 2500 | O18: =SUM(O15:O17) -> 2500 | ... S18: =SUM(S15:S17) -> 2500
B20: Objectifs de volumes vehicules neuf selon BPV | G20: Réalisé | H20: 58 | I20: 38 | J20: 53 | K20: 56 | L20: 0 | M20: 0 | N20: 0 | O20: 0 | P20: 0 | Q20: 0 | R20: 0 | S20: 0
G21: Cible | H21: 49 | I21: 53 | J21: 62 | K21: 56 | L21: 0 | M21: 0 | N21: 0 | O21: 0 | P21: 0 | Q21: 0 | R21: 0 | S21: 0
C22: de | D22: à | E22: Boni | G22: % | H22: 1.2 | I22: 0.9 | J22: =IFERROR(ROUND(J20/J21,3)," - - -") -> 0.855 | K22: =IFERROR(ROUND(K20/K21,3)," - - -") -> 1 | L22: =IFERROR(ROUND(L20/L21,3)," - - -") -> - - - | M22: =IFERROR(ROUND(M20/M21,3)," - - -") -> - - - | N22: =IFERROR(ROUND(N20/N21,3)," - - -") -> - - - | O22: =IFERROR(ROUND(O20/O21,3)," - - -") -> - - - | P22: =IFERROR(ROUND(P20/P21,3)," - - -") -> - - - | Q22: =IFERROR(ROUND(Q20/Q21,3)," - - -") -> - - - | ... S22: =IFERROR(ROUND(S20/S21,3)," - - -") -> - - -
C23: 0.9 | D23: 0.9999 | E23: 450 | H23: =IF(AND(H$22>=$C23,H$22<=$D23),$E23,0) -> 0 | I23: =IF(AND(I$22>=$C23,I$22<=$D23),$E23,0) -> 450 | J23: =IF(AND(J$22>=$C23,J$22<=$D23),$E23,0) -> 0 | K23: =IF(AND(K$22>=$C23,K$22<=$D23),$E23,0) -> 0 | L23: =IF(AND(L$22>=$C23,L$22<=$D23),$E23,0) -> 0 | M23: =IF(AND(M$22>=$C23,M$22<=$D23),$E23,0) -> 0 | N23: =IF(AND(N$22>=$C23,N$22<=$D23),$E23,0) -> 0 | O23: =IF(AND(O$22>=$C23,O$22<=$D23),$E23,0) -> 0 | ... S23: =IF(AND(S$22>=$C23,S$22<=$D23),$E23,0) -> 0
C24: 1 | D24: 1.1999 | E24: 750 | H24: =IF(AND(H$22>=$C24,H$22<=$D24),$E24,0) -> 0 | I24: =IF(AND(I$22>=$C24,I$22<=$D24),$E24,0) -> 0 | J24: =IF(AND(J$22>=$C24,J$22<=$D24),$E24,0) -> 0 | K24: =IF(AND(K$22>=$C24,K$22<=$D24),$E24,0) -> 750 | L24: =IF(AND(L$22>=$C24,L$22<=$D24),$E24,0) -> 0 | M24: =IF(AND(M$22>=$C24,M$22<=$D24),$E24,0) -> 0 | N24: =IF(AND(N$22>=$C24,N$22<=$D24),$E24,0) -> 0 | O24: =IF(AND(O$22>=$C24,O$22<=$D24),$E24,0) -> 0 | ... S24: =IF(AND(S$22>=$C24,S$22<=$D24),$E24,0) -> 0
C25: 1.2 | D25: et plus | E25: 1250 | H25: =IF(AND(H$22>=$C25,H$22<=$D25),$E25,0) -> 1250 | I25: =IF(AND(I$22>=$C25,I$22<=$D25),$E25,0) -> 0 | J25: =IF(AND(J$22>=$C25,J$22<=$D25),$E25,0) -> 0 | K25: =IF(AND(K$22>=$C25,K$22<=$D25),$E25,0) -> 0 | L25: =IF(AND(L$22>=$C25,L$22<=$D25),$E25,0) -> 1250 | M25: =IF(AND(M$22>=$C25,M$22<=$D25),$E25,0) -> 1250 | N25: =IF(AND(N$22>=$C25,N$22<=$D25),$E25,0) -> 1250 | O25: =IF(AND(O$22>=$C25,O$22<=$D25),$E25,0) -> 1250 | ... S25: =IF(AND(S$22>=$C25,S$22<=$D25),$E25,0) -> 1250
G26: Payable | H26: =SUM(H23:H25) -> 1250 | I26: =SUM(I23:I25) -> 450 | J26: =SUM(J23:J25) -> 0 | K26: =SUM(K23:K25) -> 750 | L26: =SUM(L23:L25) -> 1250 | M26: =SUM(M23:M25) -> 1250 | N26: =SUM(N23:N25) -> 1250 | O26: =SUM(O23:O25) -> 1250 | ... S26: =SUM(S23:S25) -> 1250
B28: CSI ventes: Questions D2 / D4 / D5 | C28: de | D28: à | E28: Boni | H28: 0.875 | I28: 0.85 | J28: 0.83 | K28: 0.92 | L28: 0 | M28: 0 | N28: 0 | O28: 0 | P28: 0 | Q28: 0 | R28: 0 | S28: 0
C29: 0 | D29: 0.7999 | E29: 0 | H29: =IF(AND(H28>=$C29,H28<=$D29),$E29,0) -> 0 | I29: =IF(AND(I28>=$C29,I28<=$D29),$E29,0) -> 0 | J29: =IF(AND(J28>=$C29,J28<=$D29),$E29,0) -> 0 | K29: =IF(AND(K28>=$C29,K28<=$D29),$E29,0) -> 0 | L29: =IF(AND(L28>=$C29,L28<=$D29),$E29,0) -> 0 | M29: =IF(AND(M28>=$C29,M28<=$D29),$E29,0) -> 0 | N29: =IF(AND(N28>=$C29,N28<=$D29),$E29,0) -> 0 | O29: =IF(AND(O28>=$C29,O28<=$D29),$E29,0) -> 0 | ... S29: =IF(AND(S28>=$C29,S28<=$D29),$E29,0) -> 0
C30: 0.8 | D30: 0.8999 | E30: 500 | H30: =IF(AND(H28>=$C30,H28<=$D30),$E30,0) -> 500 | I30: =IF(AND(I28>=$C30,I28<=$D30),$E30,0) -> 500 | J30: =IF(AND(J28>=$C30,J28<=$D30),$E30,0) -> 500 | K30: =IF(AND(K28>=$C30,K28<=$D30),$E30,0) -> 0 | L30: =IF(AND(L28>=$C30,L28<=$D30),$E30,0) -> 0 | M30: =IF(AND(M28>=$C30,M28<=$D30),$E30,0) -> 0 | N30: =IF(AND(N28>=$C30,N28<=$D30),$E30,0) -> 0 | O30: =IF(AND(O28>=$C30,O28<=$D30),$E30,0) -> 0 | ... S30: =IF(AND(S28>=$C30,S28<=$D30),$E30,0) -> 0
C31: 0.9 | D31: et plus | E31: 1000 | H31: =IF(AND(H28>=$C31,H28<=$D31),$E31,0) -> 0 | I31: =IF(AND(I28>=$C31,I28<=$D31),$E31,0) -> 0 | J31: =IF(AND(J28>=$C31,J28<=$D31),$E31,0) -> 0 | K31: =IF(AND(K28>=$C31,K28<=$D31),$E31,0) -> 1000 | L31: =IF(AND(L28>=$C31,L28<=$D31),$E31,0) -> 0 | M31: =IF(AND(M28>=$C31,M28<=$D31),$E31,0) -> 0 | N31: =IF(AND(N28>=$C31,N28<=$D31),$E31,0) -> 0 | O31: =IF(AND(O28>=$C31,O28<=$D31),$E31,0) -> 0 | ... S31: =IF(AND(S28>=$C31,S28<=$D31),$E31,0) -> 0
G32: Payable | H32: =SUM(H29:H31) -> 500 | I32: =SUM(I29:I31) -> 500 | J32: =SUM(J29:J31) -> 500 | K32: =SUM(K29:K31) -> 1000 | L32: =SUM(L29:L31) -> 0 | M32: =SUM(M29:M31) -> 0 | N32: =SUM(N29:N31) -> 0 | O32: =SUM(O29:O31) -> 0 | ... S32: =SUM(S29:S31) -> 0
G34: Rattrapage | J34: 1750
G36: Total Mensuel | H36: =+H10+H32+H26+H18 -> 6750 | I36: =+I10+I32+I26+I18 -> 2450 | J36: =+J10+J32+J26+J18+J34 -> 7250 | K36: =+K10+K32+K26+K18 -> 4250 | L36: =+L10+L32+L26+L18 -> 6250 | M36: =+M10+M32+M26+M18 -> 6250 | N36: =+N10+N32+N26+N18 -> 6250 | O36: =+O10+O32+O26+O18 -> 6250 | P36: =+P10+P32+P26+P18 -> 6250 | Q36: =+Q10+Q32+Q26+Q18 -> 6250 | R36: =+R10+R32+R26+R18 -> 6250 | S36: =+S10+S32+S26+S18 -> 6250
B38: Bonis Annuels
B39: Classement de la concession au Wolfsburg 2025 | G39: Réalisé
C40: de | D40: à | E40: Boni
C41: 1 | D41: 5 | E41: 10000 | S41: =IF(AND(S$39>=$C41,S$39<=$D41),$E41,0) -> 0
C42: 6 | D42: 10 | E42: 5000 | S42: =IF(AND(S$39>=$C42,S$39<=$D42),$E42,0) -> 0
C43: 11 | D43: 15 | E43: 2500 | S43: =IF(AND(S$39>=$C43,S$39<=$D43),$E43,0) -> 0
G44: Payable | S44: =SUM(S41:S43) -> 0
G46: Total Payable | S46: =+S36+S44 -> 6250

Sheet Karim Noori 2024
B1: Karim Noori - Directeur Adjoint Desk Manager
B3: Bonis Mensuels | H3: 45322 | I3: 45350 | J3: 45378 | K3: 45406 | L3: 45434 | M3: 45462 | N3: 45490 | O3: 45518 | P3: 45546 | Q3: 45574 | R3: 45602 | S3: 45630
B4: Profit brut départemental NEUF | G4: Réalisé | H4: 142187 | I4: 249483 | J4: 281559.36 | K4: ='Kaven Bonneau 2024'!K4 -> 259605 | L4: 235625 | M4: 124974 | N4: ='Kaven Bonneau v2 2024'!N4 -> 254171 | O4: 260155 | P4: =#REF! -> #REF! | Q4: =#REF! -> #REF! | R4: =#REF! -> #REF! | S4: =#REF! -> #REF! | U4: L27
B5: vs le Budget 2024 | G5: Cible | H5: 144386 | I5: 144386 | J5: 202140.81 | K5: ='Kaven Bonneau 2024'!K5 -> 288903 | L5: 331750 | M5: 259687 | N5: ='Kaven Bonneau v2 2024'!N5 -> 231018 | O5: 260155 | P5: =#REF! -> #REF! | Q5: =#REF! -> #REF! | R5: =#REF! -> #REF! | S5: =#REF! -> #REF! | U5: F27
C6: de | D6: à | E6: Boni | G6: % | H6: =IFERROR(ROUND(H4/H5,3)," - - -") -> 0.985 | I6: =IFERROR(ROUND(I4/I5,3)," - - -") -> 1.728 | J6: =IFERROR(ROUND(J4/J5,3)," - - -") -> 1.393 | K6: =IFERROR(ROUND(K4/K5,3)," - - -") -> 0.899 | L6: =IFERROR(ROUND(L4/L5,3)," - - -") -> 0.71 | M6: =IFERROR(ROUND(M4/M5,3)," - - -") -> 0.481 | N6: =IFERROR(ROUND(N4/N5,3)," - - -") -> 1.1 | O6: =IFERROR(ROUND(O4/O5,3)," - - -") -> 1 | P6: =IFERROR(ROUND(P4/P5,3)," - - -") -> - - - | Q6: 0.9 | R6: =IFERROR(ROUND(R4/R5,3)," - - -") -> - - - | S6: =IFERROR(ROUND(S4/S5,3)," - - -") -> - - -
C7: 0.85 | D7: 0.9999 | E7: 500 | H7: =IF(AND(H$6>=$C7,H$6<=$D7),$E7,0) -> 500 | I7: =IF(AND(I$6>=$C7,I$6<=$D7),$E7,0) -> 0 | J7: =IF(AND(J$6>=$C7,J$6<=$D7),$E7,0) -> 0 | K7: =IF(AND(K$6>=$C7,K$6<=$D7),$E7,0) -> 500 | L7: =IF(AND(L$6>=$C7,L$6<=$D7),$E7,0) -> 0 | M7: =IF(AND(M$6>=$C7,M$6<=$D7),$E7,0) -> 0 | N7: =IF(AND(N$6>=$C7,N$6<=$D7),$E7,0) -> 0 | O7: =IF(AND(O$6>=$C7,O$6<=$D7),$E7,0) -> 0 | ... S7: =IF(AND(S$6>=$C7,S$6<=$D7),$E7,0) -> 0
C8: 1 | D8: 1.0999 | E8: 1500 | H8: =IF(AND(H$6>=$C8,H$6<=$D8),$E8,0) -> 0 | I8: =IF(AND(I$6>=$C8,I$6<=$D8),$E8,0) -> 0 | J8: =IF(AND(J$6>=$C8,J$6<=$D8),$E8,0) -> 0 | K8: =IF(AND(K$6>=$C8,K$6<=$D8),$E8,0) -> 0 | L8: =IF(AND(L$6>=$C8,L$6<=$D8),$E8,0) -> 0 | M8: =IF(AND(M$6>=$C8,M$6<=$D8),$E8,0) -> 0 | N8: =IF(AND(N$6>=$C8,N$6<=$D8),$E8,0) -> 0 | O8: =IF(AND(O$6>=$C8,O$6<=$D8),$E8,0) -> 1500 | ... S8: =IF(AND(S$6>=$C8,S$6<=$D8),$E8,0) -> 0
C9: 1.1 | D9: et plus | E9: 2000 | H9: =IF(AND(H$6>=$C9,H$6<=$D9),$E9,0) -> 0 | I9: =IF(AND(I$6>=$C9,I$6<=$D9),$E9,0) -> 2000 | J9: =IF(AND(J$6>=$C9,J$6<=$D9),$E9,0) -> 2000 | K9: =IF(AND(K$6>=$C9,K$6<=$D9),$E9,0) -> 0 | L9: =IF(AND(L$6>=$C9,L$6<=$D9),$E9,0) -> 0 | M9: =IF(AND(M$6>=$C9,M$6<=$D9),$E9,0) -> 0 | N9: =IF(AND(N$6>=$C9,N$6<=$D9),$E9,0) -> 2000 | O9: =IF(AND(O$6>=$C9,O$6<=$D9),$E9,0) -> 0 | ... S9: =IF(AND(S$6>=$C9,S$6<=$D9),$E9,0) -> 2000
G10: Payable | H10: =SUM(H7:H9) -> 500 | I10: =SUM(I7:I9) -> 2000 | J10: =SUM(J7:J9) -> 2000 | K10: =SUM(K7:K9) -> 500 | L10: =SUM(L7:L9) -> 0 | M10: =SUM(M7:M9) -> 0 | N10: =SUM(N7:N9) -> 2000 | O10: =SUM(O7:O9) -> 1500 | ... S10: =SUM(S7:S9) -> 2000
B12: Atteinte du volume mensuel neuf au budget | G12: Réalisé | H12: 46 | I12: 75 | J12: 74 | K12: 73 | L12: 74 | M12: 40 | N12: 85 | O12: 89 | P12: =#REF! -> #REF! | Q12: =#REF! -> #REF! | R12: =#REF! -> #REF! | S12: =#REF! -> #REF! | U12: L27
B13: vs le Budget 2024 | G13: Cible | H13: 36 | I13: 36 | J13: 46.83 | K13: 72 | L13: 82 | M13: 64 | N13: 57 | O13: 64 | P13: =#REF! -> #REF! | Q13: =#REF! -> #REF! | R13: =#REF! -> #REF! | S13: =#REF! -> #REF! | U13: F27
C14: de | D14: à | E14: Boni | G14: % | H14: =IFERROR(ROUND(H12/H13,3)," - - -") -> 1.278 | I14: =IFERROR(ROUND(I12/I13,3)," - - -") -> 2.083 | J14: =IFERROR(ROUND(J12/J13,3)," - - -") -> 1.58 | K14: =IFERROR(ROUND(K12/K13,3)," - - -") -> 1.014 | L14: =IFERROR(ROUND(L12/L13,3)," - - -") -> 0.902 | M14: =IFERROR(ROUND(M12/M13,3)," - - -") -> 0.625 | N14: =IFERROR(ROUND(N12/N13,3)," - - -") -> 1.491 | O14: =IFERROR(ROUND(O12/O13,3)," - - -") -> 1.391 | P14: =IFERROR(ROUND(P12/P13,3)," - - -") -> - - - | Q14: 0.9 | R14: =IFERROR(ROUND(R12/R13,3)," - - -") -> - - - | S14: =IFERROR(ROUND(S12/S13,3)," - - -") -> - - -
C15: 0.85 | D15: 0.9999 | E15: 500 | H15: =IF(AND(H$14>=$C15,H$14<=$D15),$E15,0) -> 0 | I15: =IF(AND(I$14>=$C15,I$14<=$D15),$E15,0) -> 0 | J15: =IF(AND(J$14>=$C15,J$14<=$D15),$E15,0) -> 0 | K15: =IF(AND(K$14>=$C15,K$14<=$D15),$E15,0) -> 0 | L15: =IF(AND(L$14>=$C15,L$14<=$D15),$E15,0) -> 500 | M15: =IF(AND(M$14>=$C15,M$14<=$D15),$E15,0) -> 0 | N15: =IF(AND(N$14>=$C15,N$14<=$D15),$E15,0) -> 0 | O15: =IF(AND(O$14>=$C15,O$14<=$D15),$E15,0) -> 0 | ... S15: =IF(AND(S$14>=$C15,S$14<=$D15),$E15,0) -> 0
C16: 1 | D16: 1.0999 | E16: 1500 | H16: =IF(AND(H$14>=$C16,H$14<=$D16),$E16,0) -> 0 | I16: =IF(AND(I$14>=$C16,I$14<=$D16),$E16,0) -> 0 | J16: =IF(AND(J$14>=$C16,J$14<=$D16),$E16,0) -> 0 | K16: =IF(AND(K$14>=$C16,K$14<=$D16),$E16,0) -> 1500 | L16: =IF(AND(L$14>=$C16,L$14<=$D16),$E16,0) -> 0 | M16: =IF(AND(M$14>=$C16,M$14<=$D16),$E16,0) -> 0 | N16: =IF(AND(N$14>=$C16,N$14<=$D16),$E16,0) -> 0 | O16: =IF(AND(O$14>=$C16,O$14<=$D16),$E16,0) -> 0 | ... S16: =IF(AND(S$14>=$C16,S$14<=$D16),$E16,0) -> 0
C17: 1.1 | D17: et plus | E17: 2000 | H17: =IF(AND(H$14>=$C17,H$14<=$D17),$E17,0) -> 2000 | I17: =IF(AND(I$14>=$C17,I$14<=$D17),$E17,0) -> 2000 | J17: =IF(AND(J$14>=$C17,J$14<=$D17),$E17,0) -> 2000 | K17: =IF(AND(K$14>=$C17,K$14<=$D17),$E17,0) -> 0 | L17: =IF(AND(L$14>=$C17,L$14<=$D17),$E17,0) -> 0 | M17: =IF(AND(M$14>=$C17,M$14<=$D17),$E17,0) -> 0 | N17: =IF(AND(N$14>=$C17,N$14<=$D17),$E17,0) -> 2000 | O17: =IF(AND(O$14>=$C17,O$14<=$D17),$E17,0) -> 2000 | ... S17: =IF(AND(S$14>=$C17,S$14<=$D17),$E17,0) -> 2000
G18: Payable | H18: =SUM(H15:H17) -> 2000 | I18: =SUM(I15:I17) -> 2000 | J18: =SUM(J15:J17) -> 2000 | K18: =SUM(K15:K17) -> 1500 | L18: =SUM(L15:L17) -> 500 | M18: =SUM(M15:M17) -> 0 | N18: =SUM(N15:N17) -> 2000 | O18: =SUM(O15:O17) -> 2000 | ... S18: =SUM(S15:S17) -> 2000
B20: Atteinte des Indicateurs Expérience + ( X de 3 ) | G20: Réalisé | H20: 2 | I20: 3 | J20: 2 | K20: 3 | L20: 2 | M20: 3 | N20: 2 | O20: 2 | P20: =#REF! -> #REF! | Q20: =#REF! -> #REF! | R20: =#REF! -> #REF! | S20: 2
B21: - Closing +de 55% - Renouvellement +de 59% - Look to book neuf +de 40%. | G21: Cible | H21: 3 | I21: 3 | J21: 3 | K21: 3 | L21: 3 | M21: 3 | N21: 3 | O21: 3 | P21: =#REF! -> #REF! | Q21: =#REF! -> #REF! | R21: =#REF! -> #REF! | S21: =#REF! -> #REF!
C22: de | D22: à | E22: Boni | G22: % | H22: =IFERROR(ROUND(H20/H21,3)," - - -") -> 0.667 | I22: =IFERROR(ROUND(I20/I21,3)," - - -") -> 1 | J22: =IFERROR(ROUND(J20/J21,3)," - - -") -> 0.667 | K22: =IFERROR(ROUND(K20/K21,3)," - - -") -> 1 | L22: =IFERROR(ROUND(L20/L21,3)," - - -") -> 0.667 | M22: =IFERROR(ROUND(M20/M21,3)," - - -") -> 1 | N22: =IFERROR(ROUND(N20/N21,3)," - - -") -> 0.667 | O22: =IFERROR(ROUND(O20/O21,3)," - - -") -> 0.667 | ... S22: =IFERROR(ROUND(S20/S21,3)," - - -") -> - - -
C23: 1 | D23: 1 | E23: 100 | H23: =IF(AND(H$20>=$C23,H$20<=$D23),$E23,0) -> 0 | I23: =IF(AND(I$20>=$C23,I$20<=$D23),$E23,0) -> 0 | J23: =IF(AND(J$20>=$C23,J$20<=$D23),$E23,0) -> 0 | K23: =IF(AND(K$20>=$C23,K$20<=$D23),$E23,0) -> 0 | L23: =IF(AND(L$20>=$C23,L$20<=$D23),$E23,0) -> 0 | M23: =IF(AND(M$20>=$C23,M$20<=$D23),$E23,0) -> 0 | N23: =IF(AND(N$20>=$C23,N$20<=$D23),$E23,0) -> 0 | O23: =IF(AND(O$20>=$C23,O$20<=$D23),$E23,0) -> 0 | ... S23: =IF(AND(S$20>=$C23,S$20<=$D23),$E23,0) -> 0
C24: 2 | D24: 2 | E24: 350 | H24: =IF(AND(H$20>=$C24,H$20<=$D24),$E24,0) -> 350 | I24: =IF(AND(I$20>=$C24,I$20<=$D24),$E24,0) -> 0 | J24: =IF(AND(J$20>=$C24,J$20<=$D24),$E24,0) -> 350 | K24: =IF(AND(K$20>=$C24,K$20<=$D24),$E24,0) -> 0 | L24: =IF(AND(L$20>=$C24,L$20<=$D24),$E24,0) -> 350 | M24: =IF(AND(M$20>=$C24,M$20<=$D24),$E24,0) -> 0 | N24: =IF(AND(N$20>=$C24,N$20<=$D24),$E24,0) -> 350 | O24: =IF(AND(O$20>=$C24,O$20<=$D24),$E24,0) -> 350 | ... S24: =IF(AND(S$20>=$C24,S$20<=$D24),$E24,0) -> 350
C25: 3 | D25: 3 | E25: 1000 | H25: =IF(AND(H$20>=$C25,H$20<=$D25),$E25,0) -> 0 | I25: =IF(AND(I$20>=$C25,I$20<=$D25),$E25,0) -> 1000 | J25: =IF(AND(J$20>=$C25,J$20<=$D25),$E25,0) -> 0 | K25: =IF(AND(K$20>=$C25,K$20<=$D25),$E25,0) -> 1000 | L25: =IF(AND(L$20>=$C25,L$20<=$D25),$E25,0) -> 0 | M25: =IF(AND(M$20>=$C25,M$20<=$D25),$E25,0) -> 1000 | N25: =IF(AND(N$20>=$C25,N$20<=$D25),$E25,0) -> 0 | O25: =IF(AND(O$20>=$C25,O$20<=$D25),$E25,0) -> 0 | ... S25: =IF(AND(S$20>=$C25,S$20<=$D25),$E25,0) -> 0
G26: Payable | H26: =SUM(H23:H25) -> 350 | I26: =SUM(I23:I25) -> 1000 | J26: =SUM(J23:J25) -> 350 | K26: =SUM(K23:K25) -> 1000 | L26: =SUM(L23:L25) -> 350 | M26: =SUM(M23:M25) -> 1000 | N26: =SUM(N23:N25) -> 350 | O26: =SUM(O23:O25) -> 350 | ... S26: =SUM(S23:S25) -> 350
B28: CSI ventes | C28: de | D28: à | E28: Boni | H28: 4.87 | I28: 5 | J28: 4.63 | K28: 4.81 | L28: 4.78 | M28: 4.61 | N28: 4.48 | O28: 4.93 | P28: =#REF! -> #REF! | Q28: =#REF! -> #REF! | R28: =#REF! -> #REF! | S28: 4.89
C29: 4.6 | D29: 4.85 | E29: 0 | H29: 4.87 | I29: =IF(AND(I28>=$C29,I28<=$D29),$E29,0) -> 0 | J29: =IF(AND(J28>=$C29,J28<=$D29),$E29,0) -> 0 | K29: =IF(AND(K28>=$C29,K28<=$D29),$E29,0) -> 0 | L29: =IF(AND(L28>=$C29,L28<=$D29),$E29,0) -> 0 | M29: =IF(AND(M28>=$C29,M28<=$D29),$E29,0) -> 0 | N29: =IF(AND(N28>=$C29,N28<=$D29),$E29,0) -> 0 | O29: =IF(AND(O28>=$C29,O28<=$D29),$E29,0) -> 0 | P29: =IF(AND(P28>=$C29,P28<=$D29),$E29,0) -> #REF! | ... S29: =IF(AND(S28>=$C29,S28<=$D29),$E29,0) -> 0
C30: 4.86 | D30: 4.94 | E30: 350 | H30: =IF(AND(H28>=$C30,H28<=$D30),$E30,0) -> 350 | I30: =IF(AND(I28>=$C30,I28<=$D30),$E30,0) -> 0 | J30: =IF(AND(J28>=$C30,J28<=$D30),$E30,0) -> 0 | K30: =IF(AND(K28>=$C30,K28<=$D30),$E30,0) -> 0 | L30: =IF(AND(L28>=$C30,L28<=$D30),$E30,0) -> 0 | M30: =IF(AND(M28>=$C30,M28<=$D30),$E30,0) -> 0 | N30: =IF(AND(N28>=$C30,N28<=$D30),$E30,0) -> 0 | O30: =IF(AND(O28>=$C30,O28<=$D30),$E30,0) -> 350 | ... S30: =IF(AND(S28>=$C30,S28<=$D30),$E30,0) -> 350
C31: 4.95 | D31: et plus | E31: 750 | H31: =IF(AND(H28>=$C31,H28<=$D31),$E31,0) -> 0 | I31: =IF(AND(I28>=$C31,I28<=$D31),$E31,0) -> 750 | J31: =IF(AND(J28>=$C31,J28<=$D31),$E31,0) -> 0 | K31: =IF(AND(K28>=$C31,K28<=$D31),$E31,0) -> 0 | L31: =IF(AND(L28>=$C31,L28<=$D31),$E31,0) -> 0 | M31: =IF(AND(M28>=$C31,M28<=$D31),$E31,0) -> 0 | N31: =IF(AND(N28>=$C31,N28<=$D31),$E31,0) -> 0 | O31: =IF(AND(O28>=$C31,O28<=$D31),$E31,0) -> 0 | ... S31: =IF(AND(S28>=$C31,S28<=$D31),$E31,0) -> 0
G32: Payable | H32: =SUM(H29:H31) -> 354.87 | I32: =SUM(I29:I31) -> 750 | J32: =SUM(J29:J31) -> 0 | K32: =SUM(K29:K31) -> 0 | L32: =SUM(L29:L31) -> 0 | M32: =SUM(M29:M31) -> 0 | N32: =SUM(N29:N31) -> 0 | O32: =SUM(O29:O31) -> 350 | ... S32: =SUM(S29:S31) -> 350
J34: 520 | K34: 480 | L34: 410 | M34: 200 | N34: 1400 | R34: 773.72
G36: Total Mensuel | H36: =+H10+H32+H26+H18 -> 3204.87 | I36: =+I10+I32+I26+I18+I34 -> 5750 | J36: =+J10+J32+J26+J18+J34 -> 4870 | K36: =+K10+K32+K26+K18+K34 -> 3480 | L36: =+L10+L32+L26+L18+L34 -> 1260 | M36: =+M10+M32+M26+M18+M34 -> 1200 | N36: =+N10+N32+N26+N18+N34 -> 5750 | O36: =+O10+O32+O26+O18+O34 -> 4200 | P36: =+P10+P32+P26+P18+P34 -> #REF! | ... S36: =+S10+S32+S26+S18+S34 -> 4700
B38: Bonis Trimestriels
B39: Atteinte des Indicateurs Expérience + ( X de 3 ) | G39: Réalisé | J39: 2 | M39: 2 | P39: =#REF! -> #REF! | S39: =#REF! -> #REF!
B40: CSI + de 4,9 CarNet + de 90% Voksklick: sup 20 jours par mois | G40: Cible | J40: 3 | M40: 3 | P40: =#REF! -> #REF! | S40: =#REF! -> #REF!
C41: de | D41: à | E41: Boni
C42: 1 | D42: 1 | E42: 500 | J42: =IF(AND(J$39>=$C42,J$39<=$D42),$E42,0) -> 0 | M42: =IF(AND(M$39>=$C42,M$39<=$D42),$E42,0) -> 0 | P42: =IF(AND(P$39>=$C42,P$39<=$D42),$E42,0) -> #REF! | S42: =IF(AND(S$39>=$C42,S$39<=$D42),$E42,0) -> #REF!
C43: 2 | D43: 2 | E43: 1000 | J43: =IF(AND(J$39>=$C43,J$39<=$D43),$E43,0) -> 1000 | M43: =IF(AND(M$39>=$C43,M$39<=$D43),$E43,0) -> 1000 | P43: =IF(AND(P$39>=$C43,P$39<=$D43),$E43,0) -> #REF! | S43: =IF(AND(S$39>=$C43,S$39<=$D43),$E43,0) -> #REF!
C44: 3 | D44: 3 | E44: 2500 | J44: =IF(AND(J$39>=$C44,J$39<=$D44),$E44,0) -> 0 | M44: =IF(AND(M$39>=$C44,M$39<=$D44),$E44,0) -> 0 | P44: =IF(AND(P$39>=$C44,P$39<=$D44),$E44,0) -> #REF! | S44: =IF(AND(S$39>=$C44,S$39<=$D44),$E44,0) -> #REF!
G45: Payable | J45: =SUM(J42:J44) -> 1000 | M45: =SUM(M42:M44) -> 1000 | P45: =SUM(P42:P44) -> #REF! | S45: =SUM(S42:S44) -> #REF!
G47: Total Payable | J47: =+J36+J45 -> 5870 | M47: =+M36+M45 -> 2200 | P47: =+P36+P45 -> #REF! | S47: =+S36+S45 -> #REF!

Sheet Alexandre Paradis 2025
B1: Alexandre Paradis - Directeur Adjoint Ventes Neuf
B3: Bonis Mensuels | H3: 45688 | I3: 45716 | J3: 45747 | K3: 45777 | L3: 45808 | M3: 45838 | N3: 45869 | O3: 45900 | P3: 45930 | Q3: 45961 | R3: 45991 | S3: 46022
B4: Profit brut départemental NEUF | G4: Réalisé | H4: 190802 | I4: 136011 | J4: 155475
B5: vs le Budget 2025 | G5: Cible | H5: 204136 | I5: 187694 | J5: 178463
C6: de | D6: à | E6: Boni | G6: % | H6: =IFERROR(ROUND(H4/H5,3)," - - -") -> 0.935 | I6: =IFERROR(ROUND(I4/I5,3)," - - -") -> 0.725 | J6: =IFERROR(ROUND(J4/J5,3)," - - -") -> 0.871
C7: 0.85 | D7: 0.9999 | E7: 750 | H7: =IF(AND(H$6>=$C7,H$6<=$D7),$E7,0) -> 750 | I7: =IF(AND(I$6>=$C7,I$6<=$D7),$E7,0) -> 0 | J7: =IF(AND(J$6>=$C7,J$6<=$D7),$E7,0) -> 750
C8: 1 | D8: 1.0999 | E8: 1500 | H8: =IF(AND(H$6>=$C8,H$6<=$D8),$E8,0) -> 0 | I8: =IF(AND(I$6>=$C8,I$6<=$D8),$E8,0) -> 0 | J8: =IF(AND(J$6>=$C8,J$6<=$D8),$E8,0) -> 0
C9: 1.1 | D9: et plus | E9: 2000 | H9: =IF(AND(H$6>=$C9,H$6<=$D9),$E9,0) -> 0 | I9: =IF(AND(I$6>=$C9,I$6<=$D9),$E9,0) -> 0 | J9: =IF(AND(J$6>=$C9,J$6<=$D9),$E9,0) -> 0
G10: Payable | H10: =SUM(H7:H9) -> 750 | I10: =SUM(I7:I9) -> 0 | J10: =SUM(J7:J9) -> 750
B12: Atteinte de l'objectif mensuel de volume BPV OEM | G12: Réalisé | H12: ='Sebastien Fleury 2025'!H20 -> 58 | I12: 38 | J12: ='Sebastien Fleury 2025'!J20 -> 53
G13: Cible | H13: ='Sebastien Fleury 2025'!H21 -> 49 | I13: 53 | J13: ='Sebastien Fleury 2025'!J21 -> 62
C14: de | D14: à | E14: Boni | G14: % | H14: =IFERROR(ROUND(H12/H13,3)," - - -") -> 1.184 | I14: =IFERROR(ROUND(I12/I13,3)," - - -") -> 0.717 | J14: =IFERROR(ROUND(J12/J13,3)," - - -") -> 0.855
C15: 0.9 | D15: 0.9999 | E15: 500 | H15: =IF(AND(H14>=$C15,H14<=$D15),$E15,0) -> 0 | I15: =IF(AND(I14>=$C15,I14<=$D15),$E15,0) -> 0 | J15: =IF(AND(J14>=$C15,J14<=$D15),$E15,0) -> 0
C16: 1 | D16: 1.0999 | E16: 1000 | H16: =IF(AND(H13>=$C16,H13<=$D16),$E16,0) -> 0 | I16: =IF(AND(I13>=$C16,I13<=$D16),$E16,0) -> 0 | J16: =IF(AND(J13>=$C16,J13<=$D16),$E16,0) -> 0
C17: 1.1 | D17: et plus | E17: 1750 | H17: =IF(AND(H14>=$C17,H14<=$D17),$E17,0) -> 1750 | I17: =IF(AND(I14>=$C17,I14<=$D17),$E17,0) -> 0 | J17: =IF(AND(J14>=$C17,J14<=$D17),$E17,0) -> 0
G18: Payable | H18: =SUM(H15:H17) -> 1750 | I18: =SUM(I15:I17) -> 0 | J18: =SUM(J15:J17) -> 0
B20: Turn rate (mois d'avant) | H20: 0.45 | I20: 0.406 | J20: 0.4
C21: de | D21: à | E21: Boni
C22: 0.35 | D22: 0.39 | E22: 500 | H22: =IF(AND(H20>=$C22,H20<=$D22),$E22,0) -> 0 | I22: =IF(AND(I20>=$C22,I20<=$D22),$E22,0) -> 0 | J22: =IF(AND(J20>=$C22,J20<=$D22),$E22,0) -> 0 | U22: id4 _ tiguan stop sale
C23: 0.3901 | D23: 0.47 | E23: 1000 | H23: =IF(AND(H20>=$C23,H20<=$D23),$E23,0) -> 1000 | I23: =IF(AND(I20>=$C23,I20<=$D23),$E23,0) -> 1000 | J23: =IF(AND(J20>=$C23,J20<=$D23),$E23,0) -> 1000
C24: 0.4701 | D24: et plus | E24: 1500 | H24: =IF(AND(H20>=$C24,H20<=$D24),$E24,0) -> 0 | I24: =IF(AND(I20>=$C24,I20<=$D24),$E24,0) -> 0 | J24: =IF(AND(J20>=$C24,J20<=$D24),$E24,0) -> 0
G25: Payable | H25: =SUM(H22:H24) -> 1000 | I25: =SUM(I22:I24) -> 1000 | J25: =SUM(J22:J24) -> 1000
B27: CSI: Moyenne Questions D2 / D4 / D5 | G27: % | H27: 0.88 | I27: 0.85 | J27: 0.85
C28: de | D28: à | E28: Boni
C29: 0 | D29: 0.7999 | E29: 0 | H29: =IF(AND(H27>=$C29,H27<=$D29),$E29,0) -> 0 | I29: =IF(AND(I27>=$C29,I27<=$D29),$E29,0) -> 0 | J29: =IF(AND(J27>=$C29,J27<=$D29),$E29,0) -> 0
C30: 0.8 | D30: 0.8899 | E30: 500 | H30: =IF(AND(H27>=$C30,H27<=$D30),$E30,0) -> 500 | I30: =IF(AND(I27>=$C30,I27<=$D30),$E30,0) -> 500 | J30: =IF(AND(J27>=$C30,J27<=$D30),$E30,0) -> 500
C31: 0.89 | D31: et plus | E31: 1000 | H31: =IF(AND(H27>=$C31,H27<=$D31),$E31,0) -> 0 | I31: =IF(AND(I27>=$C31,I27<=$D31),$E31,0) -> 0 | J31: =IF(AND(J27>=$C31,J27<=$D31),$E31,0) -> 0
G32: Payable | H32: =SUM(H29:H31) -> 500 | I32: =SUM(I29:I31) -> 500 | J32: =SUM(J29:J31) -> 500
G34: Rattrapge | J34: 1000
G36: Total Mensuel | H36: =H10+H18+H25+H32 -> 4000 | I36: =I10+I18+I25+I32 -> 1500 | J36: =J10+J18+J25+J32+J34 -> 3250 | K36: =K10+K18+K25+K32 -> 0 | L36: =L10+L18+L25+L32 -> 0 | M36: =M10+M18+M25+M32 -> 0 | N36: =N10+N18+N25+N32 -> 0 | O36: =O10+O18+O25+O32 -> 0 | P36: =P10+P18+P25+P32 -> 0 | Q36: =Q10+Q18+Q25+Q32 -> 0 | R36: =R10+R18+R25+R32 -> 0 | S36: =S10+S18+S25+S32 -> 0
B39: Bonis Annuels
B40: Classement de la concession au Wolfsburg 2025 | G40: Réalisé
C41: de | D41: à | E41: Boni
C42: 1 | D42: 10 | E42: 5000 | S42: =IF(AND(S$40>=$C42,S$40<=$D42),$E42,0) -> 0
C43: 11 | D43: 15 | E43: 2500 | S43: =IF(AND(S$40>=$C43,S$40<=$D43),$E43,0) -> 0
C44: 16 | D44: 20 | E44: 500 | S44: =IF(AND(S$40>=$C44,S$40<=$D44),$E44,0) -> 0
G45: Payable | S45: =SUM(S42:S44) -> 0
G47: Total Payable | S47: =+S37+S45 -> 0

Sheet Alexandre Paradis 2025 v2
B1: Alexandre Paradis - Directeur Adjoint Ventes Neuf
B3: Bonis Mensuels | H3: 45688 | I3: 45716 | J3: 45747 | K3: 45777 | L3: 45808 | M3: 45838 | N3: 45869 | O3: 45900 | P3: 45930 | Q3: 45961 | R3: 45991 | S3: 46022
B4: Profit brut départemental NEUF | G4: Réalisé | K4: 192162 | L4: 155475 | M4: 155475 | N4: 155475 | O4: 155475 | P4: 155475 | Q4: 155475 | R4: 155475 | S4: 155475
B5: vs le Budget 2025 | G5: Cible | K5: 207380 | L5: 178463 | M5: 178463 | N5: 178463 | O5: 178463 | P5: 178463 | Q5: 178463 | R5: 178463 | S5: 178463
C6: de | D6: à | E6: Boni | G6: % | K6: =IFERROR(ROUND(K4/K5,3)," - - -") -> 0.927 | L6: =IFERROR(ROUND(L4/L5,3)," - - -") -> 0.871 | M6: =IFERROR(ROUND(M4/M5,3)," - - -") -> 0.871 | N6: =IFERROR(ROUND(N4/N5,3)," - - -") -> 0.871 | O6: =IFERROR(ROUND(O4/O5,3)," - - -") -> 0.871 | P6: =IFERROR(ROUND(P4/P5,3)," - - -") -> 0.871 | Q6: =IFERROR(ROUND(Q4/Q5,3)," - - -") -> 0.871 | R6: =IFERROR(ROUND(R4/R5,3)," - - -") -> 0.871 | S6: =IFERROR(ROUND(S4/S5,3)," - - -") -> 0.871
C7: 0.85 | D7: 0.9999 | E7: 500 | K7: =IF(AND(K$6>=$C7,K$6<=$D7),$E7,0) -> 500 | L7: =IF(AND(L$6>=$C7,L$6<=$D7),$E7,0) -> 500 | M7: =IF(AND(M$6>=$C7,M$6<=$D7),$E7,0) -> 500 | N7: =IF(AND(N$6>=$C7,N$6<=$D7),$E7,0) -> 500 | O7: =IF(AND(O$6>=$C7,O$6<=$D7),$E7,0) -> 500 | P7: =IF(AND(P$6>=$C7,P$6<=$D7),$E7,0) -> 500 | Q7: =IF(AND(Q$6>=$C7,Q$6<=$D7),$E7,0) -> 500 | R7: =IF(AND(R$6>=$C7,R$6<=$D7),$E7,0) -> 500 | S7: =IF(AND(S$6>=$C7,S$6<=$D7),$E7,0) -> 500
C8: 1 | D8: 1.0999 | E8: 1000 | K8: =IF(AND(K$6>=$C8,K$6<=$D8),$E8,0) -> 0 | L8: =IF(AND(L$6>=$C8,L$6<=$D8),$E8,0) -> 0 | M8: =IF(AND(M$6>=$C8,M$6<=$D8),$E8,0) -> 0 | N8: =IF(AND(N$6>=$C8,N$6<=$D8),$E8,0) -> 0 | O8: =IF(AND(O$6>=$C8,O$6<=$D8),$E8,0) -> 0 | P8: =IF(AND(P$6>=$C8,P$6<=$D8),$E8,0) -> 0 | Q8: =IF(AND(Q$6>=$C8,Q$6<=$D8),$E8,0) -> 0 | R8: =IF(AND(R$6>=$C8,R$6<=$D8),$E8,0) -> 0 | S8: =IF(AND(S$6>=$C8,S$6<=$D8),$E8,0) -> 0
C9: 1.1 | D9: et plus | E9: 1500 | K9: =IF(AND(K$6>=$C9,K$6<=$D9),$E9,0) -> 0 | L9: =IF(AND(L$6>=$C9,L$6<=$D9),$E9,0) -> 0 | M9: =IF(AND(M$6>=$C9,M$6<=$D9),$E9,0) -> 0 | N9: =IF(AND(N$6>=$C9,N$6<=$D9),$E9,0) -> 0 | O9: =IF(AND(O$6>=$C9,O$6<=$D9),$E9,0) -> 0 | P9: =IF(AND(P$6>=$C9,P$6<=$D9),$E9,0) -> 0 | Q9: =IF(AND(Q$6>=$C9,Q$6<=$D9),$E9,0) -> 0 | R9: =IF(AND(R$6>=$C9,R$6<=$D9),$E9,0) -> 0 | S9: =IF(AND(S$6>=$C9,S$6<=$D9),$E9,0) -> 0
G10: Payable | K10: =SUM(K7:K9) -> 500 | L10: =SUM(L7:L9) -> 500 | M10: =SUM(M7:M9) -> 500 | N10: =SUM(N7:N9) -> 500 | O10: =SUM(O7:O9) -> 500 | P10: =SUM(P7:P9) -> 500 | Q10: =SUM(Q7:Q9) -> 500 | R10: =SUM(R7:R9) -> 500 | S10: =SUM(S7:S9) -> 500
B12: Profit brut départemental USAGE | G12: Réalisé | K12: 115188 | L12: ='Sebastien Fleury 2025'!L20 -> 0 | M12: ='Sebastien Fleury 2025'!M20 -> 0 | N12: ='Sebastien Fleury 2025'!N20 -> 0 | O12: ='Sebastien Fleury 2025'!O20 -> 0 | P12: ='Sebastien Fleury 2025'!P20 -> 0 | Q12: ='Sebastien Fleury 2025'!Q20 -> 0 | R12: ='Sebastien Fleury 2025'!R20 -> 0 | S12: ='Sebastien Fleury 2025'!S20 -> 0
B13: vs le Budget 2025 | G13: Cible | K13: 109700 | L13: ='Sebastien Fleury 2025'!L21 -> 0 | M13: ='Sebastien Fleury 2025'!M21 -> 0 | N13: ='Sebastien Fleury 2025'!N21 -> 0 | O13: ='Sebastien Fleury 2025'!O21 -> 0 | P13: ='Sebastien Fleury 2025'!P21 -> 0 | Q13: ='Sebastien Fleury 2025'!Q21 -> 0 | R13: ='Sebastien Fleury 2025'!R21 -> 0 | S13: ='Sebastien Fleury 2025'!S21 -> 0
