Workbook
Name _Dates_Conc: [1]Dealers!$BF$37:$KA$63
Name _scen: '[1]Scen & Sens'!$E$26
Name _scen1: '[1]Scen & Sens'!$E$27
Name _scen2: '[1]Scen & Sens'!$E$28
Name _SCenarios: '[1]Scen & Sens'!$J$26:$O$26
Name _Sens1: '[1]Scen & Sens'!$F$9
Name _Sens2: '[1]Scen & Sens'!$F$10
Name _sensRes1: '[1]Scen & Sens'!$E$15
Name _sensRes2: '[1]Scen & Sens'!$E$16
Name _sensRes3: '[1]Scen & Sens'!$E$17
Name _sensRes4: '[1]Scen & Sens'!$E$18
Name _sensRes5: '[1]Scen & Sens'!$E$19
Name _sensRes6: '[1]Scen & Sens'!$E$20
Name _sensRes7: '[1]Scen & Sens'!$E$21
Name a: #REF!
Name a: #REF!
Name a: #REF!
Name a: #REF!
Name a: #REF!
Name a: #REF!
Name a: #REF!
Name a: #REF!
Name a: #REF!
Name a: #REF!
Name a: #REF!
Name a: #REF!
Name BLANK: #REF!
Name BLANK: #REF!
Name BLANK: #REF!
Name BLANK: #REF!
Name BLANK: #REF!
Name BLANK: #REF!
Name BLANK: #REF!
Name BLANK: #REF!
Name BLANK: #REF!
Name BLANK: #REF!
Name BLANK: #REF!
Name BLANK: #REF!
Name BROWN: #REF!
Name BROWN: #REF!
Name BROWN: #REF!
Name BROWN: #REF!
Name BROWN: #REF!
Name BROWN: #REF!
Name BROWN: #REF!
Name BROWN: #REF!
Name BROWN: #REF!
Name BROWN: #REF!
Name BROWN: #REF!
Name BROWN: #REF!
Name Compco1: #REF!
Name Compco1: #REF!
Name Compco1: #REF!
Name Compco1: #REF!
Name Compco1: #REF!
Name Compco1: #REF!
Name Compco1: #REF!
Name Compco1: #REF!
Name Compco1: #REF!
Name Compco1: #REF!

Sheet RECAP v2
B2: Delivery Fee NEW + USED
B3: =CONCATENATE(#REF!,F2,#REF!) -> #REF! | M3: BUDGET | X3: 2019
B4: STORE | C4: Units | D4: Margin | E4: Margin demo | F4: Front margin | G4: frais de livraison | H4: Ent. Stock | I4: Delivery fee | J4: Delivery fee / unit | K4: % Delivery fee / Front margin | M4: STORE | N4: Units | O4: M. new | P4: M. Demos | Q4: Front margin | R4: frais de livraison | S4: Ent. Stock | T4: Delivery fee | U4: Delivery fee / unit | V4: % Delivery fee / Front margin | X4: STORE | Y4: Units | Z4: M. used | AB4: Front margin | AC4: frais de livraison | AD4: Ent. Stock | AE4: Delivery fee | AF4: Delivery fee / unit | AG4: % Delivery fee / Front margin
B5: TOTAL | C5: =+SUM(C6:C23) -> #REF! | D5: =+SUM(D6:D23) -> #REF! | E5: =+SUM(E6:E23) -> #REF! | F5: =+SUM(F6:F23) -> #REF! | G5: =+SUM(G6:G23) -> #REF! | H5: =+SUM(H6:H23) -> #REF! | I5: =+SUM(I6:I23) -> #REF! | J5: =+I5/C5 -> #REF! | K5: =+I5/F5 -> #REF! | M5: TOTAL | N5: =+SUM(N6:N23) -> #REF! | O5: =+SUM(O6:O23) -> #REF! | P5: =+SUM(P6:P23) -> #REF! | Q5: =+SUM(Q6:Q23) -> #REF! | R5: =+SUM(R6:R23) -> #REF! | S5: =+SUM(S6:S23) -> #REF! | T5: =+SUM(T6:T23) -> #REF! | U5: =+T5/N5 -> #REF! | V5: =+T5/Q5 -> #REF! | X5: TOTAL | Y5: =+SUM(Y6:Y23) -> #REF! | Z5: =+SUM(Z6:Z23) -> #REF! | AA5: =+SUM(AA6:AA23) -> #REF! | AB5: =+SUM(AB6:AB23) -> #REF! | AC5: =+SUM(AC6:AC23) -> #REF! | AD5: =+SUM(AD6:AD23) -> #REF! | AE5: =+SUM(AE6:AE23) -> #REF! | AF5: =+AE5/Y5 -> #REF! | AG5: =+AE5/AB5 -> #REF!
B6: AUDI | C6: =+C29+C52 -> #REF! | D6: =+D29+D52 -> #REF! | E6: =+E29+E52 -> #REF! | F6: =+D6+E6 -> #REF! | G6: =+G29+G52 -> #REF! | H6: =+H29+H52 -> #REF! | I6: =+G6+H6 -> #REF! | J6: =+I6/C6 -> #REF! | K6: =+I6/F6 -> #REF! | M6: AUDI | N6: =+N29+N52 -> #REF! | O6: =+O29+O52 -> #REF! | P6: =+P29+P52 -> #REF! | Q6: =+O6+P6 -> #REF! | R6: =+R29+R52 -> #REF! | S6: =+S29+S52 -> #REF! | T6: =+R6+S6 -> #REF! | U6: =+T6/N6 -> #REF! | V6: =+T6/Q6 -> #REF! | X6: AUDI | Y6: =+Y29+Y52 -> #REF! | Z6: =+Z29+Z52 -> #REF! | AA6: =+AA29+AA52 -> #REF! | AB6: =+Z6+AA6 -> #REF! | AC6: =+AC29+AC52 -> #REF! | AD6: =+AD29+AD52 -> #REF! | AE6: =+AC6+AD6 -> #REF! | AF6: =+AE6/Y6 -> #REF! | AG6: =+AE6/AB6 -> #REF!
B7: INFINITI | C7: =+C30+C53 -> #REF! | D7: =+D30+D53 -> #REF! | E7: =+E30+E53 -> #REF! | F7: =+D7+E7 -> #REF! | G7: =+G30+G53 -> #REF! | H7: =+H30+H53 -> #REF! | I7: =+G7+H7 -> #REF! | J7: =+I7/C7 -> #REF! | K7: =+I7/F7 -> #REF! | M7: INFINITI | N7: =+N30+N53 -> #REF! | O7: =+O30+O53 -> #REF! | P7: =+P30+P53 -> #REF! | Q7: =+O7+P7 -> #REF! | R7: =+R30+R53 -> #REF! | S7: =+S30+S53 -> #REF! | T7: =+R7+S7 -> #REF! | U7: =+T7/N7 -> #REF! | V7: =+T7/Q7 -> #REF! | X7: INFINITI | Y7: =+Y30+Y53 -> #REF! | Z7: =+Z30+Z53 -> #REF! | AA7: =+AA30+AA53 -> #REF! | AB7: =+Z7+AA7 -> #REF! | AC7: =+AC30+AC53 -> #REF! | AD7: =+AD30+AD53 -> #REF! | AE7: =+AC7+AD7 -> #REF! | AF7: =+AE7/Y7 -> #REF! | AG7: =+AE7/AB7 -> #REF!
B8: MCPA LAP | C8: =+C31+C54 -> #REF! | D8: =+D31+D54 -> #REF! | E8: =+E31+E54 -> 0 | F8: =+D8+E8 -> #REF! | G8: =+G31+G54 -> #REF! | H8: =+H31+H54 -> #REF! | I8: =+G8+H8 -> #REF! | J8: =+I8/C8 -> #REF! | K8: =+I8/F8 -> #REF! | M8: MCPA LAP | N8: =+N31+N54 -> #REF! | O8: =+O31+O54 -> #REF! | P8: =+P31+P54 -> 0 | Q8: =+O8+P8 -> #REF! | R8: =+R31+R54 -> #REF! | S8: =+S31+S54 -> #REF! | T8: =+R8+S8 -> #REF! | U8: =+T8/N8 -> #REF! | V8: =+T8/Q8 -> #REF! | X8: MCPA LAP | Y8: =+Y31+Y54 -> #REF! | Z8: =+Z31+Z54 -> #REF! | AA8: =+AA31+AA54 -> 0 | AB8: =+Z8+AA8 -> #REF! | AC8: =+AC31+AC54 -> #REF! | AD8: =+AD31+AD54 -> #REF! | AE8: =+AC8+AD8 -> #REF! | AF8: =+AE8/Y8 -> #REF! | AG8: =+AE8/AB8 -> #REF!
B9: MCPA LAV | C9: =+C32+C55 -> #REF! | D9: =+D32+D55 -> #REF! | E9: =+E32+E55 -> 0 | F9: =+D9+E9 -> #REF! | G9: =+G32+G55 -> #REF! | H9: =+H32+H55 -> #REF! | I9: =+G9+H9 -> #REF! | J9: =+I9/C9 -> #REF! | K9: =+I9/F9 -> #REF! | M9: MCPA LAV | N9: =+N32+N55 -> #REF! | O9: =+O32+O55 -> #REF! | P9: =+P32+P55 -> 0 | Q9: =+O9+P9 -> #REF! | R9: =+R32+R55 -> #REF! | S9: =+S32+S55 -> #REF! | T9: =+R9+S9 -> #REF! | U9: =+T9/N9 -> #REF! | V9: =+T9/Q9 -> #REF! | X9: MCPA LAV | Y9: =+Y32+Y55 -> #REF! | Z9: =+Z32+Z55 -> #REF! | AA9: =+AA32+AA55 -> 0 | AB9: =+Z9+AA9 -> #REF! | AC9: =+AC32+AC55 -> #REF! | AD9: =+AD32+AD55 -> #REF! | AE9: =+AC9+AD9 -> #REF! | AF9: =+AE9/Y9 -> #REF! | AG9: =+AE9/AB9 -> #REF!
B10: MCPA SPE | C10: =+C33+C56 -> #REF! | D10: =+D33+D56 -> #REF! | E10: =+E33+E56 -> 0 | F10: =+D10+E10 -> #REF! | G10: =+G33+G56 -> #REF! | H10: =+H33+H56 -> #REF! | I10: =+G10+H10 -> #REF! | J10: =+I10/C10 -> #REF! | K10: =+I10/F10 -> #REF! | M10: MCPA SPE | N10: =+N33+N56 -> #REF! | O10: =+O33+O56 -> #REF! | P10: =+P33+P56 -> 0 | Q10: =+O10+P10 -> #REF! | R10: =+R33+R56 -> #REF! | S10: =+S33+S56 -> #REF! | T10: =+R10+S10 -> #REF! | U10: =+T10/N10 -> #REF! | V10: =+T10/Q10 -> #REF! | X10: MCPA SPE | Y10: =+Y33+Y56 -> #REF! | Z10: =+Z33+Z56 -> #REF! | AA10: =+AA33+AA56 -> 0 | AB10: =+Z10+AA10 -> #REF! | AC10: =+AC33+AC56 -> #REF! | AD10: =+AD33+AD56 -> #REF! | AE10: =+AC10+AD10 -> #REF! | AF10: =+AE10/Y10 -> #REF! | AG10: =+AE10/AB10 -> #REF!
B11: HONDA | C11: =+C34+C57 -> #REF! | D11: =+D34+D57 -> #REF! | E11: =+E34+E57 -> #REF! | F11: =+D11+E11 -> #REF! | G11: =+G34+G57 -> #REF! | H11: =+H34+H57 -> #REF! | I11: =+G11+H11 -> #REF! | J11: =+I11/C11 -> #REF! | K11: =+I11/F11 -> #REF! | M11: HONDA | N11: =+N34+N57 -> #REF! | O11: =+O34+O57 -> #REF! | P11: =+P34+P57 -> #REF! | Q11: =+O11+P11 -> #REF! | R11: =+R34+R57 -> #REF! | S11: =+S34+S57 -> #REF! | T11: =+R11+S11 -> #REF! | U11: =+T11/N11 -> #REF! | V11: =+T11/Q11 -> #REF! | X11: HONDA | Y11: =+Y34+Y57 -> #REF! | Z11: =+Z34+Z57 -> #REF! | AA11: =+AA34+AA57 -> #REF! | AB11: =+Z11+AA11 -> #REF! | AC11: =+AC34+AC57 -> #REF! | AD11: =+AD34+AD57 -> #REF! | AE11: =+AC11+AD11 -> #REF! | AF11: =+AE11/Y11 -> #REF! | AG11: =+AE11/AB11 -> #REF!
B12: TOYOTA | C12: =+C35+C58 -> #REF! | D12: =+D35+D58 -> #REF! | E12: =+E35+E58 -> #REF! | F12: =+D12+E12 -> #REF! | G12: =+G35+G58 -> #REF! | H12: =+H35+H58 -> #REF! | I12: =+G12+H12 -> #REF! | J12: =+I12/C12 -> #REF! | K12: =+I12/F12 -> #REF! | M12: TOYOTA | N12: =+N35+N58 -> #REF! | O12: =+O35+O58 -> #REF! | P12: =+P35+P58 -> #REF! | Q12: =+O12+P12 -> #REF! | R12: =+R35+R58 -> #REF! | S12: =+S35+S58 -> #REF! | T12: =+R12+S12 -> #REF! | U12: =+T12/N12 -> #REF! | V12: =+T12/Q12 -> #REF! | X12: TOYOTA | Y12: =+Y35+Y58 -> #REF! | Z12: =+Z35+Z58 -> #REF! | AA12: =+AA35+AA58 -> #REF! | AB12: =+Z12+AA12 -> #REF! | AC12: =+AC35+AC58 -> #REF! | AD12: =+AD35+AD58 -> #REF! | AE12: =+AC12+AD12 -> #REF! | AF12: =+AE12/Y12 -> #REF! | AG12: =+AE12/AB12 -> #REF!
B13: VOLKS | C13: =+C36+C59 -> #REF! | D13: =+D36+D59 -> #REF! | E13: =+E36+E59 -> #REF! | F13: =+D13+E13 -> #REF! | G13: =+G36+G59 -> #REF! | H13: =+H36+H59 -> #REF! | I13: =+G13+H13 -> #REF! | J13: =+I13/C13 -> #REF! | K13: =+I13/F13 -> #REF! | M13: VOLKS | N13: =+N36+N59 -> #REF! | O13: =+O36+O59 -> #REF! | P13: =+P36+P59 -> #REF! | Q13: =+O13+P13 -> #REF! | R13: =+R36+R59 -> #REF! | S13: =+S36+S59 -> #REF! | T13: =+R13+S13 -> #REF! | U13: =+T13/N13 -> #REF! | V13: =+T13/Q13 -> #REF! | X13: VOLKS | Y13: =+Y36+Y59 -> #REF! | Z13: =+Z36+Z59 -> #REF! | AA13: =+AA36+AA59 -> #REF! | AB13: =+Z13+AA13 -> #REF! | AC13: =+AC36+AC59 -> #REF! | AD13: =+AD36+AD59 -> #REF! | AE13: =+AC13+AD13 -> #REF! | AF13: =+AE13/Y13 -> #REF! | AG13: =+AE13/AB13 -> #REF!
B14: BMW PA | C14: =+C37+C60 -> #REF! | D14: =+D37+D60 -> #REF! | E14: =+E37+E60 -> #REF! | F14: =+D14+E14 -> #REF! | G14: =+G37+G60 -> #REF! | H14: =+H37+H60 -> #REF! | I14: =+G14+H14 -> #REF! | J14: =+I14/C14 -> #REF! | K14: =+I14/F14 -> #REF! | M14: BMW PA | N14: =+N37+N60 -> #REF! | O14: =+O37+O60 -> #REF! | P14: =+P37+P60 -> #REF! | Q14: =+O14+P14 -> #REF! | R14: =+R37+R60 -> #REF! | S14: =+S37+S60 -> #REF! | T14: =+R14+S14 -> #REF! | U14: =+T14/N14 -> #REF! | V14: =+T14/Q14 -> #REF! | X14: BMW PA | Y14: =+Y37+Y60 -> #REF! | Z14: =+Z37+Z60 -> #REF! | AA14: =+AA37+AA60 -> #REF! | AB14: =+Z14+AA14 -> #REF! | AC14: =+AC37+AC60 -> #REF! | AD14: =+AD37+AD60 -> #REF! | AE14: =+AC14+AD14 -> #REF! | AF14: =+AE14/Y14 -> #REF! | AG14: =+AE14/AB14 -> #REF!
B15: MINI | C15: =+C38+C61 -> #REF! | D15: =+D38+D61 -> #REF! | E15: =+E38+E61 -> #REF! | F15: =+D15+E15 -> #REF! | G15: =+G38+G61 -> #REF! | H15: =+H38+H61 -> #REF! | I15: =+G15+H15 -> #REF! | J15: =+I15/C15 -> #REF! | K15: =+I15/F15 -> #REF! | M15: MINI | N15: =+N38+N61 -> #REF! | O15: =+O38+O61 -> #REF! | P15: =+P38+P61 -> #REF! | Q15: =+O15+P15 -> #REF! | R15: =+R38+R61 -> #REF! | S15: =+S38+S61 -> #REF! | T15: =+R15+S15 -> #REF! | U15: =+T15/N15 -> #REF! | V15: =+T15/Q15 -> #REF! | X15: MINI | Y15: =+Y38+Y61 -> #REF! | Z15: =+Z38+Z61 -> #REF! | AA15: =+AA38+AA61 -> #REF! | AB15: =+Z15+AA15 -> #REF! | AC15: =+AC38+AC61 -> #REF! | AD15: =+AD38+AD61 -> #REF! | AE15: =+AC15+AD15 -> #REF! | AF15: =+AE15/Y15 -> #REF! | AG15: =+AE15/AB15 -> #REF!
B16: BMW STJ | C16: =+C39+C62 -> #REF! | D16: =+D39+D62 -> #REF! | E16: =+E39+E62 -> #REF! | F16: =+D16+E16 -> #REF! | G16: =+G39+G62 -> #REF! | H16: =+H39+H62 -> #REF! | I16: =+G16+H16 -> #REF! | J16: =+I16/C16 -> #REF! | K16: =+I16/F16 -> #REF! | M16: BMW STJ | N16: =+N39+N62 -> #REF! | O16: =+O39+O62 -> #REF! | P16: =+P39+P62 -> #REF! | Q16: =+O16+P16 -> #REF! | R16: =+R39+R62 -> #REF! | S16: =+S39+S62 -> #REF! | T16: =+R16+S16 -> #REF! | U16: =+T16/N16 -> #REF! | V16: =+T16/Q16 -> #REF! | X16: BMW STJ | Y16: =+Y39+Y62 -> #REF! | Z16: =+Z39+Z62 -> #REF! | AA16: =+AA39+AA62 -> #REF! | AB16: =+Z16+AA16 -> #REF! | AC16: =+AC39+AC62 -> #REF! | AD16: =+AD39+AD62 -> #REF! | AE16: =+AC16+AD16 -> #REF! | AF16: =+AE16/Y16 -> #REF! | AG16: =+AE16/AB16 -> #REF!
B17: LEXUS | C17: =+C40+C63 -> #REF! | D17: =+D40+D63 -> #REF! | E17: =+E40+E63 -> #REF! | F17: =+D17+E17 -> #REF! | G17: =+G40+G63 -> #REF! | H17: =+H40+H63 -> #REF! | I17: =+G17+H17 -> #REF! | J17: =+I17/C17 -> #REF! | K17: =+I17/F17 -> #REF! | M17: LEXUS | N17: =+N40+N63 -> #REF! | O17: =+O40+O63 -> #REF! | P17: =+P40+P63 -> #REF! | Q17: =+O17+P17 -> #REF! | R17: =+R40+R63 -> #REF! | S17: =+S40+S63 -> #REF! | T17: =+R17+S17 -> #REF! | U17: =+T17/N17 -> #REF! | V17: =+T17/Q17 -> #REF! | X17: LEXUS | Y17: =+Y40+Y63 -> #REF! | Z17: =+Z40+Z63 -> #REF! | AA17: =+AA40+AA63 -> #REF! | AB17: =+Z17+AA17 -> #REF! | AC17: =+AC40+AC63 -> #REF! | AD17: =+AD40+AD63 -> #REF! | AE17: =+AC17+AD17 -> #REF! | AF17: =+AE17/Y17 -> #REF! | AG17: =+AE17/AB17 -> #REF!
... B23: LHD | C23: =+C46+C69 -> #REF! | D23: =+D46+D69 -> #REF! | E23: =+E46+E69 -> #REF! | F23: =+D23+E23 -> #REF! | G23: =+G46+G69 -> #REF! | H23: =+H46+H69 -> #REF! | I23: =+G23+H23 -> #REF! | J23: =+I23/C23 -> #REF! | K23: =+I23/F23 -> #REF! | M23: LHD | N23: =+N46+N69 -> #REF! | O23: =+O46+O69 -> #REF! | P23: =+P46+P69 -> #REF! | Q23: =+O23+P23 -> #REF! | R23: =+R46+R69 -> #REF! | S23: =+S46+S69 -> #REF! | T23: =+R23+S23 -> #REF! | U23: =+T23/N23 -> #REF! | V23: =+T23/Q23 -> #REF! | X23: LHD | Y23: =+Y46+Y69 -> #REF! | Z23: =+Z46+Z69 -> #REF! | AA23: =+AA46+AA69 -> #REF! | AB23: =+Z23+AA23 -> #REF! | AC23: =+AC46+AC69 -> #REF! | AD23: =+AD46+AD69 -> #REF! | AE23: =+AC23+AD23 -> #REF! | AF23: =+AE23/Y23 -> #REF! | AG23: =+AE23/AB23 -> #REF!
B25: Delivery Fee New
B26: =B3 -> #REF! | M26: BUDGET | X26: 2019
B27: STORE | C27: Units | D27: Margin | E27: Margin demo | F27: Front margin | G27: frais de livraison | H27: Ent. Stock | I27: Delivery fee | J27: Delivery fee / unit | K27: % Delivery fee / Front margin | M27: STORE | N27: Units | O27: M. new | P27: M. Demos | Q27: Front margin | R27: frais de livraison | S27: Ent. Stock | T27: Delivery fee | U27: Delivery fee / unit | V27: % Delivery fee / Front margin | X27: STORE | Y27: Units | Z27: M. used | AB27: Front margin | AC27: frais de livraison | AD27: Ent. Stock | AE27: Delivery fee | AF27: Delivery fee / unit | AG27: % Delivery fee / Front margin
B28: TOTAL | C28: =+SUM(C29:C46) -> #REF! | D28: =+SUM(D29:D46) -> #REF! | E28: =+SUM(E29:E46) -> #REF! | F28: =+SUM(F29:F46) -> #REF! | G28: =+SUM(G29:G46) -> #REF! | H28: =+SUM(H29:H46) -> #REF! | I28: =+SUM(I29:I46) -> #REF! | J28: =+I28/C28 -> #REF! | K28: =+I28/F28 -> #REF! | M28: TOTAL | N28: =+SUM(N29:N46) -> #REF! | O28: =+SUM(O29:O46) -> #REF! | P28: =+SUM(P29:P46) -> #REF! | Q28: =+SUM(Q29:Q46) -> #REF! | R28: =+SUM(R29:R46) -> #REF! | S28: =+SUM(S29:S46) -> #REF! | T28: =+SUM(T29:T46) -> #REF! | U28: =+T28/N28 -> #REF! | V28: =+T28/Q28 -> #REF! | X28: TOTAL | Y28: =+SUM(Y29:Y46) -> #REF! | Z28: =+SUM(Z29:Z46) -> #REF! | AA28: =+SUM(AA29:AA46) -> #REF! | AB28: =+SUM(AB29:AB46) -> #REF! | AC28: =+SUM(AC29:AC46) -> #REF! | AD28: =+SUM(AD29:AD46) -> #REF! | AE28: =+SUM(AE29:AE46) -> #REF! | AF28: =+AE28/Y28 -> #REF! | AG28: =+AE28/AB28 -> #REF!
B29: AUDI | C29: =+#REF! -> #REF! | D29: =+#REF! -> #REF! | E29: =+#REF! -> #REF! | F29: =+D29+E29 -> #REF! | G29: =+#REF! -> #REF! | H29: =+#REF! -> #REF! | I29: =+G29+H29 -> #REF! | J29: =+I29/C29 -> #REF! | K29: =+I29/F29 -> #REF! | M29: AUDI | N29: =+#REF! -> #REF! | O29: =+#REF! -> #REF! | P29: =+#REF! -> #REF! | Q29: =+O29+P29 -> #REF! | R29: =+#REF! -> #REF! | S29: =+#REF! -> #REF! | T29: =+R29+S29 -> #REF! | U29: =+T29/N29 -> #REF! | V29: =+T29/Q29 -> #REF! | X29: AUDI | Y29: =+#REF! -> #REF! | Z29: =+#REF! -> #REF! | AA29: =+#REF! -> #REF! | AB29: =+Z29+AA29 -> #REF! | AC29: =+#REF! -> #REF! | AD29: =+#REF! -> #REF! | AE29: =+AC29+AD29 -> #REF! | AF29: =+AE29/Y29 -> #REF! | AG29: =+AE29/AB29 -> #REF!
B30: INFINITI | C30: =+#REF! -> #REF! | D30: =+#REF! -> #REF! | E30: =+#REF! -> #REF! | F30: =+D30+E30 -> #REF! | G30: =+#REF! -> #REF! | H30: =+#REF! -> #REF! | I30: =+G30+H30 -> #REF! | J30: =+I30/C30 -> #REF! | K30: =+I30/F30 -> #REF! | M30: INFINITI | N30: =+#REF! -> #REF! | O30: =+#REF! -> #REF! | P30: =+#REF! -> #REF! | Q30: =+O30+P30 -> #REF! | R30: =+#REF! -> #REF! | S30: =+#REF! -> #REF! | T30: =+R30+S30 -> #REF! | U30: =+T30/N30 -> #REF! | V30: =+T30/Q30 -> #REF! | X30: INFINITI | Y30: =+#REF! -> #REF! | Z30: =+#REF! -> #REF! | AA30: =+#REF! -> #REF! | AB30: =+Z30+AA30 -> #REF! | AC30: =+#REF! -> #REF! | AD30: =+#REF! -> #REF! | AE30: =+AC30+AD30 -> #REF! | AF30: =+AE30/Y30 -> #REF! | AG30: =+AE30/AB30 -> #REF!
B34: HONDA | C34: =+#REF! -> #REF! | D34: =+#REF! -> #REF! | E34: =+#REF! -> #REF! | F34: =+D34+E34 -> #REF! | G34: =+#REF! -> #REF! | H34: =+#REF! -> #REF! | I34: =+G34+H34 -> #REF! | J34: =+I34/C34 -> #REF! | K34: =+I34/F34 -> #REF! | M34: HONDA | N34: =+#REF! -> #REF! | O34: =+#REF! -> #REF! | P34: =+#REF! -> #REF! | Q34: =+O34+P34 -> #REF! | R34: =+#REF! -> #REF! | S34: =+#REF! -> #REF! | T34: =+R34+S34 -> #REF! | U34: =+T34/N34 -> #REF! | V34: =+T34/Q34 -> #REF! | X34: HONDA | Y34: =+#REF! -> #REF! | Z34: =+#REF! -> #REF! | AA34: =+#REF! -> #REF! | AB34: =+Z34+AA34 -> #REF! | AC34: =+#REF! -> #REF! | AD34: =+#REF! -> #REF! | AE34: =+AC34+AD34 -> #REF! | AF34: =+AE34/Y34 -> #REF! | AG34: =+AE34/AB34 -> #REF!
B35: TOYOTA | C35: =+#REF! -> #REF! | D35: =+#REF! -> #REF! | E35: =+#REF! -> #REF! | F35: =+D35+E35 -> #REF! | G35: =+#REF! -> #REF! | H35: =+#REF! -> #REF! | I35: =+G35+H35 -> #REF! | J35: =+I35/C35 -> #REF! | K35: =+I35/F35 -> #REF! | M35: TOYOTA | N35: =+#REF! -> #REF! | O35: =+#REF! -> #REF! | P35: =+#REF! -> #REF! | Q35: =+O35+P35 -> #REF! | R35: =+#REF! -> #REF! | S35: =+#REF! -> #REF! | T35: =+R35+S35 -> #REF! | U35: =+T35/N35 -> #REF! | V35: =+T35/Q35 -> #REF! | X35: TOYOTA | Y35: =+#REF! -> #REF! | Z35: =+#REF! -> #REF! | AA35: =+#REF! -> #REF! | AB35: =+Z35+AA35 -> #REF! | AC35: =+#REF! -> #REF! | AD35: =+#REF! -> #REF! | AE35: =+AC35+AD35 -> #REF! | AF35: =+AE35/Y35 -> #REF! | AG35: =+AE35/AB35 -> #REF!
B36: VOLKS | C36: =+#REF! -> #REF! | D36: =+#REF! -> #REF! | E36: =+#REF! -> #REF! | F36: =+D36+E36 -> #REF! | G36: =+#REF! -> #REF! | H36: =+#REF! -> #REF! | I36: =+G36+H36 -> #REF! | J36: =+I36/C36 -> #REF! | K36: =+I36/F36 -> #REF! | M36: VOLKS | N36: =+#REF! -> #REF! | O36: =+#REF! -> #REF! | P36: =+#REF! -> #REF! | Q36: =+O36+P36 -> #REF! | R36: =+#REF! -> #REF! | S36: =+#REF! -> #REF! | T36: =+R36+S36 -> #REF! | U36: =+T36/N36 -> #REF! | V36: =+T36/Q36 -> #REF! | X36: VOLKS | Y36: =+#REF! -> #REF! | Z36: =+#REF! -> #REF! | AA36: =+#REF! -> #REF! | AB36: =+Z36+AA36 -> #REF! | AC36: =+#REF! -> #REF! | AD36: =+#REF! -> #REF! | AE36: =+AC36+AD36 -> #REF! | AF36: =+AE36/Y36 -> #REF! | AG36: =+AE36/AB36 -> #REF!
B37: BMW PA | C37: =+#REF! -> #REF! | D37: =+#REF! -> #REF! | E37: =+#REF! -> #REF! | F37: =+D37+E37 -> #REF! | G37: =+#REF! -> #REF! | H37: =+#REF! -> #REF! | I37: =+G37+H37 -> #REF! | J37: =+I37/C37 -> #REF! | K37: =+I37/F37 -> #REF! | M37: BMW PA | N37: =+#REF! -> #REF! | O37: =+#REF! -> #REF! | P37: =+#REF! -> #REF! | Q37: =+O37+P37 -> #REF! | R37: =+#REF! -> #REF! | S37: =+#REF! -> #REF! | T37: =+R37+S37 -> #REF! | U37: =+T37/N37 -> #REF! | V37: =+T37/Q37 -> #REF! | X37: BMW PA | Y37: =+#REF! -> #REF! | Z37: =+#REF! -> #REF! | AA37: =+#REF! -> #REF! | AB37: =+Z37+AA37 -> #REF! | AC37: =+#REF! -> #REF! | AD37: =+#REF! -> #REF! | AE37: =+AC37+AD37 -> #REF! | AF37: =+AE37/Y37 -> #REF! | AG37: =+AE37/AB37 -> #REF!
B38: MINI | C38: =+#REF! -> #REF! | D38: =+#REF! -> #REF! | E38: =+#REF! -> #REF! | F38: =+D38+E38 -> #REF! | G38: =+#REF! -> #REF! | H38: =+#REF! -> #REF! | I38: =+G38+H38 -> #REF! | J38: =+I38/C38 -> #REF! | K38: =+I38/F38 -> #REF! | M38: MINI | N38: =+#REF! -> #REF! | O38: =+#REF! -> #REF! | P38: =+#REF! -> #REF! | Q38: =+O38+P38 -> #REF! | R38: =+#REF! -> #REF! | S38: =+#REF! -> #REF! | T38: =+R38+S38 -> #REF! | U38: =+T38/N38 -> #REF! | V38: =+T38/Q38 -> #REF! | X38: MINI | Y38: =+#REF! -> #REF! | Z38: =+#REF! -> #REF! | AA38: =+#REF! -> #REF! | AB38: =+Z38+AA38 -> #REF! | AC38: =+#REF! -> #REF! | AD38: =+#REF! -> #REF! | AE38: =+AC38+AD38 -> #REF! | AF38: =+AE38/Y38 -> #REF! | AG38: =+AE38/AB38 -> #REF!
B39: BMW STJ | C39: =+#REF! -> #REF! | D39: =+#REF! -> #REF! | E39: =+#REF! -> #REF! | F39: =+D39+E39 -> #REF! | G39: =+#REF! -> #REF! | H39: =+#REF! -> #REF! | I39: =+G39+H39 -> #REF! | J39: =+I39/C39 -> #REF! | K39: =+I39/F39 -> #REF! | M39: BMW STJ | N39: =+#REF! -> #REF! | O39: =+#REF! -> #REF! | P39: =+#REF! -> #REF! | Q39: =+O39+P39 -> #REF! | R39: =+#REF! -> #REF! | S39: =+#REF! -> #REF! | T39: =+R39+S39 -> #REF! | U39: =+T39/N39 -> #REF! | V39: =+T39/Q39 -> #REF! | X39: BMW STJ | Y39: =+#REF! -> #REF! | Z39: =+#REF! -> #REF! | AA39: =+#REF! -> #REF! | AB39: =+Z39+AA39 -> #REF! | AC39: =+#REF! -> #REF! | AD39: =+#REF! -> #REF! | AE39: =+AC39+AD39 -> #REF! | AF39: =+AE39/Y39 -> #REF! | AG39: =+AE39/AB39 -> #REF!
B40: LEXUS | C40: =+#REF! -> #REF! | D40: =+#REF! -> #REF! | E40: =+#REF! -> #REF! | F40: =+D40+E40 -> #REF! | G40: =+#REF! -> #REF! | H40: =+#REF! -> #REF! | I40: =+G40+H40 -> #REF! | J40: =+I40/C40 -> #REF! | K40: =+I40/F40 -> #REF! | M40: LEXUS | N40: =+#REF! -> #REF! | O40: =+#REF! -> #REF! | P40: =+#REF! -> #REF! | Q40: =+O40+P40 -> #REF! | R40: =+#REF! -> #REF! | S40: =+#REF! -> #REF! | T40: =+R40+S40 -> #REF! | U40: =+T40/N40 -> #REF! | V40: =+T40/Q40 -> #REF! | X40: LEXUS | Y40: =+#REF! -> #REF! | Z40: =+#REF! -> #REF! | AA40: =+#REF! -> #REF! | AB40: =+Z40+AA40 -> #REF! | AC40: =+#REF! -> #REF! | AD40: =+#REF! -> #REF! | AE40: =+AC40+AD40 -> #REF! | AF40: =+AE40/Y40 -> #REF! | AG40: =+AE40/AB40 -> #REF!
B41: BMW SHER | C41: =+#REF! -> #REF! | D41: =+#REF! -> #REF! | E41: =+#REF! -> #REF! | F41: =+D41+E41 -> #REF! | G41: =+#REF! -> #REF! | H41: =+#REF! -> #REF! | I41: =+G41+H41 -> #REF! | J41: =+I41/C41 -> #REF! | K41: =+I41/F41 -> #REF! | M41: BMW SHER | N41: =+#REF! -> #REF! | O41: =+#REF! -> #REF! | P41: =+#REF! -> #REF! | Q41: =+O41+P41 -> #REF! | R41: =+#REF! -> #REF! | S41: =+#REF! -> #REF! | T41: =+R41+S41 -> #REF! | U41: =+T41/N41 -> #REF! | V41: =+T41/Q41 -> #REF! | X41: BMW SHER | Y41: =+#REF! -> #REF! | Z41: =+#REF! -> #REF! | AA41: =+#REF! -> #REF! | AB41: =+Z41+AA41 -> #REF! | AC41: =+#REF! -> #REF! | AD41: =+#REF! -> #REF! | AE41: =+AC41+AD41 -> #REF! | AF41: =+AE41/Y41 -> #REF! | AG41: =+AE41/AB41 -> #REF!
B42: SSMB | C42: =+#REF! -> #REF! | D42: =+#REF! -> #REF! | E42: =+#REF! -> #REF! | F42: =+D42+E42 -> #REF! | G42: =+#REF! -> #REF! | H42: =+#REF! -> #REF! | I42: =+G42+H42 -> #REF! | J42: =+I42/C42 -> #REF! | K42: =+I42/F42 -> #REF! | M42: SSMB | N42: =+#REF! -> #REF! | O42: =+#REF! -> #REF! | P42: =+#REF! -> #REF! | Q42: =+O42+P42 -> #REF! | R42: =+#REF! -> #REF! | S42: =+#REF! -> #REF! | T42: =+R42+S42 -> #REF! | U42: =+T42/N42 -> #REF! | V42: =+T42/Q42 -> #REF! | X42: SSMB | Y42: =+#REF! -> #REF! | Z42: =+#REF! -> #REF! | AA42: =+#REF! -> #REF! | AB42: =+Z42+AA42 -> #REF! | AC42: =+#REF! -> #REF! | AD42: =+#REF! -> #REF! | AE42: =+AC42+AD42 -> #REF! | AF42: =+AE42/Y42 -> #REF! | AG42: =+AE42/AB42 -> #REF!
B43: MBQ | C43: =+#REF! -> #REF! | D43: =+#REF! -> #REF! | E43: =+#REF! -> #REF! | F43: =+D43+E43 -> #REF! | G43: =+#REF! -> #REF! | H43: =+#REF! -> #REF! | I43: =+G43+H43 -> #REF! | J43: =+I43/C43 -> #REF! | K43: =+I43/F43 -> #REF! | M43: MBQ | N43: =+#REF! -> #REF! | O43: =+#REF! -> #REF! | P43: =+#REF! -> #REF! | Q43: =+O43+P43 -> #REF! | R43: =+#REF! -> #REF! | S43: =+#REF! -> #REF! | T43: =+R43+S43 -> #REF! | U43: =+T43/N43 -> #REF! | V43: =+T43/Q43 -> #REF! | X43: MBQ | Y43: =+#REF! -> #REF! | Z43: =+#REF! -> #REF! | AA43: =+#REF! -> #REF! | AB43: =+Z43+AA43 -> #REF! | AC43: =+#REF! -> #REF! | AD43: =+#REF! -> #REF! | AE43: =+AC43+AD43 -> #REF! | AF43: =+AE43/Y43 -> #REF! | AG43: =+AE43/AB43 -> #REF!
... B46: LHD | C46: =+#REF! -> #REF! | D46: =+#REF! -> #REF! | E46: =+#REF! -> #REF! | F46: =+D46+E46 -> #REF! | G46: =+#REF! -> #REF! | H46: =+#REF! -> #REF! | I46: =+G46+H46 -> #REF! | J46: =+I46/C46 -> #REF! | K46: =+I46/F46 -> #REF! | M46: LHD | N46: =+#REF! -> #REF! | O46: =+#REF! -> #REF! | P46: =+#REF! -> #REF! | Q46: =+O46+P46 -> #REF! | R46: =+#REF! -> #REF! | S46: =+#REF! -> #REF! | T46: =+R46+S46 -> #REF! | U46: =+T46/N46 -> #REF! | V46: =+T46/Q46 -> #REF! | X46: LHD | Y46: =+#REF! -> #REF! | Z46: =+#REF! -> #REF! | AA46: =+#REF! -> #REF! | AB46: =+Z46+AA46 -> #REF! | AC46: =+#REF! -> #REF! | AD46: =+#REF! -> #REF! | AE46: =+AC46+AD46 -> #REF! | AF46: =+AE46/Y46 -> #REF! | AG46: =+AE46/AB46 -> #REF!
B48: Delivery Fee Used
B49: =B26 -> #REF! | M49: BUDGET | X49: 2019
B50: STORE | C50: Units | D50: Margin | E50: Margin demo | F50: Front margin | G50: frais de livraison | H50: Ent. Stock | I50: Delivery fee | J50: Delivery fee / unit | K50: % Delivery fee / Front margin | M50: STORE | N50: Units | O50: M. new | P50: M. Demos | Q50: Front margin | R50: frais de livraison | S50: Ent. Stock | T50: Delivery fee | U50: Delivery fee / unit | V50: % Delivery fee / Front margin | X50: STORE | Y50: Units | Z50: M. used | AB50: Front margin | AC50: frais de livraison | AD50: Ent. Stock | AE50: Delivery fee | AF50: Delivery fee / unit | AG50: % Delivery fee / Front margin
B51: TOTAL | C51: =+SUM(C52:C69) -> #REF! | D51: =+SUM(D52:D69) -> #REF! | F51: =+SUM(F52:F69) -> #REF! | G51: =+SUM(G52:G69) -> #REF! | H51: =+SUM(H52:H69) -> #REF! | I51: =+SUM(I52:I69) -> #REF! | J51: =+I51/C51 -> #REF! | K51: =+I51/F51 -> #REF! | M51: TOTAL | N51: =+SUM(N52:N69) -> #REF! | O51: =+SUM(O52:O69) -> #REF! | Q51: =+SUM(Q52:Q69) -> #REF! | R51: =+SUM(R52:R69) -> #REF! | S51: =+SUM(S52:S69) -> #REF! | T51: =+SUM(T52:T69) -> #REF! | U51: =+T51/N51 -> #REF! | V51: =+T51/Q51 -> #REF! | X51: TOTAL | Y51: =+SUM(Y52:Y69) -> #REF! | Z51: =+SUM(Z52:Z69) -> #REF! | AB51: =+SUM(AB52:AB69) -> #REF! | AC51: =+SUM(AC52:AC69) -> #REF! | AD51: =+SUM(AD52:AD69) -> #REF! | AE51: =+SUM(AE52:AE69) -> #REF! | AF51: =+AE51/Y51 -> #REF! | AG51: =+AE51/AB51 -> #REF!
B52: AUDI | C52: =+#REF! -> #REF! | D52: =+#REF! -> #REF! | F52: =+D52+E52 -> #REF! | G52: =+#REF! -> #REF! | H52: =+#REF! -> #REF! | I52: =+G52+H52 -> #REF! | J52: =+I52/C52 -> #REF! | K52: =+I52/F52 -> #REF! | M52: AUDI | N52: =+#REF! -> #REF! | O52: =+#REF! -> #REF! | Q52: =+O52+P52 -> #REF! | R52: =+#REF! -> #REF! | S52: =+#REF! -> #REF! | T52: =+R52+S52 -> #REF! | U52: =+T52/N52 -> #REF! | V52: =+T52/Q52 -> #REF! | X52: AUDI | Y52: =+#REF! -> #REF! | Z52: =+#REF! -> #REF! | AB52: =+Z52+AA52 -> #REF! | AC52: =+#REF! -> #REF! | AD52: =+#REF! -> #REF! | AE52: =+AC52+AD52 -> #REF! | AF52: =+AE52/Y52 -> #REF! | AG52: =+AE52/AB52 -> #REF!
B53: INFINITI | C53: =+#REF! -> #REF! | D53: =+#REF! -> #REF! | F53: =+D53+E53 -> #REF! | G53: =+#REF! -> #REF! | H53: =+#REF! -> #REF! | I53: =+G53+H53 -> #REF! | J53: =+I53/C53 -> #REF! | K53: =+I53/F53 -> #REF! | M53: INFINITI | N53: =+#REF! -> #REF! | O53: =+#REF! -> #REF! | Q53: =+O53+P53 -> #REF! | R53: =+#REF! -> #REF! | S53: =+#REF! -> #REF! | T53: =+R53+S53 -> #REF! | U53: =+T53/N53 -> #REF! | V53: =+T53/Q53 -> #REF! | X53: INFINITI | Y53: =+#REF! -> #REF! | Z53: =+#REF! -> #REF! | AB53: =+Z53+AA53 -> #REF! | AC53: =+#REF! -> #REF! | AD53: =+#REF! -> #REF! | AE53: =+AC53+AD53 -> #REF! | AF53: =+AE53/Y53 -> #REF! | AG53: =+AE53/AB53 -> #REF!
...

Sheet RECAP v1
B1: Delivery Fee NEW + USED | M1: Delivery Fee New | X1: Delivery Fee used
B3: ='RECAP v2'!B3:K3 -> #REF! | M3: =B3 -> #REF! | X3: =M3 -> #REF!
B4: STORE | C4: Units | D4: Margin | E4: Margin demo | F4: Front margin | G4: frais de livraison | H4: Ent. Stock | I4: Delivery fee | J4: Delivery fee / unit | K4: % Delivery fee / Front margin | M4: STORE | N4: Units | O4: M. new | P4: M. Demos | Q4: Front margin | R4: frais de livraison | S4: Ent. Stock | T4: Delivery fee | U4: Delivery fee / unit | V4: % Delivery fee / Front margin | X4: STORE | Y4: Units | Z4: M. used | AB4: Front margin | AC4: frais de livraison | AD4: Ent. Stock | AE4: Delivery fee | AF4: Delivery fee / unit | AG4: % Delivery fee / Front margin
B5: TOTAL | C5: =+SUM(C6:C23) -> #REF! | D5: =+SUM(D6:D23) -> #REF! | E5: =+SUM(E6:E23) -> #REF! | F5: =+SUM(F6:F23) -> #REF! | G5: =+SUM(G6:G23) -> #REF! | H5: =+SUM(H6:H23) -> #REF! | I5: =+SUM(I6:I23) -> #REF! | J5: =+I5/C5 -> #REF! | K5: =+I5/F5 -> #REF! | M5: TOTAL | N5: =+SUM(N6:N23) -> #REF! | O5: =+SUM(O6:O23) -> #REF! | P5: =+SUM(P6:P23) -> #REF! | Q5: =+SUM(Q6:Q23) -> #REF! | R5: =+SUM(R6:R23) -> #REF! | S5: =+SUM(S6:S23) -> #REF! | T5: =+SUM(T6:T23) -> #REF! | U5: =+T5/N5 -> #REF! | V5: =+T5/Q5 -> #REF! | X5: TOTAL | Y5: =+SUM(Y6:Y23) -> #REF! | Z5: =+SUM(Z6:Z23) -> #REF! | AB5: =+SUM(AB6:AB23) -> #REF! | AC5: =+SUM(AC6:AC23) -> #REF! | AD5: =+SUM(AD6:AD23) -> #REF! | AE5: =+SUM(AE6:AE23) -> #REF! | AF5: =+AE5/Y5 -> #REF! | AG5: =+AE5/AB5 -> #REF!
B6: AUDI | C6: =+N6+Y6 -> #REF! | D6: =+O6+Z6 -> #REF! | E6: =+P6+AA6 -> #REF! | F6: =+D6+E6 -> #REF! | G6: =+R6+AC6 -> #REF! | H6: =+S6+AD6 -> #REF! | I6: =+G6+H6 -> #REF! | J6: =+I6/C6 -> #REF! | K6: =+I6/F6 -> #REF! | M6: AUDI | N6: =+#REF! -> #REF! | O6: =+#REF! -> #REF! | P6: =+#REF! -> #REF! | Q6: =+O6+P6 -> #REF! | R6: =+#REF! -> #REF! | S6: =+#REF! -> #REF! | T6: =+R6+S6 -> #REF! | U6: =+T6/N6 -> #REF! | V6: =+T6/Q6 -> #REF! | X6: AUDI | Y6: =+#REF! -> #REF! | Z6: =+#REF! -> #REF! | AB6: =+Z6+AA6 -> #REF! | AC6: =+#REF! -> #REF! | AD6: =+#REF! -> #REF! | AE6: =+AC6+AD6 -> #REF! | AF6: =+AE6/Y6 -> #REF! | AG6: =+AE6/AB6 -> #REF!
B7: INFINITI | C7: =+N7+Y7 -> #REF! | D7: =+O7+Z7 -> #REF! | E7: =+P7+AA7 -> #REF! | F7: =+D7+E7 -> #REF! | G7: =+R7+AC7 -> #REF! | H7: =+S7+AD7 -> #REF! | I7: =+G7+H7 -> #REF! | J7: =+I7/C7 -> #REF! | K7: =+I7/F7 -> #REF! | M7: INFINITI | N7: =+#REF! -> #REF! | O7: =+#REF! -> #REF! | P7: =+#REF! -> #REF! | Q7: =+O7+P7 -> #REF! | R7: =+#REF! -> #REF! | S7: =+#REF! -> #REF! | T7: =+R7+S7 -> #REF! | U7: =+T7/N7 -> #REF! | V7: =+T7/Q7 -> #REF! | X7: INFINITI | Y7: =+#REF! -> #REF! | Z7: =+#REF! -> #REF! | AB7: =+Z7+AA7 -> #REF! | AC7: =+#REF! -> #REF! | AD7: =+#REF! -> #REF! | AE7: =+AC7+AD7 -> #REF! | AF7: =+AE7/Y7 -> #REF! | AG7: =+AE7/AB7 -> #REF!
B8: MCPA LAP | C8: =+N8+Y8 -> #REF! | D8: =+O8+Z8 -> #REF! | E8: =+P8+AA8 -> 0 | F8: =+D8+E8 -> #REF! | G8: =+R8+AC8 -> #REF! | H8: =+S8+AD8 -> #REF! | I8: =+G8+H8 -> #REF! | J8: =+I8/C8 -> #REF! | K8: =+I8/F8 -> #REF! | X8: MCPA LAP | Y8: =+#REF! -> #REF! | Z8: =+#REF! -> #REF! | AB8: =+Z8+AA8 -> #REF! | AC8: =+#REF! -> #REF! | AD8: =+#REF! -> #REF! | AE8: =+AC8+AD8 -> #REF! | AF8: =+AE8/Y8 -> #REF! | AG8: =+AE8/AB8 -> #REF!
B9: MCPA LAV | C9: =+N9+Y9 -> #REF! | D9: =+O9+Z9 -> #REF! | E9: =+P9+AA9 -> 0 | F9: =+D9+E9 -> #REF! | G9: =+R9+AC9 -> #REF! | H9: =+S9+AD9 -> #REF! | I9: =+G9+H9 -> #REF! | J9: =+I9/C9 -> #REF! | K9: =+I9/F9 -> #REF! | X9: MCPA LAV | Y9: =+#REF! -> #REF! | Z9: =+#REF! -> #REF! | AB9: =+Z9+AA9 -> #REF! | AC9: =+#REF! -> #REF! | AD9: =+#REF! -> #REF! | AE9: =+AC9+AD9 -> #REF! | AF9: =+AE9/Y9 -> #REF! | AG9: =+AE9/AB9 -> #REF!
B10: MCPA SPE | C10: =+N10+Y10 -> #REF! | D10: =+O10+Z10 -> #REF! | E10: =+P10+AA10 -> 0 | F10: =+D10+E10 -> #REF! | G10: =+R10+AC10 -> #REF! | H10: =+S10+AD10 -> #REF! | I10: =+G10+H10 -> #REF! | J10: =+I10/C10 -> #REF! | K10: =+I10/F10 -> #REF! | X10: MCPA SPE | Y10: =+#REF! -> #REF! | Z10: =+#REF! -> #REF! | AB10: =+Z10+AA10 -> #REF! | AC10: =+#REF! -> #REF! | AD10: =+#REF! -> #REF! | AE10: =+AC10+AD10 -> #REF! | AF10: =+AE10/Y10 -> #REF! | AG10: =+AE10/AB10 -> #REF!
B11: HONDA | C11: =+N11+Y11 -> #REF! | D11: =+O11+Z11 -> #REF! | E11: =+P11+AA11 -> #REF! | F11: =+D11+E11 -> #REF! | G11: =+R11+AC11 -> #REF! | H11: =+S11+AD11 -> #REF! | I11: =+G11+H11 -> #REF! | J11: =+I11/C11 -> #REF! | K11: =+I11/F11 -> #REF! | M11: HONDA | N11: =+#REF! -> #REF! | O11: =+#REF! -> #REF! | P11: =+#REF! -> #REF! | Q11: =+O11+P11 -> #REF! | R11: =+#REF! -> #REF! | S11: =+#REF! -> #REF! | T11: =+R11+S11 -> #REF! | U11: =+T11/N11 -> #REF! | V11: =+T11/Q11 -> #REF! | X11: HONDA | Y11: =+#REF! -> #REF! | Z11: =+#REF! -> #REF! | AB11: =+Z11+AA11 -> #REF! | AC11: =+#REF! -> #REF! | AD11: =+#REF! -> #REF! | AE11: =+AC11+AD11 -> #REF! | AF11: =+AE11/Y11 -> #REF! | AG11: =+AE11/AB11 -> #REF!
B12: TOYOTA | C12: =+N12+Y12 -> #REF! | D12: =+O12+Z12 -> #REF! | E12: =+P12+AA12 -> #REF! | F12: =+D12+E12 -> #REF! | G12: =+R12+AC12 -> #REF! | H12: =+S12+AD12 -> #REF! | I12: =+G12+H12 -> #REF! | J12: =+I12/C12 -> #REF! | K12: =+I12/F12 -> #REF! | M12: TOYOTA | N12: =+#REF! -> #REF! | O12: =+#REF! -> #REF! | P12: =+#REF! -> #REF! | Q12: =+O12+P12 -> #REF! | R12: =+#REF! -> #REF! | S12: =+#REF! -> #REF! | T12: =+R12+S12 -> #REF! | U12: =+T12/N12 -> #REF! | V12: =+T12/Q12 -> #REF! | X12: TOYOTA | Y12: =+#REF! -> #REF! | Z12: =+#REF! -> #REF! | AB12: =+Z12+AA12 -> #REF! | AC12: =+#REF! -> #REF! | AD12: =+#REF! -> #REF! | AE12: =+AC12+AD12 -> #REF! | AF12: =+AE12/Y12 -> #REF! | AG12: =+AE12/AB12 -> #REF!
B13: VOLKS | C13: =+N13+Y13 -> #REF! | D13: =+O13+Z13 -> #REF! | E13: =+P13+AA13 -> #REF! | F13: =+D13+E13 -> #REF! | G13: =+R13+AC13 -> #REF! | H13: =+S13+AD13 -> #REF! | I13: =+G13+H13 -> #REF! | J13: =+I13/C13 -> #REF! | K13: =+I13/F13 -> #REF! | M13: VOLKS | N13: =+#REF! -> #REF! | O13: =+#REF! -> #REF! | P13: =+#REF! -> #REF! | Q13: =+O13+P13 -> #REF! | R13: =+#REF! -> #REF! | S13: =+#REF! -> #REF! | T13: =+R13+S13 -> #REF! | U13: =+T13/N13 -> #REF! | V13: =+T13/Q13 -> #REF! | X13: VOLKS | Y13: =+#REF! -> #REF! | Z13: =+#REF! -> #REF! | AB13: =+Z13+AA13 -> #REF! | AC13: =+#REF! -> #REF! | AD13: =+#REF! -> #REF! | AE13: =+AC13+AD13 -> #REF! | AF13: =+AE13/Y13 -> #REF! | AG13: =+AE13/AB13 -> #REF!
B14: BMW PA | C14: =+N14+Y14 -> #REF! | D14: =+O14+Z14 -> #REF! | E14: =+P14+AA14 -> #REF! | F14: =+D14+E14 -> #REF! | G14: =+R14+AC14 -> #REF! | H14: =+S14+AD14 -> #REF! | I14: =+G14+H14 -> #REF! | J14: =+I14/C14 -> #REF! | K14: =+I14/F14 -> #REF! | M14: BMW PA | N14: =+#REF! -> #REF! | O14: =+#REF! -> #REF! | P14: =+#REF! -> #REF! | Q14: =+O14+P14 -> #REF! | R14: =+#REF! -> #REF! | S14: =+#REF! -> #REF! | T14: =+R14+S14 -> #REF! | U14: =+T14/N14 -> #REF! | V14: =+T14/Q14 -> #REF! | X14: BMW PA | Y14: =+#REF! -> #REF! | Z14: =+#REF! -> #REF! | AB14: =+Z14+AA14 -> #REF! | AC14: =+#REF! -> #REF! | AD14: =+#REF! -> #REF! | AE14: =+AC14+AD14 -> #REF! | AF14: =+AE14/Y14 -> #REF! | AG14: =+AE14/AB14 -> #REF!
B15: MINI | C15: =+N15+Y15 -> #REF! | D15: =+O15+Z15 -> #REF! | E15: =+P15+AA15 -> #REF! | F15: =+D15+E15 -> #REF! | G15: =+R15+AC15 -> #REF! | H15: =+S15+AD15 -> #REF! | I15: =+G15+H15 -> #REF! | J15: =+I15/C15 -> #REF! | K15: =+I15/F15 -> #REF! | M15: MINI | N15: =+#REF! -> #REF! | O15: =+#REF! -> #REF! | P15: =+#REF! -> #REF! | Q15: =+O15+P15 -> #REF! | R15: =+#REF! -> #REF! | S15: =+#REF! -> #REF! | T15: =+R15+S15 -> #REF! | U15: =+T15/N15 -> #REF! | V15: =+T15/Q15 -> #REF! | X15: MINI | Y15: =+#REF! -> #REF! | Z15: =+#REF! -> #REF! | AB15: =+Z15+AA15 -> #REF! | AC15: =+#REF! -> #REF! | AD15: =+#REF! -> #REF! | AE15: =+AC15+AD15 -> #REF! | AF15: =+AE15/Y15 -> #REF! | AG15: =+AE15/AB15 -> #REF!
B16: BMW STJ | C16: =+N16+Y16 -> #REF! | D16: =+O16+Z16 -> #REF! | E16: =+P16+AA16 -> #REF! | F16: =+D16+E16 -> #REF! | G16: =+R16+AC16 -> #REF! | H16: =+S16+AD16 -> #REF! | I16: =+G16+H16 -> #REF! | J16: =+I16/C16 -> #REF! | K16: =+I16/F16 -> #REF! | M16: BMW STJ | N16: =+#REF! -> #REF! | O16: =+#REF! -> #REF! | P16: =+#REF! -> #REF! | Q16: =+O16+P16 -> #REF! | R16: =+#REF! -> #REF! | S16: =+#REF! -> #REF! | T16: =+R16+S16 -> #REF! | U16: =+T16/N16 -> #REF! | V16: =+T16/Q16 -> #REF! | X16: BMW STJ | Y16: =+#REF! -> #REF! | Z16: =+#REF! -> #REF! | AB16: =+Z16+AA16 -> #REF! | AC16: =+#REF! -> #REF! | AD16: =+#REF! -> #REF! | AE16: =+AC16+AD16 -> #REF! | AF16: =+AE16/Y16 -> #REF! | AG16: =+AE16/AB16 -> #REF!
B17: LEXUS | C17: =+N17+Y17 -> #REF! | D17: =+O17+Z17 -> #REF! | E17: =+P17+AA17 -> #REF! | F17: =+D17+E17 -> #REF! | G17: =+R17+AC17 -> #REF! | H17: =+S17+AD17 -> #REF! | I17: =+G17+H17 -> #REF! | J17: =+I17/C17 -> #REF! | K17: =+I17/F17 -> #REF! | M17: LEXUS | N17: =+#REF! -> #REF! | O17: =+#REF! -> #REF! | P17: =+#REF! -> #REF! | Q17: =+O17+P17 -> #REF! | R17: =+#REF! -> #REF! | S17: =+#REF! -> #REF! | T17: =+R17+S17 -> #REF! | U17: =+T17/N17 -> #REF! | V17: =+T17/Q17 -> #REF! | X17: LEXUS | Y17: =+#REF! -> #REF! | Z17: =+#REF! -> #REF! | AB17: =+Z17+AA17 -> #REF! | AC17: =+#REF! -> #REF! | AD17: =+#REF! -> #REF! | AE17: =+AC17+AD17 -> #REF! | AF17: =+AE17/Y17 -> #REF! | AG17: =+AE17/AB17 -> #REF!
B18: BMW SHER | C18: =+N18+Y18 -> #REF! | D18: =+O18+Z18 -> #REF! | E18: =+P18+AA18 -> #REF! | F18: =+D18+E18 -> #REF! | G18: =+R18+AC18 -> #REF! | H18: =+S18+AD18 -> #REF! | I18: =+G18+H18 -> #REF! | J18: =+I18/C18 -> #REF! | K18: =+I18/F18 -> #REF! | M18: BMW SHER | N18: =+#REF! -> #REF! | O18: =+#REF! -> #REF! | P18: =+#REF! -> #REF! | Q18: =+O18+P18 -> #REF! | R18: =+#REF! -> #REF! | S18: =+#REF! -> #REF! | T18: =+R18+S18 -> #REF! | U18: =+T18/N18 -> #REF! | V18: =+T18/Q18 -> #REF! | X18: BMW SHER | Y18: =+#REF! -> #REF! | Z18: =+#REF! -> #REF! | AB18: =+Z18+AA18 -> #REF! | AC18: =+#REF! -> #REF! | AD18: =+#REF! -> #REF! | AE18: =+AC18+AD18 -> #REF! | AF18: =+AE18/Y18 -> #REF! | AG18: =+AE18/AB18 -> #REF!
B19: SSMB | C19: =+N19+Y19 -> #REF! | D19: =+O19+Z19 -> #REF! | E19: =+P19+AA19 -> #REF! | F19: =+D19+E19 -> #REF! | G19: =+R19+AC19 -> #REF! | H19: =+S19+AD19 -> #REF! | I19: =+G19+H19 -> #REF! | J19: =+I19/C19 -> #REF! | K19: =+I19/F19 -> #REF! | M19: SSMB | N19: =+#REF! -> #REF! | O19: =+#REF! -> #REF! | P19: =+#REF! -> #REF! | Q19: =+O19+P19 -> #REF! | R19: =+#REF! -> #REF! | S19: =+#REF! -> #REF! | T19: =+R19+S19 -> #REF! | U19: =+T19/N19 -> #REF! | V19: =+T19/Q19 -> #REF! | X19: SSMB | Y19: =+#REF! -> #REF! | Z19: =+#REF! -> #REF! | AB19: =+Z19+AA19 -> #REF! | AC19: =+#REF! -> #REF! | AD19: =+#REF! -> #REF! | AE19: =+AC19+AD19 -> #REF! | AF19: =+AE19/Y19 -> #REF! | AG19: =+AE19/AB19 -> #REF!
B20: MBQ | C20: =+N20+Y20 -> #REF! | D20: =+O20+Z20 -> #REF! | E20: =+P20+AA20 -> #REF! | F20: =+D20+E20 -> #REF! | G20: =+R20+AC20 -> #REF! | H20: =+S20+AD20 -> #REF! | I20: =+G20+H20 -> #REF! | J20: =+I20/C20 -> #REF! | K20: =+I20/F20 -> #REF! | M20: MBQ | N20: =+#REF! -> #REF! | O20: =+#REF! -> #REF! | P20: =+#REF! -> #REF! | Q20: =+O20+P20 -> #REF! | R20: =+#REF! -> #REF! | S20: =+#REF! -> #REF! | T20: =+R20+S20 -> #REF! | U20: =+T20/N20 -> #REF! | V20: =+T20/Q20 -> #REF! | X20: MBQ | Y20: =+#REF! -> #REF! | Z20: =+#REF! -> #REF! | AB20: =+Z20+AA20 -> #REF! | AC20: =+#REF! -> #REF! | AD20: =+#REF! -> #REF! | AE20: =+AC20+AD20 -> #REF! | AF20: =+AE20/Y20 -> #REF! | AG20: =+AE20/AB20 -> #REF!
B21: VOLVO | C21: =+N21+Y21 -> #REF! | D21: =+O21+Z21 -> #REF! | E21: =+P21+AA21 -> #REF! | F21: =+D21+E21 -> #REF! | G21: =+R21+AC21 -> #REF! | H21: =+S21+AD21 -> #REF! | I21: =+G21+H21 -> #REF! | J21: =+I21/C21 -> #REF! | K21: =+I21/F21 -> #REF! | M21: VOLVO | N21: =+#REF! -> #REF! | O21: =+#REF! -> #REF! | P21: =+#REF! -> #REF! | Q21: =+O21+P21 -> #REF! | R21: =+#REF! -> #REF! | S21: =+#REF! -> #REF! | T21: =+R21+S21 -> #REF! | U21: =+T21/N21 -> #REF! | V21: =+T21/Q21 -> #REF! | X21: VOLVO | Y21: =+#REF! -> #REF! | Z21: =+#REF! -> #REF! | AB21: =+Z21+AA21 -> #REF! | AC21: =+#REF! -> #REF! | AD21: =+#REF! -> #REF! | AE21: =+AC21+AD21 -> #REF! | AF21: =+AE21/Y21 -> #REF! | AG21: =+AE21/AB21 -> #REF!
B22: JLR | C22: =+N22+Y22 -> #REF! | D22: =+O22+Z22 -> #REF! | E22: =+P22+AA22 -> #REF! | F22: =+D22+E22 -> #REF! | G22: =+R22+AC22 -> #REF! | H22: =+S22+AD22 -> #REF! | I22: =+G22+H22 -> #REF! | J22: =+I22/C22 -> #REF! | K22: =+I22/F22 -> #REF! | M22: JLR | N22: =+#REF! -> #REF! | O22: =+#REF! -> #REF! | P22: =+#REF! -> #REF! | Q22: =+O22+P22 -> #REF! | R22: =+#REF! -> #REF! | S22: =+#REF! -> #REF! | T22: =+R22+S22 -> #REF! | U22: =+T22/N22 -> #REF! | V22: =+T22/Q22 -> #REF! | X22: JLR | Y22: =+#REF! -> #REF! | Z22: =+#REF! -> #REF! | AB22: =+Z22+AA22 -> #REF! | AC22: =+#REF! -> #REF! | AD22: =+#REF! -> #REF! | AE22: =+AC22+AD22 -> #REF! | AF22: =+AE22/Y22 -> #REF! | AG22: =+AE22/AB22 -> #REF!
B23: LHD | C23: =+N23+Y23 -> #REF! | D23: =+O23+Z23 -> #REF! | E23: =+P23+AA23 -> #REF! | F23: =+D23+E23 -> #REF! | G23: =+R23+AC23 -> #REF! | H23: =+S23+AD23 -> #REF! | I23: =+G23+H23 -> #REF! | J23: =+I23/C23 -> #REF! | K23: =+I23/F23 -> #REF! | M23: LHD | N23: =+#REF! -> #REF! | O23: =+#REF! -> #REF! | P23: =+#REF! -> #REF! | Q23: =+O23+P23 -> #REF! | R23: =+#REF! -> #REF! | S23: =+#REF! -> #REF! | T23: =+R23+S23 -> #REF! | U23: =+T23/N23 -> #REF! | V23: =+T23/Q23 -> #REF! | X23: LHD | Y23: =+#REF! -> #REF! | Z23: =+#REF! -> #REF! | AB23: =+Z23+AA23 -> #REF! | AC23: =+#REF! -> #REF! | AD23: =+#REF! -> #REF! | AE23: =+AC23+AD23 -> #REF! | AF23: =+AE23/Y23 -> #REF! | AG23: =+AE23/AB23 -> #REF!
B25: BUDGET | M25: BUDGET | X25: BUDGET
B26: STORE | C26: Units | D26: Margin | E26: Margin demo | F26: Front margin | G26: frais de livraison | H26: Ent. Stock | I26: Delivery fee | J26: Delivery fee / unit | K26: % Delivery fee / Front margin | M26: STORE | N26: Units | O26: M. new | P26: M. Demos | Q26: Front margin | R26: frais de livraison | S26: Ent. Stock | T26: Delivery fee | U26: Delivery fee / unit | V26: % Delivery fee / Front margin | X26: STORE | Y26: Units | Z26: M. used | AB26: Front margin | AC26: frais de livraison | AD26: Ent. Stock | AE26: Delivery fee | AF26: Delivery fee / unit | AG26: % Delivery fee / Front margin
B27: TOTAL | C27: =+SUM(C28:C45) -> #REF! | D27: =+SUM(D28:D45) -> #REF! | E27: =+SUM(E28:E45) -> #REF! | F27: =+SUM(F28:F45) -> #REF! | G27: =+SUM(G28:G45) -> #REF! | H27: =+SUM(H28:H45) -> #REF! | I27: =+SUM(I28:I45) -> #REF! | J27: =+I27/C27 -> #REF! | K27: =+I27/F27 -> #REF! | M27: TOTAL | N27: =+SUM(N28:N45) -> #REF! | O27: =+SUM(O28:O45) -> #REF! | P27: =+SUM(P28:P45) -> #REF! | Q27: =+SUM(Q28:Q45) -> #REF! | R27: =+SUM(R28:R45) -> #REF! | S27: =+SUM(S28:S45) -> #REF! | T27: =+SUM(T28:T45) -> #REF! | U27: =+T27/N27 -> #REF! | V27: =+T27/Q27 -> #REF! | X27: TOTAL | Y27: =+SUM(Y28:Y45) -> #REF! | Z27: =+SUM(Z28:Z45) -> #REF! | AB27: =+SUM(AB28:AB45) -> #REF! | AC27: =+SUM(AC28:AC45) -> #REF! | AD27: =+SUM(AD28:AD45) -> #REF! | AE27: =+SUM(AE28:AE45) -> #REF! | AF27: =+AE27/Y27 -> #REF! | AG27: =+AE27/AB27 -> #REF!
B28: AUDI | C28: =+N28+Y28 -> #REF! | D28: =+O28+Z28 -> #REF! | E28: =+P28+AA28 -> #REF! | F28: =+D28+E28 -> #REF! | G28: =+R28+AC28 -> #REF! | H28: =+S28+AD28 -> #REF! | I28: =+G28+H28 -> #REF! | J28: =+I28/C28 -> #REF! | K28: =+I28/F28 -> #REF! | M28: AUDI | N28: =+#REF! -> #REF! | O28: =+#REF! -> #REF! | P28: =+#REF! -> #REF! | Q28: =+O28+P28 -> #REF! | R28: =+#REF! -> #REF! | S28: =+#REF! -> #REF! | T28: =+R28+S28 -> #REF! | U28: =+T28/N28 -> #REF! | V28: =+T28/Q28 -> #REF! | X28: AUDI | Y28: =+#REF! -> #REF! | Z28: =+#REF! -> #REF! | AB28: =+Z28+AA28 -> #REF! | AC28: =+#REF! -> #REF! | AD28: =+#REF! -> #REF! | AE28: =+AC28+AD28 -> #REF! | AF28: =+AE28/Y28 -> #REF! | AG28: =+AE28/AB28 -> #REF!
B29: INFINITI | C29: =+N29+Y29 -> #REF! | D29: =+O29+Z29 -> #REF! | E29: =+P29+AA29 -> #REF! | F29: =+D29+E29 -> #REF! | G29: =+R29+AC29 -> #REF! | H29: =+S29+AD29 -> #REF! | I29: =+G29+H29 -> #REF! | J29: =+I29/C29 -> #REF! | K29: =+I29/F29 -> #REF! | M29: INFINITI | N29: =+#REF! -> #REF! | O29: =+#REF! -> #REF! | P29: =+#REF! -> #REF! | Q29: =+O29+P29 -> #REF! | R29: =+#REF! -> #REF! | S29: =+#REF! -> #REF! | T29: =+R29+S29 -> #REF! | U29: =+T29/N29 -> #REF! | V29: =+T29/Q29 -> #REF! | X29: INFINITI | Y29: =+#REF! -> #REF! | Z29: =+#REF! -> #REF! | AB29: =+Z29+AA29 -> #REF! | AC29: =+#REF! -> #REF! | AD29: =+#REF! -> #REF! | AE29: =+AC29+AD29 -> #REF! | AF29: =+AE29/Y29 -> #REF! | AG29: =+AE29/AB29 -> #REF!
B30: MCPA LAP | C30: =+N30+Y30 -> #REF! | D30: =+O30+Z30 -> #REF! | E30: =+P30+AA30 -> 0 | F30: =+D30+E30 -> #REF! | G30: =+R30+AC30 -> #REF! | H30: =+S30+AD30 -> #REF! | I30: =+G30+H30 -> #REF! | J30: =+I30/C30 -> #REF! | K30: =+I30/F30 -> #REF! | X30: MCPA LAP | Y30: =+#REF! -> #REF! | Z30: =+#REF! -> #REF! | AB30: =+Z30+AA30 -> #REF! | AC30: =+#REF! -> #REF! | AD30: =+#REF! -> #REF! | AE30: =+AC30+AD30 -> #REF! | AF30: =+AE30/Y30 -> #REF! | AG30: =+AE30/AB30 -> #REF!
B31: MCPA LAV | C31: =+N31+Y31 -> #REF! | D31: =+O31+Z31 -> #REF! | E31: =+P31+AA31 -> 0 | F31: =+D31+E31 -> #REF! | G31: =+R31+AC31 -> #REF! | H31: =+S31+AD31 -> #REF! | I31: =+G31+H31 -> #REF! | J31: =+I31/C31 -> #REF! | K31: =+I31/F31 -> #REF! | X31: MCPA LAV | Y31: =+#REF! -> #REF! | Z31: =+#REF! -> #REF! | AB31: =+Z31+AA31 -> #REF! | AC31: =+#REF! -> #REF! | AD31: =+#REF! -> #REF! | AE31: =+AC31+AD31 -> #REF! | AF31: =+AE31/Y31 -> #REF! | AG31: =+AE31/AB31 -> #REF!
B32: MCPA SPE | C32: =+N32+Y32 -> #REF! | D32: =+O32+Z32 -> #REF! | E32: =+P32+AA32 -> 0 | F32: =+D32+E32 -> #REF! | G32: =+R32+AC32 -> #REF! | H32: =+S32+AD32 -> #REF! | I32: =+G32+H32 -> #REF! | J32: =+I32/C32 -> #REF! | K32: =+I32/F32 -> #REF! | X32: MCPA SPE | Y32: =+#REF! -> #REF! | Z32: =+#REF! -> #REF! | AB32: =+Z32+AA32 -> #REF! | AC32: =+#REF! -> #REF! | AD32: =+#REF! -> #REF! | AE32: =+AC32+AD32 -> #REF! | AF32: =+AE32/Y32 -> #REF! | AG32: =+AE32/AB32 -> #REF!
B33: HONDA | C33: =+N33+Y33 -> #REF! | D33: =+O33+Z33 -> #REF! | E33: =+P33+AA33 -> #REF! | F33: =+D33+E33 -> #REF! | G33: =+R33+AC33 -> #REF! | H33: =+S33+AD33 -> #REF! | I33: =+G33+H33 -> #REF! | J33: =+I33/C33 -> #REF! | K33: =+I33/F33 -> #REF! | M33: HONDA | N33: =+#REF! -> #REF! | O33: =+#REF! -> #REF! | P33: =+#REF! -> #REF! | Q33: =+O33+P33 -> #REF! | R33: =+#REF! -> #REF! | S33: =+#REF! -> #REF! | T33: =+R33+S33 -> #REF! | U33: =+T33/N33 -> #REF! | V33: =+T33/Q33 -> #REF! | X33: HONDA | Y33: =+#REF! -> #REF! | Z33: =+#REF! -> #REF! | AB33: =+Z33+AA33 -> #REF! | AC33: =+#REF! -> #REF! | AD33: =+#REF! -> #REF! | AE33: =+AC33+AD33 -> #REF! | AF33: =+AE33/Y33 -> #REF! | AG33: =+AE33/AB33 -> #REF!
B34: TOYOTA | C34: =+N34+Y34 -> #REF! | D34: =+O34+Z34 -> #REF! | E34: =+P34+AA34 -> #REF! | F34: =+D34+E34 -> #REF! | G34: =+R34+AC34 -> #REF! | H34: =+S34+AD34 -> #REF! | I34: =+G34+H34 -> #REF! | J34: =+I34/C34 -> #REF! | K34: =+I34/F34 -> #REF! | M34: TOYOTA | N34: =+#REF! -> #REF! | O34: =+#REF! -> #REF! | P34: =+#REF! -> #REF! | Q34: =+O34+P34 -> #REF! | R34: =+#REF! -> #REF! | S34: =+#REF! -> #REF! | T34: =+R34+S34 -> #REF! | U34: =+T34/N34 -> #REF! | V34: =+T34/Q34 -> #REF! | X34: TOYOTA | Y34: =+#REF! -> #REF! | Z34: =+#REF! -> #REF! | AB34: =+Z34+AA34 -> #REF! | AC34: =+#REF! -> #REF! | AD34: =+#REF! -> #REF! | AE34: =+AC34+AD34 -> #REF! | AF34: =+AE34/Y34 -> #REF! | AG34: =+AE34/AB34 -> #REF!
B35: VOLKS | C35: =+N35+Y35 -> #REF! | D35: =+O35+Z35 -> #REF! | E35: =+P35+AA35 -> #REF! | F35: =+D35+E35 -> #REF! | G35: =+R35+AC35 -> #REF! | H35: =+S35+AD35 -> #REF! | I35: =+G35+H35 -> #REF! | J35: =+I35/C35 -> #REF! | K35: =+I35/F35 -> #REF! | M35: VOLKS | N35: =+#REF! -> #REF! | O35: =+#REF! -> #REF! | P35: =+#REF! -> #REF! | Q35: =+O35+P35 -> #REF! | R35: =+#REF! -> #REF! | S35: =+#REF! -> #REF! | T35: =+R35+S35 -> #REF! | U35: =+T35/N35 -> #REF! | V35: =+T35/Q35 -> #REF! | X35: VOLKS | Y35: =+#REF! -> #REF! | Z35: =+#REF! -> #REF! | AB35: =+Z35+AA35 -> #REF! | AC35: =+#REF! -> #REF! | AD35: =+#REF! -> #REF! | AE35: =+AC35+AD35 -> #REF! | AF35: =+AE35/Y35 -> #REF! | AG35: =+AE35/AB35 -> #REF!
B36: BMW PA | C36: =+N36+Y36 -> #REF! | D36: =+O36+Z36 -> #REF! | E36: =+P36+AA36 -> #REF! | F36: =+D36+E36 -> #REF! | G36: =+R36+AC36 -> #REF! | H36: =+S36+AD36 -> #REF! | I36: =+G36+H36 -> #REF! | J36: =+I36/C36 -> #REF! | K36: =+I36/F36 -> #REF! | M36: BMW PA | N36: =+#REF! -> #REF! | O36: =+#REF! -> #REF! | P36: =+#REF! -> #REF! | Q36: =+O36+P36 -> #REF! | R36: =+#REF! -> #REF! | S36: =+#REF! -> #REF! | T36: =+R36+S36 -> #REF! | U36: =+T36/N36 -> #REF! | V36: =+T36/Q36 -> #REF! | X36: BMW PA | Y36: =+#REF! -> #REF! | Z36: =+#REF! -> #REF! | AB36: =+Z36+AA36 -> #REF! | AC36: =+#REF! -> #REF! | AD36: =+#REF! -> #REF! | AE36: =+AC36+AD36 -> #REF! | AF36: =+AE36/Y36 -> #REF! | AG36: =+AE36/AB36 -> #REF!
B37: MINI | C37: =+N37+Y37 -> #REF! | D37: =+O37+Z37 -> #REF! | E37: =+P37+AA37 -> #REF! | F37: =+D37+E37 -> #REF! | G37: =+R37+AC37 -> #REF! | H37: =+S37+AD37 -> #REF! | I37: =+G37+H37 -> #REF! | J37: =+I37/C37 -> #REF! | K37: =+I37/F37 -> #REF! | M37: MINI | N37: =+#REF! -> #REF! | O37: =+#REF! -> #REF! | P37: =+#REF! -> #REF! | Q37: =+O37+P37 -> #REF! | R37: =+#REF! -> #REF! | S37: =+#REF! -> #REF! | T37: =+R37+S37 -> #REF! | U37: =+T37/N37 -> #REF! | V37: =+T37/Q37 -> #REF! | X37: MINI | Y37: =+#REF! -> #REF! | Z37: =+#REF! -> #REF! | AB37: =+Z37+AA37 -> #REF! | AC37: =+#REF! -> #REF! | AD37: =+#REF! -> #REF! | AE37: =+AC37+AD37 -> #REF! | AF37: =+AE37/Y37 -> #REF! | AG37: =+AE37/AB37 -> #REF!
B38: BMW STJ | C38: =+N38+Y38 -> #REF! | D38: =+O38+Z38 -> #REF! | E38: =+P38+AA38 -> #REF! | F38: =+D38+E38 -> #REF! | G38: =+R38+AC38 -> #REF! | H38: =+S38+AD38 -> #REF! | I38: =+G38+H38 -> #REF! | J38: =+I38/C38 -> #REF! | K38: =+I38/F38 -> #REF! | M38: BMW STJ | N38: =+#REF! -> #REF! | O38: =+#REF! -> #REF! | P38: =+#REF! -> #REF! | Q38: =+O38+P38 -> #REF! | R38: =+#REF! -> #REF! | S38: =+#REF! -> #REF! | T38: =+R38+S38 -> #REF! | U38: =+T38/N38 -> #REF! | V38: =+T38/Q38 -> #REF! | X38: BMW STJ | Y38: =+#REF! -> #REF! | Z38: =+#REF! -> #REF! | AB38: =+Z38+AA38 -> #REF! | AC38: =+#REF! -> #REF! | AD38: =+#REF! -> #REF! | AE38: =+AC38+AD38 -> #REF! | AF38: =+AE38/Y38 -> #REF! | AG38: =+AE38/AB38 -> #REF!
B39: LEXUS | C39: =+N39+Y39 -> #REF! | D39: =+O39+Z39 -> #REF! | E39: =+P39+AA39 -> #REF! | F39: =+D39+E39 -> #REF! | G39: =+R39+AC39 -> #REF! | H39: =+S39+AD39 -> #REF! | I39: =+G39+H39 -> #REF! | J39: =+I39/C39 -> #REF! | K39: =+I39/F39 -> #REF! | M39: LEXUS | N39: =+#REF! -> #REF! | O39: =+#REF! -> #REF! | P39: =+#REF! -> #REF! | Q39: =+O39+P39 -> #REF! | R39: =+#REF! -> #REF! | S39: =+#REF! -> #REF! | T39: =+R39+S39 -> #REF! | U39: =+T39/N39 -> #REF! | V39: =+T39/Q39 -> #REF! | X39: LEXUS | Y39: =+#REF! -> #REF! | Z39: =+#REF! -> #REF! | AB39: =+Z39+AA39 -> #REF! | AC39: =+#REF! -> #REF! | AD39: =+#REF! -> #REF! | AE39: =+AC39+AD39 -> #REF! | AF39: =+AE39/Y39 -> #REF! | AG39: =+AE39/AB39 -> #REF!
B40: BMW SHER | C40: =+N40+Y40 -> #REF! | D40: =+O40+Z40 -> #REF! | E40: =+P40+AA40 -> #REF! | F40: =+D40+E40 -> #REF! | G40: =+R40+AC40 -> #REF! | H40: =+S40+AD40 -> #REF! | I40: =+G40+H40 -> #REF! | J40: =+I40/C40 -> #REF! | K40: =+I40/F40 -> #REF! | M40: BMW SHER | N40: =+#REF! -> #REF! | O40: =+#REF! -> #REF! | P40: =+#REF! -> #REF! | Q40: =+O40+P40 -> #REF! | R40: =+#REF! -> #REF! | S40: =+#REF! -> #REF! | T40: =+R40+S40 -> #REF! | U40: =+T40/N40 -> #REF! | V40: =+T40/Q40 -> #REF! | X40: BMW SHER | Y40: =+#REF! -> #REF! | Z40: =+#REF! -> #REF! | AB40: =+Z40+AA40 -> #REF! | AC40: =+#REF! -> #REF! | AD40: =+#REF! -> #REF! | AE40: =+AC40+AD40 -> #REF! | AF40: =+AE40/Y40 -> #REF! | AG40: =+AE40/AB40 -> #REF!
B41: SSMB | C41: =+N41+Y41 -> #REF! | D41: =+O41+Z41 -> #REF! | E41: =+P41+AA41 -> #REF! | F41: =+D41+E41 -> #REF! | G41: =+R41+AC41 -> #REF! | H41: =+S41+AD41 -> #REF! | I41: =+G41+H41 -> #REF! | J41: =+I41/C41 -> #REF! | K41: =+I41/F41 -> #REF! | M41: SSMB | N41: =+#REF! -> #REF! | O41: =+#REF! -> #REF! | P41: =+#REF! -> #REF! | Q41: =+O41+P41 -> #REF! | R41: =+#REF! -> #REF! | S41: =+#REF! -> #REF! | T41: =+R41+S41 -> #REF! | U41: =+T41/N41 -> #REF! | V41: =+T41/Q41 -> #REF! | X41: SSMB | Y41: =+#REF! -> #REF! | Z41: =+#REF! -> #REF! | AB41: =+Z41+AA41 -> #REF! | AC41: =+#REF! -> #REF! | AD41: =+#REF! -> #REF! | AE41: =+AC41+AD41 -> #REF! | AF41: =+AE41/Y41 -> #REF! | AG41: =+AE41/AB41 -> #REF!
B42: MBQ | C42: =+N42+Y42 -> #REF! | D42: =+O42+Z42 -> #REF! | E42: =+P42+AA42 -> #REF! | F42: =+D42+E42 -> #REF! | G42: =+R42+AC42 -> #REF! | H42: =+S42+AD42 -> #REF! | I42: =+G42+H42 -> #REF! | J42: =+I42/C42 -> #REF! | K42: =+I42/F42 -> #REF! | M42: MBQ | N42: =+#REF! -> #REF! | O42: =+#REF! -> #REF! | P42: =+#REF! -> #REF! | Q42: =+O42+P42 -> #REF! | R42: =+#REF! -> #REF! | S42: =+#REF! -> #REF! | T42: =+R42+S42 -> #REF! | U42: =+T42/N42 -> #REF! | V42: =+T42/Q42 -> #REF! | X42: MBQ | Y42: =+#REF! -> #REF! | Z42: =+#REF! -> #REF! | AB42: =+Z42+AA42 -> #REF! | AC42: =+#REF! -> #REF! | AD42: =+#REF! -> #REF! | AE42: =+AC42+AD42 -> #REF! | AF42: =+AE42/Y42 -> #REF! | AG42: =+AE42/AB42 -> #REF!
...

Sheet Mensuel
C1: Réalisé Annuel | D1: Janvier | G1: Février | J1: Mars | M1: Avril | P1: Mai | S1: Juin | V1: Juillet | Y1: Août | AB1: Septembre | AE1: Octobre | AH1: Novembre | AK1: Décembre | AN1: Total (YTD)
D2: 1 | G2: 2 | J2: 3 | M2: 4 | P2: 5 | S2: 6 | V2: 7 | Y2: 8 | AB2: 9 | AE2: 10 | AH2: 11 | AK2: 12
C3: Véhicules neufs | D3: RÉALISATION | G3: RÉALISATION | J3: RÉALISATION | M3: RÉALISATION | P3: RÉALISATION | S3: RÉALISATION | V3: RÉALISATION | Y3: RÉALISATION | AB3: RÉALISATION | AE3: RÉALISATION | AH3: RÉALISATION | AK3: RÉALISATION | AN3: RÉALISATION
D4: UNITE | E4: $P/UNITE | F4: $PROFITS | G4: UNITE | H4: $P/UNITE | I4: $PROFITS | J4: UNITE | K4: $P/UNITE | L4: $PROFITS | M4: UNITE | N4: $P/UNITE | O4: $PROFITS | P4: UNITE | Q4: $P/UNITE | R4: $PROFITS | S4: UNITE | T4: $P/UNITE | U4: $PROFITS | V4: UNITE | W4: $P/UNITE | X4: $PROFITS | Y4: UNITE | Z4: $P/UNITE | AA4: $PROFITS | AB4: UNITE | AC4: $P/UNITE | AD4: $PROFITS | AE4: UNITE | AF4: $P/UNITE | AG4: $PROFITS | AH4: UNITE | AI4: $P/UNITE | AJ4: $PROFITS | AK4: UNITE | AL4: $P/UNITE | AM4: $PROFITS | AN4: UNITE | AO4: $P/UNITE | AP4: $PROFITS
A5: =+B5&C5 -> Véhicules neufsVentes nettes | B5: Véhicules neufs | C5: Ventes nettes | F5: ='1'!$L$5 -> 1000810 | I5: ='2'!$L$5 -> 2019283.1 | L5: ='3'!$L$5 -> 3240605.2 | O5: ='4'!$L$5 -> 3185397.8 | R5: ='5'!$L$5 -> 3760930 | U5: ='6'!$L$5 -> 2741022.2 | X5: ='7'!$L$5 -> 18845742 | AA5: ='8'!$L$5 -> 22095178 | AD5: ='9'!$L$5 -> 0 | AG5: ='10'!$L$5 -> 0 | AJ5: ='11'!$L$5 -> 0 | AM5: ='12'!$L$5 -> 0 | AP5: =SUM(F5,I5,L5,O5,R5,U5,X5,AA5,AD5,AG5,AJ5,AM5) -> 56888968
A6: =+B6&C6 -> Véhicules neufsAutos détail | B6: Véhicules neufs | C6: Autos détail | D6: ='1'!$J$6 -> 7 | E6: =IF(D6=0,0,F6/D6) -> 590.46 | F6: ='1'!$L$6 -> 4133.22 | G6: ='2'!$J$6 -> 15 | H6: =IF(G6=0,0,I6/G6) -> 1396.284 | I6: ='2'!$L$6 -> 20944.26 | J6: ='3'!$J$6 -> 32 | K6: =IF(J6=0,0,L6/J6) -> 1097.7472 | L6: ='3'!$L$6 -> 35127.91 | M6: ='4'!$J$6 -> 24 | N6: =IF(M6=0,0,O6/M6) -> 474.33792 | O6: ='4'!$L$6 -> 11384.11 | P6: ='5'!$J$6 -> 25 | Q6: =IF(P6=0,0,R6/P6) -> 1020.836 | R6: ='5'!$L$6 -> 25520.9 | S6: ='6'!$J$6 -> 23 | T6: =IF(S6=0,0,U6/S6) -> 1164.0583 | U6: ='6'!$L$6 -> 26773.34 | V6: ='7'!$J$6 -> 150 | W6: =IF(V6=0,0,X6/V6) -> 1030.7103 | X6: ='7'!$L$6 -> 154606.55 | Y6: ='8'!$J$6 -> 174 | Z6: =IF(Y6=0,0,AA6/Y6) -> 1036.2561 | AA6: ='8'!$L$6 -> 180308.56 | AB6: ='9'!$J$6 -> 0 | AC6: =IF(AB6=0,0,AD6/AB6) -> 0 | AD6: ='9'!$L$6 -> 0 | AE6: ='10'!$J$6 -> 0 | AF6: =IF(AE6=0,0,AG6/AE6) -> 0 | AG6: ='10'!$L$6 -> 0 | AH6: ='11'!$J$6 -> 0 | AI6: =IF(AH6=0,0,AJ6/AH6) -> 0 | AJ6: ='11'!$L$6 -> 0 | AK6: ='12'!$J$6 -> 0 | AL6: =IF(AK6=0,0,AM6/AK6) -> 0 | AM6: ='12'!$L$6 -> 0 | AN6: =SUM(D6,G6,J6,M6,P6,S6,V6,Y6,AB6,AE6,AH6,AK6) -> 450 | AO6: =IF(AN6=0,0,AP6/AN6) -> 1019.553 | AP6: =SUM(F6,I6,L6,O6,R6,U6,X6,AA6,AD6,AG6,AJ6,AM6) -> 458798.85
A7: =+B7&C7 -> Véhicules neufsCamions détail | B7: Véhicules neufs | C7: Camions détail | D7: ='1'!$J$7 -> 13 | E7: =IF(D7=0,0,F7/D7) -> 1549.7277 | F7: ='1'!$L$7 -> 20146.46 | G7: ='2'!$J$7 -> 21 | H7: =IF(G7=0,0,I7/G7) -> 2079.4924 | I7: ='2'!$L$7 -> 43669.34 | J7: ='3'!$J$7 -> 37 | K7: =IF(J7=0,0,L7/J7) -> 2171.0773 | L7: ='3'!$L$7 -> 80329.86 | M7: ='4'!$J$7 -> 41 | N7: =IF(M7=0,0,O7/M7) -> 2167.9161 | O7: ='4'!$L$7 -> 88884.56 | P7: ='5'!$J$7 -> 58 | Q7: =IF(P7=0,0,R7/P7) -> 2126.4852 | R7: ='5'!$L$7 -> 123336.14 | S7: ='6'!$J$7 -> 32 | T7: =IF(S7=0,0,U7/S7) -> 2323.7591 | U7: ='6'!$L$7 -> 74360.29 | V7: ='7'!$J$7 -> 239 | W7: =IF(V7=0,0,X7/V7) -> 2180.0418 | X7: ='7'!$L$7 -> 521029.98 | Y7: ='8'!$J$7 -> 278 | Z7: =IF(Y7=0,0,AA7/Y7) -> 2164.2449 | AA7: ='8'!$L$7 -> 601660.08 | AB7: ='9'!$J$7 -> 0 | AC7: =IF(AB7=0,0,AD7/AB7) -> 0 | AD7: ='9'!$L$7 -> 0 | AE7: ='10'!$J$7 -> 0 | AF7: =IF(AE7=0,0,AG7/AE7) -> 0 | AG7: ='10'!$L$7 -> 0 | AH7: ='11'!$J$7 -> 0 | AI7: =IF(AH7=0,0,AJ7/AH7) -> 0 | AJ7: ='11'!$L$7 -> 0 | AK7: ='12'!$J$7 -> 0 | AL7: =IF(AK7=0,0,AM7/AK7) -> 0 | AM7: ='12'!$L$7 -> 0 | AN7: =SUM(D7,G7,J7,M7,P7,S7,V7,Y7,AB7,AE7,AH7,AK7) -> 719 | AO7: =IF(AN7=0,0,AP7/AN7) -> 2160.5239 | AP7: =SUM(F7,I7,L7,O7,R7,U7,X7,AA7,AD7,AG7,AJ7,AM7) -> 1553416.7
A8: =+B8&C8 -> Véhicules neufsSprinter | B8: Véhicules neufs | C8: Sprinter | D8: ='1'!$J$8 -> 0 | E8: =IF(D8=0,0,F8/D8) -> 0 | F8: ='1'!$L$8 -> 0 | G8: ='2'!$J$8 -> 0 | H8: =IF(G8=0,0,I8/G8) -> 0 | I8: ='2'!$L$8 -> 0 | J8: ='3'!$J$8 -> 0 | K8: =IF(J8=0,0,L8/J8) -> 0 | L8: ='3'!$L$8 -> 0 | M8: ='4'!$J$8 -> 0 | N8: =IF(M8=0,0,O8/M8) -> 0 | O8: ='4'!$L$8 -> 0 | P8: ='5'!$J$8 -> 0 | Q8: =IF(P8=0,0,R8/P8) -> 0 | R8: ='5'!$L$8 -> 0 | S8: ='6'!$J$8 -> 0 | T8: =IF(S8=0,0,U8/S8) -> 0 | U8: ='6'!$L$8 -> 0 | V8: ='7'!$J$8 -> 0 | W8: =IF(V8=0,0,X8/V8) -> 0 | X8: ='7'!$L$8 -> 0 | Y8: ='8'!$J$8 -> 0 | Z8: =IF(Y8=0,0,AA8/Y8) -> 0 | AA8: ='8'!$L$8 -> 0 | AB8: ='9'!$J$8 -> 0 | AC8: =IF(AB8=0,0,AD8/AB8) -> 0 | AD8: ='9'!$L$8 -> 0 | AE8: ='10'!$J$8 -> 0 | AF8: =IF(AE8=0,0,AG8/AE8) -> 0 | AG8: ='10'!$L$8 -> 0 | AH8: ='11'!$J$8 -> 0 | AI8: =IF(AH8=0,0,AJ8/AH8) -> 0 | AJ8: ='11'!$L$8 -> 0 | AK8: ='12'!$J$8 -> 0 | AL8: =IF(AK8=0,0,AM8/AK8) -> 0 | AM8: ='12'!$L$8 -> 0 | AN8: =SUM(D8,G8,J8,M8,P8,S8,V8,Y8,AB8,AE8,AH8,AK8) -> 0 | AO8: =IF(AN8=0,0,AP8/AN8) -> 0 | AP8: =SUM(F8,I8,L8,O8,R8,U8,X8,AA8,AD8,AG8,AJ8,AM8) -> 0
A9: =+B9&C9 -> Véhicules neufsMoto détail | B9: Véhicules neufs | C9: Moto détail | D9: ='1'!$J$9 -> 0 | E9: =IF(D9=0,0,F9/D9) -> 0 | F9: ='1'!$L$9 -> 0 | G9: ='2'!$J$9 -> 0 | H9: =IF(G9=0,0,I9/G9) -> 0 | I9: ='2'!$L$9 -> 0 | J9: ='3'!$J$9 -> 0 | K9: =IF(J9=0,0,L9/J9) -> 0 | L9: ='3'!$L$9 -> 0 | M9: ='4'!$J$9 -> 0 | N9: =IF(M9=0,0,O9/M9) -> 0 | O9: ='4'!$L$9 -> 0 | P9: ='5'!$J$9 -> 0 | Q9: =IF(P9=0,0,R9/P9) -> 0 | R9: ='5'!$L$9 -> 0 | S9: ='6'!$J$9 -> 0 | T9: =IF(S9=0,0,U9/S9) -> 0 | U9: ='6'!$L$9 -> 0 | V9: ='7'!$J$9 -> 0 | W9: =IF(V9=0,0,X9/V9) -> 0 | X9: ='7'!$L$9 -> 0 | Y9: ='8'!$J$9 -> 0 | Z9: =IF(Y9=0,0,AA9/Y9) -> 0 | AA9: ='8'!$L$9 -> 0 | AB9: ='9'!$J$9 -> 0 | AC9: =IF(AB9=0,0,AD9/AB9) -> 0 | AD9: ='9'!$L$9 -> 0 | AE9: ='10'!$J$9 -> 0 | AF9: =IF(AE9=0,0,AG9/AE9) -> 0 | AG9: ='10'!$L$9 -> 0 | AH9: ='11'!$J$9 -> 0 | AI9: =IF(AH9=0,0,AJ9/AH9) -> 0 | AJ9: ='11'!$L$9 -> 0 | AK9: ='12'!$J$9 -> 0 | AL9: =IF(AK9=0,0,AM9/AK9) -> 0 | AM9: ='12'!$L$9 -> 0 | AN9: =SUM(D9,G9,J9,M9,P9,S9,V9,Y9,AB9,AE9,AH9,AK9) -> 0 | AO9: =IF(AN9=0,0,AP9/AN9) -> 0 | AP9: =SUM(F9,I9,L9,O9,R9,U9,X9,AA9,AD9,AG9,AJ9,AM9) -> 0
A10: =+B10&C10 -> Véhicules neufs[...] | B10: Véhicules neufs | C10: [...] | D10: ='1'!G10 -> 0 | E10: =IF(D10=0,0,F10/D10) -> 0 | F10: ='1'!$L$10 -> 0 | G10: ='2'!J10 -> 0 | H10: =IF(G10=0,0,I10/G10) -> 0 | I10: ='2'!$L$10 -> 0 | J10: ='3'!M10 -> 0 | K10: =IF(J10=0,0,L10/J10) -> 0 | L10: ='3'!$L$10 -> 0 | M10: ='4'!P10 -> 0 | N10: =IF(M10=0,0,O10/M10) -> 0 | O10: ='4'!$L$10 -> 0 | P10: ='5'!S10 -> 0 | Q10: =IF(P10=0,0,R10/P10) -> 0 | R10: ='5'!$L$10 -> 0 | S10: ='6'!V10 -> 0 | T10: =IF(S10=0,0,U10/S10) -> 0 | U10: ='6'!$L$10 -> 0 | V10: ='7'!Y10 -> 0 | W10: =IF(V10=0,0,X10/V10) -> 0 | X10: ='7'!$L$10 -> 0 | Y10: ='8'!AB10 -> 0 | Z10: =IF(Y10=0,0,AA10/Y10) -> 0 | AA10: ='8'!$L$10 -> 0 | AB10: ='9'!AE10 -> 0 | AC10: =IF(AB10=0,0,AD10/AB10) -> 0 | AD10: ='9'!$L$10 -> 0 | AE10: ='10'!AH10 -> 0 | AF10: =IF(AE10=0,0,AG10/AE10) -> 0 | AG10: ='10'!$L$10 -> 0 | AH10: ='11'!AK10 -> 0 | AI10: =IF(AH10=0,0,AJ10/AH10) -> 0 | AJ10: ='11'!$L$10 -> 0 | AK10: ='12'!AN10 -> 0 | AL10: =IF(AK10=0,0,AM10/AK10) -> 0 | AM10: ='12'!$L$10 -> 0 | AN10: =SUM(D10,G10,J10,M10,P10,S10,V10,Y10,AB10,AE10,AH10,AK10) -> 0 | AO10: =IF(AN10=0,0,AP10/AN10) -> 0 | AP10: =SUM(F10,I10,L10,O10,R10,U10,X10,AA10,AD10,AG10,AJ10,AM10) -> 0
A11: =+B11&C11 -> Véhicules neufs[...] | B11: Véhicules neufs | C11: [...] | D11: ='1'!G11 -> 0 | E11: =IF(D11=0,0,F11/D11) -> 0 | F11: ='1'!$L$11 -> 0 | G11: ='2'!J11 -> 0 | H11: =IF(G11=0,0,I11/G11) -> 0 | I11: ='2'!$L$11 -> 0 | J11: ='3'!M11 -> 0 | K11: =IF(J11=0,0,L11/J11) -> 0 | L11: ='3'!$L$11 -> 0 | M11: ='4'!P11 -> 0 | N11: =IF(M11=0,0,O11/M11) -> 0 | O11: ='4'!$L$11 -> 0 | P11: ='5'!S11 -> 0 | Q11: =IF(P11=0,0,R11/P11) -> 0 | R11: ='5'!$L$11 -> 0 | S11: ='6'!V11 -> 0 | T11: =IF(S11=0,0,U11/S11) -> 0 | U11: ='6'!$L$11 -> 0 | V11: ='7'!Y11 -> 0 | W11: =IF(V11=0,0,X11/V11) -> 0 | X11: ='7'!$L$11 -> 0 | Y11: ='8'!AB11 -> 0 | Z11: =IF(Y11=0,0,AA11/Y11) -> 0 | AA11: ='8'!$L$11 -> 0 | AB11: ='9'!AE11 -> 0 | AC11: =IF(AB11=0,0,AD11/AB11) -> 0 | AD11: ='9'!$L$11 -> 0 | AE11: ='10'!AH11 -> 0 | AF11: =IF(AE11=0,0,AG11/AE11) -> 0 | AG11: ='10'!$L$11 -> 0 | AH11: ='11'!AK11 -> 0 | AI11: =IF(AH11=0,0,AJ11/AH11) -> 0 | AJ11: ='11'!$L$11 -> 0 | AK11: ='12'!AN11 -> 0 | AL11: =IF(AK11=0,0,AM11/AK11) -> 0 | AM11: ='12'!$L$11 -> 0 | AN11: =SUM(D11,G11,J11,M11,P11,S11,V11,Y11,AB11,AE11,AH11,AK11) -> 0 | AO11: =IF(AN11=0,0,AP11/AN11) -> 0 | AP11: =SUM(F11,I11,L11,O11,R11,U11,X11,AA11,AD11,AG11,AJ11,AM11) -> 0
