Workbook
Name _Dates_Conc: [1]Dealers!$BF$37:$KA$63
Name _scen: '[1]Scen & Sens'!$E$26
Name _scen1: '[1]Scen & Sens'!$E$27
Name _scen2: '[1]Scen & Sens'!$E$28
Name _SCenarios: '[1]Scen & Sens'!$J$26:$O$26
Name _Sens1: '[1]Scen & Sens'!$F$9
Name _Sens2: '[1]Scen & Sens'!$F$10
Name _sensRes1: '[1]Scen & Sens'!$E$15
Name _sensRes2: '[1]Scen & Sens'!$E$16
Name _sensRes3: '[1]Scen & Sens'!$E$17
Name _sensRes4: '[1]Scen & Sens'!$E$18
Name _sensRes5: '[1]Scen & Sens'!$E$19
Name _sensRes6: '[1]Scen & Sens'!$E$20
Name _sensRes7: '[1]Scen & Sens'!$E$21
Name DateRange: [1]Volkswagen!$BF$6:$DY$6
Name Monetary_Unit: [1]Parameters!$B$15
Name Months: [1]Parameters!$E$9:$E$20
Name Rng_Dealers_Names: [1]!Tbl_Dealers[Dealer Name]
Name Rng_Dlr_Dates: [1]!Tbl_V_Dlr_Dates[Date]
Name Ticker: #REF!
Name Ticker: #REF!
Name Ticker: #REF!
Name Titre: [1]Front!$A$9

Sheet Paramètre
B3: Quarter
B6: BUDGET | F6: BUDGET RÉVISÉ | J6: ACTUAL | N6: LAST YEAR
B7: Ventes | C7: Profits bruts | D7: BAIIA | E7: EBIT | F7: Ventes | G7: Profits bruts | H7: BAIIA | I7: EBIT | J7: Ventes | K7: Profits bruts | L7: BAIIA | M7: EBIT | N7: Ventes | O7: Profits bruts | P7: BAIIA | Q7: EBIT
A8: CTRL | B8: =+B9-B10 -> #REF! | C8: =+C9-C10 -> #REF! | D8: =+D9-D10 -> #REF! | E8: =+E9-E10 -> #REF! | F8: =+F9-F10 -> #REF! | G8: =+G9-G10 -> #REF! | H8: =+H9-H10 -> #REF! | I8: =+I9-I10 -> #REF! | ... Q8: =+Q9-Q10 -> #REF!
A9: CONSO | B9: =+Conso!$Z$405 -> 16892003 | C9: =+Conso!$Z$406 -> 2515613.3 | D9: =+Conso!$Z$482 -> 825406.03 | E9: =+Conso!$Z$497 -> 735461.03 | F9: =+Conso!$AC$405 -> 0 | G9: =+Conso!$AC$406 -> 0 | H9: =+Conso!$AC$482 -> 0 | I9: =+Conso!$AC$497 -> 0 | J9: =+Conso!$AF$405 -> 12663799 | K9: =+Conso!$AF$406 -> 1865550.7 | L9: =+Conso!$AF$482 -> 391433.22 | M9: =+Conso!$AF$497 -> 281096.29 | N9: =+Conso!$AL$405 -> 32561866 | O9: =+Conso!$AL$406 -> 2083377.1 | P9: =+Conso!$AL$482 -> 627120.36 | Q9: =+Conso!$AL$497 -> 616275.63
A10: TOTAL | B10: =+SUM(B11:B13) -> #REF! | C10: =+SUM(C11:C13) -> #REF! | D10: =+SUM(D11:D13) -> #REF! | E10: =+SUM(E11:E13) -> #REF! | F10: =+SUM(F11:F13) -> #REF! | G10: =+SUM(G11:G13) -> #REF! | H10: =+SUM(H11:H13) -> #REF! | I10: =+SUM(I11:I13) -> #REF! | ... Q10: =+SUM(Q11:Q13) -> #REF!
A11: Mois 1 | B11: =+#REF! -> #REF! | C11: =+#REF! -> #REF! | D11: =+#REF! -> #REF! | E11: =+#REF! -> #REF! | F11: =+#REF! -> #REF! | G11: =+#REF! -> #REF! | H11: =+#REF! -> #REF! | I11: =+#REF! -> #REF! | ... Q11: =+#REF! -> #REF!
A12: Mois 2 | B12: =+#REF! -> #REF! | C12: =+#REF! -> #REF! | D12: =+#REF! -> #REF! | E12: =+#REF! -> #REF! | F12: =+#REF! -> #REF! | G12: =+#REF! -> #REF! | H12: =+#REF! -> #REF! | I12: =+#REF! -> #REF! | ... Q12: =+#REF! -> #REF!
A13: Mois 3 | B13: =+#REF! -> #REF! | C13: =+#REF! -> #REF! | D13: =+#REF! -> #REF! | E13: =+#REF! -> #REF! | F13: =+#REF! -> #REF! | G13: =+#REF! -> #REF! | H13: =+#REF! -> #REF! | I13: =+#REF! -> #REF! | ... Q13: =+#REF! -> #REF!

Sheet Conso
C1: Conso | K1: Véhicules neufs | S1: =CONCATENATE("Réalisé"," ",Paramètre!$C$2," ",Paramètre!$C$3) -> Réalisé
D2: X | E2: O | F2: U | G2: X | H2: O | I2: U
D3: BUDGET ORIGINAL | G3: BUDGET REVISE | J3: RÉALISATION | M3: ÉCART réel / original | O3: ANNÉE PRÉCÉDENTE | R3: ÉCART réel / année précédente
D4: UNITE | E4: $P/UNITÉ | F4: $PROFITS | G4: UNITE | H4: $P/UNITÉ | I4: $PROFITS | J4: UNITE | K4: $P/UNITE | L4: $PROFITS | M4: UNITÉ | N4: $PROFITS | O4: UNITE | P4: $P/UNITE | Q4: $PROFITS | R4: UNITE | S4: $PROFITS
A5: =+B5&C5 -> Véhicules neufsVentes nettes | B5: =+$K$1 -> Véhicules neufs | C5: Ventes nettes | F5: =+SUM(START:END!F5) -> 8755197.7 | I5: =+SUM(START:END!I5) -> 0 | L5: =+SUM(START:END!L5) -> 6739517.4 | Q5: =+SUM(START:END!Q5) -> 26535985
A6: =+B6&C6 -> Véhicules neufsAutos détail | B6: =+$K$1 -> Véhicules neufs | C6: Autos détail | D6: =+SUM(START:END!D6) -> 32.4 | E6: =IF(D6=0,0,F6/D6) -> 2198.1219 | F6: =+SUM(START:END!F6) -> 71219.15 | G6: =+SUM(START:END!G6) -> 0 | H6: =IF(G6=0,0,I6/G6) -> 0 | I6: =+SUM(START:END!I6) -> 0 | J6: =+SUM(START:END!J6) -> 26 | K6: =IF(J6=0,0,L6/J6) -> 1810.325 | L6: =+SUM(START:END!L6) -> 47068.45 | M6: =J6-D6 -> -6.4 | N6: =L6-F6 -> -24150.7 | O6: =+SUM(START:END!O6) -> 44 | P6: =IF(O6=0,0,Q6/O6) -> 2072.8732 | Q6: =+SUM(START:END!Q6) -> 91206.42 | R6: =J6-O6 -> -18 | S6: =L6-Q6 -> -44137.97
A7: =+B7&C7 -> Véhicules neufsCamions détail | B7: =+$K$1 -> Véhicules neufs | C7: Camions détail | D7: =+SUM(START:END!D7) -> 134.32 | E7: =IF(D7=0,0,F7/D7) -> 2864.6882 | F7: =+SUM(START:END!F7) -> 384784.92 | G7: =+SUM(START:END!G7) -> 0 | H7: =IF(G7=0,0,I7/G7) -> 0 | I7: =+SUM(START:END!I7) -> 0 | J7: =+SUM(START:END!J7) -> 83 | K7: =IF(J7=0,0,L7/J7) -> 1820.1257 | L7: =+SUM(START:END!L7) -> 151070.43 | M7: =J7-D7 -> -51.32 | N7: =L7-F7 -> -233714.49 | O7: =+SUM(START:END!O7) -> 155 | P7: =IF(O7=0,0,Q7/O7) -> 2443.4194 | Q7: =+SUM(START:END!Q7) -> 378730.01 | R7: =J7-O7 -> -72 | S7: =L7-Q7 -> -227659.58
A8: =+B8&C8 -> Véhicules neufsSprinter | B8: =+$K$1 -> Véhicules neufs | C8: Sprinter | D8: =+SUM(START:END!D8) -> 0 | E8: =IF(D8=0,0,F8/D8) -> 0 | F8: =+SUM(START:END!F8) -> 0 | G8: =+SUM(START:END!G8) -> 0 | H8: =IF(G8=0,0,I8/G8) -> 0 | I8: =+SUM(START:END!I8) -> 0 | J8: =+SUM(START:END!J8) -> 0 | K8: =IF(J8=0,0,L8/J8) -> 0 | L8: =+SUM(START:END!L8) -> 0 | M8: =J8-D8 -> 0 | N8: =L8-F8 -> 0 | O8: =+SUM(START:END!O8) -> 0 | P8: =IF(O8=0,0,Q8/O8) -> 0 | Q8: =+SUM(START:END!Q8) -> 0 | R8: =J8-O8 -> 0 | S8: =L8-Q8 -> 0
A9: =+B9&C9 -> Véhicules neufsMoto détail | B9: =+$K$1 -> Véhicules neufs | C9: Moto détail | D9: =+SUM(START:END!D9) -> 0 | E9: =IF(D9=0,0,F9/D9) -> 0 | F9: =+SUM(START:END!F9) -> 0 | G9: =+SUM(START:END!G9) -> 0 | H9: =IF(G9=0,0,I9/G9) -> 0 | I9: =+SUM(START:END!I9) -> 0 | J9: =+SUM(START:END!J9) -> 0 | K9: =IF(J9=0,0,L9/J9) -> 0 | L9: =+SUM(START:END!L9) -> 0 | M9: =J9-D9 -> 0 | N9: =L9-F9 -> 0 | O9: =+SUM(START:END!O9) -> 0 | P9: =IF(O9=0,0,Q9/O9) -> 0 | Q9: =+SUM(START:END!Q9) -> 0 | R9: =J9-O9 -> 0 | S9: =L9-Q9 -> 0
A10: =+B10&C10 -> Véhicules neufs[...] | B10: =+$K$1 -> Véhicules neufs | C10: [...] | D10: =+SUM(START:END!D10) -> 0 | E10: =IF(D10=0,0,F10/D10) -> 0 | F10: =+SUM(START:END!F10) -> 0 | G10: =+SUM(START:END!G10) -> 0 | H10: =IF(G10=0,0,I10/G10) -> 0 | I10: =+SUM(START:END!I10) -> 0 | J10: =+SUM(START:END!J10) -> 0 | K10: =IF(J10=0,0,L10/J10) -> 0 | L10: =+SUM(START:END!L10) -> 0 | M10: =J10-G10 -> 0 | N10: =L10-I10 -> 0 | O10: =+SUM(START:END!O10) -> 0 | P10: =IF(O10=0,0,Q10/O10) -> 0 | Q10: =+SUM(START:END!Q10) -> 0 | R10: =J10-O10 -> 0 | S10: =L10-Q10 -> 0
A11: =+B11&C11 -> Véhicules neufs[...] | B11: =+$K$1 -> Véhicules neufs | C11: [...] | D11: =+SUM(START:END!D11) -> 0 | E11: =IF(D11=0,0,F11/D11) -> 0 | F11: =+SUM(START:END!F11) -> 0 | G11: =+SUM(START:END!G11) -> 0 | H11: =IF(G11=0,0,I11/G11) -> 0 | I11: =+SUM(START:END!I11) -> 0 | J11: =+SUM(START:END!J11) -> 0 | K11: =IF(J11=0,0,L11/J11) -> 0 | L11: =+SUM(START:END!L11) -> 0 | M11: =J11-G11 -> 0 | N11: =L11-I11 -> 0 | O11: =+SUM(START:END!O11) -> 0 | P11: =IF(O11=0,0,Q11/O11) -> 0 | Q11: =+SUM(START:END!Q11) -> 0 | R11: =J11-O11 -> 0 | S11: =L11-Q11 -> 0
A12: =+B12&C12 -> Véhicules neufs[...] | B12: =+$K$1 -> Véhicules neufs | C12: [...] | D12: =+SUM(START:END!D12) -> 0 | E12: =IF(D12=0,0,F12/D12) -> 0 | F12: =+SUM(START:END!F12) -> 0 | G12: =+SUM(START:END!G12) -> 0 | H12: =IF(G12=0,0,I12/G12) -> 0 | I12: =+SUM(START:END!I12) -> 0 | J12: =+SUM(START:END!J12) -> 0 | K12: =IF(J12=0,0,L12/J12) -> 0 | L12: =+SUM(START:END!L12) -> 0 | M12: =J12-G12 -> 0 | N12: =L12-I12 -> 0 | O12: =+SUM(START:END!O12) -> 0 | P12: =IF(O12=0,0,Q12/O12) -> 0 | Q12: =+SUM(START:END!Q12) -> 0 | R12: =J12-O12 -> 0 | S12: =L12-Q12 -> 0
A13: =+B13&C13 -> Véhicules neufsTotal Neufs | B13: =+$K$1 -> Véhicules neufs | C13: Total Neufs | D13: =+SUM(D6:D12) -> 166.72 | E13: =IF(D13<=0,0,F13/D13) -> 2735.1492 | F13: =+SUM(F6:F12) -> 456004.07 | G13: =+SUM(G6:G12) -> 0 | H13: =IF(G13<=0,0,I13/G13) -> 0 | I13: =+SUM(I6:I12) -> 0 | J13: =+SUM(J6:J12) -> 109 | K13: =IF(J13<=0,0,L13/J13) -> 1817.7879 | L13: =+SUM(L6:L12) -> 198138.88 | M13: =+SUM(M6:M12) -> -57.72 | N13: =+SUM(N6:N12) -> -257865.19 | O13: =+SUM(O6:O12) -> 199 | P13: =IF(O13<=0,0,Q13/O13) -> 2361.4896 | Q13: =+SUM(Q6:Q12) -> 469936.43 | R13: =+SUM(R6:R12) -> -90 | S13: =+SUM(S6:S12) -> -271797.55
A14: =+B14&C14 -> Véhicules neufs | B14: =+$K$1 -> Véhicules neufs | N14: =IF(F13=0,0,N13/F13) -> -0.56548879 | R14: =R13/O13 -> -0.45226131 | S14: =IF(Q13=0,0,(S13/Q13)) -> -0.57837089
A15: =+B15&C15 -> Véhicules neufsEx-Démos et courtoisies | B15: =+$K$1 -> Véhicules neufs | C15: Ex-Démos et courtoisies | D15: =+SUM(START:END!D15) -> 13.29 | E15: =IF(D15=0,0,F15/D15) -> 2523.6763 | F15: =+SUM(START:END!F15) -> 33539.659 | G15: =+SUM(START:END!G15) -> 0 | H15: =IF(G15=0,0,I15/G15) -> 0 | I15: =+SUM(START:END!I15) -> 0 | J15: =+SUM(START:END!J15) -> 12 | K15: =IF(J15=0,0,L15/J15) -> 1517.4408 | L15: =+SUM(START:END!L15) -> 18209.29 | M15: =J15-G15 -> 12 | N15: =L15-F15 -> -15330.369 | O15: =+SUM(START:END!O15) -> 2 | P15: =IF(O15=0,0,Q15/O15) -> 2937.965 | Q15: =+SUM(START:END!Q15) -> 5875.93 | R15: =J15-O15 -> 10 | S15: =L15-Q15 -> 12333.36
A16: =+B16&C16 -> Véhicules neufs | B16: =+$K$1 -> Véhicules neufs
A17: =+B17&C17 -> Véhicules neufsFlottes | B17: =+$K$1 -> Véhicules neufs | C17: Flottes | D17: =+SUM(START:END!D17) -> 12.15 | E17: =IF(D17=0,0,F17/D17) -> 2664.4641 | F17: =+SUM(START:END!F17) -> 32373.238 | G17: =+SUM(START:END!G17) -> 0 | H17: =IF(G17=0,0,I17/G17) -> 0 | I17: =+SUM(START:END!I17) -> 0 | J17: =+SUM(START:END!J17) -> 11 | K17: =IF(J17=0,0,L17/J17) -> 1058.8518 | L17: =+SUM(START:END!L17) -> 11647.37 | M17: =J17-D17 -> -1.15 | N17: =L17-F17 -> -20725.868 | O17: =+SUM(START:END!O17) -> 10 | P17: =IF(O17=0,0,Q17/O17) -> 3147.371 | Q17: =+SUM(START:END!Q17) -> 31473.71 | R17: =J17-O17 -> 1 | S17: =L17-Q17 -> -19826.34
A18: =+B18&C18 -> Véhicules neufs | B18: =+$K$1 -> Véhicules neufs
A19: =+B19&C19 -> Véhicules neufsRachat bail | B19: =+$K$1 -> Véhicules neufs | C19: Rachat bail | F19: =+SUM(START:END!F19) -> 22950 | I19: =+SUM(START:END!I19) -> 0 | L19: =+SUM(START:END!L19) -> 23749 | N19: =L19-F19 -> 799 | Q19: =+SUM(START:END!Q19) -> 17381.51 | R19: =O19-K19 -> 0 | S19: =L19-Q19 -> 6367.49
A20: =+B20&C20 -> Véhicules neufs | B20: =+$K$1 -> Véhicules neufs
A21: =+B21&C21 -> Véhicules neufsRev. Finances | B21: =+$K$1 -> Véhicules neufs | C21: Rev. Finances | D21: 0 | E21: =IF(D21=0,0,F21/D21) -> 0 | F21: =+SUM(START:END!F21) -> 36002 | G21: 0 | H21: =IF(G21=0,0,I21/G21) -> 0 | I21: =+SUM(START:END!I21) -> 0 | K21: =IF(J13=0,0,L21/(J13+J15)) -> 10.65157 | L21: =+SUM(START:END!L21) -> 1288.84 | N21: =L21-F21 -> -34713.16 | P21: =IF(O13=0,0,Q21/(O13+O15)) -> 56.331891 | Q21: =+SUM(START:END!Q21) -> 11322.71 | R21: =O21-K21 -> -10.65157 | S21: =L21-Q21 -> -10033.87
A22: =+B22&C22 -> Véhicules neufsRev. Protections | B22: =+$K$1 -> Véhicules neufs | C22: Rev. Protections | D22: 0 | E22: =IF(D22=0,0,F22/D22) -> 0 | F22: =+SUM(START:END!F22) -> 194410.8 | G22: 0 | H22: =IF(G22=0,0,I22/G22) -> 0 | I22: =+SUM(START:END!I22) -> 0 | K22: =IF(J13=0,0,L22/(J13+J15)) -> 1036.308 | L22: =+SUM(START:END!L22) -> 125393.27 | N22: =L22-F22 -> -69017.53 | P22: =IF(O13=0,0,Q22/(O13+O15)) -> 987.88144 | Q22: =+SUM(START:END!Q22) -> 198564.17 | R22: =O22-K22 -> -1036.308 | S22: =L22-Q22 -> -73170.9
A23: =+B23&C23 -> Véhicules neufsRev. Autres | B23: =+$K$1 -> Véhicules neufs | C23: Rev. Autres | D23: 0 | E23: =IF(D23=0,0,F23/D23) -> 0 | F23: =+SUM(START:END!F23) -> 3600.2 | G23: 0 | H23: =IF(G23=0,0,I23/G23) -> 0 | I23: =+SUM(START:END!I23) -> 0 | K23: =IF(J13=0,0,L23/(J13+J15)) -> 10.65438 | L23: =+SUM(START:END!L23) -> 1289.18 | N23: =L23-F23 -> -2311.02 | P23: =IF(O13=0,0,Q23/(O13+O15)) -> 20.941791 | Q23: =+SUM(START:END!Q23) -> 4209.3 | R23: =O23-K23 -> -10.65438 | S23: =L23-Q23 -> -2920.12
A24: =+B24&C24 -> Véhicules neufsTotal F&I | B24: =+$K$1 -> Véhicules neufs | C24: Total F&I | D24: =+D15+D13 -> 180.01 | E24: =IF(D24<=0,0,F24/D24) -> 1300 | F24: =F21+F22+F23 -> 234013 | G24: =+G15+G13 -> 0 | H24: =IF(G24<=0,0,I24/G24) -> 0 | I24: =I21+I22+I23 -> 0 | J24: =+J15+J13 -> 121 | K24: =IF(J24<=0,0,L24/J24) -> 1057.614 | L24: =L21+L22+L23 -> 127971.29 | M24: =+M15+M13 -> -45.72 | N24: =N21+N22+N23 -> -106041.71 | O24: =+O15+O13 -> 201 | P24: =IF(O24<=0,0,Q24/O24) -> 1065.1551 | Q24: =Q21+Q22+Q23 -> 214096.18 | S24: =L24-Q24 -> -86124.89
A25: =+B25&C25 -> Véhicules neufs | B25: =+$K$1 -> Véhicules neufs | S25: =IF(Q24=0,0,(S24/Q24)) -> -0.40227196
A26: =+B26&C26 -> Véhicules neufs | B26: =+$K$1 -> Véhicules neufs
A27: =+B27&C27 -> Véhicules neufsTotal Dépt. Neufs | B27: =+$K$1 -> Véhicules neufs | C27: Total Dépt. Neufs | D27: =+D13+D15+D17 -> 192.16 | E27: =IF(D27<=0,0,F27/D27) -> 4053.2888 | F27: =F13+F17+F24+F19+F15 -> 778879.97 | G27: =+G13+G15+G17 -> 0 | H27: =IF(G27<=0,0,I27/G27) -> 0 | I27: =I13+I17+I24+I19+I15 -> 0 | J27: =+J13+J15+J17 -> 132 | K27: =IF(J27<=0,0,L27/J27) -> 2876.6351 | L27: =L13+L17+L24+L19+L15 -> 379715.83 | M27: =+M13+M15+M17 -> -46.87 | N27: =N13+N17+N24+N19+N15 -> -399164.14 | O27: =+O13+O15+O17 -> 211 | P27: =IF(O27<=0,0,Q27/O27) -> 3501.25 | Q27: =Q13+Q17+Q24+Q19+Q15 -> 738763.76 | R27: =J27-O27 -> -79 | S27: =L27-Q27 -> -359047.93
A28: =+B28&C28 -> Véhicules neufs | B28: =+$K$1 -> Véhicules neufs | M28: =M27/D27 -> -0.24391132 | N28: =N27/F27 -> -0.51248479 | R28: =R27/O27 -> -0.37440758 | S28: =IF(Q27=0,0,S27/Q27) -> -0.48601183
A29: =+B29&C29 -> Véhicules neufs | B29: =+$K$1 -> Véhicules neufs
A30: =+B30&C30 -> Véhicules neufsDEPENSES | B30: =+$K$1 -> Véhicules neufs | C30: DEPENSES
A31: =+B31&C31 -> Véhicules neufsComm. vendeurs | B31: =+$K$1 -> Véhicules neufs | C31: Comm. vendeurs | E31: =F31/D$24 -> 924.64235 | F31: =+SUM(START:END!F31) -> 166444.87 | H31: =I31/G$24 -> #DIV/0! | I31: =+SUM(START:END!I31) -> 0 | J31: =L31/L13 -> 0.38011581 | K31: =IF(L31=0,0,L31/J$24) -> 622.44397 | L31: =+SUM(START:END!L31) -> 75315.72 | N31: =L31-F31 -> -91129.149 | P31: =IF(Q31=0,0,Q31/O$24) -> 601.63682 | Q31: =+SUM(START:END!Q31) -> 120929 | S31: =L31-Q31 -> -45613.28
A32: =+B32&C32 -> Véhicules neufsComm. F&I | B32: =+$K$1 -> Véhicules neufs | C32: Comm. F&I | E32: =F32/D$24 -> 390 | F32: =+SUM(START:END!F32) -> 70203.9 | H32: =I32/G$24 -> #DIV/0! | I32: =+SUM(START:END!I32) -> 0 | J32: =L32/L24 -> 0.28380991 | K32: =IF(L32=0,0,L32/J$24) -> 300.16132 | L32: =+SUM(START:END!L32) -> 36319.52 | N32: =L32-F32 -> -33884.38 | P32: =IF(Q32=0,0,Q32/O$24) -> 318.93955 | Q32: =+SUM(START:END!Q32) -> 64106.85 | S32: =L32-Q32 -> -27787.33
A33: =+B33&C33 -> Véhicules neufsFrais de livraison | B33: =+$K$1 -> Véhicules neufs | C33: Frais de livraison | E33: =F33/D$24 -> 115 | F33: =+SUM(START:END!F33) -> 20701.15 | H33: =I33/G$24 -> #DIV/0! | I33: =+SUM(START:END!I33) -> 0 | K33: =IF(L33=0,0,L33/J$24) -> 157.53769 | L33: =+SUM(START:END!L33) -> 19062.06 | N33: =L33-F33 -> -1639.09 | P33: =IF(Q33=0,0,Q33/O$24) -> 150.03144 | Q33: =+SUM(START:END!Q33) -> 30156.32 | S33: =L33-Q33 -> -11094.26
A34: =+B34&C34 -> Véhicules neufsService gratuit 1 | B34: =+$K$1 -> Véhicules neufs | C34: Service gratuit 1 | E34: =F34/D$24 -> 3 | F34: =+SUM(START:END!F34) -> 540.03 | H34: =I34/G$24 -> #DIV/0! | I34: =+SUM(START:END!I34) -> 0 | K34: =IF(L34=0,0,L34/J$24) -> 47.640496 | L34: =+SUM(START:END!L34) -> 5764.5 | N34: =L34-F34 -> 5224.47 | P34: =IF(Q34=0,0,Q34/O$24) -> 38.430746 | Q34: =+SUM(START:END!Q34) -> 7724.58 | S34: =L34-Q34 -> -1960.08
A35: =+B35&C35 -> Véhicules neufsEntretien stock | B35: =+$K$1 -> Véhicules neufs | C35: Entretien stock | E35: =F35/D$24 -> 85.05 | F35: =+SUM(START:END!F35) -> 15309.85 | H35: =I35/G$24 -> #DIV/0! | I35: =+SUM(START:END!I35) -> 0 | K35: =IF(L35=0,0,L35/J$24) -> 158.87983 | L35: =+SUM(START:END!L35) -> 19224.46 | N35: =L35-F35 -> 3914.6095 | P35: =IF(Q35=0,0,Q35/O$24) -> 83.521542 | Q35: =+SUM(START:END!Q35) -> 16787.83 | S35: =L35-Q35 -> 2436.63
A36: =+B36&C36 -> Véhicules neufsPublicité 1 | B36: =+$K$1 -> Véhicules neufs | C36: Publicité 1 | E36: =F36/D$24 -> 112.25487 | F36: =+SUM(START:END!F36) -> 20207 | H36: =I36/G$24 -> #DIV/0! | I36: =+SUM(START:END!I36) -> 0 | K36: =IF(L36=0,0,L36/J$24) -> 342.80653 | L36: =+SUM(START:END!L36) -> 41479.59 | N36: =L36-F36 -> 21272.59 | P36: =IF(Q36=0,0,Q36/O$24) -> 101.00746 | Q36: =+SUM(START:END!Q36) -> 20302.5 | S36: =L36-Q36 -> 21177.09
A37: =+B37&C37 -> Véhicules neufsIntérêt de gros | B37: =+$K$1 -> Véhicules neufs | C37: Intérêt de gros | E37: =F37/D$24 -> 244.87222 | F37: =+SUM(START:END!F37) -> 44079.449 | H37: =I37/G$24 -> #DIV/0! | I37: =+SUM(START:END!I37) -> 0 | K37: =IF(L37=0,0,L37/J$24) -> -117.72405 | L37: =+SUM(START:END!L37) -> -14244.61 | N37: =L37-F37 -> -58324.059 | P37: =IF(Q37=0,0,Q37/O$24) -> 183.21866 | Q37: =+SUM(START:END!Q37) -> 36826.95 | S37: =L37-Q37 -> -51071.56
A38: =+B38&C38 -> Véhicules neufs[...] | B38: =+$K$1 -> Véhicules neufs | C38: [...] | E38: =F38/D$24 -> 0 | F38: =+SUM(START:END!F38) -> 0 | H38: =I38/G$24 -> #DIV/0! | I38: =+SUM(START:END!I38) -> 0 | K38: =IF(L38=0,0,L38/J$24) -> 0 | L38: =+SUM(START:END!L38) -> 0 | N38: =L38-I38 -> 0 | P38: =IF(Q38=0,0,Q38/O$24) -> 0 | Q38: =+SUM(START:END!Q38) -> 0 | S38: =L38-Q38 -> 0
A39: =+B39&C39 -> Véhicules neufs[...] | B39: =+$K$1 -> Véhicules neufs | C39: [...] | E39: =F39/D$24 -> 0 | F39: =+SUM(START:END!F39) -> 0 | H39: =I39/G$24 -> #DIV/0! | I39: =+SUM(START:END!I39) -> 0 | K39: =IF(L39=0,0,L39/J$24) -> 0 | L39: =+SUM(START:END!L39) -> 0 | N39: =L39-I39 -> 0 | P39: =IF(Q39=0,0,Q39/O$24) -> 0 | Q39: =+SUM(START:END!Q39) -> 0 | S39: =L39-Q39 -> 0
A40: =+B40&C40 -> Véhicules neufs[...] | B40: =+$K$1 -> Véhicules neufs | C40: [...] | E40: =F40/D$24 -> 0 | F40: =+SUM(START:END!F40) -> 0 | H40: =I40/G$24 -> #DIV/0! | I40: =+SUM(START:END!I40) -> 0 | K40: =IF(L40=0,0,L40/J$24) -> 0 | L40: =+SUM(START:END!L40) -> 0 | N40: =L40-I40 -> 0 | P40: =IF(Q40=0,0,Q40/O$24) -> 0 | Q40: =+SUM(START:END!Q40) -> 0 | S40: =L40-Q40 -> 0
...

Sheet START

Sheet 2024-10
C1: =[5]Parametres!B1 -> Volks | K1: Véhicules neufs | S1: =CONCATENATE("Réalisé,"," ",[5]Parametres!B3," ",[5]Parametres!B4) -> Réalisé, Octobre 2024
D2: X | E2: O | F2: U | J2: NB | L2: $ | O2: X | P2: O | Q2: U | V2: *** NE PAS EFFACER / Pour An Précédente ***
D3: BUDGET ORIGINAL | J3: RÉALISATION | M3: ÉCART réel / Budget | O3: ANNÉE PRÉCÉDENTE | R3: ECART (réel/ Ann.Préc.) | V3: NEUF | W3: 0.45
D4: UNITE | E4: $P/UNITÉ | F4: $PROFITS | J4: UNITÉS | K4: $P/UNITE | L4: $PROFITS | M4: UNITÉS | N4: $PROFITS | O4: UNITE | P4: $P/UNITÉ | Q4: $PROFITS | R4: UNITÉS | S4: $PROFITS | V4: USAGE | W4: 0.1
A5: Véhicules neufsVentes nettes | B5: Véhicules neufs | C5: Ventes nettes | F5: =+INDEX('[5]Budget original'!$A$2:$AO$501,MATCH($A5,'[5]Budget original'!$A$2:$A$501,0),MATCH(F$2,'[5]Budget original'!$A$2:$AO$2,0)) -> 3890933.2 | L5: =-SUMIFS([5]BV_Data_An_Cour!$O:$O,[5]BV_Data_An_Cour!$X:$X,"Oui",[5]BV_Data_An_Cour!$U:$U,$B5) -> 2470114 | Q5: {=+INDEX('[5]Réel 2023'!$A$2:$AO$501,MATCH($A5,'[5]Réel 2023'!$A$2:$A$501,0),MATCH(Q$2,'[5]Réel 2023'!$A$2:$AO$2,0))} -> 8285274.9 | V5: SERVICE | W5: 0.225
A6: Véhicules neufsAutos détail | B6: Véhicules neufs | C6: Autos détail | D6: =+INDEX('[5]Budget original'!$A$2:$AO$501,MATCH($A6,'[5]Budget original'!$A$2:$A$501,0),MATCH(D$2,'[5]Budget original'!$A$2:$AO$2,0)) -> 14.4 | E6: =IF(D6=0,0,F6/D6) -> 2198.1219 | F6: =+INDEX('[5]Budget original'!$A$2:$AO$501,MATCH($A6,'[5]Budget original'!$A$2:$A$501,0),MATCH(F$2,'[5]Budget original'!$A$2:$AO$2,0)) -> 31652.956 | J6: =-SUMIFS([5]BV_Data_An_Cour!$O:$O,[5]BV_Data_An_Cour!$U:$U,$B6,[5]BV_Data_An_Cour!$V:$V,$C6,[5]BV_Data_An_Cour!$W:$W,J$2) -> 12 | K6: =IF(J6=0,0,L6/J6) -> 1802.2583 | L6: =-SUMIFS([5]BV_Data_An_Cour!$O:$O,[5]BV_Data_An_Cour!$U:$U,$B6,[5]BV_Data_An_Cour!$V:$V,$C6,[5]BV_Data_An_Cour!$W:$W,L$2) -> 21627.1 | M6: =J6-D6 -> -2.4 | N6: =L6-F6 -> -10025.856 | O6: =+INDEX('[5]Réel 2023'!$A$2:$AO$501,MATCH($A6,'[5]Réel 2023'!$A$2:$A$501,0),MATCH(O$2,'[5]Réel 2023'!$A$2:$AO$2,0)) -> 14 | P6: =IF(O6=0,0,Q6/O6) -> 2125.1657 | Q6: {=+INDEX('[5]Réel 2023'!$A$2:$AO$501,MATCH($A6,'[5]Réel 2023'!$A$2:$A$501,0),MATCH(Q$2,'[5]Réel 2023'!$A$2:$AO$2,0))} -> 29752.32 | R6: =J6-O6 -> -2 | S6: =L6-Q6 -> -8125.22 | V6: CARROSSERIE | W6: 0.025
A7: Véhicules neufsCamions détail | B7: Véhicules neufs | C7: Camions détail | D7: =+INDEX('[5]Budget original'!$A$2:$AO$501,MATCH($A7,'[5]Budget original'!$A$2:$A$501,0),MATCH(D$2,'[5]Budget original'!$A$2:$AO$2,0)) -> 59.52 | E7: =IF(D7=0,0,F7/D7) -> 2873.2447 | F7: =+INDEX('[5]Budget original'!$A$2:$AO$501,MATCH($A7,'[5]Budget original'!$A$2:$A$501,0),MATCH(F$2,'[5]Budget original'!$A$2:$AO$2,0)) -> 171015.52 | J7: =-SUMIFS([5]BV_Data_An_Cour!$O:$O,[5]BV_Data_An_Cour!$U:$U,$B7,[5]BV_Data_An_Cour!$V:$V,$C7,[5]BV_Data_An_Cour!$W:$W,J$2) -> 32 | K7: =IF(J7=0,0,L7/J7) -> 1508.5388 | L7: =-SUMIFS([5]BV_Data_An_Cour!$O:$O,[5]BV_Data_An_Cour!$U:$U,$B7,[5]BV_Data_An_Cour!$V:$V,$C7,[5]BV_Data_An_Cour!$W:$W,L$2) -> 48273.24 | M7: =J7-D7 -> -27.52 | N7: =L7-F7 -> -122742.28 | O7: {=+INDEX('[5]Réel 2023'!$A$2:$AO$501,MATCH($A7,'[5]Réel 2023'!$A$2:$A$501,0),MATCH(O$2,'[5]Réel 2023'!$A$2:$AO$2,0))} -> 45 | P7: =IF(O7=0,0,Q7/O7) -> 2647.1667 | Q7: {=+INDEX('[5]Réel 2023'!$A$2:$AO$501,MATCH($A7,'[5]Réel 2023'!$A$2:$A$501,0),MATCH(Q$2,'[5]Réel 2023'!$A$2:$AO$2,0))} -> 119122.5 | R7: =J7-O7 -> -13 | S7: =L7-Q7 -> -70849.26 | V7: PIECES | W7: 0.2
A8: Véhicules neufsSprinter | B8: Véhicules neufs | C8: Sprinter | D8: =+INDEX('[5]Budget original'!$A$2:$AO$501,MATCH($A8,'[5]Budget original'!$A$2:$A$501,0),MATCH(D$2,'[5]Budget original'!$A$2:$AO$2,0)) -> 0 | E8: =IF(D8=0,0,F8/D8) -> 0 | F8: =+INDEX('[5]Budget original'!$A$2:$AO$501,MATCH($A8,'[5]Budget original'!$A$2:$A$501,0),MATCH(F$2,'[5]Budget original'!$A$2:$AO$2,0)) -> 0 | J8: =-SUMIFS([5]BV_Data_An_Cour!$O:$O,[5]BV_Data_An_Cour!$U:$U,$B8,[5]BV_Data_An_Cour!$V:$V,$C8,[5]BV_Data_An_Cour!$W:$W,J$2) -> 0 | K8: =IF(J8=0,0,L8/J8) -> 0 | L8: =-SUMIFS([5]BV_Data_An_Cour!$O:$O,[5]BV_Data_An_Cour!$U:$U,$B8,[5]BV_Data_An_Cour!$V:$V,$C8,[5]BV_Data_An_Cour!$W:$W,L$2) -> 0 | M8: =J8-D8 -> 0 | N8: =L8-F8 -> 0 | O8: {=+INDEX('[5]Réel 2023'!$A$2:$AO$501,MATCH($A8,'[5]Réel 2023'!$A$2:$A$501,0),MATCH(O$2,'[5]Réel 2023'!$A$2:$AO$2,0))} -> 0 | P8: =IF(O8=0,0,Q8/O8) -> 0 | Q8: {=+INDEX('[5]Réel 2023'!$A$2:$AO$501,MATCH($A8,'[5]Réel 2023'!$A$2:$A$501,0),MATCH(Q$2,'[5]Réel 2023'!$A$2:$AO$2,0))} -> 0 | R8: =J8-O8 -> 0 | S8: =L8-Q8 -> 0 | W8: =SUM(W3:W7) -> 1
A9: Véhicules neufsMoto détail | B9: Véhicules neufs | C9: Moto détail | D9: =+INDEX('[5]Budget original'!$A$2:$AO$501,MATCH($A9,'[5]Budget original'!$A$2:$A$501,0),MATCH(D$2,'[5]Budget original'!$A$2:$AO$2,0)) -> 0 | E9: =IF(D9=0,0,F9/D9) -> 0 | F9: =+INDEX('[5]Budget original'!$A$2:$AO$501,MATCH($A9,'[5]Budget original'!$A$2:$A$501,0),MATCH(F$2,'[5]Budget original'!$A$2:$AO$2,0)) -> 0 | J9: =-SUMIFS([5]BV_Data_An_Cour!$O:$O,[5]BV_Data_An_Cour!$U:$U,$B9,[5]BV_Data_An_Cour!$V:$V,$C9,[5]BV_Data_An_Cour!$W:$W,J$2) -> 0 | K9: =IF(J9=0,0,L9/J9) -> 0 | L9: =-SUMIFS([5]BV_Data_An_Cour!$O:$O,[5]BV_Data_An_Cour!$U:$U,$B9,[5]BV_Data_An_Cour!$V:$V,$C9,[5]BV_Data_An_Cour!$W:$W,L$2) -> 0 | M9: =J9-D9 -> 0 | N9: =L9-F9 -> 0 | O9: {=+INDEX('[5]Réel 2023'!$A$2:$AO$501,MATCH($A9,'[5]Réel 2023'!$A$2:$A$501,0),MATCH(O$2,'[5]Réel 2023'!$A$2:$AO$2,0))} -> 0 | P9: =IF(O9=0,0,Q9/O9) -> 0 | Q9: {=+INDEX('[5]Réel 2023'!$A$2:$AO$501,MATCH($A9,'[5]Réel 2023'!$A$2:$A$501,0),MATCH(Q$2,'[5]Réel 2023'!$A$2:$AO$2,0))} -> 0 | R9: =J9-O9 -> 0 | S9: =L9-Q9 -> 0
A10: Véhicules neufs[...] | B10: Véhicules neufs | C10: [...] | D10: =+INDEX('[5]Budget original'!$A$2:$AO$501,MATCH($A10,'[5]Budget original'!$A$2:$A$501,0),MATCH(D$2,'[5]Budget original'!$A$2:$AO$2,0)) -> 0 | E10: =IF(D10=0,0,F10/D10) -> 0 | F10: =+INDEX('[5]Budget original'!$A$2:$AO$501,MATCH($A10,'[5]Budget original'!$A$2:$A$501,0),MATCH(F$2,'[5]Budget original'!$A$2:$AO$2,0)) -> 0 | J10: =-SUMIFS([5]BV_Data_An_Cour!$O:$O,[5]BV_Data_An_Cour!$U:$U,$B10,[5]BV_Data_An_Cour!$V:$V,$C10,[5]BV_Data_An_Cour!$W:$W,J$2) -> 0 | K10: =IF(J10=0,0,L10/J10) -> 0 | L10: =-SUMIFS([5]BV_Data_An_Cour!$O:$O,[5]BV_Data_An_Cour!$U:$U,$B10,[5]BV_Data_An_Cour!$V:$V,$C10,[5]BV_Data_An_Cour!$W:$W,L$2) -> 0 | M10: =J10-D10 -> 0 | N10: =L10-F10 -> 0 | O10: {=+INDEX('[5]Réel 2023'!$A$2:$AO$501,MATCH($A10,'[5]Réel 2023'!$A$2:$A$501,0),MATCH(O$2,'[5]Réel 2023'!$A$2:$AO$2,0))} -> 0 | P10: =IF(O10=0,0,Q10/O10) -> 0 | Q10: {=+INDEX('[5]Réel 2023'!$A$2:$AO$501,MATCH($A10,'[5]Réel 2023'!$A$2:$A$501,0),MATCH(Q$2,'[5]Réel 2023'!$A$2:$AO$2,0))} -> 0 | R10: =J10-O10 -> 0 | S10: =L10-Q10 -> 0
A11: Véhicules neufs[...] | B11: Véhicules neufs | C11: [...] | D11: =+INDEX('[5]Budget original'!$A$2:$AO$501,MATCH($A11,'[5]Budget original'!$A$2:$A$501,0),MATCH(D$2,'[5]Budget original'!$A$2:$AO$2,0)) -> 0 | E11: =IF(D11=0,0,F11/D11) -> 0 | F11: =+INDEX('[5]Budget original'!$A$2:$AO$501,MATCH($A11,'[5]Budget original'!$A$2:$A$501,0),MATCH(F$2,'[5]Budget original'!$A$2:$AO$2,0)) -> 0 | J11: =-SUMIFS([5]BV_Data_An_Cour!$O:$O,[5]BV_Data_An_Cour!$U:$U,$B11,[5]BV_Data_An_Cour!$V:$V,$C11,[5]BV_Data_An_Cour!$W:$W,J$2) -> 0 | K11: =IF(J11=0,0,L11/J11) -> 0 | L11: =-SUMIFS([5]BV_Data_An_Cour!$O:$O,[5]BV_Data_An_Cour!$U:$U,$B11,[5]BV_Data_An_Cour!$V:$V,$C11,[5]BV_Data_An_Cour!$W:$W,L$2) -> 0 | M11: =J11-D11 -> 0 | N11: =L11-F11 -> 0 | O11: {=+INDEX('[5]Réel 2023'!$A$2:$AO$501,MATCH($A11,'[5]Réel 2023'!$A$2:$A$501,0),MATCH(O$2,'[5]Réel 2023'!$A$2:$AO$2,0))} -> 0 | P11: =IF(O11=0,0,Q11/O11) -> 0 | Q11: {=+INDEX('[5]Réel 2023'!$A$2:$AO$501,MATCH($A11,'[5]Réel 2023'!$A$2:$A$501,0),MATCH(Q$2,'[5]Réel 2023'!$A$2:$AO$2,0))} -> 0 | R11: =J11-O11 -> 0 | S11: =L11-Q11 -> 0
A12: Véhicules neufs[...] | B12: Véhicules neufs | C12: [...] | D12: =+INDEX('[5]Budget original'!$A$2:$AO$501,MATCH($A12,'[5]Budget original'!$A$2:$A$501,0),MATCH(D$2,'[5]Budget original'!$A$2:$AO$2,0)) -> 0 | E12: =IF(D12=0,0,F12/D12) -> 0 | F12: =+INDEX('[5]Budget original'!$A$2:$AO$501,MATCH($A12,'[5]Budget original'!$A$2:$A$501,0),MATCH(F$2,'[5]Budget original'!$A$2:$AO$2,0)) -> 0 | J12: =-SUMIFS([5]BV_Data_An_Cour!$O:$O,[5]BV_Data_An_Cour!$U:$U,$B12,[5]BV_Data_An_Cour!$V:$V,$C12,[5]BV_Data_An_Cour!$W:$W,J$2) -> 0 | K12: =IF(J12=0,0,L12/J12) -> 0 | L12: =-SUMIFS([5]BV_Data_An_Cour!$O:$O,[5]BV_Data_An_Cour!$U:$U,$B12,[5]BV_Data_An_Cour!$V:$V,$C12,[5]BV_Data_An_Cour!$W:$W,L$2) -> 0 | M12: =J12-D12 -> 0 | N12: =L12-F12 -> 0 | O12: {=+INDEX('[5]Réel 2023'!$A$2:$AO$501,MATCH($A12,'[5]Réel 2023'!$A$2:$A$501,0),MATCH(O$2,'[5]Réel 2023'!$A$2:$AO$2,0))} -> 0 | P12: =IF(O12=0,0,Q12/O12) -> 0 | Q12: {=+INDEX('[5]Réel 2023'!$A$2:$AO$501,MATCH($A12,'[5]Réel 2023'!$A$2:$A$501,0),MATCH(Q$2,'[5]Réel 2023'!$A$2:$AO$2,0))} -> 0 | R12: =J12-O12 -> 0 | S12: =L12-Q12 -> 0
A13: Véhicules neufsTotal Neufs | B13: Véhicules neufs | C13: Total Neufs | D13: =+SUM(D6:D12) -> 73.92 | E13: =IF(D13<=0,0,F13/D13) -> 2741.7272 | F13: =+SUM(F6:F12) -> 202668.48 | J13: =+SUM(J6:J12) -> 44 | K13: =IF(J13<=0,0,L13/J13) -> 1588.6441 | L13: =+SUM(L6:L12) -> 69900.34 | M13: =+SUM(M6:M12) -> -29.92 | N13: =+SUM(N6:N12) -> -132768.14 | O13: =+SUM(O6:O12) -> 59 | P13: =IF(O13<=0,0,Q13/O13) -> 2523.302 | Q13: =+SUM(Q6:Q12) -> 148874.82 | R13: =+SUM(R6:R12) -> -15 | S13: =+SUM(S6:S12) -> -78974.48
A14: Véhicules neufs | B14: Véhicules neufs | M14: =IF(D13=0,0,M13/D13) -> -0.4047619 | N14: =IF(F13=0,0,N13/F13) -> -0.65510009 | R14: =R13/O13 -> -0.25423729 | S14: =IF(Q13=0,0,(S13/Q13)) -> -0.53047574 | AD14: 20 | AE14: 1000 | AF14: =AD14*AE14 -> 20000
A15: Véhicules neufsEx-Démos et courtoisies | B15: Véhicules neufs | C15: Ex-Démos et courtoisies | D15: =+INDEX('[5]Budget original'!$A$2:$AO$501,MATCH($A15,'[5]Budget original'!$A$2:$A$501,0),MATCH(D$2,'[5]Budget original'!$A$2:$AO$2,0)) -> 5.88 | E15: =IF(D15=0,0,F15/D15) -> 2535.1216 | F15: =+INDEX('[5]Budget original'!$A$2:$AO$501,MATCH($A15,'[5]Budget original'!$A$2:$A$501,0),MATCH(F$2,'[5]Budget original'!$A$2:$AO$2,0)) -> 14906.515 | J15: =-SUMIFS([5]BV_Data_An_Cour!$O:$O,[5]BV_Data_An_Cour!$U:$U,$B15,[5]BV_Data_An_Cour!$V:$V,$C15,[5]BV_Data_An_Cour!$W:$W,J$2) -> 6 | K15: =IF(J15=0,0,L15/J15) -> 1038.8833 | L15: =-SUMIFS([5]BV_Data_An_Cour!$O:$O,[5]BV_Data_An_Cour!$U:$U,$B15,[5]BV_Data_An_Cour!$V:$V,$C15,[5]BV_Data_An_Cour!$W:$W,L$2) -> 6233.3 | M15: =J15-D15 -> 0.12 | N15: =L15-F15 -> -8673.2149 | O15: {=+INDEX('[5]Réel 2023'!$A$2:$AO$501,MATCH($A15,'[5]Réel 2023'!$A$2:$A$501,0),MATCH(O$2,'[5]Réel 2023'!$A$2:$AO$2,0))} -> 0 | P15: =IF(O15=0,0,Q15/O15) -> 0 | Q15: {=+INDEX('[5]Réel 2023'!$A$2:$AO$501,MATCH($A15,'[5]Réel 2023'!$A$2:$A$501,0),MATCH(Q$2,'[5]Réel 2023'!$A$2:$AO$2,0))} -> 3550 | R15: =J15-O15 -> 6 | S15: =L15-Q15 -> 2683.3 | AD15: 25 | AE15: =AF15/AD15 -> 800 | AF15: =AF14 -> 20000
A16: Véhicules neufs | B16: Véhicules neufs
A17: Véhicules neufsFlottes | B17: Véhicules neufs | C17: Flottes | D17: =+INDEX('[5]Budget original'!$A$2:$AO$501,MATCH($A17,'[5]Budget original'!$A$2:$A$501,0),MATCH(D$2,'[5]Budget original'!$A$2:$AO$2,0)) -> 5.4 | E17: =IF(D17=0,0,F17/D17) -> 2664.4641 | F17: =+INDEX('[5]Budget original'!$A$2:$AO$501,MATCH($A17,'[5]Budget original'!$A$2:$A$501,0),MATCH(F$2,'[5]Budget original'!$A$2:$AO$2,0)) -> 14388.106 | J17: =-SUMIFS([5]BV_Data_An_Cour!$O:$O,[5]BV_Data_An_Cour!$U:$U,$B17,[5]BV_Data_An_Cour!$V:$V,$C17,[5]BV_Data_An_Cour!$W:$W,J$2) -> 2 | K17: =IF(J17=0,0,L17/J17) -> 383.48 | L17: =-SUMIFS([5]BV_Data_An_Cour!$O:$O,[5]BV_Data_An_Cour!$U:$U,$B17,[5]BV_Data_An_Cour!$V:$V,$C17,[5]BV_Data_An_Cour!$W:$W,L$2) -> 766.96 | M17: =J17-D17 -> -3.4 | N17: =L17-F17 -> -13621.146 | O17: {=+INDEX('[5]Réel 2023'!$A$2:$AO$501,MATCH($A17,'[5]Réel 2023'!$A$2:$A$501,0),MATCH(O$2,'[5]Réel 2023'!$A$2:$AO$2,0))} -> 8 | P17: =IF(O17=0,0,Q17/O17) -> 3193.38 | Q17: {=+INDEX('[5]Réel 2023'!$A$2:$AO$501,MATCH($A17,'[5]Réel 2023'!$A$2:$A$501,0),MATCH(Q$2,'[5]Réel 2023'!$A$2:$AO$2,0))} -> 25547.04 | R17: =J17-O17 -> -6 | S17: =L17-Q17 -> -24780.08
A18: Véhicules neufs | B18: Véhicules neufs
A19: Véhicules neufsRachat bail | B19: Véhicules neufs | C19: Rachat bail | D19: =+INDEX('[5]Budget original'!$A$2:$AO$501,MATCH($A19,'[5]Budget original'!$A$2:$A$501,0),MATCH(D$2,'[5]Budget original'!$A$2:$AO$2,0)) -> 0 | E19: =IF(D19=0,0,F19/D19) -> 0 | F19: =+INDEX('[5]Budget original'!$A$2:$AO$501,MATCH($A19,'[5]Budget original'!$A$2:$A$501,0),MATCH(F$2,'[5]Budget original'!$A$2:$AO$2,0)) -> 10200 | L19: =-SUMIFS([5]BV_Data_An_Cour!$O:$O,[5]BV_Data_An_Cour!$U:$U,$B19,[5]BV_Data_An_Cour!$V:$V,$C19,[5]BV_Data_An_Cour!$W:$W,L$2) -> 10100 | N19: =L19-F19 -> -100 | Q19: {=+INDEX('[5]Réel 2023'!$A$2:$AO$501,MATCH($A19,'[5]Réel 2023'!$A$2:$A$501,0),MATCH(Q$2,'[5]Réel 2023'!$A$2:$AO$2,0))} -> 8229.71 | R19: =O19-K19 -> 0 | S19: =L19-Q19 -> 1870.29
A20: Véhicules neufs | B20: Véhicules neufs
A21: Véhicules neufsRev. Finances | B21: Véhicules neufs | C21: Rev. Finances | D21: =+INDEX('[5]Budget original'!$A$2:$AO$501,MATCH($A21,'[5]Budget original'!$A$2:$A$501,0),MATCH(D$2,'[5]Budget original'!$A$2:$AO$2,0)) -> 0 | E21: =IF(D21=0,0,F21/D21) -> 0 | F21: =+INDEX('[5]Budget original'!$A$2:$AO$501,MATCH($A21,'[5]Budget original'!$A$2:$A$501,0),MATCH(F$2,'[5]Budget original'!$A$2:$AO$2,0)) -> 15960 | K21: =IF(J13=0,0,L21/(J13+J15)) -> 0 | L21: =-SUMIFS([5]BV_Data_An_Cour!$O:$O,[5]BV_Data_An_Cour!$U:$U,$B21,[5]BV_Data_An_Cour!$V:$V,$C21,[5]BV_Data_An_Cour!$W:$W,L$2) -> 0 | N21: =L21-F21 -> -15960 | Q21: {=+INDEX('[5]Réel 2023'!$A$2:$AO$501,MATCH($A21,'[5]Réel 2023'!$A$2:$A$501,0),MATCH(Q$2,'[5]Réel 2023'!$A$2:$AO$2,0))} -> 3481.61 | R21: =O21-K21 -> 0 | S21: =L21-Q21 -> -3481.61
A22: Véhicules neufsRev. Protections | B22: Véhicules neufs | C22: Rev. Protections | D22: =+INDEX('[5]Budget original'!$A$2:$AO$501,MATCH($A22,'[5]Budget original'!$A$2:$A$501,0),MATCH(D$2,'[5]Budget original'!$A$2:$AO$2,0)) -> 0 | E22: =IF(D22=0,0,F22/D22) -> 0 | F22: =+INDEX('[5]Budget original'!$A$2:$AO$501,MATCH($A22,'[5]Budget original'!$A$2:$A$501,0),MATCH(F$2,'[5]Budget original'!$A$2:$AO$2,0)) -> 86184 | K22: =IF(J13=0,0,L22/(J13+J15)) -> 844.5266 | L22: =-SUMIFS([5]BV_Data_An_Cour!$O:$O,[5]BV_Data_An_Cour!$U:$U,$B22,[5]BV_Data_An_Cour!$V:$V,$C22,[5]BV_Data_An_Cour!$W:$W,L$2) -> 42226.33 | N22: =L22-F22 -> -43957.67 | Q22: {=+INDEX('[5]Réel 2023'!$A$2:$AO$501,MATCH($A22,'[5]Réel 2023'!$A$2:$A$501,0),MATCH(Q$2,'[5]Réel 2023'!$A$2:$AO$2,0))} -> 55582.9 | R22: =O22-K22 -> -844.5266 | S22: =L22-Q22 -> -13356.57
A23: Véhicules neufsRev. Autres | B23: Véhicules neufs | C23: Rev. Autres | D23: =+INDEX('[5]Budget original'!$A$2:$AO$501,MATCH($A23,'[5]Budget original'!$A$2:$A$501,0),MATCH(D$2,'[5]Budget original'!$A$2:$AO$2,0)) -> 0 | E23: =IF(D23=0,0,F23/D23) -> 0 | F23: =+INDEX('[5]Budget original'!$A$2:$AO$501,MATCH($A23,'[5]Budget original'!$A$2:$A$501,0),MATCH(F$2,'[5]Budget original'!$A$2:$AO$2,0)) -> 1596 | K23: =IF(J13=0,0,L23/(J13+J15)) -> 12.8804 | L23: =-SUMIFS([5]BV_Data_An_Cour!$O:$O,[5]BV_Data_An_Cour!$U:$U,$B23,[5]BV_Data_An_Cour!$V:$V,$C23,[5]BV_Data_An_Cour!$W:$W,L$2) -> 644.02 | N23: =L23-F23 -> -951.98 | Q23: {=+INDEX('[5]Réel 2023'!$A$2:$AO$501,MATCH($A23,'[5]Réel 2023'!$A$2:$A$501,0),MATCH(Q$2,'[5]Réel 2023'!$A$2:$AO$2,0))} -> 398.21 | R23: =O23-K23 -> -12.8804 | S23: =L23-Q23 -> 245.81
A24: Véhicules neufsTotal F&I | B24: Véhicules neufs | C24: Total F&I | D24: =+D15+D13 -> 79.8 | E24: =IF(D24<=0,0,F24/D24) -> 1300 | F24: =F21+F22+F23 -> 103740 | J24: =+J15+J13 -> 50 | K24: =IF(J24<=0,0,L24/J24) -> 857.407 | L24: =L21+L22+L23 -> 42870.35 | M24: =J24-D24 -> -29.8 | N24: =L24-F24 -> -60869.65 | O24: =+O15+O13 -> 59 | P24: =IF(O24<=0,0,Q24/O24) -> 1007.8427 | Q24: =Q21+Q22+Q23 -> 59462.72 | S24: =L24-Q24 -> -16592.37
A25: Véhicules neufs | B25: Véhicules neufs | N25: =IF(N24=0,0,N24/F24) -> -0.58675198 | S25: =IF(Q24=0,0,(S24/Q24)) -> -0.27903819
A26: Véhicules neufs | B26: Véhicules neufs
A27: Véhicules neufsTotal Dépt. Neufs | B27: Véhicules neufs | C27: Total Dépt. Neufs | D27: =+D13+D15+D17 -> 85.2 | E27: =IF(D27<=0,0,F27/D27) -> 4059.8955 | F27: =F13+F17+F24+F19+F15 -> 345903.1 | J27: =+J13+J15+J17 -> 52 | K27: =IF(J27<=0,0,L27/J27) -> 2497.5183 | L27: =L13+L17+L24+L19+L15 -> 129870.95 | M27: =J27-D27 -> -33.2 | N27: =L27-F27 -> -216032.15 | O27: =+O13+O15+O17 -> 67 | P27: =IF(O27<=0,0,Q27/O27) -> 3666.6312 | Q27: =Q13+Q17+Q24+Q19+Q15 -> 245664.29 | R27: =J27-O27 -> -15 | S27: =L27-Q27 -> -115793.34
A28: Véhicules neufs | B28: Véhicules neufs | L28: =L27/F27 -> 0.37545472 | M28: =M27/D27 -> -0.38967136 | N28: =N27/F27 -> -0.62454528 | R28: =R27/O27 -> -0.2238806 | S28: =IF(Q27=0,0,S27/Q27) -> -0.47134787
A29: Véhicules neufs | B29: Véhicules neufs
A30: Véhicules neufsDEPENSES | B30: Véhicules neufs | C30: DEPENSES
A31: Véhicules neufsComm. vendeurs | B31: Véhicules neufs | C31: Comm. vendeurs | D31: =F31/(F13+F15) -> 0.34 | E31: =F31/D$24 -> 927.01125 | F31: =+INDEX('[5]Budget original'!$A$2:$AO$501,MATCH($A31,'[5]Budget original'!$A$2:$A$501,0),MATCH(F$2,'[5]Budget original'!$A$2:$AO$2,0)) -> 73975.497 | J31: =L31/(L15+L13+L17) -> 0.36538037 | K31: =IF(L31=0,0,L31/J$24) -> 561.9594 | L31: =SUMIFS([5]BV_Data_An_Cour!$O:$O,[5]BV_Data_An_Cour!$U:$U,$B31,[5]BV_Data_An_Cour!$V:$V,$C31,[5]BV_Data_An_Cour!$W:$W,L$2) -> 28097.97 | N31: =L31-F31 -> -45877.527 | O31: =Q31/(Q13+Q15+Q17) -> 0.23546953 | P31: =Q31/O$24 -> 710.28729 | Q31: {=+INDEX('[5]Réel 2023'!$A$2:$AO$501,MATCH($A31,'[5]Réel 2023'!$A$2:$A$501,0),MATCH(Q$2,'[5]Réel 2023'!$A$2:$AO$2,0))} -> 41906.95 | S31: =L31-Q31 -> -13808.98
A32: Véhicules neufsComm. F&I | B32: Véhicules neufs | C32: Comm. F&I | D32: =F32/F24 -> 0.3 | E32: =F32/D$24 -> 390 | F32: =+INDEX('[5]Budget original'!$A$2:$AO$501,MATCH($A32,'[5]Budget original'!$A$2:$A$501,0),MATCH(F$2,'[5]Budget original'!$A$2:$AO$2,0)) -> 31122 | J32: =L32/L24 -> 0.26999336 | K32: =IF(L32=0,0,L32/J$24) -> 231.4942 | L32: =SUMIFS([5]BV_Data_An_Cour!$O:$O,[5]BV_Data_An_Cour!$U:$U,$B32,[5]BV_Data_An_Cour!$V:$V,$C32,[5]BV_Data_An_Cour!$W:$W,L$2) -> 11574.71 | N32: =L32-F32 -> -19547.29 | O32: =Q32/Q24 -> 0.29873305 | P32: =Q32/O$24 -> 301.07593 | Q32: {=+INDEX('[5]Réel 2023'!$A$2:$AO$501,MATCH($A32,'[5]Réel 2023'!$A$2:$A$501,0),MATCH(Q$2,'[5]Réel 2023'!$A$2:$AO$2,0))} -> 17763.48 | S32: =L32-Q32 -> -6188.77
A33: Véhicules neufsFrais de livraison | B33: Véhicules neufs | C33: Frais de livraison | E33: =F33/D$24 -> 115 | F33: =+INDEX('[5]Budget original'!$A$2:$AO$501,MATCH($A33,'[5]Budget original'!$A$2:$A$501,0),MATCH(F$2,'[5]Budget original'!$A$2:$AO$2,0)) -> 9177 | K33: =IF(L33=0,0,L33/J$24) -> 156.3466 | L33: =SUMIFS([5]BV_Data_An_Cour!$O:$O,[5]BV_Data_An_Cour!$U:$U,$B33,[5]BV_Data_An_Cour!$V:$V,$C33,[5]BV_Data_An_Cour!$W:$W,L$2) -> 7817.33 | N33: =L33-F33 -> -1359.67 | P33: =Q33/O$24 -> 131.92102 | Q33: {=+INDEX('[5]Réel 2023'!$A$2:$AO$501,MATCH($A33,'[5]Réel 2023'!$A$2:$A$501,0),MATCH(Q$2,'[5]Réel 2023'!$A$2:$AO$2,0))} -> 7783.34 | S33: =L33-Q33 -> 33.99
A34: Véhicules neufsService gratuit 1 | B34: Véhicules neufs | C34: Service gratuit 1 | E34: =F34/D$24 -> 3 | F34: =+INDEX('[5]Budget original'!$A$2:$AO$501,MATCH($A34,'[5]Budget original'!$A$2:$A$501,0),MATCH(F$2,'[5]Budget original'!$A$2:$AO$2,0)) -> 239.4 | K34: =IF(L34=0,0,L34/J$24) -> 16.8636 | L34: =SUMIFS([5]BV_Data_An_Cour!$O:$O,[5]BV_Data_An_Cour!$U:$U,$B34,[5]BV_Data_An_Cour!$V:$V,$C34,[5]BV_Data_An_Cour!$W:$W,L$2) -> 843.18 | N34: =L34-F34 -> 603.78 | P34: =Q34/O$24 -> 9.4247458 | Q34: {=+INDEX('[5]Réel 2023'!$A$2:$AO$501,MATCH($A34,'[5]Réel 2023'!$A$2:$A$501,0),MATCH(Q$2,'[5]Réel 2023'!$A$2:$AO$2,0))} -> 556.06 | S34: =L34-Q34 -> 287.12
A35: Véhicules neufsEntretien stock | B35: Véhicules neufs | C35: Entretien stock | E35: =F35/D$24 -> 85.05 | F35: =+INDEX('[5]Budget original'!$A$2:$AO$501,MATCH($A35,'[5]Budget original'!$A$2:$A$501,0),MATCH(F$2,'[5]Budget original'!$A$2:$AO$2,0)) -> 6786.99 | K35: =IF(L35=0,0,L35/J$24) -> 159.8588 | L35: =SUMIFS([5]BV_Data_An_Cour!$O:$O,[5]BV_Data_An_Cour!$U:$U,$B35,[5]BV_Data_An_Cour!$V:$V,$C35,[5]BV_Data_An_Cour!$W:$W,L$2) -> 7992.94 | N35: =L35-F35 -> 1205.95 | P35: =Q35/O$24 -> 92.110169 | Q35: {=+INDEX('[5]Réel 2023'!$A$2:$AO$501,MATCH($A35,'[5]Réel 2023'!$A$2:$A$501,0),MATCH(Q$2,'[5]Réel 2023'!$A$2:$AO$2,0))} -> 5434.5 | S35: =L35-Q35 -> 2558.44
A36: Véhicules neufsPublicité 1 | B36: Véhicules neufs | C36: Publicité 1 | E36: =F36/D$24 -> 78.39599 | F36: =+INDEX('[5]Budget original'!$A$2:$AO$501,MATCH($A36,'[5]Budget original'!$A$2:$A$501,0),MATCH(F$2,'[5]Budget original'!$A$2:$AO$2,0)) -> 6256 | K36: =IF(L36=0,0,L36/J$24) -> 224.6836 | L36: =SUMIFS([5]BV_Data_An_Cour!$O:$O,[5]BV_Data_An_Cour!$U:$U,$B36,[5]BV_Data_An_Cour!$V:$V,$C36,[5]BV_Data_An_Cour!$W:$W,L$2) -> 11234.18 | N36: =L36-F36 -> 4978.18 | P36: =Q36/O$24 -> 155.86983 | Q36: {=+INDEX('[5]Réel 2023'!$A$2:$AO$501,MATCH($A36,'[5]Réel 2023'!$A$2:$A$501,0),MATCH(Q$2,'[5]Réel 2023'!$A$2:$AO$2,0))} -> 9196.32 | S36: =L36-Q36 -> 2037.86
A37: Véhicules neufsIntérêt de gros | B37: Véhicules neufs | C37: Intérêt de gros | E37: =F37/D$24 -> 242.16209 | F37: =+INDEX('[5]Budget original'!$A$2:$AO$501,MATCH($A37,'[5]Budget original'!$A$2:$A$501,0),MATCH(F$2,'[5]Budget original'!$A$2:$AO$2,0)) -> 19324.535 | K37: =IF(L37=0,0,L37/J$24) -> 530.407 | L37: =SUMIFS([5]BV_Data_An_Cour!$O:$O,[5]BV_Data_An_Cour!$U:$U,$B37,[5]BV_Data_An_Cour!$V:$V,$C37,[5]BV_Data_An_Cour!$W:$W,L$2) -> 26520.35 | N37: =L37-F37 -> 7195.8149 | P37: =Q37/O$24 -> 0 | Q37: {=+INDEX('[5]Réel 2023'!$A$2:$AO$501,MATCH($A37,'[5]Réel 2023'!$A$2:$A$501,0),MATCH(Q$2,'[5]Réel 2023'!$A$2:$AO$2,0))} -> 0 | S37: =L37-Q37 -> 26520.35
A38: Véhicules neufs[...] | B38: Véhicules neufs | C38: [...] | E38: =F38/D$24 -> 0 | F38: =+INDEX('[5]Budget original'!$A$2:$AO$501,MATCH($A38,'[5]Budget original'!$A$2:$A$501,0),MATCH(F$2,'[5]Budget original'!$A$2:$AO$2,0)) -> 0 | K38: =IF(L38=0,0,L38/J$24) -> 0 | L38: =SUMIFS([5]BV_Data_An_Cour!$O:$O,[5]BV_Data_An_Cour!$U:$U,$B38,[5]BV_Data_An_Cour!$V:$V,$C38,[5]BV_Data_An_Cour!$W:$W,L$2) -> 0 | N38: =L38-F38 -> 0 | P38: =Q38/O$24 -> 0 | Q38: {=+INDEX('[5]Réel 2023'!$A$2:$AO$501,MATCH($A38,'[5]Réel 2023'!$A$2:$A$501,0),MATCH(Q$2,'[5]Réel 2023'!$A$2:$AO$2,0))} -> 0 | S38: =L38-Q38 -> 0
A39: Véhicules neufs[...] | B39: Véhicules neufs | C39: [...] | E39: =F39/D$24 -> 0 | F39: =+INDEX('[5]Budget original'!$A$2:$AO$501,MATCH($A39,'[5]Budget original'!$A$2:$A$501,0),MATCH(F$2,'[5]Budget original'!$A$2:$AO$2,0)) -> 0 | K39: =IF(L39=0,0,L39/J$24) -> 0 | L39: =SUMIFS([5]BV_Data_An_Cour!$O:$O,[5]BV_Data_An_Cour!$U:$U,$B39,[5]BV_Data_An_Cour!$V:$V,$C39,[5]BV_Data_An_Cour!$W:$W,L$2) -> 0 | N39: =L39-F39 -> 0 | P39: =Q39/O$24 -> 0 | Q39: {=+INDEX('[5]Réel 2023'!$A$2:$AO$501,MATCH($A39,'[5]Réel 2023'!$A$2:$A$501,0),MATCH(Q$2,'[5]Réel 2023'!$A$2:$AO$2,0))} -> 0 | S39: =L39-Q39 -> 0
A40: Véhicules neufs[...] | B40: Véhicules neufs | C40: [...] | E40: =F40/D$24 -> 0 | F40: =+INDEX('[5]Budget original'!$A$2:$AO$501,MATCH($A40,'[5]Budget original'!$A$2:$A$501,0),MATCH(F$2,'[5]Budget original'!$A$2:$AO$2,0)) -> 0 | K40: =IF(L40=0,0,L40/J$24) -> 0 | L40: =SUMIFS([5]BV_Data_An_Cour!$O:$O,[5]BV_Data_An_Cour!$U:$U,$B40,[5]BV_Data_An_Cour!$V:$V,$C40,[5]BV_Data_An_Cour!$W:$W,L$2) -> 0 | N40: =L40-F40 -> 0 | P40: =Q40/O$24 -> 0 | Q40: {=+INDEX('[5]Réel 2023'!$A$2:$AO$501,MATCH($A40,'[5]Réel 2023'!$A$2:$A$501,0),MATCH(Q$2,'[5]Réel 2023'!$A$2:$AO$2,0))} -> 0 | S40: =L40-Q40 -> 0
...

Sheet Print_Mois
C1: =[7]Parametres!B1 -> Volks | K1: Véhicules neufs | S1: =CONCATENATE("Réalisé,"," ",[7]Parametres!B3," ",[7]Parametres!B4) -> Réalisé, Novembre 2024
D2: X | E2: O | F2: U | J2: NB | L2: $ | O2: X | P2: O | Q2: U | V2: *** NE PAS EFFACER / Pour An Précédente ***
D3: BUDGET ORIGINAL | J3: RÉALISATION | M3: ÉCART réel / Budget | O3: ANNÉE PRÉCÉDENTE | R3: ECART (réel/ Ann.Préc.) | V3: NEUF | W3: 0.45
D4: UNITE | E4: $P/UNITÉ | F4: $PROFITS | J4: UNITÉS | K4: $P/UNITE | L4: $PROFITS | M4: UNITÉS | N4: $PROFITS | O4: UNITE | P4: $P/UNITÉ | Q4: $PROFITS | R4: UNITÉS | S4: $PROFITS | V4: USAGE | W4: 0.1
A5: Véhicules neufsVentes nettes | B5: Véhicules neufs | C5: Ventes nettes | F5: =+INDEX('[7]Budget original'!$A$2:$AO$501,MATCH($A5,'[7]Budget original'!$A$2:$A$501,0),MATCH(F$2,'[7]Budget original'!$A$2:$AO$2,0)) -> 3242782.3 | L5: =-SUMIFS([7]BV_Data_An_Cour!$O:$O,[7]BV_Data_An_Cour!$X:$X,"Oui",[7]BV_Data_An_Cour!$U:$U,$B5) -> 2101403.3 | Q5: {=+INDEX('[7]Réel 2023'!$A$2:$AO$501,MATCH($A5,'[7]Réel 2023'!$A$2:$A$501,0),MATCH(Q$2,'[7]Réel 2023'!$A$2:$AO$2,0))} -> 10151414 | V5: SERVICE | W5: 0.225
A6: Véhicules neufsAutos détail | B6: Véhicules neufs | C6: Autos détail | D6: =+INDEX('[7]Budget original'!$A$2:$AO$501,MATCH($A6,'[7]Budget original'!$A$2:$A$501,0),MATCH(D$2,'[7]Budget original'!$A$2:$AO$2,0)) -> 12 | E6: =IF(D6=0,0,F6/D6) -> 2198.1219 | F6: =+INDEX('[7]Budget original'!$A$2:$AO$501,MATCH($A6,'[7]Budget original'!$A$2:$A$501,0),MATCH(F$2,'[7]Budget original'!$A$2:$AO$2,0)) -> 26377.463 | J6: =-SUMIFS([7]BV_Data_An_Cour!$O:$O,[7]BV_Data_An_Cour!$U:$U,$B6,[7]BV_Data_An_Cour!$V:$V,$C6,[7]BV_Data_An_Cour!$W:$W,J$2) -> 8 | K6: =IF(J6=0,0,L6/J6) -> 2031.0612 | L6: =-SUMIFS([7]BV_Data_An_Cour!$O:$O,[7]BV_Data_An_Cour!$U:$U,$B6,[7]BV_Data_An_Cour!$V:$V,$C6,[7]BV_Data_An_Cour!$W:$W,L$2) -> 16248.49 | M6: =J6-D6 -> -4 | N6: =L6-F6 -> -10128.973 | O6: =+INDEX('[7]Réel 2023'!$A$2:$AO$501,MATCH($A6,'[7]Réel 2023'!$A$2:$A$501,0),MATCH(O$2,'[7]Réel 2023'!$A$2:$AO$2,0)) -> 18 | P6: =IF(O6=0,0,Q6/O6) -> 2139.7994 | Q6: {=+INDEX('[7]Réel 2023'!$A$2:$AO$501,MATCH($A6,'[7]Réel 2023'!$A$2:$A$501,0),MATCH(Q$2,'[7]Réel 2023'!$A$2:$AO$2,0))} -> 38516.39 | R6: =J6-O6 -> -10 | S6: =L6-Q6 -> -22267.9 | V6: CARROSSERIE | W6: 0.025
A7: Véhicules neufsCamions détail | B7: Véhicules neufs | C7: Camions détail | D7: =+INDEX('[7]Budget original'!$A$2:$AO$501,MATCH($A7,'[7]Budget original'!$A$2:$A$501,0),MATCH(D$2,'[7]Budget original'!$A$2:$AO$2,0)) -> 49.8 | E7: =IF(D7=0,0,F7/D7) -> 2861.7055 | F7: =+INDEX('[7]Budget original'!$A$2:$AO$501,MATCH($A7,'[7]Budget original'!$A$2:$A$501,0),MATCH(F$2,'[7]Budget original'!$A$2:$AO$2,0)) -> 142512.93 | J7: =-SUMIFS([7]BV_Data_An_Cour!$O:$O,[7]BV_Data_An_Cour!$U:$U,$B7,[7]BV_Data_An_Cour!$V:$V,$C7,[7]BV_Data_An_Cour!$W:$W,J$2) -> 27 | K7: =IF(J7=0,0,L7/J7) -> 2114.5019 | L7: =-SUMIFS([7]BV_Data_An_Cour!$O:$O,[7]BV_Data_An_Cour!$U:$U,$B7,[7]BV_Data_An_Cour!$V:$V,$C7,[7]BV_Data_An_Cour!$W:$W,L$2) -> 57091.55 | M7: =J7-D7 -> -22.8 | N7: =L7-F7 -> -85421.385 | O7: {=+INDEX('[7]Réel 2023'!$A$2:$AO$501,MATCH($A7,'[7]Réel 2023'!$A$2:$A$501,0),MATCH(O$2,'[7]Réel 2023'!$A$2:$AO$2,0))} -> 71 | P7: =IF(O7=0,0,Q7/O7) -> 2320.119 | Q7: {=+INDEX('[7]Réel 2023'!$A$2:$AO$501,MATCH($A7,'[7]Réel 2023'!$A$2:$A$501,0),MATCH(Q$2,'[7]Réel 2023'!$A$2:$AO$2,0))} -> 164728.45 | R7: =J7-O7 -> -44 | S7: =L7-Q7 -> -107636.9 | V7: PIECES | W7: 0.2
A8: Véhicules neufsSprinter | B8: Véhicules neufs | C8: Sprinter | D8: =+INDEX('[7]Budget original'!$A$2:$AO$501,MATCH($A8,'[7]Budget original'!$A$2:$A$501,0),MATCH(D$2,'[7]Budget original'!$A$2:$AO$2,0)) -> 0 | E8: =IF(D8=0,0,F8/D8) -> 0 | F8: =+INDEX('[7]Budget original'!$A$2:$AO$501,MATCH($A8,'[7]Budget original'!$A$2:$A$501,0),MATCH(F$2,'[7]Budget original'!$A$2:$AO$2,0)) -> 0 | J8: =-SUMIFS([7]BV_Data_An_Cour!$O:$O,[7]BV_Data_An_Cour!$U:$U,$B8,[7]BV_Data_An_Cour!$V:$V,$C8,[7]BV_Data_An_Cour!$W:$W,J$2) -> 0 | K8: =IF(J8=0,0,L8/J8) -> 0 | L8: =-SUMIFS([7]BV_Data_An_Cour!$O:$O,[7]BV_Data_An_Cour!$U:$U,$B8,[7]BV_Data_An_Cour!$V:$V,$C8,[7]BV_Data_An_Cour!$W:$W,L$2) -> 0 | M8: =J8-D8 -> 0 | N8: =L8-F8 -> 0 | O8: {=+INDEX('[7]Réel 2023'!$A$2:$AO$501,MATCH($A8,'[7]Réel 2023'!$A$2:$A$501,0),MATCH(O$2,'[7]Réel 2023'!$A$2:$AO$2,0))} -> 0 | P8: =IF(O8=0,0,Q8/O8) -> 0 | Q8: {=+INDEX('[7]Réel 2023'!$A$2:$AO$501,MATCH($A8,'[7]Réel 2023'!$A$2:$A$501,0),MATCH(Q$2,'[7]Réel 2023'!$A$2:$AO$2,0))} -> 0 | R8: =J8-O8 -> 0 | S8: =L8-Q8 -> 0 | W8: =SUM(W3:W7) -> 1
A9: Véhicules neufsMoto détail | B9: Véhicules neufs | C9: Moto détail | D9: =+INDEX('[7]Budget original'!$A$2:$AO$501,MATCH($A9,'[7]Budget original'!$A$2:$A$501,0),MATCH(D$2,'[7]Budget original'!$A$2:$AO$2,0)) -> 0 | E9: =IF(D9=0,0,F9/D9) -> 0 | F9: =+INDEX('[7]Budget original'!$A$2:$AO$501,MATCH($A9,'[7]Budget original'!$A$2:$A$501,0),MATCH(F$2,'[7]Budget original'!$A$2:$AO$2,0)) -> 0 | J9: =-SUMIFS([7]BV_Data_An_Cour!$O:$O,[7]BV_Data_An_Cour!$U:$U,$B9,[7]BV_Data_An_Cour!$V:$V,$C9,[7]BV_Data_An_Cour!$W:$W,J$2) -> 0 | K9: =IF(J9=0,0,L9/J9) -> 0 | L9: =-SUMIFS([7]BV_Data_An_Cour!$O:$O,[7]BV_Data_An_Cour!$U:$U,$B9,[7]BV_Data_An_Cour!$V:$V,$C9,[7]BV_Data_An_Cour!$W:$W,L$2) -> 0 | M9: =J9-D9 -> 0 | N9: =L9-F9 -> 0 | O9: {=+INDEX('[7]Réel 2023'!$A$2:$AO$501,MATCH($A9,'[7]Réel 2023'!$A$2:$A$501,0),MATCH(O$2,'[7]Réel 2023'!$A$2:$AO$2,0))} -> 0 | P9: =IF(O9=0,0,Q9/O9) -> 0 | Q9: {=+INDEX('[7]Réel 2023'!$A$2:$AO$501,MATCH($A9,'[7]Réel 2023'!$A$2:$A$501,0),MATCH(Q$2,'[7]Réel 2023'!$A$2:$AO$2,0))} -> 0 | R9: =J9-O9 -> 0 | S9: =L9-Q9 -> 0
A10: Véhicules neufs[...] | B10: Véhicules neufs | C10: [...] | D10: =+INDEX('[7]Budget original'!$A$2:$AO$501,MATCH($A10,'[7]Budget original'!$A$2:$A$501,0),MATCH(D$2,'[7]Budget original'!$A$2:$AO$2,0)) -> 0 | E10: =IF(D10=0,0,F10/D10) -> 0 | F10: =+INDEX('[7]Budget original'!$A$2:$AO$501,MATCH($A10,'[7]Budget original'!$A$2:$A$501,0),MATCH(F$2,'[7]Budget original'!$A$2:$AO$2,0)) -> 0 | J10: =-SUMIFS([7]BV_Data_An_Cour!$O:$O,[7]BV_Data_An_Cour!$U:$U,$B10,[7]BV_Data_An_Cour!$V:$V,$C10,[7]BV_Data_An_Cour!$W:$W,J$2) -> 0 | K10: =IF(J10=0,0,L10/J10) -> 0 | L10: =-SUMIFS([7]BV_Data_An_Cour!$O:$O,[7]BV_Data_An_Cour!$U:$U,$B10,[7]BV_Data_An_Cour!$V:$V,$C10,[7]BV_Data_An_Cour!$W:$W,L$2) -> 0 | M10: =J10-D10 -> 0 | N10: =L10-F10 -> 0 | O10: {=+INDEX('[7]Réel 2023'!$A$2:$AO$501,MATCH($A10,'[7]Réel 2023'!$A$2:$A$501,0),MATCH(O$2,'[7]Réel 2023'!$A$2:$AO$2,0))} -> 0 | P10: =IF(O10=0,0,Q10/O10) -> 0 | Q10: {=+INDEX('[7]Réel 2023'!$A$2:$AO$501,MATCH($A10,'[7]Réel 2023'!$A$2:$A$501,0),MATCH(Q$2,'[7]Réel 2023'!$A$2:$AO$2,0))} -> 0 | R10: =J10-O10 -> 0 | S10: =L10-Q10 -> 0
A11: Véhicules neufs[...] | B11: Véhicules neufs | C11: [...] | D11: =+INDEX('[7]Budget original'!$A$2:$AO$501,MATCH($A11,'[7]Budget original'!$A$2:$A$501,0),MATCH(D$2,'[7]Budget original'!$A$2:$AO$2,0)) -> 0 | E11: =IF(D11=0,0,F11/D11) -> 0 | F11: =+INDEX('[7]Budget original'!$A$2:$AO$501,MATCH($A11,'[7]Budget original'!$A$2:$A$501,0),MATCH(F$2,'[7]Budget original'!$A$2:$AO$2,0)) -> 0 | J11: =-SUMIFS([7]BV_Data_An_Cour!$O:$O,[7]BV_Data_An_Cour!$U:$U,$B11,[7]BV_Data_An_Cour!$V:$V,$C11,[7]BV_Data_An_Cour!$W:$W,J$2) -> 0 | K11: =IF(J11=0,0,L11/J11) -> 0 | L11: =-SUMIFS([7]BV_Data_An_Cour!$O:$O,[7]BV_Data_An_Cour!$U:$U,$B11,[7]BV_Data_An_Cour!$V:$V,$C11,[7]BV_Data_An_Cour!$W:$W,L$2) -> 0 | M11: =J11-D11 -> 0 | N11: =L11-F11 -> 0 | O11: {=+INDEX('[7]Réel 2023'!$A$2:$AO$501,MATCH($A11,'[7]Réel 2023'!$A$2:$A$501,0),MATCH(O$2,'[7]Réel 2023'!$A$2:$AO$2,0))} -> 0 | P11: =IF(O11=0,0,Q11/O11) -> 0 | Q11: {=+INDEX('[7]Réel 2023'!$A$2:$AO$501,MATCH($A11,'[7]Réel 2023'!$A$2:$A$501,0),MATCH(Q$2,'[7]Réel 2023'!$A$2:$AO$2,0))} -> 0 | R11: =J11-O11 -> 0 | S11: =L11-Q11 -> 0
A12: Véhicules neufs[...] | B12: Véhicules neufs | C12: [...] | D12: =+INDEX('[7]Budget original'!$A$2:$AO$501,MATCH($A12,'[7]Budget original'!$A$2:$A$501,0),MATCH(D$2,'[7]Budget original'!$A$2:$AO$2,0)) -> 0 | E12: =IF(D12=0,0,F12/D12) -> 0 | F12: =+INDEX('[7]Budget original'!$A$2:$AO$501,MATCH($A12,'[7]Budget original'!$A$2:$A$501,0),MATCH(F$2,'[7]Budget original'!$A$2:$AO$2,0)) -> 0 | J12: =-SUMIFS([7]BV_Data_An_Cour!$O:$O,[7]BV_Data_An_Cour!$U:$U,$B12,[7]BV_Data_An_Cour!$V:$V,$C12,[7]BV_Data_An_Cour!$W:$W,J$2) -> 0 | K12: =IF(J12=0,0,L12/J12) -> 0 | L12: =-SUMIFS([7]BV_Data_An_Cour!$O:$O,[7]BV_Data_An_Cour!$U:$U,$B12,[7]BV_Data_An_Cour!$V:$V,$C12,[7]BV_Data_An_Cour!$W:$W,L$2) -> 0 | M12: =J12-D12 -> 0 | N12: =L12-F12 -> 0 | O12: {=+INDEX('[7]Réel 2023'!$A$2:$AO$501,MATCH($A12,'[7]Réel 2023'!$A$2:$A$501,0),MATCH(O$2,'[7]Réel 2023'!$A$2:$AO$2,0))} -> 0 | P12: =IF(O12=0,0,Q12/O12) -> 0 | Q12: {=+INDEX('[7]Réel 2023'!$A$2:$AO$501,MATCH($A12,'[7]Réel 2023'!$A$2:$A$501,0),MATCH(Q$2,'[7]Réel 2023'!$A$2:$AO$2,0))} -> 0 | R12: =J12-O12 -> 0 | S12: =L12-Q12 -> 0
A13: Véhicules neufsTotal Neufs | B13: Véhicules neufs | C13: Total Neufs | D13: =+SUM(D6:D12) -> 61.8 | E13: =IF(D13<=0,0,F13/D13) -> 2732.8543 | F13: =+SUM(F6:F12) -> 168890.4 | J13: =+SUM(J6:J12) -> 35 | K13: =IF(J13<=0,0,L13/J13) -> 2095.4297 | L13: =+SUM(L6:L12) -> 73340.04 | M13: =+SUM(M6:M12) -> -26.8 | N13: =+SUM(N6:N12) -> -95550.358 | O13: =+SUM(O6:O12) -> 89 | P13: =IF(O13<=0,0,Q13/O13) -> 2283.6499 | Q13: =+SUM(Q6:Q12) -> 203244.84 | R13: =+SUM(R6:R12) -> -54 | S13: =+SUM(S6:S12) -> -129904.8
A14: Véhicules neufs | B14: Véhicules neufs | M14: =IF(D13=0,0,M13/D13) -> -0.43365696 | N14: =IF(F13=0,0,N13/F13) -> -0.56575364 | R14: =R13/O13 -> -0.60674157 | S14: =IF(Q13=0,0,(S13/Q13)) -> -0.63915423 | AD14: 20 | AE14: 1000 | AF14: =AD14*AE14 -> 20000
A15: Véhicules neufsEx-Démos et courtoisies | B15: Véhicules neufs | C15: Ex-Démos et courtoisies | D15: =+INDEX('[7]Budget original'!$A$2:$AO$501,MATCH($A15,'[7]Budget original'!$A$2:$A$501,0),MATCH(D$2,'[7]Budget original'!$A$2:$AO$2,0)) -> 4.96 | E15: =IF(D15=0,0,F15/D15) -> 2504.4548 | F15: =+INDEX('[7]Budget original'!$A$2:$AO$501,MATCH($A15,'[7]Budget original'!$A$2:$A$501,0),MATCH(F$2,'[7]Budget original'!$A$2:$AO$2,0)) -> 12422.096 | J15: =-SUMIFS([7]BV_Data_An_Cour!$O:$O,[7]BV_Data_An_Cour!$U:$U,$B15,[7]BV_Data_An_Cour!$V:$V,$C15,[7]BV_Data_An_Cour!$W:$W,J$2) -> 2 | K15: =IF(J15=0,0,L15/J15) -> 1396.23 | L15: =-SUMIFS([7]BV_Data_An_Cour!$O:$O,[7]BV_Data_An_Cour!$U:$U,$B15,[7]BV_Data_An_Cour!$V:$V,$C15,[7]BV_Data_An_Cour!$W:$W,L$2) -> 2792.46 | M15: =J15-D15 -> -2.96 | N15: =L15-F15 -> -9629.6358 | O15: {=+INDEX('[7]Réel 2023'!$A$2:$AO$501,MATCH($A15,'[7]Réel 2023'!$A$2:$A$501,0),MATCH(O$2,'[7]Réel 2023'!$A$2:$AO$2,0))} -> 1 | P15: =IF(O15=0,0,Q15/O15) -> 1154.94 | Q15: {=+INDEX('[7]Réel 2023'!$A$2:$AO$501,MATCH($A15,'[7]Réel 2023'!$A$2:$A$501,0),MATCH(Q$2,'[7]Réel 2023'!$A$2:$AO$2,0))} -> 1154.94 | R15: =J15-O15 -> 1 | S15: =L15-Q15 -> 1637.52 | AD15: 25 | AE15: =AF15/AD15 -> 800 | AF15: =AF14 -> 20000
A16: Véhicules neufs | B16: Véhicules neufs
A17: Véhicules neufsFlottes | B17: Véhicules neufs | C17: Flottes | D17: =+INDEX('[7]Budget original'!$A$2:$AO$501,MATCH($A17,'[7]Budget original'!$A$2:$A$501,0),MATCH(D$2,'[7]Budget original'!$A$2:$AO$2,0)) -> 4.5 | E17: =IF(D17=0,0,F17/D17) -> 2664.4641 | F17: =+INDEX('[7]Budget original'!$A$2:$AO$501,MATCH($A17,'[7]Budget original'!$A$2:$A$501,0),MATCH(F$2,'[7]Budget original'!$A$2:$AO$2,0)) -> 11990.088 | J17: =-SUMIFS([7]BV_Data_An_Cour!$O:$O,[7]BV_Data_An_Cour!$U:$U,$B17,[7]BV_Data_An_Cour!$V:$V,$C17,[7]BV_Data_An_Cour!$W:$W,J$2) -> 3 | K17: =IF(J17=0,0,L17/J17) -> 1478.8733 | L17: =-SUMIFS([7]BV_Data_An_Cour!$O:$O,[7]BV_Data_An_Cour!$U:$U,$B17,[7]BV_Data_An_Cour!$V:$V,$C17,[7]BV_Data_An_Cour!$W:$W,L$2) -> 4436.62 | M17: =J17-D17 -> -1.5 | N17: =L17-F17 -> -7553.4683 | O17: {=+INDEX('[7]Réel 2023'!$A$2:$AO$501,MATCH($A17,'[7]Réel 2023'!$A$2:$A$501,0),MATCH(O$2,'[7]Réel 2023'!$A$2:$AO$2,0))} -> 2 | P17: =IF(O17=0,0,Q17/O17) -> 3324.41 | Q17: {=+INDEX('[7]Réel 2023'!$A$2:$AO$501,MATCH($A17,'[7]Réel 2023'!$A$2:$A$501,0),MATCH(Q$2,'[7]Réel 2023'!$A$2:$AO$2,0))} -> 6648.82 | R17: =J17-O17 -> 1 | S17: =L17-Q17 -> -2212.2
A18: Véhicules neufs | B18: Véhicules neufs
A19: Véhicules neufsRachat bail | B19: Véhicules neufs | C19: Rachat bail | D19: =+INDEX('[7]Budget original'!$A$2:$AO$501,MATCH($A19,'[7]Budget original'!$A$2:$A$501,0),MATCH(D$2,'[7]Budget original'!$A$2:$AO$2,0)) -> 0 | E19: =IF(D19=0,0,F19/D19) -> 0 | F19: =+INDEX('[7]Budget original'!$A$2:$AO$501,MATCH($A19,'[7]Budget original'!$A$2:$A$501,0),MATCH(F$2,'[7]Budget original'!$A$2:$AO$2,0)) -> 8500 | L19: =-SUMIFS([7]BV_Data_An_Cour!$O:$O,[7]BV_Data_An_Cour!$U:$U,$B19,[7]BV_Data_An_Cour!$V:$V,$C19,[7]BV_Data_An_Cour!$W:$W,L$2) -> 7700 | N19: =L19-F19 -> -800 | Q19: {=+INDEX('[7]Réel 2023'!$A$2:$AO$501,MATCH($A19,'[7]Réel 2023'!$A$2:$A$501,0),MATCH(Q$2,'[7]Réel 2023'!$A$2:$AO$2,0))} -> 3732.16 | R19: =O19-K19 -> 0 | S19: =L19-Q19 -> 3967.84
A20: Véhicules neufs | B20: Véhicules neufs
A21: Véhicules neufsRev. Finances | B21: Véhicules neufs | C21: Rev. Finances | D21: =+INDEX('[7]Budget original'!$A$2:$AO$501,MATCH($A21,'[7]Budget original'!$A$2:$A$501,0),MATCH(D$2,'[7]Budget original'!$A$2:$AO$2,0)) -> 0 | E21: =IF(D21=0,0,F21/D21) -> 0 | F21: =+INDEX('[7]Budget original'!$A$2:$AO$501,MATCH($A21,'[7]Budget original'!$A$2:$A$501,0),MATCH(F$2,'[7]Budget original'!$A$2:$AO$2,0)) -> 13352 | K21: =IF(J13=0,0,L21/(J13+J15)) -> 0 | L21: =-SUMIFS([7]BV_Data_An_Cour!$O:$O,[7]BV_Data_An_Cour!$U:$U,$B21,[7]BV_Data_An_Cour!$V:$V,$C21,[7]BV_Data_An_Cour!$W:$W,L$2) -> 0 | N21: =L21-F21 -> -13352 | Q21: {=+INDEX('[7]Réel 2023'!$A$2:$AO$501,MATCH($A21,'[7]Réel 2023'!$A$2:$A$501,0),MATCH(Q$2,'[7]Réel 2023'!$A$2:$AO$2,0))} -> 4322.42 | R21: =O21-K21 -> 0 | S21: =L21-Q21 -> -4322.42
A22: Véhicules neufsRev. Protections | B22: Véhicules neufs | C22: Rev. Protections | D22: =+INDEX('[7]Budget original'!$A$2:$AO$501,MATCH($A22,'[7]Budget original'!$A$2:$A$501,0),MATCH(D$2,'[7]Budget original'!$A$2:$AO$2,0)) -> 0 | E22: =IF(D22=0,0,F22/D22) -> 0 | F22: =+INDEX('[7]Budget original'!$A$2:$AO$501,MATCH($A22,'[7]Budget original'!$A$2:$A$501,0),MATCH(F$2,'[7]Budget original'!$A$2:$AO$2,0)) -> 72100.8 | K22: =IF(J13=0,0,L22/(J13+J15)) -> 1044.0162 | L22: =-SUMIFS([7]BV_Data_An_Cour!$O:$O,[7]BV_Data_An_Cour!$U:$U,$B22,[7]BV_Data_An_Cour!$V:$V,$C22,[7]BV_Data_An_Cour!$W:$W,L$2) -> 38628.6 | N22: =L22-F22 -> -33472.2 | Q22: {=+INDEX('[7]Réel 2023'!$A$2:$AO$501,MATCH($A22,'[7]Réel 2023'!$A$2:$A$501,0),MATCH(Q$2,'[7]Réel 2023'!$A$2:$AO$2,0))} -> 89386.52 | R22: =O22-K22 -> -1044.0162 | S22: =L22-Q22 -> -50757.92
A23: Véhicules neufsRev. Autres | B23: Véhicules neufs | C23: Rev. Autres | D23: =+INDEX('[7]Budget original'!$A$2:$AO$501,MATCH($A23,'[7]Budget original'!$A$2:$A$501,0),MATCH(D$2,'[7]Budget original'!$A$2:$AO$2,0)) -> 0 | E23: =IF(D23=0,0,F23/D23) -> 0 | F23: =+INDEX('[7]Budget original'!$A$2:$AO$501,MATCH($A23,'[7]Budget original'!$A$2:$A$501,0),MATCH(F$2,'[7]Budget original'!$A$2:$AO$2,0)) -> 1335.2 | K23: =IF(J13=0,0,L23/(J13+J15)) -> 17.436757 | L23: =-SUMIFS([7]BV_Data_An_Cour!$O:$O,[7]BV_Data_An_Cour!$U:$U,$B23,[7]BV_Data_An_Cour!$V:$V,$C23,[7]BV_Data_An_Cour!$W:$W,L$2) -> 645.16 | N23: =L23-F23 -> -690.04 | Q23: {=+INDEX('[7]Réel 2023'!$A$2:$AO$501,MATCH($A23,'[7]Réel 2023'!$A$2:$A$501,0),MATCH(Q$2,'[7]Réel 2023'!$A$2:$AO$2,0))} -> 1350.84 | R23: =O23-K23 -> -17.436757 | S23: =L23-Q23 -> -705.68
A24: Véhicules neufsTotal F&I | B24: Véhicules neufs | C24: Total F&I | D24: =+D15+D13 -> 66.76 | E24: =IF(D24<=0,0,F24/D24) -> 1300 | F24: =F21+F22+F23 -> 86788 | J24: =+J15+J13 -> 37 | K24: =IF(J24<=0,0,L24/J24) -> 1061.453 | L24: =L21+L22+L23 -> 39273.76 | M24: =J24-D24 -> -29.76 | N24: =L24-F24 -> -47514.24 | O24: =+O15+O13 -> 90 | P24: =IF(O24<=0,0,Q24/O24) -> 1056.2198 | Q24: =Q21+Q22+Q23 -> 95059.78 | S24: =L24-Q24 -> -55786.02
A25: Véhicules neufs | B25: Véhicules neufs | N25: =IF(N24=0,0,N24/F24) -> -0.54747477 | S25: =IF(Q24=0,0,(S24/Q24)) -> -0.58685198
A26: Véhicules neufs | B26: Véhicules neufs
A27: Véhicules neufsTotal Dépt. Neufs | B27: Véhicules neufs | C27: Total Dépt. Neufs | D27: =+D13+D15+D17 -> 71.26 | E27: =IF(D27<=0,0,F27/D27) -> 4049.8257 | F27: =F13+F17+F24+F19+F15 -> 288590.58 | J27: =+J13+J15+J17 -> 40 | K27: =IF(J27<=0,0,L27/J27) -> 3188.572 | L27: =L13+L17+L24+L19+L15 -> 127542.88 | M27: =J27-D27 -> -31.26 | N27: =L27-F27 -> -161047.7 | O27: =+O13+O15+O17 -> 92 | P27: =IF(O27<=0,0,Q27/O27) -> 3367.832 | Q27: =Q13+Q17+Q24+Q19+Q15 -> 309840.54 | R27: =J27-O27 -> -52 | S27: =L27-Q27 -> -182297.66
A28: Véhicules neufs | B28: Véhicules neufs | L28: =L27/F27 -> 0.44195094 | M28: =M27/D27 -> -0.43867527 | N28: =N27/F27 -> -0.55804906 | R28: =R27/O27 -> -0.56521739 | S28: =IF(Q27=0,0,S27/Q27) -> -0.58835961
A29: Véhicules neufs | B29: Véhicules neufs
A30: Véhicules neufsDEPENSES | B30: Véhicules neufs | C30: DEPENSES
A31: Véhicules neufsComm. vendeurs | B31: Véhicules neufs | C31: Comm. vendeurs | D31: =F31/(F13+F15) -> 0.34 | E31: =F31/D$24 -> 923.40096 | F31: =+INDEX('[7]Budget original'!$A$2:$AO$501,MATCH($A31,'[7]Budget original'!$A$2:$A$501,0),MATCH(F$2,'[7]Budget original'!$A$2:$AO$2,0)) -> 61646.248 | J31: =L31/(L15+L13+L17) -> 0.29663462 | K31: =IF(L31=0,0,L31/J$24) -> 645.93486 | L31: =SUMIFS([7]BV_Data_An_Cour!$O:$O,[7]BV_Data_An_Cour!$U:$U,$B31,[7]BV_Data_An_Cour!$V:$V,$C31,[7]BV_Data_An_Cour!$W:$W,L$2) -> 23899.59 | N31: =L31-F31 -> -37746.658 | O31: =Q31/(Q13+Q15+Q17) -> 0.21328163 | P31: =Q31/O$24 -> 500.14211 | Q31: {=+INDEX('[7]Réel 2023'!$A$2:$AO$501,MATCH($A31,'[7]Réel 2023'!$A$2:$A$501,0),MATCH(Q$2,'[7]Réel 2023'!$A$2:$AO$2,0))} -> 45012.79 | S31: =L31-Q31 -> -21113.2
A32: Véhicules neufsComm. F&I | B32: Véhicules neufs | C32: Comm. F&I | D32: =F32/F24 -> 0.3 | E32: =F32/D$24 -> 390 | F32: =+INDEX('[7]Budget original'!$A$2:$AO$501,MATCH($A32,'[7]Budget original'!$A$2:$A$501,0),MATCH(F$2,'[7]Budget original'!$A$2:$AO$2,0)) -> 26036.4 | J32: =L32/L24 -> 0.27998974 | K32: =IF(L32=0,0,L32/J$24) -> 297.19595 | L32: =SUMIFS([7]BV_Data_An_Cour!$O:$O,[7]BV_Data_An_Cour!$U:$U,$B32,[7]BV_Data_An_Cour!$V:$V,$C32,[7]BV_Data_An_Cour!$W:$W,L$2) -> 10996.25 | N32: =L32-F32 -> -15040.15 | O32: =Q32/Q24 -> 0.29960999 | P32: =Q32/O$24 -> 316.454 | Q32: {=+INDEX('[7]Réel 2023'!$A$2:$AO$501,MATCH($A32,'[7]Réel 2023'!$A$2:$A$501,0),MATCH(Q$2,'[7]Réel 2023'!$A$2:$AO$2,0))} -> 28480.86 | S32: =L32-Q32 -> -17484.61
