Workbook
Name _Dates_Conc: [1]Dealers!$BF$37:$KA$63
Name _scen: '[1]Scen & Sens'!$E$26
Name _scen1: '[1]Scen & Sens'!$E$27
Name _scen2: '[1]Scen & Sens'!$E$28
Name _SCenarios: '[1]Scen & Sens'!$J$26:$O$26
Name _Sens1: '[1]Scen & Sens'!$F$9
Name _Sens2: '[1]Scen & Sens'!$F$10
Name _sensRes1: '[1]Scen & Sens'!$E$15
Name _sensRes2: '[1]Scen & Sens'!$E$16
Name _sensRes3: '[1]Scen & Sens'!$E$17
Name _sensRes4: '[1]Scen & Sens'!$E$18
Name _sensRes5: '[1]Scen & Sens'!$E$19
Name _sensRes6: '[1]Scen & Sens'!$E$20
Name _sensRes7: '[1]Scen & Sens'!$E$21
Name DateRange: [1]Volkswagen!$BF$6:$DY$6
Name Monetary_Unit: [1]Parameters!$B$15
Name Months: [1]Parameters!$E$9:$E$20
Name Rng_Dealers_Names: [1]!Tbl_Dealers[Dealer Name]
Name Rng_Dlr_Dates: [1]!Tbl_V_Dlr_Dates[Date]
Name Ticker: #REF!
Name Ticker: #REF!
Name Ticker: #REF!
Name Titre: [1]Front!$A$9

Sheet Paramètre
B3: Quarter
B6: BUDGET | F6: BUDGET RÉVISÉ | J6: ACTUAL | N6: LAST YEAR
B7: Ventes | C7: Profits bruts | D7: BAIIA | E7: EBIT | F7: Ventes | G7: Profits bruts | H7: BAIIA | I7: EBIT | J7: Ventes | K7: Profits bruts | L7: BAIIA | M7: EBIT | N7: Ventes | O7: Profits bruts | P7: BAIIA | Q7: EBIT
A8: CTRL | B8: =+B9-B10 -> #REF! | C8: =+C9-C10 -> #REF! | D8: =+D9-D10 -> #REF! | E8: =+E9-E10 -> #REF! | F8: =+F9-F10 -> #REF! | G8: =+G9-G10 -> #REF! | H8: =+H9-H10 -> #REF! | I8: =+I9-I10 -> #REF! | ... Q8: =+Q9-Q10 -> #REF!
A9: CONSO | B9: =+Conso!$Z$405 -> 19264267 | C9: =+Conso!$Z$406 -> 2767342.7 | D9: =+Conso!$Z$482 -> 1036365.6 | E9: =+Conso!$Z$497 -> 1031420.6 | F9: =+Conso!$AC$405 -> 0 | G9: =+Conso!$AC$406 -> 0 | H9: =+Conso!$AC$482 -> 0 | I9: =+Conso!$AC$497 -> 0 | J9: =+Conso!$AF$405 -> 16428062 | K9: =+Conso!$AF$406 -> 1897181 | L9: =+Conso!$AF$482 -> 366005.68 | M9: =+Conso!$AF$497 -> 361195.19 | N9: =+Conso!$AL$405 -> 13893961 | O9: =+Conso!$AL$406 -> 1960729.2 | P9: =+Conso!$AL$482 -> 554891.33 | Q9: =+Conso!$AL$497 -> 541947.83
A10: TOTAL | B10: =+SUM(B11:B13) -> #REF! | C10: =+SUM(C11:C13) -> #REF! | D10: =+SUM(D11:D13) -> #REF! | E10: =+SUM(E11:E13) -> #REF! | F10: =+SUM(F11:F13) -> #REF! | G10: =+SUM(G11:G13) -> #REF! | H10: =+SUM(H11:H13) -> #REF! | I10: =+SUM(I11:I13) -> #REF! | ... Q10: =+SUM(Q11:Q13) -> #REF!
A11: Mois 1 | B11: =+#REF! -> #REF! | C11: =+#REF! -> #REF! | D11: =+#REF! -> #REF! | E11: =+#REF! -> #REF! | F11: =+#REF! -> #REF! | G11: =+#REF! -> #REF! | H11: =+#REF! -> #REF! | I11: =+#REF! -> #REF! | ... Q11: =+#REF! -> #REF!
A12: Mois 2 | B12: =+#REF! -> #REF! | C12: =+#REF! -> #REF! | D12: =+#REF! -> #REF! | E12: =+#REF! -> #REF! | F12: =+#REF! -> #REF! | G12: =+#REF! -> #REF! | H12: =+#REF! -> #REF! | I12: =+#REF! -> #REF! | ... Q12: =+#REF! -> #REF!
A13: Mois 3 | B13: =+#REF! -> #REF! | C13: =+#REF! -> #REF! | D13: =+#REF! -> #REF! | E13: =+#REF! -> #REF! | F13: =+#REF! -> #REF! | G13: =+#REF! -> #REF! | H13: =+#REF! -> #REF! | I13: =+#REF! -> #REF! | ... Q13: =+#REF! -> #REF!

Sheet Conso
C1: Conso | K1: Véhicules neufs | S1: =CONCATENATE("Réalisé"," ",Paramètre!$C$2," ",Paramètre!$C$3) -> Réalisé
D2: X | E2: O | F2: U | G2: X | H2: O | I2: U
D3: BUDGET ORIGINAL | G3: BUDGET REVISE | J3: RÉALISATION | M3: ÉCART réel / original | O3: ANNÉE PRÉCÉDENTE | R3: ÉCART réel / année précédente
D4: UNITE | E4: $P/UNITÉ | F4: $PROFITS | G4: UNITE | H4: $P/UNITÉ | I4: $PROFITS | J4: UNITE | K4: $P/UNITE | L4: $PROFITS | M4: UNITÉ | N4: $PROFITS | O4: UNITE | P4: $P/UNITE | Q4: $PROFITS | R4: UNITE | S4: $PROFITS
A5: =+B5&C5 -> Véhicules neufsVentes nettes | B5: =+$K$1 -> Véhicules neufs | C5: Ventes nettes | F5: =+SUM(START:END!F5) -> 9890625.2 | I5: =+SUM(START:END!I5) -> 0 | L5: =+SUM(START:END!L5) -> 9890070 | Q5: =+SUM(START:END!Q5) -> 7425353.9
A6: =+B6&C6 -> Véhicules neufsAutos détail | B6: =+$K$1 -> Véhicules neufs | C6: Autos détail | D6: =+SUM(START:END!D6) -> 37 | E6: =IF(D6=0,0,F6/D6) -> 2174.3584 | F6: =+SUM(START:END!F6) -> 80451.263 | G6: =+SUM(START:END!G6) -> 0 | H6: =IF(G6=0,0,I6/G6) -> 0 | I6: =+SUM(START:END!I6) -> 0 | J6: =+SUM(START:END!J6) -> 51 | K6: =IF(J6=0,0,L6/J6) -> 1956.158 | L6: =+SUM(START:END!L6) -> 99764.06 | M6: =J6-D6 -> 14 | N6: =L6-F6 -> 19312.797 | O6: =+SUM(START:END!O6) -> 40 | P6: =IF(O6=0,0,Q6/O6) -> 2348.4692 | Q6: =+SUM(START:END!Q6) -> 93938.77 | R6: =J6-O6 -> 11 | S6: =L6-Q6 -> 5825.29
A7: =+B7&C7 -> Véhicules neufsCamions détail | B7: =+$K$1 -> Véhicules neufs | C7: Camions détail | D7: =+SUM(START:END!D7) -> 151.68 | E7: =IF(D7=0,0,F7/D7) -> 2865.6675 | F7: =+SUM(START:END!F7) -> 434664.45 | G7: =+SUM(START:END!G7) -> 0 | H7: =IF(G7=0,0,I7/G7) -> 0 | I7: =+SUM(START:END!I7) -> 0 | J7: =+SUM(START:END!J7) -> 127 | K7: =IF(J7=0,0,L7/J7) -> 2623.2423 | L7: =+SUM(START:END!L7) -> 333151.77 | M7: =J7-D7 -> -24.68 | N7: =L7-F7 -> -101512.68 | O7: =+SUM(START:END!O7) -> 89 | P7: =IF(O7=0,0,Q7/O7) -> 2474.2398 | Q7: =+SUM(START:END!Q7) -> 220207.34 | R7: =J7-O7 -> 38 | S7: =L7-Q7 -> 112944.43
A8: =+B8&C8 -> Véhicules neufsSprinter | B8: =+$K$1 -> Véhicules neufs | C8: Sprinter | D8: =+SUM(START:END!D8) -> 0 | E8: =IF(D8=0,0,F8/D8) -> 0 | F8: =+SUM(START:END!F8) -> 0 | G8: =+SUM(START:END!G8) -> 0 | H8: =IF(G8=0,0,I8/G8) -> 0 | I8: =+SUM(START:END!I8) -> 0 | J8: =+SUM(START:END!J8) -> 0 | K8: =IF(J8=0,0,L8/J8) -> 0 | L8: =+SUM(START:END!L8) -> 0 | M8: =J8-D8 -> 0 | N8: =L8-F8 -> 0 | O8: =+SUM(START:END!O8) -> 0 | P8: =IF(O8=0,0,Q8/O8) -> 0 | Q8: =+SUM(START:END!Q8) -> 0 | R8: =J8-O8 -> 0 | S8: =L8-Q8 -> 0
A9: =+B9&C9 -> Véhicules neufsMoto détail | B9: =+$K$1 -> Véhicules neufs | C9: Moto détail | D9: =+SUM(START:END!D9) -> 0 | E9: =IF(D9=0,0,F9/D9) -> 0 | F9: =+SUM(START:END!F9) -> 0 | G9: =+SUM(START:END!G9) -> 0 | H9: =IF(G9=0,0,I9/G9) -> 0 | I9: =+SUM(START:END!I9) -> 0 | J9: =+SUM(START:END!J9) -> 0 | K9: =IF(J9=0,0,L9/J9) -> 0 | L9: =+SUM(START:END!L9) -> 0 | M9: =J9-D9 -> 0 | N9: =L9-F9 -> 0 | O9: =+SUM(START:END!O9) -> 0 | P9: =IF(O9=0,0,Q9/O9) -> 0 | Q9: =+SUM(START:END!Q9) -> 0 | R9: =J9-O9 -> 0 | S9: =L9-Q9 -> 0
A10: =+B10&C10 -> Véhicules neufs[...] | B10: =+$K$1 -> Véhicules neufs | C10: [...] | D10: =+SUM(START:END!D10) -> 0 | E10: =IF(D10=0,0,F10/D10) -> 0 | F10: =+SUM(START:END!F10) -> 0 | G10: =+SUM(START:END!G10) -> 0 | H10: =IF(G10=0,0,I10/G10) -> 0 | I10: =+SUM(START:END!I10) -> 0 | J10: =+SUM(START:END!J10) -> 0 | K10: =IF(J10=0,0,L10/J10) -> 0 | L10: =+SUM(START:END!L10) -> 0 | M10: =J10-G10 -> 0 | N10: =L10-I10 -> 0 | O10: =+SUM(START:END!O10) -> 0 | P10: =IF(O10=0,0,Q10/O10) -> 0 | Q10: =+SUM(START:END!Q10) -> 0 | R10: =J10-O10 -> 0 | S10: =L10-Q10 -> 0
A11: =+B11&C11 -> Véhicules neufs[...] | B11: =+$K$1 -> Véhicules neufs | C11: [...] | D11: =+SUM(START:END!D11) -> 0 | E11: =IF(D11=0,0,F11/D11) -> 0 | F11: =+SUM(START:END!F11) -> 0 | G11: =+SUM(START:END!G11) -> 0 | H11: =IF(G11=0,0,I11/G11) -> 0 | I11: =+SUM(START:END!I11) -> 0 | J11: =+SUM(START:END!J11) -> 0 | K11: =IF(J11=0,0,L11/J11) -> 0 | L11: =+SUM(START:END!L11) -> 0 | M11: =J11-G11 -> 0 | N11: =L11-I11 -> 0 | O11: =+SUM(START:END!O11) -> 0 | P11: =IF(O11=0,0,Q11/O11) -> 0 | Q11: =+SUM(START:END!Q11) -> 0 | R11: =J11-O11 -> 0 | S11: =L11-Q11 -> 0
A12: =+B12&C12 -> Véhicules neufs[...] | B12: =+$K$1 -> Véhicules neufs | C12: [...] | D12: =+SUM(START:END!D12) -> 0 | E12: =IF(D12=0,0,F12/D12) -> 0 | F12: =+SUM(START:END!F12) -> 0 | G12: =+SUM(START:END!G12) -> 0 | H12: =IF(G12=0,0,I12/G12) -> 0 | I12: =+SUM(START:END!I12) -> 0 | J12: =+SUM(START:END!J12) -> 0 | K12: =IF(J12=0,0,L12/J12) -> 0 | L12: =+SUM(START:END!L12) -> 0 | M12: =J12-G12 -> 0 | N12: =L12-I12 -> 0 | O12: =+SUM(START:END!O12) -> 0 | P12: =IF(O12=0,0,Q12/O12) -> 0 | Q12: =+SUM(START:END!Q12) -> 0 | R12: =J12-O12 -> 0 | S12: =L12-Q12 -> 0
A13: =+B13&C13 -> Véhicules neufsTotal Neufs | B13: =+$K$1 -> Véhicules neufs | C13: Total Neufs | D13: =+SUM(D6:D12) -> 188.68 | E13: =IF(D13<=0,0,F13/D13) -> 2730.1024 | F13: =+SUM(F6:F12) -> 515115.71 | G13: =+SUM(G6:G12) -> 0 | H13: =IF(G13<=0,0,I13/G13) -> 0 | I13: =+SUM(I6:I12) -> 0 | J13: =+SUM(J6:J12) -> 178 | K13: =IF(J13<=0,0,L13/J13) -> 2432.1114 | L13: =+SUM(L6:L12) -> 432915.83 | M13: =+SUM(M6:M12) -> -10.68 | N13: =+SUM(N6:N12) -> -82199.884 | O13: =+SUM(O6:O12) -> 129 | P13: =IF(O13<=0,0,Q13/O13) -> 2435.2412 | Q13: =+SUM(Q6:Q12) -> 314146.11 | R13: =+SUM(R6:R12) -> 49 | S13: =+SUM(S6:S12) -> 118769.72
A14: =+B14&C14 -> Véhicules neufs | B14: =+$K$1 -> Véhicules neufs | N14: =IF(F13=0,0,N13/F13) -> -0.15957557 | R14: =R13/O13 -> 0.37984496 | S14: =IF(Q13=0,0,(S13/Q13)) -> 0.37807159
A15: =+B15&C15 -> Véhicules neufsEx-Démos et courtoisies | B15: =+$K$1 -> Véhicules neufs | C15: Ex-Démos et courtoisies | D15: =+SUM(START:END!D15) -> 15.045 | E15: =IF(D15=0,0,F15/D15) -> 2518.2713 | F15: =+SUM(START:END!F15) -> 37887.392 | G15: =+SUM(START:END!G15) -> 0 | H15: =IF(G15=0,0,I15/G15) -> 0 | I15: =+SUM(START:END!I15) -> 0 | J15: =+SUM(START:END!J15) -> 9 | K15: =IF(J15=0,0,L15/J15) -> 1653.9344 | L15: =+SUM(START:END!L15) -> 14885.41 | M15: =J15-G15 -> 9 | N15: =L15-I15 -> 14885.41 | O15: =+SUM(START:END!O15) -> 15 | P15: =IF(O15=0,0,Q15/O15) -> 2083.5413 | Q15: =+SUM(START:END!Q15) -> 31253.12 | R15: =J15-O15 -> -6 | S15: =L15-Q15 -> -16367.71
A16: =+B16&C16 -> Véhicules neufs | B16: =+$K$1 -> Véhicules neufs
A17: =+B17&C17 -> Véhicules neufsFlottes | B17: =+$K$1 -> Véhicules neufs | C17: Flottes | D17: =+SUM(START:END!D17) -> 13.725 | E17: =IF(D17=0,0,F17/D17) -> 2664.4641 | F17: =+SUM(START:END!F17) -> 36569.769 | G17: =+SUM(START:END!G17) -> 0 | H17: =IF(G17=0,0,I17/G17) -> 0 | I17: =+SUM(START:END!I17) -> 0 | J17: =+SUM(START:END!J17) -> 0 | K17: =IF(J17=0,0,L17/J17) -> 0 | L17: =+SUM(START:END!L17) -> 0 | M17: =J17-D17 -> -13.725 | N17: =L17-F17 -> -36569.769 | O17: =+SUM(START:END!O17) -> 8 | P17: =IF(O17=0,0,Q17/O17) -> 2410.1687 | Q17: =+SUM(START:END!Q17) -> 19281.35 | R17: =J17-O17 -> -8 | S17: =L17-Q17 -> -19281.35
A18: =+B18&C18 -> Véhicules neufs | B18: =+$K$1 -> Véhicules neufs
A19: =+B19&C19 -> Véhicules neufsRachat bail | B19: =+$K$1 -> Véhicules neufs | C19: Rachat bail | F19: =+SUM(START:END!F19) -> 25925 | I19: =+SUM(START:END!I19) -> 0 | L19: =+SUM(START:END!L19) -> 22060.37 | N19: =L19-F19 -> -3864.63 | Q19: =+SUM(START:END!Q19) -> 32801.63 | R19: =O19-K19 -> 0 | S19: =L19-Q19 -> -10741.26
A20: =+B20&C20 -> Véhicules neufs | B20: =+$K$1 -> Véhicules neufs
A21: =+B21&C21 -> Véhicules neufsRev. Finances | B21: =+$K$1 -> Véhicules neufs | C21: Rev. Finances | D21: 0 | E21: =IF(D21=0,0,F21/D21) -> 0 | F21: =+SUM(START:END!F21) -> 40745 | G21: 0 | H21: =IF(G21=0,0,I21/G21) -> 0 | I21: =+SUM(START:END!I21) -> 0 | K21: =IF(J13=0,0,L21/(J13+J15)) -> 4.2780749 | L21: =+SUM(START:END!L21) -> 800 | N21: =L21-F21 -> -39945 | P21: =IF(O13=0,0,Q21/(O13+O15)) -> 102.54681 | Q21: =+SUM(START:END!Q21) -> 14766.74 | R21: =O21-K21 -> -4.2780749 | S21: =L21-Q21 -> -13966.74
A22: =+B22&C22 -> Véhicules neufsRev. Protections | B22: =+$K$1 -> Véhicules neufs | C22: Rev. Protections | D22: 0 | E22: =IF(D22=0,0,F22/D22) -> 0 | F22: =+SUM(START:END!F22) -> 220023 | G22: 0 | H22: =IF(G22=0,0,I22/G22) -> 0 | I22: =+SUM(START:END!I22) -> 0 | K22: =IF(J13=0,0,L22/(J13+J15)) -> 777.99171 | L22: =+SUM(START:END!L22) -> 145484.45 | N22: =L22-F22 -> -74538.55 | P22: =IF(O13=0,0,Q22/(O13+O15)) -> 928.50687 | Q22: =+SUM(START:END!Q22) -> 133704.99 | R22: =O22-K22 -> -777.99171 | S22: =L22-Q22 -> 11779.46
A23: =+B23&C23 -> Véhicules neufsRev. Autres | B23: =+$K$1 -> Véhicules neufs | C23: Rev. Autres | D23: 0 | E23: =IF(D23=0,0,F23/D23) -> 0 | F23: =+SUM(START:END!F23) -> 4074.5 | G23: 0 | H23: =IF(G23=0,0,I23/G23) -> 0 | I23: =+SUM(START:END!I23) -> 0 | K23: =IF(J13=0,0,L23/(J13+J15)) -> 21.696417 | L23: =+SUM(START:END!L23) -> 4057.23 | N23: =L23-F23 -> -17.27 | P23: =IF(O13=0,0,Q23/(O13+O15)) -> 12.119236 | Q23: =+SUM(START:END!Q23) -> 1745.17 | R23: =O23-K23 -> -21.696417 | S23: =L23-Q23 -> 2312.06
A24: =+B24&C24 -> Véhicules neufsTotal F&I | B24: =+$K$1 -> Véhicules neufs | C24: Total F&I | D24: =+D15+D13 -> 203.725 | E24: =IF(D24<=0,0,F24/D24) -> 1300 | F24: =F21+F22+F23 -> 264842.5 | G24: =+G15+G13 -> 0 | H24: =IF(G24<=0,0,I24/G24) -> 0 | I24: =I21+I22+I23 -> 0 | J24: =+J15+J13 -> 187 | K24: =IF(J24<=0,0,L24/J24) -> 803.9662 | L24: =L21+L22+L23 -> 150341.68 | M24: =+M15+M13 -> -1.68 | N24: =N21+N22+N23 -> -114500.82 | O24: =+O15+O13 -> 144 | P24: =IF(O24<=0,0,Q24/O24) -> 1043.1729 | Q24: =Q21+Q22+Q23 -> 150216.9 | S24: =L24-Q24 -> 124.78
A25: =+B25&C25 -> Véhicules neufs | B25: =+$K$1 -> Véhicules neufs | S25: =IF(Q24=0,0,(S24/Q24)) -> 0.00083066552
A26: =+B26&C26 -> Véhicules neufs | B26: =+$K$1 -> Véhicules neufs
A27: =+B27&C27 -> Véhicules neufsTotal Dépt. Neufs | B27: =+$K$1 -> Véhicules neufs | C27: Total Dépt. Neufs | D27: =+D13+D15+D17 -> 217.45 | E27: =IF(D27<=0,0,F27/D27) -> 4048.4726 | F27: =F13+F17+F24+F19+F15 -> 880340.38 | G27: =+G13+G15+G17 -> 0 | H27: =IF(G27<=0,0,I27/G27) -> 0 | I27: =I13+I17+I24+I19+I15 -> 0 | J27: =+J13+J15+J17 -> 187 | K27: =IF(J27<=0,0,L27/J27) -> 3316.5951 | L27: =L13+L17+L24+L19+L15 -> 620203.29 | M27: =+M13+M15+M17 -> -15.405 | N27: =N13+N17+N24+N19+N15 -> -222249.69 | O27: =+O13+O15+O17 -> 152 | P27: =IF(O27<=0,0,Q27/O27) -> 3603.2836 | Q27: =Q13+Q17+Q24+Q19+Q15 -> 547699.11 | R27: =J27-O27 -> 35 | S27: =L27-Q27 -> 72504.18
A28: =+B28&C28 -> Véhicules neufs | B28: =+$K$1 -> Véhicules neufs | M28: =M27/D27 -> -0.070843872 | N28: =N27/F27 -> -0.25245882 | R28: =R27/O27 -> 0.23026316 | S28: =IF(Q27=0,0,S27/Q27) -> 0.13237958
A29: =+B29&C29 -> Véhicules neufs | B29: =+$K$1 -> Véhicules neufs
A30: =+B30&C30 -> Véhicules neufsDEPENSES | B30: =+$K$1 -> Véhicules neufs | C30: DEPENSES
A31: =+B31&C31 -> Véhicules neufsComm. vendeurs | B31: =+$K$1 -> Véhicules neufs | C31: Comm. vendeurs | E31: =F31/D$24 -> 922.91597 | F31: =+SUM(START:END!F31) -> 188021.06 | H31: =I31/G$24 -> #DIV/0! | I31: =+SUM(START:END!I31) -> 0 | J31: =L31/L13 -> 0.25250262 | K31: =IF(L31=0,0,L31/J$24) -> 584.55818 | L31: =+SUM(START:END!L31) -> 109312.38 | N31: =L31-F31 -> -78708.676 | P31: =IF(Q31=0,0,Q31/O$24) -> 853.17653 | Q31: =+SUM(START:END!Q31) -> 122857.42 | S31: =L31-Q31 -> -13545.04
A32: =+B32&C32 -> Véhicules neufsComm. F&I | B32: =+$K$1 -> Véhicules neufs | C32: Comm. F&I | E32: =F32/D$24 -> 390 | F32: =+SUM(START:END!F32) -> 79452.75 | H32: =I32/G$24 -> #DIV/0! | I32: =+SUM(START:END!I32) -> 0 | J32: =L32/L24 -> 0.23238792 | K32: =IF(L32=0,0,L32/J$24) -> 186.83203 | L32: =+SUM(START:END!L32) -> 34937.59 | N32: =L32-F32 -> -44515.16 | P32: =IF(Q32=0,0,Q32/O$24) -> 312.93014 | Q32: =+SUM(START:END!Q32) -> 45061.94 | S32: =L32-Q32 -> -10124.35
A33: =+B33&C33 -> Véhicules neufsFrais de livraison | B33: =+$K$1 -> Véhicules neufs | C33: Frais de livraison | E33: =F33/D$24 -> 115 | F33: =+SUM(START:END!F33) -> 23428.375 | H33: =I33/G$24 -> #DIV/0! | I33: =+SUM(START:END!I33) -> 0 | K33: =IF(L33=0,0,L33/J$24) -> 108.74684 | L33: =+SUM(START:END!L33) -> 20335.66 | N33: =L33-F33 -> -3092.715 | P33: =IF(Q33=0,0,Q33/O$24) -> 103.9 | Q33: =+SUM(START:END!Q33) -> 14961.6 | S33: =L33-Q33 -> 5374.06
A34: =+B34&C34 -> Véhicules neufsService gratuit 1 | B34: =+$K$1 -> Véhicules neufs | C34: Service gratuit 1 | E34: =F34/D$24 -> 3 | F34: =+SUM(START:END!F34) -> 611.175 | H34: =I34/G$24 -> #DIV/0! | I34: =+SUM(START:END!I34) -> 0 | K34: =IF(L34=0,0,L34/J$24) -> 6.8069519 | L34: =+SUM(START:END!L34) -> 1272.9 | N34: =L34-F34 -> 661.725 | P34: =IF(Q34=0,0,Q34/O$24) -> 0.55555556 | Q34: =+SUM(START:END!Q34) -> 80 | S34: =L34-Q34 -> 1192.9
A35: =+B35&C35 -> Véhicules neufsEntretien stock | B35: =+$K$1 -> Véhicules neufs | C35: Entretien stock | E35: =F35/D$24 -> 85.05 | F35: =+SUM(START:END!F35) -> 17326.811 | H35: =I35/G$24 -> #DIV/0! | I35: =+SUM(START:END!I35) -> 0 | K35: =IF(L35=0,0,L35/J$24) -> 156.67278 | L35: =+SUM(START:END!L35) -> 29297.81 | N35: =L35-F35 -> 11970.999 | P35: =IF(Q35=0,0,Q35/O$24) -> 73.293611 | Q35: =+SUM(START:END!Q35) -> 10554.28 | S35: =L35-Q35 -> 18743.53
A36: =+B36&C36 -> Véhicules neufsPublicité 1 | B36: =+$K$1 -> Véhicules neufs | C36: Publicité 1 | E36: =F36/D$24 -> 87.546938 | F36: =+SUM(START:END!F36) -> 17835.5 | H36: =I36/G$24 -> #DIV/0! | I36: =+SUM(START:END!I36) -> 0 | K36: =IF(L36=0,0,L36/J$24) -> 173.37182 | L36: =+SUM(START:END!L36) -> 32420.53 | N36: =L36-F36 -> 14585.03 | P36: =IF(Q36=0,0,Q36/O$24) -> 106.97472 | Q36: =+SUM(START:END!Q36) -> 15404.36 | S36: =L36-Q36 -> 17016.17
A37: =+B37&C37 -> Véhicules neufsIntérêt de gros | B37: =+$K$1 -> Véhicules neufs | C37: Intérêt de gros | E37: =F37/D$24 -> 274.63015 | F37: =+SUM(START:END!F37) -> 55949.028 | H37: =I37/G$24 -> #DIV/0! | I37: =+SUM(START:END!I37) -> 0 | K37: =IF(L37=0,0,L37/J$24) -> 654.65048 | L37: =+SUM(START:END!L37) -> 122419.64 | N37: =L37-F37 -> 66470.612 | P37: =IF(Q37=0,0,Q37/O$24) -> 86.623472 | Q37: =+SUM(START:END!Q37) -> 12473.78 | S37: =L37-Q37 -> 109945.86
A38: =+B38&C38 -> Véhicules neufs[...] | B38: =+$K$1 -> Véhicules neufs | C38: [...] | E38: =F38/D$24 -> 0 | F38: =+SUM(START:END!F38) -> 0 | H38: =I38/G$24 -> #DIV/0! | I38: =+SUM(START:END!I38) -> 0 | K38: =IF(L38=0,0,L38/J$24) -> 0 | L38: =+SUM(START:END!L38) -> 0 | N38: =L38-I38 -> 0 | P38: =IF(Q38=0,0,Q38/O$24) -> 0 | Q38: =+SUM(START:END!Q38) -> 0 | S38: =L38-Q38 -> 0
A39: =+B39&C39 -> Véhicules neufs[...] | B39: =+$K$1 -> Véhicules neufs | C39: [...] | E39: =F39/D$24 -> 0 | F39: =+SUM(START:END!F39) -> 0 | H39: =I39/G$24 -> #DIV/0! | I39: =+SUM(START:END!I39) -> 0 | K39: =IF(L39=0,0,L39/J$24) -> 0 | L39: =+SUM(START:END!L39) -> 0 | N39: =L39-I39 -> 0 | P39: =IF(Q39=0,0,Q39/O$24) -> 0 | Q39: =+SUM(START:END!Q39) -> 0 | S39: =L39-Q39 -> 0
A40: =+B40&C40 -> Véhicules neufs[...] | B40: =+$K$1 -> Véhicules neufs | C40: [...] | E40: =F40/D$24 -> 0 | F40: =+SUM(START:END!F40) -> 0 | H40: =I40/G$24 -> #DIV/0! | I40: =+SUM(START:END!I40) -> 0 | K40: =IF(L40=0,0,L40/J$24) -> 0 | L40: =+SUM(START:END!L40) -> 0 | N40: =L40-I40 -> 0 | P40: =IF(Q40=0,0,Q40/O$24) -> 0 | Q40: =+SUM(START:END!Q40) -> 0 | S40: =L40-Q40 -> 0
...

Sheet START

Sheet Avril 2024
C1: Volks | K1: Véhicules neufs | S1: Réalisé, Avril 2024
D2: X | E2: O | F2: U | J2: NB | L2: $ | O2: X | P2: O | Q2: U | V2: *** NE PAS EFFACER / Pour An Précédente ***
D3: BUDGET ORIGINAL | J3: RÉALISATION | M3: ÉCART réel / Budget | O3: ANNÉE PRÉCÉDENTE | R3: ECART (réel/ Ann.Préc.) | V3: NEUF | W3: 0.45
D4: UNITE | E4: $P/UNITÉ | F4: $PROFITS | J4: UNITÉS | K4: $P/UNITE | L4: $PROFITS | M4: UNITÉS | N4: $PROFITS | O4: UNITE | P4: $P/UNITÉ | Q4: $PROFITS | R4: UNITÉS | S4: $PROFITS | V4: USAGE | W4: 0.1
A5: Véhicules neufsVentes nettes | B5: Véhicules neufs | C5: Ventes nettes | F5: 3243094.3 | L5: 3890022.9 | Q5: 1765867 | V5: SERVICE | W5: 0.225
A6: Véhicules neufsAutos détail | B6: Véhicules neufs | C6: Autos détail | D6: 12 | E6: 2198.1219 | F6: 26377.463 | J6: 18 | K6: 2168.0939 | L6: 39025.69 | M6: 6 | N6: 12648.227 | O6: 12 | P6: 2975.6025 | Q6: 35707.23 | R6: 6 | S6: 3318.46 | V6: CARROSSERIE | W6: 0.025
A7: Véhicules neufsCamions détail | B7: Véhicules neufs | C7: Camions détail | D7: 50 | E7: 2850.2587 | F7: 142512.93 | J7: 51 | K7: 2906.2869 | L7: 148220.63 | M7: 1 | N7: 5707.6952 | O7: 16 | P7: 2481.2725 | Q7: 39700.36 | R7: 35 | S7: 108520.27 | V7: PIECES | W7: 0.2
A8: Véhicules neufsSprinter | B8: Véhicules neufs | C8: Sprinter | D8: 0 | E8: 0 | F8: 0 | J8: 0 | K8: 0 | L8: 0 | M8: 0 | N8: 0 | O8: 0 | P8: 0 | Q8: 0 | R8: 0 | S8: 0 | W8: 1
A9: Véhicules neufsMoto détail | B9: Véhicules neufs | C9: Moto détail | D9: 0 | E9: 0 | F9: 0 | J9: 0 | K9: 0 | L9: 0 | M9: 0 | N9: 0 | O9: 0 | P9: 0 | Q9: 0 | R9: 0 | S9: 0
A10: Véhicules neufs[...] | B10: Véhicules neufs | C10: [...] | D10: 0 | E10: 0 | F10: 0 | J10: 0 | K10: 0 | L10: 0 | M10: 0 | N10: 0 | O10: 0 | P10: 0 | Q10: 0 | R10: 0 | S10: 0
A11: Véhicules neufs[...] | B11: Véhicules neufs | C11: [...] | D11: 0 | E11: 0 | F11: 0 | J11: 0 | K11: 0 | L11: 0 | M11: 0 | N11: 0 | O11: 0 | P11: 0 | Q11: 0 | R11: 0 | S11: 0
A12: Véhicules neufs[...] | B12: Véhicules neufs | C12: [...] | D12: 0 | E12: 0 | F12: 0 | J12: 0 | K12: 0 | L12: 0 | M12: 0 | N12: 0 | O12: 0 | P12: 0 | Q12: 0 | R12: 0 | S12: 0
A13: Véhicules neufsTotal Neufs | B13: Véhicules neufs | C13: Total Neufs | D13: 62 | E13: 2724.0387 | F13: 168890.4 | J13: 69 | K13: 2713.7148 | L13: 187246.32 | M13: 7 | N13: 18355.922 | O13: 28 | P13: 2693.1282 | Q13: 75407.59 | R13: 41 | S13: 111838.73
A14: Véhicules neufs | B14: Véhicules neufs | M14: 0.11290323 | N14: 0.10868541 | R14: 1.4642857 | S14: 1.483123 | AD14: 20 | AE14: 1000 | AF14: 20000
A15: Véhicules neufsEx-Démos et courtoisies | B15: Véhicules neufs | C15: Ex-Démos et courtoisies | D15: 5 | E15: 2484.4192 | F15: 12422.096 | J15: 4 | K15: 2264.375 | L15: 9057.5 | M15: -1 | N15: -3364.5958 | O15: 6 | P15: 1717.8083 | Q15: 10306.85 | R15: -2 | S15: -1249.35 | AD15: 25 | AE15: 800 | AF15: 20000
A16: Véhicules neufs | B16: Véhicules neufs
A17: Véhicules neufsFlottes | B17: Véhicules neufs | C17: Flottes | D17: 4.5 | E17: 2664.4641 | F17: 11990.088 | J17: 0 | K17: 0 | L17: 0 | M17: -4.5 | N17: -11990.088 | O17: 3 | P17: 3228.9067 | Q17: 9686.72 | R17: -3 | S17: -9686.72
A18: Véhicules neufs | B18: Véhicules neufs
A19: Véhicules neufsRachat bail | B19: Véhicules neufs | C19: Rachat bail | D19: 0 | E19: 0 | F19: 8500 | L19: 6030.37 | N19: -2469.63 | Q19: 7229.27 | R19: 0 | S19: -1198.9
A20: Véhicules neufs | B20: Véhicules neufs
A21: Véhicules neufsRev. Finances | B21: Véhicules neufs | C21: Rev. Finances | D21: 0 | E21: 0 | F21: 13400 | K21: 0 | L21: 0 | N21: -13400 | Q21: 2434.63 | R21: 0 | S21: -2434.63
A22: Véhicules neufsRev. Protections | B22: Véhicules neufs | C22: Rev. Protections | D22: 0 | E22: 0 | F22: 72360 | K22: 765.92219 | L22: 55912.32 | N22: -16447.68 | Q22: 31050.48 | R22: -765.92219 | S22: 24861.84
A23: Véhicules neufsRev. Autres | B23: Véhicules neufs | C23: Rev. Autres | D23: 0 | E23: 0 | F23: 1340 | K23: 18.60589 | L23: 1358.23 | N23: 18.23 | Q23: 0 | R23: -18.60589 | S23: 1358.23
A24: Véhicules neufsTotal F&I | B24: Véhicules neufs | C24: Total F&I | D24: 67 | E24: 1300 | F24: 87100 | J24: 73 | K24: 784.52808 | L24: 57270.55 | M24: 6 | N24: -29829.45 | O24: 34 | P24: 984.85618 | Q24: 33485.11 | S24: 23785.44
A25: Véhicules neufs | B25: Véhicules neufs | N25: -0.34247359 | S25: 0.71032886
A26: Véhicules neufs | B26: Véhicules neufs
A27: Véhicules neufsTotal Dépt. Neufs | B27: Véhicules neufs | C27: Total Dépt. Neufs | D27: 71.5 | E27: 4040.5956 | F27: 288902.58 | J27: 73 | K27: 3556.2293 | L27: 259604.74 | M27: 1.5 | N27: -29297.842 | O27: 37 | P27: 3678.7984 | Q27: 136115.54 | R27: 36 | S27: 123489.2
A28: Véhicules neufs | B28: Véhicules neufs | L28: 0.8985892 | M28: 0.020979021 | N28: -0.1014108 | R28: 0.97297297 | S28: 0.90723807
A29: Véhicules neufs | B29: Véhicules neufs
A30: Véhicules neufsDEPENSES | B30: Véhicules neufs | C30: DEPENSES
A31: Véhicules neufsComm. vendeurs | B31: Véhicules neufs | C31: Comm. vendeurs | D31: 0.34 | E31: 920.09325 | F31: 61646.248 | J31: 0.24820205 | K31: 667.43849 | L31: 48723.01 | N31: -12923.238 | O31: 0.38883657 | P31: 1091.0429 | Q31: 37095.46 | S31: 11627.55
A32: Véhicules neufsComm. F&I | B32: Véhicules neufs | C32: Comm. F&I | D32: 0.3 | E32: 390 | F32: 26130 | J32: 0.29711868 | K32: 233.09795 | L32: 17016.15 | N32: -9113.85 | O32: 0.2997816 | P32: 295.24176 | Q32: 10038.22 | S32: 6977.93
A33: Véhicules neufsFrais de livraison | B33: Véhicules neufs | C33: Frais de livraison | E33: 115 | F33: 7705 | K33: 51.42137 | L33: 3753.76 | N33: -3951.24 | P33: 99.448824 | Q33: 3381.26 | S33: 372.5
A34: Véhicules neufsService gratuit 1 | B34: Véhicules neufs | C34: Service gratuit 1 | E34: 3 | F34: 201 | K34: 1.5160274 | L34: 110.67 | N34: -90.33 | P34: 2.3529412 | Q34: 80 | S34: 30.67
A35: Véhicules neufsEntretien stock | B35: Véhicules neufs | C35: Entretien stock | E35: 85.05 | F35: 5698.35 | K35: 164.94 | L35: 12040.62 | N35: 6342.27 | P35: 88.82 | Q35: 3019.88 | S35: 9020.74
A36: Véhicules neufsPublicité 1 | B36: Véhicules neufs | C36: Publicité 1 | E36: 112.47761 | F36: 7536 | K36: 131.05397 | L36: 9566.94 | N36: 2030.94 | P36: 159.71529 | Q36: 5430.32 | S36: 4136.62
A37: Véhicules neufsIntérêt de gros | B37: Véhicules neufs | C37: Intérêt de gros | E37: 318.30489 | F37: 21326.428 | K37: 474.72863 | L37: 34655.19 | N37: 13328.762 | P37: 54.914412 | Q37: 1867.09 | S37: 32788.1
A38: Véhicules neufs[...] | B38: Véhicules neufs | C38: [...] | E38: 0 | F38: 0 | K38: 0 | L38: 0 | N38: 0 | P38: 0 | Q38: 0 | S38: 0
A39: Véhicules neufs[...] | B39: Véhicules neufs | C39: [...] | E39: 0 | F39: 0 | K39: 0 | L39: 0 | N39: 0 | P39: 0 | Q39: 0 | S39: 0
A40: Véhicules neufs[...] | B40: Véhicules neufs | C40: [...] | E40: 0 | F40: 0 | K40: 0 | L40: 0 | N40: 0 | P40: 0 | Q40: 0 | S40: 0
...

Sheet Mai 2024
C1: Volks | K1: Véhicules neufs | S1: Réalisé, Mai 2024
D2: X | E2: O | F2: U | J2: NB | L2: $ | O2: X | P2: O | Q2: U | V2: *** NE PAS EFFACER / Pour An Précédente ***
D3: BUDGET ORIGINAL | J3: RÉALISATION | M3: ÉCART réel / Budget | O3: ANNÉE PRÉCÉDENTE | R3: ECART (réel/ Ann.Préc.) | V3: NEUF | W3: 0.45
D4: UNITE | E4: $P/UNITÉ | F4: $PROFITS | J4: UNITÉS | K4: $P/UNITE | L4: $PROFITS | M4: UNITÉS | N4: $PROFITS | O4: UNITE | P4: $P/UNITÉ | Q4: $PROFITS | R4: UNITÉS | S4: $PROFITS | V4: USAGE | W4: 0.1
A5: Véhicules neufsVentes nettes | B5: Véhicules neufs | C5: Ventes nettes | F5: 3729071 | L5: 3906259.8 | Q5: 2808157.7 | V5: SERVICE | W5: 0.225
A6: Véhicules neufsAutos détail | B6: Véhicules neufs | C6: Autos détail | D6: 14 | E6: 2166.7202 | F6: 30334.083 | J6: 18 | K6: 1997.7756 | L6: 35959.96 | M6: 4 | N6: 5625.8774 | O6: 12 | P6: 2048.03 | Q6: 24576.36 | R6: 6 | S6: 11383.6 | V6: CARROSSERIE | W6: 0.025
A7: Véhicules neufsCamions détail | B7: Véhicules neufs | C7: Camions détail | D7: 57.04 | E7: 2873.2447 | F7: 163889.88 | J7: 51 | K7: 2441.8604 | L7: 124534.88 | M7: -6.04 | N7: -39354.995 | O7: 34 | P7: 2504.1768 | Q7: 85142.01 | R7: 17 | S7: 39392.87 | V7: PIECES | W7: 0.2
A8: Véhicules neufsSprinter | B8: Véhicules neufs | C8: Sprinter | D8: 0 | E8: 0 | F8: 0 | J8: 0 | K8: 0 | L8: 0 | M8: 0 | N8: 0 | O8: 0 | P8: 0 | Q8: 0 | R8: 0 | S8: 0 | W8: 1
A9: Véhicules neufsMoto détail | B9: Véhicules neufs | C9: Moto détail | D9: 0 | E9: 0 | F9: 0 | J9: 0 | K9: 0 | L9: 0 | M9: 0 | N9: 0 | O9: 0 | P9: 0 | Q9: 0 | R9: 0 | S9: 0
A10: Véhicules neufs[...] | B10: Véhicules neufs | C10: [...] | D10: 0 | E10: 0 | F10: 0 | J10: 0 | K10: 0 | L10: 0 | M10: 0 | N10: 0 | O10: 0 | P10: 0 | Q10: 0 | R10: 0 | S10: 0
A11: Véhicules neufs[...] | B11: Véhicules neufs | C11: [...] | D11: 0 | E11: 0 | F11: 0 | J11: 0 | K11: 0 | L11: 0 | M11: 0 | N11: 0 | O11: 0 | P11: 0 | Q11: 0 | R11: 0 | S11: 0
A12: Véhicules neufs[...] | B12: Véhicules neufs | C12: [...] | D12: 0 | E12: 0 | F12: 0 | J12: 0 | K12: 0 | L12: 0 | M12: 0 | N12: 0 | O12: 0 | P12: 0 | Q12: 0 | R12: 0 | S12: 0
A13: Véhicules neufsTotal Neufs | B13: Véhicules neufs | C13: Total Neufs | D13: 71.04 | E13: 2734.0084 | F13: 194223.96 | J13: 69 | K13: 2326.0122 | L13: 160494.84 | M13: -2.04 | N13: -33729.118 | O13: 46 | P13: 2385.182 | Q13: 109718.37 | R13: 23 | S13: 50776.47
A14: Véhicules neufs | B14: Véhicules neufs | M14: -0.028716216 | N14: -0.17366095 | R14: 0.5 | S14: 0.46278914 | AD14: 20 | AE14: 1000 | AF14: 20000
A15: Véhicules neufsEx-Démos et courtoisies | B15: Véhicules neufs | C15: Ex-Démos et courtoisies | D15: 5.635 | E15: 2535.1216 | F15: 14285.41 | J15: 5 | K15: 1165.582 | L15: 5827.91 | M15: -0.635 | N15: -8457.5001 | O15: 7 | P15: 2567.5443 | Q15: 17972.81 | R15: -2 | S15: -12144.9 | AD15: 25 | AE15: 800 | AF15: 20000
A16: Véhicules neufs | B16: Véhicules neufs
A17: Véhicules neufsFlottes | B17: Véhicules neufs | C17: Flottes | D17: 5.175 | E17: 2664.4641 | F17: 13788.602 | J17: 0 | K17: 0 | L17: 0 | M17: -5.175 | N17: -13788.602 | O17: 3 | P17: 1222.9133 | Q17: 3668.74 | R17: -3 | S17: -3668.74
A18: Véhicules neufs | B18: Véhicules neufs
A19: Véhicules neufsRachat bail | B19: Véhicules neufs | C19: Rachat bail | D19: 0 | E19: 0 | F19: 9775 | L19: 9930 | N19: 155 | Q19: 12671.61 | R19: 0 | S19: -2741.61
A20: Véhicules neufs | B20: Véhicules neufs
A21: Véhicules neufsRev. Finances | B21: Véhicules neufs | C21: Rev. Finances | D21: 0 | E21: 0 | F21: 15335 | K21: 10.810811 | L21: 800 | N21: -14535 | Q21: 7236.22 | R21: -10.810811 | S21: -6436.22
A22: Véhicules neufsRev. Protections | B22: Véhicules neufs | C22: Rev. Protections | D22: 0 | E22: 0 | F22: 82809 | K22: 791.51257 | L22: 58571.93 | N22: -24237.07 | Q22: 53155.27 | R22: -791.51257 | S22: 5416.66
A23: Véhicules neufsRev. Autres | B23: Véhicules neufs | C23: Rev. Autres | D23: 0 | E23: 0 | F23: 1533.5 | K23: 0 | L23: 0 | N23: -1533.5 | Q23: 1745.17 | R23: 0 | S23: -1745.17
A24: Véhicules neufsTotal F&I | B24: Véhicules neufs | C24: Total F&I | D24: 76.675 | E24: 1300 | F24: 99677.5 | J24: 74 | K24: 802.32338 | L24: 59371.93 | M24: -2.675 | N24: -40305.57 | O24: 53 | P24: 1172.3898 | Q24: 62136.66 | S24: -2764.73
A25: Véhicules neufs | B25: Véhicules neufs | N25: -0.40435976 | S25: -0.044494345
A26: Véhicules neufs | B26: Véhicules neufs
A27: Véhicules neufsTotal Dépt. Neufs | B27: Véhicules neufs | C27: Total Dépt. Neufs | D27: 81.85 | E27: 4053.1517 | F27: 331750.47 | J27: 74 | K27: 3184.1173 | L27: 235624.68 | M27: -7.85 | N27: -96125.789 | O27: 56 | P27: 3681.5748 | Q27: 206168.19 | R27: 18 | S27: 29456.49
A28: Véhicules neufs | B28: Véhicules neufs | L28: 0.71024671 | M28: -0.095907147 | N28: -0.28975329 | R28: 0.32142857 | S28: 0.14287602
A29: Véhicules neufs | B29: Véhicules neufs
A30: Véhicules neufsDEPENSES | B30: Véhicules neufs | C30: DEPENSES
A31: Véhicules neufsComm. vendeurs | B31: Véhicules neufs | C31: Comm. vendeurs | D31: 0.34 | E31: 924.59322 | F31: 70893.185 | J31: 0.21053999 | K31: 473.21068 | L31: 35017.59 | N31: -35875.595 | O31: 0.3181647 | P31: 788.56774 | Q31: 41794.09 | S31: -6776.5
A32: Véhicules neufsComm. F&I | B32: Véhicules neufs | C32: Comm. F&I | D32: 0.3 | E32: 390 | F32: 29903.25 | J32: 0.29999833 | K32: 240.69568 | L32: 17811.48 | N32: -12091.77 | O32: 0.29997187 | P32: 351.68396 | Q32: 18639.25 | S32: -827.77
A33: Véhicules neufsFrais de livraison | B33: Véhicules neufs | C33: Frais de livraison | E33: 115 | F33: 8817.625 | K33: 153.52486 | L33: 11360.84 | N33: 2543.215 | P33: 112.82151 | Q33: 5979.54 | S33: 5381.3
A34: Véhicules neufsService gratuit 1 | B34: Véhicules neufs | C34: Service gratuit 1 | E34: 3 | F34: 230.025 | K34: 13.206486 | L34: 977.28 | N34: 747.255 | P34: 0 | Q34: 0 | S34: 977.28
A35: Véhicules neufsEntretien stock | B35: Véhicules neufs | C35: Entretien stock | E35: 85.05 | F35: 6521.2087 | K35: 132.78284 | L35: 9825.93 | N35: 3304.7213 | P35: 66.649057 | Q35: 3532.4 | S35: 6293.53
A36: Véhicules neufsPublicité 1 | B36: Véhicules neufs | C36: Publicité 1 | E36: 26.977502 | F36: 2068.5 | K36: 164.58405 | L36: 12179.22 | N36: 10110.72 | P36: 56.458679 | Q36: 2992.31 | S36: 9186.91 | U36: PPM VENTE PRIVEE - 5K
A37: Véhicules neufsIntérêt de gros | B37: Véhicules neufs | C37: Intérêt de gros | E37: 234.37935 | F37: 17971.036 | K37: 644.70649 | L37: 47708.28 | N37: 29737.244 | P37: 110.78396 | Q37: 5871.55 | S37: 41836.73
A38: Véhicules neufs[...] | B38: Véhicules neufs | C38: [...] | E38: 0 | F38: 0 | K38: 0 | L38: 0 | N38: 0 | P38: 0 | Q38: 0 | S38: 0
A39: Véhicules neufs[...] | B39: Véhicules neufs | C39: [...] | E39: 0 | F39: 0 | K39: 0 | L39: 0 | N39: 0 | P39: 0 | Q39: 0 | S39: 0
A40: Véhicules neufs[...] | B40: Véhicules neufs | C40: [...] | E40: 0 | F40: 0 | K40: 0 | L40: 0 | N40: 0 | P40: 0 | Q40: 0 | S40: 0
...

Sheet Juin 2024
C1: Volks | K1: Véhicules neufs | S1: Réalisé, Juin 2024
D2: X | E2: O | F2: U | J2: NB | L2: $ | O2: X | P2: O | Q2: U | V2: *** NE PAS EFFACER / Pour An Précédente ***
D3: BUDGET ORIGINAL | J3: RÉALISATION | M3: ÉCART réel / Budget | O3: ANNÉE PRÉCÉDENTE | R3: ECART (réel/ Ann.Préc.) | V3: NEUF | W3: 0.45
D4: UNITE | E4: $P/UNITÉ | F4: $PROFITS | J4: UNITÉS | K4: $P/UNITE | L4: $PROFITS | M4: UNITÉS | N4: $PROFITS | O4: UNITE | P4: $P/UNITÉ | Q4: $PROFITS | R4: UNITÉS | S4: $PROFITS | V4: USAGE | W4: 0.1
A5: Véhicules neufsVentes nettes | B5: Véhicules neufs | C5: Ventes nettes | F5: 2918459.9 | L5: 2093787.4 | Q5: 2851329.3 | V5: SERVICE | W5: 0.225
A6: Véhicules neufsAutos détail | B6: Véhicules neufs | C6: Autos détail | D6: 11 | E6: 2158.1561 | F6: 23739.717 | J6: 15 | K6: 1651.894 | L6: 24778.41 | M6: 4 | N6: 1038.6932 | O6: 16 | P6: 2103.4488 | Q6: 33655.18 | R6: -1 | S6: -8876.77 | V6: CARROSSERIE | W6: 0.025
A7: Véhicules neufsCamions détail | B7: Véhicules neufs | C7: Camions détail | D7: 44.64 | E7: 2873.2447 | F7: 128261.64 | J7: 25 | K7: 2415.8504 | L7: 60396.26 | M7: -19.64 | N7: -67865.381 | O7: 39 | P7: 2445.2556 | Q7: 95364.97 | R7: -14 | S7: -34968.71 | V7: PIECES | W7: 0.2
A8: Véhicules neufsSprinter | B8: Véhicules neufs | C8: Sprinter | D8: 0 | E8: 0 | F8: 0 | J8: 0 | K8: 0 | L8: 0 | M8: 0 | N8: 0 | O8: 0 | P8: 0 | Q8: 0 | R8: 0 | S8: 0 | W8: 1
A9: Véhicules neufsMoto détail | B9: Véhicules neufs | C9: Moto détail | D9: 0 | E9: 0 | F9: 0 | J9: 0 | K9: 0 | L9: 0 | M9: 0 | N9: 0 | O9: 0 | P9: 0 | Q9: 0 | R9: 0 | S9: 0
A10: Véhicules neufs[...] | B10: Véhicules neufs | C10: [...] | D10: 0 | E10: 0 | F10: 0 | J10: 0 | K10: 0 | L10: 0 | M10: 0 | N10: 0 | O10: 0 | P10: 0 | Q10: 0 | R10: 0 | S10: 0
A11: Véhicules neufs[...] | B11: Véhicules neufs | C11: [...] | D11: 0 | E11: 0 | F11: 0 | J11: 0 | K11: 0 | L11: 0 | M11: 0 | N11: 0 | O11: 0 | P11: 0 | Q11: 0 | R11: 0 | S11: 0
A12: Véhicules neufs[...] | B12: Véhicules neufs | C12: [...] | D12: 0 | E12: 0 | F12: 0 | J12: 0 | K12: 0 | L12: 0 | M12: 0 | N12: 0 | O12: 0 | P12: 0 | Q12: 0 | R12: 0 | S12: 0
A13: Véhicules neufsTotal Neufs | B13: Véhicules neufs | C13: Total Neufs | D13: 55.64 | E13: 2731.872 | F13: 152001.36 | J13: 40 | K13: 2129.3667 | L13: 85174.67 | M13: -15.64 | N13: -66826.688 | O13: 55 | P13: 2345.8209 | Q13: 129020.15 | R13: -15 | S13: -43845.48
A14: Véhicules neufs | B14: Véhicules neufs | M14: -0.28109274 | N14: -0.43964534 | R14: -0.27272727 | S14: -0.33983436 | AD14: 20 | AE14: 1000 | AF14: 20000
A15: Véhicules neufsEx-Démos et courtoisies | B15: Véhicules neufs | C15: Ex-Démos et courtoisies | D15: 4.41 | E15: 2535.1216 | F15: 11179.886 | J15: 0 | K15: 0 | L15: 0 | M15: -4.41 | N15: -11179.886 | O15: 2 | P15: 1486.73 | Q15: 2973.46 | R15: -2 | S15: -2973.46 | AD15: 25 | AE15: 800 | AF15: 20000
A16: Véhicules neufs | B16: Véhicules neufs
A17: Véhicules neufsFlottes | B17: Véhicules neufs | C17: Flottes | D17: 4.05 | E17: 2664.4641 | F17: 10791.079 | J17: 0 | K17: 0 | L17: 0 | M17: -4.05 | N17: -10791.079 | O17: 2 | P17: 2962.945 | Q17: 5925.89 | R17: -2 | S17: -5925.89
A18: Véhicules neufs | B18: Véhicules neufs
A19: Véhicules neufsRachat bail | B19: Véhicules neufs | C19: Rachat bail | D19: 0 | E19: 0 | F19: 7650 | L19: 6100 | N19: -1550 | Q19: 12900.75 | R19: 0 | S19: -6800.75
A20: Véhicules neufs | B20: Véhicules neufs
A21: Véhicules neufsRev. Finances | B21: Véhicules neufs | C21: Rev. Finances | D21: 0 | E21: 0 | F21: 12010 | K21: 0 | L21: 0 | N21: -12010 | Q21: 5095.89 | R21: 0 | S21: -5095.89
A22: Véhicules neufsRev. Protections | B22: Véhicules neufs | C22: Rev. Protections | D22: 0 | E22: 0 | F22: 64854 | K22: 775.005 | L22: 31000.2 | N22: -33853.8 | Q22: 49499.24 | R22: -775.005 | S22: -18499.04
A23: Véhicules neufsRev. Autres | B23: Véhicules neufs | C23: Rev. Autres | D23: 0 | E23: 0 | F23: 1201 | K23: 67.475 | L23: 2699 | N23: 1498 | Q23: 0 | R23: -67.475 | S23: 2699
A24: Véhicules neufsTotal F&I | B24: Véhicules neufs | C24: Total F&I | D24: 60.05 | E24: 1300 | F24: 78065 | J24: 40 | K24: 842.48 | L24: 33699.2 | M24: -20.05 | N24: -44365.8 | O24: 57 | P24: 957.8093 | Q24: 54595.13 | S24: -20895.93
A25: Véhicules neufs | B25: Véhicules neufs | N25: -0.56831871 | S25: -0.38274348
A26: Véhicules neufs | B26: Véhicules neufs
A27: Véhicules neufsTotal Dépt. Neufs | B27: Véhicules neufs | C27: Total Dépt. Neufs | D27: 64.1 | E27: 4051.2843 | F27: 259687.32 | J27: 40 | K27: 3124.3467 | L27: 124973.87 | M27: -24.1 | N27: -134713.45 | O27: 59 | P27: 3481.6166 | Q27: 205415.38 | R27: -19 | S27: -80441.51
A28: Véhicules neufs | B28: Véhicules neufs | L28: 0.48124748 | M28: -0.37597504 | N28: -0.51875252 | R28: -0.3220339 | S28: -0.39160412
A29: Véhicules neufs | B29: Véhicules neufs
A30: Véhicules neufsDEPENSES | B30: Véhicules neufs | C30: DEPENSES
A31: Véhicules neufsComm. vendeurs | B31: Véhicules neufs | C31: Comm. vendeurs | D31: 0.34 | E31: 923.92378 | F31: 55481.623 | J31: 0.30022752 | K31: 639.2945 | L31: 25571.78 | N31: -29909.843 | O31: 0.31879372 | P31: 771.36614 | Q31: 43967.87 | S31: -18396.09
A32: Véhicules neufsComm. F&I | B32: Véhicules neufs | C32: Comm. F&I | D32: 0.3 | E32: 390 | F32: 23419.5 | J32: 0.0032629855 | K32: 2.749 | L32: 109.96 | N32: -23309.54 | O32: 0.30010864 | P32: 287.44684 | Q32: 16384.47 | S32: -16274.51
A33: Véhicules neufsFrais de livraison | B33: Véhicules neufs | C33: Frais de livraison | E33: 115 | F33: 6905.75 | K33: 130.5265 | L33: 5221.06 | N33: -1684.69 | P33: 98.259649 | Q33: 5600.8 | S33: -379.74
A34: Véhicules neufsService gratuit 1 | B34: Véhicules neufs | C34: Service gratuit 1 | E34: 3 | F34: 180.15 | K34: 4.62375 | L34: 184.95 | N34: 4.8 | P34: 0 | Q34: 0 | S34: 184.95
A35: Véhicules neufsEntretien stock | B35: Véhicules neufs | C35: Entretien stock | E35: 85.05 | F35: 5107.2525 | K35: 185.7815 | L35: 7431.26 | N35: 2324.0075 | P35: 70.210526 | Q35: 4002 | S35: 3429.26
A36: Véhicules neufsPublicité 1 | B36: Véhicules neufs | C36: Publicité 1 | E36: 137.06911 | F36: 8231 | K36: 266.85925 | L36: 10674.37 | N36: 2443.37 | P36: 122.48649 | Q36: 6981.73 | S36: 3692.64 | U36: PPM VENTE PRIVEE - 5K
A37: Véhicules neufsIntérêt de gros | B37: Véhicules neufs | C37: Intérêt de gros | E37: 277.29499 | F37: 16651.564 | K37: 1001.4042 | L37: 40056.17 | N37: 23404.606 | P37: 83.072632 | Q37: 4735.14 | S37: 35321.03
A38: Véhicules neufs[...] | B38: Véhicules neufs | C38: [...] | E38: 0 | F38: 0 | K38: 0 | L38: 0 | N38: 0 | P38: 0 | Q38: 0 | S38: 0
A39: Véhicules neufs[...] | B39: Véhicules neufs | C39: [...] | E39: 0 | F39: 0 | K39: 0 | L39: 0 | N39: 0 | P39: 0 | Q39: 0 | S39: 0
A40: Véhicules neufs[...] | B40: Véhicules neufs | C40: [...] | E40: 0 | F40: 0 | K40: 0 | L40: 0 | N40: 0 | P40: 0 | Q40: 0 | S40: 0
...

Sheet END
