Workbook
Name _Dates_Conc: [1]Dealers!$BF$37:$KA$63
Name _scen: '[1]Scen & Sens'!$E$26
Name _scen1: '[1]Scen & Sens'!$E$27
Name _scen2: '[1]Scen & Sens'!$E$28
Name _SCenarios: '[1]Scen & Sens'!$J$26:$O$26
Name _Sens1: '[1]Scen & Sens'!$F$9
Name _Sens2: '[1]Scen & Sens'!$F$10
Name _sensRes1: '[1]Scen & Sens'!$E$15
Name _sensRes2: '[1]Scen & Sens'!$E$16
Name _sensRes3: '[1]Scen & Sens'!$E$17
Name _sensRes4: '[1]Scen & Sens'!$E$18
Name _sensRes5: '[1]Scen & Sens'!$E$19
Name _sensRes6: '[1]Scen & Sens'!$E$20
Name _sensRes7: '[1]Scen & Sens'!$E$21
Name DateRange: [1]Volkswagen!$BF$6:$DY$6
Name Monetary_Unit: [1]Parameters!$B$15
Name Months: [1]Parameters!$E$9:$E$20
Name Rng_Dealers_Names: [1]!Tbl_Dealers[Dealer Name]
Name Rng_Dlr_Dates: [1]!Tbl_V_Dlr_Dates[Date]
Name Ticker: #REF!
Name Ticker: #REF!
Name Ticker: #REF!
Name Titre: [1]Front!$A$9

Sheet Paramètre
B3: Quarter
B6: BUDGET | F6: BUDGET RÉVISÉ | J6: ACTUAL | N6: LAST YEAR
B7: Ventes | C7: Profits bruts | D7: BAIIA | E7: EBIT | F7: Ventes | G7: Profits bruts | H7: BAIIA | I7: EBIT | J7: Ventes | K7: Profits bruts | L7: BAIIA | M7: EBIT | N7: Ventes | O7: Profits bruts | P7: BAIIA | Q7: EBIT
A8: CTRL | B8: =+B9-B10 -> #REF! | C8: =+C9-C10 -> #REF! | D8: =+D9-D10 -> #REF! | E8: =+E9-E10 -> #REF! | F8: =+F9-F10 -> #REF! | G8: =+G9-G10 -> #REF! | H8: =+H9-H10 -> #REF! | I8: =+I9-I10 -> #REF! | ... Q8: =+Q9-Q10 -> #REF!
A9: CONSO | B9: =+Conso!$Z$405 -> 20000715 | C9: =+Conso!$Z$406 -> 2455615.9 | D9: =+Conso!$Z$482 -> 742277.72 | E9: =+Conso!$Z$497 -> 614571.22 | F9: =+Conso!$AC$405 -> 0 | G9: =+Conso!$AC$406 -> 0 | H9: =+Conso!$AC$482 -> 0 | I9: =+Conso!$AC$497 -> 0 | J9: =+Conso!$AF$405 -> 17432381 | K9: =+Conso!$AF$406 -> 2121598.6 | L9: =+Conso!$AF$482 -> 595238.07 | M9: =+Conso!$AF$497 -> 468373.07 | N9: =+Conso!$AL$405 -> 12663799 | O9: =+Conso!$AL$406 -> 1865550.7 | P9: =+Conso!$AL$482 -> 359623.03 | Q9: =+Conso!$AL$497 -> 249286.1
A10: TOTAL | B10: =+SUM(B11:B13) -> #REF! | C10: =+SUM(C11:C13) -> #REF! | D10: =+SUM(D11:D13) -> #REF! | E10: =+SUM(E11:E13) -> #REF! | F10: =+SUM(F11:F13) -> #REF! | G10: =+SUM(G11:G13) -> #REF! | H10: =+SUM(H11:H13) -> #REF! | I10: =+SUM(I11:I13) -> #REF! | ... Q10: =+SUM(Q11:Q13) -> #REF!
A11: Mois 1 | B11: =+#REF! -> #REF! | C11: =+#REF! -> #REF! | D11: =+#REF! -> #REF! | E11: =+#REF! -> #REF! | F11: =+#REF! -> #REF! | G11: =+#REF! -> #REF! | H11: =+#REF! -> #REF! | I11: =+#REF! -> #REF! | ... Q11: =+#REF! -> #REF!
A12: Mois 2 | B12: =+#REF! -> #REF! | C12: =+#REF! -> #REF! | D12: =+#REF! -> #REF! | E12: =+#REF! -> #REF! | F12: =+#REF! -> #REF! | G12: =+#REF! -> #REF! | H12: =+#REF! -> #REF! | I12: =+#REF! -> #REF! | ... Q12: =+#REF! -> #REF!
A13: Mois 3 | B13: =+#REF! -> #REF! | C13: =+#REF! -> #REF! | D13: =+#REF! -> #REF! | E13: =+#REF! -> #REF! | F13: =+#REF! -> #REF! | G13: =+#REF! -> #REF! | H13: =+#REF! -> #REF! | I13: =+#REF! -> #REF! | ... Q13: =+#REF! -> #REF!

Sheet Conso
C1: Conso | K1: Véhicules neufs | S1: =CONCATENATE("Réalisé"," ",Paramètre!$C$2," ",Paramètre!$C$3) -> Réalisé
D2: X | E2: O | F2: U | G2: X | H2: O | I2: U
D3: BUDGET ORIGINAL | G3: BUDGET REVISE | J3: RÉALISATION | M3: ÉCART réel / original | O3: ANNÉE PRÉCÉDENTE | R3: ÉCART réel / année précédente
D4: UNITE | E4: $P/UNITÉ | F4: $PROFITS | G4: UNITE | H4: $P/UNITÉ | I4: $PROFITS | J4: UNITE | K4: $P/UNITE | L4: $PROFITS | M4: UNITÉ | N4: $PROFITS | O4: UNITE | P4: $P/UNITE | Q4: $PROFITS | R4: UNITE | S4: $PROFITS
A5: =+B5&C5 -> Véhicules neufsVentes nettes | B5: =+$K$1 -> Véhicules neufs | C5: Ventes nettes | F5: =+SUM(START:END!F5) -> 11342294 | I5: =+SUM(START:END!I5) -> 0 | L5: =+SUM(START:END!L5) -> 9449688.8 | Q5: =+SUM(START:END!Q5) -> 6739517.4
A6: =+B6&C6 -> Véhicules neufsAutos détail | B6: =+$K$1 -> Véhicules neufs | C6: Autos détail | D6: =+SUM(START:END!D6) -> 56 | E6: =IF(D6=0,0,F6/D6) -> 1953.6492 | F6: =+SUM(START:END!F6) -> 109404.35 | G6: =+SUM(START:END!G6) -> 0 | H6: =IF(G6=0,0,I6/G6) -> 0 | I6: =+SUM(START:END!I6) -> 0 | J6: =+SUM(START:END!J6) -> 23 | K6: =IF(J6=0,0,L6/J6) -> 1641.91 | L6: =+SUM(START:END!L6) -> 37763.93 | M6: =J6-D6 -> -33 | N6: =L6-F6 -> -71640.423 | O6: =+SUM(START:END!O6) -> 26 | P6: =IF(O6=0,0,Q6/O6) -> 1810.325 | Q6: =+SUM(START:END!Q6) -> 47068.45 | R6: =J6-O6 -> -3 | S6: =L6-Q6 -> -9304.52
A7: =+B7&C7 -> Véhicules neufsCamions détail | B7: =+$K$1 -> Véhicules neufs | C7: Camions détail | D7: =+SUM(START:END!D7) -> 149 | E7: =IF(D7=0,0,F7/D7) -> 2435.9047 | F7: =+SUM(START:END!F7) -> 362949.8 | G7: =+SUM(START:END!G7) -> 0 | H7: =IF(G7=0,0,I7/G7) -> 0 | I7: =+SUM(START:END!I7) -> 0 | J7: =+SUM(START:END!J7) -> 134 | K7: =IF(J7=0,0,L7/J7) -> 1956.4093 | L7: =+SUM(START:END!L7) -> 262158.85 | M7: =J7-D7 -> -15 | N7: =L7-F7 -> -100790.95 | O7: =+SUM(START:END!O7) -> 83 | P7: =IF(O7=0,0,Q7/O7) -> 1820.1257 | Q7: =+SUM(START:END!Q7) -> 151070.43 | R7: =J7-O7 -> 51 | S7: =L7-Q7 -> 111088.42
A8: =+B8&C8 -> Véhicules neufsSprinter | B8: =+$K$1 -> Véhicules neufs | C8: Sprinter | D8: =+SUM(START:END!D8) -> 0 | E8: =IF(D8=0,0,F8/D8) -> 0 | F8: =+SUM(START:END!F8) -> 0 | G8: =+SUM(START:END!G8) -> 0 | H8: =IF(G8=0,0,I8/G8) -> 0 | I8: =+SUM(START:END!I8) -> 0 | J8: =+SUM(START:END!J8) -> 0 | K8: =IF(J8=0,0,L8/J8) -> 0 | L8: =+SUM(START:END!L8) -> 0 | M8: =J8-D8 -> 0 | N8: =L8-F8 -> 0 | O8: =+SUM(START:END!O8) -> 0 | P8: =IF(O8=0,0,Q8/O8) -> 0 | Q8: =+SUM(START:END!Q8) -> 0 | R8: =J8-O8 -> 0 | S8: =L8-Q8 -> 0
A9: =+B9&C9 -> Véhicules neufsMoto détail | B9: =+$K$1 -> Véhicules neufs | C9: Moto détail | D9: =+SUM(START:END!D9) -> 0 | E9: =IF(D9=0,0,F9/D9) -> 0 | F9: =+SUM(START:END!F9) -> 0 | G9: =+SUM(START:END!G9) -> 0 | H9: =IF(G9=0,0,I9/G9) -> 0 | I9: =+SUM(START:END!I9) -> 0 | J9: =+SUM(START:END!J9) -> 0 | K9: =IF(J9=0,0,L9/J9) -> 0 | L9: =+SUM(START:END!L9) -> 0 | M9: =J9-D9 -> 0 | N9: =L9-F9 -> 0 | O9: =+SUM(START:END!O9) -> 0 | P9: =IF(O9=0,0,Q9/O9) -> 0 | Q9: =+SUM(START:END!Q9) -> 0 | R9: =J9-O9 -> 0 | S9: =L9-Q9 -> 0
A10: =+B10&C10 -> Véhicules neufs[...] | B10: =+$K$1 -> Véhicules neufs | C10: [...] | D10: =+SUM(START:END!D10) -> 0 | E10: =IF(D10=0,0,F10/D10) -> 0 | F10: =+SUM(START:END!F10) -> 0 | G10: =+SUM(START:END!G10) -> 0 | H10: =IF(G10=0,0,I10/G10) -> 0 | I10: =+SUM(START:END!I10) -> 0 | J10: =+SUM(START:END!J10) -> 0 | K10: =IF(J10=0,0,L10/J10) -> 0 | L10: =+SUM(START:END!L10) -> 0 | M10: =J10-G10 -> 0 | N10: =L10-I10 -> 0 | O10: =+SUM(START:END!O10) -> 0 | P10: =IF(O10=0,0,Q10/O10) -> 0 | Q10: =+SUM(START:END!Q10) -> 0 | R10: =J10-O10 -> 0 | S10: =L10-Q10 -> 0
A11: =+B11&C11 -> Véhicules neufs[...] | B11: =+$K$1 -> Véhicules neufs | C11: [...] | D11: =+SUM(START:END!D11) -> 0 | E11: =IF(D11=0,0,F11/D11) -> 0 | F11: =+SUM(START:END!F11) -> 0 | G11: =+SUM(START:END!G11) -> 0 | H11: =IF(G11=0,0,I11/G11) -> 0 | I11: =+SUM(START:END!I11) -> 0 | J11: =+SUM(START:END!J11) -> 0 | K11: =IF(J11=0,0,L11/J11) -> 0 | L11: =+SUM(START:END!L11) -> 0 | M11: =J11-G11 -> 0 | N11: =L11-I11 -> 0 | O11: =+SUM(START:END!O11) -> 0 | P11: =IF(O11=0,0,Q11/O11) -> 0 | Q11: =+SUM(START:END!Q11) -> 0 | R11: =J11-O11 -> 0 | S11: =L11-Q11 -> 0
A12: =+B12&C12 -> Véhicules neufs[...] | B12: =+$K$1 -> Véhicules neufs | C12: [...] | D12: =+SUM(START:END!D12) -> 0 | E12: =IF(D12=0,0,F12/D12) -> 0 | F12: =+SUM(START:END!F12) -> 0 | G12: =+SUM(START:END!G12) -> 0 | H12: =IF(G12=0,0,I12/G12) -> 0 | I12: =+SUM(START:END!I12) -> 0 | J12: =+SUM(START:END!J12) -> 0 | K12: =IF(J12=0,0,L12/J12) -> 0 | L12: =+SUM(START:END!L12) -> 0 | M12: =J12-G12 -> 0 | N12: =L12-I12 -> 0 | O12: =+SUM(START:END!O12) -> 0 | P12: =IF(O12=0,0,Q12/O12) -> 0 | Q12: =+SUM(START:END!Q12) -> 0 | R12: =J12-O12 -> 0 | S12: =L12-Q12 -> 0
A13: =+B13&C13 -> Véhicules neufsTotal Neufs | B13: =+$K$1 -> Véhicules neufs | C13: Total Neufs | D13: =+SUM(D6:D12) -> 205 | E13: =IF(D13<=0,0,F13/D13) -> 2304.1666 | F13: =+SUM(F6:F12) -> 472354.15 | G13: =+SUM(G6:G12) -> 0 | H13: =IF(G13<=0,0,I13/G13) -> 0 | I13: =+SUM(I6:I12) -> 0 | J13: =+SUM(J6:J12) -> 157 | K13: =IF(J13<=0,0,L13/J13) -> 1910.3362 | L13: =+SUM(L6:L12) -> 299922.78 | M13: =+SUM(M6:M12) -> -48 | N13: =+SUM(N6:N12) -> -172431.37 | O13: =+SUM(O6:O12) -> 109 | P13: =IF(O13<=0,0,Q13/O13) -> 1817.7879 | Q13: =+SUM(Q6:Q12) -> 198138.88 | R13: =+SUM(R6:R12) -> 48 | S13: =+SUM(S6:S12) -> 101783.9
A14: =+B14&C14 -> Véhicules neufs | B14: =+$K$1 -> Véhicules neufs | N14: =IF(F13=0,0,N13/F13) -> -0.3650468 | R14: =R13/O13 -> 0.44036697 | S14: =IF(Q13=0,0,(S13/Q13)) -> 0.51369978
A15: =+B15&C15 -> Véhicules neufsEx-Démos et courtoisies | B15: =+$K$1 -> Véhicules neufs | C15: Ex-Démos et courtoisies | D15: =+SUM(START:END!D15) -> 10 | E15: =IF(D15=0,0,F15/D15) -> 1534.7521 | F15: =+SUM(START:END!F15) -> 15347.521 | G15: =+SUM(START:END!G15) -> 0 | H15: =IF(G15=0,0,I15/G15) -> 0 | I15: =+SUM(START:END!I15) -> 0 | J15: =+SUM(START:END!J15) -> 8 | K15: =IF(J15=0,0,L15/J15) -> 822.34625 | L15: =+SUM(START:END!L15) -> 6578.77 | M15: =J15-D15 -> -2 | N15: =L15-F15 -> -8768.7514 | O15: =+SUM(START:END!O15) -> 12 | P15: =IF(O15=0,0,Q15/O15) -> 1517.4408 | Q15: =+SUM(START:END!Q15) -> 18209.29 | R15: =J15-O15 -> -4 | S15: =L15-Q15 -> -11630.52
A16: =+B16&C16 -> Véhicules neufs | B16: =+$K$1 -> Véhicules neufs
A17: =+B17&C17 -> Véhicules neufsFlottes | B17: =+$K$1 -> Véhicules neufs | C17: Flottes | D17: =+SUM(START:END!D17) -> 5 | E17: =IF(D17=0,0,F17/D17) -> 2393.8521 | F17: =+SUM(START:END!F17) -> 11969.261 | G17: =+SUM(START:END!G17) -> 0 | H17: =IF(G17=0,0,I17/G17) -> 0 | I17: =+SUM(START:END!I17) -> 0 | J17: =+SUM(START:END!J17) -> 5 | K17: =IF(J17=0,0,L17/J17) -> 2778.144 | L17: =+SUM(START:END!L17) -> 13890.72 | M17: =J17-D17 -> 0 | N17: =L17-F17 -> 1921.4594 | O17: =+SUM(START:END!O17) -> 11 | P17: =IF(O17=0,0,Q17/O17) -> 1058.8518 | Q17: =+SUM(START:END!Q17) -> 11647.37 | R17: =J17-O17 -> -6 | S17: =L17-Q17 -> 2243.35
A18: =+B18&C18 -> Véhicules neufs | B18: =+$K$1 -> Véhicules neufs
A19: =+B19&C19 -> Véhicules neufsRachat bail | B19: =+$K$1 -> Véhicules neufs | C19: Rachat bail | F19: =+SUM(START:END!F19) -> 22950 | I19: =+SUM(START:END!I19) -> 0 | L19: =+SUM(START:END!L19) -> 27609.85 | N19: =L19-F19 -> 4659.85 | Q19: =+SUM(START:END!Q19) -> 23749 | R19: =O19-K19 -> 0 | S19: =L19-Q19 -> 3860.85
A20: =+B20&C20 -> Véhicules neufs | B20: =+$K$1 -> Véhicules neufs
A21: =+B21&C21 -> Véhicules neufsRev. Finances | B21: =+$K$1 -> Véhicules neufs | C21: Rev. Finances | D21: 0 | E21: =IF(D21=0,0,F21/D21) -> 0 | F21: =+SUM(START:END!F21) -> 10750 | G21: 0 | H21: =IF(G21=0,0,I21/G21) -> 0 | I21: =+SUM(START:END!I21) -> 0 | K21: =IF(J13=0,0,L21/(J13+J15)) -> 34.835879 | L21: =+SUM(START:END!L21) -> 5747.92 | N21: =L21-F21 -> -5002.08 | P21: =IF(O13=0,0,Q21/(O13+O15)) -> 10.65157 | Q21: =+SUM(START:END!Q21) -> 1288.84 | R21: =O21-K21 -> -34.835879 | S21: =L21-Q21 -> 4459.08
A22: =+B22&C22 -> Véhicules neufsRev. Protections | B22: =+$K$1 -> Véhicules neufs | C22: Rev. Protections | D22: 0 | E22: =IF(D22=0,0,F22/D22) -> 0 | F22: =+SUM(START:END!F22) -> 199950 | G22: 0 | H22: =IF(G22=0,0,I22/G22) -> 0 | I22: =+SUM(START:END!I22) -> 0 | K22: =IF(J13=0,0,L22/(J13+J15)) -> 938.41255 | L22: =+SUM(START:END!L22) -> 154838.07 | N22: =L22-F22 -> -45111.93 | P22: =IF(O13=0,0,Q22/(O13+O15)) -> 1036.308 | Q22: =+SUM(START:END!Q22) -> 125393.27 | R22: =O22-K22 -> -938.41255 | S22: =L22-Q22 -> 29444.8
A23: =+B23&C23 -> Véhicules neufsRev. Autres | B23: =+$K$1 -> Véhicules neufs | C23: Rev. Autres | D23: 0 | E23: =IF(D23=0,0,F23/D23) -> 0 | F23: =+SUM(START:END!F23) -> 4300 | G23: 0 | H23: =IF(G23=0,0,I23/G23) -> 0 | I23: =+SUM(START:END!I23) -> 0 | K23: =IF(J13=0,0,L23/(J13+J15)) -> 11.995879 | L23: =+SUM(START:END!L23) -> 1979.32 | N23: =L23-F23 -> -2320.68 | P23: =IF(O13=0,0,Q23/(O13+O15)) -> 10.65438 | Q23: =+SUM(START:END!Q23) -> 1289.18 | R23: =O23-K23 -> -11.995879 | S23: =L23-Q23 -> 690.14
A24: =+B24&C24 -> Véhicules neufsTotal F&I | B24: =+$K$1 -> Véhicules neufs | C24: Total F&I | D24: =+D15+D13 -> 215 | E24: =IF(D24<=0,0,F24/D24) -> 1000 | F24: =F21+F22+F23 -> 215000 | G24: =+G15+G13 -> 0 | H24: =IF(G24<=0,0,I24/G24) -> 0 | I24: =I21+I22+I23 -> 0 | J24: =+J15+J13 -> 165 | K24: =IF(J24<=0,0,L24/J24) -> 985.2443 | L24: =L21+L22+L23 -> 162565.31 | M24: =+M15+M13 -> -50 | N24: =N21+N22+N23 -> -52434.69 | O24: =+O15+O13 -> 121 | P24: =IF(O24<=0,0,Q24/O24) -> 1057.614 | Q24: =Q21+Q22+Q23 -> 127971.29 | S24: =L24-Q24 -> 34594.02
A25: =+B25&C25 -> Véhicules neufs | B25: =+$K$1 -> Véhicules neufs | S25: =IF(Q24=0,0,(S24/Q24)) -> 0.27032641
A26: =+B26&C26 -> Véhicules neufs | B26: =+$K$1 -> Véhicules neufs
A27: =+B27&C27 -> Véhicules neufsTotal Dépt. Neufs | B27: =+$K$1 -> Véhicules neufs | C27: Total Dépt. Neufs | D27: =+D13+D15+D17 -> 220 | E27: =IF(D27<=0,0,F27/D27) -> 3352.8224 | F27: =F13+F17+F24+F19+F15 -> 737620.93 | G27: =+G13+G15+G17 -> 0 | H27: =IF(G27<=0,0,I27/G27) -> 0 | I27: =I13+I17+I24+I19+I15 -> 0 | J27: =+J13+J15+J17 -> 170 | K27: =IF(J27<=0,0,L27/J27) -> 3003.3378 | L27: =L13+L17+L24+L19+L15 -> 510567.43 | M27: =+M13+M15+M17 -> -50 | N27: =N13+N17+N24+N19+N15 -> -227053.5 | O27: =+O13+O15+O17 -> 132 | P27: =IF(O27<=0,0,Q27/O27) -> 2876.6351 | Q27: =Q13+Q17+Q24+Q19+Q15 -> 379715.83 | R27: =J27-O27 -> 38 | S27: =L27-Q27 -> 130851.6
A28: =+B28&C28 -> Véhicules neufs | B28: =+$K$1 -> Véhicules neufs | M28: =M27/D27 -> -0.22727273 | N28: =N27/F27 -> -0.30781868 | R28: =R27/O27 -> 0.28787879 | S28: =IF(Q27=0,0,S27/Q27) -> 0.34460402
A29: =+B29&C29 -> Véhicules neufs | B29: =+$K$1 -> Véhicules neufs
A30: =+B30&C30 -> Véhicules neufsDEPENSES | B30: =+$K$1 -> Véhicules neufs | C30: DEPENSES
A31: =+B31&C31 -> Véhicules neufsComm. vendeurs | B31: =+$K$1 -> Véhicules neufs | C31: Comm. vendeurs | E31: =F31/D$24 -> 740.68293 | F31: =+SUM(START:END!F31) -> 159246.83 | H31: =I31/G$24 -> #DIV/0! | I31: =+SUM(START:END!I31) -> 0 | J31: =L31/L13 -> 0.35182456 | K31: =IF(L31=0,0,L31/J$24) -> 639.51636 | L31: =+SUM(START:END!L31) -> 105520.2 | N31: =L31-F31 -> -53726.629 | P31: =IF(Q31=0,0,Q31/O$24) -> 622.44397 | Q31: =+SUM(START:END!Q31) -> 75315.72 | S31: =L31-Q31 -> 30204.48
A32: =+B32&C32 -> Véhicules neufsComm. F&I | B32: =+$K$1 -> Véhicules neufs | C32: Comm. F&I | E32: =F32/D$24 -> 280 | F32: =+SUM(START:END!F32) -> 60200 | H32: =I32/G$24 -> #DIV/0! | I32: =+SUM(START:END!I32) -> 0 | J32: =L32/L24 -> 0.26999918 | K32: =IF(L32=0,0,L32/J$24) -> 266.01515 | L32: =+SUM(START:END!L32) -> 43892.5 | N32: =L32-F32 -> -16307.5 | P32: =IF(Q32=0,0,Q32/O$24) -> 300.16132 | Q32: =+SUM(START:END!Q32) -> 36319.52 | S32: =L32-Q32 -> 7572.98
A33: =+B33&C33 -> Véhicules neufsFrais de livraison | B33: =+$K$1 -> Véhicules neufs | C33: Frais de livraison | E33: =F33/D$24 -> 115 | F33: =+SUM(START:END!F33) -> 24725 | H33: =I33/G$24 -> #DIV/0! | I33: =+SUM(START:END!I33) -> 0 | K33: =IF(L33=0,0,L33/J$24) -> 98.449515 | L33: =+SUM(START:END!L33) -> 16244.17 | N33: =L33-F33 -> -8480.83 | P33: =IF(Q33=0,0,Q33/O$24) -> 157.53769 | Q33: =+SUM(START:END!Q33) -> 19062.06 | S33: =L33-Q33 -> -2817.89
A34: =+B34&C34 -> Véhicules neufsService gratuit 1 | B34: =+$K$1 -> Véhicules neufs | C34: Service gratuit 1 | E34: =F34/D$24 -> 10 | F34: =+SUM(START:END!F34) -> 2150 | H34: =I34/G$24 -> #DIV/0! | I34: =+SUM(START:END!I34) -> 0 | K34: =IF(L34=0,0,L34/J$24) -> 3.3441818 | L34: =+SUM(START:END!L34) -> 551.79 | N34: =L34-F34 -> -1598.21 | P34: =IF(Q34=0,0,Q34/O$24) -> 47.640496 | Q34: =+SUM(START:END!Q34) -> 5764.5 | S34: =L34-Q34 -> -5212.71
A35: =+B35&C35 -> Véhicules neufsEntretien stock | B35: =+$K$1 -> Véhicules neufs | C35: Entretien stock | E35: =F35/D$24 -> 120.75 | F35: =+SUM(START:END!F35) -> 25961.25 | H35: =I35/G$24 -> #DIV/0! | I35: =+SUM(START:END!I35) -> 0 | K35: =IF(L35=0,0,L35/J$24) -> 119.71527 | L35: =+SUM(START:END!L35) -> 19753.02 | N35: =L35-F35 -> -6208.23 | P35: =IF(Q35=0,0,Q35/O$24) -> 158.87983 | Q35: =+SUM(START:END!Q35) -> 19224.46 | S35: =L35-Q35 -> 528.56
A36: =+B36&C36 -> Véhicules neufsPublicité 1 | B36: =+$K$1 -> Véhicules neufs | C36: Publicité 1 | E36: =F36/D$24 -> 115.74884 | F36: =+SUM(START:END!F36) -> 24886 | H36: =I36/G$24 -> #DIV/0! | I36: =+SUM(START:END!I36) -> 0 | K36: =IF(L36=0,0,L36/J$24) -> 166.23073 | L36: =+SUM(START:END!L36) -> 27428.07 | N36: =L36-F36 -> 2542.07 | P36: =IF(Q36=0,0,Q36/O$24) -> 342.80653 | Q36: =+SUM(START:END!Q36) -> 41479.59 | S36: =L36-Q36 -> -14051.52
A37: =+B37&C37 -> Véhicules neufsIntérêt de gros | B37: =+$K$1 -> Véhicules neufs | C37: Intérêt de gros | E37: =F37/D$24 -> 514.75141 | F37: =+SUM(START:END!F37) -> 110671.55 | H37: =I37/G$24 -> #DIV/0! | I37: =+SUM(START:END!I37) -> 0 | K37: =IF(L37=0,0,L37/J$24) -> 393.62709 | L37: =+SUM(START:END!L37) -> 64948.47 | N37: =L37-F37 -> -45723.082 | P37: =IF(Q37=0,0,Q37/O$24) -> -117.72405 | Q37: =+SUM(START:END!Q37) -> -14244.61 | S37: =L37-Q37 -> 79193.08
A38: =+B38&C38 -> Véhicules neufs[...] | B38: =+$K$1 -> Véhicules neufs | C38: [...] | E38: =F38/D$24 -> 0 | F38: =+SUM(START:END!F38) -> 0 | H38: =I38/G$24 -> #DIV/0! | I38: =+SUM(START:END!I38) -> 0 | K38: =IF(L38=0,0,L38/J$24) -> 0 | L38: =+SUM(START:END!L38) -> 0 | N38: =L38-I38 -> 0 | P38: =IF(Q38=0,0,Q38/O$24) -> 0 | Q38: =+SUM(START:END!Q38) -> 0 | S38: =L38-Q38 -> 0
A39: =+B39&C39 -> Véhicules neufs[...] | B39: =+$K$1 -> Véhicules neufs | C39: [...] | E39: =F39/D$24 -> 0 | F39: =+SUM(START:END!F39) -> 0 | H39: =I39/G$24 -> #DIV/0! | I39: =+SUM(START:END!I39) -> 0 | K39: =IF(L39=0,0,L39/J$24) -> 0 | L39: =+SUM(START:END!L39) -> 0 | N39: =L39-I39 -> 0 | P39: =IF(Q39=0,0,Q39/O$24) -> 0 | Q39: =+SUM(START:END!Q39) -> 0 | S39: =L39-Q39 -> 0
A40: =+B40&C40 -> Véhicules neufs[...] | B40: =+$K$1 -> Véhicules neufs | C40: [...] | E40: =F40/D$24 -> 0 | F40: =+SUM(START:END!F40) -> 0 | H40: =I40/G$24 -> #DIV/0! | I40: =+SUM(START:END!I40) -> 0 | K40: =IF(L40=0,0,L40/J$24) -> 0 | L40: =+SUM(START:END!L40) -> 0 | N40: =L40-I40 -> 0 | P40: =IF(Q40=0,0,Q40/O$24) -> 0 | Q40: =+SUM(START:END!Q40) -> 0 | S40: =L40-Q40 -> 0
...

Sheet START

Sheet 2025-10
C1: Volks | K1: Véhicules neufs | S1: Réalisé, Octobre 2025
D2: X | E2: O | F2: U | J2: NB | L2: $ | O2: X | P2: O | Q2: U | V2: *** NE PAS EFFACER / Pour An Précédente ***
D3: BUDGET ORIGINAL | J3: RÉALISATION | M3: ÉCART réel / Budget | O3: ANNÉE PRÉCÉDENTE | R3: ECART (réel/ Ann.Préc.) | V3: NEUF | W3: 0.45
D4: UNITE | E4: $P/UNITÉ | F4: $PROFITS | J4: UNITÉS | K4: $P/UNITE | L4: $PROFITS | M4: UNITÉS | N4: $PROFITS | O4: UNITE | P4: $P/UNITÉ | Q4: $PROFITS | R4: UNITÉS | S4: $PROFITS | V4: USAGE | W4: 0.1
A5: Véhicules neufsVentes nettes | B5: Véhicules neufs | C5: Ventes nettes | F5: 3781098.2 | L5: 2861489.8 | Q5: 2470114 | V5: SERVICE | W5: 0.225
A6: Véhicules neufsAutos détail | B6: Véhicules neufs | C6: Autos détail | D6: 19 | E6: 1953.6492 | F6: 37119.334 | J6: 11 | K6: 1392.1182 | L6: 15313.3 | M6: -8 | N6: -21806.034 | O6: 12 | P6: 1802.2583 | Q6: 21627.1 | R6: -1 | S6: -6313.8 | V6: CARROSSERIE | W6: 0.025
A7: Véhicules neufsCamions détail | B7: Véhicules neufs | C7: Camions détail | D7: 50 | E7: 2435.9047 | F7: 121795.23 | J7: 37 | K7: 2420.7516 | L7: 89567.81 | M7: -13 | N7: -32227.424 | O7: 32 | P7: 1508.5388 | Q7: 48273.24 | R7: 5 | S7: 41294.57 | V7: PIECES | W7: 0.2
A8: Véhicules neufsSprinter | B8: Véhicules neufs | C8: Sprinter | D8: 0 | E8: 0 | F8: 0 | J8: 0 | K8: 0 | L8: 0 | M8: 0 | N8: 0 | O8: 0 | P8: 0 | Q8: 0 | R8: 0 | S8: 0 | W8: 1
A9: Véhicules neufsMoto détail | B9: Véhicules neufs | C9: Moto détail | D9: 0 | E9: 0 | F9: 0 | J9: 0 | K9: 0 | L9: 0 | M9: 0 | N9: 0 | O9: 0 | P9: 0 | Q9: 0 | R9: 0 | S9: 0
A10: Véhicules neufs[...] | B10: Véhicules neufs | C10: [...] | D10: 0 | E10: 0 | F10: 0 | J10: 0 | K10: 0 | L10: 0 | M10: 0 | N10: 0 | O10: 0 | P10: 0 | Q10: 0 | R10: 0 | S10: 0
A11: Véhicules neufs[...] | B11: Véhicules neufs | C11: [...] | D11: 0 | E11: 0 | F11: 0 | J11: 0 | K11: 0 | L11: 0 | M11: 0 | N11: 0 | O11: 0 | P11: 0 | Q11: 0 | R11: 0 | S11: 0
A12: Véhicules neufs[...] | B12: Véhicules neufs | C12: [...] | D12: 0 | E12: 0 | F12: 0 | J12: 0 | K12: 0 | L12: 0 | M12: 0 | N12: 0 | O12: 0 | P12: 0 | Q12: 0 | R12: 0 | S12: 0
A13: Véhicules neufsTotal Neufs | B13: Véhicules neufs | C13: Total Neufs | D13: 69 | E13: 2303.1097 | F13: 158914.57 | J13: 48 | K13: 2185.0231 | L13: 104881.11 | M13: -21 | N13: -54033.458 | O13: 44 | P13: 1588.6441 | Q13: 69900.34 | R13: 4 | S13: 34980.77
A14: Véhicules neufs | B14: Véhicules neufs | M14: -0.30434783 | N14: -0.34001576 | R14: 0.090909091 | S14: 0.50043777 | AD14: 20 | AE14: 1000 | AF14: 20000
A15: Véhicules neufsEx-Démos et courtoisies | B15: Véhicules neufs | C15: Ex-Démos et courtoisies | D15: 3 | E15: 1534.7521 | F15: 4604.2564 | J15: 3 | K15: 1277.7867 | L15: 3833.36 | M15: 0 | N15: -770.89643 | O15: 6 | P15: 1038.8833 | Q15: 6233.3 | R15: -3 | S15: -2399.94 | AD15: 25 | AE15: 800 | AF15: 20000
A16: Véhicules neufs | B16: Véhicules neufs
A17: Véhicules neufsFlottes | B17: Véhicules neufs | C17: Flottes | D17: 2 | E17: 2393.8521 | F17: 4787.7042 | J17: 3 | K17: 2106.1833 | L17: 6318.55 | M17: 1 | N17: 1530.8458 | O17: 2 | P17: 383.48 | Q17: 766.96 | R17: 1 | S17: 5551.59
A18: Véhicules neufs | B18: Véhicules neufs
A19: Véhicules neufsRachat bail | B19: Véhicules neufs | C19: Rachat bail | D19: 0 | E19: 0 | F19: 7650 | L19: 9560 | N19: 1910 | Q19: 10100 | R19: 0 | S19: -540
A20: Véhicules neufs | B20: Véhicules neufs
A21: Véhicules neufsRev. Finances | B21: Véhicules neufs | C21: Rev. Finances | D21: 0 | E21: 0 | F21: 3600 | K21: 38.216863 | L21: 1949.06 | N21: -1650.94 | Q21: 0 | R21: -38.216863 | S21: 1949.06
A22: Véhicules neufsRev. Protections | B22: Véhicules neufs | C22: Rev. Protections | D22: 0 | E22: 0 | F22: 66960 | K22: 968.15549 | L22: 49375.93 | N22: -17584.07 | Q22: 42226.33 | R22: -968.15549 | S22: 7149.6
A23: Véhicules neufsRev. Autres | B23: Véhicules neufs | C23: Rev. Autres | D23: 0 | E23: 0 | F23: 1440 | K23: 0 | L23: 0 | N23: -1440 | Q23: 644.02 | R23: 0 | S23: -644.02
A24: Véhicules neufsTotal F&I | B24: Véhicules neufs | C24: Total F&I | D24: 72 | E24: 1000 | F24: 72000 | J24: 51 | K24: 1006.3724 | L24: 51324.99 | M24: -21 | N24: -20675.01 | O24: 50 | P24: 857.407 | Q24: 42870.35 | S24: 8454.64
A25: Véhicules neufs | B25: Véhicules neufs | N25: -0.28715292 | S25: 0.19721416
A26: Véhicules neufs | B26: Véhicules neufs
A27: Véhicules neufsTotal Dépt. Neufs | B27: Véhicules neufs | C27: Total Dépt. Neufs | D27: 74 | E27: 3350.7639 | F27: 247956.53 | J27: 54 | K27: 3257.7409 | L27: 175918.01 | M27: -20 | N27: -72038.519 | O27: 52 | P27: 2497.5183 | Q27: 129870.95 | R27: 2 | S27: 46047.06
A28: Véhicules neufs | B28: Véhicules neufs | L28: 0.70947118 | M28: -0.27027027 | N28: -0.29052882 | R28: 0.038461538 | S28: 0.35456012
A29: Véhicules neufs | B29: Véhicules neufs
A30: Véhicules neufsDEPENSES | B30: Véhicules neufs | C30: DEPENSES
A31: Véhicules neufsComm. vendeurs | B31: Véhicules neufs | C31: Comm. vendeurs | D31: 0.33313833 | E31: 756.58872 | F31: 54474.388 | J31: 0.35861573 | K31: 808.87549 | L31: 41252.65 | N31: -13221.738 | O31: 0.36538037 | P31: 561.9594 | Q31: 28097.97 | S31: 13154.68
A32: Véhicules neufsComm. F&I | B32: Véhicules neufs | C32: Comm. F&I | D32: 0.28 | E32: 280 | F32: 20160 | J32: 0.26999966 | K32: 271.7202 | L32: 13857.73 | N32: -6302.27 | O32: 0.26999336 | P32: 231.4942 | Q32: 11574.71 | S32: 2283.02
A33: Véhicules neufsFrais de livraison | B33: Véhicules neufs | C33: Frais de livraison | E33: 115 | F33: 8280 | K33: 127.63843 | L33: 6509.56 | N33: -1770.44 | P33: 156.3466 | Q33: 7817.33 | S33: -1307.77
A34: Véhicules neufsService gratuit 1 | B34: Véhicules neufs | C34: Service gratuit 1 | E34: 10 | F34: 720 | K34: 4.0194118 | L34: 204.99 | N34: -515.01 | P34: 16.8636 | Q34: 843.18 | S34: -638.19
A35: Véhicules neufsEntretien stock | B35: Véhicules neufs | C35: Entretien stock | E35: 120.75 | F35: 8694 | K35: 94.619412 | L35: 4825.59 | N35: -3868.41 | P35: 159.8588 | Q35: 7992.94 | S35: -3167.35
A36: Véhicules neufsPublicité 1 | B36: Véhicules neufs | C36: Publicité 1 | E36: 225.86111 | F36: 16262 | K36: 233.87333 | L36: 11927.54 | N36: -4334.46 | P36: 224.6836 | Q36: 11234.18 | S36: 693.36 | U36: credit 8,000 glassroom
A37: Véhicules neufsIntérêt de gros | B37: Véhicules neufs | C37: Intérêt de gros | E37: 565.31871 | F37: 40702.947 | K37: 425.86784 | L37: 21719.26 | N37: -18983.687 | P37: 530.407 | Q37: 26520.35 | S37: -4801.09
A38: Véhicules neufs[...] | B38: Véhicules neufs | C38: [...] | E38: 0 | F38: 0 | K38: 0 | L38: 0 | N38: 0 | P38: 0 | Q38: 0 | S38: 0
A39: Véhicules neufs[...] | B39: Véhicules neufs | C39: [...] | E39: 0 | F39: 0 | K39: 0 | L39: 0 | N39: 0 | P39: 0 | Q39: 0 | S39: 0
A40: Véhicules neufs[...] | B40: Véhicules neufs | C40: [...] | E40: 0 | F40: 0 | K40: 0 | L40: 0 | N40: 0 | P40: 0 | Q40: 0 | S40: 0
...

Sheet 2025-11
C1: Volks | K1: Véhicules neufs | S1: Réalisé, Novembre 2025
D2: X | E2: O | F2: U | J2: NB | L2: $ | O2: X | P2: O | Q2: U | V2: *** NE PAS EFFACER / Pour An Précédente ***
D3: BUDGET ORIGINAL | J3: RÉALISATION | M3: ÉCART réel / Budget | O3: ANNÉE PRÉCÉDENTE | R3: ECART (réel/ Ann.Préc.) | V3: NEUF | W3: 0.45
D4: UNITE | E4: $P/UNITÉ | F4: $PROFITS | J4: UNITÉS | K4: $P/UNITE | L4: $PROFITS | M4: UNITÉS | N4: $PROFITS | O4: UNITE | P4: $P/UNITÉ | Q4: $PROFITS | R4: UNITÉS | S4: $PROFITS | V4: USAGE | W4: 0.1
A5: Véhicules neufsVentes nettes | B5: Véhicules neufs | C5: Ventes nettes | F5: 4620342.2 | L5: 4142859.5 | Q5: 2101403.3 | V5: SERVICE | W5: 0.225
A6: Véhicules neufsAutos détail | B6: Véhicules neufs | C6: Autos détail | D6: 23 | E6: 1953.6492 | F6: 44933.931 | J6: 10 | K6: 1542.296 | L6: 15422.96 | M6: -13 | N6: -29510.971 | O6: 8 | P6: 2031.0612 | Q6: 16248.49 | R6: 2 | S6: -825.53 | V6: CARROSSERIE | W6: 0.025
A7: Véhicules neufsCamions détail | B7: Véhicules neufs | C7: Camions détail | D7: 60 | E7: 2435.9047 | F7: 146154.28 | J7: 60 | K7: 1856.0265 | L7: 111361.59 | M7: 0 | N7: -34792.691 | O7: 27 | P7: 2114.5019 | Q7: 57091.55 | R7: 33 | S7: 54270.04 | V7: PIECES | W7: 0.2
A8: Véhicules neufsSprinter | B8: Véhicules neufs | C8: Sprinter | D8: 0 | E8: 0 | F8: 0 | J8: 0 | K8: 0 | L8: 0 | M8: 0 | N8: 0 | O8: 0 | P8: 0 | Q8: 0 | R8: 0 | S8: 0 | W8: 1
A9: Véhicules neufsMoto détail | B9: Véhicules neufs | C9: Moto détail | D9: 0 | E9: 0 | F9: 0 | J9: 0 | K9: 0 | L9: 0 | M9: 0 | N9: 0 | O9: 0 | P9: 0 | Q9: 0 | R9: 0 | S9: 0
A10: Véhicules neufs[...] | B10: Véhicules neufs | C10: [...] | D10: 0 | E10: 0 | F10: 0 | J10: 0 | K10: 0 | L10: 0 | M10: 0 | N10: 0 | O10: 0 | P10: 0 | Q10: 0 | R10: 0 | S10: 0
A11: Véhicules neufs[...] | B11: Véhicules neufs | C11: [...] | D11: 0 | E11: 0 | F11: 0 | J11: 0 | K11: 0 | L11: 0 | M11: 0 | N11: 0 | O11: 0 | P11: 0 | Q11: 0 | R11: 0 | S11: 0
A12: Véhicules neufs[...] | B12: Véhicules neufs | C12: [...] | D12: 0 | E12: 0 | F12: 0 | J12: 0 | K12: 0 | L12: 0 | M12: 0 | N12: 0 | O12: 0 | P12: 0 | Q12: 0 | R12: 0 | S12: 0
A13: Véhicules neufsTotal Neufs | B13: Véhicules neufs | C13: Total Neufs | D13: 83 | E13: 2302.2676 | F13: 191088.21 | J13: 70 | K13: 1811.2079 | L13: 126784.55 | M13: -13 | N13: -64303.662 | O13: 35 | P13: 2095.4297 | Q13: 73340.04 | R13: 35 | S13: 53444.51
A14: Véhicules neufs | B14: Véhicules neufs | M14: -0.15662651 | N14: -0.33651297 | R14: 1 | S14: 0.72872213 | AD14: 20 | AE14: 1000 | AF14: 20000
A15: Véhicules neufsEx-Démos et courtoisies | B15: Véhicules neufs | C15: Ex-Démos et courtoisies | D15: 4 | E15: 1534.7521 | F15: 6139.0086 | J15: 2 | K15: 2386.71 | L15: 4773.42 | M15: -2 | N15: -1365.5886 | O15: 2 | P15: 1396.23 | Q15: 2792.46 | R15: 0 | S15: 1980.96 | AD15: 25 | AE15: 800 | AF15: 20000
A16: Véhicules neufs | B16: Véhicules neufs
A17: Véhicules neufsFlottes | B17: Véhicules neufs | C17: Flottes | D17: 2 | E17: 2393.8521 | F17: 4787.7042 | J17: 2 | K17: 3786.085 | L17: 7572.17 | M17: 0 | N17: 2784.4658 | O17: 3 | P17: 1478.8733 | Q17: 4436.62 | R17: -1 | S17: 3135.55
A18: Véhicules neufs | B18: Véhicules neufs
A19: Véhicules neufsRachat bail | B19: Véhicules neufs | C19: Rachat bail | D19: 0 | E19: 0 | F19: 9350 | L19: 10650.01 | N19: 1300.01 | Q19: 7700 | R19: 0 | S19: 2950.01
A20: Véhicules neufs | B20: Véhicules neufs
A21: Véhicules neufsRev. Finances | B21: Véhicules neufs | C21: Rev. Finances | D21: 0 | E21: 0 | F21: 4350 | K21: 0 | L21: 0 | N21: -4350 | Q21: 0 | R21: 0 | S21: 0
A22: Véhicules neufsRev. Protections | B22: Véhicules neufs | C22: Rev. Protections | D22: 0 | E22: 0 | F22: 80910 | K22: 995.15556 | L22: 71651.2 | N22: -9258.8 | Q22: 38628.6 | R22: -995.15556 | S22: 33022.6
A23: Véhicules neufsRev. Autres | B23: Véhicules neufs | C23: Rev. Autres | D23: 0 | E23: 0 | F23: 1740 | K23: 13.881806 | L23: 999.49 | N23: -740.51 | Q23: 645.16 | R23: -13.881806 | S23: 354.33
A24: Véhicules neufsTotal F&I | B24: Véhicules neufs | C24: Total F&I | D24: 87 | E24: 1000 | F24: 87000 | J24: 72 | K24: 1009.0374 | L24: 72650.69 | M24: -15 | N24: -14349.31 | O24: 37 | P24: 1061.453 | Q24: 39273.76 | S24: 33376.93
A25: Véhicules neufs | B25: Véhicules neufs | N25: -0.1649346 | S25: 0.84985318
A26: Véhicules neufs | B26: Véhicules neufs
A27: Véhicules neufsTotal Dépt. Neufs | B27: Véhicules neufs | C27: Total Dépt. Neufs | D27: 89 | E27: 3352.4149 | F27: 298364.92 | J27: 74 | K27: 3005.8222 | L27: 222430.84 | M27: -15 | N27: -75934.084 | O27: 40 | P27: 3188.572 | Q27: 127542.88 | R27: 34 | S27: 94887.96
A28: Véhicules neufs | B28: Véhicules neufs | L28: 0.74549929 | M28: -0.16853933 | N28: -0.25450071 | R28: 0.85 | S28: 0.74396909
A29: Véhicules neufs | B29: Véhicules neufs
A30: Véhicules neufsDEPENSES | B30: Véhicules neufs | C30: DEPENSES
A31: Véhicules neufsComm. vendeurs | B31: Véhicules neufs | C31: Comm. vendeurs | D31: 0.31738468 | E31: 719.50459 | F31: 62596.899 | J31: 0.26163339 | K31: 505.57069 | L31: 36401.09 | N31: -26195.809 | O31: 0.29663462 | P31: 645.93486 | Q31: 23899.59 | S31: 12501.5
A32: Véhicules neufsComm. F&I | B32: Véhicules neufs | C32: Comm. F&I | D32: 0.28 | E32: 280 | F32: 24360 | J32: 0.26999661 | K32: 272.43667 | L32: 19615.44 | N32: -4744.56 | O32: 0.27998974 | P32: 297.19595 | Q32: 10996.25 | S32: 8619.19
A33: Véhicules neufsFrais de livraison | B33: Véhicules neufs | C33: Frais de livraison | E33: 115 | F33: 10005 | K33: 73.22125 | L33: 5271.93 | N33: -4733.07 | P33: 233.92757 | Q33: 8655.32 | S33: -3383.39
A34: Véhicules neufsService gratuit 1 | B34: Véhicules neufs | C34: Service gratuit 1 | E34: 10 | F34: 870 | K34: 3.7194444 | L34: 267.8 | N34: -602.2 | P34: 108.85892 | Q34: 4027.78 | S34: -3759.98
A35: Véhicules neufsEntretien stock | B35: Véhicules neufs | C35: Entretien stock | E35: 120.75 | F35: 10505.25 | K35: 109.28875 | L35: 7868.79 | N35: -2636.46 | P35: 212.08676 | Q35: 7847.21 | S35: 21.58
A36: Véhicules neufsPublicité 1 | B36: Véhicules neufs | C36: Publicité 1 | E36: 31.747126 | F36: 2762 | K36: 53.550417 | L36: 3855.63 | N36: 1093.63 | P36: 527.05568 | Q36: 19501.06 | S36: -15645.43
A37: Véhicules neufsIntérêt de gros | B37: Véhicules neufs | C37: Intérêt de gros | E37: 402.18682 | F37: 34990.253 | K37: 337.88694 | L37: 24327.86 | N37: -10662.393 | P37: -1003.7751 | Q37: -37139.68 | S37: 61467.54
A38: Véhicules neufs[...] | B38: Véhicules neufs | C38: [...] | E38: 0 | F38: 0 | K38: 0 | L38: 0 | N38: 0 | P38: 0 | Q38: 0 | S38: 0
A39: Véhicules neufs[...] | B39: Véhicules neufs | C39: [...] | E39: 0 | F39: 0 | K39: 0 | L39: 0 | N39: 0 | P39: 0 | Q39: 0 | S39: 0
A40: Véhicules neufs[...] | B40: Véhicules neufs | C40: [...] | E40: 0 | F40: 0 | K40: 0 | L40: 0 | N40: 0 | P40: 0 | Q40: 0 | S40: 0
...

Sheet 2025-12
C1: Volks | K1: Véhicules neufs | S1: Réalisé, Décembre 2025
D2: X | E2: O | F2: U | J2: NB | L2: $ | O2: X | P2: O | Q2: U | V2: *** NE PAS EFFACER / Pour An Précédente ***
D3: BUDGET ORIGINAL | J3: RÉALISATION | M3: ÉCART réel / Budget | O3: ANNÉE PRÉCÉDENTE | R3: ECART (réel/ Ann.Préc.) | V3: NEUF | W3: 0.45
D4: UNITE | E4: $P/UNITÉ | F4: $PROFITS | J4: UNITÉS | K4: $P/UNITE | L4: $PROFITS | M4: UNITÉS | N4: $PROFITS | O4: UNITE | P4: $P/UNITÉ | Q4: $PROFITS | R4: UNITÉS | S4: $PROFITS | V4: USAGE | W4: 0.1
A5: Véhicules neufsVentes nettes | B5: Véhicules neufs | C5: Ventes nettes | F5: 2940854.1 | L5: 2445339.6 | Q5: 2168000.1 | V5: SERVICE | W5: 0.225
A6: Véhicules neufsAutos détail | B6: Véhicules neufs | C6: Autos détail | D6: 14 | E6: 1953.6492 | F6: 27351.088 | J6: 2 | K6: 3513.835 | L6: 7027.67 | M6: -12 | N6: -20323.418 | O6: 6 | P6: 1532.1433 | Q6: 9192.86 | R6: -4 | S6: -2165.19 | V6: CARROSSERIE | W6: 0.025
A7: Véhicules neufsCamions détail | B7: Véhicules neufs | C7: Camions détail | D7: 39 | E7: 2435.9047 | F7: 95000.282 | J7: 37 | K7: 1654.85 | L7: 61229.45 | M7: -2 | N7: -33770.832 | O7: 24 | P7: 1904.4017 | Q7: 45705.64 | R7: 13 | S7: 15523.81 | V7: PIECES | W7: 0.2
A8: Véhicules neufsSprinter | B8: Véhicules neufs | C8: Sprinter | D8: 0 | E8: 0 | F8: 0 | J8: 0 | K8: 0 | L8: 0 | M8: 0 | N8: 0 | O8: 0 | P8: 0 | Q8: 0 | R8: 0 | S8: 0 | W8: 1
A9: Véhicules neufsMoto détail | B9: Véhicules neufs | C9: Moto détail | D9: 0 | E9: 0 | F9: 0 | J9: 0 | K9: 0 | L9: 0 | M9: 0 | N9: 0 | O9: 0 | P9: 0 | Q9: 0 | R9: 0 | S9: 0
A10: Véhicules neufs[...] | B10: Véhicules neufs | C10: [...] | D10: 0 | E10: 0 | F10: 0 | J10: 0 | K10: 0 | L10: 0 | M10: 0 | N10: 0 | O10: 0 | P10: 0 | Q10: 0 | R10: 0 | S10: 0
A11: Véhicules neufs[...] | B11: Véhicules neufs | C11: [...] | D11: 0 | E11: 0 | F11: 0 | J11: 0 | K11: 0 | L11: 0 | M11: 0 | N11: 0 | O11: 0 | P11: 0 | Q11: 0 | R11: 0 | S11: 0
A12: Véhicules neufs[...] | B12: Véhicules neufs | C12: [...] | D12: 0 | E12: 0 | F12: 0 | J12: 0 | K12: 0 | L12: 0 | M12: 0 | N12: 0 | O12: 0 | P12: 0 | Q12: 0 | R12: 0 | S12: 0
A13: Véhicules neufsTotal Neufs | B13: Véhicules neufs | C13: Total Neufs | D13: 53 | E13: 2308.5164 | F13: 122351.37 | J13: 39 | K13: 1750.1826 | L13: 68257.12 | M13: -14 | N13: -54094.251 | O13: 30 | P13: 1829.95 | Q13: 54898.5 | R13: 9 | S13: 13358.62
A14: Véhicules neufs | B14: Véhicules neufs | M14: -0.26415094 | N14: -0.44212215 | R14: 0.3 | S14: 0.24333306 | AD14: 20 | AE14: 1000 | AF14: 20000
A15: Véhicules neufsEx-Démos et courtoisies | B15: Véhicules neufs | C15: Ex-Démos et courtoisies | D15: 3 | E15: 1534.7521 | F15: 4604.2564 | J15: 3 | K15: -676.00333 | L15: -2028.01 | M15: 0 | N15: -6632.2664 | O15: 4 | P15: 2295.8825 | Q15: 9183.53 | R15: -1 | S15: -11211.54 | AD15: 25 | AE15: 800 | AF15: 20000
A16: Véhicules neufs | B16: Véhicules neufs
A17: Véhicules neufsFlottes | B17: Véhicules neufs | C17: Flottes | D17: 1 | E17: 2393.8521 | F17: 2393.8521 | J17: 0 | K17: 0 | L17: 0 | M17: -1 | N17: -2393.8521 | O17: 6 | P17: 1073.965 | Q17: 6443.79 | R17: -6 | S17: -6443.79
A18: Véhicules neufs | B18: Véhicules neufs
A19: Véhicules neufsRachat bail | B19: Véhicules neufs | C19: Rachat bail | D19: 0 | E19: 0 | F19: 5950 | L19: 7399.84 | N19: 1449.84 | Q19: 5949 | R19: 0 | S19: 1450.84
A20: Véhicules neufs | B20: Véhicules neufs
A21: Véhicules neufsRev. Finances | B21: Véhicules neufs | C21: Rev. Finances | D21: 0 | E21: 0 | F21: 2800 | K21: 90.449048 | L21: 3798.86 | N21: 998.86 | Q21: 1288.84 | R21: -90.449048 | S21: 2510.02
A22: Véhicules neufsRev. Protections | B22: Véhicules neufs | C22: Rev. Protections | D22: 0 | E22: 0 | F22: 52080 | K22: 805.02238 | L22: 33810.94 | N22: -18269.06 | Q22: 44538.34 | R22: -805.02238 | S22: -10727.4
A23: Véhicules neufsRev. Autres | B23: Véhicules neufs | C23: Rev. Autres | D23: 0 | E23: 0 | F23: 1120 | K23: 23.329286 | L23: 979.83 | N23: -140.17 | Q23: 0 | R23: -23.329286 | S23: 979.83
A24: Véhicules neufsTotal F&I | B24: Véhicules neufs | C24: Total F&I | D24: 56 | E24: 1000 | F24: 56000 | J24: 42 | K24: 918.80071 | L24: 38589.63 | M24: -14 | N24: -17410.37 | O24: 34 | P24: 1347.8582 | Q24: 45827.18 | S24: -7237.55
A25: Véhicules neufs | B25: Véhicules neufs | N25: -0.31089946 | S25: -0.15793138
A26: Véhicules neufs | B26: Véhicules neufs
A27: Véhicules neufsTotal Dépt. Neufs | B27: Véhicules neufs | C27: Total Dépt. Neufs | D27: 57 | E27: 3356.1312 | F27: 191299.48 | J27: 42 | K27: 2671.871 | L27: 112218.58 | M27: -15 | N27: -79080.899 | O27: 40 | P27: 3057.55 | Q27: 122302 | R27: 2 | S27: -10083.42
A28: Véhicules neufs | B28: Véhicules neufs | L28: 0.58661205 | M28: -0.26315789 | N28: -0.41338795 | R28: 0.05 | S28: -0.082446894
A29: Véhicules neufs | B29: Véhicules neufs
A30: Véhicules neufsDEPENSES | B30: Véhicules neufs | C30: DEPENSES
A31: Véhicules neufsComm. vendeurs | B31: Véhicules neufs | C31: Comm. vendeurs | D31: 0.33220695 | E31: 753.13468 | F31: 42175.542 | J31: 0.42075849 | K31: 663.48714 | L31: 27866.46 | N31: -14309.082 | O31: 0.33063295 | P31: 685.82824 | Q31: 23318.16 | S31: 4548.3
A32: Véhicules neufsComm. F&I | B32: Véhicules neufs | C32: Comm. F&I | D32: 0.28 | E32: 280 | F32: 15680 | J32: 0.27000337 | K32: 248.07929 | L32: 10419.33 | N32: -5260.67 | O32: 0.30000886 | P32: 404.36941 | Q32: 13748.56 | S32: -3329.23
A33: Véhicules neufsFrais de livraison | B33: Véhicules neufs | C33: Frais de livraison | E33: 115 | F33: 6440 | K33: 106.25429 | L33: 4462.68 | N33: -1977.32 | P33: 76.159118 | Q33: 2589.41 | S33: 1873.27
A34: Véhicules neufsService gratuit 1 | B34: Véhicules neufs | C34: Service gratuit 1 | E34: 10 | F34: 560 | K34: 1.8809524 | L34: 79 | N34: -481 | P34: 26.280588 | Q34: 893.54 | S34: -814.54
A35: Véhicules neufsEntretien stock | B35: Véhicules neufs | C35: Entretien stock | E35: 120.75 | F35: 6762 | K35: 168.06286 | L35: 7058.64 | N35: 296.64 | P35: 99.538529 | Q35: 3384.31 | S35: 3674.33
A36: Véhicules neufsPublicité 1 | B36: Véhicules neufs | C36: Publicité 1 | E36: 104.67857 | F36: 5862 | K36: 277.25952 | L36: 11644.9 | N36: 5782.9 | P36: 316.01029 | Q36: 10744.35 | S36: 900.55
A37: Véhicules neufsIntérêt de gros | B37: Véhicules neufs | C37: Intérêt de gros | E37: 624.61342 | F37: 34978.352 | K37: 450.03214 | L37: 18901.35 | N37: -16077.002 | P37: -106.62588 | Q37: -3625.28 | S37: 22526.63
A38: Véhicules neufs[...] | B38: Véhicules neufs | C38: [...] | E38: 0 | F38: 0 | K38: 0 | L38: 0 | N38: 0 | P38: 0 | Q38: 0 | S38: 0
A39: Véhicules neufs[...] | B39: Véhicules neufs | C39: [...] | E39: 0 | F39: 0 | K39: 0 | L39: 0 | N39: 0 | P39: 0 | Q39: 0 | S39: 0
A40: Véhicules neufs[...] | B40: Véhicules neufs | C40: [...] | E40: 0 | F40: 0 | K40: 0 | L40: 0 | N40: 0 | P40: 0 | Q40: 0 | S40: 0
...

Sheet END
