Workbook
Name _Dates_Conc: [1]Dealers!$BF$37:$KA$63
Name _scen: '[1]Scen & Sens'!$E$26
Name _scen1: '[1]Scen & Sens'!$E$27
Name _scen2: '[1]Scen & Sens'!$E$28
Name _SCenarios: '[1]Scen & Sens'!$J$26:$O$26
Name _Sens1: '[1]Scen & Sens'!$F$9
Name _Sens2: '[1]Scen & Sens'!$F$10
Name _sensRes1: '[1]Scen & Sens'!$E$15
Name _sensRes2: '[1]Scen & Sens'!$E$16
Name _sensRes3: '[1]Scen & Sens'!$E$17
Name _sensRes4: '[1]Scen & Sens'!$E$18
Name _sensRes5: '[1]Scen & Sens'!$E$19
Name _sensRes6: '[1]Scen & Sens'!$E$20
Name _sensRes7: '[1]Scen & Sens'!$E$21
Name DateRange: [1]Volkswagen!$BF$6:$DY$6
Name Monetary_Unit: [1]Parameters!$B$15
Name Months: [1]Parameters!$E$9:$E$20
Name Rng_Dealers_Names: [1]!Tbl_Dealers[Dealer Name]
Name Rng_Dlr_Dates: [1]!Tbl_V_Dlr_Dates[Date]
Name Ticker: #REF!
Name Ticker: #REF!
Name Ticker: #REF!
Name Titre: [1]Front!$A$9

Sheet Paramètre
B3: Quarter
B6: BUDGET | F6: BUDGET RÉVISÉ | J6: ACTUAL | N6: LAST YEAR
B7: Ventes | C7: Profits bruts | D7: BAIIA | E7: EBIT | F7: Ventes | G7: Profits bruts | H7: BAIIA | I7: EBIT | J7: Ventes | K7: Profits bruts | L7: BAIIA | M7: EBIT | N7: Ventes | O7: Profits bruts | P7: BAIIA | Q7: EBIT
A8: CTRL | B8: =+B9-B10 -> #REF! | C8: =+C9-C10 -> #REF! | D8: =+D9-D10 -> #REF! | E8: =+E9-E10 -> #REF! | F8: =+F9-F10 -> #REF! | G8: =+G9-G10 -> #REF! | H8: =+H9-H10 -> #REF! | I8: =+I9-I10 -> #REF! | ... Q8: =+Q9-Q10 -> #REF!
A9: CONSO | B9: =+Conso!$Z$405 -> 18083868 | C9: =+Conso!$Z$406 -> 2262964.7 | D9: =+Conso!$Z$482 -> 548567.16 | E9: =+Conso!$Z$497 -> 423860.66 | F9: =+Conso!$AC$405 -> 0 | G9: =+Conso!$AC$406 -> 0 | H9: =+Conso!$AC$482 -> 0 | I9: =+Conso!$AC$497 -> 0 | J9: =+Conso!$AF$405 -> 14843581 | K9: =+Conso!$AF$406 -> 2095633.8 | L9: =+Conso!$AF$482 -> 482154.45 | M9: =+Conso!$AF$497 -> 357447.45 | N9: =+Conso!$AL$405 -> 16428062 | O9: =+Conso!$AL$406 -> 1897181 | P9: =+Conso!$AL$482 -> 366005.68 | Q9: =+Conso!$AL$497 -> 361195.19
A10: TOTAL | B10: =+SUM(B11:B13) -> #REF! | C10: =+SUM(C11:C13) -> #REF! | D10: =+SUM(D11:D13) -> #REF! | E10: =+SUM(E11:E13) -> #REF! | F10: =+SUM(F11:F13) -> #REF! | G10: =+SUM(G11:G13) -> #REF! | H10: =+SUM(H11:H13) -> #REF! | I10: =+SUM(I11:I13) -> #REF! | ... Q10: =+SUM(Q11:Q13) -> #REF!
A11: Mois 1 | B11: =+#REF! -> #REF! | C11: =+#REF! -> #REF! | D11: =+#REF! -> #REF! | E11: =+#REF! -> #REF! | F11: =+#REF! -> #REF! | G11: =+#REF! -> #REF! | H11: =+#REF! -> #REF! | I11: =+#REF! -> #REF! | ... Q11: =+#REF! -> #REF!
A12: Mois 2 | B12: =+#REF! -> #REF! | C12: =+#REF! -> #REF! | D12: =+#REF! -> #REF! | E12: =+#REF! -> #REF! | F12: =+#REF! -> #REF! | G12: =+#REF! -> #REF! | H12: =+#REF! -> #REF! | I12: =+#REF! -> #REF! | ... Q12: =+#REF! -> #REF!
A13: Mois 3 | B13: =+#REF! -> #REF! | C13: =+#REF! -> #REF! | D13: =+#REF! -> #REF! | E13: =+#REF! -> #REF! | F13: =+#REF! -> #REF! | G13: =+#REF! -> #REF! | H13: =+#REF! -> #REF! | I13: =+#REF! -> #REF! | ... Q13: =+#REF! -> #REF!

Sheet Conso
C1: Conso | K1: Véhicules neufs | S1: =CONCATENATE("Réalisé"," ",Paramètre!$C$2," ",Paramètre!$C$3) -> Réalisé
D2: X | E2: O | F2: U | G2: X | H2: O | I2: U
D3: BUDGET ORIGINAL | G3: BUDGET REVISE | J3: RÉALISATION | M3: ÉCART réel / original | O3: ANNÉE PRÉCÉDENTE | R3: ÉCART réel / année précédente
D4: UNITE | E4: $P/UNITÉ | F4: $PROFITS | G4: UNITE | H4: $P/UNITÉ | I4: $PROFITS | J4: UNITE | K4: $P/UNITE | L4: $PROFITS | M4: UNITÉ | N4: $PROFITS | O4: UNITE | P4: $P/UNITE | Q4: $PROFITS | R4: UNITE | S4: $PROFITS
A5: =+B5&C5 -> Véhicules neufsVentes nettes | B5: =+$K$1 -> Véhicules neufs | C5: Ventes nettes | F5: =+SUM(START:END!F5) -> 10167353 | I5: =+SUM(START:END!I5) -> 0 | L5: =+SUM(START:END!L5) -> 8306066.7 | Q5: =+SUM(START:END!Q5) -> 9890070
A6: =+B6&C6 -> Véhicules neufsAutos détail | B6: =+$K$1 -> Véhicules neufs | C6: Autos détail | D6: =+SUM(START:END!D6) -> 50 | E6: =IF(D6=0,0,F6/D6) -> 1953.6492 | F6: =+SUM(START:END!F6) -> 97682.458 | G6: =+SUM(START:END!G6) -> 0 | H6: =IF(G6=0,0,I6/G6) -> 0 | I6: =+SUM(START:END!I6) -> 0 | J6: =+SUM(START:END!J6) -> 46 | K6: =IF(J6=0,0,L6/J6) -> 2161.2191 | L6: =+SUM(START:END!L6) -> 99416.08 | M6: =J6-D6 -> -4 | N6: =L6-F6 -> 1733.6216 | O6: =+SUM(START:END!O6) -> 51 | P6: =IF(O6=0,0,Q6/O6) -> 1956.158 | Q6: =+SUM(START:END!Q6) -> 99764.06 | R6: =J6-O6 -> -5 | S6: =L6-Q6 -> -347.98
A7: =+B7&C7 -> Véhicules neufsCamions détail | B7: =+$K$1 -> Véhicules neufs | C7: Camions détail | D7: =+SUM(START:END!D7) -> 135 | E7: =IF(D7=0,0,F7/D7) -> 2435.9047 | F7: =+SUM(START:END!F7) -> 328847.13 | G7: =+SUM(START:END!G7) -> 0 | H7: =IF(G7=0,0,I7/G7) -> 0 | I7: =+SUM(START:END!I7) -> 0 | J7: =+SUM(START:END!J7) -> 103 | K7: =IF(J7=0,0,L7/J7) -> 2274.877 | L7: =+SUM(START:END!L7) -> 234312.33 | M7: =J7-D7 -> -32 | N7: =L7-F7 -> -94534.801 | O7: =+SUM(START:END!O7) -> 127 | P7: =IF(O7=0,0,Q7/O7) -> 2623.2423 | Q7: =+SUM(START:END!Q7) -> 333151.77 | R7: =J7-O7 -> -24 | S7: =L7-Q7 -> -98839.44
A8: =+B8&C8 -> Véhicules neufsSprinter | B8: =+$K$1 -> Véhicules neufs | C8: Sprinter | D8: =+SUM(START:END!D8) -> 0 | E8: =IF(D8=0,0,F8/D8) -> 0 | F8: =+SUM(START:END!F8) -> 0 | G8: =+SUM(START:END!G8) -> 0 | H8: =IF(G8=0,0,I8/G8) -> 0 | I8: =+SUM(START:END!I8) -> 0 | J8: =+SUM(START:END!J8) -> 0 | K8: =IF(J8=0,0,L8/J8) -> 0 | L8: =+SUM(START:END!L8) -> 0 | M8: =J8-D8 -> 0 | N8: =L8-F8 -> 0 | O8: =+SUM(START:END!O8) -> 0 | P8: =IF(O8=0,0,Q8/O8) -> 0 | Q8: =+SUM(START:END!Q8) -> 0 | R8: =J8-O8 -> 0 | S8: =L8-Q8 -> 0
A9: =+B9&C9 -> Véhicules neufsMoto détail | B9: =+$K$1 -> Véhicules neufs | C9: Moto détail | D9: =+SUM(START:END!D9) -> 0 | E9: =IF(D9=0,0,F9/D9) -> 0 | F9: =+SUM(START:END!F9) -> 0 | G9: =+SUM(START:END!G9) -> 0 | H9: =IF(G9=0,0,I9/G9) -> 0 | I9: =+SUM(START:END!I9) -> 0 | J9: =+SUM(START:END!J9) -> 0 | K9: =IF(J9=0,0,L9/J9) -> 0 | L9: =+SUM(START:END!L9) -> 0 | M9: =J9-D9 -> 0 | N9: =L9-F9 -> 0 | O9: =+SUM(START:END!O9) -> 0 | P9: =IF(O9=0,0,Q9/O9) -> 0 | Q9: =+SUM(START:END!Q9) -> 0 | R9: =J9-O9 -> 0 | S9: =L9-Q9 -> 0
A10: =+B10&C10 -> Véhicules neufs[...] | B10: =+$K$1 -> Véhicules neufs | C10: [...] | D10: =+SUM(START:END!D10) -> 0 | E10: =IF(D10=0,0,F10/D10) -> 0 | F10: =+SUM(START:END!F10) -> 0 | G10: =+SUM(START:END!G10) -> 0 | H10: =IF(G10=0,0,I10/G10) -> 0 | I10: =+SUM(START:END!I10) -> 0 | J10: =+SUM(START:END!J10) -> 0 | K10: =IF(J10=0,0,L10/J10) -> 0 | L10: =+SUM(START:END!L10) -> 0 | M10: =J10-G10 -> 0 | N10: =L10-I10 -> 0 | O10: =+SUM(START:END!O10) -> 0 | P10: =IF(O10=0,0,Q10/O10) -> 0 | Q10: =+SUM(START:END!Q10) -> 0 | R10: =J10-O10 -> 0 | S10: =L10-Q10 -> 0
A11: =+B11&C11 -> Véhicules neufs[...] | B11: =+$K$1 -> Véhicules neufs | C11: [...] | D11: =+SUM(START:END!D11) -> 0 | E11: =IF(D11=0,0,F11/D11) -> 0 | F11: =+SUM(START:END!F11) -> 0 | G11: =+SUM(START:END!G11) -> 0 | H11: =IF(G11=0,0,I11/G11) -> 0 | I11: =+SUM(START:END!I11) -> 0 | J11: =+SUM(START:END!J11) -> 0 | K11: =IF(J11=0,0,L11/J11) -> 0 | L11: =+SUM(START:END!L11) -> 0 | M11: =J11-G11 -> 0 | N11: =L11-I11 -> 0 | O11: =+SUM(START:END!O11) -> 0 | P11: =IF(O11=0,0,Q11/O11) -> 0 | Q11: =+SUM(START:END!Q11) -> 0 | R11: =J11-O11 -> 0 | S11: =L11-Q11 -> 0
A12: =+B12&C12 -> Véhicules neufs[...] | B12: =+$K$1 -> Véhicules neufs | C12: [...] | D12: =+SUM(START:END!D12) -> 0 | E12: =IF(D12=0,0,F12/D12) -> 0 | F12: =+SUM(START:END!F12) -> 0 | G12: =+SUM(START:END!G12) -> 0 | H12: =IF(G12=0,0,I12/G12) -> 0 | I12: =+SUM(START:END!I12) -> 0 | J12: =+SUM(START:END!J12) -> 0 | K12: =IF(J12=0,0,L12/J12) -> 0 | L12: =+SUM(START:END!L12) -> 0 | M12: =J12-G12 -> 0 | N12: =L12-I12 -> 0 | O12: =+SUM(START:END!O12) -> 0 | P12: =IF(O12=0,0,Q12/O12) -> 0 | Q12: =+SUM(START:END!Q12) -> 0 | R12: =J12-O12 -> 0 | S12: =L12-Q12 -> 0
A13: =+B13&C13 -> Véhicules neufsTotal Neufs | B13: =+$K$1 -> Véhicules neufs | C13: Total Neufs | D13: =+SUM(D6:D12) -> 185 | E13: =IF(D13<=0,0,F13/D13) -> 2305.5654 | F13: =+SUM(F6:F12) -> 426529.59 | G13: =+SUM(G6:G12) -> 0 | H13: =IF(G13<=0,0,I13/G13) -> 0 | I13: =+SUM(I6:I12) -> 0 | J13: =+SUM(J6:J12) -> 149 | K13: =IF(J13<=0,0,L13/J13) -> 2239.788 | L13: =+SUM(L6:L12) -> 333728.41 | M13: =+SUM(M6:M12) -> -36 | N13: =+SUM(N6:N12) -> -92801.18 | O13: =+SUM(O6:O12) -> 178 | P13: =IF(O13<=0,0,Q13/O13) -> 2432.1114 | Q13: =+SUM(Q6:Q12) -> 432915.83 | R13: =+SUM(R6:R12) -> -29 | S13: =+SUM(S6:S12) -> -99187.42
A14: =+B14&C14 -> Véhicules neufs | B14: =+$K$1 -> Véhicules neufs | N14: =IF(F13=0,0,N13/F13) -> -0.21757267 | R14: =R13/O13 -> -0.16292135 | S14: =IF(Q13=0,0,(S13/Q13)) -> -0.22911479
A15: =+B15&C15 -> Véhicules neufsEx-Démos et courtoisies | B15: =+$K$1 -> Véhicules neufs | C15: Ex-Démos et courtoisies | D15: =+SUM(START:END!D15) -> 9 | E15: =IF(D15=0,0,F15/D15) -> 1534.7521 | F15: =+SUM(START:END!F15) -> 13812.769 | G15: =+SUM(START:END!G15) -> 0 | H15: =IF(G15=0,0,I15/G15) -> 0 | I15: =+SUM(START:END!I15) -> 0 | J15: =+SUM(START:END!J15) -> 13 | K15: =IF(J15=0,0,L15/J15) -> 1451.6415 | L15: =+SUM(START:END!L15) -> 18871.34 | M15: =J15-D15 -> 4 | N15: =L15-F15 -> 5058.5707 | O15: =+SUM(START:END!O15) -> 9 | P15: =IF(O15=0,0,Q15/O15) -> 1653.9344 | Q15: =+SUM(START:END!Q15) -> 14885.41 | R15: =J15-O15 -> 4 | S15: =L15-Q15 -> 3985.93
A16: =+B16&C16 -> Véhicules neufs | B16: =+$K$1 -> Véhicules neufs
A17: =+B17&C17 -> Véhicules neufsFlottes | B17: =+$K$1 -> Véhicules neufs | C17: Flottes | D17: =+SUM(START:END!D17) -> 6 | E17: =IF(D17=0,0,F17/D17) -> 2393.8521 | F17: =+SUM(START:END!F17) -> 14363.113 | G17: =+SUM(START:END!G17) -> 0 | H17: =IF(G17=0,0,I17/G17) -> 0 | I17: =+SUM(START:END!I17) -> 0 | J17: =+SUM(START:END!J17) -> 0 | K17: =IF(J17=0,0,L17/J17) -> 0 | L17: =+SUM(START:END!L17) -> 0 | M17: =J17-D17 -> -6 | N17: =L17-F17 -> -14363.113 | O17: =+SUM(START:END!O17) -> 0 | P17: =IF(O17=0,0,Q17/O17) -> 0 | Q17: =+SUM(START:END!Q17) -> 0 | R17: =J17-O17 -> 0 | S17: =L17-Q17 -> 0
A18: =+B18&C18 -> Véhicules neufs | B18: =+$K$1 -> Véhicules neufs
A19: =+B19&C19 -> Véhicules neufsRachat bail | B19: =+$K$1 -> Véhicules neufs | C19: Rachat bail | F19: =+SUM(START:END!F19) -> 20570 | I19: =+SUM(START:END!I19) -> 0 | L19: =+SUM(START:END!L19) -> 23810.21 | N19: =L19-F19 -> 3240.21 | Q19: =+SUM(START:END!Q19) -> 22060.37 | R19: =O19-K19 -> 0 | S19: =L19-Q19 -> 1749.84
A20: =+B20&C20 -> Véhicules neufs | B20: =+$K$1 -> Véhicules neufs
A21: =+B21&C21 -> Véhicules neufsRev. Finances | B21: =+$K$1 -> Véhicules neufs | C21: Rev. Finances | D21: 0 | E21: =IF(D21=0,0,F21/D21) -> 0 | F21: =+SUM(START:END!F21) -> 9700 | G21: 0 | H21: =IF(G21=0,0,I21/G21) -> 0 | I21: =+SUM(START:END!I21) -> 0 | K21: =IF(J13=0,0,L21/(J13+J15)) -> 8.1129012 | L21: =+SUM(START:END!L21) -> 1314.29 | N21: =L21-F21 -> -8385.71 | P21: =IF(O13=0,0,Q21/(O13+O15)) -> 4.2780749 | Q21: =+SUM(START:END!Q21) -> 800 | R21: =O21-K21 -> -8.1129012 | S21: =L21-Q21 -> 514.29
A22: =+B22&C22 -> Véhicules neufsRev. Protections | B22: =+$K$1 -> Véhicules neufs | C22: Rev. Protections | D22: 0 | E22: =IF(D22=0,0,F22/D22) -> 0 | F22: =+SUM(START:END!F22) -> 180420 | G22: 0 | H22: =IF(G22=0,0,I22/G22) -> 0 | I22: =+SUM(START:END!I22) -> 0 | K22: =IF(J13=0,0,L22/(J13+J15)) -> 1014.0912 | L22: =+SUM(START:END!L22) -> 164282.77 | N22: =L22-F22 -> -16137.23 | P22: =IF(O13=0,0,Q22/(O13+O15)) -> 777.99171 | Q22: =+SUM(START:END!Q22) -> 145484.45 | R22: =O22-K22 -> -1014.0912 | S22: =L22-Q22 -> 18798.32
A23: =+B23&C23 -> Véhicules neufsRev. Autres | B23: =+$K$1 -> Véhicules neufs | C23: Rev. Autres | D23: 0 | E23: =IF(D23=0,0,F23/D23) -> 0 | F23: =+SUM(START:END!F23) -> 3880 | G23: 0 | H23: =IF(G23=0,0,I23/G23) -> 0 | I23: =+SUM(START:END!I23) -> 0 | K23: =IF(J13=0,0,L23/(J13+J15)) -> 1.6458642 | L23: =+SUM(START:END!L23) -> 266.63 | N23: =L23-F23 -> -3613.37 | P23: =IF(O13=0,0,Q23/(O13+O15)) -> 21.696417 | Q23: =+SUM(START:END!Q23) -> 4057.23 | R23: =O23-K23 -> -1.6458642 | S23: =L23-Q23 -> -3790.6
A24: =+B24&C24 -> Véhicules neufsTotal F&I | B24: =+$K$1 -> Véhicules neufs | C24: Total F&I | D24: =+D15+D13 -> 194 | E24: =IF(D24<=0,0,F24/D24) -> 1000 | F24: =F21+F22+F23 -> 194000 | G24: =+G15+G13 -> 0 | H24: =IF(G24<=0,0,I24/G24) -> 0 | I24: =I21+I22+I23 -> 0 | J24: =+J15+J13 -> 162 | K24: =IF(J24<=0,0,L24/J24) -> 1023.8499 | L24: =L21+L22+L23 -> 165863.69 | M24: =+M15+M13 -> -32 | N24: =N21+N22+N23 -> -28136.31 | O24: =+O15+O13 -> 187 | P24: =IF(O24<=0,0,Q24/O24) -> 803.9662 | Q24: =Q21+Q22+Q23 -> 150341.68 | S24: =L24-Q24 -> 15522.01
A25: =+B25&C25 -> Véhicules neufs | B25: =+$K$1 -> Véhicules neufs | S25: =IF(Q24=0,0,(S24/Q24)) -> 0.10324489
A26: =+B26&C26 -> Véhicules neufs | B26: =+$K$1 -> Véhicules neufs
A27: =+B27&C27 -> Véhicules neufsTotal Dépt. Neufs | B27: =+$K$1 -> Véhicules neufs | C27: Total Dépt. Neufs | D27: =+D13+D15+D17 -> 200 | E27: =IF(D27<=0,0,F27/D27) -> 3346.3774 | F27: =F13+F17+F24+F19+F15 -> 669275.47 | G27: =+G13+G15+G17 -> 0 | H27: =IF(G27<=0,0,I27/G27) -> 0 | I27: =I13+I17+I24+I19+I15 -> 0 | J27: =+J13+J15+J17 -> 162 | K27: =IF(J27<=0,0,L27/J27) -> 3347.3682 | L27: =L13+L17+L24+L19+L15 -> 542273.65 | M27: =+M13+M15+M17 -> -38 | N27: =N13+N17+N24+N19+N15 -> -127001.82 | O27: =+O13+O15+O17 -> 187 | P27: =IF(O27<=0,0,Q27/O27) -> 3316.5951 | Q27: =Q13+Q17+Q24+Q19+Q15 -> 620203.29 | R27: =J27-O27 -> -25 | S27: =L27-Q27 -> -77929.64
A28: =+B28&C28 -> Véhicules neufs | B28: =+$K$1 -> Véhicules neufs | M28: =M27/D27 -> -0.19 | N28: =N27/F27 -> -0.18976016 | R28: =R27/O27 -> -0.13368984 | S28: =IF(Q27=0,0,S27/Q27) -> -0.12565177
A29: =+B29&C29 -> Véhicules neufs | B29: =+$K$1 -> Véhicules neufs
A30: =+B30&C30 -> Véhicules neufsDEPENSES | B30: =+$K$1 -> Véhicules neufs | C30: DEPENSES
A31: =+B31&C31 -> Véhicules neufsComm. vendeurs | B31: =+$K$1 -> Véhicules neufs | C31: Comm. vendeurs | E31: =F31/D$24 -> 755.06949 | F31: =+SUM(START:END!F31) -> 146483.48 | H31: =I31/G$24 -> #DIV/0! | I31: =+SUM(START:END!I31) -> 0 | J31: =L31/L13 -> 0.34752193 | K31: =IF(L31=0,0,L31/J$24) -> 715.91321 | L31: =+SUM(START:END!L31) -> 115977.94 | N31: =L31-F31 -> -30505.541 | P31: =IF(Q31=0,0,Q31/O$24) -> 584.55818 | Q31: =+SUM(START:END!Q31) -> 109312.38 | S31: =L31-Q31 -> 6665.56
A32: =+B32&C32 -> Véhicules neufsComm. F&I | B32: =+$K$1 -> Véhicules neufs | C32: Comm. F&I | E32: =F32/D$24 -> 280 | F32: =+SUM(START:END!F32) -> 54320 | H32: =I32/G$24 -> #DIV/0! | I32: =+SUM(START:END!I32) -> 0 | J32: =L32/L24 -> 0.26720592 | K32: =IF(L32=0,0,L32/J$24) -> 273.57877 | L32: =+SUM(START:END!L32) -> 44319.76 | N32: =L32-F32 -> -10000.24 | P32: =IF(Q32=0,0,Q32/O$24) -> 186.83203 | Q32: =+SUM(START:END!Q32) -> 34937.59 | S32: =L32-Q32 -> 9382.17
A33: =+B33&C33 -> Véhicules neufsFrais de livraison | B33: =+$K$1 -> Véhicules neufs | C33: Frais de livraison | E33: =F33/D$24 -> 115 | F33: =+SUM(START:END!F33) -> 22310 | H33: =I33/G$24 -> #DIV/0! | I33: =+SUM(START:END!I33) -> 0 | K33: =IF(L33=0,0,L33/J$24) -> 140.65593 | L33: =+SUM(START:END!L33) -> 22786.26 | N33: =L33-F33 -> 476.26 | P33: =IF(Q33=0,0,Q33/O$24) -> 108.74684 | Q33: =+SUM(START:END!Q33) -> 20335.66 | S33: =L33-Q33 -> 2450.6
A34: =+B34&C34 -> Véhicules neufsService gratuit 1 | B34: =+$K$1 -> Véhicules neufs | C34: Service gratuit 1 | E34: =F34/D$24 -> 10 | F34: =+SUM(START:END!F34) -> 1940 | H34: =I34/G$24 -> #DIV/0! | I34: =+SUM(START:END!I34) -> 0 | K34: =IF(L34=0,0,L34/J$24) -> 3.7731481 | L34: =+SUM(START:END!L34) -> 611.25 | N34: =L34-F34 -> -1328.75 | P34: =IF(Q34=0,0,Q34/O$24) -> 6.8069519 | Q34: =+SUM(START:END!Q34) -> 1272.9 | S34: =L34-Q34 -> -661.65
A35: =+B35&C35 -> Véhicules neufsEntretien stock | B35: =+$K$1 -> Véhicules neufs | C35: Entretien stock | E35: =F35/D$24 -> 120.75 | F35: =+SUM(START:END!F35) -> 23425.5 | H35: =I35/G$24 -> #DIV/0! | I35: =+SUM(START:END!I35) -> 0 | K35: =IF(L35=0,0,L35/J$24) -> 156.02105 | L35: =+SUM(START:END!L35) -> 25275.41 | N35: =L35-F35 -> 1849.91 | P35: =IF(Q35=0,0,Q35/O$24) -> 156.67278 | Q35: =+SUM(START:END!Q35) -> 29297.81 | S35: =L35-Q35 -> -4022.4
A36: =+B36&C36 -> Véhicules neufsPublicité 1 | B36: =+$K$1 -> Véhicules neufs | C36: Publicité 1 | E36: =F36/D$24 -> 77.247423 | F36: =+SUM(START:END!F36) -> 14986 | H36: =I36/G$24 -> #DIV/0! | I36: =+SUM(START:END!I36) -> 0 | K36: =IF(L36=0,0,L36/J$24) -> 179.76198 | L36: =+SUM(START:END!L36) -> 29121.44 | N36: =L36-F36 -> 14135.44 | P36: =IF(Q36=0,0,Q36/O$24) -> 173.37182 | Q36: =+SUM(START:END!Q36) -> 32420.53 | S36: =L36-Q36 -> -3299.09
A37: =+B37&C37 -> Véhicules neufsIntérêt de gros | B37: =+$K$1 -> Véhicules neufs | C37: Intérêt de gros | E37: =F37/D$24 -> 579.73542 | F37: =+SUM(START:END!F37) -> 112468.67 | H37: =I37/G$24 -> #DIV/0! | I37: =+SUM(START:END!I37) -> 0 | K37: =IF(L37=0,0,L37/J$24) -> 130.63019 | L37: =+SUM(START:END!L37) -> 21162.09 | N37: =L37-F37 -> -91306.581 | P37: =IF(Q37=0,0,Q37/O$24) -> 654.65048 | Q37: =+SUM(START:END!Q37) -> 122419.64 | S37: =L37-Q37 -> -101257.55
A38: =+B38&C38 -> Véhicules neufs[...] | B38: =+$K$1 -> Véhicules neufs | C38: [...] | E38: =F38/D$24 -> 0 | F38: =+SUM(START:END!F38) -> 0 | H38: =I38/G$24 -> #DIV/0! | I38: =+SUM(START:END!I38) -> 0 | K38: =IF(L38=0,0,L38/J$24) -> 0 | L38: =+SUM(START:END!L38) -> 0 | N38: =L38-I38 -> 0 | P38: =IF(Q38=0,0,Q38/O$24) -> 0 | Q38: =+SUM(START:END!Q38) -> 0 | S38: =L38-Q38 -> 0
A39: =+B39&C39 -> Véhicules neufs[...] | B39: =+$K$1 -> Véhicules neufs | C39: [...] | E39: =F39/D$24 -> 0 | F39: =+SUM(START:END!F39) -> 0 | H39: =I39/G$24 -> #DIV/0! | I39: =+SUM(START:END!I39) -> 0 | K39: =IF(L39=0,0,L39/J$24) -> 0 | L39: =+SUM(START:END!L39) -> 0 | N39: =L39-I39 -> 0 | P39: =IF(Q39=0,0,Q39/O$24) -> 0 | Q39: =+SUM(START:END!Q39) -> 0 | S39: =L39-Q39 -> 0
A40: =+B40&C40 -> Véhicules neufs[...] | B40: =+$K$1 -> Véhicules neufs | C40: [...] | E40: =F40/D$24 -> 0 | F40: =+SUM(START:END!F40) -> 0 | H40: =I40/G$24 -> #DIV/0! | I40: =+SUM(START:END!I40) -> 0 | K40: =IF(L40=0,0,L40/J$24) -> 0 | L40: =+SUM(START:END!L40) -> 0 | N40: =L40-I40 -> 0 | P40: =IF(Q40=0,0,Q40/O$24) -> 0 | Q40: =+SUM(START:END!Q40) -> 0 | S40: =L40-Q40 -> 0
...

Sheet START

Sheet Avril 2025
C1: Volks | K1: Véhicules neufs | S1: Réalisé, Avril 2025
D2: X | E2: O | F2: U | J2: NB | L2: $ | O2: X | P2: O | Q2: U | V2: *** NE PAS EFFACER / Pour An Précédente ***
D3: BUDGET ORIGINAL | J3: RÉALISATION | M3: ÉCART réel / Budget | O3: ANNÉE PRÉCÉDENTE | R3: ECART (réel/ Ann.Préc.) | V3: NEUF | W3: 0.45
D4: UNITE | E4: $P/UNITÉ | F4: $PROFITS | J4: UNITÉS | K4: $P/UNITE | L4: $PROFITS | M4: UNITÉS | N4: $PROFITS | O4: UNITE | P4: $P/UNITÉ | Q4: $PROFITS | R4: UNITÉS | S4: $PROFITS | V4: USAGE | W4: 0.1
A5: Véhicules neufsVentes nettes | B5: Véhicules neufs | C5: Ventes nettes | F5: 3150915.1 | L5: 2860821 | Q5: 3890022.9 | V5: SERVICE | W5: 0.225
A6: Véhicules neufsAutos détail | B6: Véhicules neufs | C6: Autos détail | D6: 15 | E6: 1953.6492 | F6: 29304.738 | J6: 24 | K6: 1996.3658 | L6: 47912.78 | M6: 9 | N6: 18608.042 | O6: 18 | P6: 2168.0939 | Q6: 39025.69 | R6: 6 | S6: 8887.09 | V6: CARROSSERIE | W6: 0.025
A7: Véhicules neufsCamions détail | B7: Véhicules neufs | C7: Camions détail | D7: 42 | E7: 2435.9047 | F7: 102308 | J7: 32 | K7: 2603.3338 | L7: 83306.68 | M7: -10 | N7: -19001.316 | O7: 51 | P7: 2906.2869 | Q7: 148220.63 | R7: -19 | S7: -64913.95 | V7: PIECES | W7: 0.2
A8: Véhicules neufsSprinter | B8: Véhicules neufs | C8: Sprinter | D8: 0 | E8: 0 | F8: 0 | J8: 0 | K8: 0 | L8: 0 | M8: 0 | N8: 0 | O8: 0 | P8: 0 | Q8: 0 | R8: 0 | S8: 0 | W8: 1
A9: Véhicules neufsMoto détail | B9: Véhicules neufs | C9: Moto détail | D9: 0 | E9: 0 | F9: 0 | J9: 0 | K9: 0 | L9: 0 | M9: 0 | N9: 0 | O9: 0 | P9: 0 | Q9: 0 | R9: 0 | S9: 0
A10: Véhicules neufs[...] | B10: Véhicules neufs | C10: [...] | D10: 0 | E10: 0 | F10: 0 | J10: 0 | K10: 0 | L10: 0 | M10: 0 | N10: 0 | O10: 0 | P10: 0 | Q10: 0 | R10: 0 | S10: 0
A11: Véhicules neufs[...] | B11: Véhicules neufs | C11: [...] | D11: 0 | E11: 0 | F11: 0 | J11: 0 | K11: 0 | L11: 0 | M11: 0 | N11: 0 | O11: 0 | P11: 0 | Q11: 0 | R11: 0 | S11: 0
A12: Véhicules neufs[...] | B12: Véhicules neufs | C12: [...] | D12: 0 | E12: 0 | F12: 0 | J12: 0 | K12: 0 | L12: 0 | M12: 0 | N12: 0 | O12: 0 | P12: 0 | Q12: 0 | R12: 0 | S12: 0
A13: Véhicules neufsTotal Neufs | B13: Véhicules neufs | C13: Total Neufs | D13: 57 | E13: 2308.9953 | F13: 131612.73 | J13: 56 | K13: 2343.2046 | L13: 131219.46 | M13: -1 | N13: -393.27398 | O13: 69 | P13: 2713.7148 | Q13: 187246.32 | R13: -13 | S13: -56026.86
A14: Véhicules neufs | B14: Véhicules neufs | M14: -0.01754386 | N14: -0.002988115 | R14: -0.1884058 | S14: -0.29921475 | AD14: 20 | AE14: 1000 | AF14: 20000
A15: Véhicules neufsEx-Démos et courtoisies | B15: Véhicules neufs | C15: Ex-Démos et courtoisies | D15: 3 | E15: 1534.7521 | F15: 4604.2564 | J15: 2 | K15: 495.505 | L15: 991.01 | M15: -1 | N15: -3613.2464 | O15: 4 | P15: 2264.375 | Q15: 9057.5 | R15: -2 | S15: -8066.49 | AD15: 25 | AE15: 800 | AF15: 20000
A16: Véhicules neufs | B16: Véhicules neufs
A17: Véhicules neufsFlottes | B17: Véhicules neufs | C17: Flottes | D17: 2 | E17: 2393.8521 | F17: 4787.7042 | J17: 0 | K17: 0 | L17: 0 | M17: -2 | N17: -4787.7042 | O17: 0 | P17: 0 | Q17: 0 | R17: 0 | S17: 0
A18: Véhicules neufs | B18: Véhicules neufs
A19: Véhicules neufsRachat bail | B19: Véhicules neufs | C19: Rachat bail | D19: 0 | E19: 0 | F19: 6375 | L19: 5903.29 | N19: -471.71 | Q19: 6030.37 | R19: 0 | S19: -127.08
A20: Véhicules neufs | B20: Véhicules neufs
A21: Véhicules neufsRev. Finances | B21: Véhicules neufs | C21: Rev. Finances | D21: 0 | E21: 0 | F21: 3000 | K21: 0 | L21: 0 | N21: -3000 | Q21: 0 | R21: 0 | S21: 0
A22: Véhicules neufsRev. Protections | B22: Véhicules neufs | C22: Rev. Protections | D22: 0 | E22: 0 | F22: 55800 | K22: 931.86034 | L22: 54047.9 | N22: -1752.1 | Q22: 55912.32 | R22: -931.86034 | S22: -1864.42
A23: Véhicules neufsRev. Autres | B23: Véhicules neufs | C23: Rev. Autres | D23: 0 | E23: 0 | F23: 1200 | K23: 0 | L23: 0 | N23: -1200 | Q23: 1358.23 | R23: 0 | S23: -1358.23
A24: Véhicules neufsTotal F&I | B24: Véhicules neufs | C24: Total F&I | D24: 60 | E24: 1000 | F24: 60000 | J24: 58 | K24: 931.86034 | L24: 54047.9 | M24: -2 | N24: -5952.1 | O24: 73 | P24: 784.52808 | Q24: 57270.55 | S24: -3222.65
A25: Véhicules neufs | B25: Véhicules neufs | N25: -0.099201667 | S25: -0.056270631
A26: Véhicules neufs | B26: Véhicules neufs
A27: Véhicules neufsTotal Dépt. Neufs | B27: Véhicules neufs | C27: Total Dépt. Neufs | D27: 62 | E27: 3344.8338 | F27: 207379.69 | J27: 58 | K27: 3313.1321 | L27: 192161.66 | M27: -4 | N27: -15218.035 | O27: 73 | P27: 3556.2293 | Q27: 259604.74 | R27: -15 | S27: -67443.08
A28: Véhicules neufs | B28: Véhicules neufs | L28: 0.92661753 | M28: -0.064516129 | N28: -0.073382472 | R28: -0.20547945 | S28: -0.2597914
A29: Véhicules neufs | B29: Véhicules neufs
A30: Véhicules neufsDEPENSES | B30: Véhicules neufs | C30: DEPENSES
A31: Véhicules neufsComm. vendeurs | B31: Véhicules neufs | C31: Comm. vendeurs | D31: 0.33304494 | E31: 756.10632 | F31: 45366.379 | J31: 0.30815298 | K31: 702.4319 | L31: 40741.05 | N31: -4625.3291 | O31: 0.24820205 | P31: 667.43849 | Q31: 48723.01 | S31: -7981.96
A32: Véhicules neufsComm. F&I | B32: Véhicules neufs | C32: Comm. F&I | D32: 0.28 | E32: 280 | F32: 16800 | J32: 0.2000087 | K32: 186.38017 | L32: 10810.05 | N32: -5989.95 | O32: 0.29711868 | P32: 233.09795 | Q32: 17016.15 | S32: -6206.1
A33: Véhicules neufsFrais de livraison | B33: Véhicules neufs | C33: Frais de livraison | E33: 115 | F33: 6900 | K33: 166.21517 | L33: 9640.48 | N33: 2740.48 | P33: 51.42137 | Q33: 3753.76 | S33: 5886.72
A34: Véhicules neufsService gratuit 1 | B34: Véhicules neufs | C34: Service gratuit 1 | E34: 10 | F34: 600 | K34: 6.017069 | L34: 348.99 | N34: -251.01 | P34: 1.5160274 | Q34: 110.67 | S34: 238.32
A35: Véhicules neufsEntretien stock | B35: Véhicules neufs | C35: Entretien stock | E35: 120.75 | F35: 7245 | K35: 133.99603 | L35: 7771.77 | N35: 526.77 | P35: 164.94 | Q35: 12040.62 | S35: -4268.85
A36: Véhicules neufsPublicité 1 | B36: Véhicules neufs | C36: Publicité 1 | E36: 91.033333 | F36: 5462 | K36: 245.72724 | L36: 14252.18 | N36: 8790.18 | P36: 131.05397 | Q36: 9566.94 | S36: 4685.24
A37: Véhicules neufsIntérêt de gros | B37: Véhicules neufs | C37: Intérêt de gros | E37: 601.02305 | F37: 36061.383 | K37: -85.485517 | L37: -4958.16 | N37: -41019.543 | P37: 474.72863 | Q37: 34655.19 | S37: -39613.35
A38: Véhicules neufs[...] | B38: Véhicules neufs | C38: [...] | E38: 0 | F38: 0 | K38: 0 | L38: 0 | N38: 0 | P38: 0 | Q38: 0 | S38: 0
A39: Véhicules neufs[...] | B39: Véhicules neufs | C39: [...] | E39: 0 | F39: 0 | K39: 0 | L39: 0 | N39: 0 | P39: 0 | Q39: 0 | S39: 0
A40: Véhicules neufs[...] | B40: Véhicules neufs | C40: [...] | E40: 0 | F40: 0 | K40: 0 | L40: 0 | N40: 0 | P40: 0 | Q40: 0 | S40: 0
...

Sheet Mai 2025
C1: Volks | K1: Véhicules neufs | S1: Réalisé, Mai 2025
D2: X | E2: O | F2: U | J2: NB | L2: $ | O2: X | P2: O | Q2: U | V2: *** NE PAS EFFACER / Pour An Précédente ***
D3: BUDGET ORIGINAL | J3: RÉALISATION | M3: ÉCART réel / Budget | O3: ANNÉE PRÉCÉDENTE | R3: ECART (réel/ Ann.Préc.) | V3: NEUF | W3: 0.45
D4: UNITE | E4: $P/UNITÉ | F4: $PROFITS | J4: UNITÉS | K4: $P/UNITE | L4: $PROFITS | M4: UNITÉS | N4: $PROFITS | O4: UNITE | P4: $P/UNITÉ | Q4: $PROFITS | R4: UNITÉS | S4: $PROFITS | V4: USAGE | W4: 0.1
A5: Véhicules neufsVentes nettes | B5: Véhicules neufs | C5: Ventes nettes | F5: 3234339.5 | L5: 3181778.8 | Q5: 3906259.8 | V5: SERVICE | W5: 0.225
A6: Véhicules neufsAutos détail | B6: Véhicules neufs | C6: Autos détail | D6: 16 | E6: 1953.6492 | F6: 31258.387 | J6: 10 | K6: 2530.125 | L6: 25301.25 | M6: -6 | N6: -5957.1367 | O6: 18 | P6: 1997.7756 | Q6: 35959.96 | R6: -8 | S6: -10658.71 | V6: CARROSSERIE | W6: 0.025
A7: Véhicules neufsCamions détail | B7: Véhicules neufs | C7: Camions détail | D7: 43 | E7: 2435.9047 | F7: 104743.9 | J7: 42 | K7: 2234.159 | L7: 93834.68 | M7: -1 | N7: -10909.221 | O7: 51 | P7: 2441.8604 | Q7: 124534.88 | R7: -9 | S7: -30700.2 | V7: PIECES | W7: 0.2
A8: Véhicules neufsSprinter | B8: Véhicules neufs | C8: Sprinter | D8: 0 | E8: 0 | F8: 0 | J8: 0 | K8: 0 | L8: 0 | M8: 0 | N8: 0 | O8: 0 | P8: 0 | Q8: 0 | R8: 0 | S8: 0 | W8: 1
A9: Véhicules neufsMoto détail | B9: Véhicules neufs | C9: Moto détail | D9: 0 | E9: 0 | F9: 0 | J9: 0 | K9: 0 | L9: 0 | M9: 0 | N9: 0 | O9: 0 | P9: 0 | Q9: 0 | R9: 0 | S9: 0
A10: Véhicules neufs[...] | B10: Véhicules neufs | C10: [...] | D10: 0 | E10: 0 | F10: 0 | J10: 0 | K10: 0 | L10: 0 | M10: 0 | N10: 0 | O10: 0 | P10: 0 | Q10: 0 | R10: 0 | S10: 0
A11: Véhicules neufs[...] | B11: Véhicules neufs | C11: [...] | D11: 0 | E11: 0 | F11: 0 | J11: 0 | K11: 0 | L11: 0 | M11: 0 | N11: 0 | O11: 0 | P11: 0 | Q11: 0 | R11: 0 | S11: 0
A12: Véhicules neufs[...] | B12: Véhicules neufs | C12: [...] | D12: 0 | E12: 0 | F12: 0 | J12: 0 | K12: 0 | L12: 0 | M12: 0 | N12: 0 | O12: 0 | P12: 0 | Q12: 0 | R12: 0 | S12: 0
A13: Véhicules neufsTotal Neufs | B13: Véhicules neufs | C13: Total Neufs | D13: 59 | E13: 2305.1235 | F13: 136002.29 | J13: 52 | K13: 2291.0756 | L13: 119135.93 | M13: -7 | N13: -16866.358 | O13: 69 | P13: 2326.0122 | Q13: 160494.84 | R13: -17 | S13: -41358.91
A14: Véhicules neufs | B14: Véhicules neufs | M14: -0.11864407 | N14: -0.12401525 | R14: -0.24637681 | S14: -0.2576962 | AD14: 20 | AE14: 1000 | AF14: 20000
A15: Véhicules neufsEx-Démos et courtoisies | B15: Véhicules neufs | C15: Ex-Démos et courtoisies | D15: 2 | E15: 1534.7521 | F15: 3069.5043 | J15: 5 | K15: 2015.852 | L15: 10079.26 | M15: 3 | N15: 7009.7557 | O15: 5 | P15: 1165.582 | Q15: 5827.91 | R15: 0 | S15: 4251.35 | AD15: 25 | AE15: 800 | AF15: 20000
A16: Véhicules neufs | B16: Véhicules neufs
A17: Véhicules neufsFlottes | B17: Véhicules neufs | C17: Flottes | D17: 2 | E17: 2393.8521 | F17: 4787.7042 | J17: 0 | K17: 0 | L17: 0 | M17: -2 | N17: -4787.7042 | O17: 0 | P17: 0 | Q17: 0 | R17: 0 | S17: 0
A18: Véhicules neufs | B18: Véhicules neufs
A19: Véhicules neufsRachat bail | B19: Véhicules neufs | C19: Rachat bail | D19: 0 | E19: 0 | F19: 6545 | L19: 11767.32 | N19: 5222.32 | Q19: 9930 | R19: 0 | S19: 1837.32
A20: Véhicules neufs | B20: Véhicules neufs
A21: Véhicules neufsRev. Finances | B21: Véhicules neufs | C21: Rev. Finances | D21: 0 | E21: 0 | F21: 3050 | K21: 11.182281 | L21: 637.39 | N21: -2412.61 | Q21: 800 | R21: -11.182281 | S21: -162.61
A22: Véhicules neufsRev. Protections | B22: Véhicules neufs | C22: Rev. Protections | D22: 0 | E22: 0 | F22: 56730 | K22: 1090.3154 | L22: 62147.98 | N22: 5417.98 | Q22: 58571.93 | R22: -1090.3154 | S22: 3576.05
A23: Véhicules neufsRev. Autres | B23: Véhicules neufs | C23: Rev. Autres | D23: 0 | E23: 0 | F23: 1220 | K23: 4.6777193 | L23: 266.63 | N23: -953.37 | Q23: 0 | R23: -4.6777193 | S23: 266.63
A24: Véhicules neufsTotal F&I | B24: Véhicules neufs | C24: Total F&I | D24: 61 | E24: 1000 | F24: 61000 | J24: 57 | K24: 1106.1754 | L24: 63052 | M24: -4 | N24: 2052 | O24: 74 | P24: 802.32338 | Q24: 59371.93 | S24: 3680.07
A25: Véhicules neufs | B25: Véhicules neufs | N25: 0.033639344 | S25: 0.061983331
A26: Véhicules neufs | B26: Véhicules neufs
A27: Véhicules neufsTotal Dépt. Neufs | B27: Véhicules neufs | C27: Total Dépt. Neufs | D27: 63 | E27: 3355.6269 | F27: 211404.5 | J27: 57 | K27: 3579.5528 | L27: 204034.51 | M27: -6 | N27: -7369.9864 | O27: 74 | P27: 3184.1173 | Q27: 235624.68 | R27: -17 | S27: -31590.17
A28: Véhicules neufs | B28: Véhicules neufs | L28: 0.96513799 | M28: -0.095238095 | N28: -0.034862013 | R28: -0.22972973 | S28: -0.13406987
A29: Véhicules neufs | B29: Véhicules neufs
A30: Véhicules neufsDEPENSES | B30: Véhicules neufs | C30: DEPENSES
A31: Véhicules neufsComm. vendeurs | B31: Véhicules neufs | C31: Comm. vendeurs | D31: 0.34122338 | E31: 777.94339 | F31: 47454.547 | J31: 0.33936869 | K31: 769.32614 | L31: 43851.59 | N31: -3602.9565 | O31: 0.21053999 | P31: 473.21068 | Q31: 35017.59 | S31: 8834
A32: Véhicules neufsComm. F&I | B32: Véhicules neufs | C32: Comm. F&I | D32: 0.28 | E32: 280 | F32: 17080 | J32: 0.29999762 | K32: 331.85 | L32: 18915.45 | N32: 1835.45 | O32: 0.29999833 | P32: 240.69568 | Q32: 17811.48 | S32: 1103.97
A33: Véhicules neufsFrais de livraison | B33: Véhicules neufs | C33: Frais de livraison | E33: 115 | F33: 7015 | K33: 138.49439 | L33: 7894.18 | N33: 879.18 | P33: 153.52486 | Q33: 11360.84 | S33: -3466.66
A34: Véhicules neufsService gratuit 1 | B34: Véhicules neufs | C34: Service gratuit 1 | E34: 10 | F34: 610 | K34: 0.066315789 | L34: 3.78 | N34: -606.22 | P34: 13.206486 | Q34: 977.28 | S34: -973.5
A35: Véhicules neufsEntretien stock | B35: Véhicules neufs | C35: Entretien stock | E35: 120.75 | F35: 7365.75 | K35: 167.94544 | L35: 9572.89 | N35: 2207.14 | P35: 132.78284 | Q35: 9825.93 | S35: -253.04
A36: Véhicules neufsPublicité 1 | B36: Véhicules neufs | C36: Publicité 1 | E36: 87.901639 | F36: 5362 | K36: 171.58053 | L36: 9780.09 | N36: 4418.09 | P36: 164.58405 | Q36: 12179.22 | S36: -2399.13
A37: Véhicules neufsIntérêt de gros | B37: Véhicules neufs | C37: Intérêt de gros | E37: 626.28924 | F37: 38203.644 | K37: 227.21439 | L37: 12951.22 | N37: -25252.424 | P37: 644.70649 | Q37: 47708.28 | S37: -34757.06
A38: Véhicules neufs[...] | B38: Véhicules neufs | C38: [...] | E38: 0 | F38: 0 | K38: 0 | L38: 0 | N38: 0 | P38: 0 | Q38: 0 | S38: 0
A39: Véhicules neufs[...] | B39: Véhicules neufs | C39: [...] | E39: 0 | F39: 0 | K39: 0 | L39: 0 | N39: 0 | P39: 0 | Q39: 0 | S39: 0
A40: Véhicules neufs[...] | B40: Véhicules neufs | C40: [...] | E40: 0 | F40: 0 | K40: 0 | L40: 0 | N40: 0 | P40: 0 | Q40: 0 | S40: 0
...

Sheet Juin 2025
C1: Volks | K1: Véhicules neufs | S1: Réalisé, Juin 2025
D2: X | E2: O | F2: U | J2: NB | L2: $ | O2: X | P2: O | Q2: U | V2: *** NE PAS EFFACER / Pour An Précédente ***
D3: BUDGET ORIGINAL | J3: RÉALISATION | M3: ÉCART réel / Budget | O3: ANNÉE PRÉCÉDENTE | R3: ECART (réel/ Ann.Préc.) | V3: NEUF | W3: 0.45
D4: UNITE | E4: $P/UNITÉ | F4: $PROFITS | J4: UNITÉS | K4: $P/UNITE | L4: $PROFITS | M4: UNITÉS | N4: $PROFITS | O4: UNITE | P4: $P/UNITÉ | Q4: $PROFITS | R4: UNITÉS | S4: $PROFITS | V4: USAGE | W4: 0.1
A5: Véhicules neufsVentes nettes | B5: Véhicules neufs | C5: Ventes nettes | F5: 3782098.2 | L5: 2263467 | Q5: 2093787.4 | V5: SERVICE | W5: 0.225
A6: Véhicules neufsAutos détail | B6: Véhicules neufs | C6: Autos détail | D6: 19 | E6: 1953.6492 | F6: 37119.334 | J6: 12 | K6: 2183.5042 | L6: 26202.05 | M6: -7 | N6: -10917.284 | O6: 15 | P6: 1651.894 | Q6: 24778.41 | R6: -3 | S6: 1423.64 | V6: CARROSSERIE | W6: 0.025
A7: Véhicules neufsCamions détail | B7: Véhicules neufs | C7: Camions détail | D7: 50 | E7: 2435.9047 | F7: 121795.23 | J7: 29 | K7: 1971.4128 | L7: 57170.97 | M7: -21 | N7: -64624.264 | O7: 25 | P7: 2415.8504 | Q7: 60396.26 | R7: 4 | S7: -3225.29 | V7: PIECES | W7: 0.2
A8: Véhicules neufsSprinter | B8: Véhicules neufs | C8: Sprinter | D8: 0 | E8: 0 | F8: 0 | J8: 0 | K8: 0 | L8: 0 | M8: 0 | N8: 0 | O8: 0 | P8: 0 | Q8: 0 | R8: 0 | S8: 0 | W8: 1
A9: Véhicules neufsMoto détail | B9: Véhicules neufs | C9: Moto détail | D9: 0 | E9: 0 | F9: 0 | J9: 0 | K9: 0 | L9: 0 | M9: 0 | N9: 0 | O9: 0 | P9: 0 | Q9: 0 | R9: 0 | S9: 0
A10: Véhicules neufs[...] | B10: Véhicules neufs | C10: [...] | D10: 0 | E10: 0 | F10: 0 | J10: 0 | K10: 0 | L10: 0 | M10: 0 | N10: 0 | O10: 0 | P10: 0 | Q10: 0 | R10: 0 | S10: 0
A11: Véhicules neufs[...] | B11: Véhicules neufs | C11: [...] | D11: 0 | E11: 0 | F11: 0 | J11: 0 | K11: 0 | L11: 0 | M11: 0 | N11: 0 | O11: 0 | P11: 0 | Q11: 0 | R11: 0 | S11: 0
A12: Véhicules neufs[...] | B12: Véhicules neufs | C12: [...] | D12: 0 | E12: 0 | F12: 0 | J12: 0 | K12: 0 | L12: 0 | M12: 0 | N12: 0 | O12: 0 | P12: 0 | Q12: 0 | R12: 0 | S12: 0
A13: Véhicules neufsTotal Neufs | B13: Véhicules neufs | C13: Total Neufs | D13: 69 | E13: 2303.1097 | F13: 158914.57 | J13: 41 | K13: 2033.4883 | L13: 83373.02 | M13: -28 | N13: -75541.548 | O13: 40 | P13: 2129.3667 | Q13: 85174.67 | R13: 1 | S13: -1801.65
A14: Véhicules neufs | B14: Véhicules neufs | M14: -0.4057971 | N14: -0.47535949 | R14: 0.025 | S14: -0.021152415 | AD14: 20 | AE14: 1000 | AF14: 20000
A15: Véhicules neufsEx-Démos et courtoisies | B15: Véhicules neufs | C15: Ex-Démos et courtoisies | D15: 4 | E15: 1534.7521 | F15: 6139.0086 | J15: 6 | K15: 1300.1783 | L15: 7801.07 | M15: 2 | N15: 1662.0614 | O15: 0 | P15: 0 | Q15: 0 | R15: 6 | S15: 7801.07 | AD15: 25 | AE15: 800 | AF15: 20000
A16: Véhicules neufs | B16: Véhicules neufs
A17: Véhicules neufsFlottes | B17: Véhicules neufs | C17: Flottes | D17: 2 | E17: 2393.8521 | F17: 4787.7042 | J17: 0 | K17: 0 | L17: 0 | M17: -2 | N17: -4787.7042 | O17: 0 | P17: 0 | Q17: 0 | R17: 0 | S17: 0
A18: Véhicules neufs | B18: Véhicules neufs
A19: Véhicules neufsRachat bail | B19: Véhicules neufs | C19: Rachat bail | D19: 0 | E19: 0 | F19: 7650 | L19: 6139.6 | N19: -1510.4 | Q19: 6100 | R19: 0 | S19: 39.6
A20: Véhicules neufs | B20: Véhicules neufs
A21: Véhicules neufsRev. Finances | B21: Véhicules neufs | C21: Rev. Finances | D21: 0 | E21: 0 | F21: 3650 | K21: 14.402128 | L21: 676.9 | N21: -2973.1 | Q21: 0 | R21: -14.402128 | S21: 676.9
A22: Véhicules neufsRev. Protections | B22: Véhicules neufs | C22: Rev. Protections | D22: 0 | E22: 0 | F22: 67890 | K22: 1023.1253 | L22: 48086.89 | N22: -19803.11 | Q22: 31000.2 | R22: -1023.1253 | S22: 17086.69
A23: Véhicules neufsRev. Autres | B23: Véhicules neufs | C23: Rev. Autres | D23: 0 | E23: 0 | F23: 1460 | K23: 0 | L23: 0 | N23: -1460 | Q23: 2699 | R23: 0 | S23: -2699
A24: Véhicules neufsTotal F&I | B24: Véhicules neufs | C24: Total F&I | D24: 73 | E24: 1000 | F24: 73000 | J24: 47 | K24: 1037.5274 | L24: 48763.79 | M24: -26 | N24: -24236.21 | O24: 40 | P24: 842.48 | Q24: 33699.2 | S24: 15064.59
A25: Véhicules neufs | B25: Véhicules neufs | N25: -0.33200288 | S25: 0.44703109
A26: Véhicules neufs | B26: Véhicules neufs
A27: Véhicules neufsTotal Dépt. Neufs | B27: Véhicules neufs | C27: Total Dépt. Neufs | D27: 75 | E27: 3339.8837 | F27: 250491.28 | J27: 47 | K27: 3108.0315 | L27: 146077.48 | M27: -28 | N27: -104413.8 | O27: 40 | P27: 3124.3467 | Q27: 124973.87 | R27: 7 | S27: 21103.61
A28: Véhicules neufs | B28: Véhicules neufs | L28: 0.58316393 | M28: -0.37333333 | N28: -0.41683607 | R28: 0.175 | S28: 0.16886418
A29: Véhicules neufs | B29: Véhicules neufs
A30: Véhicules neufsDEPENSES | B30: Véhicules neufs | C30: DEPENSES
A31: Véhicules neufsComm. vendeurs | B31: Véhicules neufs | C31: Comm. vendeurs | D31: 0.32512204 | E31: 735.1035 | F31: 53662.555 | J31: 0.34423486 | K31: 667.77234 | L31: 31385.3 | N31: -22277.255 | O31: 0.30022752 | P31: 639.2945 | Q31: 25571.78 | S31: 5813.52
A32: Véhicules neufsComm. F&I | B32: Véhicules neufs | C32: Comm. F&I | D32: 0.28 | E32: 280 | F32: 20440 | J32: 0.29928478 | K32: 310.51617 | L32: 14594.26 | N32: -5845.74 | O32: 0.0032629855 | P32: 2.749 | Q32: 109.96 | S32: 14484.3
A33: Véhicules neufsFrais de livraison | B33: Véhicules neufs | C33: Frais de livraison | E33: 115 | F33: 8395 | K33: 111.73617 | L33: 5251.6 | N33: -3143.4 | P33: 130.5265 | Q33: 5221.06 | S33: 30.54
A34: Véhicules neufsService gratuit 1 | B34: Véhicules neufs | C34: Service gratuit 1 | E34: 10 | F34: 730 | K34: 5.4995745 | L34: 258.48 | N34: -471.52 | P34: 4.62375 | Q34: 184.95 | S34: 73.53
A35: Véhicules neufsEntretien stock | B35: Véhicules neufs | C35: Entretien stock | E35: 120.75 | F35: 8814.75 | K35: 168.73936 | L35: 7930.75 | N35: -884 | P35: 185.7815 | Q35: 7431.26 | S35: 499.49
A36: Véhicules neufsPublicité 1 | B36: Véhicules neufs | C36: Publicité 1 | E36: 57.013699 | F36: 4162 | K36: 108.28021 | L36: 5089.17 | N36: 927.17 | P36: 266.85925 | Q36: 10674.37 | S36: -5585.2
A37: Véhicules neufsIntérêt de gros | B37: Véhicules neufs | C37: Intérêt de gros | E37: 523.33758 | F37: 38203.644 | K37: 280.19213 | L37: 13169.03 | N37: -25034.614 | P37: 1001.4042 | Q37: 40056.17 | S37: -26887.14
A38: Véhicules neufs[...] | B38: Véhicules neufs | C38: [...] | E38: 0 | F38: 0 | K38: 0 | L38: 0 | N38: 0 | P38: 0 | Q38: 0 | S38: 0
A39: Véhicules neufs[...] | B39: Véhicules neufs | C39: [...] | E39: 0 | F39: 0 | K39: 0 | L39: 0 | N39: 0 | P39: 0 | Q39: 0 | S39: 0
A40: Véhicules neufs[...] | B40: Véhicules neufs | C40: [...] | E40: 0 | F40: 0 | K40: 0 | L40: 0 | N40: 0 | P40: 0 | Q40: 0 | S40: 0
...

Sheet END
