Workbook
Name _Dates_Conc: [1]Dealers!$BF$37:$KA$63
Name _scen: '[1]Scen & Sens'!$E$26
Name _scen1: '[1]Scen & Sens'!$E$27
Name _scen2: '[1]Scen & Sens'!$E$28
Name _SCenarios: '[1]Scen & Sens'!$J$26:$O$26
Name _Sens1: '[1]Scen & Sens'!$F$9
Name _Sens2: '[1]Scen & Sens'!$F$10
Name _sensRes1: '[1]Scen & Sens'!$E$15
Name _sensRes2: '[1]Scen & Sens'!$E$16
Name _sensRes3: '[1]Scen & Sens'!$E$17
Name _sensRes4: '[1]Scen & Sens'!$E$18
Name _sensRes5: '[1]Scen & Sens'!$E$19
Name _sensRes6: '[1]Scen & Sens'!$E$20
Name _sensRes7: '[1]Scen & Sens'!$E$21
Name DateRange: [1]Volkswagen!$BF$6:$DY$6
Name Monetary_Unit: [1]Parameters!$B$15
Name Months: [1]Parameters!$E$9:$E$20
Name Rng_Dealers_Names: [1]!Tbl_Dealers[Dealer Name]
Name Rng_Dlr_Dates: [1]!Tbl_V_Dlr_Dates[Date]
Name Ticker: #REF!
Name Ticker: #REF!
Name Ticker: #REF!
Name Titre: [1]Front!$A$9

Sheet Paramètre
B3: Quarter
B6: BUDGET | F6: BUDGET RÉVISÉ | J6: ACTUAL | N6: LAST YEAR
B7: Ventes | C7: Profits bruts | D7: BAIIA | E7: EBIT | F7: Ventes | G7: Profits bruts | H7: BAIIA | I7: EBIT | J7: Ventes | K7: Profits bruts | L7: BAIIA | M7: EBIT | N7: Ventes | O7: Profits bruts | P7: BAIIA | Q7: EBIT
A8: CTRL | B8: =+B9-B10 -> #REF! | C8: =+C9-C10 -> #REF! | D8: =+D9-D10 -> #REF! | E8: =+E9-E10 -> #REF! | F8: =+F9-F10 -> #REF! | G8: =+G9-G10 -> #REF! | H8: =+H9-H10 -> #REF! | I8: =+I9-I10 -> #REF! | ... Q8: =+Q9-Q10 -> #REF!
A9: CONSO | B9: =+Conso!$Z$405 -> 18674893 | C9: =+Conso!$Z$406 -> 2124468.2 | D9: =+Conso!$Z$482 -> 529849.51 | E9: =+Conso!$Z$497 -> 402143.01 | F9: =+Conso!$AC$405 -> 0 | G9: =+Conso!$AC$406 -> 0 | H9: =+Conso!$AC$482 -> 0 | I9: =+Conso!$AC$497 -> 0 | J9: =+Conso!$AF$405 -> 18192349 | K9: =+Conso!$AF$406 -> 2265034.2 | L9: =+Conso!$AF$482 -> 875124.12 | M9: =+Conso!$AF$497 -> 749338.12 | N9: =+Conso!$AL$405 -> 17443640 | O9: =+Conso!$AL$406 -> 1880122.8 | P9: =+Conso!$AL$482 -> 419717.69 | Q9: =+Conso!$AL$497 -> 322893.68
A10: TOTAL | B10: =+SUM(B11:B13) -> #REF! | C10: =+SUM(C11:C13) -> #REF! | D10: =+SUM(D11:D13) -> #REF! | E10: =+SUM(E11:E13) -> #REF! | F10: =+SUM(F11:F13) -> #REF! | G10: =+SUM(G11:G13) -> #REF! | H10: =+SUM(H11:H13) -> #REF! | I10: =+SUM(I11:I13) -> #REF! | ... Q10: =+SUM(Q11:Q13) -> #REF!
A11: Mois 1 | B11: =+#REF! -> #REF! | C11: =+#REF! -> #REF! | D11: =+#REF! -> #REF! | E11: =+#REF! -> #REF! | F11: =+#REF! -> #REF! | G11: =+#REF! -> #REF! | H11: =+#REF! -> #REF! | I11: =+#REF! -> #REF! | ... Q11: =+#REF! -> #REF!
A12: Mois 2 | B12: =+#REF! -> #REF! | C12: =+#REF! -> #REF! | D12: =+#REF! -> #REF! | E12: =+#REF! -> #REF! | F12: =+#REF! -> #REF! | G12: =+#REF! -> #REF! | H12: =+#REF! -> #REF! | I12: =+#REF! -> #REF! | ... Q12: =+#REF! -> #REF!
A13: Mois 3 | B13: =+#REF! -> #REF! | C13: =+#REF! -> #REF! | D13: =+#REF! -> #REF! | E13: =+#REF! -> #REF! | F13: =+#REF! -> #REF! | G13: =+#REF! -> #REF! | H13: =+#REF! -> #REF! | I13: =+#REF! -> #REF! | ... Q13: =+#REF! -> #REF!

Sheet Conso
C1: Conso | K1: Véhicules neufs | S1: =CONCATENATE("Réalisé"," ",Paramètre!$C$2," ",Paramètre!$C$3) -> Réalisé
D2: X | E2: O | F2: U | G2: X | H2: O | I2: U
D3: BUDGET ORIGINAL | G3: BUDGET REVISE | J3: RÉALISATION | M3: ÉCART réel / original | O3: ANNÉE PRÉCÉDENTE | R3: ÉCART réel / année précédente
D4: UNITE | E4: $P/UNITÉ | F4: $PROFITS | G4: UNITE | H4: $P/UNITÉ | I4: $PROFITS | J4: UNITE | K4: $P/UNITE | L4: $PROFITS | M4: UNITÉ | N4: $PROFITS | O4: UNITE | P4: $P/UNITE | Q4: $PROFITS | R4: UNITE | S4: $PROFITS
A5: =+B5&C5 -> Véhicules neufsVentes nettes | B5: =+$K$1 -> Véhicules neufs | C5: Ventes nettes | F5: =+SUM(START:END!F5) -> 11763417 | I5: =+SUM(START:END!I5) -> 0 | L5: =+SUM(START:END!L5) -> 10668360 | Q5: =+SUM(START:END!Q5) -> 11588445
A6: =+B6&C6 -> Véhicules neufsAutos détail | B6: =+$K$1 -> Véhicules neufs | C6: Autos détail | D6: =+SUM(START:END!D6) -> 58 | E6: =IF(D6=0,0,F6/D6) -> 1953.6492 | F6: =+SUM(START:END!F6) -> 113311.65 | G6: =+SUM(START:END!G6) -> 0 | H6: =IF(G6=0,0,I6/G6) -> 0 | I6: =+SUM(START:END!I6) -> 0 | J6: =+SUM(START:END!J6) -> 27 | K6: =IF(J6=0,0,L6/J6) -> 1261.5104 | L6: =+SUM(START:END!L6) -> 34060.78 | M6: =J6-D6 -> -31 | N6: =L6-F6 -> -79250.872 | O6: =+SUM(START:END!O6) -> 58 | P6: =IF(O6=0,0,Q6/O6) -> 1768.8329 | Q6: =+SUM(START:END!Q6) -> 102592.31 | R6: =J6-O6 -> -31 | S6: =L6-Q6 -> -68531.53
A7: =+B7&C7 -> Véhicules neufsCamions détail | B7: =+$K$1 -> Véhicules neufs | C7: Camions détail | D7: =+SUM(START:END!D7) -> 155 | E7: =IF(D7=0,0,F7/D7) -> 2435.9047 | F7: =+SUM(START:END!F7) -> 377565.23 | G7: =+SUM(START:END!G7) -> 0 | H7: =IF(G7=0,0,I7/G7) -> 0 | I7: =+SUM(START:END!I7) -> 0 | J7: =+SUM(START:END!J7) -> 175 | K7: =IF(J7=0,0,L7/J7) -> 2328.2872 | L7: =+SUM(START:END!L7) -> 407450.26 | M7: =J7-D7 -> 20 | N7: =L7-F7 -> 29885.035 | O7: =+SUM(START:END!O7) -> 142 | P7: =IF(O7=0,0,Q7/O7) -> 2240.5756 | Q7: =+SUM(START:END!Q7) -> 318161.73 | R7: =J7-O7 -> 33 | S7: =L7-Q7 -> 89288.53
A8: =+B8&C8 -> Véhicules neufsSprinter | B8: =+$K$1 -> Véhicules neufs | C8: Sprinter | D8: =+SUM(START:END!D8) -> 0 | E8: =IF(D8=0,0,F8/D8) -> 0 | F8: =+SUM(START:END!F8) -> 0 | G8: =+SUM(START:END!G8) -> 0 | H8: =IF(G8=0,0,I8/G8) -> 0 | I8: =+SUM(START:END!I8) -> 0 | J8: =+SUM(START:END!J8) -> 0 | K8: =IF(J8=0,0,L8/J8) -> 0 | L8: =+SUM(START:END!L8) -> 0 | M8: =J8-D8 -> 0 | N8: =L8-F8 -> 0 | O8: =+SUM(START:END!O8) -> 0 | P8: =IF(O8=0,0,Q8/O8) -> 0 | Q8: =+SUM(START:END!Q8) -> 0 | R8: =J8-O8 -> 0 | S8: =L8-Q8 -> 0
A9: =+B9&C9 -> Véhicules neufsMoto détail | B9: =+$K$1 -> Véhicules neufs | C9: Moto détail | D9: =+SUM(START:END!D9) -> 0 | E9: =IF(D9=0,0,F9/D9) -> 0 | F9: =+SUM(START:END!F9) -> 0 | G9: =+SUM(START:END!G9) -> 0 | H9: =IF(G9=0,0,I9/G9) -> 0 | I9: =+SUM(START:END!I9) -> 0 | J9: =+SUM(START:END!J9) -> 0 | K9: =IF(J9=0,0,L9/J9) -> 0 | L9: =+SUM(START:END!L9) -> 0 | M9: =J9-D9 -> 0 | N9: =L9-F9 -> 0 | O9: =+SUM(START:END!O9) -> 0 | P9: =IF(O9=0,0,Q9/O9) -> 0 | Q9: =+SUM(START:END!Q9) -> 0 | R9: =J9-O9 -> 0 | S9: =L9-Q9 -> 0
A10: =+B10&C10 -> Véhicules neufs[...] | B10: =+$K$1 -> Véhicules neufs | C10: [...] | D10: =+SUM(START:END!D10) -> 0 | E10: =IF(D10=0,0,F10/D10) -> 0 | F10: =+SUM(START:END!F10) -> 0 | G10: =+SUM(START:END!G10) -> 0 | H10: =IF(G10=0,0,I10/G10) -> 0 | I10: =+SUM(START:END!I10) -> 0 | J10: =+SUM(START:END!J10) -> 0 | K10: =IF(J10=0,0,L10/J10) -> 0 | L10: =+SUM(START:END!L10) -> 0 | M10: =J10-G10 -> 0 | N10: =L10-I10 -> 0 | O10: =+SUM(START:END!O10) -> 0 | P10: =IF(O10=0,0,Q10/O10) -> 0 | Q10: =+SUM(START:END!Q10) -> 0 | R10: =J10-O10 -> 0 | S10: =L10-Q10 -> 0
A11: =+B11&C11 -> Véhicules neufs[...] | B11: =+$K$1 -> Véhicules neufs | C11: [...] | D11: =+SUM(START:END!D11) -> 0 | E11: =IF(D11=0,0,F11/D11) -> 0 | F11: =+SUM(START:END!F11) -> 0 | G11: =+SUM(START:END!G11) -> 0 | H11: =IF(G11=0,0,I11/G11) -> 0 | I11: =+SUM(START:END!I11) -> 0 | J11: =+SUM(START:END!J11) -> 0 | K11: =IF(J11=0,0,L11/J11) -> 0 | L11: =+SUM(START:END!L11) -> 0 | M11: =J11-G11 -> 0 | N11: =L11-I11 -> 0 | O11: =+SUM(START:END!O11) -> 0 | P11: =IF(O11=0,0,Q11/O11) -> 0 | Q11: =+SUM(START:END!Q11) -> 0 | R11: =J11-O11 -> 0 | S11: =L11-Q11 -> 0
A12: =+B12&C12 -> Véhicules neufs[...] | B12: =+$K$1 -> Véhicules neufs | C12: [...] | D12: =+SUM(START:END!D12) -> 0 | E12: =IF(D12=0,0,F12/D12) -> 0 | F12: =+SUM(START:END!F12) -> 0 | G12: =+SUM(START:END!G12) -> 0 | H12: =IF(G12=0,0,I12/G12) -> 0 | I12: =+SUM(START:END!I12) -> 0 | J12: =+SUM(START:END!J12) -> 0 | K12: =IF(J12=0,0,L12/J12) -> 0 | L12: =+SUM(START:END!L12) -> 0 | M12: =J12-G12 -> 0 | N12: =L12-I12 -> 0 | O12: =+SUM(START:END!O12) -> 0 | P12: =IF(O12=0,0,Q12/O12) -> 0 | Q12: =+SUM(START:END!Q12) -> 0 | R12: =J12-O12 -> 0 | S12: =L12-Q12 -> 0
A13: =+B13&C13 -> Véhicules neufsTotal Neufs | B13: =+$K$1 -> Véhicules neufs | C13: Total Neufs | D13: =+SUM(D6:D12) -> 213 | E13: =IF(D13<=0,0,F13/D13) -> 2304.5863 | F13: =+SUM(F6:F12) -> 490876.88 | G13: =+SUM(G6:G12) -> 0 | H13: =IF(G13<=0,0,I13/G13) -> 0 | I13: =+SUM(I6:I12) -> 0 | J13: =+SUM(J6:J12) -> 202 | K13: =IF(J13<=0,0,L13/J13) -> 2185.6982 | L13: =+SUM(L6:L12) -> 441511.04 | M13: =+SUM(M6:M12) -> -11 | N13: =+SUM(N6:N12) -> -49365.837 | O13: =+SUM(O6:O12) -> 200 | P13: =IF(O13<=0,0,Q13/O13) -> 2103.7702 | Q13: =+SUM(Q6:Q12) -> 420754.04 | R13: =+SUM(R6:R12) -> 2 | S13: =+SUM(S6:S12) -> 20757
A14: =+B14&C14 -> Véhicules neufs | B14: =+$K$1 -> Véhicules neufs | N14: =IF(F13=0,0,N13/F13) -> -0.10056664 | R14: =R13/O13 -> 0.01 | S14: =IF(Q13=0,0,(S13/Q13)) -> 0.04933286
A15: =+B15&C15 -> Véhicules neufsEx-Démos et courtoisies | B15: =+$K$1 -> Véhicules neufs | C15: Ex-Démos et courtoisies | D15: =+SUM(START:END!D15) -> 11 | E15: =IF(D15=0,0,F15/D15) -> 1534.7521 | F15: =+SUM(START:END!F15) -> 16882.274 | G15: =+SUM(START:END!G15) -> 0 | H15: =IF(G15=0,0,I15/G15) -> 0 | I15: =+SUM(START:END!I15) -> 0 | J15: =+SUM(START:END!J15) -> 6 | K15: =IF(J15=0,0,L15/J15) -> 1347.48 | L15: =+SUM(START:END!L15) -> 8084.88 | M15: =J15-D15 -> -5 | N15: =L15-F15 -> -8797.3936 | O15: =+SUM(START:END!O15) -> 12 | P15: =IF(O15=0,0,Q15/O15) -> 1630.9883 | Q15: =+SUM(START:END!Q15) -> 19571.86 | R15: =J15-O15 -> -6 | S15: =L15-Q15 -> -11486.98
A16: =+B16&C16 -> Véhicules neufs | B16: =+$K$1 -> Véhicules neufs
A17: =+B17&C17 -> Véhicules neufsFlottes | B17: =+$K$1 -> Véhicules neufs | C17: Flottes | D17: =+SUM(START:END!D17) -> 6 | E17: =IF(D17=0,0,F17/D17) -> 2393.8521 | F17: =+SUM(START:END!F17) -> 14363.113 | G17: =+SUM(START:END!G17) -> 0 | H17: =IF(G17=0,0,I17/G17) -> 0 | I17: =+SUM(START:END!I17) -> 0 | J17: =+SUM(START:END!J17) -> 6 | K17: =IF(J17=0,0,L17/J17) -> 626.18667 | L17: =+SUM(START:END!L17) -> 3757.12 | M17: =J17-D17 -> 0 | N17: =L17-F17 -> -10605.993 | O17: =+SUM(START:END!O17) -> 7 | P17: =IF(O17=0,0,Q17/O17) -> 2725.3286 | Q17: =+SUM(START:END!Q17) -> 19077.3 | R17: =J17-O17 -> -1 | S17: =L17-Q17 -> -15320.18
A18: =+B18&C18 -> Véhicules neufs | B18: =+$K$1 -> Véhicules neufs
A19: =+B19&C19 -> Véhicules neufsRachat bail | B19: =+$K$1 -> Véhicules neufs | C19: Rachat bail | F19: =+SUM(START:END!F19) -> 23800 | I19: =+SUM(START:END!I19) -> 0 | L19: =+SUM(START:END!L19) -> 35877.19 | N19: =L19-F19 -> 12077.19 | Q19: =+SUM(START:END!Q19) -> 29115 | R19: =O19-K19 -> 0 | S19: =L19-Q19 -> 6762.19
A20: =+B20&C20 -> Véhicules neufs | B20: =+$K$1 -> Véhicules neufs
A21: =+B21&C21 -> Véhicules neufsRev. Finances | B21: =+$K$1 -> Véhicules neufs | C21: Rev. Finances | D21: 0 | E21: =IF(D21=0,0,F21/D21) -> 0 | F21: =+SUM(START:END!F21) -> 11200 | G21: 0 | H21: =IF(G21=0,0,I21/G21) -> 0 | I21: =+SUM(START:END!I21) -> 0 | K21: =IF(J13=0,0,L21/(J13+J15)) -> 2.9064904 | L21: =+SUM(START:END!L21) -> 604.55 | N21: =L21-F21 -> -10595.45 | P21: =IF(O13=0,0,Q21/(O13+O15)) -> 0 | Q21: =+SUM(START:END!Q21) -> 0 | R21: =O21-K21 -> -2.9064904 | S21: =L21-Q21 -> 604.55
A22: =+B22&C22 -> Véhicules neufsRev. Protections | B22: =+$K$1 -> Véhicules neufs | C22: Rev. Protections | D22: 0 | E22: =IF(D22=0,0,F22/D22) -> 0 | F22: =+SUM(START:END!F22) -> 208320 | G22: 0 | H22: =IF(G22=0,0,I22/G22) -> 0 | I22: =+SUM(START:END!I22) -> 0 | K22: =IF(J13=0,0,L22/(J13+J15)) -> 967.72736 | L22: =+SUM(START:END!L22) -> 201287.29 | N22: =L22-F22 -> -7032.71 | P22: =IF(O13=0,0,Q22/(O13+O15)) -> 865.45189 | Q22: =+SUM(START:END!Q22) -> 183475.8 | R22: =O22-K22 -> -967.72736 | S22: =L22-Q22 -> 17811.49
A23: =+B23&C23 -> Véhicules neufsRev. Autres | B23: =+$K$1 -> Véhicules neufs | C23: Rev. Autres | D23: 0 | E23: =IF(D23=0,0,F23/D23) -> 0 | F23: =+SUM(START:END!F23) -> 4480 | G23: 0 | H23: =IF(G23=0,0,I23/G23) -> 0 | I23: =+SUM(START:END!I23) -> 0 | K23: =IF(J13=0,0,L23/(J13+J15)) -> 0.89682692 | L23: =+SUM(START:END!L23) -> 186.54 | N23: =L23-F23 -> -4293.46 | P23: =IF(O13=0,0,Q23/(O13+O15)) -> 10.368208 | Q23: =+SUM(START:END!Q23) -> 2198.06 | R23: =O23-K23 -> -0.89682692 | S23: =L23-Q23 -> -2011.52
A24: =+B24&C24 -> Véhicules neufsTotal F&I | B24: =+$K$1 -> Véhicules neufs | C24: Total F&I | D24: =+D15+D13 -> 224 | E24: =IF(D24<=0,0,F24/D24) -> 1000 | F24: =F21+F22+F23 -> 224000 | G24: =+G15+G13 -> 0 | H24: =IF(G24<=0,0,I24/G24) -> 0 | I24: =I21+I22+I23 -> 0 | J24: =+J15+J13 -> 208 | K24: =IF(J24<=0,0,L24/J24) -> 971.53067 | L24: =L21+L22+L23 -> 202078.38 | M24: =+M15+M13 -> -16 | N24: =N21+N22+N23 -> -21921.62 | O24: =+O15+O13 -> 212 | P24: =IF(O24<=0,0,Q24/O24) -> 875.82009 | Q24: =Q21+Q22+Q23 -> 185673.86 | S24: =L24-Q24 -> 16404.52
A25: =+B25&C25 -> Véhicules neufs | B25: =+$K$1 -> Véhicules neufs | S25: =IF(Q24=0,0,(S24/Q24)) -> 0.088351263
A26: =+B26&C26 -> Véhicules neufs | B26: =+$K$1 -> Véhicules neufs
A27: =+B27&C27 -> Véhicules neufsTotal Dépt. Neufs | B27: =+$K$1 -> Véhicules neufs | C27: Total Dépt. Neufs | D27: =+D13+D15+D17 -> 230 | E27: =IF(D27<=0,0,F27/D27) -> 3347.4881 | F27: =F13+F17+F24+F19+F15 -> 769922.26 | G27: =+G13+G15+G17 -> 0 | H27: =IF(G27<=0,0,I27/G27) -> 0 | I27: =I13+I17+I24+I19+I15 -> 0 | J27: =+J13+J15+J17 -> 214 | K27: =IF(J27<=0,0,L27/J27) -> 3230.4141 | L27: =L13+L17+L24+L19+L15 -> 691308.61 | M27: =+M13+M15+M17 -> -16 | N27: =N13+N17+N24+N19+N15 -> -78613.653 | O27: =+O13+O15+O17 -> 219 | P27: =IF(O27<=0,0,Q27/O27) -> 3078.5026 | Q27: =Q13+Q17+Q24+Q19+Q15 -> 674192.06 | R27: =J27-O27 -> -5 | S27: =L27-Q27 -> 17116.55
A28: =+B28&C28 -> Véhicules neufs | B28: =+$K$1 -> Véhicules neufs | M28: =M27/D27 -> -0.069565217 | N28: =N27/F27 -> -0.10210596 | R28: =R27/O27 -> -0.02283105 | S28: =IF(Q27=0,0,S27/Q27) -> 0.02538824
A29: =+B29&C29 -> Véhicules neufs | B29: =+$K$1 -> Véhicules neufs
A30: =+B30&C30 -> Véhicules neufsDEPENSES | B30: =+$K$1 -> Véhicules neufs | C30: DEPENSES
A31: =+B31&C31 -> Véhicules neufsComm. vendeurs | B31: =+$K$1 -> Véhicules neufs | C31: Comm. vendeurs | E31: =F31/D$24 -> 739.41296 | F31: =+SUM(START:END!F31) -> 165628.5 | H31: =I31/G$24 -> #DIV/0! | I31: =+SUM(START:END!I31) -> 0 | J31: =L31/L13 -> 0.29719193 | K31: =IF(L31=0,0,L31/J$24) -> 630.83423 | L31: =+SUM(START:END!L31) -> 131213.52 | N31: =L31-F31 -> -34414.983 | P31: =IF(Q31=0,0,Q31/O$24) -> 713.76486 | Q31: =+SUM(START:END!Q31) -> 151318.15 | S31: =L31-Q31 -> -20104.63
A32: =+B32&C32 -> Véhicules neufsComm. F&I | B32: =+$K$1 -> Véhicules neufs | C32: Comm. F&I | E32: =F32/D$24 -> 280 | F32: =+SUM(START:END!F32) -> 62720 | H32: =I32/G$24 -> #DIV/0! | I32: =+SUM(START:END!I32) -> 0 | J32: =L32/L24 -> 0.4246913 | K32: =IF(L32=0,0,L32/J$24) -> 412.60062 | L32: =+SUM(START:END!L32) -> 85820.93 | N32: =L32-F32 -> 23100.93 | P32: =IF(Q32=0,0,Q32/O$24) -> 242.45613 | Q32: =+SUM(START:END!Q32) -> 51400.7 | S32: =L32-Q32 -> 34420.23
A33: =+B33&C33 -> Véhicules neufsFrais de livraison | B33: =+$K$1 -> Véhicules neufs | C33: Frais de livraison | E33: =F33/D$24 -> 115 | F33: =+SUM(START:END!F33) -> 25760 | H33: =I33/G$24 -> #DIV/0! | I33: =+SUM(START:END!I33) -> 0 | K33: =IF(L33=0,0,L33/J$24) -> 99.199423 | L33: =+SUM(START:END!L33) -> 20633.48 | N33: =L33-F33 -> -5126.52 | P33: =IF(Q33=0,0,Q33/O$24) -> 111.38486 | Q33: =+SUM(START:END!Q33) -> 23613.59 | S33: =L33-Q33 -> -2980.11
A34: =+B34&C34 -> Véhicules neufsService gratuit 1 | B34: =+$K$1 -> Véhicules neufs | C34: Service gratuit 1 | E34: =F34/D$24 -> 10 | F34: =+SUM(START:END!F34) -> 2240 | H34: =I34/G$24 -> #DIV/0! | I34: =+SUM(START:END!I34) -> 0 | K34: =IF(L34=0,0,L34/J$24) -> 0 | L34: =+SUM(START:END!L34) -> 0 | N34: =L34-F34 -> -2240 | P34: =IF(Q34=0,0,Q34/O$24) -> 29.79566 | Q34: =+SUM(START:END!Q34) -> 6316.68 | S34: =L34-Q34 -> -6316.68
A35: =+B35&C35 -> Véhicules neufsEntretien stock | B35: =+$K$1 -> Véhicules neufs | C35: Entretien stock | E35: =F35/D$24 -> 120.75 | F35: =+SUM(START:END!F35) -> 27048 | H35: =I35/G$24 -> #DIV/0! | I35: =+SUM(START:END!I35) -> 0 | K35: =IF(L35=0,0,L35/J$24) -> 91.710048 | L35: =+SUM(START:END!L35) -> 19075.69 | N35: =L35-F35 -> -7972.31 | P35: =IF(Q35=0,0,Q35/O$24) -> 94.111038 | Q35: =+SUM(START:END!Q35) -> 19951.54 | S35: =L35-Q35 -> -875.85
A36: =+B36&C36 -> Véhicules neufsPublicité 1 | B36: =+$K$1 -> Véhicules neufs | C36: Publicité 1 | E36: =F36/D$24 -> 53.508929 | F36: =+SUM(START:END!F36) -> 11986 | H36: =I36/G$24 -> #DIV/0! | I36: =+SUM(START:END!I36) -> 0 | K36: =IF(L36=0,0,L36/J$24) -> 84.837163 | L36: =+SUM(START:END!L36) -> 17646.13 | N36: =L36-F36 -> 5660.13 | P36: =IF(Q36=0,0,Q36/O$24) -> 56.937264 | Q36: =+SUM(START:END!Q36) -> 12070.7 | S36: =L36-Q36 -> 5575.43
A37: =+B37&C37 -> Véhicules neufsIntérêt de gros | B37: =+$K$1 -> Véhicules neufs | C37: Intérêt de gros | E37: =F37/D$24 -> 514.84383 | F37: =+SUM(START:END!F37) -> 115325.02 | H37: =I37/G$24 -> #DIV/0! | I37: =+SUM(START:END!I37) -> 0 | K37: =IF(L37=0,0,L37/J$24) -> 236.20462 | L37: =+SUM(START:END!L37) -> 49130.56 | N37: =L37-F37 -> -66194.458 | P37: =IF(Q37=0,0,Q37/O$24) -> 521.73509 | Q37: =+SUM(START:END!Q37) -> 110607.84 | S37: =L37-Q37 -> -61477.28
A38: =+B38&C38 -> Véhicules neufs[...] | B38: =+$K$1 -> Véhicules neufs | C38: [...] | E38: =F38/D$24 -> 0 | F38: =+SUM(START:END!F38) -> 0 | H38: =I38/G$24 -> #DIV/0! | I38: =+SUM(START:END!I38) -> 0 | K38: =IF(L38=0,0,L38/J$24) -> 0 | L38: =+SUM(START:END!L38) -> 0 | N38: =L38-I38 -> 0 | P38: =IF(Q38=0,0,Q38/O$24) -> 0 | Q38: =+SUM(START:END!Q38) -> 0 | S38: =L38-Q38 -> 0
A39: =+B39&C39 -> Véhicules neufs[...] | B39: =+$K$1 -> Véhicules neufs | C39: [...] | E39: =F39/D$24 -> 0 | F39: =+SUM(START:END!F39) -> 0 | H39: =I39/G$24 -> #DIV/0! | I39: =+SUM(START:END!I39) -> 0 | K39: =IF(L39=0,0,L39/J$24) -> 0 | L39: =+SUM(START:END!L39) -> 0 | N39: =L39-I39 -> 0 | P39: =IF(Q39=0,0,Q39/O$24) -> 0 | Q39: =+SUM(START:END!Q39) -> 0 | S39: =L39-Q39 -> 0
A40: =+B40&C40 -> Véhicules neufs[...] | B40: =+$K$1 -> Véhicules neufs | C40: [...] | E40: =F40/D$24 -> 0 | F40: =+SUM(START:END!F40) -> 0 | H40: =I40/G$24 -> #DIV/0! | I40: =+SUM(START:END!I40) -> 0 | K40: =IF(L40=0,0,L40/J$24) -> 0 | L40: =+SUM(START:END!L40) -> 0 | N40: =L40-I40 -> 0 | P40: =IF(Q40=0,0,Q40/O$24) -> 0 | Q40: =+SUM(START:END!Q40) -> 0 | S40: =L40-Q40 -> 0
...

Sheet START

Sheet Juillet 2025
C1: Volks | K1: Véhicules neufs | S1: Réalisé, Juillet 2025
D2: X | E2: O | F2: U | J2: NB | L2: $ | O2: X | P2: O | Q2: U | V2: *** NE PAS EFFACER / Pour An Précédente ***
D3: BUDGET ORIGINAL | J3: RÉALISATION | M3: ÉCART réel / Budget | O3: ANNÉE PRÉCÉDENTE | R3: ECART (réel/ Ann.Préc.) | V3: NEUF | W3: 0.45
D4: UNITE | E4: $P/UNITÉ | F4: $PROFITS | J4: UNITÉS | K4: $P/UNITE | L4: $PROFITS | M4: UNITÉS | N4: $PROFITS | O4: UNITE | P4: $P/UNITÉ | Q4: $PROFITS | R4: UNITÉS | S4: $PROFITS | V4: USAGE | W4: 0.1
A5: Véhicules neufsVentes nettes | B5: Véhicules neufs | C5: Ventes nettes | F5: 3782098.2 | L5: 4089468.3 | Q5: 4524162.1 | V5: SERVICE | W5: 0.225
A6: Véhicules neufsAutos détail | B6: Véhicules neufs | C6: Autos détail | D6: 19 | E6: 1953.6492 | F6: 37119.334 | J6: 13 | K6: 1905.2108 | L6: 24767.74 | M6: -6 | N6: -12351.594 | O6: 23 | P6: 1942.4757 | Q6: 44676.94 | R6: -10 | S6: -19909.2 | V6: CARROSSERIE | W6: 0.025
A7: Véhicules neufsCamions détail | B7: Véhicules neufs | C7: Camions détail | D7: 50 | E7: 2435.9047 | F7: 121795.23 | J7: 63 | K7: 2276.0851 | L7: 143393.36 | M7: 13 | N7: 21598.126 | O7: 54 | P7: 2267.4683 | Q7: 122443.29 | R7: 9 | S7: 20950.07 | V7: PIECES | W7: 0.2
A8: Véhicules neufsSprinter | B8: Véhicules neufs | C8: Sprinter | D8: 0 | E8: 0 | F8: 0 | J8: 0 | K8: 0 | L8: 0 | M8: 0 | N8: 0 | O8: 0 | P8: 0 | Q8: 0 | R8: 0 | S8: 0 | W8: 1
A9: Véhicules neufsMoto détail | B9: Véhicules neufs | C9: Moto détail | D9: 0 | E9: 0 | F9: 0 | J9: 0 | K9: 0 | L9: 0 | M9: 0 | N9: 0 | O9: 0 | P9: 0 | Q9: 0 | R9: 0 | S9: 0
A10: Véhicules neufs[...] | B10: Véhicules neufs | C10: [...] | D10: 0 | E10: 0 | F10: 0 | J10: 0 | K10: 0 | L10: 0 | M10: 0 | N10: 0 | O10: 0 | P10: 0 | Q10: 0 | R10: 0 | S10: 0
A11: Véhicules neufs[...] | B11: Véhicules neufs | C11: [...] | D11: 0 | E11: 0 | F11: 0 | J11: 0 | K11: 0 | L11: 0 | M11: 0 | N11: 0 | O11: 0 | P11: 0 | Q11: 0 | R11: 0 | S11: 0
A12: Véhicules neufs[...] | B12: Véhicules neufs | C12: [...] | D12: 0 | E12: 0 | F12: 0 | J12: 0 | K12: 0 | L12: 0 | M12: 0 | N12: 0 | O12: 0 | P12: 0 | Q12: 0 | R12: 0 | S12: 0
A13: Véhicules neufsTotal Neufs | B13: Véhicules neufs | C13: Total Neufs | D13: 69 | E13: 2303.1097 | F13: 158914.57 | J13: 76 | K13: 2212.6461 | L13: 168161.1 | M13: 7 | N13: 9246.5319 | O13: 77 | P13: 2170.3926 | Q13: 167120.23 | R13: -1 | S13: 1040.87
A14: Véhicules neufs | B14: Véhicules neufs | M14: 0.10144928 | N14: 0.058185552 | R14: -0.012987013 | S14: 0.0062282705 | AD14: 20 | AE14: 1000 | AF14: 20000
A15: Véhicules neufsEx-Démos et courtoisies | B15: Véhicules neufs | C15: Ex-Démos et courtoisies | D15: 4 | E15: 1534.7521 | F15: 6139.0086 | J15: 5 | K15: 1374.508 | L15: 6872.54 | M15: 1 | N15: 733.53143 | O15: 3 | P15: 913.29 | Q15: 2739.87 | R15: 2 | S15: 4132.67 | AD15: 25 | AE15: 800 | AF15: 20000
A16: Véhicules neufs | B16: Véhicules neufs
A17: Véhicules neufsFlottes | B17: Véhicules neufs | C17: Flottes | D17: 2 | E17: 2393.8521 | F17: 4787.7042 | J17: 0 | K17: 0 | L17: 0 | M17: -2 | N17: -4787.7042 | O17: 5 | P17: 2550.916 | Q17: 12754.58 | R17: -5 | S17: -12754.58
A18: Véhicules neufs | B18: Véhicules neufs
A19: Véhicules neufsRachat bail | B19: Véhicules neufs | C19: Rachat bail | D19: 0 | E19: 0 | F19: 7650 | L19: 12602.35 | N19: 4952.35 | Q19: 10000 | R19: 0 | S19: 2602.35
A20: Véhicules neufs | B20: Véhicules neufs
A21: Véhicules neufsRev. Finances | B21: Véhicules neufs | C21: Rev. Finances | D21: 0 | E21: 0 | F21: 3650 | K21: 7.4635802 | L21: 604.55 | N21: -3045.45 | Q21: 0 | R21: -7.4635802 | S21: 604.55
A22: Véhicules neufsRev. Protections | B22: Véhicules neufs | C22: Rev. Protections | D22: 0 | E22: 0 | F22: 67890 | K22: 985.36333 | L22: 79814.43 | N22: 11924.43 | Q22: 60986.88 | R22: -985.36333 | S22: 18827.55
A23: Véhicules neufsRev. Autres | B23: Véhicules neufs | C23: Rev. Autres | D23: 0 | E23: 0 | F23: 1460 | K23: 2.302963 | L23: 186.54 | N23: -1273.46 | Q23: 569.82 | R23: -2.302963 | S23: -383.28
A24: Véhicules neufsTotal F&I | B24: Véhicules neufs | C24: Total F&I | D24: 73 | E24: 1000 | F24: 73000 | J24: 81 | K24: 995.12988 | L24: 80605.52 | M24: 8 | N24: 7605.52 | O24: 80 | P24: 769.45875 | Q24: 61556.7 | S24: 19048.82
A25: Véhicules neufs | B25: Véhicules neufs | N25: 0.10418521 | S25: 0.30945161
A26: Véhicules neufs | B26: Véhicules neufs
A27: Véhicules neufsTotal Dépt. Neufs | B27: Véhicules neufs | C27: Total Dépt. Neufs | D27: 75 | E27: 3339.8837 | F27: 250491.28 | J27: 81 | K27: 3311.6236 | L27: 268241.51 | M27: 6 | N27: 17750.229 | O27: 85 | P27: 2990.2515 | Q27: 254171.38 | R27: -4 | S27: 14070.13
A28: Véhicules neufs | B28: Véhicules neufs | L28: 1.0708617 | M28: 0.08 | N28: 0.070861665 | R28: -0.047058824 | S28: 0.055356862
A29: Véhicules neufs | B29: Véhicules neufs
A30: Véhicules neufsDEPENSES | B30: Véhicules neufs | C30: DEPENSES
A31: Véhicules neufsComm. vendeurs | B31: Véhicules neufs | C31: Comm. vendeurs | D31: 0.32512204 | E31: 735.1035 | F31: 53662.555 | J31: 0.29871778 | K31: 645.50198 | L31: 52285.66 | N31: -1376.8954 | O31: 0.31203959 | P31: 712.28763 | Q31: 56983.01 | S31: -4697.35
A32: Véhicules neufsComm. F&I | B32: Véhicules neufs | C32: Comm. F&I | D32: 0.28 | E32: 280 | F32: 20440 | J32: 0.25000198 | K32: 248.78444 | L32: 20151.54 | N32: -288.46 | O32: 0.26999709 | P32: 207.75163 | Q32: 16620.13 | S32: 3531.41
A33: Véhicules neufsFrais de livraison | B33: Véhicules neufs | C33: Frais de livraison | E33: 115 | F33: 8395 | K33: 112.60815 | L33: 9121.26 | N33: 726.26 | P33: 95.093 | Q33: 7607.44 | S33: 1513.82
A34: Véhicules neufsService gratuit 1 | B34: Véhicules neufs | C34: Service gratuit 1 | E34: 10 | F34: 730 | K34: 0 | L34: 0 | N34: -730 | P34: 33.065625 | Q34: 2645.25 | S34: -2645.25
A35: Véhicules neufsEntretien stock | B35: Véhicules neufs | C35: Entretien stock | E35: 120.75 | F35: 8814.75 | K35: 43.995185 | L35: 3563.61 | N35: -5251.14 | P35: 79.675375 | Q35: 6374.03 | S35: -2810.42
A36: Véhicules neufsPublicité 1 | B36: Véhicules neufs | C36: Publicité 1 | E36: 57.013699 | F36: 4162 | K36: 45.389259 | L36: 3676.53 | N36: -485.47 | P36: 39.7595 | Q36: 3180.76 | S36: 495.77
A37: Véhicules neufsIntérêt de gros | B37: Véhicules neufs | C37: Intérêt de gros | E37: 560.02013 | F37: 40881.469 | K37: 273.39222 | L37: 22144.77 | N37: -18736.699 | P37: 565.70337 | Q37: 45256.27 | S37: -23111.5
A38: Véhicules neufs[...] | B38: Véhicules neufs | C38: [...] | E38: 0 | F38: 0 | K38: 0 | L38: 0 | N38: 0 | P38: 0 | Q38: 0 | S38: 0
A39: Véhicules neufs[...] | B39: Véhicules neufs | C39: [...] | E39: 0 | F39: 0 | K39: 0 | L39: 0 | N39: 0 | P39: 0 | Q39: 0 | S39: 0
A40: Véhicules neufs[...] | B40: Véhicules neufs | C40: [...] | E40: 0 | F40: 0 | K40: 0 | L40: 0 | N40: 0 | P40: 0 | Q40: 0 | S40: 0
...

Sheet Aout 2025
C1: Volks | K1: Véhicules neufs | S1: Réalisé, Août 2025
D2: X | E2: O | F2: U | J2: NB | L2: $ | O2: X | P2: O | Q2: U | V2: *** NE PAS EFFACER / Pour An Précédente ***
D3: BUDGET ORIGINAL | J3: RÉALISATION | M3: ÉCART réel / Budget | O3: ANNÉE PRÉCÉDENTE | R3: ECART (réel/ Ann.Préc.) | V3: NEUF | W3: 0.45
D4: UNITE | E4: $P/UNITÉ | F4: $PROFITS | J4: UNITÉS | K4: $P/UNITE | L4: $PROFITS | M4: UNITÉS | N4: $PROFITS | O4: UNITE | P4: $P/UNITÉ | Q4: $PROFITS | R4: UNITÉS | S4: $PROFITS | V4: USAGE | W4: 0.1
A5: Véhicules neufsVentes nettes | B5: Véhicules neufs | C5: Ventes nettes | F5: 4621342.2 | L5: 3275050 | Q5: 4621444.5 | V5: SERVICE | W5: 0.225
A6: Véhicules neufsAutos détail | B6: Véhicules neufs | C6: Autos détail | D6: 23 | E6: 1953.6492 | F6: 44933.931 | J6: 7 | K6: 639.14571 | L6: 4474.02 | M6: -16 | N6: -40459.911 | O6: 19 | P6: 1667.12 | Q6: 31675.28 | R6: -12 | S6: -27201.26 | V6: CARROSSERIE | W6: 0.025
A7: Véhicules neufsCamions détail | B7: Véhicules neufs | C7: Camions détail | D7: 61 | E7: 2435.9047 | F7: 148590.19 | J7: 56 | K7: 2079.0589 | L7: 116427.3 | M7: -5 | N7: -32162.885 | O7: 62 | P7: 2284.2913 | Q7: 141626.06 | R7: -6 | S7: -25198.76 | V7: PIECES | W7: 0.2
A8: Véhicules neufsSprinter | B8: Véhicules neufs | C8: Sprinter | D8: 0 | E8: 0 | F8: 0 | J8: 0 | K8: 0 | L8: 0 | M8: 0 | N8: 0 | O8: 0 | P8: 0 | Q8: 0 | R8: 0 | S8: 0 | W8: 1
A9: Véhicules neufsMoto détail | B9: Véhicules neufs | C9: Moto détail | D9: 0 | E9: 0 | F9: 0 | J9: 0 | K9: 0 | L9: 0 | M9: 0 | N9: 0 | O9: 0 | P9: 0 | Q9: 0 | R9: 0 | S9: 0
A10: Véhicules neufs[...] | B10: Véhicules neufs | C10: [...] | D10: 0 | E10: 0 | F10: 0 | J10: 0 | K10: 0 | L10: 0 | M10: 0 | N10: 0 | O10: 0 | P10: 0 | Q10: 0 | R10: 0 | S10: 0
A11: Véhicules neufs[...] | B11: Véhicules neufs | C11: [...] | D11: 0 | E11: 0 | F11: 0 | J11: 0 | K11: 0 | L11: 0 | M11: 0 | N11: 0 | O11: 0 | P11: 0 | Q11: 0 | R11: 0 | S11: 0
A12: Véhicules neufs[...] | B12: Véhicules neufs | C12: [...] | D12: 0 | E12: 0 | F12: 0 | J12: 0 | K12: 0 | L12: 0 | M12: 0 | N12: 0 | O12: 0 | P12: 0 | Q12: 0 | R12: 0 | S12: 0
A13: Véhicules neufsTotal Neufs | B13: Véhicules neufs | C13: Total Neufs | D13: 84 | E13: 2303.8585 | F13: 193524.12 | J13: 63 | K13: 1919.0686 | L13: 120901.32 | M13: -21 | N13: -72622.796 | O13: 81 | P13: 2139.5227 | Q13: 173301.34 | R13: -18 | S13: -52400.02
A14: Véhicules neufs | B14: Véhicules neufs | M14: -0.25 | N14: -0.37526484 | R14: -0.22222222 | S14: -0.30236362 | AD14: 20 | AE14: 1000 | AF14: 20000
A15: Véhicules neufsEx-Démos et courtoisies | B15: Véhicules neufs | C15: Ex-Démos et courtoisies | D15: 4 | E15: 1534.7521 | F15: 6139.0086 | J15: 0 | K15: 0 | L15: 0 | M15: -4 | N15: -6139.0086 | O15: 6 | P15: 1521.5767 | Q15: 9129.46 | R15: -6 | S15: -9129.46 | AD15: 25 | AE15: 800 | AF15: 20000
A16: Véhicules neufs | B16: Véhicules neufs
A17: Véhicules neufsFlottes | B17: Véhicules neufs | C17: Flottes | D17: 2 | E17: 2393.8521 | F17: 4787.7042 | J17: 3 | K17: 626.18667 | L17: 1878.56 | M17: 1 | N17: -2909.1442 | O17: 1 | P17: 1402.08 | Q17: 1402.08 | R17: 2 | S17: 476.48
A18: Véhicules neufs | B18: Véhicules neufs
A19: Véhicules neufsRachat bail | B19: Véhicules neufs | C19: Rachat bail | D19: 0 | E19: 0 | F19: 9350 | L19: 11637.42 | N19: 2287.42 | Q19: 4315 | R19: 0 | S19: 7322.42
A20: Véhicules neufs | B20: Véhicules neufs
A21: Véhicules neufsRev. Finances | B21: Véhicules neufs | C21: Rev. Finances | D21: 0 | E21: 0 | F21: 4400 | K21: 0 | L21: 0 | N21: -4400 | Q21: 0 | R21: 0 | S21: 0
A22: Véhicules neufsRev. Protections | B22: Véhicules neufs | C22: Rev. Protections | D22: 0 | E22: 0 | F22: 81840 | K22: 960.30048 | L22: 60498.93 | N22: -21341.07 | Q22: 76578.39 | R22: -960.30048 | S22: -16079.46
A23: Véhicules neufsRev. Autres | B23: Véhicules neufs | C23: Rev. Autres | D23: 0 | E23: 0 | F23: 1760 | K23: 0 | L23: 0 | N23: -1760 | Q23: 0 | R23: 0 | S23: 0
A24: Véhicules neufsTotal F&I | B24: Véhicules neufs | C24: Total F&I | D24: 88 | E24: 1000 | F24: 88000 | J24: 63 | K24: 960.30048 | L24: 60498.93 | M24: -25 | N24: -27501.07 | O24: 87 | P24: 880.21138 | Q24: 76578.39 | S24: -16079.46
A25: Véhicules neufs | B25: Véhicules neufs | N25: -0.31251216 | S25: -0.20997386
A26: Véhicules neufs | B26: Véhicules neufs
A27: Véhicules neufsTotal Dépt. Neufs | B27: Véhicules neufs | C27: Total Dépt. Neufs | D27: 90 | E27: 3353.3425 | F27: 301800.83 | J27: 66 | K27: 2953.2762 | L27: 194916.23 | M27: -24 | N27: -106884.6 | O27: 88 | P27: 3008.2531 | Q27: 264726.27 | R27: -22 | S27: -69810.04
A28: Véhicules neufs | B28: Véhicules neufs | L28: 0.64584392 | M28: -0.26666667 | N28: -0.35415608 | R28: -0.25 | S28: -0.26370651
A29: Véhicules neufs | B29: Véhicules neufs
A30: Véhicules neufsDEPENSES | B30: Véhicules neufs | C30: DEPENSES
A31: Véhicules neufsComm. vendeurs | B31: Véhicules neufs | C31: Comm. vendeurs | D31: 0.32397102 | E31: 735.05757 | F31: 64685.066 | J31: 0.29473827 | K31: 574.41159 | L31: 36187.93 | N31: -28497.136 | O31: 0.34685797 | P31: 732.91839 | Q31: 63763.9 | S31: -27575.97
A32: Véhicules neufsComm. F&I | B32: Véhicules neufs | C32: Comm. F&I | D32: 0.28 | E32: 280 | F32: 24640 | J32: 0.8234187 | K32: 790.72937 | L32: 49815.95 | N32: 25175.95 | O32: 0.26932885 | P32: 237.06632 | Q32: 20624.77 | S32: 29191.18
A33: Véhicules neufsFrais de livraison | B33: Véhicules neufs | C33: Frais de livraison | E33: 115 | F33: 10120 | K33: 50.647937 | L33: 3190.82 | N33: -6929.18 | P33: 120.29333 | Q33: 10465.52 | S33: -7274.7
A34: Véhicules neufsService gratuit 1 | B34: Véhicules neufs | C34: Service gratuit 1 | E34: 10 | F34: 880 | K34: 0 | L34: 0 | N34: -880 | P34: 23.456092 | Q34: 2040.68 | S34: -2040.68
A35: Véhicules neufsEntretien stock | B35: Véhicules neufs | C35: Entretien stock | E35: 120.75 | F35: 10626 | K35: 123.11175 | L35: 7756.04 | N35: -2869.96 | P35: 65.982069 | Q35: 5740.44 | S35: 2015.6
A36: Véhicules neufsPublicité 1 | B36: Véhicules neufs | C36: Publicité 1 | E36: 30.25 | F36: 2662 | K36: 95.550635 | L36: 6019.69 | N36: 3357.69 | P36: 8.5896552 | Q36: 747.3 | S36: 5272.39
A37: Véhicules neufsIntérêt de gros | B37: Véhicules neufs | C37: Intérêt de gros | E37: 413.84576 | F37: 36418.427 | K37: 390.07746 | L37: 24574.88 | N37: -11843.547 | P37: 400.05483 | Q37: 34804.77 | S37: -10229.89
A38: Véhicules neufs[...] | B38: Véhicules neufs | C38: [...] | E38: 0 | F38: 0 | K38: 0 | L38: 0 | N38: 0 | P38: 0 | Q38: 0 | S38: 0
A39: Véhicules neufs[...] | B39: Véhicules neufs | C39: [...] | E39: 0 | F39: 0 | K39: 0 | L39: 0 | N39: 0 | P39: 0 | Q39: 0 | S39: 0
A40: Véhicules neufs[...] | B40: Véhicules neufs | C40: [...] | E40: 0 | F40: 0 | K40: 0 | L40: 0 | N40: 0 | P40: 0 | Q40: 0 | S40: 0
...

Sheet Septembre 2025
C1: Volks | K1: Véhicules neufs | S1: Réalisé, Septembre 2025
D2: X | E2: O | F2: U | J2: NB | L2: $ | O2: X | P2: O | Q2: U | V2: *** NE PAS EFFACER / Pour An Précédente ***
D3: BUDGET ORIGINAL | J3: RÉALISATION | M3: ÉCART réel / Budget | O3: ANNÉE PRÉCÉDENTE | R3: ECART (réel/ Ann.Préc.) | V3: NEUF | W3: 0.45
D4: UNITE | E4: $P/UNITÉ | F4: $PROFITS | J4: UNITÉS | K4: $P/UNITE | L4: $PROFITS | M4: UNITÉS | N4: $PROFITS | O4: UNITE | P4: $P/UNITÉ | Q4: $PROFITS | R4: UNITÉS | S4: $PROFITS | V4: USAGE | W4: 0.1
A5: Véhicules neufsVentes nettes | B5: Véhicules neufs | C5: Ventes nettes | F5: 3359976.1 | L5: 3303841.7 | Q5: 2442838.5 | V5: SERVICE | W5: 0.225
A6: Véhicules neufsAutos détail | B6: Véhicules neufs | C6: Autos détail | D6: 16 | E6: 1953.6492 | F6: 31258.387 | J6: 7 | K6: 688.43143 | L6: 4819.02 | M6: -9 | N6: -26439.367 | O6: 16 | P6: 1640.0056 | Q6: 26240.09 | R6: -9 | S6: -21421.07 | V6: CARROSSERIE | W6: 0.025
A7: Véhicules neufsCamions détail | B7: Véhicules neufs | C7: Camions détail | D7: 44 | E7: 2435.9047 | F7: 107179.81 | J7: 56 | K7: 2636.2429 | L7: 147629.6 | M7: 12 | N7: 40449.794 | O7: 26 | P7: 2080.4762 | Q7: 54092.38 | R7: 30 | S7: 93537.22 | V7: PIECES | W7: 0.2
A8: Véhicules neufsSprinter | B8: Véhicules neufs | C8: Sprinter | D8: 0 | E8: 0 | F8: 0 | J8: 0 | K8: 0 | L8: 0 | M8: 0 | N8: 0 | O8: 0 | P8: 0 | Q8: 0 | R8: 0 | S8: 0 | W8: 1
A9: Véhicules neufsMoto détail | B9: Véhicules neufs | C9: Moto détail | D9: 0 | E9: 0 | F9: 0 | J9: 0 | K9: 0 | L9: 0 | M9: 0 | N9: 0 | O9: 0 | P9: 0 | Q9: 0 | R9: 0 | S9: 0
A10: Véhicules neufs[...] | B10: Véhicules neufs | C10: [...] | D10: 0 | E10: 0 | F10: 0 | J10: 0 | K10: 0 | L10: 0 | M10: 0 | N10: 0 | O10: 0 | P10: 0 | Q10: 0 | R10: 0 | S10: 0
A11: Véhicules neufs[...] | B11: Véhicules neufs | C11: [...] | D11: 0 | E11: 0 | F11: 0 | J11: 0 | K11: 0 | L11: 0 | M11: 0 | N11: 0 | O11: 0 | P11: 0 | Q11: 0 | R11: 0 | S11: 0
A12: Véhicules neufs[...] | B12: Véhicules neufs | C12: [...] | D12: 0 | E12: 0 | F12: 0 | J12: 0 | K12: 0 | L12: 0 | M12: 0 | N12: 0 | O12: 0 | P12: 0 | Q12: 0 | R12: 0 | S12: 0
A13: Véhicules neufsTotal Neufs | B13: Véhicules neufs | C13: Total Neufs | D13: 60 | E13: 2307.3032 | F13: 138438.19 | J13: 63 | K13: 2419.8194 | L13: 152448.62 | M13: 3 | N13: 14010.427 | O13: 42 | P13: 1912.6779 | Q13: 80332.47 | R13: 21 | S13: 72116.15
A14: Véhicules neufs | B14: Véhicules neufs | M14: 0.05 | N14: 0.10120348 | R14: 0.5 | S14: 0.89772106 | AD14: 20 | AE14: 1000 | AF14: 20000
A15: Véhicules neufsEx-Démos et courtoisies | B15: Véhicules neufs | C15: Ex-Démos et courtoisies | D15: 3 | E15: 1534.7521 | F15: 4604.2564 | J15: 1 | K15: 1212.34 | L15: 1212.34 | M15: -2 | N15: -3391.9164 | O15: 3 | P15: 2567.51 | Q15: 7702.53 | R15: -2 | S15: -6490.19 | AD15: 25 | AE15: 800 | AF15: 20000
A16: Véhicules neufs | B16: Véhicules neufs
A17: Véhicules neufsFlottes | B17: Véhicules neufs | C17: Flottes | D17: 2 | E17: 2393.8521 | F17: 4787.7042 | J17: 3 | K17: 626.18667 | L17: 1878.56 | M17: 1 | N17: -2909.1442 | O17: 1 | P17: 4920.64 | Q17: 4920.64 | R17: 2 | S17: -3042.08
A18: Véhicules neufs | B18: Véhicules neufs
A19: Véhicules neufsRachat bail | B19: Véhicules neufs | C19: Rachat bail | D19: 0 | E19: 0 | F19: 6800 | L19: 11637.42 | N19: 4837.42 | Q19: 14800 | R19: 0 | S19: -3162.58
A20: Véhicules neufs | B20: Véhicules neufs
A21: Véhicules neufsRev. Finances | B21: Véhicules neufs | C21: Rev. Finances | D21: 0 | E21: 0 | F21: 3150 | K21: 0 | L21: 0 | N21: -3150 | Q21: 0 | R21: 0 | S21: 0
A22: Véhicules neufsRev. Protections | B22: Véhicules neufs | C22: Rev. Protections | D22: 0 | E22: 0 | F22: 58590 | K22: 952.71766 | L22: 60973.93 | N22: 2383.93 | Q22: 45910.53 | R22: -952.71766 | S22: 15063.4
A23: Véhicules neufsRev. Autres | B23: Véhicules neufs | C23: Rev. Autres | D23: 0 | E23: 0 | F23: 1260 | K23: 0 | L23: 0 | N23: -1260 | Q23: 1628.24 | R23: 0 | S23: -1628.24
A24: Véhicules neufsTotal F&I | B24: Véhicules neufs | C24: Total F&I | D24: 63 | E24: 1000 | F24: 63000 | J24: 64 | K24: 952.71766 | L24: 60973.93 | M24: 1 | N24: -2026.07 | O24: 45 | P24: 1056.4171 | Q24: 47538.77 | S24: 13435.16
A25: Véhicules neufs | B25: Véhicules neufs | N25: -0.032159841 | S25: 0.2826148
A26: Véhicules neufs | B26: Véhicules neufs
A27: Véhicules neufsTotal Dépt. Neufs | B27: Véhicules neufs | C27: Total Dépt. Neufs | D27: 65 | E27: 3348.1562 | F27: 217630.15 | J27: 67 | K27: 3405.2369 | L27: 228150.87 | M27: 2 | N27: 10520.717 | O27: 46 | P27: 3375.9654 | Q27: 155294.41 | R27: 21 | S27: 72856.46
A28: Véhicules neufs | B28: Véhicules neufs | L28: 1.0483422 | M28: 0.030769231 | N28: 0.048342184 | R28: 0.45652174 | S28: 0.46915056
A29: Véhicules neufs | B29: Véhicules neufs
A30: Véhicules neufsDEPENSES | B30: Véhicules neufs | C30: DEPENSES
A31: Véhicules neufsComm. vendeurs | B31: Véhicules neufs | C31: Comm. vendeurs | D31: 0.33053742 | E31: 750.49018 | F31: 47280.881 | J31: 0.27478502 | K31: 667.81141 | L31: 42739.93 | N31: -4540.9513 | O31: 0.32887988 | P31: 679.36089 | Q31: 30571.24 | S31: 12168.69
A32: Véhicules neufsComm. F&I | B32: Véhicules neufs | C32: Comm. F&I | D32: 0.28 | E32: 280 | F32: 17640 | J32: 0.26000358 | K32: 247.71 | L32: 15853.44 | N32: -1786.56 | O32: 0.2977738 | P32: 314.57333 | Q32: 14155.8 | S32: 1697.64
A33: Véhicules neufsFrais de livraison | B33: Véhicules neufs | C33: Frais de livraison | E33: 115 | F33: 7245 | K33: 130.02187 | L33: 8321.4 | N33: 1076.4 | P33: 123.12511 | Q33: 5540.63 | S33: 2780.77
A34: Véhicules neufsService gratuit 1 | B34: Véhicules neufs | C34: Service gratuit 1 | E34: 10 | F34: 630 | K34: 0 | L34: 0 | N34: -630 | P34: 36.238889 | Q34: 1630.75 | S34: -1630.75
A35: Véhicules neufsEntretien stock | B35: Véhicules neufs | C35: Entretien stock | E35: 120.75 | F35: 7607.25 | K35: 121.18812 | L35: 7756.04 | N35: 148.79 | P35: 174.15711 | Q35: 7837.07 | S35: -81.03
A36: Véhicules neufsPublicité 1 | B36: Véhicules neufs | C36: Publicité 1 | E36: 81.936508 | F36: 5162 | K36: 124.21734 | L36: 7949.91 | N36: 2787.91 | P36: 180.94756 | Q36: 8142.64 | S36: -192.73
A37: Véhicules neufsIntérêt de gros | B37: Véhicules neufs | C37: Intérêt de gros | E37: 603.57336 | F37: 38025.122 | K37: 37.670469 | L37: 2410.91 | N37: -35614.212 | P37: 678.81778 | Q37: 30546.8 | S37: -28135.89
A38: Véhicules neufs[...] | B38: Véhicules neufs | C38: [...] | E38: 0 | F38: 0 | K38: 0 | L38: 0 | N38: 0 | P38: 0 | Q38: 0 | S38: 0
A39: Véhicules neufs[...] | B39: Véhicules neufs | C39: [...] | E39: 0 | F39: 0 | K39: 0 | L39: 0 | N39: 0 | P39: 0 | Q39: 0 | S39: 0
A40: Véhicules neufs[...] | B40: Véhicules neufs | C40: [...] | E40: 0 | F40: 0 | K40: 0 | L40: 0 | N40: 0 | P40: 0 | Q40: 0 | S40: 0
...

Sheet END
