Workbook

Sheet Suivi fin d'année
A1: Type | B1: #Compte | C1: Description | D1: fdm | E1: Solde au livre 2020 | F1: Notes | G1: Écart à concilier | H1: To do 1 | I1: To do 2
A2: Cash | B2: 1102 | C2: BANQUE DE COMMERCE C/C | D2: =VLOOKUP(B2,BV!A:E,5,FALSE) -> 2208806.1 | E2: 2687686.6 | F2: reclass paie 2503
A3: Cash | B3: 1142 | C3: ARGENT IN TRUST | D3: =VLOOKUP(B3,BV!A:E,5,FALSE) -> #N/A | E3: 0
A4: Cash | B4: 1182 | C4: PETITE CAISSE | D4: =VLOOKUP(B4,BV!A:E,5,FALSE) -> 50.2 | E4: 150.2
A5: AR | B5: 1202 | C5: CONTRATS EN TRANSIT | D5: =VLOOKUP(B5,BV!A:E,5,FALSE) -> 2230376.1 | E5: 185749.87
A6: AR | B6: 1302 | C6: RECEVABLE-CLIENT-VEHICULE | D6: =VLOOKUP(B6,BV!A:E,5,FALSE) -> 20771.5 | E6: -40954.26
A7: AR | B7: 1303 | C7: RECEVABLES LPA ET AU GROS | D7: =VLOOKUP(B7,BV!A:E,5,FALSE) -> 195957.92 | E7: 129272.5
A8: AR | B8: 1304 | C8: RECEVABLES PIECES & SERVICE | D8: =VLOOKUP(B8,BV!A:E,5,FALSE) -> 56720.5 | E8: 77161.54
A9: AR | B9: 1305 | C9: RECEVABLES CARROSSERIE | D9: =VLOOKUP(B9,BV!A:E,5,FALSE) -> 49488.46 | E9: 22041.85
A10: AR MANUF | B10: 1312 | C10: RESEVE VOLKS | D10: =VLOOKUP(B10,BV!A:E,5,FALSE) -> 49411 | E10: -15530 | F10: PDI et holdback recevables manuf | G10: 53570 paye en double 2019
A11: AR MANUF | B11: 1332 | C11: RECLAM. RECEVABLE-GARANTIE | D11: =VLOOKUP(B11,BV!A:E,5,FALSE) -> 41335.66 | E11: 59126.78 | F11: claim service - suivi fait par Manfai Fan | G11: $4,400 + 90 jours ok
A12: AR | B12: 1340 | C12: GARANTIE PPM | D12: =VLOOKUP(B12,BV!A:E,5,FALSE) -> 69.81 | E12: 16307.01 | F12: LGM prolonge plus audi approuve | G12: res20 éga; + 90 jours $4400
A13: AR MANUF | B13: 1352 | C13: RECEV. MANUFACTURIER VOLKS | D13: =VLOOKUP(B13,BV!A:E,5,FALSE) -> 212907.72 | E13: 161978.07
A14: AR | B14: 1364 | C14: A RECEVOIR LAR | D14: =VLOOKUP(B14,BV!A:E,5,FALSE) -> #N/A | E14: 0 | F14: a 0
A15: AR | B15: 1372 | C15: TAXES DE VENTES A RECEVOIR | D15: =VLOOKUP(B15,BV!A:E,5,FALSE) -> 112961.83 | E15: 53960.13 | F15: Amendé soumis pour prélèvement en trop pour avril qui avait été payé avec Juin
A16: AR | B16: 1399 | C16: RESERVE CREANCE DOUTEUSES | D16: =VLOOKUP(B16,BV!A:E,5,FALSE) -> -45000 | E16: -45000 | F16: 25k corpo et 20k reseve boni piece recu an trop
B17: 1402 | C17: VEHIC. NEUFS VOLKS | D17: =VLOOKUP(B17,BV!A:E,5,FALSE) -> 5578101.8 | E17: 3678703.2
B18: 1403 | C18: BRUISING VOLKS VEH. NEUFS | D18: =VLOOKUP(B18,BV!A:E,5,FALSE) -> -125014.36 | E18: -132337.5
B19: 1413 | C19: BRUISING USED CAR | D19: =VLOOKUP(B19,BV!A:E,5,FALSE) -> -30432.58 | E19: -15000
B20: 1423 | D20: =VLOOKUP(B20,BV!A:E,5,FALSE) -> -17732.75 | E20: -15404.61
B21: 1433 | D21: =VLOOKUP(B21,BV!A:E,5,FALSE) -> -28856.09 | E21: -33322.31
B22: 1416 | C22: INV. VEH. USAGE VW | D22: =VLOOKUP(B22,BV!A:E,5,FALSE) -> 1576844.3 | E22: 1275119.9
B23: 1442 | C23: PIECES & ACCESSOIRES NEUFS | D23: =VLOOKUP(B23,BV!A:E,5,FALSE) -> 135376.55 | E23: 259079.71
B24: 1448 | C24: AUTRES MARQUES P&A | D24: =VLOOKUP(B24,BV!A:E,5,FALSE) -> -9.14 | E24: 329.48
B25: 1452 | C25: PNEUS | D25: =VLOOKUP(B25,BV!A:E,5,FALSE) -> 196930.05 | E25: 130332.05
B26: 1456 | C26: PIECES VW NON ORIGINE | D26: =VLOOKUP(B26,BV!A:E,5,FALSE) -> 36227.3 | E26: 30227.87
B27: 1472 | C27: WIP M-O VW | D27: =VLOOKUP(B27,BV!A:E,5,FALSE) -> 9187.7 | E27: 16790.64 | F27: labour sur des bon pas ferme en fin de mois
B28: 1474 | C28: INVENTAIRE SOUS-TRAITANTS | D28: =VLOOKUP(B28,BV!A:E,5,FALSE) -> -3164.81 | E28: 17257.13 | F28: factures de fournisseurs pas encore ferme sur des bon de travail
B29: 1492 | C29: CARBURANT, HUILE, GRAISSE | D29: =VLOOKUP(B29,BV!A:E,5,FALSE) -> 23431.94 | E29: 26215.66
B30: 1498 | C30: AUTRES INVENTAIRES | D30: =VLOOKUP(B30,BV!A:E,5,FALSE) -> 55.02 | E30: 0 | F30: reclass to 1456
B31: 1502 | C31: FPA PUB.VEHICULES NEUFS | D31: =VLOOKUP(B31,BV!A:E,5,FALSE) -> -2911.69 | E31: 0 | F31: 0
B32: 1504 | C32: PUBLICITE VEH USAGES | D32: =VLOOKUP(B32,BV!A:E,5,FALSE) -> #N/A | E32: 0 | F32: 0
B33: 1506 | C33: FPA PUBLICITE SERVICE | D33: =VLOOKUP(B33,BV!A:E,5,FALSE) -> -4837.66 | E33: 0 | F33: 0
B34: 1508 | C34: FPA PUBLICITE PIECES | D34: =VLOOKUP(B34,BV!A:E,5,FALSE) -> #N/A | E34: 0
B35: 1510 | C35: DIAMOND KOTE (NANO) | D35: =VLOOKUP(B35,BV!A:E,5,FALSE) -> 3846.95 | E35: 3221.95 | F35: INVENTAIRE NANO OK JESS VA VALIDER APRES
B36: 1520 | C36: FPA IMMATRICULATION | D36: =VLOOKUP(B36,BV!A:E,5,FALSE) -> 6779.64 | E36: 2925 | F36: meme chiffre que l'année passé plus bas | G36: cobien de x et f x annuel
B37: 1522 | C37: ASSURANCE DALE PARIZEAU | D37: =VLOOKUP(B37,BV!A:E,5,FALSE) -> #N/A | E37: 0 | F37: 0
B38: 1528 | C38: FPA DEDUCTIBLE ASSURANCE | D38: =VLOOKUP(B38,BV!A:E,5,FALSE) -> #N/A | E38: 0 | F38: 0
B39: 1530 | C39: FPA PAPETERIE | D39: =VLOOKUP(B39,BV!A:E,5,FALSE) -> #N/A | E39: 2554.43 | F39: meme chiffre que l'année passé plus bas
B40: 1532 | C40: FPA C.C.A.M.Q. | D40: =VLOOKUP(B40,BV!A:E,5,FALSE) -> 1769.3 | E40: 0 | F40: 0
...

Sheet RES cédule
A1: Réserve fin d'année
D2: Réserve | E2: a conserver | F2: Ajust a faire | G2: GL
A3: 1302 | C3: =VLOOKUP(A3,'Suivi fin d''année'!B:C,2,FALSE) -> RECEVABLE-CLIENT-VEHICULE | D3: -3968.08 | E3: =-D3 -> 3968.08 | F3: =SUM(D3:E3) -> 0
A4: 2285 | C4: =VLOOKUP(A4,'Suivi fin d''année'!B:C,2,FALSE) -> PROTECTIONS A PAYER | D4: -10655.57 | E4: =-D4 -> 10655.57 | F4: =SUM(D4:E4) -> 0
A5: 2287 | C5: =VLOOKUP(A5,'Suivi fin d''année'!B:C,2,FALSE) -> A PAYER INVAPLAN | D5: -371.29 | E5: 0 | F5: =SUM(D5:E5) -> -371.29 | G5: F & I
A6: 1202 | C6: =VLOOKUP(A6,'Suivi fin d''année'!B:C,2,FALSE) -> CONTRATS EN TRANSIT | D6: -21681.71 | E6: 25000 | F6: =SUM(D6:E6) -> 3318.29 | G6: 1399 | H6: neuf
A7: 2401 | C7: =VLOOKUP(A7,'Suivi fin d''année'!B:C,2,FALSE) -> DEPOTS FIDUCIE-VENTE CLIENTS | D7: -1325 | E7: 0 | F7: =SUM(D7:E7) -> -1325 | G7: Neuf
A8: 1402 | C8: =VLOOKUP(A8,'Suivi fin d''année'!B:C,2,FALSE) -> VEHIC. NEUFS VOLKS | D8: -1852.75 | E8: 0 | F8: =SUM(D8:E8) -> -1852.75 | G8: Neuf
A9: 1416 | C9: =VLOOKUP(A9,'Suivi fin d''année'!B:C,2,FALSE) -> INV. VEH. USAGE VW | D9: -38558.48 | E9: 0 | F9: =SUM(D9:E9) -> -38558.48 | G9: Used
A10: 1806 | C10: =VLOOKUP(A10,'Suivi fin d''année'!B:C,2,FALSE) -> FINANCEMENT RECEVABLE | D10: 0 | E10: 0 | F10: =SUM(D10:E10) -> 0
A11: 1332 | C11: =VLOOKUP(A11,'Suivi fin d''année'!B:C,2,FALSE) -> RECLAM. RECEVABLE-GARANTIE | D11: -6503.3 | E11: 0 | F11: =SUM(D11:E11) -> -6503.3 | G11: service
A12: 1352 | C12: =VLOOKUP(A12,'Suivi fin d''année'!B:C,2,FALSE) -> RECEV. MANUFACTURIER VOLKS | D12: -25600.8 | E12: 25600.8 | F12: =SUM(D12:E12) -> 0
A13: 1312 | C13: =VLOOKUP(A13,'Suivi fin d''année'!B:C,2,FALSE) -> RESEVE VOLKS | D13: -53570 | E13: =-D13 -> 53570 | F13: =SUM(D13:E13) -> 0
D14: =SUM(D3:D13) -> -164086.98 | F14: =SUM(F3:F13) -> -45292.53
E16: F&I | F16: =F5 -> -371.29 | G16: 9170
E17: Neuf | F17: =F6+F7+F8 -> 140.54 | G17: 5139
E18: Used | F18: =+F9 -> -38558.48 | G18: 5291
E19: Service | F19: =+F11 -> -6503.3 | G19: 6403
F20: =SUM(F16:F19) -> -45292.53

Sheet Réserve BEFORE
B1: Solde réserve | C1: Réserve nécéssaire | D1: QG | E1: Ajust à faire | F1: Notes
A2: CORRECTION FERIE A PAYER | E2: =SUM(B2:D2) -> 0
A3: Recevable programme manufacturier | B3: -25600.8 | C3: 25600.8 | E3: =SUM(B3:D3) -> 0 | F3: TOT estimé
A4: Mauvaise créances pièce et service | B4: -45000 | C4: =(13233*0.5)+13383.5 -> 20000 | D4: 25000 | E4: =SUM(B4:D4) -> 0 | F4: 50% 90 jours + et ristournce piece prise mais pas recu
A5: Réserve neuf | B5: -121526.96 | C5: 37000 | D5: 75000 | E5: =SUM(B5:D5) -> -9526.96
A6: Ajustement prix piece | B6: -1315.08 | C6: 1315.08 | E6: =SUM(B6:D6) -> 0
A7: Réserve demo | B7: -37481 | C7: 15405 | E7: =SUM(B7:D7) -> -22076 | F7: 6 demos 2% par mois sur route
A8: Réserve courtoisie | B8: -33322 | C8: 33322 | E8: =SUM(B8:D8) -> 0 | F8: 21 court 2% par mois sur route
A9: Réserve renouvellement | B9: -20412.5 | E9: =SUM(B9:D9) -> -20412.5 | G9: MOVE TO RESERVE NEUF
A10: Réserve usagé | B10: -18940.14 | C10: 15000 | E10: =SUM(B10:D10) -> -3940.14
A11: Réserve garantie légale | B11: -821.29 | C11: 5000 | E11: =SUM(B11:D11) -> 4178.71
A12: Boni VP DG | B12: -26252 | D12: 26252 | E12: =SUM(B12:D12) -> 0
B13: -350350.63 | C13: =SUM(C2:C12) -> 152642.88 | D13: =SUM(D2:D12) -> 126252 | E13: =SUM(E2:E12) -> -51776.89
D17: TO PROFIT | E17: 9526.96
E18: 3940.14
E19: 17897.29
E20: =SUM(E17:E19) -> 31364.39
D22: VAR | E22: =E13+E20 -> -20412.5 | F22: RENOUVELLEMENT KEPT MOVED TO RESERVE NEUF

Sheet Réserve FINAL
B1: Solde réserve | C1: QG | D1: VW
A2: CORRECTION FERIE A PAYER | D2: =SUM(B2:C2) -> 0
A3: Recevable programme manufacturier | B3: ='RES cédule'!D12 -> -25600.8 | D3: =SUM(B3:C3) -> -25600.8
A4: Mauvaise créances pièce et service | B4: ='Suivi fin d''année'!D16 -> -45000 | C4: 25000 | D4: =SUM(B4:C4) -> -20000
A5: Réserve neuf | B5: ='Suivi fin d''année'!D18 -> -125014.36 | C5: 75000 | D5: =SUM(B5:C5) -> -50014.36
A6: Réserve demo | B6: ='Suivi fin d''année'!D20 -> -17732.75 | D6: =SUM(B6:C6) -> -17732.75
A7: Réserve courtoisie | B7: ='Suivi fin d''année'!D21 -> -28856.09 | D7: =SUM(B7:C7) -> -28856.09
A8: Réserve renouvellement | B8: ='Suivi fin d''année'!D90 -> -10400 | D8: =SUM(B8:C8) -> -10400
A9: Réserve usagé | B9: ='Suivi fin d''année'!D19 -> -30432.58 | D9: =SUM(B9:C9) -> -30432.58
A10: Réserve garantie légale | B10: ='Suivi fin d''année'!D88 -> -6441.96 | D10: =SUM(B10:C10) -> -6441.96
A11: Boni VP DG | B11: -61252.01 | D11: =SUM(B11:C11) -> -61252.01 | E11: due a Audi $16,857.67
A12: Préavis (2503) | B12: -14540.93 | C12: -14540.93 | D12: =SUM(B12:C12) -> -29081.86
A13: Salaire a payer (2503) | B13: -10000 | D13: =SUM(B13:C13) -> -10000
A14: Dépense varia | B14: -22187 | D14: =SUM(B14:C14) -> -22187
A15: Carte privilege piece | B15: ='Suivi fin d''année'!D104 -> -19603.39 | D15: =SUM(B15:C15) -> -19603.39
B18: =SUM(B2:B17) -> -417061.87 | C18: =SUM(C2:C17) -> 85459.07 | D18: =SUM(D2:D17) -> -331602.8

Sheet BV
A1: #Compte | B1: Description | C1: Solde d'ouverture | D1: Solde courant | E1: Solde de fin | F1: Type compte | G1: #Groupe | H1: Préfixe | I1: CUC/Mémo solde début | J1: CUC/Mémo solde actuel | K1: CUC/Mémo solde fin | L1: AT Sort
A2: 1102 | B2: BANQUE DE COMMERCE C/C | C2: 2525466.3 | D2: -316660.2 | E2: 2208806.1 | F2: 2-Actifs | G2: 1102 | L2: 1
A3: 1182 | B3: PETITE CAISSE | C3: 150.2 | D3: -100 | E3: 50.2 | F3: 2-Actifs | G3: 1102 | L3: 1
A4: 1202 | B4: CONTRATS EN TRANSIT | C4: 1823359.5 | D4: 407016.56 | E4: 2230376.1 | F4: 2-Actifs | G4: 1202 | L4: 1
A5: 1302 | B5: RECEVABLE-CLIENT-VEHICULE | C5: 19471.49 | D5: 1300.01 | E5: 20771.5 | F5: 2-Actifs | G5: 1302 | L5: 1
A6: 1303 | B6: RECEVABLES LPA ET AU GROS | C6: 383976.36 | D6: -188018.44 | E6: 195957.92 | F6: 2-Actifs | G6: 1302 | L6: 1
A7: 1304 | B7: RECEVABLES PIECES & SERVICE | C7: 38128.36 | D7: 18592.14 | E7: 56720.5 | F7: 2-Actifs | G7: 1304 | L7: 1
A8: 1305 | B8: RECEVABLES CARROSSERIE | C8: 28649.41 | D8: 20839.05 | E8: 49488.46 | F8: 2-Actifs | G8: 1304 | L8: 1
A9: 1312 | B9: RESEVE VOLKS | C9: 101308 | D9: -51897 | E9: 49411 | F9: 2-Actifs | G9: 1314 | L9: 1
A10: 1332 | B10: RECLAM. RECEVABLE-GARANTIE | C10: 135386.41 | D10: -94050.75 | E10: 41335.66 | F10: 2-Actifs | G10: 1332 | L10: 1
A11: 1340 | B11: GARANTIE PPM | C11: 4402.72 | D11: -4332.91 | E11: 69.81 | F11: 2-Actifs | G11: 1382 | L11: 1
A12: 1352 | B12: RECEV. MANUFACTURIER VOLKS | C12: 31105.98 | D12: 181801.74 | E12: 212907.72 | F12: 2-Actifs | G12: 1314 | L12: 1
A13: 1372 | B13: TAXES DE VENTES A RECEVOIR | C13: 53960.13 | D13: 59001.7 | E13: 112961.83 | F13: 2-Actifs | G13: 1372 | L13: 1
... A91: 2901 | B91: RESERVE CARTES PRIVILEGE | C91: -23392.41 | D91: 3789.02 | E91: -19603.39 | F91: 3-Passifs | G91: 2901 | L91: 2

Sheet 1202
A1: #Contrôle | B1: Description | C1: Total | D1: 1202 | E1: Jours | F1: NIV | G1: NIV-6 derniers | H1: Remarques
A2: RES20 | C2: -21681.71 | D2: -21681.71 | E2: 43
A3: 90788 | B3: EMILE C CHAMPIGNY | C3: 16711.79 | D3: 16711.79 | E3: 14
A4: 90839 | B4: PRATIK MADAN KULKARNI | C4: 9729.62 | D4: 9729.62 | E4: 2
A5: 90816 | B5: JONATHAN GAD AMAR | C5: 46335.99 | D5: 46335.99 | E5: 0 | H5: 1ER PMT
A6: 90832 | B6: GILLES BRISSON | C6: 52018.91 | D6: 52018.91 | E6: 0
A7: 90847 | B7: SABRINA SAVARD | C7: 19905.26 | D7: 19905.26 | E7: 0
A8: 90854 | B8: JACOB DORAIS | C8: 41048.3 | D8: 41048.3 | E8: 0

Sheet 1302
A1: #Contrôle | B1: Description | C1: Total | D1: 1302 | E1: Jours | F1: NIV | G1: NIV-6 derniers
A2: RES20 | C2: -7816.83 | D2: -7816.83 | E2: 315
A3: 88911 | B3: EDITH LAPLANTE | C3: 1355.91 | D3: 1355.91 | E3: 286 | G3: a risk | H3: a recevoir ass remplacement mais retrouve pas dossier
A4: 4826 | B4: PARK AVENUE AUDI | C4: -22326.42 | D4: -22326.42 | E4: 85 | H4: 0 en janvier
A5: 90379 | B5: MELANIE GUIGNARD | C5: 4680 | D5: 4680 | E5: 64 | H5: depot de securite
A6: 90703 | B6: CHRISTINA PAIEMENT | C6: 894 | D6: 894 | E6: 31 | H6: reboursement ssq
A7: 90688 | B7: DIDIER GARCIA CAPOTE | C7: 1264.73 | D7: 1264.73 | E7: 31
A8: 90686 | B8: STE-FOY HYUNDAI | C8: -19014.08 | D8: -19014.08 | E8: 24 | H8: vente en janvier
A9: 30521 | B9: MINI BROSSARD | C9: -671.23 | D9: -671.23 | E9: 24
A10: 90704 | B10: OUMAMA ISMAILI | C10: 400 | D10: 400 | E10: 20
A11: 90789 | B11: XAVIER DUGUAY-MERCIER | C11: -367.92 | D11: -367.92 | E11: 15
A12: 90836 | B12: GARRY LYNCH | C12: 5130 | D12: 5130 | E12: 8
A13: 80761 | B13: VINCENT CUTILLAS | C13: -10896.4 | D13: -10896.4 | E13: 2
A14: 90839 | B14: PRATIK MADAN KULKARNI | C14: -1731.61 | D14: -1731.61 | E14: 2
A15: 88370 | B15: IUSTIN-STEFAN DANULET | C15: -3679.48 | D15: -3679.48 | E15: 0
A16: 90854 | B16: JACOB DORAIS | C16: -3297.98 | D16: -3297.98 | E16: 0
A17: 86132 | B17: CHARLES GIRARD | C17: -191.28 | D17: -191.28 | E17: 0
A18: 90816 | B18: JONATHAN GAD AMAR | C18: -83.79 | D18: -83.79 | E18: 0
A19: 89649 | B19: LYNE RIOUX | C19: 766.71 | D19: 766.71 | E19: 0
A20: 90847 | B20: SABRINA SAVARD | C20: 4169.9 | D20: 4169.9 | E20: 0
A21: 90832 | B21: GILLES BRISSON | C21: 7186.21 | D21: 7186.21 | E21: 0

Sheet 1303
A1: #Contrôle | B1: Description | C1: 1303 | D1: Jours | E1: NIV | F1: Remarques
A2: RES20 | B2: AJ CEDULE | C2: -338.68 | D2: 35 | G2: transférer au client
A3: 200523 | B3: 20 VOLKSWAGEN ATLAS | C3: 44333.8 | D3: 15 | E3: 1V2MC2CA3LC207864
A4: 200101A | B4: 17 JEEP GRAND CHEROKEE | C4: 33075 | D4: 14 | E4: 1C4RJFLG0HC739315
A5: 200406B | B5: 13 VOLKSWAGEN BEETLE | C5: 8400 | D5: 14 | E5: 3VWJL7AT1DM648735
A6: 191706A | B6: 15 VOLKSWAGEN GOLF 5 | C6: 13545 | D6: 13 | E6: 3VW4T7AU9FM002979
A7: 200472A | B7: 03 FORD TAURUS | C7: 420 | D7: 0 | E7: 1FAFP53U13G183492
A8: 210074 | B8: 21 VOLKSWAGEN GOLF | C8: 29498.7 | D8: 0 | E8: 3VWG57AUXMM002932

Sheet 1312
A1: #Contrôle | B1: Description | C1: Total | D1: 1312 | E1: Jours | F1: NIV | G1: NIV-6 derniers | H1: #Téléphone | I1: Adresse | J1: Remarques | K1: Jours en stock
A2: 1V2BR2CA5MC544379 | B2: 21 VOLKSWAGEN ATLAS | C2: 2251 | D2: 2251 | E2: 21 | F2: 1V2BR2CA5MC544379 | G2: 544379 | K2: 22 | N2: payables une fois par mois pour vehic mois avant
A3: 1V2FR2CA0MC542430 | B3: 21 VOLKSWAGEN ATLAS | C3: 2434 | D3: 2434 | E3: 1 | F3: 1V2FR2CA0MC542430 | G3: 542430 | K3: 10
A4: 1V2FR2CA3MC551705 | B4: 21 VOLKSWAGEN ATLAS | C4: 2434 | D4: 2434 | E4: 1 | F4: 1V2FR2CA3MC551705 | G4: 551705 | K4: 10
A5: 1V2LP2CA5MC551813 | B5: 21 VOLKSWAGEN ATLAS | C5: 2056 | D5: 2056 | E5: 1 | F5: 1V2LP2CA5MC551813 | G5: 551813 | K5: 8
A6: 1V2LR2CA9MC545183 | B6: 21 VOLKSWAGEN ATLAS | C6: 2122 | D6: 2122 | E6: 22 | F6: 1V2LR2CA9MC545183 | G6: 545183 | K6: 24
A7: 3VV1B7AX9MM040195 | B7: 21 VOLKSWAGEN TIGUAN | C7: 1609 | D7: 1609 | E7: 1 | F7: 3VV1B7AX9MM040195 | G7: 040195 | K7: 8
A8: 3VV2B7AX0MM036198 | B8: 21 VOLKSWAGEN TIGUAN | C8: 1805 | D8: 1805 | E8: 15 | F8: 3VV2B7AX0MM036198 | G8: 036198 | K8: 17
A9: 3VV2B7AX1MM017451 | B9: 21 VOLKSWAGEN TIGUAN | C9: 1805 | D9: 1805 | E9: 21 | F9: 3VV2B7AX1MM017451 | G9: 017451 | K9: 22
A10: 3VV2B7AX2MM032959 | B10: 21 VOLKSWAGEN TIGUAN | C10: 1805 | D10: 1805 | E10: 13 | F10: 3VV2B7AX2MM032959 | G10: 032959 | K10: 15
A11: 3VV2B7AX9MM036166 | B11: 21 VOLKSWAGEN TIGUAN | C11: 1805 | D11: 1805 | E11: 13 | F11: 3VV2B7AX9MM036166 | G11: 036166 | K11: 15
A12: 3VWC57BU0MM018666 | B12: 21 VOLKSWAGEN JETTA | C12: 1305 | D12: 1305 | E12: 21 | F12: 3VWC57BU0MM018666 | G12: 018666 | K12: 22
A13: 3VWC57BU0MM023950 | B13: 21 VOLKSWAGEN JETTA | C13: 1305 | D13: 1305 | E13: 21 | F13: 3VWC57BU0MM023950 | G13: 023950 | K13: 22
A14: 3VWC57BU1MM023603 | B14: 21 VOLKSWAGEN JETTA | C14: 1305 | D14: 1305 | E14: 21 | F14: 3VWC57BU1MM023603 | G14: 023603 | K14: 22
... A25: 3VWG57BU3MM028450 | B25: 21 VOLKSWAGEN JETTA | C25: 1485 | D25: 1485 | E25: 1 | F25: 3VWG57BU3MM028450 | G25: 028450 | K25: 8
A26: CREDIT2019 | B26: PDI CREDIT EN DOUBLE | C26: -53570 | D26: -53570 | E26: 366 | F26: CREDIT2019 | G26: IT2019

Sheet 1332
A1: #Contrôle | B1: Description | C1: Date org | D1: Total | E1: Actuel | F1: 31-60 | G1: 61-90 | H1: 91+ | I1: Remarques
A2: 33833XC | B2: WVGEF9BP8FD003728 | C2: 43580 | D2: -55 | E2: -55
A3: 38357XC | B3: 1V2NR2CA7JC506967 | C3: 43693 | D3: -55 | E3: -55
A4: 39716XC | B4: 3VV4B7AX3JM048074 | C4: 43738 | D4: -55 | E4: -55
A5: 41820XC | B5: 3VWR17AU7JM764132 | C5: 43797 | D5: -55 | E5: -55
A6: RES20 | B6: CLAIMS 2018 ET MOINS | C6: 43910 | D6: -6795.6 | E6: -6795.6
A7: 48080XC | B7: WVGJV7AX1GW034042 | C7: 44005 | D7: -55 | E7: -55
A8: 50046A | B8: 3VWM17AU7JM758972 | C8: 44070 | D8: 1134.23 | H8: 1134.23
A9: 49897B | B9: WVGNV7AX1HK032351 | C9: 44074 | D9: 123.21 | H9: 123.21
A10: 50047A | B10: 1VWUA7A33LC005628 | C10: 44076 | D10: -350 | E10: -350
A11: 50048A | B11: 1VWUA7A30LC005568 | C11: 44076 | D11: -350 | E11: -350
A12: 50051A | B12: 1VWUA7A31LC007975 | C12: 44076 | D12: -350 | E12: -350
A13: 50089A | B13: 1VWUA7A31LC013338 | C13: 44076 | D13: -350 | E13: -350
A14: 50090A | B14: 1VWUA7A32LC004759 | C14: 44076 | D14: -350 | E14: -350
A15: 50091A | B15: 1VWUA7A32LC014806 | C15: 44076 | D15: -350 | E15: -350
A16: 50092A | B16: 1VWUA7A33LC004883 | C16: 44076 | D16: -350 | E16: -350
A17: 50122A | B17: 1VWUA7A39LC006024 | C17: 44076 | D17: -350 | E17: -350
A18: 50125A | B18: 1VWUA7A38LC010131 | C18: 44076 | D18: -350 | E18: -350
A19: 50264A | B19: 1VWUA7A39LC015192 | C19: 44076 | D19: -350 | E19: -350
A20: 50270A | B20: 1VWUA7A39LC005990 | C20: 44076 | D20: -350 | E20: -350
A21: 50124A | B21: 1VWUA7A3XLC009563 | C21: 44077 | D21: -350 | E21: -350
... A30: 50321A | B30: 1VWUA7A34LC004777 | C30: 44084 | D30: -350 | E30: -350
A31: 50049A | C31: 44085 | D31: -400 | E31: -400
A32: 50050A | C32: 44085 | D32: -400 | E32: -400
A33: 50266A | C33: 44085 | D33: -350 | E33: -350
A34: 50364A | B34: 1VWUA7A34LC004875 | C34: 44085 | D34: -400 | E34: -400
A35: 50365A | B35: 1VWUA7A35LC012676 | C35: 44085 | D35: -400 | E35: -400
A36: 50366A | B36: 1VWUA7A36LC005736 | C36: 44085 | D36: -400 | E36: -400
A37: 50367A | B37: 1VWUA7A36LC007809 | C37: 44085 | D37: -400 | E37: -400
A38: 50368A | B38: 1VWUA7A38LC016964 | C38: 44085 | D38: -400 | E38: -400
A39: 49925A | B39: 3VWN57BU3KM098549 | C39: 44096 | D39: 169.09 | H39: 169.09
A40: 50837E | B40: 3VWE57BUXKM084941 | C40: 44103 | D40: -55 | E40: -55
A41: 49778XC | B41: 3VW267AJ2GM261397 | C41: 44104 | D41: -55 | E41: -55
A42: 50773B | B42: 1V2NR2CA3JC520963 | C42: 44104 | D42: 2975.1 | H42: 2975.1
A43: 51077XC | B43: 3VW817AU9HM035586 | C43: 44106 | D43: -55 | E43: -55
A44: 50962XC | B44: 3VWC17AU2HM503457 | C44: 44112 | D44: -55 | E44: -55
A45: 51045XC | B45: 3VWDB7AJ5HM224821 | C45: 44112 | D45: -55 | E45: -55
A46: 51272XC | B46: 3VWD17AU1JM767148 | C46: 44119 | D46: -55 | E46: -55
A47: 51554XC | B47: 3VWDB7AJ4HM282497 | C47: 44126 | D47: -55 | E47: -55
A48: 51797A | B48: 3VW217AU7HM036967 | C48: 44127 | D48: 303.56 | G48: 303.56
...

Sheet 1340
A1: #Contrôle | B1: Description | C1: Date org | D1: Total | E1: Actuel | F1: 31-60 | G1: 61-90 | H1: 91+ | I1: Remarques
A2: 245157 | B2: AJUSTEMENT DEPOT 0305 | C2: 43896 | D2: 96.07 | H2: 96.07
A3: RES20 | B3: AJ CEDULE | C3: 43963 | D3: -4370.55 | E3: -4370.55
A4: 248649 | B4: WVGJV7AX4DW526236 | C4: 44020 | D4: 1419.39 | H4: 1419.39
A5: 248917 | B5: 3VWE57BU9KM101826 | C5: 44027 | D5: 35.65 | H5: 35.65
A6: 247087 | B6: 3VWC17AU6GM501984 | C6: 44043 | D6: 119.57 | H6: 119.57
A7: 249220 | B7: WVGJV3AX4EW580906 | C7: 44047 | D7: 1776.84 | H7: 1776.84 | I7: ATTENTE PMT OK BRUNO LAFONTAIN
A8: 249870 | B8: 3VV2B7AX2JM054875 | C8: 44062 | D8: 718.08 | H8: 718.08 | I8: ATTENTE CHQ SUPERVITRE
A9: 251816 | B9: 3VW217AU0KM513178 | C9: 44126 | D9: 160.98 | G9: 160.98 | I9: RENVOI LGM 14 JANV
A10: 251442 | B10: 3VWC17AU8GM506832 | C10: 44132 | D10: 549.95 | G10: 549.95 | I10: CLIENTE PAS PAYER SA PARTIE
A11: 251211 | B11: 3VWH17AU5HM529833 | C11: 44135 | D11: 1896.66 | F11: 1896.66 | I11: CHQ ENVOYE CLIENT 24 NOV
A12: 252268 | B12: 3VWPX7AJ3DM607424 | C12: 44137 | D12: 114.97 | G12: 114.97
A13: 252862 | B13: 1V2HR2CA2KC554181 | C13: 44148 | D13: 373.49 | G13: 373.49
A14: 252876 | B14: WVWSR7AN2KE019611 | C14: 44148 | D14: 211.72 | G14: 211.72
A15: 252953 | B15: 3VW217AU5HM071040 | C15: 44152 | D15: 272.38 | G15: 272.38
A16: 253142 | B16: WVWDA7AJ2BW051983 | C16: 44158 | D16: 1325 | F16: 1325 | I16: VOIR VINCENT M
A17: 253372 | B17: WVGEP9BP7DD004993 | C17: 44161 | D17: 357.17 | F17: 357.17 | I17: COURRIEL COMPT 19 JANV 21
A18: 253519 | B18: WVWPR7AUXLW903255 | C18: 44161 | D18: 752.52 | F18: 752.52 | I18: ATTENTE CHQ SUPERVITRE
A19: 252499 | B19: WVWPF7AJ8DW083676 | C19: 44168 | D19: 1236.44 | F19: 1236.44
A20: 253951 | C20: 44173 | D20: -241.39 | E20: -241.39
A21: 253460 | B21: WVWVF7AU5HW174041 | C21: 44195 | D21: 492.96 | E21: 492.96
A22: 254266 | C22: 44204 | D22: -500 | E22: -500
A23: 254553 | C23: 44204 | D23: -149.41 | E23: -149.41
A24: 254578 | C24: 44207 | D24: -218.8 | E24: -218.8
A25: 254620 | C25: 44208 | D25: -257.54 | E25: -257.54
A26: 253556 | C26: 44211 | D26: -539.12 | E26: -539.12
A27: 254704 | B27: 1VWAH7A37EC054638 | C27: 44211 | D27: 509.77 | E27: 509.77
H28: =SUM(H4:H27) -> 4069.53

Sheet 1352 VIN
A1: #Contrôle | B1: Description | C1: NIV | D1: Jours | E1: Total | F1: Remarques | H1: date achat donc date
A2: WVWPR7AU9LW900850 | B2: 20 VOLKSWAGEN GOLF | C2: WVWPR7AU9LW900850 | D2: 384 | E2: 5000 | F2: roulez vert long a collecté
A3: WVWPR7AU4LW902697 | B3: 20 VOLKSWAGEN GOLF | C3: WVWPR7AU4LW902697 | D3: 315 | E3: 5000 | F3: roulez vert long a collecté
A4: 3VWG57AU7KM019247 | B4: 19 VOLKSWAGEN GOLF | C4: 3VWG57AU7KM019247 | D4: 266 | E4: -500
A5: 3VV0B7AX9LM095126 | B5: 20 VOLKSWAGEN TIGUAN | C5: 3VV0B7AX9LM095126 | D5: 174 | E5: -500
A6: WVWPR7AU5LW906161 | B6: 20 VOLKSWAGEN GOLF | C6: WVWPR7AU5LW906161 | D6: 111 | E6: 4400
A7: WVWPR7AU1LW903810 | B7: 20 VOLKSWAGEN GOLF | C7: WVWPR7AU1LW903810 | D7: 69 | E7: 5000 | F7: roulez vert long a collecté
A8: WVWPR7AU7LW909482 | B8: 20 VOLKSWAGEN GOLF | C8: WVWPR7AU7LW909482 | D8: 69 | E8: 5000 | F8: roulez vert long a collecté
A9: 1VWEA7A39LC001572 | B9: 20 VOLKSWAGEN PASSAT | C9: 1VWEA7A39LC001572 | D9: 63 | E9: 2500
A10: 3VV4B7AX7LM138623 | B10: 20 VOLKSWAGEN TIGUAN | C10: 3VV4B7AX7LM138623 | D10: 62 | E10: -2000
A11: 3VW5T7AU5LM017091 | B11: 20 VOLKSWAGEN GTI | C11: 3VW5T7AU5LM017091 | D11: 62 | E11: 1500
A12: 1VWUA7A30LC011645 | B12: 20 VOLKSWAGEN PASSAT | C12: 1VWUA7A30LC011645 | D12: 55 | E12: -1000
A13: 3VV4B7AX2LM175823 | B13: 20 VOLKSWAGEN TIGUAN | C13: 3VV4B7AX2LM175823 | D13: 37 | E13: 700
A14: WVWPR7AU3LW901587 | B14: 20 VOLKSWAGEN GOLF | C14: WVWPR7AU3LW901587 | D14: 36 | E14: 5000 | F14: roulez vert long a collecté
A15: 3VV2B7AX5LM104171 | B15: 20 VOLKSWAGEN TIGUAN | C15: 3VV2B7AX5LM104171 | D15: 35 | E15: -2000
A16: WVWPR7AU3LW909320 | B16: 20 VOLKSWAGEN GOLF | C16: WVWPR7AU3LW909320 | D16: 35 | E16: 5496.59
A17: 3VV2B7AX5LM137042 | B17: 20 VOLKSWAGEN TIGUAN | C17: 3VV2B7AX5LM137042 | D17: 34 | E17: -700
A18: 1V2BR2CA9MC509974 | B18: 21 VOLKSWAGEN ATLAS | C18: 1V2BR2CA9MC509974 | D18: 31 | E18: 700
A19: 3VV0B7AX4LM134706 | B19: 20 VOLKSWAGEN TIGUAN | C19: 3VV0B7AX4LM134706 | D19: 31 | E19: 700
A20: 3VV0B7AX7LM097795 | B20: 20 VOLKSWAGEN TIGUAN | C20: 3VV0B7AX7LM097795 | D20: 31 | E20: 700
A21: 3VV2B7AX8LM137004 | B21: 20 VOLKSWAGEN TIGUAN | C21: 3VV2B7AX8LM137004 | D21: 31 | E21: 700
A22: 3VV4B7AX0LM013480 | B22: 20 VOLKSWAGEN TIGUAN | C22: 3VV4B7AX0LM013480 | D22: 31 | E22: 700
A23: 3VV0B7AX5MM013359 | B23: 21 VOLKSWAGEN TIGUAN | C23: 3VV0B7AX5MM013359 | D23: 27 | E23: -900
A24: 3VV2B7AX4MM011515 | B24: 21 VOLKSWAGEN TIGUAN | C24: 3VV2B7AX4MM011515 | D24: 27 | E24: -275
A25: 3VV2B7AX4MM013250 | B25: 21 VOLKSWAGEN TIGUAN | C25: 3VV2B7AX4MM013250 | D25: 27 | E25: -275
A26: 3VV2B7AX5LM160837 | B26: 20 VOLKSWAGEN TIGUAN | C26: 3VV2B7AX5LM160837 | D26: 27 | E26: 250
... A109: 3VV4B7AX8LM144172 | B109: 20 VOLKSWAGEN TIGUAN | C109: 3VV4B7AX8LM144172 | D109: 0 | E109: 250
E110: =SUM(E2:E109) -> 88021.59

Sheet 1352 TOT
A1: #Contrôle | B1: Description | C1: NIV | D1: Jours | E1: Total | F1: Remarques
A2: VWAVAN2020Q2 | C2: VWAVAN2020Q2 | D2: 133 | E2: -18965 | F2: RES20
A3: RES20 | B3: AJUST CEDULE | C3: RES20 | D3: 127 | E3: -12123.19 | F3: RES20
A4: VWAVAN2020Q1 | B4: VW PROTECTION PLUS | C4: VWAVAN2020Q1 | D4: 237 | E4: -10325 | F4: RES20
A5: VWAVANTQ32020 | B5: VCI | C5: VWAVANTQ32020 | D5: 36 | E5: -8000 | F5: RES20
A6: BONUS-REP | B6: BONI REPRESENTANT DEC 20 | C6: BONUS-REP | D6: 13 | E6: -1000 | F6: RES20
A7: TOT-Q3 | C7: TOT-Q3 | D7: 125 | E7: 2476.59 | F7: RES20
A8: PIECES2006 | B8: RISTOURNE DE PIECES | C8: PIECES2006 | D8: 184 | E8: 3740.48 | F8: RES20
A9: PIECES0820 | B9: RISTOURNCE PIECE | C9: PIECES0820 | D9: 122 | E9: 4000 | F9: RES20
A10: RIST-PIECE-JUILLE | C10: RIST-PIECE-JUILLE | D10: 153 | E10: 5130.98 | F10: RES20
A11: TOT-Q2 | C11: TOT-Q2 | D11: 195 | E11: 9368.27 | F11: RES20
E12: =SUM(E2:E11) -> -25696.87
A14: TOT-Q4 | B14: TOT Q4 | C14: TOT-Q4 | D14: 34 | E14: -7247.72
A15: TOT-12 | B15: TOT | C15: TOT-12 | D15: 0 | E15: 15700
A16: RISTPIECEDEC | B16: RECEV RISTOURNES PIECE DE | C16: RISTPIECEDEC | D16: 0 | E16: 91105

Sheet 1416
A1: #Contrôle | B1: Description | C1: NIV | D1: Jours | E1: Total | F1: Remarques
A2: 210054A | B2: 18 VOLKSWAGEN ATLAS | C2: 1V2MR2CA0JC533391 | D2: 51 | E2: 31523.99
A3: 200311A | B3: 18 VOLKSWAGEN ATLAS | C3: 1V2LR2CA8JC509741 | D3: 133 | E3: 31348.15
A4: 210060A | B4: 18 VOLKSWAGEN ATLAS | C4: 1V2MR2CA2JC509125 | D4: 31 | E4: 30700.5
A5: 210018A | B5: 18 VOLKSWAGEN TIGUAN | C5: 3VV4B7AX3JM172300 | D5: 71 | E5: 29795.25
A6: 200434A | B6: 18 VOLKSWAGEN TIGUAN | C6: 3VV4B7AX4JM022289 | D6: 62 | E6: 29275.84
A7: 210055A | B7: 18 VOLKSWAGEN TIGUAN | C7: 3VV4B7AX0JM013993 | D7: 43 | E7: 29030.78
A8: 200531A | B8: 18 VOLKSWAGEN TIGUAN | C8: 3VV4B7AX4JM202422 | D8: 8 | E8: 29015 | F8: PROTEX
A9: 4836P | B9: 18 VOLKSWAGEN ATLAS | C9: 1V2LR2CA1JC509094 | D9: 98 | E9: 29011.77
A10: 4869P | B10: 19 VOLKSWAGEN GOLF GTI | C10: 3VW5T7AU3KM006184 | D10: 36 | E10: 28670.62
A11: 200520A | B11: 18 VOLKSWAGEN TIGUAN | C11: 3VV4B7AX2JM118812 | D11: 15 | E11: 28370
A12: 4870P | B12: 18 VOLKSWAGEN TIGUAN | C12: 3VV4B7AX4JM008537 | D12: 24 | E12: 26125.3
A13: 200298A | B13: 18 VOLKSWAGEN TIGUAN | C13: 3VV2B7AX2JM105193 | D13: 36 | E13: 24993.29
A14: 210089A | B14: 18 VOLKSWAGEN TIGUAN | C14: 3VV2B7AX9JM031402 | D14: 20 | E14: 24766.8
A15: 4861P | B15: 18 VOLKSWAGEN GOLF GTI | C15: 3VW447AU5JM292210 | D15: 51 | E15: 24609.08
A16: 200530A | B16: 17 ACURA RDX | C16: 5J8TB4H72HL810290 | D16: 0 | E16: 24415
A17: 200489A | B17: 18 VOLKSWAGEN TIGUAN | C17: 3VV2B7AXXJM006136 | D17: 61 | E17: 23667.55
A18: 4882P | B18: 16 VOLKSWAGEN GOLF R | C18: WVWUF7AU5GW309951 | D18: 1 | E18: 23415
A19: 200045A | B19: 18 VOLKSWAGEN TIGUAN | C19: 3VV2B7AXXJM150396 | D19: 8 | E19: 22915
A20: 200465A | B20: 19 VOLKSWAGEN JETTA | C20: 3VWG57BU6KM017486 | D20: 71 | E20: 22625.3
... A77: 4858P | B77: 08 VOLKSWAGEN JETTA SEDAN | C77: 3VWHM71K48M147346 | D77: 62 | E77: 1415
A80: 200477A | B80: 16 VOLKSWAGEN JETTA SEDAN | C80: 3VWB67AJ1GM304904 | D80: 61 | E80: 155 | F80: PARE-PIERRE
A81: 200507A | B81: 17 VOLKSWAGEN JETTA SEDAN | C81: 3VWDB7AJ8HM234467 | D81: 43 | E81: 125
A82: 4859P | B82: 19 VOLKSWAGEN TIGUAN | C82: 3VV4B7AX8KM038044 | D82: 58 | E82: 10 | F82: PARE-PIERRE
A83: 4811P | B83: 14 VOLKSWAGEN JETTA SEDAN | C83: 3VWG07AJ4EM318770 | D83: 142 | E83: -80.47 | F83: RESERVE SERVICE
A84: 4832P | B84: 18 VOLKSWAGEN GOLF GTI | C84: 3VW447AU4JM288410 | D84: 98 | E84: -110.5
A85: 200284A | B85: 17 VOLKSWAGEN JETTA SEDAN | C85: 3VWDB7AJ7HM223055 | D85: 76 | E85: -150 | F85: RES CHANGEMENT HUILE
A86: 200303A | B86: 16 VOLKSWAGEN JETTA | C86: 3VWD07AJ4GM390395 | D86: 122 | E86: -223.6 | F86: VITRES TEINTEES
A87: 200276A | B87: 17 VOLKSWAGEN TIGUAN | C87: WVGLV7AX1HW508307 | D87: 147 | E87: -500 | F87: RES MAGS
A88: 4794P | B88: 18 VOLKSWAGEN BEETLE CONVERTI | C88: 3VW5DAAT9JM516989 | D88: 160 | E88: -668.33 | F88: DEMARREUR + PNEU
A89: 4827P | B89: 17 VOLKSWAGEN TIGUAN | C89: WVGNV7AX4HW504079 | D89: 122 | E89: -2645.31 | F89: BON DE TRAVAIL FERME JANVIER
E90: =SUM(E80:E89) -> -4088.21

Sheet RES
A1: RES19 | B1: 190272A | D1: 366 | E1: -38334.12
A2: RES20 | B2: AJ CEDULE | D2: 94 | E2: -234.36
E3: =SUM(E1:E2) -> -38568.48

Sheet 1402
A1: #Contrôle | B1: Description | C1: NIV | D1: Jours | E1: Total | F1: Remarques
A2: 210113 | B2: 21 VOLKSWAGEN ATLAS | C2: 1V2FR2CA4MC542463 | D2: 9 | E2: 57474.16
A3: 210114 | B3: 21 VOLKSWAGEN ATLAS | C3: 1V2FR2CA3MC551705 | D3: 1 | E3: 54855
A4: 210115 | B4: 21 VOLKSWAGEN ATLAS | C4: 1V2FR2CA0MC542430 | D4: 1 | E4: 54855
A5: 200401 | B5: 20 VOLKSWAGEN ARTEON | C5: WVWSR7AN5LE012590 | D5: 122 | E5: 54238.51
A6: 210082 | B6: 21 VOLKSWAGEN ATLAS | C6: 1V2BC2CA7MC200635 | D6: 34 | E6: 52379.8
A7: 210092 | B7: 21 VOLKSWAGEN ATLAS | C7: 1V2BR2CA5MC544379 | D7: 21 | E7: 49577.46
A8: 210091 | B8: 21 VOLKSWAGEN ATLAS | C8: 1V2LR2CA9MC545183 | D8: 22 | E8: 45596.46
A9: 210086 | B9: 21 VOLKSWAGEN ATLAS | C9: 1V2LP2CA7MC540778 | D9: 34 | E9: 43196
A10: 210118 | B10: 21 VOLKSWAGEN ATLAS | C10: 1V2LP2CA5MC551813 | D10: 1 | E10: 43196
A11: 210112 | B11: 21 VOLKSWAGEN ATLAS | C11: 1V2LP2CA9MC517101 | D11: 15 | E11: 43011
A12: 210025 | B12: 21 VOLKSWAGEN TIGUAN | C12: 3VV4B7AX5MM000211 | D12: 63 | E12: 42850.71
A13: 200239 | B13: 20 VOLKSWAGEN GTI | C13: 3VW6T7AU3LM011245 | D13: 161 | E13: 42591.24
... A54: 200509 | B54: 20 VOLKSWAGEN PASSAT | C54: 1VWBA7A3XLC005469 | D54: 38 | E54: 33387.83
A55: 200450 | B55: 20 VOLKSWAGEN TIGUAN | C55: 3VV0B7AX6LM133170 | D55: 91 | E55: 32941.71 | F55: TAG
A56: 200452 | B56: 20 VOLKSWAGEN TIGUAN | C56: 3VV0B7AX9LM131221 | D56: 94 | E56: 31904.96
A57: 200471 | B57: 20 VOLKSWAGEN TIGUAN | C57: 3VV0B7AX3LM133160 | D57: 76 | E57: 31904.96
A58: 210119 | B58: 21 VOLKSWAGEN TIGUAN | C58: 3VV1B7AX9MM040195 | D58: 1 | E58: 30420
A59: 210117 | B59: 21 VOLKSWAGEN JETTA | C59: 3VWG57BU3MM028450 | D59: 1 | E59: 28777
A60: 210031 | B60: 21 VOLKSWAGEN GOLF | C60: 3VWG57AU7MM000281 | D60: 62 | E60: 28072.11
A61: 210037 | B61: 21 VOLKSWAGEN GOLF | C61: 3VWG57AUXMM001862 | D61: 62 | E61: 27794
A62: 210038 | B62: 21 VOLKSWAGEN GOLF | C62: 3VWG57AUXMM001876 | D62: 62 | E62: 27794
A63: 210048 | B63: 21 VOLKSWAGEN GOLF | C63: 3VWG57AU6MM001826 | D63: 55 | E63: 27794
A64: 210073 | B64: 21 VOLKSWAGEN GOLF | C64: 3VWG57AUXMM004048 | D64: 34 | E64: 27794
A65: 210076 | B65: 21 VOLKSWAGEN GOLF | C65: 3VWG57AU6MM003236 | D65: 34 | E65: 27794
A66: 210078 | B66: 21 VOLKSWAGEN GOLF | C66: 3VWG57AU2MM003475 | D66: 34 | E66: 27794
A67: 210079 | B67: 21 VOLKSWAGEN GOLF | C67: 3VWG57AU2MM002682 | D67: 34 | E67: 27794
... A115: 200501 | B115: 20 VOLKSWAGEN JETTA | C115: 3VWCB7BU5LM006410 | D115: 57 | E115: 23376.99
A118: 200398 | B118: 20 VOLKSWAGEN TIGUAN | C118: 3VV2B7AX9LM159142 | D118: 122 | E118: 500 | F118: A REC LGM | G118: A REC CLIENT
A119: 200506 | B119: 20 VOLKSWAGEN JETTA | C119: 3VWEB7BU6LM059769 | D119: 50 | E119: -44.95 | F119: ENTREPOSAGE PNEUS ETE
A120: 200215 | B120: 20 VOLKSWAGEN TIGUAN | C120: 3VV2B7AX9LM101189 | D120: 184 | E120: -135 | F120: RES TAPIS
A121: 190448 | B121: 19 VOLKSWAGEN JETTA | C121: 3VWN57BU5KM135519 | D121: 715 | E121: -223.6 | F121: VITRES TEINTE
A122: 190458 | B122: 19 VOLKSWAGEN JETTA | C122: 3VWN57BU0KM147352 | D122: 709 | E122: -223.6 | F122: VITRES TIENTEES
A123: 200416 | B123: 20 VOLKSWAGEN GOLF | C123: 3VWG57AU7LM007164 | D123: 111 | E123: -350 | F123: RES CHANGEMENT HUILE
A124: 210074 | B124: 21 VOLKSWAGEN GOLF | C124: 3VWG57AUXMM002932 | D124: 34 | E124: -408.55
A125: 200518 | B125: 20 VOLKSWAGEN ATLAS | C125: 1V2GC2CA4LC213492 | D125: 34 | E125: -458.85 | F125: RES 253792
A126: 200499 | B126: 20 VOLKSWAGEN TIGUAN | C126: 3VV0B7AX3LM132574 | D126: 57 | E126: -615 | F126: RENONCIATION DETTE
A127: 190849 | B127: 19 VOLKSWAGEN ATLAS | C127: 1V2AP2CAXKC557465 | D127: 605 | E127: -808 | F127: RESERVE PNEUS
A128: 200354 | B128: 20 VOLKSWAGEN TIGUAN | C128: 3VV2B7AX2LM117122 | D128: 126 | E128: -915.07 | F128: DEMARREUR 254181
A129: 200525 | B129: 20 VOLKSWAGEN TIGUAN | C129: 3VV2B7AX8LM143045 | D129: 17 | E129: -1061.57 | F129: DEMARREUR + TAG
...

Sheet  RES NEUF
A1: RESCOU | B1: VEH NEUF RESERVE | D1: 1096 | E1: -33322.31
A2: RESDEM | B2: 191285 DEP FEV- MARS | D2: 233 | E2: -37480.61
A3: RES20 | B3: AJUST CEDULE | D3: 280 | E3: -1852.75

Sheet 2281
A1: #Contrôle | B1: Description | C1: Total | D1: 2281 | E1: Jours | F1: NIV | G1: NIV-6 derniers | H1: Remarques
A2: 90407 | B2: QC INC 9157-4731 QUEBEC INC | C2: 35250.71 | D2: 35250.71 | E2: 28 | H2: paye en double a audi cheque de audi a vw pour canceller en janvier
A3: 90811 | B3: SIMON BEAULIEU | C3: 9989.96 | D3: 9989.96 | E3: 14 | H3: recevable de Ind Alliance pour ass rempl recu 13 janvier - traiter dans le compte paid ou a payer parceque…mais recevable client
A4: 90874 | B4: MAXIME ALLAN-CHARTRAND | C4: -5.81 | D4: -5.81 | E4: 0 | H4: cheque annuler a passer au profit en 13e
A5: 87968 | B5: GUY THERIAULT | C5: -30 | D5: -30 | E5: 0 | H5: cheque annuler a passer au profit en 13e
A6: 80397 | B6: PATRICK MARCOTRIGIANO | C6: -257.81 | D6: -257.81 | E6: 23 | H6: voir avec Yves
A7: 88991 | B7: ELIZ 9357-4101 QUEBEC INC | C7: -391.29 | D7: -391.29 | E7: 0 | H7: cheque annuler a passer au profit en 13e
A8: 90786 | B8: JULIE THIBAULT | C8: -9698.41 | D8: -9698.41 | E8: 15 | H8: 1ER PMT DEDUIT DEBOURSER
A9: 90832 | B9: GILLES BRISSON | C9: -23756.23 | D9: -23756.23 | E9: 0 | H9: cheque en janvier
A10: 90689 | B10: GILLIAN BARTLETT | C10: -59853.33 | D10: -59853.33 | E10: 15 | H10: cheque en janvier

Sheet 2285
A1: #Contrôle | B1: Description | C1: 2285 | D1: Jours | E1: NIV | F1: Remarques
A3: 200186 | B3: 20 VOLKSWAGEN TIGUAN | C3: -44.1 | D3: 131 | E3: 3VV0B7AX2LM112929
A4: 210010 | B4: 21 VOLKSWAGEN ATLAS | C4: -714 | D4: 75 | E4: 1V2LR2CA0MC515750
A5: 200490 | B5: 20 VOLKSWAGEN TIGUAN | C5: 874 | D5: 61 | E5: 3VV4B7AX0LM020834 | F5: promo entretien prepaye recevable de VW
A6: 200508 | B6: 20 VOLKSWAGEN TIGUAN | C6: 874 | D6: 43 | E6: 3VV4B7AX2LM175823 | F6: promo entretien prepaye recevable de VW
A7: 200442 | B7: 20 VOLKSWAGEN TIGUAN | C7: 874 | D7: 37 | E7: 3VV0B7AX4LM131739 | F7: promo entretien prepaye recevable de VW
A8: 191688 | B8: 19 VOLKSWAGEN GOLF | C8: -44.1 | D8: 22 | E8: 3VWR17AU8KM517784
A9: 200450 | B9: 20 VOLKSWAGEN TIGUAN | C9: -377.18 | D9: 0 | E9: 3VV0B7AX6LM133170
A13: RES20 | B13: CREDIT PSC028189 | C13: -10610.32 | D13: 230 | F13: confirmer avec F & I ok

Sheet 2287
A1: #Contrôle | B1: Description | C1: Total | D1: 2287 | E1: Jours | F1: NIV | G1: NIV-6 derniers | H1: #Téléphone | I1: Adresse | J1: Remarques
A2: 90802 | B2: JOANIE LABELLE | C2: -486.28 | D2: -486.28 | E2: 21 | H2: (514) 266-1115 | I2: 156 DAIGNEAULT CHAMBLY, QC J3L 0X3
A3: 200302 | C3: -1172.09 | D3: -1172.09 | E3: 147
A4: RES20 | C4: -371.29 | D4: -371.29 | E4: 104

Sheet 2292
A1: #Contrôle | B1: Description | C1: 2292 | D1: Jours | E1: NIV | F1: Remarques
A2: 4879P | B2: 17 VOLKSWAGEN JETTA SEDAN | C2: -10000 | D2: 0 | E2: 3VW2B7AJ3HM314413 | F2: Audi | H2: cheque fait en janvier
A3: 200242 | B3: 20 VOLKSWAGEN GOLF | C3: -25559.99 | D3: 0 | E3: 3VWG57AU8LM010770 | F3: VW outaoauis | H3: cheque juillet pas recu annulé 31 dec pour en faire un autre en janvier
