Workbook
Name _Dates_Conc: [1]Dealers!$BF$37:$KA$63
Name _scen: '[1]Scen & Sens'!$E$26
Name _scen1: '[1]Scen & Sens'!$E$27
Name _scen2: '[1]Scen & Sens'!$E$28
Name _SCenarios: '[1]Scen & Sens'!$J$26:$O$26
Name _Sens1: '[1]Scen & Sens'!$F$9
Name _Sens2: '[1]Scen & Sens'!$F$10
Name _sensRes1: '[1]Scen & Sens'!$E$15
Name _sensRes2: '[1]Scen & Sens'!$E$16
Name _sensRes3: '[1]Scen & Sens'!$E$17
Name _sensRes4: '[1]Scen & Sens'!$E$18
Name _sensRes5: '[1]Scen & Sens'!$E$19
Name _sensRes6: '[1]Scen & Sens'!$E$20
Name _sensRes7: '[1]Scen & Sens'!$E$21
Name DateRange: [1]Volkswagen!$BF$6:$DY$6
Name Monetary_Unit: [1]Parameters!$B$15
Name Months: [1]Parameters!$E$9:$E$20
Name Rng_Dealers_Names: [1]!Tbl_Dealers[Dealer Name]
Name Rng_Dlr_Dates: [1]!Tbl_V_Dlr_Dates[Date]
Name Titre: [1]Front!$A$9

Sheet Paramètre
B3: AUDI QUARTER
B6: BUDGET | F6: BUDGET RÉVISÉ | J6: ACTUAL | N6: LAST YEAR
B7: Ventes | C7: Profits bruts | D7: BAIIA | E7: EBIT | F7: Ventes | G7: Profits bruts | H7: BAIIA | I7: EBIT | J7: Ventes | K7: Profits bruts | L7: BAIIA | M7: EBIT | N7: Ventes | O7: Profits bruts | P7: BAIIA | Q7: EBIT
A8: CTRL | B8: =+B9-B10 -> 0 | C8: =+C9-C10 -> 0 | D8: =+D9-D10 -> 0 | E8: =+E9-E10 -> 0 | F8: =+F9-F10 -> 0 | G8: =+G9-G10 -> 0 | H8: =+H9-H10 -> 0 | I8: =+I9-I10 -> 0 | ... Q8: =+Q9-Q10 -> 0
A9: CONSO | B9: =+Conso!$Z$405 -> 8038384.2 | C9: =+Conso!$Z$406 -> 1712610.5 | D9: =+Conso!$Z$482 -> 409156.36 | E9: =+Conso!$Z$497 -> 378559.99 | F9: =+Conso!$AC$405 -> 8038384.2 | G9: =+Conso!$AC$406 -> 1778116.1 | H9: =+Conso!$AC$482 -> 396422.33 | I9: =+Conso!$AC$497 -> 365825.96 | J9: =+Conso!$AF$405 -> 16048941 | K9: =+Conso!$AF$406 -> 1948196.7 | L9: =+Conso!$AF$482 -> 633129.42 | M9: =+Conso!$AF$497 -> 633961.81 | N9: =+Conso!$AL$405 -> 15054918 | O9: =+Conso!$AL$406 -> 1646743.3 | P9: =+Conso!$AL$482 -> 270793.34 | Q9: =+Conso!$AL$497 -> 231534.21
A10: TOTAL | B10: =+SUM(B11:B13) -> 8038384.2 | C10: =+SUM(C11:C13) -> 1712610.5 | D10: =+SUM(D11:D13) -> 409156.36 | E10: =+SUM(E11:E13) -> 378559.99 | F10: =+SUM(F11:F13) -> 8038384.2 | G10: =+SUM(G11:G13) -> 1778116.1 | H10: =+SUM(H11:H13) -> 396422.33 | I10: =+SUM(I11:I13) -> 365825.96 | ... Q10: =+SUM(Q11:Q13) -> 231534.21
A11: AUDI 1 | B11: =+'VW 4'!$Z$405 -> 2470120.3 | C11: =+'VW 4'!$Z$406 -> 545849 | D11: =+'VW 4'!$Z$482 -> 130720.25 | E11: =+'VW 4'!$Z$497 -> 120519.68 | F11: =+'VW 4'!$AC$405 -> 2470120.3 | G11: =+'VW 4'!$AC$406 -> 574246.67 | H11: =+'VW 4'!$AC$482 -> 121216.05 | I11: =+'VW 4'!$AC$497 -> 111015.48 | J11: =+'VW 4'!$AF$405 -> 5121135.5 | K11: =+'VW 4'!$AF$406 -> 640912.74 | L11: =+'VW 4'!$AF$482 -> 194923.31 | M11: =+'VW 4'!$AF$497 -> 187231.25 | N11: =+'VW 4'!$AL$405 -> 4604575.2 | O11: =+'VW 4'!$AL$406 -> 538002.03 | P11: =+'VW 4'!$AL$482 -> 114960.78 | Q11: =+'VW 4'!$AL$497 -> 102916.93
A12: AUDI 2 | B12: =+'VW 5'!$Z$405 -> 3070578.4 | C12: =+'VW 5'!$Z$406 -> 640640.26 | D12: =+'VW 5'!$Z$482 -> 205500.39 | E12: =+'VW 5'!$Z$497 -> 195297.69 | F12: =+'VW 5'!$AC$405 -> 3070578.4 | G12: =+'VW 5'!$AC$406 -> 677748.24 | H12: =+'VW 5'!$AC$482 -> 202270.56 | I12: =+'VW 5'!$AC$497 -> 192067.87 | J12: =+'VW 5'!$AF$405 -> 5749670.9 | K12: =+'VW 5'!$AF$406 -> 685822.65 | L12: =+'VW 5'!$AF$482 -> 267930.12 | M12: =+'VW 5'!$AF$497 -> 281298.69 | N12: =+'VW 5'!$AL$405 -> 5181423.9 | O12: =+'VW 5'!$AL$406 -> 554370.65 | P12: =+'VW 5'!$AL$482 -> 77916.28 | Q12: =+'VW 5'!$AL$497 -> 64308.64
A13: AUDI 3 | B13: =+'VW 6'!$Z$405 -> 2497685.5 | C13: =+'VW 6'!$Z$406 -> 526121.24 | D13: =+'VW 6'!$Z$482 -> 72935.719 | E13: =+'VW 6'!$Z$497 -> 62742.617 | F13: =+'VW 6'!$AC$405 -> 2497685.5 | G13: =+'VW 6'!$AC$406 -> 526121.24 | H13: =+'VW 6'!$AC$482 -> 72935.719 | I13: =+'VW 6'!$AC$497 -> 62742.617 | J13: =+'VW 6'!$AF$405 -> 5178134.8 | K13: =+'VW 6'!$AF$406 -> 621461.3 | L13: =+'VW 6'!$AF$482 -> 170275.99 | M13: =+'VW 6'!$AF$497 -> 165431.87 | N13: =+'VW 6'!$AL$405 -> 5268919.3 | O13: =+'VW 6'!$AL$406 -> 554370.65 | P13: =+'VW 6'!$AL$482 -> 77916.28 | Q13: =+'VW 6'!$AL$497 -> 64308.64

Sheet Conso
C1: Conso | K1: Véhicules neufs | S1: =CONCATENATE("Réalisé"," ",Paramètre!$C$2," ",Paramètre!$C$3) -> Réalisé | V1: BUDGET | W1: RÉVISÉ | X1: ACTUAL | Y1: LY
D2: X | E2: O | F2: U | G2: X | H2: O | I2: U
D3: BUDGET ORIGINAL | G3: BUDGET REVISE | J3: RÉALISATION | M3: ÉCART réel / révisé | O3: ANNÉE PRÉCÉDENTE | R3: ÉCART réel / original
D4: UNITE | E4: $P/UNITÉ | F4: $PROFITS | G4: UNITE | H4: $P/UNITÉ | I4: $PROFITS | J4: UNITE | K4: $P/UNITE | L4: $PROFITS | M4: UNITÉ | N4: $PROFITS | O4: UNITE | P4: $P/UNITE | Q4: $PROFITS | R4: UNITE | S4: $PROFITS | V4: =+SUM(V5:V398) -> 0 | W4: =+SUM(W5:W398) -> 0 | X4: =+SUM(X5:X398) -> 0 | Y4: =+SUM(Y5:Y398) -> 0
A5: =+B5&C5 -> Véhicules neufsVentes nettes | B5: =+$K$1 -> Véhicules neufs | C5: Ventes nettes | F5: =+SUM(START:END!F5) -> 2424853.6 | I5: =+SUM(START:END!I5) -> 2424853.6 | L5: =+SUM(START:END!L5) -> 9687350 | Q5: =+SUM(START:END!Q5) -> 9378048.7
A6: =+B6&C6 -> Véhicules neufsAutos détail | B6: =+$K$1 -> Véhicules neufs | C6: Autos détail | D6: =+SUM(START:END!D6) -> 98.886679 | E6: =IF(D6=0,0,F6/D6) -> 629.09316 | F6: =+SUM(START:END!F6) -> 62208.934 | G6: =+SUM(START:END!G6) -> 88.126469 | H6: =IF(G6=0,0,I6/G6) -> 957.16463 | I6: =+SUM(START:END!I6) -> 84351.539 | J6: =+SUM(START:END!J6) -> 72 | K6: =IF(J6=0,0,L6/J6) -> 884.42153 | L6: =+SUM(START:END!L6) -> 63678.35 | M6: =J6-G6 -> -16.126469 | N6: =L6-I6 -> -20673.189 | O6: =+SUM(START:END!O6) -> 164 | P6: =IF(O6=0,0,Q6/O6) -> 634.92622 | Q6: =+SUM(START:END!Q6) -> 104127.9 | R6: =J6-O6 -> -92 | S6: =L6-Q6 -> -40449.55
A7: =+B7&C7 -> Véhicules neufsCamions détail | B7: =+$K$1 -> Véhicules neufs | C7: Camions détail | D7: =+SUM(START:END!D7) -> 132.82798 | E7: =IF(D7=0,0,F7/D7) -> 1273.5738 | F7: =+SUM(START:END!F7) -> 169166.23 | G7: =+SUM(START:END!G7) -> 118.79364 | H7: =IF(G7=0,0,I7/G7) -> 1700.4049 | I7: =+SUM(START:END!I7) -> 201997.29 | J7: =+SUM(START:END!J7) -> 131 | K7: =IF(J7=0,0,L7/J7) -> 2187.6411 | L7: =+SUM(START:END!L7) -> 286580.99 | M7: =J7-G7 -> 12.20636 | N7: =L7-I7 -> 84583.699 | O7: =+SUM(START:END!O7) -> 74 | P7: =IF(O7=0,0,Q7/O7) -> 871.185 | Q7: =+SUM(START:END!Q7) -> 64467.69 | R7: =J7-O7 -> 57 | S7: =L7-Q7 -> 222113.3
A8: =+B8&C8 -> Véhicules neufsSprinter | B8: =+$K$1 -> Véhicules neufs | C8: Sprinter | D8: =+SUM(START:END!D8) -> 0 | E8: =IF(D8=0,0,F8/D8) -> 0 | F8: =+SUM(START:END!F8) -> 0 | G8: =+SUM(START:END!G8) -> 0 | H8: =IF(G8=0,0,I8/G8) -> 0 | I8: =+SUM(START:END!I8) -> 0 | J8: =+SUM(START:END!J8) -> 0 | K8: =IF(J8=0,0,L8/J8) -> 0 | L8: =+SUM(START:END!L8) -> 0 | M8: =J8-G8 -> 0 | N8: =L8-I8 -> 0 | O8: =+SUM(START:END!O8) -> 0 | P8: =IF(O8=0,0,Q8/O8) -> 0 | Q8: =+SUM(START:END!Q8) -> 0 | R8: =J8-O8 -> 0 | S8: =L8-Q8 -> 0
A9: =+B9&C9 -> Véhicules neufsMoto détail | B9: =+$K$1 -> Véhicules neufs | C9: Moto détail | D9: =+SUM(START:END!D9) -> 0 | E9: =IF(D9=0,0,F9/D9) -> 0 | F9: =+SUM(START:END!F9) -> 0 | G9: =+SUM(START:END!G9) -> 0 | H9: =IF(G9=0,0,I9/G9) -> 0 | I9: =+SUM(START:END!I9) -> 0 | J9: =+SUM(START:END!J9) -> 0 | K9: =IF(J9=0,0,L9/J9) -> 0 | L9: =+SUM(START:END!L9) -> 0 | M9: =J9-G9 -> 0 | N9: =L9-I9 -> 0 | O9: =+SUM(START:END!O9) -> 0 | P9: =IF(O9=0,0,Q9/O9) -> 0 | Q9: =+SUM(START:END!Q9) -> 0 | R9: =J9-O9 -> 0 | S9: =L9-Q9 -> 0
A10: =+B10&C10 -> Véhicules neufs[...] | B10: =+$K$1 -> Véhicules neufs | C10: [...] | D10: =+SUM(START:END!D10) -> 0 | E10: =IF(D10=0,0,F10/D10) -> 0 | F10: =+SUM(START:END!F10) -> 0 | G10: =+SUM(START:END!G10) -> 0 | H10: =IF(G10=0,0,I10/G10) -> 0 | I10: =+SUM(START:END!I10) -> 0 | J10: =+SUM(START:END!J10) -> 0 | K10: =IF(J10=0,0,L10/J10) -> 0 | L10: =+SUM(START:END!L10) -> 0 | M10: =J10-G10 -> 0 | N10: =L10-I10 -> 0 | O10: =+SUM(START:END!O10) -> 0 | P10: =IF(O10=0,0,Q10/O10) -> 0 | Q10: =+SUM(START:END!Q10) -> 0 | R10: =J10-O10 -> 0 | S10: =L10-Q10 -> 0
A11: =+B11&C11 -> Véhicules neufs[...] | B11: =+$K$1 -> Véhicules neufs | C11: [...] | D11: =+SUM(START:END!D11) -> 0 | E11: =IF(D11=0,0,F11/D11) -> 0 | F11: =+SUM(START:END!F11) -> 0 | G11: =+SUM(START:END!G11) -> 0 | H11: =IF(G11=0,0,I11/G11) -> 0 | I11: =+SUM(START:END!I11) -> 0 | J11: =+SUM(START:END!J11) -> 0 | K11: =IF(J11=0,0,L11/J11) -> 0 | L11: =+SUM(START:END!L11) -> 0 | M11: =J11-G11 -> 0 | N11: =L11-I11 -> 0 | O11: =+SUM(START:END!O11) -> 0 | P11: =IF(O11=0,0,Q11/O11) -> 0 | Q11: =+SUM(START:END!Q11) -> 0 | R11: =J11-O11 -> 0 | S11: =L11-Q11 -> 0
A12: =+B12&C12 -> Véhicules neufs[...] | B12: =+$K$1 -> Véhicules neufs | C12: [...] | D12: =+SUM(START:END!D12) -> 0 | E12: =IF(D12=0,0,F12/D12) -> 0 | F12: =+SUM(START:END!F12) -> 0 | G12: =+SUM(START:END!G12) -> 0 | H12: =IF(G12=0,0,I12/G12) -> 0 | I12: =+SUM(START:END!I12) -> 0 | J12: =+SUM(START:END!J12) -> 0 | K12: =IF(J12=0,0,L12/J12) -> 0 | L12: =+SUM(START:END!L12) -> 0 | M12: =J12-G12 -> 0 | N12: =L12-I12 -> 0 | O12: =+SUM(START:END!O12) -> 0 | P12: =IF(O12=0,0,Q12/O12) -> 0 | Q12: =+SUM(START:END!Q12) -> 0 | R12: =J12-O12 -> 0 | S12: =L12-Q12 -> 0
A13: =+B13&C13 -> Véhicules neufsTotal Neufs | B13: =+$K$1 -> Véhicules neufs | C13: Total Neufs | D13: =+SUM(D6:D12) -> 231.71466 | E13: =IF(D13<=0,0,F13/D13) -> 998.53486 | F13: =+SUM(F6:F12) -> 231375.16 | G13: =+SUM(G6:G12) -> 206.92011 | H13: =IF(G13<=0,0,I13/G13) -> 1383.8618 | I13: =+SUM(I6:I12) -> 286348.83 | J13: =+SUM(J6:J12) -> 203 | K13: =IF(J13<=0,0,L13/J13) -> 1725.4155 | L13: =+SUM(L6:L12) -> 350259.34 | M13: =+SUM(M6:M12) -> -3.9201093 | N13: =+SUM(N6:N12) -> 63910.509 | O13: =+SUM(O6:O12) -> 238 | P13: =IF(O13<=0,0,Q13/O13) -> 708.38483 | Q13: =+SUM(Q6:Q12) -> 168595.59 | R13: =+SUM(R6:R12) -> -35 | S13: =+SUM(S6:S12) -> 181663.75 | V13: =+SUM(START:END!D13)-D13 -> 0 | W13: =+SUM(START:END!G13)-G13 -> 0 | X13: =+SUM(START:END!J13)-J13 -> 0 | Y13: =+SUM(START:END!O13)-O13 -> 0
A14: =+B14&C14 -> Véhicules neufs | B14: =+$K$1 -> Véhicules neufs | M14: =IF(G13=0,0,M13/G13) -> -0.018945038 | N14: =IF(I13=0,0,N13/I13) -> 0.2231911 | R14: =R13/O13 -> -0.14705882 | S14: =IF(Q13=0,0,(S13/Q13)) -> 1.0775119
A15: =+B15&C15 -> Véhicules neufsEx-Démos et courtoisies | B15: =+$K$1 -> Véhicules neufs | C15: Ex-Démos et courtoisies | D15: =+SUM(START:END!D15) -> 24.150542 | E15: =IF(D15=0,0,F15/D15) -> 456.63516 | F15: =+SUM(START:END!F15) -> 11027.987 | G15: =+SUM(START:END!G15) -> 21.417025 | H15: =IF(G15=0,0,I15/G15) -> 795.68226 | I15: =+SUM(START:END!I15) -> 17041.147 | J15: =+SUM(START:END!J15) -> 16 | K15: =IF(J15=0,0,L15/J15) -> 1493.6619 | L15: =+SUM(START:END!L15) -> 23898.59 | M15: =J15-G15 -> -5.4170255 | N15: =L15-I15 -> 6857.4427 | O15: =+SUM(START:END!O15) -> 22 | P15: =IF(O15=0,0,Q15/O15) -> 30.737273 | Q15: =+SUM(START:END!Q15) -> 676.22 | R15: =J15-O15 -> -6 | S15: =L15-Q15 -> 23222.37 | V15: =+SUM(START:END!D15)-D15 -> 0 | W15: =+SUM(START:END!G15)-G15 -> 0 | X15: =+SUM(START:END!J15)-J15 -> 0 | Y15: =+SUM(START:END!O15)-O15 -> 0
A16: =+B16&C16 -> Véhicules neufs | B16: =+$K$1 -> Véhicules neufs
A17: =+B17&C17 -> Véhicules neufsFlottes | B17: =+$K$1 -> Véhicules neufs | C17: Flottes | D17: =+SUM(START:END!D17) -> 3.1998137 | E17: =IF(D17=0,0,F17/D17) -> 563.63318 | F17: =+SUM(START:END!F17) -> 1803.5212 | G17: =+SUM(START:END!G17) -> 7.648539 | H17: =IF(G17=0,0,I17/G17) -> 826.60916 | I17: =+SUM(START:END!I17) -> 6322.3524 | J17: =+SUM(START:END!J17) -> 10 | K17: =IF(J17=0,0,L17/J17) -> 2419.503 | L17: =+SUM(START:END!L17) -> 24195.03 | M17: =J17-G17 -> 2.351461 | N17: =L17-I17 -> 17872.678 | O17: =+SUM(START:END!O17) -> 6 | P17: =IF(O17=0,0,Q17/O17) -> 1624.1633 | Q17: =+SUM(START:END!Q17) -> 9744.98 | R17: =J17-O17 -> 4 | S17: =L17-Q17 -> 14450.05 | V17: =+SUM(START:END!D17)-D17 -> 0 | W17: =+SUM(START:END!G17)-G17 -> 0 | X17: =+SUM(START:END!J17)-J17 -> 0 | Y17: =+SUM(START:END!O17)-O17 -> 0
A18: =+B18&C18 -> Véhicules neufs | B18: =+$K$1 -> Véhicules neufs
A19: =+B19&C19 -> Véhicules neufsRachat bail | B19: =+$K$1 -> Véhicules neufs | C19: Rachat bail | F19: =+SUM(START:END!F19) -> 15000 | I19: =+SUM(START:END!I19) -> 15000 | L19: =+SUM(START:END!L19) -> 24413.88 | N19: =L19-I19 -> 9413.88 | Q19: =+SUM(START:END!Q19) -> 14219.24 | R19: =O19-K19 -> 0 | S19: =L19-Q19 -> 10194.64
A20: =+B20&C20 -> Véhicules neufs | B20: =+$K$1 -> Véhicules neufs
A21: =+B21&C21 -> Véhicules neufsRev. Finances | B21: =+$K$1 -> Véhicules neufs | C21: Rev. Finances | D21: 0 | E21: =IF(D21=0,0,F21/D21) -> 0 | F21: =+SUM(START:END!F21) -> 21499.773 | G21: 0 | H21: =IF(G21=0,0,I21/G21) -> 0 | I21: =+SUM(START:END!I21) -> 21499.773 | K21: =IF(J13=0,0,L21/(J13+J15)) -> 35.485023 | L21: =+SUM(START:END!L21) -> 7771.22 | N21: =L21-I21 -> -13728.553 | P21: =IF(O13=0,0,Q21/(O13+O15)) -> 89.401038 | Q21: =+SUM(START:END!Q21) -> 23244.27 | R21: =O21-K21 -> -35.485023 | S21: =L21-Q21 -> -15473.05
A22: =+B22&C22 -> Véhicules neufsRev. Protections | B22: =+$K$1 -> Véhicules neufs | C22: Rev. Protections | D22: 0 | E22: =IF(D22=0,0,F22/D22) -> 0 | F22: =+SUM(START:END!F22) -> 168498.22 | G22: 0 | H22: =IF(G22=0,0,I22/G22) -> 0 | I22: =+SUM(START:END!I22) -> 168498.22 | K22: =IF(J13=0,0,L22/(J13+J15)) -> 797.75068 | L22: =+SUM(START:END!L22) -> 174707.4 | N22: =L22-I22 -> 6209.1813 | P22: =IF(O13=0,0,Q22/(O13+O15)) -> 460.87235 | Q22: =+SUM(START:END!Q22) -> 119826.81 | R22: =O22-K22 -> -797.75068 | S22: =L22-Q22 -> 54880.59
A23: =+B23&C23 -> Véhicules neufsRev. Autres | B23: =+$K$1 -> Véhicules neufs | C23: Rev. Autres | D23: 0 | E23: =IF(D23=0,0,F23/D23) -> 0 | F23: =+SUM(START:END!F23) -> 4249.9551 | G23: 0 | H23: =IF(G23=0,0,I23/G23) -> 0 | I23: =+SUM(START:END!I23) -> 4249.9551 | K23: =IF(J13=0,0,L23/(J13+J15)) -> 20.952374 | L23: =+SUM(START:END!L23) -> 4588.57 | N23: =L23-I23 -> 338.61493 | P23: =IF(O13=0,0,Q23/(O13+O15)) -> 7.2941923 | Q23: =+SUM(START:END!Q23) -> 1896.49 | R23: =O23-K23 -> -20.952374 | S23: =L23-Q23 -> 2692.08
A24: =+B24&C24 -> Véhicules neufsTotal F&I | B24: =+$K$1 -> Véhicules neufs | C24: Total F&I | D24: =+D15+D13 -> 255.8652 | E24: =IF(D24<=0,0,F24/D24) -> 759.18079 | F24: =F21+F22+F23 -> 194247.95 | G24: =+G15+G13 -> 228.33713 | H24: =IF(G24<=0,0,I24/G24) -> 850.70677 | I24: =I21+I22+I23 -> 194247.95 | J24: =+J15+J13 -> 219 | K24: =IF(J24<=0,0,L24/J24) -> 854.18808 | L24: =L21+L22+L23 -> 187067.19 | M24: =J24-G24 -> -9.3371347 | N24: =L24-I24 -> -7180.7565 | O24: =+O15+O13 -> 260 | P24: =IF(O24<=0,0,Q24/O24) -> 557.56758 | Q24: =Q21+Q22+Q23 -> 144967.57 | S24: =L24-Q24 -> 42099.62 | V24: =+SUM(START:END!D24)-D24 -> 0 | W24: =+SUM(START:END!G24)-G24 -> 0 | X24: =+SUM(START:END!J24)-J24 -> 0 | Y24: =+SUM(START:END!O24)-O24 -> 0
A25: =+B25&C25 -> Véhicules neufs | B25: =+$K$1 -> Véhicules neufs | N25: =IF(N24=0,0,N24/I24) -> -0.036966962 | S25: =IF(Q24=0,0,(S24/Q24)) -> 0.29040716
A26: =+B26&C26 -> Véhicules neufs | B26: =+$K$1 -> Véhicules neufs
A27: =+B27&C27 -> Véhicules neufsTotal Dépt. Neufs | B27: =+$K$1 -> Véhicules neufs | C27: Total Dépt. Neufs | D27: =+D13+D15+D17 -> 259.06502 | E27: =IF(D27<=0,0,F27/D27) -> 1750.3507 | F27: =F13+F17+F24+F19+F15 -> 453454.62 | G27: =+G13+G15+G17 -> 235.98567 | H27: =IF(G27<=0,0,I27/G27) -> 2199.1177 | I27: =I13+I17+I24+I19+I15 -> 518960.28 | J27: =+J13+J15+J17 -> 229 | K27: =IF(J27<=0,0,L27/J27) -> 2663.0307 | L27: =L13+L17+L24+L19+L15 -> 609834.03 | M27: =J27-G27 -> -6.9856738 | N27: =L27-I27 -> 90873.753 | O27: =+O13+O15+O17 -> 266 | P27: =IF(O27<=0,0,Q27/O27) -> 1271.4421 | Q27: =Q13+Q17+Q24+Q19+Q15 -> 338203.6 | R27: =J27-O27 -> -37 | S27: =L27-Q27 -> 271630.43 | V27: =+SUM(START:END!D27)-D27 -> 0 | W27: =+SUM(START:END!G27)-G27 -> 0 | X27: =+SUM(START:END!J27)-J27 -> 0 | Y27: =+SUM(START:END!O27)-O27 -> 0
A28: =+B28&C28 -> Véhicules neufs | B28: =+$K$1 -> Véhicules neufs | M28: =M27/G27 -> -0.02960211 | N28: =N27/I27 -> 0.17510734 | R28: =R27/O27 -> -0.13909774 | S28: =IF(Q27=0,0,S27/Q27) -> 0.80315653
A29: =+B29&C29 -> Véhicules neufs | B29: =+$K$1 -> Véhicules neufs
A30: =+B30&C30 -> Véhicules neufsDEPENSES | B30: =+$K$1 -> Véhicules neufs | C30: DEPENSES
A31: =+B31&C31 -> Véhicules neufsComm. vendeurs | B31: =+$K$1 -> Véhicules neufs | C31: Comm. vendeurs | E31: =F31/D$24 -> 328.14376 | F31: =+SUM(START:END!F31) -> 83960.569 | H31: =I31/G$24 -> 372.99134 | I31: =+SUM(START:END!I31) -> 85167.775 | J31: =L31/L13 -> 0.38852737 | K31: =IF(L31=0,0,L31/J$24) -> 621.39425 | L31: =+SUM(START:END!L31) -> 136085.34 | N31: =L31-I31 -> 50917.565 | P31: =IF(Q31=0,0,Q31/O$24) -> 415.49396 | Q31: =+SUM(START:END!Q31) -> 108028.43 | S31: =L31-Q31 -> 28056.91
A32: =+B32&C32 -> Véhicules neufsComm. F&I | B32: =+$K$1 -> Véhicules neufs | C32: Comm. F&I | E32: =F32/D$24 -> 227.75424 | F32: =+SUM(START:END!F32) -> 58274.384 | H32: =I32/G$24 -> 255.21203 | I32: =+SUM(START:END!I32) -> 58274.384 | J32: =L32/L24 -> 0.30881375 | K32: =IF(L32=0,0,L32/J$24) -> 263.78502 | L32: =+SUM(START:END!L32) -> 57768.92 | N32: =L32-I32 -> -505.46394 | P32: =IF(Q32=0,0,Q32/O$24) -> 230.9225 | Q32: =+SUM(START:END!Q32) -> 60039.85 | S32: =L32-Q32 -> -2270.93
A33: =+B33&C33 -> Véhicules neufsFrais de livraison | B33: =+$K$1 -> Véhicules neufs | C33: Frais de livraison | E33: =F33/D$24 -> 175.95131 | F33: =+SUM(START:END!F33) -> 45019.818 | H33: =I33/G$24 -> 197.1638 | I33: =+SUM(START:END!I33) -> 45019.818 | K33: =IF(L33=0,0,L33/J$24) -> 138.73658 | L33: =+SUM(START:END!L33) -> 30383.31 | N33: =L33-I33 -> -14636.508 | P33: =IF(Q33=0,0,Q33/O$24) -> 140.66046 | Q33: =+SUM(START:END!Q33) -> 36571.72 | S33: =L33-Q33 -> -6188.41
A34: =+B34&C34 -> Véhicules neufsService gratuit 1 | B34: =+$K$1 -> Véhicules neufs | C34: Service gratuit 1 | E34: =F34/D$24 -> 5.3589232 | F34: =+SUM(START:END!F34) -> 1371.162 | H34: =I34/G$24 -> 6.004989 | I34: =+SUM(START:END!I34) -> 1371.162 | K34: =IF(L34=0,0,L34/J$24) -> 10.976895 | L34: =+SUM(START:END!L34) -> 2403.94 | N34: =L34-I34 -> 1032.778 | P34: =IF(Q34=0,0,Q34/O$24) -> 2.5856923 | Q34: =+SUM(START:END!Q34) -> 672.28 | S34: =L34-Q34 -> 1731.66
A35: =+B35&C35 -> Véhicules neufsEntretien stock | B35: =+$K$1 -> Véhicules neufs | C35: Entretien stock | E35: =F35/D$24 -> 30.367232 | F35: =+SUM(START:END!F35) -> 7769.9179 | H35: =I35/G$24 -> 34.028271 | I35: =+SUM(START:END!I35) -> 7769.9179 | K35: =IF(L35=0,0,L35/J$24) -> 9.8088128 | L35: =+SUM(START:END!L35) -> 2148.13 | N35: =L35-I35 -> -5621.7879 | P35: =IF(Q35=0,0,Q35/O$24) -> 21.498423 | Q35: =+SUM(START:END!Q35) -> 5589.59 | S35: =L35-Q35 -> -3441.46
A36: =+B36&C36 -> Véhicules neufsPublicité 1 | B36: =+$K$1 -> Véhicules neufs | C36: Publicité 1 | E36: =F36/D$24 -> 161.36579 | F36: =+SUM(START:END!F36) -> 41287.891 | H36: =I36/G$24 -> 180.81987 | I36: =+SUM(START:END!I36) -> 41287.891 | K36: =IF(L36=0,0,L36/J$24) -> 160.28037 | L36: =+SUM(START:END!L36) -> 35101.4 | N36: =L36-I36 -> -6186.4907 | P36: =IF(Q36=0,0,Q36/O$24) -> 87.653846 | Q36: =+SUM(START:END!Q36) -> 22790 | S36: =L36-Q36 -> 12311.4
A37: =+B37&C37 -> Véhicules neufsIntérêt de gros | B37: =+$K$1 -> Véhicules neufs | C37: Intérêt de gros | E37: =F37/D$24 -> 177.19171 | F37: =+SUM(START:END!F37) -> 45337.194 | H37: =I37/G$24 -> 199.83587 | I37: =+SUM(START:END!I37) -> 45629.951 | K37: =IF(L37=0,0,L37/J$24) -> 202.50959 | L37: =+SUM(START:END!L37) -> 44349.6 | N37: =L37-I37 -> -1280.3507 | P37: =IF(Q37=0,0,Q37/O$24) -> 241.01169 | Q37: =+SUM(START:END!Q37) -> 62663.04 | S37: =L37-Q37 -> -18313.44
A38: =+B38&C38 -> Véhicules neufs[...] | B38: =+$K$1 -> Véhicules neufs | C38: [...] | E38: =F38/D$24 -> 0 | F38: =+SUM(START:END!F38) -> 0 | H38: =I38/G$24 -> 0 | I38: =+SUM(START:END!I38) -> 0 | K38: =IF(L38=0,0,L38/J$24) -> 0 | L38: =+SUM(START:END!L38) -> 0 | N38: =L38-I38 -> 0 | P38: =IF(Q38=0,0,Q38/O$24) -> 0 | Q38: =+SUM(START:END!Q38) -> 0 | S38: =L38-Q38 -> 0
A39: =+B39&C39 -> Véhicules neufs[...] | B39: =+$K$1 -> Véhicules neufs | C39: [...] | E39: =F39/D$24 -> 0 | F39: =+SUM(START:END!F39) -> 0 | H39: =I39/G$24 -> 0 | I39: =+SUM(START:END!I39) -> 0 | K39: =IF(L39=0,0,L39/J$24) -> 0 | L39: =+SUM(START:END!L39) -> 0 | N39: =L39-I39 -> 0 | P39: =IF(Q39=0,0,Q39/O$24) -> 0 | Q39: =+SUM(START:END!Q39) -> 0 | S39: =L39-Q39 -> 0
A40: =+B40&C40 -> Véhicules neufs[...] | B40: =+$K$1 -> Véhicules neufs | C40: [...] | E40: =F40/D$24 -> 0 | F40: =+SUM(START:END!F40) -> 0 | H40: =I40/G$24 -> 0 | I40: =+SUM(START:END!I40) -> 0 | K40: =IF(L40=0,0,L40/J$24) -> 0 | L40: =+SUM(START:END!L40) -> 0 | N40: =L40-I40 -> 0 | P40: =IF(Q40=0,0,Q40/O$24) -> 0 | Q40: =+SUM(START:END!Q40) -> 0 | S40: =L40-Q40 -> 0
...

Sheet START

Sheet VW 4
C1: =[5]Parametres!B1 -> Volks | K1: Véhicules neufs | S1: =CONCATENATE("Réalisé,"," ",[5]Parametres!B3," ",[5]Parametres!B4) -> Réalisé, Avril 2021
D2: X | E2: O | F2: U | G2: X | H2: O | I2: U | J2: NB | L2: $ | O2: NB | Q2: $
D3: BUDGET ORIGINAL | G3: BUDGET REVISE | J3: RÉALISATION | M3: ÉCART réel / révisé | O3: ANNÉE PRÉCÉDENTE | R3: ÉCART réel / original | V3: NEUF | W3: 0.45
D4: UNITE | E4: $P/UNITÉ | F4: $PROFITS | G4: UNITE | H4: $P/UNITÉ | I4: $PROFITS | J4: UNITE | K4: $P/UNITE | L4: $PROFITS | M4: UNITÉ | N4: $PROFITS | O4: UNITE | P4: $P/UNITE | Q4: $PROFITS | R4: UNITE | S4: $PROFITS | V4: USAGE | W4: 0.1
A5: =+B5&C5 -> Véhicules neufsVentes nettes | B5: =+$K$1 -> Véhicules neufs | C5: Ventes nettes | F5: =+INDEX('[5]Budget original'!$A$2:$AO$496,MATCH($A5,'[5]Budget original'!$A$2:$A$496,0),MATCH(F$2,'[5]Budget original'!$A$2:$AO$2,0)) -> 751340.66 | I5: =+INDEX('[5]Budget révisé'!$A$2:$AO$496,MATCH($A5,'[5]Budget révisé'!$A$2:$A$496,0),MATCH(I$2,'[5]Budget révisé'!$A$2:$AO$2,0)) -> 751340.66 | L5: =-SUMIFS([5]BV_Data_An_Cour!$O:$O,[5]BV_Data_An_Cour!$X:$X,"Oui",[5]BV_Data_An_Cour!$U:$U,$B5) -> 3185397.8 | Q5: =-SUMIFS([5]BV_Data_An_Prec!$O:$O,[5]BV_Data_An_Prec!$X:$X,"Oui",[5]BV_Data_An_Prec!$U:$U,$B5) -> 3012832.6 | V5: SERVICE | W5: 0.225
A6: =+B6&C6 -> Véhicules neufsAutos détail | B6: =+$K$1 -> Véhicules neufs | C6: Autos détail | D6: =+INDEX('[5]Budget original'!$A$2:$AO$496,MATCH($A6,'[5]Budget original'!$A$2:$A$496,0),MATCH(D$2,'[5]Budget original'!$A$2:$AO$2,0)) -> 27.36626 | E6: =IF(D6=0,0,F6/D6) -> 604.29043 | F6: =+INDEX('[5]Budget original'!$A$2:$AO$496,MATCH($A6,'[5]Budget original'!$A$2:$A$496,0),MATCH(F$2,'[5]Budget original'!$A$2:$AO$2,0)) -> 16537.169 | G6: =+INDEX('[5]Budget révisé'!$A$2:$AO$496,MATCH($A6,'[5]Budget révisé'!$A$2:$A$496,0),MATCH(G$2,'[5]Budget révisé'!$A$2:$AO$2,0)) -> 27.36626 | H6: =IF(G6=0,0,I6/G6) -> 955.05622 | I6: =+INDEX('[5]Budget révisé'!$A$2:$AO$496,MATCH($A6,'[5]Budget révisé'!$A$2:$A$496,0),MATCH(I$2,'[5]Budget révisé'!$A$2:$AO$2,0)) -> 26136.316 | J6: =-SUMIFS([5]BV_Data_An_Cour!$O:$O,[5]BV_Data_An_Cour!$U:$U,$B6,[5]BV_Data_An_Cour!$V:$V,$C6,[5]BV_Data_An_Cour!$W:$W,J$2) -> 24 | K6: =IF(J6=0,0,L6/J6) -> 474.33792 | L6: =-SUMIFS([5]BV_Data_An_Cour!$O:$O,[5]BV_Data_An_Cour!$U:$U,$B6,[5]BV_Data_An_Cour!$V:$V,$C6,[5]BV_Data_An_Cour!$W:$W,L$2) -> 11384.11 | M6: =J6-G6 -> -3.3662596 | N6: =L6-I6 -> -14752.206 | O6: =-SUMIFS([5]BV_Data_An_Prec!$O:$O,[5]BV_Data_An_Prec!$U:$U,$B6,[5]BV_Data_An_Prec!$V:$V,$C6,[5]BV_Data_An_Prec!$W:$W,O$2) -> 56 | P6: =IF(O6=0,0,Q6/O6) -> 756.66714 | Q6: =-SUMIFS([5]BV_Data_An_Prec!$O:$O,[5]BV_Data_An_Prec!$U:$U,$B6,[5]BV_Data_An_Prec!$V:$V,$C6,[5]BV_Data_An_Prec!$W:$W,Q$2) -> 42373.36 | R6: =J6-O6 -> -32 | S6: =L6-Q6 -> -30989.25 | V6: CARROSSERIE | W6: 0.025
A7: =+B7&C7 -> Véhicules neufsCamions détail | B7: =+$K$1 -> Véhicules neufs | C7: Camions détail | D7: =+INDEX('[5]Budget original'!$A$2:$AO$496,MATCH($A7,'[5]Budget original'!$A$2:$A$496,0),MATCH(D$2,'[5]Budget original'!$A$2:$AO$2,0)) -> 36.759299 | E7: =IF(D7=0,0,F7/D7) -> 1315.4791 | F7: =+INDEX('[5]Budget original'!$A$2:$AO$496,MATCH($A7,'[5]Budget original'!$A$2:$A$496,0),MATCH(F$2,'[5]Budget original'!$A$2:$AO$2,0)) -> 48356.09 | G7: =+INDEX('[5]Budget révisé'!$A$2:$AO$496,MATCH($A7,'[5]Budget révisé'!$A$2:$A$496,0),MATCH(G$2,'[5]Budget révisé'!$A$2:$AO$2,0)) -> 36.759299 | H7: =IF(G7=0,0,I7/G7) -> 1702.6669 | I7: =+INDEX('[5]Budget révisé'!$A$2:$AO$496,MATCH($A7,'[5]Budget révisé'!$A$2:$A$496,0),MATCH(I$2,'[5]Budget révisé'!$A$2:$AO$2,0)) -> 62588.841 | J7: =-SUMIFS([5]BV_Data_An_Cour!$O:$O,[5]BV_Data_An_Cour!$U:$U,$B7,[5]BV_Data_An_Cour!$V:$V,$C7,[5]BV_Data_An_Cour!$W:$W,J$2) -> 41 | K7: =IF(J7=0,0,L7/J7) -> 2167.9161 | L7: =-SUMIFS([5]BV_Data_An_Cour!$O:$O,[5]BV_Data_An_Cour!$U:$U,$B7,[5]BV_Data_An_Cour!$V:$V,$C7,[5]BV_Data_An_Cour!$W:$W,L$2) -> 88884.56 | M7: =J7-G7 -> 4.2407008 | N7: =L7-I7 -> 26295.719 | O7: =-SUMIFS([5]BV_Data_An_Prec!$O:$O,[5]BV_Data_An_Prec!$U:$U,$B7,[5]BV_Data_An_Prec!$V:$V,$C7,[5]BV_Data_An_Prec!$W:$W,O$2) -> 28 | P7: =IF(O7=0,0,Q7/O7) -> 666.27321 | Q7: =-SUMIFS([5]BV_Data_An_Prec!$O:$O,[5]BV_Data_An_Prec!$U:$U,$B7,[5]BV_Data_An_Prec!$V:$V,$C7,[5]BV_Data_An_Prec!$W:$W,Q$2) -> 18655.65 | R7: =J7-O7 -> 13 | S7: =L7-Q7 -> 70228.91 | V7: PIECES | W7: 0.2
A8: =+B8&C8 -> Véhicules neufsSprinter | B8: =+$K$1 -> Véhicules neufs | C8: Sprinter | D8: =+INDEX('[5]Budget original'!$A$2:$AO$496,MATCH($A8,'[5]Budget original'!$A$2:$A$496,0),MATCH(D$2,'[5]Budget original'!$A$2:$AO$2,0)) -> 0 | E8: =IF(D8=0,0,F8/D8) -> 0 | F8: =+INDEX('[5]Budget original'!$A$2:$AO$496,MATCH($A8,'[5]Budget original'!$A$2:$A$496,0),MATCH(F$2,'[5]Budget original'!$A$2:$AO$2,0)) -> 0 | G8: =+INDEX('[5]Budget révisé'!$A$2:$AO$496,MATCH($A8,'[5]Budget révisé'!$A$2:$A$496,0),MATCH(G$2,'[5]Budget révisé'!$A$2:$AO$2,0)) -> 0 | H8: =IF(G8=0,0,I8/G8) -> 0 | I8: =+INDEX('[5]Budget révisé'!$A$2:$AO$496,MATCH($A8,'[5]Budget révisé'!$A$2:$A$496,0),MATCH(I$2,'[5]Budget révisé'!$A$2:$AO$2,0)) -> 0 | J8: =-SUMIFS([5]BV_Data_An_Cour!$O:$O,[5]BV_Data_An_Cour!$U:$U,$B8,[5]BV_Data_An_Cour!$V:$V,$C8,[5]BV_Data_An_Cour!$W:$W,J$2) -> 0 | K8: =IF(J8=0,0,L8/J8) -> 0 | L8: =-SUMIFS([5]BV_Data_An_Cour!$O:$O,[5]BV_Data_An_Cour!$U:$U,$B8,[5]BV_Data_An_Cour!$V:$V,$C8,[5]BV_Data_An_Cour!$W:$W,L$2) -> 0 | M8: =J8-G8 -> 0 | N8: =L8-I8 -> 0 | O8: =-SUMIFS([5]BV_Data_An_Prec!$O:$O,[5]BV_Data_An_Prec!$U:$U,$B8,[5]BV_Data_An_Prec!$V:$V,$C8,[5]BV_Data_An_Prec!$W:$W,O$2) -> 0 | P8: =IF(O8=0,0,Q8/O8) -> 0 | Q8: =-SUMIFS([5]BV_Data_An_Prec!$O:$O,[5]BV_Data_An_Prec!$U:$U,$B8,[5]BV_Data_An_Prec!$V:$V,$C8,[5]BV_Data_An_Prec!$W:$W,Q$2) -> 0 | R8: =J8-O8 -> 0 | S8: =L8-Q8 -> 0 | W8: =SUM(W3:W7) -> 1
A9: =+B9&C9 -> Véhicules neufsMoto détail | B9: =+$K$1 -> Véhicules neufs | C9: Moto détail | D9: =+INDEX('[5]Budget original'!$A$2:$AO$496,MATCH($A9,'[5]Budget original'!$A$2:$A$496,0),MATCH(D$2,'[5]Budget original'!$A$2:$AO$2,0)) -> 0 | E9: =IF(D9=0,0,F9/D9) -> 0 | F9: =+INDEX('[5]Budget original'!$A$2:$AO$496,MATCH($A9,'[5]Budget original'!$A$2:$A$496,0),MATCH(F$2,'[5]Budget original'!$A$2:$AO$2,0)) -> 0 | G9: =+INDEX('[5]Budget révisé'!$A$2:$AO$496,MATCH($A9,'[5]Budget révisé'!$A$2:$A$496,0),MATCH(G$2,'[5]Budget révisé'!$A$2:$AO$2,0)) -> 0 | H9: =IF(G9=0,0,I9/G9) -> 0 | I9: =+INDEX('[5]Budget révisé'!$A$2:$AO$496,MATCH($A9,'[5]Budget révisé'!$A$2:$A$496,0),MATCH(I$2,'[5]Budget révisé'!$A$2:$AO$2,0)) -> 0 | J9: =-SUMIFS([5]BV_Data_An_Cour!$O:$O,[5]BV_Data_An_Cour!$U:$U,$B9,[5]BV_Data_An_Cour!$V:$V,$C9,[5]BV_Data_An_Cour!$W:$W,J$2) -> 0 | K9: =IF(J9=0,0,L9/J9) -> 0 | L9: =-SUMIFS([5]BV_Data_An_Cour!$O:$O,[5]BV_Data_An_Cour!$U:$U,$B9,[5]BV_Data_An_Cour!$V:$V,$C9,[5]BV_Data_An_Cour!$W:$W,L$2) -> 0 | M9: =J9-G9 -> 0 | N9: =L9-I9 -> 0 | O9: =-SUMIFS([5]BV_Data_An_Prec!$O:$O,[5]BV_Data_An_Prec!$U:$U,$B9,[5]BV_Data_An_Prec!$V:$V,$C9,[5]BV_Data_An_Prec!$W:$W,O$2) -> 0 | P9: =IF(O9=0,0,Q9/O9) -> 0 | Q9: =-SUMIFS([5]BV_Data_An_Prec!$O:$O,[5]BV_Data_An_Prec!$U:$U,$B9,[5]BV_Data_An_Prec!$V:$V,$C9,[5]BV_Data_An_Prec!$W:$W,Q$2) -> 0 | R9: =J9-O9 -> 0 | S9: =L9-Q9 -> 0
A10: =+B10&C10 -> Véhicules neufs[...] | B10: =+$K$1 -> Véhicules neufs | C10: [...] | D10: =+INDEX('[5]Budget original'!$A$2:$AO$496,MATCH($A10,'[5]Budget original'!$A$2:$A$496,0),MATCH(D$2,'[5]Budget original'!$A$2:$AO$2,0)) -> 0 | E10: =IF(D10=0,0,F10/D10) -> 0 | F10: =+INDEX('[5]Budget original'!$A$2:$AO$496,MATCH($A10,'[5]Budget original'!$A$2:$A$496,0),MATCH(F$2,'[5]Budget original'!$A$2:$AO$2,0)) -> 0 | G10: =+INDEX('[5]Budget révisé'!$A$2:$AO$496,MATCH($A10,'[5]Budget révisé'!$A$2:$A$496,0),MATCH(G$2,'[5]Budget révisé'!$A$2:$AO$2,0)) -> 0 | H10: =IF(G10=0,0,I10/G10) -> 0 | I10: =+INDEX('[5]Budget révisé'!$A$2:$AO$496,MATCH($A10,'[5]Budget révisé'!$A$2:$A$496,0),MATCH(I$2,'[5]Budget révisé'!$A$2:$AO$2,0)) -> 0 | J10: =-SUMIFS([5]BV_Data_An_Cour!$O:$O,[5]BV_Data_An_Cour!$U:$U,$B10,[5]BV_Data_An_Cour!$V:$V,$C10,[5]BV_Data_An_Cour!$W:$W,J$2) -> 0 | K10: =IF(J10=0,0,L10/J10) -> 0 | L10: =-SUMIFS([5]BV_Data_An_Cour!$O:$O,[5]BV_Data_An_Cour!$U:$U,$B10,[5]BV_Data_An_Cour!$V:$V,$C10,[5]BV_Data_An_Cour!$W:$W,L$2) -> 0 | M10: =J10-G10 -> 0 | N10: =L10-I10 -> 0 | O10: =-SUMIFS([5]BV_Data_An_Prec!$O:$O,[5]BV_Data_An_Prec!$U:$U,$B10,[5]BV_Data_An_Prec!$V:$V,$C10,[5]BV_Data_An_Prec!$W:$W,O$2) -> 0 | P10: =IF(O10=0,0,Q10/O10) -> 0 | Q10: =-SUMIFS([5]BV_Data_An_Prec!$O:$O,[5]BV_Data_An_Prec!$U:$U,$B10,[5]BV_Data_An_Prec!$V:$V,$C10,[5]BV_Data_An_Prec!$W:$W,Q$2) -> 0 | R10: =J10-O10 -> 0 | S10: =L10-Q10 -> 0
A11: =+B11&C11 -> Véhicules neufs[...] | B11: =+$K$1 -> Véhicules neufs | C11: [...] | D11: =+INDEX('[5]Budget original'!$A$2:$AO$496,MATCH($A11,'[5]Budget original'!$A$2:$A$496,0),MATCH(D$2,'[5]Budget original'!$A$2:$AO$2,0)) -> 0 | E11: =IF(D11=0,0,F11/D11) -> 0 | F11: =+INDEX('[5]Budget original'!$A$2:$AO$496,MATCH($A11,'[5]Budget original'!$A$2:$A$496,0),MATCH(F$2,'[5]Budget original'!$A$2:$AO$2,0)) -> 0 | G11: =+INDEX('[5]Budget révisé'!$A$2:$AO$496,MATCH($A11,'[5]Budget révisé'!$A$2:$A$496,0),MATCH(G$2,'[5]Budget révisé'!$A$2:$AO$2,0)) -> 0 | H11: =IF(G11=0,0,I11/G11) -> 0 | I11: =+INDEX('[5]Budget révisé'!$A$2:$AO$496,MATCH($A11,'[5]Budget révisé'!$A$2:$A$496,0),MATCH(I$2,'[5]Budget révisé'!$A$2:$AO$2,0)) -> 0 | J11: =-SUMIFS([5]BV_Data_An_Cour!$O:$O,[5]BV_Data_An_Cour!$U:$U,$B11,[5]BV_Data_An_Cour!$V:$V,$C11,[5]BV_Data_An_Cour!$W:$W,J$2) -> 0 | K11: =IF(J11=0,0,L11/J11) -> 0 | L11: =-SUMIFS([5]BV_Data_An_Cour!$O:$O,[5]BV_Data_An_Cour!$U:$U,$B11,[5]BV_Data_An_Cour!$V:$V,$C11,[5]BV_Data_An_Cour!$W:$W,L$2) -> 0 | M11: =J11-G11 -> 0 | N11: =L11-I11 -> 0 | O11: =-SUMIFS([5]BV_Data_An_Prec!$O:$O,[5]BV_Data_An_Prec!$U:$U,$B11,[5]BV_Data_An_Prec!$V:$V,$C11,[5]BV_Data_An_Prec!$W:$W,O$2) -> 0 | P11: =IF(O11=0,0,Q11/O11) -> 0 | Q11: =-SUMIFS([5]BV_Data_An_Prec!$O:$O,[5]BV_Data_An_Prec!$U:$U,$B11,[5]BV_Data_An_Prec!$V:$V,$C11,[5]BV_Data_An_Prec!$W:$W,Q$2) -> 0 | R11: =J11-O11 -> 0 | S11: =L11-Q11 -> 0
A12: =+B12&C12 -> Véhicules neufs[...] | B12: =+$K$1 -> Véhicules neufs | C12: [...] | D12: =+INDEX('[5]Budget original'!$A$2:$AO$496,MATCH($A12,'[5]Budget original'!$A$2:$A$496,0),MATCH(D$2,'[5]Budget original'!$A$2:$AO$2,0)) -> 0 | E12: =IF(D12=0,0,F12/D12) -> 0 | F12: =+INDEX('[5]Budget original'!$A$2:$AO$496,MATCH($A12,'[5]Budget original'!$A$2:$A$496,0),MATCH(F$2,'[5]Budget original'!$A$2:$AO$2,0)) -> 0 | G12: =+INDEX('[5]Budget révisé'!$A$2:$AO$496,MATCH($A12,'[5]Budget révisé'!$A$2:$A$496,0),MATCH(G$2,'[5]Budget révisé'!$A$2:$AO$2,0)) -> 0 | H12: =IF(G12=0,0,I12/G12) -> 0 | I12: =+INDEX('[5]Budget révisé'!$A$2:$AO$496,MATCH($A12,'[5]Budget révisé'!$A$2:$A$496,0),MATCH(I$2,'[5]Budget révisé'!$A$2:$AO$2,0)) -> 0 | J12: =-SUMIFS([5]BV_Data_An_Cour!$O:$O,[5]BV_Data_An_Cour!$U:$U,$B12,[5]BV_Data_An_Cour!$V:$V,$C12,[5]BV_Data_An_Cour!$W:$W,J$2) -> 0 | K12: =IF(J12=0,0,L12/J12) -> 0 | L12: =-SUMIFS([5]BV_Data_An_Cour!$O:$O,[5]BV_Data_An_Cour!$U:$U,$B12,[5]BV_Data_An_Cour!$V:$V,$C12,[5]BV_Data_An_Cour!$W:$W,L$2) -> 0 | M12: =J12-G12 -> 0 | N12: =L12-I12 -> 0 | O12: =-SUMIFS([5]BV_Data_An_Prec!$O:$O,[5]BV_Data_An_Prec!$U:$U,$B12,[5]BV_Data_An_Prec!$V:$V,$C12,[5]BV_Data_An_Prec!$W:$W,O$2) -> 0 | P12: =IF(O12=0,0,Q12/O12) -> 0 | Q12: =-SUMIFS([5]BV_Data_An_Prec!$O:$O,[5]BV_Data_An_Prec!$U:$U,$B12,[5]BV_Data_An_Prec!$V:$V,$C12,[5]BV_Data_An_Prec!$W:$W,Q$2) -> 0 | R12: =J12-O12 -> 0 | S12: =L12-Q12 -> 0
A13: =+B13&C13 -> Véhicules neufsTotal Neufs | B13: =+$K$1 -> Véhicules neufs | C13: Total Neufs | D13: =+SUM(D6:D12) -> 64.125559 | E13: =IF(D13<=0,0,F13/D13) -> 1011.9718 | F13: =+SUM(F6:F12) -> 64893.259 | G13: =+SUM(G6:G12) -> 64.125559 | H13: =IF(G13<=0,0,I13/G13) -> 1383.6161 | I13: =+SUM(I6:I12) -> 88725.158 | J13: =+SUM(J6:J12) -> 65 | K13: =IF(J13<=0,0,L13/J13) -> 1542.5949 | L13: =+SUM(L6:L12) -> 100268.67 | M13: =+SUM(M6:M12) -> 0.87444115 | N13: =+SUM(N6:N12) -> 11543.512 | O13: =+SUM(O6:O12) -> 84 | P13: =IF(O13<=0,0,Q13/O13) -> 726.53583 | Q13: =+SUM(Q6:Q12) -> 61029.01 | R13: =+SUM(R6:R12) -> -19 | S13: =+SUM(S6:S12) -> 39239.66
A14: =+B14&C14 -> Véhicules neufs | B14: =+$K$1 -> Véhicules neufs | M14: =IF(G13=0,0,M13/G13) -> 0.01363639 | N14: =IF(I13=0,0,N13/I13) -> 0.13010416 | R14: =R13/O13 -> -0.22619048 | S14: =IF(Q13=0,0,(S13/Q13)) -> 0.64296734
A15: =+B15&C15 -> Véhicules neufsEx-Démos et courtoisies | B15: =+$K$1 -> Véhicules neufs | C15: Ex-Démos et courtoisies | D15: =+INDEX('[5]Budget original'!$A$2:$AO$496,MATCH($A15,'[5]Budget original'!$A$2:$A$496,0),MATCH(D$2,'[5]Budget original'!$A$2:$AO$2,0)) -> 6.683509 | E15: =IF(D15=0,0,F15/D15) -> 400 | F15: =+INDEX('[5]Budget original'!$A$2:$AO$496,MATCH($A15,'[5]Budget original'!$A$2:$A$496,0),MATCH(F$2,'[5]Budget original'!$A$2:$AO$2,0)) -> 2673.4036 | G15: =+INDEX('[5]Budget révisé'!$A$2:$AO$496,MATCH($A15,'[5]Budget révisé'!$A$2:$A$496,0),MATCH(G$2,'[5]Budget révisé'!$A$2:$AO$2,0)) -> 6.683509 | H15: =IF(G15=0,0,I15/G15) -> 790.03378 | I15: =+INDEX('[5]Budget révisé'!$A$2:$AO$496,MATCH($A15,'[5]Budget révisé'!$A$2:$A$496,0),MATCH(I$2,'[5]Budget révisé'!$A$2:$AO$2,0)) -> 5280.1979 | J15: =-SUMIFS([5]BV_Data_An_Cour!$O:$O,[5]BV_Data_An_Cour!$U:$U,$B15,[5]BV_Data_An_Cour!$V:$V,$C15,[5]BV_Data_An_Cour!$W:$W,J$2) -> 3 | K15: =IF(J15=0,0,L15/J15) -> 1041.6767 | L15: =-SUMIFS([5]BV_Data_An_Cour!$O:$O,[5]BV_Data_An_Cour!$U:$U,$B15,[5]BV_Data_An_Cour!$V:$V,$C15,[5]BV_Data_An_Cour!$W:$W,L$2) -> 3125.03 | M15: =J15-G15 -> -3.683509 | N15: =L15-I15 -> -2155.1679 | O15: =-SUMIFS([5]BV_Data_An_Prec!$O:$O,[5]BV_Data_An_Prec!$U:$U,$B15,[5]BV_Data_An_Prec!$V:$V,$C15,[5]BV_Data_An_Prec!$W:$W,O$2) -> 0 | P15: =IF(O15=0,0,Q15/O15) -> 0 | Q15: =-SUMIFS([5]BV_Data_An_Prec!$O:$O,[5]BV_Data_An_Prec!$U:$U,$B15,[5]BV_Data_An_Prec!$V:$V,$C15,[5]BV_Data_An_Prec!$W:$W,Q$2) -> 0 | R15: =J15-O15 -> 3 | S15: =L15-Q15 -> 3125.03 | V15: =3125-L15 -> -0.03
A16: =+B16&C16 -> Véhicules neufs | B16: =+$K$1 -> Véhicules neufs
A17: =+B17&C17 -> Véhicules neufsFlottes | B17: =+$K$1 -> Véhicules neufs | C17: Flottes | D17: =+INDEX('[5]Budget original'!$A$2:$AO$496,MATCH($A17,'[5]Budget original'!$A$2:$A$496,0),MATCH(D$2,'[5]Budget original'!$A$2:$AO$2,0)) -> 0 | E17: =IF(D17=0,0,F17/D17) -> 0 | F17: =+INDEX('[5]Budget original'!$A$2:$AO$496,MATCH($A17,'[5]Budget original'!$A$2:$A$496,0),MATCH(F$2,'[5]Budget original'!$A$2:$AO$2,0)) -> 0 | G17: =+INDEX('[5]Budget révisé'!$A$2:$AO$496,MATCH($A17,'[5]Budget révisé'!$A$2:$A$496,0),MATCH(G$2,'[5]Budget révisé'!$A$2:$AO$2,0)) -> 2.4487254 | H17: =IF(G17=0,0,I17/G17) -> 800 | I17: =+INDEX('[5]Budget révisé'!$A$2:$AO$496,MATCH($A17,'[5]Budget révisé'!$A$2:$A$496,0),MATCH(I$2,'[5]Budget révisé'!$A$2:$AO$2,0)) -> 1958.9803 | J17: =-SUMIFS([5]BV_Data_An_Cour!$O:$O,[5]BV_Data_An_Cour!$U:$U,$B17,[5]BV_Data_An_Cour!$V:$V,$C17,[5]BV_Data_An_Cour!$W:$W,J$2) -> 5 | K17: =IF(J17=0,0,L17/J17) -> 2400.116 | L17: =-SUMIFS([5]BV_Data_An_Cour!$O:$O,[5]BV_Data_An_Cour!$U:$U,$B17,[5]BV_Data_An_Cour!$V:$V,$C17,[5]BV_Data_An_Cour!$W:$W,L$2) -> 12000.58 | M17: =J17-G17 -> 2.5512746 | N17: =L17-I17 -> 10041.6 | O17: =-SUMIFS([5]BV_Data_An_Prec!$O:$O,[5]BV_Data_An_Prec!$U:$U,$B17,[5]BV_Data_An_Prec!$V:$V,$C17,[5]BV_Data_An_Prec!$W:$W,O$2) -> 0 | P17: =IF(O17=0,0,Q17/O17) -> 0 | Q17: =-SUMIFS([5]BV_Data_An_Prec!$O:$O,[5]BV_Data_An_Prec!$U:$U,$B17,[5]BV_Data_An_Prec!$V:$V,$C17,[5]BV_Data_An_Prec!$W:$W,Q$2) -> 0 | R17: =J17-O17 -> 5 | S17: =L17-Q17 -> 12000.58
A18: =+B18&C18 -> Véhicules neufs | B18: =+$K$1 -> Véhicules neufs
A19: =+B19&C19 -> Véhicules neufsRachat bail | B19: =+$K$1 -> Véhicules neufs | C19: Rachat bail | D19: =+INDEX('[5]Budget original'!$A$2:$AO$496,MATCH($A19,'[5]Budget original'!$A$2:$A$496,0),MATCH(D$2,'[5]Budget original'!$A$2:$AO$2,0)) -> 0 | E19: =IF(D19=0,0,F19/D19) -> 0 | F19: =+INDEX('[5]Budget original'!$A$2:$AO$496,MATCH($A19,'[5]Budget original'!$A$2:$A$496,0),MATCH(F$2,'[5]Budget original'!$A$2:$AO$2,0)) -> 5000 | G19: =+INDEX('[5]Budget révisé'!$A$2:$AO$496,MATCH($A19,'[5]Budget révisé'!$A$2:$A$496,0),MATCH(G$2,'[5]Budget révisé'!$A$2:$AO$2,0)) -> 0 | H19: =IF(G19=0,0,I19/G19) -> 0 | I19: =+INDEX('[5]Budget révisé'!$A$2:$AO$496,MATCH($A19,'[5]Budget révisé'!$A$2:$A$496,0),MATCH(I$2,'[5]Budget révisé'!$A$2:$AO$2,0)) -> 5000 | L19: =-SUMIFS([5]BV_Data_An_Cour!$O:$O,[5]BV_Data_An_Cour!$U:$U,$B19,[5]BV_Data_An_Cour!$V:$V,$C19,[5]BV_Data_An_Cour!$W:$W,L$2) -> 10386.97 | N19: =L19-I19 -> 5386.97 | Q19: =-SUMIFS([5]BV_Data_An_Prec!$O:$O,[5]BV_Data_An_Prec!$U:$U,$B19,[5]BV_Data_An_Prec!$V:$V,$C19,[5]BV_Data_An_Prec!$W:$W,Q$2) -> 6189.54 | R19: =O19-K19 -> 0 | S19: =L19-Q19 -> 4197.43 | U19: Budget | V19: =G13+G15+G17 -> 73.257793 | W19: =I13+I15+I17 -> 95964.336 | X19: =W19/V19 -> 1309.954
A20: =+B20&C20 -> Véhicules neufs | B20: =+$K$1 -> Véhicules neufs | U20: 2021 | V20: =J13+J15+J17 -> 73 | W20: =L13+L15+L17 -> 115394.28 | X20: =W20/V20 -> 1580.7436
A21: =+B21&C21 -> Véhicules neufsRev. Finances | B21: =+$K$1 -> Véhicules neufs | C21: Rev. Finances | D21: =+INDEX('[5]Budget original'!$A$2:$AO$496,MATCH($A21,'[5]Budget original'!$A$2:$A$496,0),MATCH(D$2,'[5]Budget original'!$A$2:$AO$2,0)) -> 0 | E21: =IF(D21=0,0,F21/D21) -> 0 | F21: =+INDEX('[5]Budget original'!$A$2:$AO$496,MATCH($A21,'[5]Budget original'!$A$2:$A$496,0),MATCH(F$2,'[5]Budget original'!$A$2:$AO$2,0)) -> 6661.7025 | G21: =+INDEX('[5]Budget révisé'!$A$2:$AO$496,MATCH($A21,'[5]Budget révisé'!$A$2:$A$496,0),MATCH(G$2,'[5]Budget révisé'!$A$2:$AO$2,0)) -> 0 | H21: =IF(G21=0,0,I21/G21) -> 0 | I21: =+INDEX('[5]Budget révisé'!$A$2:$AO$496,MATCH($A21,'[5]Budget révisé'!$A$2:$A$496,0),MATCH(I$2,'[5]Budget révisé'!$A$2:$AO$2,0)) -> 6661.7025 | K21: =IF(J13=0,0,L21/(J13+J15)) -> 93.977941 | L21: =-SUMIFS([5]BV_Data_An_Cour!$O:$O,[5]BV_Data_An_Cour!$U:$U,$B21,[5]BV_Data_An_Cour!$V:$V,$C21,[5]BV_Data_An_Cour!$W:$W,L$2) -> 6390.5 | N21: =L21-I21 -> -271.20252 | P21: =IF(O13=0,0,Q21/(O13+O15)) -> 136.6225 | Q21: =-SUMIFS([5]BV_Data_An_Prec!$O:$O,[5]BV_Data_An_Prec!$U:$U,$B21,[5]BV_Data_An_Prec!$V:$V,$C21,[5]BV_Data_An_Prec!$W:$W,Q$2) -> 11476.29 | R21: =O21-K21 -> -93.977941 | S21: =L21-Q21 -> -5085.79
A22: =+B22&C22 -> Véhicules neufsRev. Protections | B22: =+$K$1 -> Véhicules neufs | C22: Rev. Protections | D22: =+INDEX('[5]Budget original'!$A$2:$AO$496,MATCH($A22,'[5]Budget original'!$A$2:$A$496,0),MATCH(D$2,'[5]Budget original'!$A$2:$AO$2,0)) -> 0 | E22: =IF(D22=0,0,F22/D22) -> 0 | F22: =+INDEX('[5]Budget original'!$A$2:$AO$496,MATCH($A22,'[5]Budget original'!$A$2:$A$496,0),MATCH(F$2,'[5]Budget original'!$A$2:$AO$2,0)) -> 52209.157 | G22: =+INDEX('[5]Budget révisé'!$A$2:$AO$496,MATCH($A22,'[5]Budget révisé'!$A$2:$A$496,0),MATCH(G$2,'[5]Budget révisé'!$A$2:$AO$2,0)) -> 0 | H22: =IF(G22=0,0,I22/G22) -> 0 | I22: =+INDEX('[5]Budget révisé'!$A$2:$AO$496,MATCH($A22,'[5]Budget révisé'!$A$2:$A$496,0),MATCH(I$2,'[5]Budget révisé'!$A$2:$AO$2,0)) -> 52209.157 | K22: =IF(J13=0,0,L22/(J13+J15)) -> 763.56294 | L22: =-SUMIFS([5]BV_Data_An_Cour!$O:$O,[5]BV_Data_An_Cour!$U:$U,$B22,[5]BV_Data_An_Cour!$V:$V,$C22,[5]BV_Data_An_Cour!$W:$W,L$2) -> 51922.28 | N22: =L22-I22 -> -286.87694 | P22: =IF(O13=0,0,Q22/(O13+O15)) -> 607.75679 | Q22: =-SUMIFS([5]BV_Data_An_Prec!$O:$O,[5]BV_Data_An_Prec!$U:$U,$B22,[5]BV_Data_An_Prec!$V:$V,$C22,[5]BV_Data_An_Prec!$W:$W,Q$2) -> 51051.57 | R22: =O22-K22 -> -763.56294 | S22: =L22-Q22 -> 870.71
A23: =+B23&C23 -> Véhicules neufsRev. Autres | B23: =+$K$1 -> Véhicules neufs | C23: Rev. Autres | D23: =+INDEX('[5]Budget original'!$A$2:$AO$496,MATCH($A23,'[5]Budget original'!$A$2:$A$496,0),MATCH(D$2,'[5]Budget original'!$A$2:$AO$2,0)) -> 0 | E23: =IF(D23=0,0,F23/D23) -> 0 | F23: =+INDEX('[5]Budget original'!$A$2:$AO$496,MATCH($A23,'[5]Budget original'!$A$2:$A$496,0),MATCH(F$2,'[5]Budget original'!$A$2:$AO$2,0)) -> 1316.8482 | G23: =+INDEX('[5]Budget révisé'!$A$2:$AO$496,MATCH($A23,'[5]Budget révisé'!$A$2:$A$496,0),MATCH(G$2,'[5]Budget révisé'!$A$2:$AO$2,0)) -> 0 | H23: =IF(G23=0,0,I23/G23) -> 0 | I23: =+INDEX('[5]Budget révisé'!$A$2:$AO$496,MATCH($A23,'[5]Budget révisé'!$A$2:$A$496,0),MATCH(I$2,'[5]Budget révisé'!$A$2:$AO$2,0)) -> 1316.8482 | K23: =IF(J13=0,0,L23/(J13+J15)) -> 14.451618 | L23: =-SUMIFS([5]BV_Data_An_Cour!$O:$O,[5]BV_Data_An_Cour!$U:$U,$B23,[5]BV_Data_An_Cour!$V:$V,$C23,[5]BV_Data_An_Cour!$W:$W,L$2) -> 982.71 | N23: =L23-I23 -> -334.13817 | P23: =IF(O13=0,0,Q23/(O13+O15)) -> 9.5772619 | Q23: =-SUMIFS([5]BV_Data_An_Prec!$O:$O,[5]BV_Data_An_Prec!$U:$U,$B23,[5]BV_Data_An_Prec!$V:$V,$C23,[5]BV_Data_An_Prec!$W:$W,Q$2) -> 804.49 | R23: =O23-K23 -> -14.451618 | S23: =L23-Q23 -> 178.22
A24: =+B24&C24 -> Véhicules neufsTotal F&I | B24: =+$K$1 -> Véhicules neufs | C24: Total F&I | D24: =+D15+D13 -> 70.809068 | E24: =IF(D24<=0,0,F24/D24) -> 850 | F24: =F21+F22+F23 -> 60187.708 | G24: =+G15+G13 -> 70.809068 | H24: =IF(G24<=0,0,I24/G24) -> 850 | I24: =I21+I22+I23 -> 60187.708 | J24: =+J15+J13 -> 68 | K24: =IF(J24<=0,0,L24/J24) -> 871.9925 | L24: =L21+L22+L23 -> 59295.49 | M24: =J24-G24 -> -2.8090678 | N24: =L24-I24 -> -892.21763 | O24: =+O15+O13 -> 84 | P24: =IF(O24<=0,0,Q24/O24) -> 753.95655 | Q24: =Q21+Q22+Q23 -> 63332.35 | S24: =L24-Q24 -> -4036.86
A25: =+B25&C25 -> Véhicules neufs | B25: =+$K$1 -> Véhicules neufs | N25: =IF(N24=0,0,N24/I24) -> -0.014823918 | S25: =IF(Q24=0,0,(S24/Q24)) -> -0.063740884
A26: =+B26&C26 -> Véhicules neufs | B26: =+$K$1 -> Véhicules neufs
A27: =+B27&C27 -> Véhicules neufsTotal Dépt. Neufs | B27: =+$K$1 -> Véhicules neufs | C27: Total Dépt. Neufs | D27: =+D13+D15+D17 -> 70.809068 | E27: =IF(D27<=0,0,F27/D27) -> 1874.8216 | F27: =F13+F17+F24+F19+F15 -> 132754.37 | G27: =+G13+G15+G17 -> 73.257793 | H27: =IF(G27<=0,0,I27/G27) -> 2199.7939 | I27: =I13+I17+I24+I19+I15 -> 161152.04 | J27: =+J13+J15+J17 -> 73 | K27: =IF(J27<=0,0,L27/J27) -> 2535.2978 | L27: =L13+L17+L24+L19+L15 -> 185076.74 | M27: =J27-G27 -> -0.25779317 | N27: =L27-I27 -> 23924.696 | O27: =+O13+O15+O17 -> 84 | P27: =IF(O27<=0,0,Q27/O27) -> 1554.1774 | Q27: =Q13+Q17+Q24+Q19+Q15 -> 130550.9 | R27: =J27-O27 -> -11 | S27: =L27-Q27 -> 54525.84
A28: =+B28&C28 -> Véhicules neufs | B28: =+$K$1 -> Véhicules neufs | M28: =M27/G27 -> -0.0035189862 | N28: =N27/I27 -> 0.1484604 | R28: =R27/O27 -> -0.13095238 | S28: =IF(Q27=0,0,S27/Q27) -> 0.41765963
A29: =+B29&C29 -> Véhicules neufs | B29: =+$K$1 -> Véhicules neufs
A30: =+B30&C30 -> Véhicules neufsDEPENSES | B30: =+$K$1 -> Véhicules neufs | C30: DEPENSES
A31: =+B31&C31 -> Véhicules neufsComm. vendeurs | B31: =+$K$1 -> Véhicules neufs | C31: Comm. vendeurs | E31: =F31/D$24 -> 372.59495 | F31: =+INDEX('[5]Budget original'!$A$2:$AO$496,MATCH($A31,'[5]Budget original'!$A$2:$A$496,0),MATCH(F$2,'[5]Budget original'!$A$2:$AO$2,0)) -> 26383.101 | G31: =I31/(I15+I13) -> 0.28622244 | H31: =I31/G$24 -> 379.98583 | I31: =+INDEX('[5]Budget révisé'!$A$2:$AO$496,MATCH($A31,'[5]Budget révisé'!$A$2:$A$496,0),MATCH(I$2,'[5]Budget révisé'!$A$2:$AO$2,0)) -> 26906.443 | J31: =L31/(L15+L13) -> 0.40075885 | K31: =IF(L31=0,0,L31/J$24) -> 609.35206 | L31: =SUMIFS([5]BV_Data_An_Cour!$O:$O,[5]BV_Data_An_Cour!$U:$U,$B31,[5]BV_Data_An_Cour!$V:$V,$C31,[5]BV_Data_An_Cour!$W:$W,L$2) -> 41435.94 | N31: =L31-I31 -> 14529.497 | P31: =IF(Q31=0,0,Q31/O$24) -> 356.51679 | Q31: =SUMIFS([5]BV_Data_An_Prec!$O:$O,[5]BV_Data_An_Prec!$U:$U,$B31,[5]BV_Data_An_Prec!$V:$V,$C31,[5]BV_Data_An_Prec!$W:$W,Q$2) -> 29947.41 | S31: =L31-Q31 -> 11488.53
A32: =+B32&C32 -> Véhicules neufsComm. F&I | B32: =+$K$1 -> Véhicules neufs | C32: Comm. F&I | E32: =F32/D$24 -> 255 | F32: =+INDEX('[5]Budget original'!$A$2:$AO$496,MATCH($A32,'[5]Budget original'!$A$2:$A$496,0),MATCH(F$2,'[5]Budget original'!$A$2:$AO$2,0)) -> 18056.312 | G32: =I32/I24 -> 0.3 | H32: =I32/G$24 -> 255 | I32: =+INDEX('[5]Budget révisé'!$A$2:$AO$496,MATCH($A32,'[5]Budget révisé'!$A$2:$A$496,0),MATCH(I$2,'[5]Budget révisé'!$A$2:$AO$2,0)) -> 18056.312 | J32: =L32/L24 -> 0.31930793 | K32: =IF(L32=0,0,L32/J$24) -> 278.43412 | L32: =SUMIFS([5]BV_Data_An_Cour!$O:$O,[5]BV_Data_An_Cour!$U:$U,$B32,[5]BV_Data_An_Cour!$V:$V,$C32,[5]BV_Data_An_Cour!$W:$W,L$2) -> 18933.52 | N32: =L32-I32 -> 877.20771 | P32: =IF(Q32=0,0,Q32/O$24) -> 201.43083 | Q32: =SUMIFS([5]BV_Data_An_Prec!$O:$O,[5]BV_Data_An_Prec!$U:$U,$B32,[5]BV_Data_An_Prec!$V:$V,$C32,[5]BV_Data_An_Prec!$W:$W,Q$2) -> 16920.19 | S32: =L32-Q32 -> 2013.33
A33: =+B33&C33 -> Véhicules neufsFrais de livraison | B33: =+$K$1 -> Véhicules neufs | C33: Frais de livraison | E33: =F33/D$24 -> 197 | F33: =+INDEX('[5]Budget original'!$A$2:$AO$496,MATCH($A33,'[5]Budget original'!$A$2:$A$496,0),MATCH(F$2,'[5]Budget original'!$A$2:$AO$2,0)) -> 13949.386 | H33: =I33/G$24 -> 197 | I33: =+INDEX('[5]Budget révisé'!$A$2:$AO$496,MATCH($A33,'[5]Budget révisé'!$A$2:$A$496,0),MATCH(I$2,'[5]Budget révisé'!$A$2:$AO$2,0)) -> 13949.386 | K33: =IF(L33=0,0,L33/J$24) -> 186.22485 | L33: =SUMIFS([5]BV_Data_An_Cour!$O:$O,[5]BV_Data_An_Cour!$U:$U,$B33,[5]BV_Data_An_Cour!$V:$V,$C33,[5]BV_Data_An_Cour!$W:$W,L$2) -> 12663.29 | N33: =L33-I33 -> -1286.0964 | P33: =IF(Q33=0,0,Q33/O$24) -> 160.20167 | Q33: =SUMIFS([5]BV_Data_An_Prec!$O:$O,[5]BV_Data_An_Prec!$U:$U,$B33,[5]BV_Data_An_Prec!$V:$V,$C33,[5]BV_Data_An_Prec!$W:$W,Q$2) -> 13456.94 | S33: =L33-Q33 -> -793.65 | W33: =L24*0.3 -> 17788.647
A34: =+B34&C34 -> Véhicules neufsService gratuit 1 | B34: =+$K$1 -> Véhicules neufs | C34: Service gratuit 1 | E34: =F34/D$24 -> 6 | F34: =+INDEX('[5]Budget original'!$A$2:$AO$496,MATCH($A34,'[5]Budget original'!$A$2:$A$496,0),MATCH(F$2,'[5]Budget original'!$A$2:$AO$2,0)) -> 424.85441 | H34: =I34/G$24 -> 6 | I34: =+INDEX('[5]Budget révisé'!$A$2:$AO$496,MATCH($A34,'[5]Budget révisé'!$A$2:$A$496,0),MATCH(I$2,'[5]Budget révisé'!$A$2:$AO$2,0)) -> 424.85441 | K34: =IF(L34=0,0,L34/J$24) -> 10.717647 | L34: =SUMIFS([5]BV_Data_An_Cour!$O:$O,[5]BV_Data_An_Cour!$U:$U,$B34,[5]BV_Data_An_Cour!$V:$V,$C34,[5]BV_Data_An_Cour!$W:$W,L$2) -> 728.8 | N34: =L34-I34 -> 303.94559 | P34: =IF(Q34=0,0,Q34/O$24) -> 0 | Q34: =SUMIFS([5]BV_Data_An_Prec!$O:$O,[5]BV_Data_An_Prec!$U:$U,$B34,[5]BV_Data_An_Prec!$V:$V,$C34,[5]BV_Data_An_Prec!$W:$W,Q$2) -> 0 | S34: =L34-Q34 -> 728.8
A35: =+B35&C35 -> Véhicules neufsEntretien stock | B35: =+$K$1 -> Véhicules neufs | C35: Entretien stock | E35: =F35/D$24 -> 34 | F35: =+INDEX('[5]Budget original'!$A$2:$AO$496,MATCH($A35,'[5]Budget original'!$A$2:$A$496,0),MATCH(F$2,'[5]Budget original'!$A$2:$AO$2,0)) -> 2407.5083 | H35: =I35/G$24 -> 34 | I35: =+INDEX('[5]Budget révisé'!$A$2:$AO$496,MATCH($A35,'[5]Budget révisé'!$A$2:$A$496,0),MATCH(I$2,'[5]Budget révisé'!$A$2:$AO$2,0)) -> 2407.5083 | K35: =IF(L35=0,0,L35/J$24) -> 13.796029 | L35: =SUMIFS([5]BV_Data_An_Cour!$O:$O,[5]BV_Data_An_Cour!$U:$U,$B35,[5]BV_Data_An_Cour!$V:$V,$C35,[5]BV_Data_An_Cour!$W:$W,L$2) -> 938.13 | N35: =L35-I35 -> -1469.3783 | P35: =IF(Q35=0,0,Q35/O$24) -> 14.53869 | Q35: =SUMIFS([5]BV_Data_An_Prec!$O:$O,[5]BV_Data_An_Prec!$U:$U,$B35,[5]BV_Data_An_Prec!$V:$V,$C35,[5]BV_Data_An_Prec!$W:$W,Q$2) -> 1221.25 | S35: =L35-Q35 -> -283.12 | W35: =L32-W33 -> 1144.873
A36: =+B36&C36 -> Véhicules neufsPublicité 1 | B36: =+$K$1 -> Véhicules neufs | C36: Publicité 1 | E36: =F36/D$24 -> 180.66964 | F36: =+INDEX('[5]Budget original'!$A$2:$AO$496,MATCH($A36,'[5]Budget original'!$A$2:$A$496,0),MATCH(F$2,'[5]Budget original'!$A$2:$AO$2,0)) -> 12793.049 | H36: =I36/G$24 -> 180.66964 | I36: =+INDEX('[5]Budget révisé'!$A$2:$AO$496,MATCH($A36,'[5]Budget révisé'!$A$2:$A$496,0),MATCH(I$2,'[5]Budget révisé'!$A$2:$AO$2,0)) -> 12793.049 | K36: =IF(L36=0,0,L36/J$24) -> 179.49603 | L36: =SUMIFS([5]BV_Data_An_Cour!$O:$O,[5]BV_Data_An_Cour!$U:$U,$B36,[5]BV_Data_An_Cour!$V:$V,$C36,[5]BV_Data_An_Cour!$W:$W,L$2) -> 12205.73 | N36: =L36-I36 -> -587.31899 | P36: =IF(Q36=0,0,Q36/O$24) -> 76.071429 | Q36: =SUMIFS([5]BV_Data_An_Prec!$O:$O,[5]BV_Data_An_Prec!$U:$U,$B36,[5]BV_Data_An_Prec!$V:$V,$C36,[5]BV_Data_An_Prec!$W:$W,Q$2) -> 6390 | S36: =L36-Q36 -> 5815.73
A37: =+B37&C37 -> Véhicules neufsIntérêt de gros | B37: =+$K$1 -> Véhicules neufs | C37: Intérêt de gros | E37: =F37/D$24 -> 217.69014 | F37: =+INDEX('[5]Budget original'!$A$2:$AO$496,MATCH($A37,'[5]Budget original'!$A$2:$A$496,0),MATCH(F$2,'[5]Budget original'!$A$2:$AO$2,0)) -> 15414.436 | H37: =I37/G$24 -> 219.79355 | I37: =+INDEX('[5]Budget révisé'!$A$2:$AO$496,MATCH($A37,'[5]Budget révisé'!$A$2:$A$496,0),MATCH(I$2,'[5]Budget révisé'!$A$2:$AO$2,0)) -> 15563.376 | K37: =IF(L37=0,0,L37/J$24) -> 226.95059 | L37: =SUMIFS([5]BV_Data_An_Cour!$O:$O,[5]BV_Data_An_Cour!$U:$U,$B37,[5]BV_Data_An_Cour!$V:$V,$C37,[5]BV_Data_An_Cour!$W:$W,L$2) -> 15432.64 | N37: =L37-I37 -> -130.73608 | P37: =IF(Q37=0,0,Q37/O$24) -> 235.93357 | Q37: =SUMIFS([5]BV_Data_An_Prec!$O:$O,[5]BV_Data_An_Prec!$U:$U,$B37,[5]BV_Data_An_Prec!$V:$V,$C37,[5]BV_Data_An_Prec!$W:$W,Q$2) -> 19818.42 | S37: =L37-Q37 -> -4385.78
A38: =+B38&C38 -> Véhicules neufs[...] | B38: =+$K$1 -> Véhicules neufs | C38: [...] | E38: =F38/D$24 -> 0 | F38: =+INDEX('[5]Budget original'!$A$2:$AO$496,MATCH($A38,'[5]Budget original'!$A$2:$A$496,0),MATCH(F$2,'[5]Budget original'!$A$2:$AO$2,0)) -> 0 | H38: =I38/G$24 -> 0 | I38: =+INDEX('[5]Budget révisé'!$A$2:$AO$496,MATCH($A38,'[5]Budget révisé'!$A$2:$A$496,0),MATCH(I$2,'[5]Budget révisé'!$A$2:$AO$2,0)) -> 0 | K38: =IF(L38=0,0,L38/J$24) -> 0 | L38: =SUMIFS([5]BV_Data_An_Cour!$O:$O,[5]BV_Data_An_Cour!$U:$U,$B38,[5]BV_Data_An_Cour!$V:$V,$C38,[5]BV_Data_An_Cour!$W:$W,L$2) -> 0 | N38: =L38-I38 -> 0 | P38: =IF(Q38=0,0,Q38/O$24) -> 0 | Q38: =SUMIFS([5]BV_Data_An_Prec!$O:$O,[5]BV_Data_An_Prec!$U:$U,$B38,[5]BV_Data_An_Prec!$V:$V,$C38,[5]BV_Data_An_Prec!$W:$W,Q$2) -> 0 | S38: =L38-Q38 -> 0
A39: =+B39&C39 -> Véhicules neufs[...] | B39: =+$K$1 -> Véhicules neufs | C39: [...] | E39: =F39/D$24 -> 0 | F39: =+INDEX('[5]Budget original'!$A$2:$AO$496,MATCH($A39,'[5]Budget original'!$A$2:$A$496,0),MATCH(F$2,'[5]Budget original'!$A$2:$AO$2,0)) -> 0 | H39: =I39/G$24 -> 0 | I39: =+INDEX('[5]Budget révisé'!$A$2:$AO$496,MATCH($A39,'[5]Budget révisé'!$A$2:$A$496,0),MATCH(I$2,'[5]Budget révisé'!$A$2:$AO$2,0)) -> 0 | K39: =IF(L39=0,0,L39/J$24) -> 0 | L39: =SUMIFS([5]BV_Data_An_Cour!$O:$O,[5]BV_Data_An_Cour!$U:$U,$B39,[5]BV_Data_An_Cour!$V:$V,$C39,[5]BV_Data_An_Cour!$W:$W,L$2) -> 0 | N39: =L39-I39 -> 0 | P39: =IF(Q39=0,0,Q39/O$24) -> 0 | Q39: =SUMIFS([5]BV_Data_An_Prec!$O:$O,[5]BV_Data_An_Prec!$U:$U,$B39,[5]BV_Data_An_Prec!$V:$V,$C39,[5]BV_Data_An_Prec!$W:$W,Q$2) -> 0 | S39: =L39-Q39 -> 0
A40: =+B40&C40 -> Véhicules neufs[...] | B40: =+$K$1 -> Véhicules neufs | C40: [...] | E40: =F40/D$24 -> 0 | F40: =+INDEX('[5]Budget original'!$A$2:$AO$496,MATCH($A40,'[5]Budget original'!$A$2:$A$496,0),MATCH(F$2,'[5]Budget original'!$A$2:$AO$2,0)) -> 0 | H40: =I40/G$24 -> 0 | I40: =+INDEX('[5]Budget révisé'!$A$2:$AO$496,MATCH($A40,'[5]Budget révisé'!$A$2:$A$496,0),MATCH(I$2,'[5]Budget révisé'!$A$2:$AO$2,0)) -> 0 | K40: =IF(L40=0,0,L40/J$24) -> 0 | L40: =SUMIFS([5]BV_Data_An_Cour!$O:$O,[5]BV_Data_An_Cour!$U:$U,$B40,[5]BV_Data_An_Cour!$V:$V,$C40,[5]BV_Data_An_Cour!$W:$W,L$2) -> 0 | N40: =L40-I40 -> 0 | P40: =IF(Q40=0,0,Q40/O$24) -> 0 | Q40: =SUMIFS([5]BV_Data_An_Prec!$O:$O,[5]BV_Data_An_Prec!$U:$U,$B40,[5]BV_Data_An_Prec!$V:$V,$C40,[5]BV_Data_An_Prec!$W:$W,Q$2) -> 0 | S40: =L40-Q40 -> 0
...

Sheet VW 5
C1: =[6]Parametres!B1 -> Volks | K1: Véhicules neufs | S1: =CONCATENATE("Réalisé,"," ",[6]Parametres!B3," ",[6]Parametres!B4) -> Réalisé, Mai 2021
D2: X | E2: O | F2: U | G2: X | H2: O | I2: U | J2: NB | L2: $ | O2: NB | Q2: $
D3: BUDGET ORIGINAL | G3: BUDGET REVISE | J3: RÉALISATION | M3: ÉCART réel / révisé | O3: ANNÉE PRÉCÉDENTE | R3: ÉCART réel / original | V3: NEUF | W3: 0.45
D4: UNITE | E4: $P/UNITÉ | F4: $PROFITS | G4: UNITE | H4: $P/UNITÉ | I4: $PROFITS | J4: UNITE | K4: $P/UNITE | L4: $PROFITS | M4: UNITÉ | N4: $PROFITS | O4: UNITE | P4: $P/UNITE | Q4: $PROFITS | R4: UNITE | S4: $PROFITS | V4: USAGE | W4: 0.1
A5: =+B5&C5 -> Véhicules neufsVentes nettes | B5: =+$K$1 -> Véhicules neufs | C5: Ventes nettes | F5: =+INDEX('[6]Budget original'!$A$2:$AO$496,MATCH($A5,'[6]Budget original'!$A$2:$A$496,0),MATCH(F$2,'[6]Budget original'!$A$2:$AO$2,0)) -> 981796.55 | I5: =+INDEX('[6]Budget révisé'!$A$2:$AO$496,MATCH($A5,'[6]Budget révisé'!$A$2:$A$496,0),MATCH(I$2,'[6]Budget révisé'!$A$2:$AO$2,0)) -> 981796.55 | L5: =-SUMIFS([6]BV_Data_An_Cour!$O:$O,[6]BV_Data_An_Cour!$X:$X,"Oui",[6]BV_Data_An_Cour!$U:$U,$B5) -> 3760930 | Q5: =-SUMIFS([6]BV_Data_An_Prec!$O:$O,[6]BV_Data_An_Prec!$X:$X,"Oui",[6]BV_Data_An_Prec!$U:$U,$B5) -> 3162199.2 | V5: SERVICE | W5: 0.225
A6: =+B6&C6 -> Véhicules neufsAutos détail | B6: =+$K$1 -> Véhicules neufs | C6: Autos détail | D6: =+INDEX('[6]Budget original'!$A$2:$AO$496,MATCH($A6,'[6]Budget original'!$A$2:$A$496,0),MATCH(D$2,'[6]Budget original'!$A$2:$AO$2,0)) -> 35.76021 | E6: =IF(D6=0,0,F6/D6) -> 604.29043 | F6: =+INDEX('[6]Budget original'!$A$2:$AO$496,MATCH($A6,'[6]Budget original'!$A$2:$A$496,0),MATCH(F$2,'[6]Budget original'!$A$2:$AO$2,0)) -> 21609.552 | G6: =+INDEX('[6]Budget révisé'!$A$2:$AO$496,MATCH($A6,'[6]Budget révisé'!$A$2:$A$496,0),MATCH(G$2,'[6]Budget révisé'!$A$2:$AO$2,0)) -> 35.76021 | H6: =IF(G6=0,0,I6/G6) -> 955.05622 | I6: =+INDEX('[6]Budget révisé'!$A$2:$AO$496,MATCH($A6,'[6]Budget révisé'!$A$2:$A$496,0),MATCH(I$2,'[6]Budget révisé'!$A$2:$AO$2,0)) -> 34153.01 | J6: =-SUMIFS([6]BV_Data_An_Cour!$O:$O,[6]BV_Data_An_Cour!$U:$U,$B6,[6]BV_Data_An_Cour!$V:$V,$C6,[6]BV_Data_An_Cour!$W:$W,J$2) -> 25 | K6: =IF(J6=0,0,L6/J6) -> 1020.836 | L6: =-SUMIFS([6]BV_Data_An_Cour!$O:$O,[6]BV_Data_An_Cour!$U:$U,$B6,[6]BV_Data_An_Cour!$V:$V,$C6,[6]BV_Data_An_Cour!$W:$W,L$2) -> 25520.9 | M6: =J6-G6 -> -10.76021 | N6: =L6-I6 -> -8632.1105 | O6: =-SUMIFS([6]BV_Data_An_Prec!$O:$O,[6]BV_Data_An_Prec!$U:$U,$B6,[6]BV_Data_An_Prec!$V:$V,$C6,[6]BV_Data_An_Prec!$W:$W,O$2) -> 54 | P6: =IF(O6=0,0,Q6/O6) -> 571.8013 | Q6: =-SUMIFS([6]BV_Data_An_Prec!$O:$O,[6]BV_Data_An_Prec!$U:$U,$B6,[6]BV_Data_An_Prec!$V:$V,$C6,[6]BV_Data_An_Prec!$W:$W,Q$2) -> 30877.27 | R6: =J6-O6 -> -29 | S6: =L6-Q6 -> -5356.37 | V6: CARROSSERIE | W6: 0.025
A7: =+B7&C7 -> Véhicules neufsCamions détail | B7: =+$K$1 -> Véhicules neufs | C7: Camions détail | D7: =+INDEX('[6]Budget original'!$A$2:$AO$496,MATCH($A7,'[6]Budget original'!$A$2:$A$496,0),MATCH(D$2,'[6]Budget original'!$A$2:$AO$2,0)) -> 48.034341 | E7: =IF(D7=0,0,F7/D7) -> 1315.4791 | F7: =+INDEX('[6]Budget original'!$A$2:$AO$496,MATCH($A7,'[6]Budget original'!$A$2:$A$496,0),MATCH(F$2,'[6]Budget original'!$A$2:$AO$2,0)) -> 63188.172 | G7: =+INDEX('[6]Budget révisé'!$A$2:$AO$496,MATCH($A7,'[6]Budget révisé'!$A$2:$A$496,0),MATCH(G$2,'[6]Budget révisé'!$A$2:$AO$2,0)) -> 48.034341 | H7: =IF(G7=0,0,I7/G7) -> 1702.6669 | I7: =+INDEX('[6]Budget révisé'!$A$2:$AO$496,MATCH($A7,'[6]Budget révisé'!$A$2:$A$496,0),MATCH(I$2,'[6]Budget révisé'!$A$2:$AO$2,0)) -> 81786.481 | J7: =-SUMIFS([6]BV_Data_An_Cour!$O:$O,[6]BV_Data_An_Cour!$U:$U,$B7,[6]BV_Data_An_Cour!$V:$V,$C7,[6]BV_Data_An_Cour!$W:$W,J$2) -> 58 | K7: =IF(J7=0,0,L7/J7) -> 2126.4852 | L7: =-SUMIFS([6]BV_Data_An_Cour!$O:$O,[6]BV_Data_An_Cour!$U:$U,$B7,[6]BV_Data_An_Cour!$V:$V,$C7,[6]BV_Data_An_Cour!$W:$W,L$2) -> 123336.14 | M7: =J7-G7 -> 9.9656591 | N7: =L7-I7 -> 41549.659 | O7: =-SUMIFS([6]BV_Data_An_Prec!$O:$O,[6]BV_Data_An_Prec!$U:$U,$B7,[6]BV_Data_An_Prec!$V:$V,$C7,[6]BV_Data_An_Prec!$W:$W,O$2) -> 23 | P7: =IF(O7=0,0,Q7/O7) -> 995.91391 | Q7: =-SUMIFS([6]BV_Data_An_Prec!$O:$O,[6]BV_Data_An_Prec!$U:$U,$B7,[6]BV_Data_An_Prec!$V:$V,$C7,[6]BV_Data_An_Prec!$W:$W,Q$2) -> 22906.02 | R7: =J7-O7 -> 35 | S7: =L7-Q7 -> 100430.12 | V7: PIECES | W7: 0.2
A8: =+B8&C8 -> Véhicules neufsSprinter | B8: =+$K$1 -> Véhicules neufs | C8: Sprinter | D8: =+INDEX('[6]Budget original'!$A$2:$AO$496,MATCH($A8,'[6]Budget original'!$A$2:$A$496,0),MATCH(D$2,'[6]Budget original'!$A$2:$AO$2,0)) -> 0 | E8: =IF(D8=0,0,F8/D8) -> 0 | F8: =+INDEX('[6]Budget original'!$A$2:$AO$496,MATCH($A8,'[6]Budget original'!$A$2:$A$496,0),MATCH(F$2,'[6]Budget original'!$A$2:$AO$2,0)) -> 0 | G8: =+INDEX('[6]Budget révisé'!$A$2:$AO$496,MATCH($A8,'[6]Budget révisé'!$A$2:$A$496,0),MATCH(G$2,'[6]Budget révisé'!$A$2:$AO$2,0)) -> 0 | H8: =IF(G8=0,0,I8/G8) -> 0 | I8: =+INDEX('[6]Budget révisé'!$A$2:$AO$496,MATCH($A8,'[6]Budget révisé'!$A$2:$A$496,0),MATCH(I$2,'[6]Budget révisé'!$A$2:$AO$2,0)) -> 0 | J8: =-SUMIFS([6]BV_Data_An_Cour!$O:$O,[6]BV_Data_An_Cour!$U:$U,$B8,[6]BV_Data_An_Cour!$V:$V,$C8,[6]BV_Data_An_Cour!$W:$W,J$2) -> 0 | K8: =IF(J8=0,0,L8/J8) -> 0 | L8: =-SUMIFS([6]BV_Data_An_Cour!$O:$O,[6]BV_Data_An_Cour!$U:$U,$B8,[6]BV_Data_An_Cour!$V:$V,$C8,[6]BV_Data_An_Cour!$W:$W,L$2) -> 0 | M8: =J8-G8 -> 0 | N8: =L8-I8 -> 0 | O8: =-SUMIFS([6]BV_Data_An_Prec!$O:$O,[6]BV_Data_An_Prec!$U:$U,$B8,[6]BV_Data_An_Prec!$V:$V,$C8,[6]BV_Data_An_Prec!$W:$W,O$2) -> 0 | P8: =IF(O8=0,0,Q8/O8) -> 0 | Q8: =-SUMIFS([6]BV_Data_An_Prec!$O:$O,[6]BV_Data_An_Prec!$U:$U,$B8,[6]BV_Data_An_Prec!$V:$V,$C8,[6]BV_Data_An_Prec!$W:$W,Q$2) -> 0 | R8: =J8-O8 -> 0 | S8: =L8-Q8 -> 0 | W8: =SUM(W3:W7) -> 1
A9: =+B9&C9 -> Véhicules neufsMoto détail | B9: =+$K$1 -> Véhicules neufs | C9: Moto détail | D9: =+INDEX('[6]Budget original'!$A$2:$AO$496,MATCH($A9,'[6]Budget original'!$A$2:$A$496,0),MATCH(D$2,'[6]Budget original'!$A$2:$AO$2,0)) -> 0 | E9: =IF(D9=0,0,F9/D9) -> 0 | F9: =+INDEX('[6]Budget original'!$A$2:$AO$496,MATCH($A9,'[6]Budget original'!$A$2:$A$496,0),MATCH(F$2,'[6]Budget original'!$A$2:$AO$2,0)) -> 0 | G9: =+INDEX('[6]Budget révisé'!$A$2:$AO$496,MATCH($A9,'[6]Budget révisé'!$A$2:$A$496,0),MATCH(G$2,'[6]Budget révisé'!$A$2:$AO$2,0)) -> 0 | H9: =IF(G9=0,0,I9/G9) -> 0 | I9: =+INDEX('[6]Budget révisé'!$A$2:$AO$496,MATCH($A9,'[6]Budget révisé'!$A$2:$A$496,0),MATCH(I$2,'[6]Budget révisé'!$A$2:$AO$2,0)) -> 0 | J9: =-SUMIFS([6]BV_Data_An_Cour!$O:$O,[6]BV_Data_An_Cour!$U:$U,$B9,[6]BV_Data_An_Cour!$V:$V,$C9,[6]BV_Data_An_Cour!$W:$W,J$2) -> 0 | K9: =IF(J9=0,0,L9/J9) -> 0 | L9: =-SUMIFS([6]BV_Data_An_Cour!$O:$O,[6]BV_Data_An_Cour!$U:$U,$B9,[6]BV_Data_An_Cour!$V:$V,$C9,[6]BV_Data_An_Cour!$W:$W,L$2) -> 0 | M9: =J9-G9 -> 0 | N9: =L9-I9 -> 0 | O9: =-SUMIFS([6]BV_Data_An_Prec!$O:$O,[6]BV_Data_An_Prec!$U:$U,$B9,[6]BV_Data_An_Prec!$V:$V,$C9,[6]BV_Data_An_Prec!$W:$W,O$2) -> 0 | P9: =IF(O9=0,0,Q9/O9) -> 0 | Q9: =-SUMIFS([6]BV_Data_An_Prec!$O:$O,[6]BV_Data_An_Prec!$U:$U,$B9,[6]BV_Data_An_Prec!$V:$V,$C9,[6]BV_Data_An_Prec!$W:$W,Q$2) -> 0 | R9: =J9-O9 -> 0 | S9: =L9-Q9 -> 0
A10: =+B10&C10 -> Véhicules neufs[...] | B10: =+$K$1 -> Véhicules neufs | C10: [...] | D10: =+INDEX('[6]Budget original'!$A$2:$AO$496,MATCH($A10,'[6]Budget original'!$A$2:$A$496,0),MATCH(D$2,'[6]Budget original'!$A$2:$AO$2,0)) -> 0 | E10: =IF(D10=0,0,F10/D10) -> 0 | F10: =+INDEX('[6]Budget original'!$A$2:$AO$496,MATCH($A10,'[6]Budget original'!$A$2:$A$496,0),MATCH(F$2,'[6]Budget original'!$A$2:$AO$2,0)) -> 0 | G10: =+INDEX('[6]Budget révisé'!$A$2:$AO$496,MATCH($A10,'[6]Budget révisé'!$A$2:$A$496,0),MATCH(G$2,'[6]Budget révisé'!$A$2:$AO$2,0)) -> 0 | H10: =IF(G10=0,0,I10/G10) -> 0 | I10: =+INDEX('[6]Budget révisé'!$A$2:$AO$496,MATCH($A10,'[6]Budget révisé'!$A$2:$A$496,0),MATCH(I$2,'[6]Budget révisé'!$A$2:$AO$2,0)) -> 0 | J10: =-SUMIFS([6]BV_Data_An_Cour!$O:$O,[6]BV_Data_An_Cour!$U:$U,$B10,[6]BV_Data_An_Cour!$V:$V,$C10,[6]BV_Data_An_Cour!$W:$W,J$2) -> 0 | K10: =IF(J10=0,0,L10/J10) -> 0 | L10: =-SUMIFS([6]BV_Data_An_Cour!$O:$O,[6]BV_Data_An_Cour!$U:$U,$B10,[6]BV_Data_An_Cour!$V:$V,$C10,[6]BV_Data_An_Cour!$W:$W,L$2) -> 0 | M10: =J10-G10 -> 0 | N10: =L10-I10 -> 0 | O10: =-SUMIFS([6]BV_Data_An_Prec!$O:$O,[6]BV_Data_An_Prec!$U:$U,$B10,[6]BV_Data_An_Prec!$V:$V,$C10,[6]BV_Data_An_Prec!$W:$W,O$2) -> 0 | P10: =IF(O10=0,0,Q10/O10) -> 0 | Q10: =-SUMIFS([6]BV_Data_An_Prec!$O:$O,[6]BV_Data_An_Prec!$U:$U,$B10,[6]BV_Data_An_Prec!$V:$V,$C10,[6]BV_Data_An_Prec!$W:$W,Q$2) -> 0 | R10: =J10-O10 -> 0 | S10: =L10-Q10 -> 0
