Workbook
Name _Dates_Conc: [1]Dealers!$BF$37:$KA$63
Name _scen: '[1]Scen & Sens'!$E$26
Name _scen1: '[1]Scen & Sens'!$E$27
Name _scen2: '[1]Scen & Sens'!$E$28
Name _SCenarios: '[1]Scen & Sens'!$J$26:$O$26
Name _Sens1: '[1]Scen & Sens'!$F$9
Name _Sens2: '[1]Scen & Sens'!$F$10
Name _sensRes1: '[1]Scen & Sens'!$E$15
Name _sensRes2: '[1]Scen & Sens'!$E$16
Name _sensRes3: '[1]Scen & Sens'!$E$17
Name _sensRes4: '[1]Scen & Sens'!$E$18
Name _sensRes5: '[1]Scen & Sens'!$E$19
Name _sensRes6: '[1]Scen & Sens'!$E$20
Name _sensRes7: '[1]Scen & Sens'!$E$21
Name DateRange: [1]Volkswagen!$BF$6:$DY$6
Name Monetary_Unit: [1]Parameters!$B$15
Name Months: [1]Parameters!$E$9:$E$20
Name Rng_Dealers_Names: [1]!Tbl_Dealers[Dealer Name]
Name Rng_Dlr_Dates: [1]!Tbl_V_Dlr_Dates[Date]
Name Titre: [1]Front!$A$9

Sheet Parametres
A1: Compagnie | B1: Volks
G2: 1-Mémo | M2: Mois | N2: YTD
A3: Mois Courant | B3: Mars | C3: =+VLOOKUP(B3,$K$3:$L$14,2,0) -> 3 | G3: 10-Compte compteur | K3: Janvier | L3: 1 | M3: =+IF($K3=$B$3,"X","") | N3: =+IF(K3=B3,"X",IF(L3<=$C$3,"X","")) -> X
A4: Année | B4: 2021 | K4: Février | L4: 2 | M4: =+IF($K4=$B$3,"X","") | N4: =+IF(K4=B4,"X",IF(L4<=$C$3,"X","")) -> X
K5: Mars | L5: 3 | M5: =+IF($K5=$B$3,"X","") -> X | N5: =+IF(K5=B5,"X",IF(L5<=$C$3,"X","")) -> X
K6: Avril | L6: 4 | M6: =+IF($K6=$B$3,"X","") | N6: =+IF(K6=B6,"X",IF(L6<=$C$3,"X",""))
K7: Mai | L7: 5 | M7: =+IF($K7=$B$3,"X","") | N7: =+IF(K7=B7,"X",IF(L7<=$C$3,"X",""))
K8: Juin | L8: 6 | M8: =+IF($K8=$B$3,"X","") | N8: =+IF(K8=B8,"X",IF(L8<=$C$3,"X",""))
A9: Sélectionner le mois en B3 | K9: Juillet | L9: 7 | M9: =+IF($K9=$B$3,"X","") | N9: =+IF(K9=B9,"X",IF(L9<=$C$3,"X",""))
A10: Coller les balances de vérification respectives en cellule A1 dans les onglets BV_Data_An_Cour et BV_Data_An_Prec | K10: Août | L10: 8 | M10: =+IF($K10=$B$3,"X","") | N10: =+IF(K10=B10,"X",IF(L10<=$C$3,"X",""))
A11: Vérifier s'il y a des #N/A dans les colonnes T à X des onlgets de BV | K11: Septembre | L11: 9 | M11: =+IF($K11=$B$3,"X","") | N11: =+IF(K11=B11,"X",IF(L11<=$C$3,"X",""))
A12: Vérifier les chiffres avec l'état financier et les réalisés an passé pour les résultat net mois et aad | K12: Octobre | L12: 10 | M12: =+IF($K12=$B$3,"X","") | N12: =+IF(K12=B12,"X",IF(L12<=$C$3,"X",""))
K13: Novembre | L13: 11 | M13: =+IF($K13=$B$3,"X","") | N13: =+IF(K13=B13,"X",IF(L13<=$C$3,"X",""))
K14: Décembre | L14: 12 | M14: =+IF($K14=$B$3,"X","") | N14: =+IF(K14=B14,"X",IF(L14<=$C$3,"X",""))

Sheet Bilan
A1: BILAN
A2: =+Parametres!B1 -> Volks
A3: =CONCATENATE("",,Parametres!B3," ",Parametres!B4) -> Mars 2021
A5: Encaisse | B5: =SUMIFS(BV_Data_An_Cour!$P:$P,BV_Data_An_Cour!$U:$U,$A$1,BV_Data_An_Cour!$V:$V,$A5) -> 2208856.3 | D5: Marge de crédit | E5: =-SUMIFS(BV_Data_An_Cour!$P:$P,BV_Data_An_Cour!$U:$U,$A$1,BV_Data_An_Cour!$V:$V,$D5) -> 0
A6: Total Trésorerie et équivalent de Trésorerie | B6: =SUM(B5) -> 2208856.3
D7: Portion Court Terme de la Dette Long Terme | E7: =-SUMIFS(BV_Data_An_Cour!$P:$P,BV_Data_An_Cour!$U:$U,$A$1,BV_Data_An_Cour!$V:$V,$D7) -> 15810
A8: Recevables Contrats en Transit | B8: =SUMIFS(BV_Data_An_Cour!$P:$P,BV_Data_An_Cour!$U:$U,$A$1,BV_Data_An_Cour!$V:$V,$A8) -> 2230376.1
A9: Recevables Véhicules | B9: =SUMIFS(BV_Data_An_Cour!$P:$P,BV_Data_An_Cour!$U:$U,$A$1,BV_Data_An_Cour!$V:$V,$A9) -> 216729.42 | D9: Avances à payer | E9: =-SUMIFS(BV_Data_An_Cour!$P:$P,BV_Data_An_Cour!$U:$U,$A$1,BV_Data_An_Cour!$V:$V,$D9) -> 0
A10: Recevables Manufacturier | B10: =SUMIFS(BV_Data_An_Cour!$P:$P,BV_Data_An_Cour!$U:$U,$A$1,BV_Data_An_Cour!$V:$V,$A10) -> 262318.72 | D10: Comptes à Payer Fournisseurs | E10: =-SUMIFS(BV_Data_An_Cour!$P:$P,BV_Data_An_Cour!$U:$U,$A$1,BV_Data_An_Cour!$V:$V,$D10) -> 75113.78
A11: Recevables Pièces et Service | B11: =SUMIFS(BV_Data_An_Cour!$P:$P,BV_Data_An_Cour!$U:$U,$A$1,BV_Data_An_Cour!$V:$V,$A11) -> 11720.5 | D11: Taxes de Vente à Payer | E11: =-SUMIFS(BV_Data_An_Cour!$P:$P,BV_Data_An_Cour!$U:$U,$A$1,BV_Data_An_Cour!$V:$V,$D11) -> 79114.99
A12: Recevables Garantie Manufacturier | B12: =SUMIFS(BV_Data_An_Cour!$P:$P,BV_Data_An_Cour!$U:$U,$A$1,BV_Data_An_Cour!$V:$V,$A12) -> 41335.66 | D12: Impôts à payer | E12: =-SUMIFS(BV_Data_An_Cour!$P:$P,BV_Data_An_Cour!$U:$U,$A$1,BV_Data_An_Cour!$V:$V,$D12) -> 0
A13: Recevables Carrosserie | B13: =SUMIFS(BV_Data_An_Cour!$P:$P,BV_Data_An_Cour!$U:$U,$A$1,BV_Data_An_Cour!$V:$V,$A13) -> 49488.46 | D13: Dépôts de Client | E13: =-SUMIFS(BV_Data_An_Cour!$P:$P,BV_Data_An_Cour!$U:$U,$A$1,BV_Data_An_Cour!$V:$V,$D13) -> 5450
A14: Recevables Intercos | B14: =SUMIFS(BV_Data_An_Cour!$P:$P,BV_Data_An_Cour!$U:$U,$A$1,BV_Data_An_Cour!$V:$V,$A14) -> 0 | D14: Payables Intercos | E14: =-SUMIFS(BV_Data_An_Cour!$P:$P,BV_Data_An_Cour!$U:$U,$A$1,BV_Data_An_Cour!$V:$V,$D14) -> 0
A15: Recevables Autres | B15: =SUMIFS(BV_Data_An_Cour!$P:$P,BV_Data_An_Cour!$U:$U,$A$1,BV_Data_An_Cour!$V:$V,$A15) -> 128036.83 | D15: Autres Comptes à Payer | E15: =-SUMIFS(BV_Data_An_Cour!$P:$P,BV_Data_An_Cour!$U:$U,$A$1,BV_Data_An_Cour!$V:$V,$D15) -> 759599.57
A16: Total Comptes à Recevoir | B16: =+SUM(B8:B15) -> 2940005.7 | D16: Total Comptes à Payer | E16: =+SUM(E10:E15) -> 919278.34
A18: Inventaire Véhicules Neufs | B18: =SUMIFS(BV_Data_An_Cour!$P:$P,BV_Data_An_Cour!$U:$U,$A$1,BV_Data_An_Cour!$V:$V,$A18) -> 5406498.6 | D18: Effet à Payer Véhicules Neufs | E18: =-SUMIFS(BV_Data_An_Cour!$P:$P,BV_Data_An_Cour!$U:$U,$A$1,BV_Data_An_Cour!$V:$V,$D18) -> 7036543.5
A19: Inventaire Véhicules Usagés | B19: =SUMIFS(BV_Data_An_Cour!$P:$P,BV_Data_An_Cour!$U:$U,$A$1,BV_Data_An_Cour!$V:$V,$A19) -> 1545206.7 | D19: Effet à Payer Véhicules Usagés | E19: =-SUMIFS(BV_Data_An_Cour!$P:$P,BV_Data_An_Cour!$U:$U,$A$1,BV_Data_An_Cour!$V:$V,$D19) -> 286517.08
A20: Inventaire Pièces, Pneus, Huile | B20: =SUMIFS(BV_Data_An_Cour!$P:$P,BV_Data_An_Cour!$U:$U,$A$1,BV_Data_An_Cour!$V:$V,$A20) -> 383225.37 | D20: Total Effets à Payer | E20: =+SUM(E18:E19) -> 7323060.6
A21: Total Inventaires | B21: =SUM(B18:B20) -> 7334930.7
D22: Salaires à Payer | E22: =-SUMIFS(BV_Data_An_Cour!$P:$P,BV_Data_An_Cour!$U:$U,$A$1,BV_Data_An_Cour!$V:$V,$D22) -> 389840.6
A23: Avances à recevoir | B23: =SUMIFS(BV_Data_An_Cour!$P:$P,BV_Data_An_Cour!$U:$U,$A$1,BV_Data_An_Cour!$V:$V,$A23) -> 0 | D23: DAS à Payer | E23: =-SUMIFS(BV_Data_An_Cour!$P:$P,BV_Data_An_Cour!$U:$U,$A$1,BV_Data_An_Cour!$V:$V,$D23) -> 23855.95
A24: Travaux en Cours | B24: =SUMIFS(BV_Data_An_Cour!$P:$P,BV_Data_An_Cour!$U:$U,$A$1,BV_Data_An_Cour!$V:$V,$A24) -> 9187.7 | D24: Autres Courus | E24: =-SUMIFS(BV_Data_An_Cour!$P:$P,BV_Data_An_Cour!$U:$U,$A$1,BV_Data_An_Cour!$V:$V,$D24) -> 40040.82
A25: Sous-Traitance | B25: =SUMIFS(BV_Data_An_Cour!$P:$P,BV_Data_An_Cour!$U:$U,$A$1,BV_Data_An_Cour!$V:$V,$A25) -> -3164.81 | D25: [...] | E25: =-SUMIFS(BV_Data_An_Cour!$P:$P,BV_Data_An_Cour!$U:$U,$A$1,BV_Data_An_Cour!$V:$V,$D25) -> 0
A26: Frais Payés d'Avance | B26: =SUMIFS(BV_Data_An_Cour!$P:$P,BV_Data_An_Cour!$U:$U,$A$1,BV_Data_An_Cour!$V:$V,$A26) -> 133193.71 | D26: [...] | E26: =-SUMIFS(BV_Data_An_Cour!$P:$P,BV_Data_An_Cour!$U:$U,$A$1,BV_Data_An_Cour!$V:$V,$D26) -> 0
A27: [...] | B27: =SUMIFS(BV_Data_An_Cour!$P:$P,BV_Data_An_Cour!$U:$U,$A$1,BV_Data_An_Cour!$V:$V,$A27) -> 0 | D27: [...] | E27: =-SUMIFS(BV_Data_An_Cour!$P:$P,BV_Data_An_Cour!$U:$U,$A$1,BV_Data_An_Cour!$V:$V,$D27) -> 0
A28: [...] | B28: =SUMIFS(BV_Data_An_Cour!$P:$P,BV_Data_An_Cour!$U:$U,$A$1,BV_Data_An_Cour!$V:$V,$A28) -> 0 | D28: Total Frais Courus | E28: =SUM(E22:E24) -> 453737.37
A29: [...] | B29: =SUMIFS(BV_Data_An_Cour!$P:$P,BV_Data_An_Cour!$U:$U,$A$1,BV_Data_An_Cour!$V:$V,$A29) -> 0
A30: Total Autres | B30: =SUM(B23:B29) -> 139216.6 | D30: Total Passif Court Terme | E30: =+E5+E7+E16+E20+E28 -> 8711886.3
A32: Total Actif Court Terme | B32: =+B6+B16+B21+B30 -> 12623009
D33: Impôts Futurs à payer | E33: =-SUMIFS(BV_Data_An_Cour!$P:$P,BV_Data_An_Cour!$U:$U,$A$1,BV_Data_An_Cour!$V:$V,$D33) -> 0
A35: Terrain | B35: =SUMIFS(BV_Data_An_Cour!$P:$P,BV_Data_An_Cour!$U:$U,$A$1,BV_Data_An_Cour!$V:$V,$A35) -> 0 | D35: Avances Long Terme à Payer | E35: =-SUMIFS(BV_Data_An_Cour!$P:$P,BV_Data_An_Cour!$U:$U,$A$1,BV_Data_An_Cour!$V:$V,$D35) -> 0
A36: Bâtisse | B36: =SUMIFS(BV_Data_An_Cour!$P:$P,BV_Data_An_Cour!$U:$U,$A$1,BV_Data_An_Cour!$V:$V,$A36) -> 0 | D36: Hypothèque à Payer | E36: =-SUMIFS(BV_Data_An_Cour!$P:$P,BV_Data_An_Cour!$U:$U,$A$1,BV_Data_An_Cour!$V:$V,$D36) -> 0
A37: Améliorations Locatives | B37: =SUMIFS(BV_Data_An_Cour!$P:$P,BV_Data_An_Cour!$U:$U,$A$1,BV_Data_An_Cour!$V:$V,$A37) -> -2490.69 | D37: Dette à Long Terme | E37: =-SUMIFS(BV_Data_An_Cour!$P:$P,BV_Data_An_Cour!$U:$U,$A$1,BV_Data_An_Cour!$V:$V,$D37) -> 24206.25
A38: Améliorations Locatives Permanentes | B38: =SUMIFS(BV_Data_An_Cour!$P:$P,BV_Data_An_Cour!$U:$U,$A$1,BV_Data_An_Cour!$V:$V,$A38) -> 0 | D38: Autres Dettes à Long Terme | E38: =-SUMIFS(BV_Data_An_Cour!$P:$P,BV_Data_An_Cour!$U:$U,$A$1,BV_Data_An_Cour!$V:$V,$D38) -> 0
A39: Équipements Service | B39: =SUMIFS(BV_Data_An_Cour!$P:$P,BV_Data_An_Cour!$U:$U,$A$1,BV_Data_An_Cour!$V:$V,$A39) -> 176871.8 | D39: [...] | E39: =-SUMIFS(BV_Data_An_Cour!$P:$P,BV_Data_An_Cour!$U:$U,$A$1,BV_Data_An_Cour!$V:$V,$D39) -> 0
A40: Mobilier | B40: =SUMIFS(BV_Data_An_Cour!$P:$P,BV_Data_An_Cour!$U:$U,$A$1,BV_Data_An_Cour!$V:$V,$A40) -> 33213.95 | D40: [...] | E40: =-SUMIFS(BV_Data_An_Cour!$P:$P,BV_Data_An_Cour!$U:$U,$A$1,BV_Data_An_Cour!$V:$V,$D40) -> 0
A41: Équipements Informatique | B41: =SUMIFS(BV_Data_An_Cour!$P:$P,BV_Data_An_Cour!$U:$U,$A$1,BV_Data_An_Cour!$V:$V,$A41) -> 21605.62 | D41: [...] | E41: =-SUMIFS(BV_Data_An_Cour!$P:$P,BV_Data_An_Cour!$U:$U,$A$1,BV_Data_An_Cour!$V:$V,$D41) -> 0
A42: Équipements Téléphonique | B42: =SUMIFS(BV_Data_An_Cour!$P:$P,BV_Data_An_Cour!$U:$U,$A$1,BV_Data_An_Cour!$V:$V,$A42) -> 60 | D42: Total Passif long terme | E42: =+SUM(E33:E38) -> 24206.25
A43: Enseigne | B43: =SUMIFS(BV_Data_An_Cour!$P:$P,BV_Data_An_Cour!$U:$U,$A$1,BV_Data_An_Cour!$V:$V,$A43) -> -554.99
A44: Total Immobilisations Nettes | B44: =SUM(B35:B43) -> 228705.69
...

Sheet Budget original
B1: ="Budget 2021 Mensuel"&" "&Parametres!$B$1 -> Budget 2021 Mensuel Volks
B2: Mois | F2: =+IF(Parametres!$B$3=F$6,"X","") | G2: =+IF(Parametres!$B$3=F$6,"O","") | H2: =+IF(Parametres!$B$3=F$6,"U","") | I2: =+IF(Parametres!$B$3=I$6,"X","") | J2: =+IF(Parametres!$B$3=I$6,"O","") | K2: =+IF(Parametres!$B$3=I$6,"U","") | L2: =+IF(Parametres!$B$3=L$6,"X","") -> X | M2: =+IF(Parametres!$B$3=L$6,"O","") -> O | N2: =+IF(Parametres!$B$3=L$6,"U","") -> U | O2: =+IF(Parametres!$B$3=O$6,"X","") | P2: =+IF(Parametres!$B$3=O$6,"O","") | Q2: =+IF(Parametres!$B$3=O$6,"U","") | R2: =+IF(Parametres!$B$3=R$6,"X","") | S2: =+IF(Parametres!$B$3=R$6,"O","") | T2: =+IF(Parametres!$B$3=R$6,"U","") | U2: =+IF(Parametres!$B$3=U$6,"X","") | V2: =+IF(Parametres!$B$3=U$6,"O","") | W2: =+IF(Parametres!$B$3=U$6,"U","") | X2: =+IF(Parametres!$B$3=X$6,"X","") | Y2: =+IF(Parametres!$B$3=X$6,"O","") | Z2: =+IF(Parametres!$B$3=X$6,"U","") | AA2: =+IF(Parametres!$B$3=AA$6,"X","") | AB2: =+IF(Parametres!$B$3=AA$6,"O","") | AC2: =+IF(Parametres!$B$3=AA$6,"U","") | AD2: =+IF(Parametres!$B$3=AD$6,"X","") | AE2: =+IF(Parametres!$B$3=AD$6,"O","") | AF2: =+IF(Parametres!$B$3=AD$6,"U","") | AG2: =+IF(Parametres!$B$3=AG$6,"X","") | AH2: =+IF(Parametres!$B$3=AG$6,"O","") | AI2: =+IF(Parametres!$B$3=AG$6,"U","") | AJ2: =+IF(Parametres!$B$3=AJ$6,"X","") | AK2: =+IF(Parametres!$B$3=AJ$6,"O","") | AL2: =+IF(Parametres!$B$3=AJ$6,"U","") | AM2: =+IF(Parametres!$B$3=AM$6,"X","") | AN2: =+IF(Parametres!$B$3=AM$6,"O","") | AO2: =+IF(Parametres!$B$3=AM$6,"U","")
B3: YTD | F3: =+IF(VLOOKUP(F$6,Parametres!$K$3:$N$14,4,0)="X","X","") -> X | G3: =+IF(VLOOKUP(F$6,Parametres!$K$3:$N$14,4,0)="X","O","") -> O | H3: =+IF(VLOOKUP(F$6,Parametres!$K$3:$N$14,4,0)="X","U","") -> U | I3: =+IF(VLOOKUP(I$6,Parametres!$K$3:$N$14,4,0)="X","X","") -> X | J3: =+IF(VLOOKUP(I$6,Parametres!$K$3:$N$14,4,0)="X","O","") -> O | K3: =+IF(VLOOKUP(I$6,Parametres!$K$3:$N$14,4,0)="X","U","") -> U | L3: =+IF(VLOOKUP(L$6,Parametres!$K$3:$N$14,4,0)="X","X","") -> X | M3: =+IF(VLOOKUP(L$6,Parametres!$K$3:$N$14,4,0)="X","O","") -> O | N3: =+IF(VLOOKUP(L$6,Parametres!$K$3:$N$14,4,0)="X","U","") -> U | O3: =+IF(VLOOKUP(O$6,Parametres!$K$3:$N$14,4,0)="X","X","") | P3: =+IF(VLOOKUP(O$6,Parametres!$K$3:$N$14,4,0)="X","O","") | Q3: =+IF(VLOOKUP(O$6,Parametres!$K$3:$N$14,4,0)="X","U","") | R3: =+IF(VLOOKUP(R$6,Parametres!$K$3:$N$14,4,0)="X","X","") | S3: =+IF(VLOOKUP(R$6,Parametres!$K$3:$N$14,4,0)="X","O","") | T3: =+IF(VLOOKUP(R$6,Parametres!$K$3:$N$14,4,0)="X","U","") | U3: =+IF(VLOOKUP(U$6,Parametres!$K$3:$N$14,4,0)="X","X","") | V3: =+IF(VLOOKUP(U$6,Parametres!$K$3:$N$14,4,0)="X","O","") | W3: =+IF(VLOOKUP(U$6,Parametres!$K$3:$N$14,4,0)="X","U","") | X3: =+IF(VLOOKUP(X$6,Parametres!$K$3:$N$14,4,0)="X","X","") | Y3: =+IF(VLOOKUP(X$6,Parametres!$K$3:$N$14,4,0)="X","O","") | Z3: =+IF(VLOOKUP(X$6,Parametres!$K$3:$N$14,4,0)="X","U","") | AA3: =+IF(VLOOKUP(AA$6,Parametres!$K$3:$N$14,4,0)="X","X","") | AB3: =+IF(VLOOKUP(AA$6,Parametres!$K$3:$N$14,4,0)="X","O","") | AC3: =+IF(VLOOKUP(AA$6,Parametres!$K$3:$N$14,4,0)="X","U","") | AD3: =+IF(VLOOKUP(AD$6,Parametres!$K$3:$N$14,4,0)="X","X","") | AE3: =+IF(VLOOKUP(AD$6,Parametres!$K$3:$N$14,4,0)="X","O","") | AF3: =+IF(VLOOKUP(AD$6,Parametres!$K$3:$N$14,4,0)="X","U","") | AG3: =+IF(VLOOKUP(AG$6,Parametres!$K$3:$N$14,4,0)="X","X","") | AH3: =+IF(VLOOKUP(AG$6,Parametres!$K$3:$N$14,4,0)="X","O","") | AI3: =+IF(VLOOKUP(AG$6,Parametres!$K$3:$N$14,4,0)="X","U","") | AJ3: =+IF(VLOOKUP(AJ$6,Parametres!$K$3:$N$14,4,0)="X","X","") | AK3: =+IF(VLOOKUP(AJ$6,Parametres!$K$3:$N$14,4,0)="X","O","") | AL3: =+IF(VLOOKUP(AJ$6,Parametres!$K$3:$N$14,4,0)="X","U","") | AM3: =+IF(VLOOKUP(AM$6,Parametres!$K$3:$N$14,4,0)="X","X","") | AN3: =+IF(VLOOKUP(AM$6,Parametres!$K$3:$N$14,4,0)="X","O","") | AO3: =+IF(VLOOKUP(AM$6,Parametres!$K$3:$N$14,4,0)="X","U","")
B4: Budget 2021 | C4: Véhicules neufs
B6: Mois | C6: TOTAL | F6: Janvier | I6: Février | L6: Mars | O6: Avril | R6: Mai | U6: Juin | X6: Juillet | AA6: Août | AD6: Septembre | AG6: Octobre | AJ6: Novembre | AM6: Décembre
C7: UNITE | D7: $P/UNITE | E7: $PROFITS | F7: UNITE | G7: $P/UNITE | H7: $PROFITS | I7: UNITE | J7: $P/UNITE | K7: $PROFITS | L7: UNITE | M7: $P/UNITE | N7: $PROFITS | O7: UNITE | P7: $P/UNITE | Q7: $PROFITS | R7: UNITE | S7: $P/UNITE | T7: $PROFITS | U7: UNITE | V7: $P/UNITE | W7: $PROFITS | X7: UNITE | Y7: $P/UNITE | Z7: $PROFITS | AA7: UNITE | AB7: $P/UNITE | AC7: $PROFITS | AD7: UNITE | AE7: $P/UNITE | AF7: $PROFITS | AG7: UNITE | AH7: $P/UNITE | AI7: $PROFITS | AJ7: UNITE | AK7: $P/UNITE | AL7: $PROFITS | AM7: UNITE | AN7: $P/UNITE | AO7: $PROFITS
A8: =+$C$4&B8 -> Véhicules neufsVentes nettes | B8: Ventes nettes | E8: =+SUM(H8,K8,N8,Q8,T8,W8,Z8,AC8,AF8,AI8,AL8,AO8) -> 9553310.1 | H8: 1882577.9 | K8: 446219.11 | N8: 678330.08 | Q8: 751340.66 | T8: 981796.55 | W8: 691716.4 | Z8: 688676.89 | AC8: 729220.97 | AF8: 799077.54 | AI8: 991144.07 | AL8: 576007.02 | AO8: 337202.89
A9: =+$C$4&B9 -> Véhicules neufsAutos détail | B9: Autos détail | C9: =+SUM(F9,I9,L9,O9,R9,U9,X9,AA9,AD9,AG9,AJ9,AM9) -> 303 | D9: =IF(C9=0,0,E9/C9) -> 604.29043 | E9: =+SUM(H9,K9,N9,Q9,T9,W9,Z9,AC9,AF9,AI9,AL9,AO9) -> 183100 | F9: 23.607096 | G9: =IF(F9=0,0,H9/F9) -> 604.29043 | H9: 14265.542 | I9: 16.252745 | J9: =IF(I9=0,0,K9/I9) -> 604.29043 | K9: 9821.3783 | L9: 24.706978 | M9: =IF(L9=0,0,N9/L9) -> 604.29043 | N9: 14930.19 | O9: 27.36626 | P9: =IF(O9=0,0,Q9/O9) -> 604.29043 | Q9: 16537.169 | R9: 35.76021 | S9: =IF(R9=0,0,T9/R9) -> 604.29043 | T9: 21609.552 | U9: 25.194551 | V9: =IF(U9=0,0,W9/U9) -> 604.29043 | W9: 15224.826 | X9: 25.083842 | Y9: =IF(X9=0,0,Z9/X9) -> 604.29043 | Z9: 15157.926 | AA9: 26.560589 | AB9: =IF(AA9=0,0,AC9/AA9) -> 604.29043 | AC9: 16050.31 | AD9: 29.104991 | AE9: =IF(AD9=0,0,AF9/AD9) -> 604.29043 | AF9: 17587.868 | AG9: 36.100676 | AH9: =IF(AG9=0,0,AI9/AG9) -> 604.29043 | AI9: 21815.293 | AJ9: 20.980041 | AK9: =IF(AJ9=0,0,AL9/AJ9) -> 604.29043 | AL9: 12678.038 | AM9: 12.282021 | AN9: =IF(AM9=0,0,AO9/AM9) -> 604.29043 | AO9: 7421.9079
A10: =+$C$4&B10 -> Véhicules neufsCamions détail | B10: Camions détail | C10: =+SUM(F10,I10,L10,O10,R10,U10,X10,AA10,AD10,AG10,AJ10,AM10) -> 407 | D10: =IF(C10=0,0,E10/C10) -> 1315.4791 | E10: =+SUM(H10,K10,N10,Q10,T10,W10,Z10,AC10,AF10,AI10,AL10,AO10) -> 535400 | F10: 31.709861 | G10: =IF(F10=0,0,H10/F10) -> 1315.4791 | H10: 41713.66 | I10: 21.831245 | J10: =IF(I10=0,0,K10/I10) -> 1315.4791 | K10: 28718.547 | L10: 33.187261 | M10: =IF(L10=0,0,N10/L10) -> 1315.4791 | N10: 43657.149 | O10: 36.759299 | P10: =IF(O10=0,0,Q10/O10) -> 1315.4791 | Q10: 48356.09 | R10: 48.034341 | S10: =IF(R10=0,0,T10/R10) -> 1315.4791 | T10: 63188.172 | U10: 33.842186 | V10: =IF(U10=0,0,W10/U10) -> 1315.4791 | W10: 44518.688 | X10: 33.693478 | Y10: =IF(X10=0,0,Z10/X10) -> 1315.4791 | Z10: 44323.067 | AA10: 35.677095 | AB10: =IF(AA10=0,0,AC10/AA10) -> 1315.4791 | AC10: 46932.473 | AD10: 39.094824 | AE10: =IF(AD10=0,0,AF10/AD10) -> 1315.4791 | AF10: 51428.424 | AG10: 48.491668 | AH10: =IF(AG10=0,0,AI10/AG10) -> 1315.4791 | AI10: 63789.776 | AJ10: 28.181111 | AK10: =IF(AJ10=0,0,AL10/AJ10) -> 1315.4791 | AL10: 37071.663 | AM10: 16.497633 | AN10: =IF(AM10=0,0,AO10/AM10) -> 1315.4791 | AO10: 21702.291
A11: =+$C$4&B11 -> Véhicules neufsSprinter | B11: Sprinter | C11: =+SUM(F11,I11,L11,O11,R11,U11,X11,AA11,AD11,AG11,AJ11,AM11) -> 0 | D11: =IF(C11=0,0,E11/C11) -> 0 | E11: =+SUM(H11,K11,N11,Q11,T11,W11,Z11,AC11,AF11,AI11,AL11,AO11) -> 0 | G11: =IF(F11=0,0,H11/F11) -> 0 | J11: =IF(I11=0,0,K11/I11) -> 0 | M11: =IF(L11=0,0,N11/L11) -> 0 | P11: =IF(O11=0,0,Q11/O11) -> 0 | S11: =IF(R11=0,0,T11/R11) -> 0 | V11: =IF(U11=0,0,W11/U11) -> 0 | Y11: =IF(X11=0,0,Z11/X11) -> 0 | AB11: =IF(AA11=0,0,AC11/AA11) -> 0 | AE11: =IF(AD11=0,0,AF11/AD11) -> 0 | AH11: =IF(AG11=0,0,AI11/AG11) -> 0 | AK11: =IF(AJ11=0,0,AL11/AJ11) -> 0 | AN11: =IF(AM11=0,0,AO11/AM11) -> 0
A12: =+$C$4&B12 -> Véhicules neufsMoto détail | B12: Moto détail | C12: =+SUM(F12,I12,L12,O12,R12,U12,X12,AA12,AD12,AG12,AJ12,AM12) -> 0 | D12: =IF(C12=0,0,E12/C12) -> 0 | E12: =+SUM(H12,K12,N12,Q12,T12,W12,Z12,AC12,AF12,AI12,AL12,AO12) -> 0 | G12: =IF(F12=0,0,H12/F12) -> 0 | J12: =IF(I12=0,0,K12/I12) -> 0 | M12: =IF(L12=0,0,N12/L12) -> 0 | P12: =IF(O12=0,0,Q12/O12) -> 0 | S12: =IF(R12=0,0,T12/R12) -> 0 | V12: =IF(U12=0,0,W12/U12) -> 0 | Y12: =IF(X12=0,0,Z12/X12) -> 0 | AB12: =IF(AA12=0,0,AC12/AA12) -> 0 | AE12: =IF(AD12=0,0,AF12/AD12) -> 0 | AH12: =IF(AG12=0,0,AI12/AG12) -> 0 | AK12: =IF(AJ12=0,0,AL12/AJ12) -> 0 | AN12: =IF(AM12=0,0,AO12/AM12) -> 0
A13: =+$C$4&B13 -> Véhicules neufs[...] | B13: [...] | C13: =+SUM(F13,I13,L13,O13,R13,U13,X13,AA13,AD13,AG13,AJ13,AM13) -> 0 | D13: =IF(C13=0,0,E13/C13) -> 0 | E13: =+SUM(H13,K13,N13,Q13,T13,W13,Z13,AC13,AF13,AI13,AL13,AO13) -> 0 | G13: =IF(F13=0,0,H13/F13) -> 0 | J13: =IF(I13=0,0,K13/I13) -> 0 | M13: =IF(L13=0,0,N13/L13) -> 0 | P13: =IF(O13=0,0,Q13/O13) -> 0 | S13: =IF(R13=0,0,T13/R13) -> 0 | V13: =IF(U13=0,0,W13/U13) -> 0 | Y13: =IF(X13=0,0,Z13/X13) -> 0 | AB13: =IF(AA13=0,0,AC13/AA13) -> 0 | AE13: =IF(AD13=0,0,AF13/AD13) -> 0 | AH13: =IF(AG13=0,0,AI13/AG13) -> 0 | AK13: =IF(AJ13=0,0,AL13/AJ13) -> 0 | AN13: =IF(AM13=0,0,AO13/AM13) -> 0
A14: =+$C$4&B14 -> Véhicules neufs[...] | B14: [...] | C14: =+SUM(F14,I14,L14,O14,R14,U14,X14,AA14,AD14,AG14,AJ14,AM14) -> 0 | D14: =IF(C14=0,0,E14/C14) -> 0 | E14: =+SUM(H14,K14,N14,Q14,T14,W14,Z14,AC14,AF14,AI14,AL14,AO14) -> 0 | G14: =IF(F14=0,0,H14/F14) -> 0 | J14: =IF(I14=0,0,K14/I14) -> 0 | M14: =IF(L14=0,0,N14/L14) -> 0 | P14: =IF(O14=0,0,Q14/O14) -> 0 | S14: =IF(R14=0,0,T14/R14) -> 0 | V14: =IF(U14=0,0,W14/U14) -> 0 | Y14: =IF(X14=0,0,Z14/X14) -> 0 | AB14: =IF(AA14=0,0,AC14/AA14) -> 0 | AE14: =IF(AD14=0,0,AF14/AD14) -> 0 | AH14: =IF(AG14=0,0,AI14/AG14) -> 0 | AK14: =IF(AJ14=0,0,AL14/AJ14) -> 0 | AN14: =IF(AM14=0,0,AO14/AM14) -> 0
A15: =+$C$4&B15 -> Véhicules neufs[...] | B15: [...] | C15: =+SUM(F15,I15,L15,O15,R15,U15,X15,AA15,AD15,AG15,AJ15,AM15) -> 0 | D15: =IF(C15=0,0,E15/C15) -> 0 | E15: =+SUM(H15,K15,N15,Q15,T15,W15,Z15,AC15,AF15,AI15,AL15,AO15) -> 0 | G15: =IF(F15=0,0,H15/F15) -> 0 | J15: =IF(I15=0,0,K15/I15) -> 0 | M15: =IF(L15=0,0,N15/L15) -> 0 | P15: =IF(O15=0,0,Q15/O15) -> 0 | S15: =IF(R15=0,0,T15/R15) -> 0 | V15: =IF(U15=0,0,W15/U15) -> 0 | Y15: =IF(X15=0,0,Z15/X15) -> 0 | AB15: =IF(AA15=0,0,AC15/AA15) -> 0 | AE15: =IF(AD15=0,0,AF15/AD15) -> 0 | AH15: =IF(AG15=0,0,AI15/AG15) -> 0 | AK15: =IF(AJ15=0,0,AL15/AJ15) -> 0 | AN15: =IF(AM15=0,0,AO15/AM15) -> 0
A16: =+$C$4&B16 -> Véhicules neufsTotal Neufs | B16: Total Neufs | C16: =+SUM(C9:C15) -> 710 | D16: =IF(C16<=0,0,E16/C16) -> 1011.9718 | E16: =+SUM(E9:E15) -> 718500 | F16: =+SUM(F9:F15) -> 55.316957 | G16: =IF(F16<=0,0,H16/F16) -> 1011.9718 | H16: =+SUM(H9:H15) -> 55979.202 | I16: =+SUM(I9:I15) -> 38.08399 | J16: =IF(I16<=0,0,K16/I16) -> 1011.9718 | K16: =+SUM(K9:K15) -> 38539.925 | L16: =+SUM(L9:L15) -> 57.894239 | M16: =IF(L16<=0,0,N16/L16) -> 1011.9718 | N16: =+SUM(N9:N15) -> 58587.339 | O16: =+SUM(O9:O15) -> 64.125559 | P16: =IF(O16<=0,0,Q16/O16) -> 1011.9718 | Q16: =+SUM(Q9:Q15) -> 64893.259 | R16: =+SUM(R9:R15) -> 83.79455 | S16: =IF(R16<=0,0,T16/R16) -> 1011.9718 | T16: =+SUM(T9:T15) -> 84797.725 | U16: =+SUM(U9:U15) -> 59.036736 | V16: =IF(U16<=0,0,W16/U16) -> 1011.9718 | W16: =+SUM(W9:W15) -> 59743.514 | X16: =+SUM(X9:X15) -> 58.77732 | Y16: =IF(X16<=0,0,Z16/X16) -> 1011.9718 | Z16: =+SUM(Z9:Z15) -> 59480.992 | AA16: =+SUM(AA9:AA15) -> 62.237684 | AB16: =IF(AA16<=0,0,AC16/AA16) -> 1011.9718 | AC16: =+SUM(AC9:AC15) -> 62982.783 | AD16: =+SUM(AD9:AD15) -> 68.199815 | AE16: =IF(AD16<=0,0,AF16/AD16) -> 1011.9718 | AF16: =+SUM(AF9:AF15) -> 69016.292 | AG16: =+SUM(AG9:AG15) -> 84.592344 | AH16: =IF(AG16<=0,0,AI16/AG16) -> 1011.9718 | AI16: =+SUM(AI9:AI15) -> 85605.069 | AJ16: =+SUM(AJ9:AJ15) -> 49.161152 | AK16: =IF(AJ16<=0,0,AL16/AJ16) -> 1011.9718 | AL16: =+SUM(AL9:AL15) -> 49749.701 | AM16: =+SUM(AM9:AM15) -> 28.779654 | AN16: =IF(AM16<=0,0,AO16/AM16) -> 1011.9718 | AO16: =+SUM(AO9:AO15) -> 29124.199
A17: =+$C$4&B17 -> Véhicules neufs
A18: =+$C$4&B18 -> Véhicules neufsEx-Démos et courtoisies | B18: Ex-Démos et courtoisies | C18: =+SUM(F18,I18,L18,O18,R18,U18,X18,AA18,AD18,AG18,AJ18,AM18) -> 74 | D18: =IF(C18=0,0,E18/C18) -> 400 | E18: =+SUM(H18,K18,N18,Q18,T18,W18,Z18,AC18,AF18,AI18,AL18,AO18) -> 29600 | F18: 5.7654293 | G18: =IF(F18=0,0,H18/F18) -> 400 | H18: 2306.1717 | I18: 3.9693173 | J18: =IF(I18=0,0,K18/I18) -> 400 | K18: 1587.7269 | L18: 6.0340474 | M18: =IF(L18=0,0,N18/L18) -> 400 | N18: 2413.619 | O18: 6.683509 | P18: =IF(O18=0,0,Q18/O18) -> 400 | Q18: 2673.4036 | R18: 8.7335165 | S18: =IF(R18=0,0,T18/R18) -> 400 | T18: 3493.4066 | U18: 6.1531246 | V18: =IF(U18=0,0,W18/U18) -> 400 | W18: 2461.2499 | X18: 6.1260869 | Y18: =IF(X18=0,0,Z18/X18) -> 400 | Z18: 2450.4348 | AA18: 6.4867445 | AB18: =IF(AA18=0,0,AC18/AA18) -> 400 | AC18: 2594.6978 | AD18: 7.1081497 | AE18: =IF(AD18=0,0,AF18/AD18) -> 400 | AF18: 2843.2599 | AG18: 8.8166669 | AH18: =IF(AG18=0,0,AI18/AG18) -> 400 | AI18: 3526.6667 | AJ18: 5.1238383 | AK18: =IF(AJ18=0,0,AL18/AJ18) -> 400 | AL18: 2049.5353 | AM18: 2.9995696 | AN18: =IF(AM18=0,0,AO18/AM18) -> 400 | AO18: 1199.8278
A19: =+$C$4&B19 -> Véhicules neufs
A20: =+$C$4&B20 -> Véhicules neufsFlottes | B20: Flottes | C20: =+SUM(F20,I20,L20,O20,R20,U20,X20,AA20,AD20,AG20,AJ20,AM20) -> 0 | D20: =IF(C20=0,0,E20/C20) -> 0 | E20: =+SUM(H20,K20,N20,Q20,T20,W20,Z20,AC20,AF20,AI20,AL20,AO20) -> 0 | F20: 0 | G20: =IF(F20=0,0,H20/F20) -> 0 | H20: 0 | I20: 0 | J20: =IF(I20=0,0,K20/I20) -> 0 | K20: 0 | L20: 0 | M20: =IF(L20=0,0,N20/L20) -> 0 | N20: 0 | O20: 0 | P20: =IF(O20=0,0,Q20/O20) -> 0 | Q20: 0 | R20: 0 | S20: =IF(R20=0,0,T20/R20) -> 0 | T20: 0 | U20: 0 | V20: =IF(U20=0,0,W20/U20) -> 0 | W20: 0 | X20: 0 | Y20: =IF(X20=0,0,Z20/X20) -> 0 | Z20: 0 | AA20: 0 | AB20: =IF(AA20=0,0,AC20/AA20) -> 0 | AC20: 0 | AD20: 0 | AE20: =IF(AD20=0,0,AF20/AD20) -> 0 | AF20: 0 | AG20: 0 | AH20: =IF(AG20=0,0,AI20/AG20) -> 0 | AI20: 0 | AJ20: 0 | AK20: =IF(AJ20=0,0,AL20/AJ20) -> 0 | AL20: 0 | AM20: 0 | AN20: =IF(AM20=0,0,AO20/AM20) -> 0 | AO20: 0
A21: =+$C$4&B21 -> Véhicules neufs
A22: =+$C$4&B22 -> Véhicules neufsRachat bail | B22: Rachat bail | E22: =+SUM(H22,K22,N22,Q22,T22,W22,Z22,AC22,AF22,AI22,AL22,AO22) -> 60000 | H22: 5000 | K22: 5000 | N22: 5000 | Q22: 5000 | T22: 5000 | W22: 5000 | Z22: 5000 | AC22: 5000 | AF22: 5000 | AI22: 5000 | AL22: 5000 | AO22: 5000
A23: =+$C$4&B23 -> Véhicules neufs
A24: =+$C$4&B24 -> Véhicules neufsRev. Finances | B24: Rev. Finances | D24: =IF(C16=0,0,E24/(C16+C18)) -> 94.079794 | E24: =+SUM(H24,K24,N24,Q24,T24,W24,Z24,AC24,AF24,AI24,AL24,AO24) -> 73758.559 | G24: =IF(F16=0,0,H24/(F16+F18)) -> 94.079794 | H24: 5746.6183 | J24: =IF(I16=0,0,K24/(I16+I18)) -> 94.079794 | K24: 3956.3665 | M24: =IF(L16=0,0,N24/(L16+L18)) -> 94.079794 | N24: 6014.36 | P24: =IF(O16=0,0,Q24/(O16+O18)) -> 94.079794 | Q24: 6661.7025 | S24: =IF(R16=0,0,T24/(R16+R18)) -> 94.079794 | T24: 8705.0215 | V24: =IF(U16=0,0,W24/(U16+U18)) -> 94.079794 | W24: 6133.0487 | Y24: =IF(X16=0,0,Z24/(X16+X18)) -> 94.079794 | Z24: 6106.0992 | AB24: =IF(AA16=0,0,AC24/(AA16+AA18)) -> 94.079794 | AC24: 6465.5801 | AE24: =IF(AD16=0,0,AF24/(AD16+AD18)) -> 94.079794 | AF24: 7084.9578 | AH24: =IF(AG16=0,0,AI24/(AG16+AG18)) -> 94.079794 | AI24: 8787.9005 | AK24: =IF(AJ16=0,0,AL24/(AJ16+AJ18)) -> 94.079794 | AL24: 5107.1207 | AN24: =IF(AM16=0,0,AO24/(AM16+AM18)) -> 94.079794 | AO24: 2989.7828
A25: =+$C$4&B25 -> Véhicules neufsRev. Protections | B25: Rev. Protections | D25: =IF(C16=0,0,E25/(C16+C18)) -> 737.32304 | E25: =+SUM(H25,K25,N25,Q25,T25,W25,Z25,AC25,AF25,AI25,AL25,AO25) -> 578061.26 | G25: =IF(F16=0,0,H25/(F16+F18)) -> 737.32304 | H25: 45037.45 | J25: =IF(I16=0,0,K25/(I16+I18)) -> 737.32304 | K25: 31006.872 | M25: =IF(L16=0,0,N25/(L16+L18)) -> 737.32304 | N25: 47135.798 | P25: =IF(O16=0,0,Q25/(O16+O18)) -> 737.32304 | Q25: 52209.157 | S25: =IF(R16=0,0,T25/(R16+R18)) -> 737.32304 | T25: 68223.075 | V25: =IF(U16=0,0,W25/(U16+U18)) -> 737.32304 | W25: 48065.986 | Y25: =IF(X16=0,0,Z25/(X16+X18)) -> 737.32304 | Z25: 47854.777 | AB25: =IF(AA16=0,0,AC25/(AA16+AA18)) -> 737.32304 | AC25: 50672.104 | AE25: =IF(AD16=0,0,AF25/(AD16+AD18)) -> 737.32304 | AF25: 55526.297 | AH25: =IF(AG16=0,0,AI25/(AG16+AG18)) -> 737.32304 | AI25: 68872.616 | AK25: =IF(AJ16=0,0,AL25/(AJ16+AJ18)) -> 737.32304 | AL25: 40025.574 | AN25: =IF(AM16=0,0,AO25/(AM16+AM18)) -> 737.32304 | AO25: 23431.554
A26: =+$C$4&B26 -> Véhicules neufsRev. Autres | B26: Rev. Autres | D26: =IF(C16=0,0,E26/(C16+C18)) -> 18.597169 | E26: =+SUM(H26,K26,N26,Q26,T26,W26,Z26,AC26,AF26,AI26,AL26,AO26) -> 14580.18 | G26: =IF(F16=0,0,H26/(F16+F18)) -> 18.597169 | H26: 1135.9594 | J26: =IF(I16=0,0,K26/(I16+I18)) -> 18.597169 | K26: 782.07244 | M26: =IF(L16=0,0,N26/(L16+L18)) -> 18.597169 | N26: 1188.8851 | P26: =IF(O16=0,0,Q26/(O16+O18)) -> 18.597169 | Q26: 1316.8482 | S26: =IF(R16=0,0,T26/(R16+R18)) -> 18.597169 | T26: 1720.7601 | V26: =IF(U16=0,0,W26/(U16+U18)) -> 18.597169 | W26: 1212.3468 | Y26: =IF(X16=0,0,Z26/(X16+X18)) -> 18.597169 | Z26: 1207.0196 | AB26: =IF(AA16=0,0,AC26/(AA16+AA18)) -> 18.597169 | AC26: 1278.0798 | AE26: =IF(AD16=0,0,AF26/(AD16+AD18)) -> 18.597169 | AF26: 1400.5149 | AH26: =IF(AG16=0,0,AI26/(AG16+AG18)) -> 18.597169 | AI26: 1737.1431 | AK26: =IF(AJ16=0,0,AL26/(AJ16+AJ18)) -> 18.597169 | AL26: 1009.5471 | AN26: =IF(AM16=0,0,AO26/(AM16+AM18)) -> 18.597169 | AO26: 591.00358
A27: =+$C$4&B27 -> Véhicules neufsTotal F&I | B27: Total F&I | C27: =+C18+C16 -> 784 | D27: =IF(C27<=0,0,E27/C27) -> 850 | E27: =E24+E25+E26 -> 666400 | F27: =+F18+F16 -> 61.082386 | G27: =IF(F27<=0,0,H27/F27) -> 850 | H27: =H24+H25+H26 -> 51920.028 | I27: =+I18+I16 -> 42.053307 | J27: =IF(I27<=0,0,K27/I27) -> 850 | K27: =K24+K25+K26 -> 35745.311 | L27: =+L18+L16 -> 63.928286 | M27: =IF(L27<=0,0,N27/L27) -> 850 | N27: =N24+N25+N26 -> 54339.043 | O27: =+O18+O16 -> 70.809068 | P27: =IF(O27<=0,0,Q27/O27) -> 850 | Q27: =Q24+Q25+Q26 -> 60187.708 | R27: =+R18+R16 -> 92.528067 | S27: =IF(R27<=0,0,T27/R27) -> 850 | T27: =$T$24+$T$25+$T$26 -> 78648.857 | U27: =+U18+U16 -> 65.189861 | V27: =IF(U27<=0,0,W27/U27) -> 850 | W27: =W24+W25+W26 -> 55411.382 | X27: =+X18+X16 -> 64.903407 | Y27: =IF(X27<=0,0,Z27/X27) -> 850 | Z27: =Z24+Z25+Z26 -> 55167.896 | AA27: =+AA18+AA16 -> 68.724428 | AB27: =IF(AA27<=0,0,AC27/AA27) -> 850 | AC27: =AC24+AC25+AC26 -> 58415.764 | AD27: =+AD18+AD16 -> 75.307965 | AE27: =IF(AD27<=0,0,AF27/AD27) -> 850 | AF27: =AF24+AF25+AF26 -> 64011.77 | AG27: =+AG18+AG16 -> 93.409011 | AH27: =IF(AG27<=0,0,AI27/AG27) -> 850 | AI27: =AI24+AI25+AI26 -> 79397.659 | AJ27: =+AJ18+AJ16 -> 54.28499 | AK27: =IF(AJ27<=0,0,AL27/AJ27) -> 850 | AL27: =AL24+AL25+AL26 -> 46142.241 | AM27: =+AM18+AM16 -> 31.779223 | AN27: =IF(AM27<=0,0,AO27/AM27) -> 850 | AO27: =AO24+AO25+AO26 -> 27012.34
A28: =+$C$4&B28 -> Véhicules neufs
A29: =+$C$4&B29 -> Véhicules neufs
A30: =+$C$4&B30 -> Véhicules neufsTotal Dépt. Neufs | B30: Total Dépt. Neufs | C30: =+C16+C18+C20 -> 784 | D30: =IF(C30<=0,0,E30/C30) -> 1880.7398 | E30: =E16+E20+E27+E22+E18 -> 1474500 | F30: =+F16+F18+F20 -> 61.082386 | G30: =IF(F30<=0,0,H30/F30) -> 1886.0658 | H30: =H16+H20+H27+H22+H18 -> 115205.4 | I30: =+I16+I18+I20 -> 42.053307 | J30: =IF(I30<=0,0,K30/I30) -> 1923.1059 | K30: =K16+K20+K27+K22+K18 -> 80872.963 | L30: =+L16+L18+L20 -> 63.928286 | M30: =IF(L30<=0,0,N30/L30) -> 1882.4218 | N30: =N16+N20+N27+N22+N18 -> 120340 | O30: =+O16+O18+O20 -> 70.809068 | P30: =IF(O30<=0,0,Q30/O30) -> 1874.8216 | Q30: =Q16+Q20+Q27+Q22+Q18 -> 132754.37 | R30: =+R16+R18+R20 -> 92.528067 | S30: =IF(R30<=0,0,T30/R30) -> 1858.2468 | T30: =T16+T20+T27+T22+T18 -> 171939.99 | U30: =+U16+U18+U20 -> 65.189861 | V30: =IF(U30<=0,0,W30/U30) -> 1880.9082 | W30: =W16+W20+W27+W22+W18 -> 122616.15 | X30: =+X16+X18+X20 -> 64.903407 | Y30: =IF(X30<=0,0,Z30/X30) -> 1881.2467 | Z30: =Z16+Z20+Z27+Z22+Z18 -> 122099.32 | AA30: =+AA16+AA18+AA20 -> 68.724428 | AB30: =IF(AA30<=0,0,AC30/AA30) -> 1876.9635 | AC30: =AC16+AC20+AC27+AC22+AC18 -> 128993.24 | AD30: =+AD16+AD18+AD20 -> 75.307965 | AE30: =IF(AD30<=0,0,AF30/AD30) -> 1870.6032 | AF30: =AF16+AF20+AF27+AF22+AF18 -> 140871.32 | AG30: =+AG16+AG18+AG20 -> 93.409011 | AH30: =IF(AG30<=0,0,AI30/AG30) -> 1857.7372 | AI30: =AI16+AI20+AI27+AI22+AI18 -> 173529.4 | AJ30: =+AJ16+AJ18+AJ20 -> 54.28499 | AK30: =IF(AJ30<=0,0,AL30/AJ30) -> 1896.3157 | AL30: =AL16+AL20+AL27+AL22+AL18 -> 102941.48 | AM30: =+AM16+AM18+AM20 -> 31.779223 | AN30: =IF(AM30<=0,0,AO30/AM30) -> 1961.5447 | AO30: =AO16+AO20+AO27+AO22+AO18 -> 62336.367
A31: =+$C$4&B31 -> Véhicules neufs
A32: =+$C$4&B32 -> Véhicules neufs
A33: =+$C$4&B33 -> Véhicules neufsDEPENSES | B33: DEPENSES
A34: =+$C$4&B34 -> Véhicules neufsComm. vendeurs | B34: Comm. vendeurs | C34: =E34/(E16+E18) -> 0.39740476 | D34: =IF(E34=0,0,E34/C$27) -> 379.20727 | E34: =+SUM(H34,K34,N34,Q34,T34,W34,Z34,AC34,AF34,AI34,AL34,AO34) -> 297298.5 | F34: =H34/(H16+H18) -> 0.40539344 | G34: =IF(H34=0,0,H34/F$27) -> 386.83015 | H34: 23628.508 | I34: =K34/(K16+K18) -> 0.44880474 | J34: =IF(K34=0,0,K34/I$27) -> 428.25361 | K34: 18009.481 | L34: =N34/(N16+N18) -> 0.40432916 | M34: =IF(N34=0,0,N34/L$27) -> 385.8146 | N34: 24664.466 | O34: =Q34/(Q16+Q18) -> 0.39047512 | P34: =IF(Q34=0,0,Q34/O$27) -> 372.59495 | Q34: 26383.101 | R34: =T34/(T16+T18) -> 0.36587948 | S34: =IF(T34=0,0,T34/R$27) -> 349.12556 | T34: 32303.913 | U34: =W34/(W16+W18) -> 0.39855056 | V34: =IF(W34=0,0,W34/U$27) -> 380.30061 | W34: 24791.744 | X34: =Z34/(Z16+Z18) -> 0.40271347 | Y34: =IF(Z34=0,0,Z34/X$27) -> 384.27289 | Z34: 24940.62 | AA34: =AC34/(AC16+AC18) -> 0.39331691 | AB34: =IF(AC34=0,0,AC34/AA$27) -> 375.3066 | AC34: 25792.732 | AD34: =AF34/(AF16+AF18) -> 0.38487837 | AE34: =IF(AF34=0,0,AF34/AD$27) -> 367.25447 | AF34: 27657.187 | AG34: =AI34/(AI16+AI18) -> 0.36780834 | AH34: =IF(AI34=0,0,AI34/AG$27) -> 350.9661 | AI34: 32783.396 | AJ34: =AL34/(AL16+AL18) -> 0.41899244 | AK34: =IF(AL34=0,0,AL34/AJ$27) -> 399.80644 | AL34: 21703.488 | AM34: =AO34/(AO16+AO18) -> 0.482781 | AN34: =IF(AO34=0,0,AO34/AM$27) -> 460.67406 | AO34: 14639.864
A35: =+$C$4&B35 -> Véhicules neufsComm. F&I | B35: Comm. F&I | C35: =E35/E27 -> 0.3 | D35: =IF(E35=0,0,E35/C$27) -> 255 | E35: =+SUM(H35,K35,N35,Q35,T35,W35,Z35,AC35,AF35,AI35,AL35,AO35) -> 199920 | F35: =H35/H27 -> 0.3 | G35: =IF(H35=0,0,H35/F$27) -> 255 | H35: 15576.008 | I35: =K35/K27 -> 0.3 | J35: =IF(K35=0,0,K35/I$27) -> 255 | K35: 10723.593 | L35: =N35/N27 -> 0.3 | M35: =IF(N35=0,0,N35/L$27) -> 255 | N35: 16301.713 | O35: =Q35/Q27 -> 0.3 | P35: =IF(Q35=0,0,Q35/O$27) -> 255 | Q35: 18056.312 | R35: =T35/T27 -> 0.3 | S35: =IF(T35=0,0,T35/R$27) -> 255 | T35: 23594.657 | U35: =W35/W27 -> 0.3 | V35: =IF(W35=0,0,W35/U$27) -> 255 | W35: 16623.415 | X35: =Z35/Z27 -> 0.3 | Y35: =IF(Z35=0,0,Z35/X$27) -> 255 | Z35: 16550.369 | AA35: =AC35/AC27 -> 0.3 | AB35: =IF(AC35=0,0,AC35/AA$27) -> 255 | AC35: 17524.729 | AD35: =AF35/AF27 -> 0.3 | AE35: =IF(AF35=0,0,AF35/AD$27) -> 255 | AF35: 19203.531 | AG35: =AI35/AI27 -> 0.3 | AH35: =IF(AI35=0,0,AI35/AG$27) -> 255 | AI35: 23819.298 | AJ35: =AL35/AL27 -> 0.3 | AK35: =IF(AL35=0,0,AL35/AJ$27) -> 255 | AL35: 13842.672 | AM35: =AO35/AO27 -> 0.3 | AN35: =IF(AO35=0,0,AO35/AM$27) -> 255 | AO35: 8103.702
A36: =+$C$4&B36 -> Véhicules neufsFrais de livraison | B36: Frais de livraison | D36: =IF(E36=0,0,E36/C$27) -> 197 | E36: =+SUM(H36,K36,N36,Q36,T36,W36,Z36,AC36,AF36,AI36,AL36,AO36) -> 154448 | G36: =IF(H36=0,0,H36/F$27) -> 197 | H36: 12033.23 | J36: =IF(K36=0,0,K36/I$27) -> 197 | K36: 8284.5015 | M36: =IF(N36=0,0,N36/L$27) -> 197 | N36: 12593.872 | P36: =IF(Q36=0,0,Q36/O$27) -> 197 | Q36: 13949.386 | S36: =IF(T36=0,0,T36/R$27) -> 197 | T36: 18228.029 | V36: =IF(W36=0,0,W36/U$27) -> 197 | W36: 12842.403 | Y36: =IF(Z36=0,0,Z36/X$27) -> 197 | Z36: 12785.971 | AB36: =IF(AC36=0,0,AC36/AA$27) -> 197 | AC36: 13538.712 | AE36: =IF(AF36=0,0,AF36/AD$27) -> 197 | AF36: 14835.669 | AH36: =IF(AI36=0,0,AI36/AG$27) -> 197 | AI36: 18401.575 | AK36: =IF(AL36=0,0,AL36/AJ$27) -> 197 | AL36: 10694.143 | AN36: =IF(AO36=0,0,AO36/AM$27) -> 197 | AO36: 6260.507
A37: =+$C$4&B37 -> Véhicules neufsService gratuit 1 | B37: Service gratuit 1 | D37: =IF(E37=0,0,E37/C$27) -> 6 | E37: =+SUM(H37,K37,N37,Q37,T37,W37,Z37,AC37,AF37,AI37,AL37,AO37) -> 4704 | G37: =IF(H37=0,0,H37/F$27) -> 6 | H37: 366.49431 | J37: =IF(K37=0,0,K37/I$27) -> 6 | K37: 252.31984 | M37: =IF(N37=0,0,N37/L$27) -> 6 | N37: 383.56972 | P37: =IF(Q37=0,0,Q37/O$27) -> 6 | Q37: 424.85441 | S37: =IF(T37=0,0,T37/R$27) -> 6 | T37: 555.1684 | V37: =IF(W37=0,0,W37/U$27) -> 6 | W37: 391.13917 | Y37: =IF(Z37=0,0,Z37/X$27) -> 6 | Z37: 389.42044 | AB37: =IF(AC37=0,0,AC37/AA$27) -> 6 | AC37: 412.34657 | AE37: =IF(AF37=0,0,AF37/AD$27) -> 6 | AF37: 451.84779 | AH37: =IF(AI37=0,0,AI37/AG$27) -> 6 | AI37: 560.45407 | AK37: =IF(AL37=0,0,AL37/AJ$27) -> 6 | AL37: 325.70994 | AN37: =IF(AO37=0,0,AO37/AM$27) -> 6 | AO37: 190.67534
A38: =+$C$4&B38 -> Véhicules neufsEntretien stock | B38: Entretien stock | D38: =IF(E38=0,0,E38/C$27) -> 34 | E38: =+SUM(H38,K38,N38,Q38,T38,W38,Z38,AC38,AF38,AI38,AL38,AO38) -> 26656 | G38: =IF(H38=0,0,H38/F$27) -> 34 | H38: 2076.8011 | J38: =IF(K38=0,0,K38/I$27) -> 34 | K38: 1429.8124 | M38: =IF(N38=0,0,N38/L$27) -> 34 | N38: 2173.5617 | P38: =IF(Q38=0,0,Q38/O$27) -> 34 | Q38: 2407.5083 | S38: =IF(T38=0,0,T38/R$27) -> 34 | T38: 3145.9543 | V38: =IF(W38=0,0,W38/U$27) -> 34 | W38: 2216.4553 | Y38: =IF(Z38=0,0,Z38/X$27) -> 34 | Z38: 2206.7158 | AB38: =IF(AC38=0,0,AC38/AA$27) -> 34 | AC38: 2336.6306 | AE38: =IF(AF38=0,0,AF38/AD$27) -> 34 | AF38: 2560.4708 | AH38: =IF(AI38=0,0,AI38/AG$27) -> 34 | AI38: 3175.9064 | AK38: =IF(AL38=0,0,AL38/AJ$27) -> 34 | AL38: 1845.6897 | AN38: =IF(AO38=0,0,AO38/AM$27) -> 34 | AO38: 1080.4936
A39: =+$C$4&B39 -> Véhicules neufsPublicité 1 | B39: Publicité 1 | D39: =IF(E39=0,0,E39/C$27) -> 180.66964 | E39: =+SUM(H39,K39,N39,Q39,T39,W39,Z39,AC39,AF39,AI39,AL39,AO39) -> 141645 | G39: =IF(H39=0,0,H39/F$27) -> 180.66964 | H39: 11035.733 | J39: =IF(K39=0,0,K39/I$27) -> 180.66964 | K39: 7597.756 | M39: =IF(N39=0,0,N39/L$27) -> 180.66964 | N39: 11549.901 | P39: =IF(Q39=0,0,Q39/O$27) -> 180.66964 | Q39: 12793.049 | S39: =IF(T39=0,0,T39/R$27) -> 180.66964 | T39: 16717.013 | V39: =IF(W39=0,0,W39/U$27) -> 180.66964 | W39: 11777.829 | Y39: =IF(Z39=0,0,Z39/X$27) -> 180.66964 | Z39: 11726.075 | AB39: =IF(AC39=0,0,AC39/AA$27) -> 180.66964 | AC39: 12416.418 | AE39: =IF(AF39=0,0,AF39/AD$27) -> 180.66964 | AF39: 13605.863 | AH39: =IF(AI39=0,0,AI39/AG$27) -> 180.66964 | AI39: 16876.173 | AK39: =IF(AL39=0,0,AL39/AJ$27) -> 180.66964 | AL39: 9807.6498 | AN39: =IF(AO39=0,0,AO39/AM$27) -> 180.66964 | AO39: 5741.5409
A40: =+$C$4&B40 -> Véhicules neufsIntérêt de gros | B40: Intérêt de gros | D40: =IF(E40=0,0,E40/C$27) -> 222.74973 | E40: =+SUM(H40,K40,N40,Q40,T40,W40,Z40,AC40,AF40,AI40,AL40,AO40) -> 174635.78 | G40: =IF(H40=0,0,H40/F$27) -> 226.36716 | H40: 13827.046 | J40: =IF(K40=0,0,K40/I$27) -> 330.58249 | K40: 13902.087 | M40: =IF(N40=0,0,N40/L$27) -> 229.32443 | N40: 14660.318 | P40: =IF(Q40=0,0,Q40/O$27) -> 217.69014 | Q40: 15414.436 | S40: =IF(T40=0,0,T40/R$27) -> 164.99068 | T40: 15266.269 | V40: =IF(W40=0,0,W40/U$27) -> 223.00803 | W40: 14537.863 | Y40: =IF(Z40=0,0,Z40/X$27) -> 225.42826 | Z40: 14631.062 | AB40: =IF(AC40=0,0,AC40/AA$27) -> 216.88662 | AC40: 14905.409 | AE40: =IF(AF40=0,0,AF40/AD$27) -> 206.569 | AF40: 15556.291 | AH40: =IF(AI40=0,0,AI40/AG$27) -> 160.60504 | AI40: 15001.958 | AK40: =IF(AL40=0,0,AL40/AJ$27) -> 246.41998 | AL40: 13376.906 | AN40: =IF(AO40=0,0,AO40/AM$27) -> 426.57241 | AO40: 13556.14
A41: =+$C$4&B41 -> Véhicules neufs[...] | B41: [...] | D41: =IF(E41=0,0,E41/C$27) -> 0 | E41: =+SUM(H41,K41,N41,Q41,T41,W41,Z41,AC41,AF41,AI41,AL41,AO41) -> 0 | G41: =IF(H41=0,0,H41/F$27) -> 0 | J41: =IF(K41=0,0,K41/I$27) -> 0 | M41: =IF(N41=0,0,N41/L$27) -> 0 | P41: =IF(Q41=0,0,Q41/O$27) -> 0 | S41: =IF(T41=0,0,T41/R$27) -> 0 | V41: =IF(W41=0,0,W41/U$27) -> 0 | Y41: =IF(Z41=0,0,Z41/X$27) -> 0 | AB41: =IF(AC41=0,0,AC41/AA$27) -> 0 | AE41: =IF(AF41=0,0,AF41/AD$27) -> 0 | AH41: =IF(AI41=0,0,AI41/AG$27) -> 0 | AK41: =IF(AL41=0,0,AL41/AJ$27) -> 0 | AN41: =IF(AO41=0,0,AO41/AM$27) -> 0
...

Sheet 2pager
B1: =Parametres!$B$1&" "&"2 pager"&" "&Parametres!$B$3&" "&Parametres!$B$4 -> Volks 2 pager Mars 2021
B3: New | C3: Actual | D3: Forecast | E3: Budget | F3: 2019 | G3: ▲ Forecast | H3: ▲ Budget | I3: ▲2019 | J3: % ▲ Forecast | K3: % ▲ Budget | L3: % ▲ 2019 | M3: Commentaires
B4: Units | C4: =+Print_Mois!$J$13+Print_Mois!$J$15 -> 78 | D4: =+Print_Mois!$G$13+Print_Mois!$G$15 -> 63.928286 | E4: =+Print_Mois!$D$13+Print_Mois!$D$15 -> 63.928286 | F4: =+Print_Mois!$O$13+Print_Mois!$O$15 -> 75 | G4: =+IFERROR($C4-D4,"") -> 14.071714 | H4: =+IFERROR($C4-E4,"") -> 14.071714 | I4: =+IFERROR($C4-F4,"") -> 3 | J4: =+IFERROR(G4/ABS($D4),"") -> 0.22011717 | K4: =+IFERROR(H4/ABS($E4),"") -> 0.22011717 | L4: =+IFERROR(I4/ABS($F4),"") -> 0.04 | M4: -Excellente moyenne en ligne avec V3. Volume aussi au RV pour février. -Salaire et commission encore légèrement élevé. à suivre de près -F&I aussi difficile chez VW. Moyenne plus tough avec le type d'acheteur hivernal moins émotif. -Other incomes explosé par le versement final des TOTS et beaucoup de HB. - Bonne gestion des frais variable de Louis et son équipe dans le neuf.
B5: Front Margin | C5: =+Print_Mois!$L$13+Print_Mois!$L$15 -> 122247.05 | D5: =+Print_Mois!$I$13+Print_Mois!$I$15 -> 84870.504 | E5: =+Print_Mois!$F$13+Print_Mois!$F$15 -> 61000.958 | F5: =+Print_Mois!$Q$13+Print_Mois!$Q$15 -> 41360.79 | G5: =+IFERROR($C5-D5,"") -> 37376.546 | H5: =+IFERROR($C5-E5,"") -> 61246.092 | I5: =+IFERROR($C5-F5,"") -> 80886.26 | J5: =+IFERROR(G5/ABS($D5),"") -> 0.440395 | K5: =+IFERROR(H5/ABS($E5),"") -> 1.0040185 | L5: =+IFERROR(I5/ABS($F5),"") -> 1.9556266
B6: Front margin / unit | C6: =+C5/C4 -> 1567.2699 | D6: =+D5/D4 -> 1327.5892 | E6: =+E5/E4 -> 954.20918 | F6: =+F5/F4 -> 551.4772 | G6: =+IFERROR($C6-D6,"") -> 239.68064 | H6: =+IFERROR($C6-E6,"") -> 613.06069 | I6: =+IFERROR($C6-F6,"") -> 1015.7927 | J6: =+IFERROR(G6/ABS($D6),"") -> 0.18053826 | K6: =+IFERROR(H6/ABS($E6),"") -> 0.64248039 | L6: =+IFERROR(I6/ABS($F6),"") -> 1.8419486
B7: $ Salaires et commission | C7: =+Print_Mois!$L$31 -> 41980.82 | D7: =+Print_Mois!$I$31 -> 25136.953 | E7: =+Print_Mois!$F$31 -> 24664.466 | F7: =+Print_Mois!$Q$31 -> 30014.5 | G7: =+IFERROR($C7-D7,"") -> 16843.867 | H7: =+IFERROR($C7-E7,"") -> 17316.354 | I7: =+IFERROR($C7-F7,"") -> 11966.32 | J7: =+IFERROR(G7/ABS($D7),"") -> 0.67008389 | K7: =+IFERROR(H7/ABS($E7),"") -> 0.70207697 | L7: =+IFERROR(I7/ABS($F7),"") -> 0.39868464
B8: % Salaires et commission | C8: =+C7/C5 -> 0.34340968 | D8: =+D7/D5 -> 0.29618008 | E8: =+E7/E5 -> 0.40432916 | F8: =+F7/F5 -> 0.72567521 | G8: =+IFERROR($C8-D8,"") -> 0.047229596 | H8: =+IFERROR($C8-E8,"") -> -0.060919485 | I8: =+IFERROR($C8-F8,"") -> -0.38226553 | J8: =+IFERROR(G8/ABS($D8),"") -> 0.15946243 | K8: =+IFERROR(H8/ABS($E8),"") -> -0.15066805 | L8: =+IFERROR(I8/ABS($F8),"") -> -0.52677221
B9: Back Margin | C9: =+Print_Mois!$L$24 -> 53578.88 | D9: =+Print_Mois!$I$24 -> 54339.043 | E9: =+Print_Mois!$F$24 -> 54339.043 | F9: =+Print_Mois!$Q$24 -> 46251.59 | G9: =+IFERROR($C9-D9,"") -> -760.16344 | H9: =+IFERROR($C9-E9,"") -> -760.16344 | I9: =+IFERROR($C9-F9,"") -> 7327.29 | J9: =+IFERROR(G9/ABS($D9),"") -> -0.013989268 | K9: =+IFERROR(H9/ABS($E9),"") -> -0.013989268 | L9: =+IFERROR(I9/ABS($F9),"") -> 0.15842245
B10: Back Margin / unit | C10: =+C9/C4 -> 686.90872 | D10: =+D9/D4 -> 850 | E10: =+E9/E4 -> 850 | F10: =+F9/F4 -> 616.68787 | G10: =+IFERROR($C10-D10,"") -> -163.09128 | H10: =+IFERROR($C10-E10,"") -> -163.09128 | I10: =+IFERROR($C10-F10,"") -> 70.220851 | J10: =+IFERROR(G10/ABS($D10),"") -> -0.1918721 | K10: =+IFERROR(H10/ABS($E10),"") -> -0.1918721 | L10: =+IFERROR(I10/ABS($F10),"") -> 0.11386774
B11: $ commission FI | C11: =+Print_Mois!$L$32 -> 15873.98 | D11: =+Print_Mois!$I$32 -> 16301.713 | E11: =+Print_Mois!$F$32 -> 16301.713 | F11: =+Print_Mois!$Q$32 -> 20977.35 | G11: =+IFERROR($C11-D11,"") -> -427.73303 | H11: =+IFERROR($C11-E11,"") -> -427.73303 | I11: =+IFERROR($C11-F11,"") -> -5103.37 | J11: =+IFERROR(G11/ABS($D11),"") -> -0.026238533 | K11: =+IFERROR(H11/ABS($E11),"") -> -0.026238533 | L11: =+IFERROR(I11/ABS($F11),"") -> -0.24328001
B12: % commission FI | C12: =+C11/C9 -> 0.29627308 | D12: =+D11/D9 -> 0.3 | E12: =+E11/E9 -> 0.3 | F12: =+F11/F9 -> 0.45354873 | G12: =+IFERROR($C12-D12,"") -> -0.0037269163 | H12: =+IFERROR($C12-E12,"") -> -0.0037269163 | I12: =+IFERROR($C12-F12,"") -> -0.15727565 | J12: =+IFERROR(G12/ABS($D12),"") -> -0.012423054 | K12: =+IFERROR(H12/ABS($E12),"") -> -0.012423054 | L12: =+IFERROR(I12/ABS($F12),"") -> -0.34676681
B13: Variable fees | C13: =+Print_Mois!$L$41-C7-C11 -> 31611.66 | D13: =+Print_Mois!$I$41-D7-D11 -> 41484.084 | E13: =+Print_Mois!$F$41-E7-E11 -> 41361.222 | F13: =+Print_Mois!$Q$41-F7-F11 -> 42339.06 | G13: =+IFERROR($C13-D13,"") -> -9872.4238 | H13: =+IFERROR($C13-E13,"") -> -9749.5623 | I13: =+IFERROR($C13-F13,"") -> -10727.4 | J13: =+IFERROR(G13/ABS($D13),"") -> -0.237981 | K13: =+IFERROR(H13/ABS($E13),"") -> -0.23571746 | L13: =+IFERROR(I13/ABS($F13),"") -> -0.25336887
B14: Variable fees / units | C14: =+C13/C4 -> 405.27769 | D14: =+D13/D4 -> 648.91594 | E14: =+E13/E4 -> 646.99407 | F14: =+F13/F4 -> 564.5208 | G14: =+IFERROR($C14-D14,"") -> -243.63824 | H14: =+IFERROR($C14-E14,"") -> -241.71638 | I14: =+IFERROR($C14-F14,"") -> -159.24311 | J14: =+IFERROR(G14/ABS($D14),"") -> -0.37545425 | K14: =+IFERROR(H14/ABS($E14),"") -> -0.37359906 | L14: =+IFERROR(I14/ABS($F14),"") -> -0.28208546
B15: Other Revenues | C15: =+Print_Mois!$L$83 -> 138129 | D15: =+Print_Mois!$I$83 -> 94764.54 | E15: =+Print_Mois!$F$83 -> 138213.08 | F15: =+Print_Mois!$Q$83 -> 105593 | G15: =+IFERROR($C15-D15,"") -> 43364.46 | H15: =+IFERROR($C15-E15,"") -> -84.079759 | I15: =+IFERROR($C15-F15,"") -> 32536 | J15: =+IFERROR(G15/ABS($D15),"") -> 0.45760218 | K15: =+IFERROR(H15/ABS($E15),"") -> -0.00060833432 | L15: =+IFERROR(I15/ABS($F15),"") -> 0.30812649
B16: Inventory
B17: Units | C17: 164 | D17: 164 | E17: 141 | F17: 306 | G17: =+IFERROR($C17-D17,"") -> 0 | H17: =+IFERROR($C17-E17,"") -> 23 | I17: =+IFERROR($C17-F17,"") -> -142 | J17: =+IFERROR(G17/ABS($D17),"") -> 0 | K17: =+IFERROR(H17/ABS($E17),"") -> 0.16312057 | L17: =+IFERROR(I17/ABS($F17),"") -> -0.46405229
B18: $ | C18: 5689693.2 | D18: 5689693.2 | E18: 4513319 | F18: 9372292.9 | G18: =+IFERROR($C18-D18,"") -> 0 | H18: =+IFERROR($C18-E18,"") -> 1176374.2 | I18: =+IFERROR($C18-F18,"") -> -3682599.7 | J18: =+IFERROR(G18/ABS($D18),"") -> 0 | K18: =+IFERROR(H18/ABS($E18),"") -> 0.26064503 | L18: =+IFERROR(I18/ABS($F18),"") -> -0.39292409
B20: Used | C20: Actual | D20: Forecast | E20: Budget | F20: 2019 | G20: ▲ Forecast | H20: ▲ Budget | I20: ▲2019 | J20: % ▲ Forecast | K20: % ▲ Budget | L20: % ▲ 2019 | M20: Commentaires
B21: Units | C21: =+Print_Mois!$J$96 -> 42 | D21: =+Print_Mois!$G$96 -> 24.069687 | E21: =+Print_Mois!$D$96 -> 24.069687 | F21: =+Print_Mois!$O$96 -> 33 | G21: =+IFERROR($C21-D21,"") -> 17.930313 | H21: =+IFERROR($C21-E21,"") -> 17.930313 | I21: =+IFERROR($C21-F21,"") -> 9 | J21: =+IFERROR(G21/ABS($D21),"") -> 0.74493335 | K21: =+IFERROR(H21/ABS($E21),"") -> 0.74493335 | L21: =+IFERROR(I21/ABS($F21),"") -> 0.27272727 | M21: -Front margin au budegt. Volume au RV. Il faut continuer de travailler la moyenne chez VW dans le used -Salaire et commissions en ligne cependant -F&I tout près du budget. Donc ok! -Frais variable par unités un peu élevé. à surveiller! -autre revenus. ok!
B22: Front Margin | C22: =+Print_Mois!$L$96 -> 39178.43 | D22: =+Print_Mois!$I$96 -> 18052.265 | E22: =+Print_Mois!$F$96 -> 18052.265 | F22: =+Print_Mois!$Q$96 -> 4871.72 | G22: =+IFERROR($C22-D22,"") -> 21126.165 | H22: =+IFERROR($C22-E22,"") -> 21126.165 | I22: =+IFERROR($C22-F22,"") -> 34306.71 | J22: =+IFERROR(G22/ABS($D22),"") -> 1.1702778 | K22: =+IFERROR(H22/ABS($E22),"") -> 1.1702778 | L22: =+IFERROR(I22/ABS($F22),"") -> 7.0420119
B23: Front margin / unit | C23: =+C22/C21 -> 932.81976 | D23: =+D22/D21 -> 750 | E23: =+E22/E21 -> 750 | F23: =+F22/F21 -> 147.62788 | G23: =+IFERROR($C23-D23,"") -> 182.81976 | H23: =+IFERROR($C23-E23,"") -> 182.81976 | I23: =+IFERROR($C23-F23,"") -> 785.19188 | J23: =+IFERROR(G23/ABS($D23),"") -> 0.24375968 | K23: =+IFERROR(H23/ABS($E23),"") -> 0.24375968 | L23: =+IFERROR(I23/ABS($F23),"") -> 5.3187236
B24: $ Salaires et commission | C24: =+Print_Mois!$L$111 -> 19590.26 | D24: =+Print_Mois!$I$111 -> 11976.554 | E24: =+Print_Mois!$F$111 -> 11976.554 | F24: =+Print_Mois!$Q$111 -> 11183.93 | G24: =+IFERROR($C24-D24,"") -> 7613.7058 | H24: =+IFERROR($C24-E24,"") -> 7613.7058 | I24: =+IFERROR($C24-F24,"") -> 8406.33 | J24: =+IFERROR(G24/ABS($D24),"") -> 0.63571756 | K24: =+IFERROR(H24/ABS($E24),"") -> 0.63571756 | L24: =+IFERROR(I24/ABS($F24),"") -> 0.75164365
B25: % Salaires et commission | C25: =+C24/C22 -> 0.50002667 | D25: =+D24/D22 -> 0.66343774 | E25: =+E24/E22 -> 0.66343774 | F25: =+F24/F22 -> 2.2956841 | G25: =+IFERROR($C25-D25,"") -> -0.16341107 | H25: =+IFERROR($C25-E25,"") -> -0.16341107 | I25: =+IFERROR($C25-F25,"") -> -1.7956574 | J25: =+IFERROR(G25/ABS($D25),"") -> -0.24630958 | K25: =+IFERROR(H25/ABS($E25),"") -> -0.24630958 | L25: =+IFERROR(I25/ABS($F25),"") -> -0.78218838
B26: Back Margin | C26: =+Print_Mois!$L$104 -> 69859.68 | D26: =+Print_Mois!$I$104 -> 41289.132 | E26: =+Print_Mois!$F$104 -> 41289.132 | F26: =+Print_Mois!$Q$104 -> 42143.94 | G26: =+IFERROR($C26-D26,"") -> 28570.548 | H26: =+IFERROR($C26-E26,"") -> 28570.548 | I26: =+IFERROR($C26-F26,"") -> 27715.74 | J26: =+IFERROR(G26/ABS($D26),"") -> 0.69196291 | K26: =+IFERROR(H26/ABS($E26),"") -> 0.69196291 | L26: =+IFERROR(I26/ABS($F26),"") -> 0.65764473
B27: Back Margin / unit | C27: =+C26/C21 -> 1663.3257 | D27: =+D26/D21 -> 1715.3996 | E27: =+E26/E21 -> 1715.3996 | F27: =+F26/F21 -> 1277.0891 | G27: =+IFERROR($C27-D27,"") -> -52.073896 | H27: =+IFERROR($C27-E27,"") -> -52.073896 | I27: =+IFERROR($C27-F27,"") -> 386.23662 | J27: =+IFERROR(G27/ABS($D27),"") -> -0.030356714 | K27: =+IFERROR(H27/ABS($E27),"") -> -0.030356714 | L27: =+IFERROR(I27/ABS($F27),"") -> 0.30243514
B28: $ commission FI | C28: =+Print_Mois!$L$112 -> 22319.2 | D28: =+Print_Mois!$I$112 -> 12386.74 | E28: =+Print_Mois!$F$112 -> 12386.74 | F28: =+Print_Mois!$Q$112 -> 7116.21 | G28: =+IFERROR($C28-D28,"") -> 9932.4604 | H28: =+IFERROR($C28-E28,"") -> 9932.4604 | I28: =+IFERROR($C28-F28,"") -> 15202.99 | J28: =+IFERROR(G28/ABS($D28),"") -> 0.80186237 | K28: =+IFERROR(H28/ABS($E28),"") -> 0.80186237 | L28: =+IFERROR(I28/ABS($F28),"") -> 2.1363886
B29: % commission FI | C29: =+C28/C26 -> 0.31948615 | D29: =+D28/D26 -> 0.3 | E29: =+E28/E26 -> 0.3 | F29: =+F28/F26 -> 0.16885488 | G29: =+IFERROR($C29-D29,"") -> 0.019486147 | H29: =+IFERROR($C29-E29,"") -> 0.019486147 | I29: =+IFERROR($C29-F29,"") -> 0.15063127 | J29: =+IFERROR(G29/ABS($D29),"") -> 0.064953824 | K29: =+IFERROR(H29/ABS($E29),"") -> 0.064953824 | L29: =+IFERROR(I29/ABS($F29),"") -> 0.89207528
B30: Variable fees | C30: =+Print_Mois!$L$121-C24-C28 -> 9002.56 | D30: =+Print_Mois!$I$121-D24-D28 -> 7134.6511 | E30: =+Print_Mois!$F$121-E24-E28 -> 7134.6511 | F30: =+Print_Mois!$Q$121-F24-F28 -> 7499.93 | G30: =+IFERROR($C30-D30,"") -> 1867.9089 | H30: =+IFERROR($C30-E30,"") -> 1867.9089 | I30: =+IFERROR($C30-F30,"") -> 1502.63 | J30: =+IFERROR(G30/ABS($D30),"") -> 0.26180802 | K30: =+IFERROR(H30/ABS($E30),"") -> 0.26180802 | L30: =+IFERROR(I30/ABS($F30),"") -> 0.20035254
B31: Variable fees / units | C31: =+C30/C21 -> 214.34667 | D31: =+D30/D21 -> 296.41644 | E31: =+E30/E21 -> 296.41644 | F31: =+F30/F21 -> 227.27061 | G31: =+IFERROR($C31-D31,"") -> -82.069778 | H31: =+IFERROR($C31-E31,"") -> -82.069778 | I31: =+IFERROR($C31-F31,"") -> -12.923939 | J31: =+IFERROR(G31/ABS($D31),"") -> -0.27687323 | K31: =+IFERROR(H31/ABS($E31),"") -> -0.27687323 | L31: =+IFERROR(I31/ABS($F31),"") -> -0.056865864
B32: Other Revenues | C32: =+Print_Mois!$L$162 -> 23158 | D32: =+Print_Mois!$I$162 -> 16060.289 | E32: =+Print_Mois!$F$162 -> 16060.289 | F32: =+Print_Mois!$Q$162 -> 0 | G32: =+IFERROR($C32-D32,"") -> 7097.7112 | H32: =+IFERROR($C32-E32,"") -> 7097.7112 | I32: =+IFERROR($C32-F32,"") -> 23158 | J32: =+IFERROR(G32/ABS($D32),"") -> 0.4419417 | K32: =+IFERROR(H32/ABS($E32),"") -> 0.4419417 | L32: =+IFERROR(I32/ABS($F32),"")
B33: Inventory
B34: Units | C34: 92 | D34: 92 | E34: 55 | F34: 49 | G34: =+IFERROR($C34-D34,"") -> 0 | H34: =+IFERROR($C34-E34,"") -> 37 | I34: =+IFERROR($C34-F34,"") -> 43 | J34: =+IFERROR(G34/ABS($D34),"") -> 0 | K34: =+IFERROR(H34/ABS($E34),"") -> 0.67272727 | L34: =+IFERROR(I34/ABS($F34),"") -> 0.87755102
B35: $ | C35: 1510979 | D35: 1510979 | E35: 919262 | F35: 813537 | G35: =+IFERROR($C35-D35,"") -> 0 | H35: =+IFERROR($C35-E35,"") -> 591717 | I35: =+IFERROR($C35-F35,"") -> 697442 | J35: =+IFERROR(G35/ABS($D35),"") -> 0 | K35: =+IFERROR(H35/ABS($E35),"") -> 0.643687 | L35: =+IFERROR(I35/ABS($F35),"") -> 0.85729598
B37: Service | C37: Actual | D37: Forecast | E37: Budget | F37: 2019 | G37: ▲ Forecast | H37: ▲ Budget | I37: ▲2019 | J37: % ▲ Forecast | K37: % ▲ Budget | L37: % ▲ 2019 | M37: Commentaires
B38: Revenus | C38: =+Print_Mois!$K$193 -> 230012.55 | D38: =+Print_Mois!$H$193 -> 224331.67 | E38: =+Print_Mois!$E$193 -> 224331.67 | F38: =+Print_Mois!$P$193 -> 219906.5 | G38: =+IFERROR($C38-D38,"") -> 5680.875 | H38: =+IFERROR($C38-E38,"") -> 5680.875 | I38: =+IFERROR($C38-F38,"") -> 10106.05 | J38: =+IFERROR(G38/ABS($D38),"") -> 0.025323553 | K38: =+IFERROR(H38/ABS($E38),"") -> 0.025323553 | L38: =+IFERROR(I38/ABS($F38),"") -> 0.045956122 | M38: -Belle réalisatio presque qu'a budget en client. Mars sera bon pour VW! -Moyenne par bon légèrement sous la cible. à suivre de près sans over sale. -Bonne gestion des salaires -Véhicule de compagnie en lien avec le budget -Bonne gestion du lost time -Gestion efficace, maintenant il faut entrer du volume!
B39: Gross margin | C39: =+Print_Mois!$L$193 -> 160416.79 | D39: =+Print_Mois!$I$193 -> 148974.88 | E39: =+Print_Mois!$F$193 -> 148974.88 | F39: =+Print_Mois!$Q$193 -> 136594.91 | G39: =+IFERROR($C39-D39,"") -> 11441.911 | H39: =+IFERROR($C39-E39,"") -> 11441.911 | I39: =+IFERROR($C39-F39,"") -> 23821.88 | J39: =+IFERROR(G39/ABS($D39),"") -> 0.076804299 | K39: =+IFERROR(H39/ABS($E39),"") -> 0.076804299 | L39: =+IFERROR(I39/ABS($F39),"") -> 0.17439801
B40: $ Revenus / #WO client | C40: =+Print_Mois!$K$171/Print_Mois!$J$171 -> 224.72885 | D40: =+IFERROR(Print_Mois!$H$171/Print_Mois!$G$171,"") -> 245.43849 | E40: =+IFERROR(Print_Mois!$E$171/Print_Mois!$D$171,"") -> 245.43849 | F40: =+Print_Mois!$P$171/Print_Mois!$O$171 -> 239.17334 | G40: =+IFERROR($C40-D40,"") -> -20.709639 | H40: =+IFERROR($C40-E40,"") -> -20.709639 | I40: =+IFERROR($C40-F40,"") -> -14.444496 | J40: =+IFERROR(G40/ABS($D40),"") -> -0.084378123 | K40: =+IFERROR(H40/ABS($E40),"") -> -0.084378123 | L40: =+IFERROR(I40/ABS($F40),"") -> -0.060393419
B41: $ Revenus / #WO garantie | C41: =+Print_Mois!$K$174/Print_Mois!$J$174 -> 207.33353 | D41: =+IFERROR(Print_Mois!$H$174/Print_Mois!$G$174,"") -> 176.734 | E41: =+IFERROR(Print_Mois!$E$174/Print_Mois!$D$174,"") -> 176.734 | F41: =+Print_Mois!$P$174/Print_Mois!$O$174 -> 229.84493 | G41: =+IFERROR($C41-D41,"") -> 30.599527 | H41: =+IFERROR($C41-E41,"") -> 30.599527 | I41: =+IFERROR($C41-F41,"") -> -22.5114 | J41: =+IFERROR(G41/ABS($D41),"") -> 0.17313888 | K41: =+IFERROR(H41/ABS($E41),"") -> 0.17313888 | L41: =+IFERROR(I41/ABS($F41),"") -> -0.097941685
B42: Lost time | C42: =+Print_Mois!$L$183 -> -3087.66 | D42: =+Print_Mois!$I$183 -> -3475.708 | E42: =+Print_Mois!$F$183 -> -3475.708 | F42: =+Print_Mois!$Q$183 -> -3388.98 | G42: =+IFERROR($C42-D42,"") -> 388.04804 | H42: =+IFERROR($C42-E42,"") -> 388.04804 | I42: =+IFERROR($C42-F42,"") -> 301.32 | J42: =+IFERROR(G42/ABS($D42),"") -> 0.11164575 | K42: =+IFERROR(H42/ABS($E42),"") -> 0.11164575 | L42: =+IFERROR(I42/ABS($F42),"") -> 0.088911708
B43: Total salaries | C43: =+Print_Mois!$L$209 -> 112764.76 | D43: =+Print_Mois!$I$209 -> 118025.5 | E43: =+Print_Mois!$F$209 -> 118025.5 | F43: =+Print_Mois!$Q$209 -> 83086.49 | G43: =+IFERROR($C43-D43,"") -> -5260.7378 | H43: =+IFERROR($C43-E43,"") -> -5260.7378 | I43: =+IFERROR($C43-F43,"") -> 29678.27 | J43: =+IFERROR(G43/ABS($D43),"") -> -0.044572892 | K43: =+IFERROR(H43/ABS($E43),"") -> -0.044572892 | L43: =+IFERROR(I43/ABS($F43),"") -> 0.3571973
...

Sheet Budget révisé
B1: ="Budget 2021 Mensuel Révisé"&" "&Parametres!$B$1 -> Budget 2021 Mensuel Révisé Volks
B2: Mois | F2: =+IF(Parametres!$B$3=F$6,"X","") | G2: =+IF(Parametres!$B$3=F$6,"O","") | H2: =+IF(Parametres!$B$3=F$6,"U","") | I2: =+IF(Parametres!$B$3=I$6,"X","") | J2: =+IF(Parametres!$B$3=I$6,"O","") | K2: =+IF(Parametres!$B$3=I$6,"U","") | L2: =+IF(Parametres!$B$3=L$6,"X","") -> X | M2: =+IF(Parametres!$B$3=L$6,"O","") -> O | N2: =+IF(Parametres!$B$3=L$6,"U","") -> U | O2: =+IF(Parametres!$B$3=O$6,"X","") | P2: =+IF(Parametres!$B$3=O$6,"O","") | Q2: =+IF(Parametres!$B$3=O$6,"U","") | R2: =+IF(Parametres!$B$3=R$6,"X","") | S2: =+IF(Parametres!$B$3=R$6,"O","") | T2: =+IF(Parametres!$B$3=R$6,"U","") | U2: =+IF(Parametres!$B$3=U$6,"X","") | V2: =+IF(Parametres!$B$3=U$6,"O","") | W2: =+IF(Parametres!$B$3=U$6,"U","") | X2: =+IF(Parametres!$B$3=X$6,"X","") | Y2: =+IF(Parametres!$B$3=X$6,"O","") | Z2: =+IF(Parametres!$B$3=X$6,"U","") | AA2: =+IF(Parametres!$B$3=AA$6,"X","") | AB2: =+IF(Parametres!$B$3=AA$6,"O","") | AC2: =+IF(Parametres!$B$3=AA$6,"U","") | AD2: =+IF(Parametres!$B$3=AD$6,"X","") | AE2: =+IF(Parametres!$B$3=AD$6,"O","") | AF2: =+IF(Parametres!$B$3=AD$6,"U","") | AG2: =+IF(Parametres!$B$3=AG$6,"X","") | AH2: =+IF(Parametres!$B$3=AG$6,"O","") | AI2: =+IF(Parametres!$B$3=AG$6,"U","") | AJ2: =+IF(Parametres!$B$3=AJ$6,"X","") | AK2: =+IF(Parametres!$B$3=AJ$6,"O","") | AL2: =+IF(Parametres!$B$3=AJ$6,"U","") | AM2: =+IF(Parametres!$B$3=AM$6,"X","") | AN2: =+IF(Parametres!$B$3=AM$6,"O","") | AO2: =+IF(Parametres!$B$3=AM$6,"U","")
B3: YTD | F3: =+IF(VLOOKUP(F$6,Parametres!$K$3:$N$14,4,0)="X","X","") -> X | G3: =+IF(VLOOKUP(F$6,Parametres!$K$3:$N$14,4,0)="X","O","") -> O | H3: =+IF(VLOOKUP(F$6,Parametres!$K$3:$N$14,4,0)="X","U","") -> U | I3: =+IF(VLOOKUP(I$6,Parametres!$K$3:$N$14,4,0)="X","X","") -> X | J3: =+IF(VLOOKUP(I$6,Parametres!$K$3:$N$14,4,0)="X","O","") -> O | K3: =+IF(VLOOKUP(I$6,Parametres!$K$3:$N$14,4,0)="X","U","") -> U | L3: =+IF(VLOOKUP(L$6,Parametres!$K$3:$N$14,4,0)="X","X","") -> X | M3: =+IF(VLOOKUP(L$6,Parametres!$K$3:$N$14,4,0)="X","O","") -> O | N3: =+IF(VLOOKUP(L$6,Parametres!$K$3:$N$14,4,0)="X","U","") -> U | O3: =+IF(VLOOKUP(O$6,Parametres!$K$3:$N$14,4,0)="X","X","") | P3: =+IF(VLOOKUP(O$6,Parametres!$K$3:$N$14,4,0)="X","O","") | Q3: =+IF(VLOOKUP(O$6,Parametres!$K$3:$N$14,4,0)="X","U","") | R3: =+IF(VLOOKUP(R$6,Parametres!$K$3:$N$14,4,0)="X","X","") | S3: =+IF(VLOOKUP(R$6,Parametres!$K$3:$N$14,4,0)="X","O","") | T3: =+IF(VLOOKUP(R$6,Parametres!$K$3:$N$14,4,0)="X","U","") | U3: =+IF(VLOOKUP(U$6,Parametres!$K$3:$N$14,4,0)="X","X","") | V3: =+IF(VLOOKUP(U$6,Parametres!$K$3:$N$14,4,0)="X","O","") | W3: =+IF(VLOOKUP(U$6,Parametres!$K$3:$N$14,4,0)="X","U","") | X3: =+IF(VLOOKUP(X$6,Parametres!$K$3:$N$14,4,0)="X","X","") | Y3: =+IF(VLOOKUP(X$6,Parametres!$K$3:$N$14,4,0)="X","O","") | Z3: =+IF(VLOOKUP(X$6,Parametres!$K$3:$N$14,4,0)="X","U","") | AA3: =+IF(VLOOKUP(AA$6,Parametres!$K$3:$N$14,4,0)="X","X","") | AB3: =+IF(VLOOKUP(AA$6,Parametres!$K$3:$N$14,4,0)="X","O","") | AC3: =+IF(VLOOKUP(AA$6,Parametres!$K$3:$N$14,4,0)="X","U","") | AD3: =+IF(VLOOKUP(AD$6,Parametres!$K$3:$N$14,4,0)="X","X","") | AE3: =+IF(VLOOKUP(AD$6,Parametres!$K$3:$N$14,4,0)="X","O","") | AF3: =+IF(VLOOKUP(AD$6,Parametres!$K$3:$N$14,4,0)="X","U","") | AG3: =+IF(VLOOKUP(AG$6,Parametres!$K$3:$N$14,4,0)="X","X","") | AH3: =+IF(VLOOKUP(AG$6,Parametres!$K$3:$N$14,4,0)="X","O","") | AI3: =+IF(VLOOKUP(AG$6,Parametres!$K$3:$N$14,4,0)="X","U","") | AJ3: =+IF(VLOOKUP(AJ$6,Parametres!$K$3:$N$14,4,0)="X","X","") | AK3: =+IF(VLOOKUP(AJ$6,Parametres!$K$3:$N$14,4,0)="X","O","") | AL3: =+IF(VLOOKUP(AJ$6,Parametres!$K$3:$N$14,4,0)="X","U","") | AM3: =+IF(VLOOKUP(AM$6,Parametres!$K$3:$N$14,4,0)="X","X","") | AN3: =+IF(VLOOKUP(AM$6,Parametres!$K$3:$N$14,4,0)="X","O","") | AO3: =+IF(VLOOKUP(AM$6,Parametres!$K$3:$N$14,4,0)="X","U","")
B4: Budget 2021 | C4: Véhicules neufs
B6: Mois | C6: 2021 | F6: Janvier | I6: Février | L6: Mars | O6: Avril | R6: Mai | U6: Juin | X6: Juillet | AA6: Août | AD6: Septembre | AG6: Octobre | AJ6: Novembre | AM6: Décembre
C7: UNITE | D7: $P/UNITE | E7: $PROFITS | F7: UNITE | G7: $P/UNITE | H7: $PROFITS | I7: UNITE | J7: $P/UNITE | K7: $PROFITS | L7: UNITE | M7: $P/UNITE | N7: $PROFITS | O7: UNITE | P7: $P/UNITE | Q7: $PROFITS | R7: UNITE | S7: $P/UNITE | T7: $PROFITS | U7: UNITE | V7: $P/UNITE | W7: $PROFITS | X7: UNITE | Y7: $P/UNITE | Z7: $PROFITS | AA7: UNITE | AB7: $P/UNITE | AC7: $PROFITS | AD7: UNITE | AE7: $P/UNITE | AF7: $PROFITS | AG7: UNITE | AH7: $P/UNITE | AI7: $PROFITS | AJ7: UNITE | AK7: $P/UNITE | AL7: $PROFITS | AM7: UNITE | AN7: $P/UNITE | AO7: $PROFITS
A8: =+$C$4&B8 -> Véhicules neufsVentes nettes | B8: Ventes nettes | E8: =+SUM(H8,K8,N8,Q8,T8,W8,Z8,AC8,AF8,AI8,AL8,AO8) -> 9553310.1 | H8: ='[5]véh neufs'!E7+'[5]véh neufs'!E23+'[5]véh neufs'!E38+H27 -> 1882577.9 | K8: ='[5]véh neufs'!$F$7 -> 446219.11 | N8: ='[5]véh neufs'!$G$7 -> 678330.08 | Q8: ='[5]véh neufs'!$H$7 -> 751340.66 | T8: ='[5]véh neufs'!$I$7 -> 981796.55 | W8: ='[5]véh neufs'!$J$7 -> 691716.4 | Z8: ='[5]véh neufs'!$K$7 -> 688676.89 | AC8: ='[5]véh neufs'!$L$7 -> 729220.97 | AF8: ='[5]véh neufs'!$M$7 -> 799077.54 | AI8: ='[5]véh neufs'!$N$7 -> 991144.07 | AL8: ='[5]véh neufs'!$O$7 -> 576007.02 | AO8: ='[5]véh neufs'!$P$7 -> 337202.89
