Workbook
Name _Dates_Conc: [1]Dealers!$BF$37:$KA$63
Name _scen: '[1]Scen & Sens'!$E$26
Name _scen1: '[1]Scen & Sens'!$E$27
Name _scen2: '[1]Scen & Sens'!$E$28
Name _SCenarios: '[1]Scen & Sens'!$J$26:$O$26
Name _Sens1: '[1]Scen & Sens'!$F$9
Name _Sens2: '[1]Scen & Sens'!$F$10
Name _sensRes1: '[1]Scen & Sens'!$E$15
Name _sensRes2: '[1]Scen & Sens'!$E$16
Name _sensRes3: '[1]Scen & Sens'!$E$17
Name _sensRes4: '[1]Scen & Sens'!$E$18
Name _sensRes5: '[1]Scen & Sens'!$E$19
Name _sensRes6: '[1]Scen & Sens'!$E$20
Name _sensRes7: '[1]Scen & Sens'!$E$21
Name DateRange: [1]Volkswagen!$BF$6:$DY$6
Name Monetary_Unit: [1]Parameters!$B$15
Name Months: [1]Parameters!$E$9:$E$20
Name Rng_Dealers_Names: [1]!Tbl_Dealers[Dealer Name]
Name Rng_Dlr_Dates: [1]!Tbl_V_Dlr_Dates[Date]
Name Titre: [1]Front!$A$9

Sheet Paramètre
B3: VOLKS QUARTER | C3: Volks T3 2022
B6: BUDGET | F6: BUDGET RÉVISÉ | J6: ACTUAL | N6: LAST YEAR
B7: Ventes | C7: Profits bruts | D7: BAIIA | E7: EBIT | F7: Ventes | G7: Profits bruts | H7: BAIIA | I7: EBIT | J7: Ventes | K7: Profits bruts | L7: BAIIA | M7: EBIT | N7: Ventes | O7: Profits bruts | P7: BAIIA | Q7: EBIT
A8: CTRL | B8: =+B9-B10 -> #REF! | C8: =+C9-C10 -> #REF! | D8: =+D9-D10 -> #REF! | E8: =+E9-E10 -> #REF! | F8: =+F9-F10 -> #REF! | G8: =+G9-G10 -> #REF! | H8: =+H9-H10 -> #REF! | I8: =+I9-I10 -> #REF! | ... Q8: =+Q9-Q10 -> #REF!
A9: CONSO | B9: =+Conso!$Z$405 -> 15410876 | C9: =+Conso!$Z$406 -> 1937855.6 | D9: =+Conso!$Z$482 -> 599108.28 | E9: =+Conso!$Z$497 -> 575436.8 | F9: =+Conso!$AC$405 -> 15410876 | G9: =+Conso!$AC$406 -> 1937855.6 | H9: =+Conso!$AC$482 -> 599108.28 | I9: =+Conso!$AC$497 -> 575436.8 | J9: =+Conso!$AF$405 -> 16244538 | K9: =+Conso!$AF$406 -> 2131721.5 | L9: =+Conso!$AF$482 -> 790555.34 | M9: =+Conso!$AF$497 -> 776331.47 | N9: =+Conso!$AL$405 -> 16217057 | O9: =+Conso!$AL$406 -> 1882405.7 | P9: =+Conso!$AL$482 -> 621516.25 | Q9: =+Conso!$AL$497 -> 605825.37
A10: TOTAL | B10: =+SUM(B11:B13) -> #REF! | C10: =+SUM(C11:C13) -> #REF! | D10: =+SUM(D11:D13) -> #REF! | E10: =+SUM(E11:E13) -> #REF! | F10: =+SUM(F11:F13) -> #REF! | G10: =+SUM(G11:G13) -> #REF! | H10: =+SUM(H11:H13) -> #REF! | I10: =+SUM(I11:I13) -> #REF! | ... Q10: =+SUM(Q11:Q13) -> #REF!
A11: AUDI 1 | B11: =+#REF! -> #REF! | C11: =+#REF! -> #REF! | D11: =+#REF! -> #REF! | E11: =+#REF! -> #REF! | F11: =+#REF! -> #REF! | G11: =+#REF! -> #REF! | H11: =+#REF! -> #REF! | I11: =+#REF! -> #REF! | ... Q11: =+#REF! -> #REF!
A12: AUDI 2 | B12: =+#REF! -> #REF! | C12: =+#REF! -> #REF! | D12: =+#REF! -> #REF! | E12: =+#REF! -> #REF! | F12: =+#REF! -> #REF! | G12: =+#REF! -> #REF! | H12: =+#REF! -> #REF! | I12: =+#REF! -> #REF! | ... Q12: =+#REF! -> #REF!
A13: AUDI 3 | B13: =+#REF! -> #REF! | C13: =+#REF! -> #REF! | D13: =+#REF! -> #REF! | E13: =+#REF! -> #REF! | F13: =+#REF! -> #REF! | G13: =+#REF! -> #REF! | H13: =+#REF! -> #REF! | I13: =+#REF! -> #REF! | ... Q13: =+#REF! -> #REF!

Sheet Conso
C1: Conso | K1: Véhicules neufs | S1: =CONCATENATE("Réalisé"," ",Paramètre!$C$2," ",Paramètre!$C$3) -> Réalisé Volks T3 2022 | V1: BUDGET | W1: RÉVISÉ | X1: ACTUAL | Y1: LY
D2: X | E2: O | F2: U | G2: X | H2: O | I2: U
D3: BUDGET ORIGINAL | G3: BUDGET REVISE | J3: RÉALISATION | M3: ÉCART réel / révisé | O3: ANNÉE PRÉCÉDENTE | R3: ÉCART réel / original
D4: UNITE | E4: $P/UNITÉ | F4: $PROFITS | G4: UNITE | H4: $P/UNITÉ | I4: $PROFITS | J4: UNITE | K4: $P/UNITE | L4: $PROFITS | M4: UNITÉ | N4: $PROFITS | O4: UNITE | P4: $P/UNITE | Q4: $PROFITS | R4: UNITE | S4: $PROFITS | V4: =+SUM(V5:V398) -> 0 | W4: =+SUM(W5:W398) -> 0 | X4: =+SUM(X5:X398) -> 0 | Y4: =+SUM(Y5:Y398) -> 0
A5: =+B5&C5 -> Véhicules neufsVentes nettes | B5: =+$K$1 -> Véhicules neufs | C5: Ventes nettes | F5: =+SUM(START:END!F5) -> 9485067.2 | I5: =+SUM(START:END!I5) -> 9485067.2 | L5: =+SUM(START:END!L5) -> 8779737.5 | Q5: =+SUM(START:END!Q5) -> 9633112.6
A6: =+B6&C6 -> Véhicules neufsAutos détail | B6: =+$K$1 -> Véhicules neufs | C6: Autos détail | D6: =+SUM(START:END!D6) -> 48.375904 | E6: =IF(D6=0,0,F6/D6) -> 1450.6298 | F6: =+SUM(START:END!F6) -> 70175.526 | G6: =+SUM(START:END!G6) -> 48.375904 | H6: =IF(G6=0,0,I6/G6) -> 1450.6298 | I6: =+SUM(START:END!I6) -> 70175.526 | J6: =+SUM(START:END!J6) -> 50 | K6: =IF(J6=0,0,L6/J6) -> 2395.0896 | L6: =+SUM(START:END!L6) -> 119754.48 | M6: =J6-G6 -> 1.6240964 | N6: =L6-I6 -> 49578.954 | O6: =+SUM(START:END!O6) -> 83 | P6: =IF(O6=0,0,Q6/O6) -> 1209.0878 | Q6: =+SUM(START:END!Q6) -> 100354.29 | R6: =J6-O6 -> -33 | S6: =L6-Q6 -> 19400.19
A7: =+B7&C7 -> Véhicules neufsCamions détail | B7: =+$K$1 -> Véhicules neufs | C7: Camions détail | D7: =+SUM(START:END!D7) -> 167.01205 | E7: =IF(D7=0,0,F7/D7) -> 2081.8276 | F7: =+SUM(START:END!F7) -> 347690.29 | G7: =+SUM(START:END!G7) -> 167.01205 | H7: =IF(G7=0,0,I7/G7) -> 2081.8276 | I7: =+SUM(START:END!I7) -> 347690.29 | J7: =+SUM(START:END!J7) -> 120 | K7: =IF(J7=0,0,L7/J7) -> 2998.4707 | L7: =+SUM(START:END!L7) -> 359816.49 | M7: =J7-G7 -> -47.012048 | N7: =L7-I7 -> 12126.201 | O7: =+SUM(START:END!O7) -> 125 | P7: =IF(O7=0,0,Q7/O7) -> 2271.0883 | Q7: =+SUM(START:END!Q7) -> 283886.04 | R7: =J7-O7 -> -5 | S7: =L7-Q7 -> 75930.45
A8: =+B8&C8 -> Véhicules neufsSprinter | B8: =+$K$1 -> Véhicules neufs | C8: Sprinter | D8: =+SUM(START:END!D8) -> 0 | E8: =IF(D8=0,0,F8/D8) -> 0 | F8: =+SUM(START:END!F8) -> 0 | G8: =+SUM(START:END!G8) -> 0 | H8: =IF(G8=0,0,I8/G8) -> 0 | I8: =+SUM(START:END!I8) -> 0 | J8: =+SUM(START:END!J8) -> 0 | K8: =IF(J8=0,0,L8/J8) -> 0 | L8: =+SUM(START:END!L8) -> 0 | M8: =J8-G8 -> 0 | N8: =L8-I8 -> 0 | O8: =+SUM(START:END!O8) -> 0 | P8: =IF(O8=0,0,Q8/O8) -> 0 | Q8: =+SUM(START:END!Q8) -> 0 | R8: =J8-O8 -> 0 | S8: =L8-Q8 -> 0
A9: =+B9&C9 -> Véhicules neufsMoto détail | B9: =+$K$1 -> Véhicules neufs | C9: Moto détail | D9: =+SUM(START:END!D9) -> 0 | E9: =IF(D9=0,0,F9/D9) -> 0 | F9: =+SUM(START:END!F9) -> 0 | G9: =+SUM(START:END!G9) -> 0 | H9: =IF(G9=0,0,I9/G9) -> 0 | I9: =+SUM(START:END!I9) -> 0 | J9: =+SUM(START:END!J9) -> 0 | K9: =IF(J9=0,0,L9/J9) -> 0 | L9: =+SUM(START:END!L9) -> 0 | M9: =J9-G9 -> 0 | N9: =L9-I9 -> 0 | O9: =+SUM(START:END!O9) -> 0 | P9: =IF(O9=0,0,Q9/O9) -> 0 | Q9: =+SUM(START:END!Q9) -> 0 | R9: =J9-O9 -> 0 | S9: =L9-Q9 -> 0
A10: =+B10&C10 -> Véhicules neufs[...] | B10: =+$K$1 -> Véhicules neufs | C10: [...] | D10: =+SUM(START:END!D10) -> 0 | E10: =IF(D10=0,0,F10/D10) -> 0 | F10: =+SUM(START:END!F10) -> 0 | G10: =+SUM(START:END!G10) -> 0 | H10: =IF(G10=0,0,I10/G10) -> 0 | I10: =+SUM(START:END!I10) -> 0 | J10: =+SUM(START:END!J10) -> 0 | K10: =IF(J10=0,0,L10/J10) -> 0 | L10: =+SUM(START:END!L10) -> 0 | M10: =J10-G10 -> 0 | N10: =L10-I10 -> 0 | O10: =+SUM(START:END!O10) -> 0 | P10: =IF(O10=0,0,Q10/O10) -> 0 | Q10: =+SUM(START:END!Q10) -> 0 | R10: =J10-O10 -> 0 | S10: =L10-Q10 -> 0
A11: =+B11&C11 -> Véhicules neufs[...] | B11: =+$K$1 -> Véhicules neufs | C11: [...] | D11: =+SUM(START:END!D11) -> 0 | E11: =IF(D11=0,0,F11/D11) -> 0 | F11: =+SUM(START:END!F11) -> 0 | G11: =+SUM(START:END!G11) -> 0 | H11: =IF(G11=0,0,I11/G11) -> 0 | I11: =+SUM(START:END!I11) -> 0 | J11: =+SUM(START:END!J11) -> 0 | K11: =IF(J11=0,0,L11/J11) -> 0 | L11: =+SUM(START:END!L11) -> 0 | M11: =J11-G11 -> 0 | N11: =L11-I11 -> 0 | O11: =+SUM(START:END!O11) -> 0 | P11: =IF(O11=0,0,Q11/O11) -> 0 | Q11: =+SUM(START:END!Q11) -> 0 | R11: =J11-O11 -> 0 | S11: =L11-Q11 -> 0
A12: =+B12&C12 -> Véhicules neufs[...] | B12: =+$K$1 -> Véhicules neufs | C12: [...] | D12: =+SUM(START:END!D12) -> 0 | E12: =IF(D12=0,0,F12/D12) -> 0 | F12: =+SUM(START:END!F12) -> 0 | G12: =+SUM(START:END!G12) -> 0 | H12: =IF(G12=0,0,I12/G12) -> 0 | I12: =+SUM(START:END!I12) -> 0 | J12: =+SUM(START:END!J12) -> 0 | K12: =IF(J12=0,0,L12/J12) -> 0 | L12: =+SUM(START:END!L12) -> 0 | M12: =J12-G12 -> 0 | N12: =L12-I12 -> 0 | O12: =+SUM(START:END!O12) -> 0 | P12: =IF(O12=0,0,Q12/O12) -> 0 | Q12: =+SUM(START:END!Q12) -> 0 | R12: =J12-O12 -> 0 | S12: =L12-Q12 -> 0
A13: =+B13&C13 -> Véhicules neufsTotal Neufs | B13: =+$K$1 -> Véhicules neufs | C13: Total Neufs | D13: =+SUM(D6:D12) -> 215.38795 | E13: =IF(D13<=0,0,F13/D13) -> 1940.0612 | F13: =+SUM(F6:F12) -> 417865.81 | G13: =+SUM(G6:G12) -> 215.38795 | H13: =IF(G13<=0,0,I13/G13) -> 1940.0612 | I13: =+SUM(I6:I12) -> 417865.81 | J13: =+SUM(J6:J12) -> 170 | K13: =IF(J13<=0,0,L13/J13) -> 2821.0057 | L13: =+SUM(L6:L12) -> 479570.97 | M13: =+SUM(M6:M12) -> -45.387952 | N13: =+SUM(N6:N12) -> 61705.155 | O13: =+SUM(O6:O12) -> 208 | P13: =IF(O13<=0,0,Q13/O13) -> 1847.3093 | Q13: =+SUM(Q6:Q12) -> 384240.33 | R13: =+SUM(R6:R12) -> -38 | S13: =+SUM(S6:S12) -> 95330.64 | V13: =+SUM(START:END!D13)-D13 -> 0 | W13: =+SUM(START:END!G13)-G13 -> 0 | X13: =+SUM(START:END!J13)-J13 -> 0 | Y13: =+SUM(START:END!O13)-O13 -> 0
A14: =+B14&C14 -> Véhicules neufs | B14: =+$K$1 -> Véhicules neufs | M14: =IF(G13=0,0,M13/G13) -> -0.21072651 | N14: =IF(I13=0,0,N13/I13) -> 0.14766739 | R14: =R13/O13 -> -0.18269231 | S14: =IF(Q13=0,0,(S13/Q13)) -> 0.2481016
A15: =+B15&C15 -> Véhicules neufsEx-Démos et courtoisies | B15: =+$K$1 -> Véhicules neufs | C15: Ex-Démos et courtoisies | D15: =+SUM(START:END!D15) -> 20.156627 | E15: =IF(D15=0,0,F15/D15) -> 1386.1016 | F15: =+SUM(START:END!F15) -> 27939.133 | G15: =+SUM(START:END!G15) -> 20.156627 | H15: =IF(G15=0,0,I15/G15) -> 1386.1016 | I15: =+SUM(START:END!I15) -> 27939.133 | J15: =+SUM(START:END!J15) -> 6 | K15: =IF(J15=0,0,L15/J15) -> 3041.8483 | L15: =+SUM(START:END!L15) -> 18251.09 | M15: =J15-G15 -> -14.156627 | N15: =L15-I15 -> -9688.0426 | O15: =+SUM(START:END!O15) -> 27 | P15: =IF(O15=0,0,Q15/O15) -> 1456.8074 | Q15: =+SUM(START:END!Q15) -> 39333.8 | R15: =J15-O15 -> -21 | S15: =L15-Q15 -> -21082.71 | V15: =+SUM(START:END!D15)-D15 -> 0 | W15: =+SUM(START:END!G15)-G15 -> 0 | X15: =+SUM(START:END!J15)-J15 -> 0 | Y15: =+SUM(START:END!O15)-O15 -> 0
A16: =+B16&C16 -> Véhicules neufs | B16: =+$K$1 -> Véhicules neufs
A17: =+B17&C17 -> Véhicules neufsFlottes | B17: =+$K$1 -> Véhicules neufs | C17: Flottes | D17: =+SUM(START:END!D17) -> 3.6257901 | E17: =IF(D17=0,0,F17/D17) -> 1938.8732 | F17: =+SUM(START:END!F17) -> 7029.9472 | G17: =+SUM(START:END!G17) -> 3.6257901 | H17: =IF(G17=0,0,I17/G17) -> 1938.8732 | I17: =+SUM(START:END!I17) -> 7029.9472 | J17: =+SUM(START:END!J17) -> 9 | K17: =IF(J17=0,0,L17/J17) -> 2185.0778 | L17: =+SUM(START:END!L17) -> 19665.7 | M17: =J17-G17 -> 5.3742099 | N17: =L17-I17 -> 12635.753 | O17: =+SUM(START:END!O17) -> 1 | P17: =IF(O17=0,0,Q17/O17) -> 707.9 | Q17: =+SUM(START:END!Q17) -> 707.9 | R17: =J17-O17 -> 8 | S17: =L17-Q17 -> 18957.8 | V17: =+SUM(START:END!D17)-D17 -> 0 | W17: =+SUM(START:END!G17)-G17 -> 0 | X17: =+SUM(START:END!J17)-J17 -> 0 | Y17: =+SUM(START:END!O17)-O17 -> 0
A18: =+B18&C18 -> Véhicules neufs | B18: =+$K$1 -> Véhicules neufs
A19: =+B19&C19 -> Véhicules neufsRachat bail | B19: =+$K$1 -> Véhicules neufs | C19: Rachat bail | F19: =+SUM(START:END!F19) -> 16832.078 | I19: =+SUM(START:END!I19) -> 16832.078 | L19: =+SUM(START:END!L19) -> 47656.29 | N19: =L19-I19 -> 30824.212 | Q19: =+SUM(START:END!Q19) -> 19061.91 | R19: =O19-K19 -> 0 | S19: =L19-Q19 -> 28594.38
A20: =+B20&C20 -> Véhicules neufs | B20: =+$K$1 -> Véhicules neufs
A21: =+B21&C21 -> Véhicules neufsRev. Finances | B21: =+$K$1 -> Véhicules neufs | C21: Rev. Finances | D21: 0 | E21: =IF(D21=0,0,F21/D21) -> 0 | F21: =+SUM(START:END!F21) -> 7048.3801 | G21: 0 | H21: =IF(G21=0,0,I21/G21) -> 0 | I21: =+SUM(START:END!I21) -> 7048.3801 | K21: =IF(J13=0,0,L21/(J13+J15)) -> 194.34903 | L21: =+SUM(START:END!L21) -> 34205.43 | N21: =L21-I21 -> 27157.05 | P21: =IF(O13=0,0,Q21/(O13+O15)) -> 7.2280426 | Q21: =+SUM(START:END!Q21) -> 1698.59 | R21: =O21-K21 -> -194.34903 | S21: =L21-Q21 -> 32506.84
A22: =+B22&C22 -> Véhicules neufsRev. Protections | B22: =+$K$1 -> Véhicules neufs | C22: Rev. Protections | D22: 0 | E22: =IF(D22=0,0,F22/D22) -> 0 | F22: =+SUM(START:END!F22) -> 188499.12 | G22: 0 | H22: =IF(G22=0,0,I22/G22) -> 0 | I22: =+SUM(START:END!I22) -> 188499.12 | K22: =IF(J13=0,0,L22/(J13+J15)) -> 896.49438 | L22: =+SUM(START:END!L22) -> 157783.01 | N22: =L22-I22 -> -30716.106 | P22: =IF(O13=0,0,Q22/(O13+O15)) -> 864.27902 | Q22: =+SUM(START:END!Q22) -> 203105.57 | R22: =O22-K22 -> -896.49438 | S22: =L22-Q22 -> -45322.56
A23: =+B23&C23 -> Véhicules neufsRev. Autres | B23: =+$K$1 -> Véhicules neufs | C23: Rev. Autres | D23: 0 | E23: =IF(D23=0,0,F23/D23) -> 0 | F23: =+SUM(START:END!F23) -> 4665.3959 | G23: 0 | H23: =IF(G23=0,0,I23/G23) -> 0 | I23: =+SUM(START:END!I23) -> 4665.3959 | K23: =IF(J13=0,0,L23/(J13+J15)) -> 24.29125 | L23: =+SUM(START:END!L23) -> 4275.26 | N23: =L23-I23 -> -390.13594 | P23: =IF(O13=0,0,Q23/(O13+O15)) -> 20.335277 | Q23: =+SUM(START:END!Q23) -> 4778.79 | R23: =O23-K23 -> -24.29125 | S23: =L23-Q23 -> -503.53
A24: =+B24&C24 -> Véhicules neufsTotal F&I | B24: =+$K$1 -> Véhicules neufs | C24: Total F&I | D24: =+D15+D13 -> 235.54458 | E24: =IF(D24<=0,0,F24/D24) -> 850 | F24: =F21+F22+F23 -> 200212.89 | G24: =+G15+G13 -> 235.54458 | H24: =IF(G24<=0,0,I24/G24) -> 850 | I24: =I21+I22+I23 -> 200212.89 | J24: =+J15+J13 -> 176 | K24: =IF(J24<=0,0,L24/J24) -> 1115.1347 | L24: =L21+L22+L23 -> 196263.7 | M24: =J24-G24 -> -59.544578 | N24: =L24-I24 -> -3949.1916 | O24: =+O15+O13 -> 235 | P24: =IF(O24<=0,0,Q24/O24) -> 891.84234 | Q24: =Q21+Q22+Q23 -> 209582.95 | S24: =L24-Q24 -> -13319.25 | V24: =+SUM(START:END!D24)-D24 -> 0 | W24: =+SUM(START:END!G24)-G24 -> 0 | X24: =+SUM(START:END!J24)-J24 -> 0 | Y24: =+SUM(START:END!O24)-O24 -> 0
A25: =+B25&C25 -> Véhicules neufs | B25: =+$K$1 -> Véhicules neufs | N25: =IF(N24=0,0,N24/I24) -> -0.019724961 | S25: =IF(Q24=0,0,(S24/Q24)) -> -0.06355121
A26: =+B26&C26 -> Véhicules neufs | B26: =+$K$1 -> Véhicules neufs
A27: =+B27&C27 -> Véhicules neufsTotal Dépt. Neufs | B27: =+$K$1 -> Véhicules neufs | C27: Total Dépt. Neufs | D27: =+D13+D15+D17 -> 239.17037 | E27: =IF(D27<=0,0,F27/D27) -> 2800.8481 | F27: =F13+F17+F24+F19+F15 -> 669879.86 | G27: =+G13+G15+G17 -> 239.17037 | H27: =IF(G27<=0,0,I27/G27) -> 2800.8481 | I27: =I13+I17+I24+I19+I15 -> 669879.86 | J27: =+J13+J15+J17 -> 185 | K27: =IF(J27<=0,0,L27/J27) -> 4115.7176 | L27: =L13+L17+L24+L19+L15 -> 761407.75 | M27: =J27-G27 -> -54.170368 | N27: =L27-I27 -> 91527.886 | O27: =+O13+O15+O17 -> 236 | P27: =IF(O27<=0,0,Q27/O27) -> 2766.6394 | Q27: =Q13+Q17+Q24+Q19+Q15 -> 652926.89 | R27: =J27-O27 -> -51 | S27: =L27-Q27 -> 108480.86 | V27: =+SUM(START:END!D27)-D27 -> 0 | W27: =+SUM(START:END!G27)-G27 -> 0 | X27: =+SUM(START:END!J27)-J27 -> 0 | Y27: =+SUM(START:END!O27)-O27 -> 0
A28: =+B28&C28 -> Véhicules neufs | B28: =+$K$1 -> Véhicules neufs | M28: =M27/G27 -> -0.22649281 | N28: =N27/I27 -> 0.13663328 | R28: =R27/O27 -> -0.21610169 | S28: =IF(Q27=0,0,S27/Q27) -> 0.16614549
A29: =+B29&C29 -> Véhicules neufs | B29: =+$K$1 -> Véhicules neufs
A30: =+B30&C30 -> Véhicules neufsDEPENSES | B30: =+$K$1 -> Véhicules neufs | C30: DEPENSES
A31: =+B31&C31 -> Véhicules neufsComm. vendeurs | B31: =+$K$1 -> Véhicules neufs | C31: Comm. vendeurs | E31: =F31/D$24 -> 611.17523 | F31: =+SUM(START:END!F31) -> 143959.01 | H31: =I31/G$24 -> 611.17523 | I31: =+SUM(START:END!I31) -> 143959.01 | J31: =L31/L13 -> 0.30107775 | K31: =IF(L31=0,0,L31/J$24) -> 820.38722 | L31: =+SUM(START:END!L31) -> 144388.15 | N31: =L31-I31 -> 429.13706 | P31: =IF(Q31=0,0,Q31/O$24) -> 603.03817 | Q31: =+SUM(START:END!Q31) -> 141713.97 | S31: =L31-Q31 -> 2674.18
A32: =+B32&C32 -> Véhicules neufsComm. F&I | B32: =+$K$1 -> Véhicules neufs | C32: Comm. F&I | E32: =F32/D$24 -> 255 | F32: =+SUM(START:END!F32) -> 60063.867 | H32: =I32/G$24 -> 255 | I32: =+SUM(START:END!I32) -> 60063.867 | J32: =L32/L24 -> 0.35298519 | K32: =IF(L32=0,0,L32/J$24) -> 393.62602 | L32: =+SUM(START:END!L32) -> 69278.18 | N32: =L32-I32 -> 9214.3125 | P32: =IF(Q32=0,0,Q32/O$24) -> 263.91732 | Q32: =+SUM(START:END!Q32) -> 62020.57 | S32: =L32-Q32 -> 7257.61
A33: =+B33&C33 -> Véhicules neufsFrais de livraison | B33: =+$K$1 -> Véhicules neufs | C33: Frais de livraison | E33: =F33/D$24 -> 167.8493 | F33: =+SUM(START:END!F33) -> 39535.993 | H33: =I33/G$24 -> 167.8493 | I33: =+SUM(START:END!I33) -> 39535.993 | K33: =IF(L33=0,0,L33/J$24) -> 47.600852 | L33: =+SUM(START:END!L33) -> 8377.75 | N33: =L33-I33 -> -31158.243 | P33: =IF(Q33=0,0,Q33/O$24) -> 157.34409 | Q33: =+SUM(START:END!Q33) -> 36975.86 | S33: =L33-Q33 -> -28598.11
A34: =+B34&C34 -> Véhicules neufsService gratuit 1 | B34: =+$K$1 -> Véhicules neufs | C34: Service gratuit 1 | E34: =F34/D$24 -> 7.3548076 | F34: =+SUM(START:END!F34) -> 1732.3851 | H34: =I34/G$24 -> 7.3548076 | I34: =+SUM(START:END!I34) -> 1732.3851 | K34: =IF(L34=0,0,L34/J$24) -> 1.2465341 | L34: =+SUM(START:END!L34) -> 219.39 | N34: =L34-I34 -> -1512.9951 | P34: =IF(Q34=0,0,Q34/O$24) -> 11.313191 | Q34: =+SUM(START:END!Q34) -> 2658.6 | S34: =L34-Q34 -> -2439.21
A35: =+B35&C35 -> Véhicules neufsEntretien stock | B35: =+$K$1 -> Véhicules neufs | C35: Entretien stock | E35: =F35/D$24 -> 17.733118 | F35: =+SUM(START:END!F35) -> 4176.9399 | H35: =I35/G$24 -> 17.733118 | I35: =+SUM(START:END!I35) -> 4176.9399 | K35: =IF(L35=0,0,L35/J$24) -> 98.528693 | L35: =+SUM(START:END!L35) -> 17341.05 | N35: =L35-I35 -> 13164.11 | P35: =IF(Q35=0,0,Q35/O$24) -> 18.307191 | Q35: =+SUM(START:END!Q35) -> 4302.19 | S35: =L35-Q35 -> 13038.86
A36: =+B36&C36 -> Véhicules neufsPublicité 1 | B36: =+$K$1 -> Véhicules neufs | C36: Publicité 1 | E36: =F36/D$24 -> 195.93765 | F36: =+SUM(START:END!F36) -> 46152.052 | H36: =I36/G$24 -> 195.93765 | I36: =+SUM(START:END!I36) -> 46152.052 | K36: =IF(L36=0,0,L36/J$24) -> 87.593295 | L36: =+SUM(START:END!L36) -> 15416.42 | N36: =L36-I36 -> -30735.632 | P36: =IF(Q36=0,0,Q36/O$24) -> 119.74332 | Q36: =+SUM(START:END!Q36) -> 28139.68 | S36: =L36-Q36 -> -12723.26
A37: =+B37&C37 -> Véhicules neufsIntérêt de gros | B37: =+$K$1 -> Véhicules neufs | C37: Intérêt de gros | E37: =F37/D$24 -> 98.977128 | F37: =+SUM(START:END!F37) -> 23313.526 | H37: =I37/G$24 -> 98.977128 | I37: =+SUM(START:END!I37) -> 23313.526 | K37: =IF(L37=0,0,L37/J$24) -> 57.844545 | L37: =+SUM(START:END!L37) -> 10180.64 | N37: =L37-I37 -> -13132.886 | P37: =IF(Q37=0,0,Q37/O$24) -> 151.65362 | Q37: =+SUM(START:END!Q37) -> 35638.6 | S37: =L37-Q37 -> -25457.96
A38: =+B38&C38 -> Véhicules neufs[...] | B38: =+$K$1 -> Véhicules neufs | C38: [...] | E38: =F38/D$24 -> 0 | F38: =+SUM(START:END!F38) -> 0 | H38: =I38/G$24 -> 0 | I38: =+SUM(START:END!I38) -> 0 | K38: =IF(L38=0,0,L38/J$24) -> 0 | L38: =+SUM(START:END!L38) -> 0 | N38: =L38-I38 -> 0 | P38: =IF(Q38=0,0,Q38/O$24) -> 0 | Q38: =+SUM(START:END!Q38) -> 0 | S38: =L38-Q38 -> 0
A39: =+B39&C39 -> Véhicules neufs[...] | B39: =+$K$1 -> Véhicules neufs | C39: [...] | E39: =F39/D$24 -> 0 | F39: =+SUM(START:END!F39) -> 0 | H39: =I39/G$24 -> 0 | I39: =+SUM(START:END!I39) -> 0 | K39: =IF(L39=0,0,L39/J$24) -> 0 | L39: =+SUM(START:END!L39) -> 0 | N39: =L39-I39 -> 0 | P39: =IF(Q39=0,0,Q39/O$24) -> 0 | Q39: =+SUM(START:END!Q39) -> 0 | S39: =L39-Q39 -> 0
A40: =+B40&C40 -> Véhicules neufs[...] | B40: =+$K$1 -> Véhicules neufs | C40: [...] | E40: =F40/D$24 -> 0 | F40: =+SUM(START:END!F40) -> 0 | H40: =I40/G$24 -> 0 | I40: =+SUM(START:END!I40) -> 0 | K40: =IF(L40=0,0,L40/J$24) -> 0 | L40: =+SUM(START:END!L40) -> 0 | N40: =L40-I40 -> 0 | P40: =IF(Q40=0,0,Q40/O$24) -> 0 | Q40: =+SUM(START:END!Q40) -> 0 | S40: =L40-Q40 -> 0
...

Sheet START

Sheet VW 2022-07
C1: Volks | K1: Véhicules neufs | S1: Réalisé, Juillet 2022
D2: X | E2: O | F2: U | G2: X | H2: O | I2: U | J2: NB | L2: $ | O2: NB | Q2: $ | V2: *** NE PAS EFFACER / Pour An Précédente ***
D3: BUDGET ORIGINAL | G3: BUDGET REVISE | J3: RÉALISATION | M3: ÉCART réel / révisé | O3: ANNÉE PRÉCÉDENTE | R3: ÉCART réel / original | V3: NEUF | W3: 0.45
D4: UNITE | E4: $P/UNITÉ | F4: $PROFITS | G4: UNITE | H4: $P/UNITÉ | I4: $PROFITS | J4: UNITE | K4: $P/UNITE | L4: $PROFITS | M4: UNITÉ | N4: $PROFITS | O4: UNITE | P4: $P/UNITE | Q4: $PROFITS | R4: UNITE | S4: $PROFITS | V4: USAGE | W4: 0.1
A5: Véhicules neufsVentes nettes | B5: Véhicules neufs | C5: Ventes nettes | F5: 3373350.3 | I5: 3373350.3 | L5: 2657067 | Q5: 2770249.7 | V5: SERVICE | W5: 0.225
A6: Véhicules neufsAutos détail | B6: Véhicules neufs | C6: Autos détail | D6: 17.204819 | E6: =IF(D6=0,0,F6/D6) -> 1450.6298 | F6: 24957.823 | G6: 17.204819 | H6: =IF(G6=0,0,I6/G6) -> 1450.6298 | I6: 24957.823 | J6: 13 | K6: =IF(J6=0,0,L6/J6) -> 2819.2123 | L6: 36649.76 | M6: =J6-G6 -> -4.2048193 | N6: =L6-I6 -> 11691.937 | O6: 24 | P6: =IF(O6=0,0,Q6/O6) -> 1259.8542 | Q6: 30236.5 | R6: =J6-O6 -> -11 | S6: =L6-Q6 -> 6413.26 | V6: CARROSSERIE | W6: 0.025
A7: Véhicules neufsCamions détail | B7: Véhicules neufs | C7: Camions détail | D7: 59.39759 | E7: =IF(D7=0,0,F7/D7) -> 2081.8276 | F7: 123655.54 | G7: 59.39759 | H7: =IF(G7=0,0,I7/G7) -> 2081.8276 | I7: 123655.54 | J7: 37 | K7: =IF(J7=0,0,L7/J7) -> 3278.5565 | L7: 121306.59 | M7: =J7-G7 -> -22.39759 | N7: =L7-I7 -> -2348.9522 | O7: 37 | P7: =IF(O7=0,0,Q7/O7) -> 2440.6305 | Q7: 90303.33 | R7: =J7-O7 -> 0 | S7: =L7-Q7 -> 31003.26 | V7: PIECES | W7: 0.2
A8: Véhicules neufsSprinter | B8: Véhicules neufs | C8: Sprinter | D8: 0 | E8: =IF(D8=0,0,F8/D8) -> 0 | F8: 0 | G8: 0 | H8: =IF(G8=0,0,I8/G8) -> 0 | I8: 0 | J8: 0 | K8: =IF(J8=0,0,L8/J8) -> 0 | L8: 0 | M8: =J8-G8 -> 0 | N8: =L8-I8 -> 0 | O8: 0 | P8: =IF(O8=0,0,Q8/O8) -> 0 | Q8: 0 | R8: =J8-O8 -> 0 | S8: =L8-Q8 -> 0 | W8: =SUM(W3:W7) -> 1
A9: Véhicules neufsMoto détail | B9: Véhicules neufs | C9: Moto détail | D9: 0 | E9: =IF(D9=0,0,F9/D9) -> 0 | F9: 0 | G9: 0 | H9: =IF(G9=0,0,I9/G9) -> 0 | I9: 0 | J9: 0 | K9: =IF(J9=0,0,L9/J9) -> 0 | L9: 0 | M9: =J9-G9 -> 0 | N9: =L9-I9 -> 0 | O9: 0 | P9: =IF(O9=0,0,Q9/O9) -> 0 | Q9: 0 | R9: =J9-O9 -> 0 | S9: =L9-Q9 -> 0
A10: Véhicules neufs[...] | B10: Véhicules neufs | C10: [...] | D10: 0 | E10: =IF(D10=0,0,F10/D10) -> 0 | F10: 0 | G10: 0 | H10: =IF(G10=0,0,I10/G10) -> 0 | I10: 0 | J10: 0 | K10: =IF(J10=0,0,L10/J10) -> 0 | L10: 0 | M10: =J10-G10 -> 0 | N10: =L10-I10 -> 0 | O10: 0 | P10: =IF(O10=0,0,Q10/O10) -> 0 | Q10: 0 | R10: =J10-O10 -> 0 | S10: =L10-Q10 -> 0
A11: Véhicules neufs[...] | B11: Véhicules neufs | C11: [...] | D11: 0 | E11: =IF(D11=0,0,F11/D11) -> 0 | F11: 0 | G11: 0 | H11: =IF(G11=0,0,I11/G11) -> 0 | I11: 0 | J11: 0 | K11: =IF(J11=0,0,L11/J11) -> 0 | L11: 0 | M11: =J11-G11 -> 0 | N11: =L11-I11 -> 0 | O11: 0 | P11: =IF(O11=0,0,Q11/O11) -> 0 | Q11: 0 | R11: =J11-O11 -> 0 | S11: =L11-Q11 -> 0
A12: Véhicules neufs[...] | B12: Véhicules neufs | C12: [...] | D12: 0 | E12: =IF(D12=0,0,F12/D12) -> 0 | F12: 0 | G12: 0 | H12: =IF(G12=0,0,I12/G12) -> 0 | I12: 0 | J12: 0 | K12: =IF(J12=0,0,L12/J12) -> 0 | L12: 0 | M12: =J12-G12 -> 0 | N12: =L12-I12 -> 0 | O12: 0 | P12: =IF(O12=0,0,Q12/O12) -> 0 | Q12: 0 | R12: =J12-O12 -> 0 | S12: =L12-Q12 -> 0
A13: Véhicules neufsTotal Neufs | B13: Véhicules neufs | C13: Total Neufs | D13: =+SUM(D6:D12) -> 76.60241 | E13: =IF(D13<=0,0,F13/D13) -> 1940.0612 | F13: =+SUM(F6:F12) -> 148613.37 | G13: =+SUM(G6:G12) -> 76.60241 | H13: =IF(G13<=0,0,I13/G13) -> 1940.0612 | I13: =+SUM(I6:I12) -> 148613.37 | J13: =+SUM(J6:J12) -> 50 | K13: =IF(J13<=0,0,L13/J13) -> 3159.127 | L13: =+SUM(L6:L12) -> 157956.35 | M13: =+SUM(M6:M12) -> -26.60241 | N13: =+SUM(N6:N12) -> 9342.9849 | O13: =+SUM(O6:O12) -> 61 | P13: =IF(O13<=0,0,Q13/O13) -> 1976.0628 | Q13: =+SUM(Q6:Q12) -> 120539.83 | R13: =+SUM(R6:R12) -> -11 | S13: =+SUM(S6:S12) -> 37416.52
A14: Véhicules neufs | B14: Véhicules neufs | R14: =R13/O13 -> -0.18032787 | S14: =IF(Q13=0,0,(S13/Q13)) -> 0.31040794
A15: Véhicules neufsEx-Démos et courtoisies | B15: Véhicules neufs | C15: Ex-Démos et courtoisies | D15: 7.1686747 | E15: =IF(D15=0,0,F15/D15) -> 1386.1016 | F15: 9936.5116 | G15: 7.1686747 | H15: =IF(G15=0,0,I15/G15) -> 1386.1016 | I15: 9936.5116 | J15: 3 | K15: =IF(J15=0,0,L15/J15) -> 2992.6 | L15: 8977.8 | M15: =J15-G15 -> -4.1686747 | N15: =L15-I15 -> -958.7116 | O15: 6 | P15: =IF(O15=0,0,Q15/O15) -> 1260.9683 | Q15: 7565.81 | R15: =J15-O15 -> -3 | S15: =L15-Q15 -> 1411.99
A16: Véhicules neufs | B16: Véhicules neufs
A17: Véhicules neufsFlottes | B17: Véhicules neufs | C17: Flottes | D17: 1.289507 | E17: =IF(D17=0,0,F17/D17) -> 1938.8732 | F17: 2500.1904 | G17: 1.289507 | H17: =IF(G17=0,0,I17/G17) -> 1938.8732 | I17: 2500.1904 | J17: 2 | K17: =IF(J17=0,0,L17/J17) -> 4190.8 | L17: 8381.6 | M17: =J17-G17 -> 0.71049305 | N17: =L17-I17 -> 5881.4096 | O17: 0 | P17: =IF(O17=0,0,Q17/O17) -> 0 | Q17: -276 | R17: =J17-O17 -> 2 | S17: =L17-Q17 -> 8657.6
A18: Véhicules neufs | B18: Véhicules neufs
A19: Véhicules neufsRachat bail | B19: Véhicules neufs | C19: Rachat bail | D19: 0 | E19: =IF(D19=0,0,F19/D19) -> 0 | F19: 7013.3658 | G19: 0 | H19: =IF(G19=0,0,I19/G19) -> 0 | I19: 7013.3658 | L19: 13968.33 | N19: =L19-I19 -> 6954.9642 | Q19: 5617.12 | R19: =O19-K19 -> 0 | S19: =L19-Q19 -> 8351.21
A20: Véhicules neufs | B20: Véhicules neufs
A21: Véhicules neufsRev. Finances | B21: Véhicules neufs | C21: Rev. Finances | D21: 0 | E21: =IF(D21=0,0,F21/D21) -> 0 | F21: 2506.7461 | G21: 0 | H21: =IF(G21=0,0,I21/G21) -> 0 | I21: 2506.7461 | K21: =IF(J13=0,0,L21/(J13+J15)) -> 208.71698 | L21: 11062 | N21: =L21-I21 -> 8555.2539 | P21: =IF(O13=0,0,Q21/(O13+O15)) -> 1.4925373 | Q21: 100 | R21: =O21-K21 -> -208.71698 | S21: =L21-Q21 -> 10962
A22: Véhicules neufsRev. Protections | B22: Véhicules neufs | C22: Rev. Protections | D22: 0 | E22: =IF(D22=0,0,F22/D22) -> 0 | F22: 67039.434 | G22: 0 | H22: =IF(G22=0,0,I22/G22) -> 0 | I22: 67039.434 | K22: =IF(J13=0,0,L22/(J13+J15)) -> 1043.6472 | L22: 55313.3 | N22: =L22-I22 -> -11726.134 | P22: =IF(O13=0,0,Q22/(O13+O15)) -> 822.7094 | Q22: 55121.53 | R22: =O22-K22 -> -1043.6472 | S22: =L22-Q22 -> 191.77
A23: Véhicules neufsRev. Autres | B23: Véhicules neufs | C23: Rev. Autres | D23: 0 | E23: =IF(D23=0,0,F23/D23) -> 0 | F23: 1659.2412 | G23: 0 | H23: =IF(G23=0,0,I23/G23) -> 0 | I23: 1659.2412 | K23: =IF(J13=0,0,L23/(J13+J15)) -> 26.998868 | L23: 1430.94 | N23: =L23-I23 -> -228.30123 | P23: =IF(O13=0,0,Q23/(O13+O15)) -> 26.582985 | Q23: 1781.06 | R23: =O23-K23 -> -26.998868 | S23: =L23-Q23 -> -350.12
A24: Véhicules neufsTotal F&I | B24: Véhicules neufs | C24: Total F&I | D24: =+D15+D13 -> 83.771084 | E24: =IF(D24<=0,0,F24/D24) -> 850 | F24: =F21+F22+F23 -> 71205.422 | G24: =+G15+G13 -> 83.771084 | H24: =IF(G24<=0,0,I24/G24) -> 850 | I24: =I21+I22+I23 -> 71205.422 | J24: =+J15+J13 -> 53 | K24: =IF(J24<=0,0,L24/J24) -> 1279.363 | L24: =L21+L22+L23 -> 67806.24 | M24: =J24-G24 -> -30.771084 | N24: =L24-I24 -> -3399.1817 | O24: =+O15+O13 -> 67 | P24: =IF(O24<=0,0,Q24/O24) -> 850.78493 | Q24: =Q21+Q22+Q23 -> 57002.59 | S24: =L24-Q24 -> 10803.65
A25: Véhicules neufs | B25: Véhicules neufs | N25: =IF(N24=0,0,N24/I24) -> -0.047737681 | S25: =IF(Q24=0,0,(S24/Q24)) -> 0.18952911
A26: Véhicules neufs | B26: Véhicules neufs
A27: Véhicules neufsTotal Dépt. Neufs | B27: Véhicules neufs | C27: Total Dépt. Neufs | D27: =+D13+D15+D17 -> 85.060591 | E27: =IF(D27<=0,0,F27/D27) -> 2812.9225 | F27: =F13+F17+F24+F19+F15 -> 239268.85 | G27: =+G13+G15+G17 -> 85.060591 | H27: =IF(G27<=0,0,I27/G27) -> 2812.9225 | I27: =I13+I17+I24+I19+I15 -> 239268.85 | J27: =+J13+J15+J17 -> 55 | K27: =IF(J27<=0,0,L27/J27) -> 4674.3695 | L27: =L13+L17+L24+L19+L15 -> 257090.32 | M27: =J27-G27 -> -30.060591 | N27: =L27-I27 -> 17821.465 | O27: =+O13+O15+O17 -> 67 | P27: =IF(O27<=0,0,Q27/O27) -> 2842.5276 | Q27: =Q13+Q17+Q24+Q19+Q15 -> 190449.35 | R27: =J27-O27 -> -12 | S27: =L27-Q27 -> 66640.97
A28: Véhicules neufs | B28: Véhicules neufs | M28: =M27/G27 -> -0.3534021 | N28: =N27/I27 -> 0.074483014 | R28: =R27/O27 -> -0.17910448 | S28: =IF(Q27=0,0,S27/Q27) -> 0.3499144
A29: Véhicules neufs | B29: Véhicules neufs
A30: Véhicules neufsDEPENSES | B30: Véhicules neufs | C30: DEPENSES
A31: Véhicules neufsComm. vendeurs | B31: Véhicules neufs | C31: Comm. vendeurs | D31: =F31/(F15+F13+F17) -> 0.31276628 | E31: =F31/D$24 -> 601.29375 | F31: 50371.03 | G31: =I31/(I15+I13) -> 0.31769832 | H31: =I31/G$24 -> 601.29375 | I31: 50371.03 | J31: =L31/(L15+L13+L17) -> 0.32276575 | K31: =IF(L31=0,0,L31/J$24) -> 1067.6589 | L31: 56585.92 | N31: =L31-I31 -> 6214.8903 | P31: =IF(Q31=0,0,Q31/O$24) -> 569.64836 | Q31: 38166.44 | S31: =L31-Q31 -> 18419.48
A32: Véhicules neufsComm. F&I | B32: Véhicules neufs | C32: Comm. F&I | D32: =F32/F24 -> 0.3 | E32: =F32/D$24 -> 255 | F32: 21361.627 | G32: =I32/I24 -> 0.3 | H32: =I32/G$24 -> 255 | I32: 21361.627 | J32: =L32/L24 -> 0.33139561 | K32: =IF(L32=0,0,L32/J$24) -> 423.97528 | L32: 22470.69 | N32: =L32-I32 -> 1109.0635 | P32: =IF(Q32=0,0,Q32/O$24) -> 260.55 | Q32: 17456.85 | S32: =L32-Q32 -> 5013.84 | U32: =(L32+L112)/(L104+L24+L19) -> 0.26924386 | V32: <<- F&A total Neuf Usagé Rachat
A33: Véhicules neufsFrais de livraison | B33: Véhicules neufs | C33: Frais de livraison | E33: =F33/D$24 -> 167.8493 | F33: 14060.918 | H33: =I33/G$24 -> 167.8493 | I33: 14060.918 | K33: =IF(L33=0,0,L33/J$24) -> 145.86774 | L33: 7730.99 | N33: =L33-I33 -> -6329.9281 | P33: =IF(Q33=0,0,Q33/O$24) -> 252.36746 | Q33: 16908.62 | S33: =L33-Q33 -> -9177.63
A34: Véhicules neufsService gratuit 1 | B34: Véhicules neufs | C34: Service gratuit 1 | E34: =F34/D$24 -> 7.3548076 | F34: 616.12021 | H34: =I34/G$24 -> 7.3548076 | I34: 616.12021 | K34: =IF(L34=0,0,L34/J$24) -> 3.5922642 | L34: 190.39 | N34: =L34-I34 -> -425.73021 | P34: =IF(Q34=0,0,Q34/O$24) -> 6.6438806 | Q34: 445.14 | S34: =L34-Q34 -> -254.75
A35: Véhicules neufsEntretien stock | B35: Véhicules neufs | C35: Entretien stock | E35: =F35/D$24 -> 17.733118 | F35: 1485.5225 | H35: =I35/G$24 -> 17.733118 | I35: 1485.5225 | K35: =IF(L35=0,0,L35/J$24) -> 176.23962 | L35: 9340.7 | N35: =L35-I35 -> 7855.1775 | P35: =IF(Q35=0,0,Q35/O$24) -> 2.6119403 | Q35: 175 | S35: =L35-Q35 -> 9165.7 | U35: Pneus 3,168 + Accroch Jess 2,000
A36: Véhicules neufsPublicité 1 | B36: Véhicules neufs | C36: Publicité 1 | E36: =F36/D$24 -> 195.93765 | F36: 16413.91 | H36: =I36/G$24 -> 195.93765 | I36: 16413.91 | K36: =IF(L36=0,0,L36/J$24) -> 185.94774 | L36: 9855.23 | N36: =L36-I36 -> -6558.6796 | P36: =IF(Q36=0,0,Q36/O$24) -> 153.44896 | Q36: 10281.08 | S36: =L36-Q36 -> -425.85
A37: Véhicules neufsIntérêt de gros | B37: Véhicules neufs | C37: Intérêt de gros | E37: =F37/D$24 -> 86.224826 | F37: 7223.1472 | H37: =I37/G$24 -> 86.224826 | I37: 7223.1472 | K37: =IF(L37=0,0,L37/J$24) -> 21.345283 | L37: 1131.3 | N37: =L37-I37 -> -6091.8472 | P37: =IF(Q37=0,0,Q37/O$24) -> 159.04104 | Q37: 10655.75 | S37: =L37-Q37 -> -9524.45
A38: Véhicules neufs[...] | B38: Véhicules neufs | C38: [...] | E38: =F38/D$24 -> 0 | F38: 0 | H38: =I38/G$24 -> 0 | I38: 0 | K38: =IF(L38=0,0,L38/J$24) -> 0 | L38: 0 | N38: =L38-I38 -> 0 | P38: =IF(Q38=0,0,Q38/O$24) -> 0 | Q38: 0 | S38: =L38-Q38 -> 0
A39: Véhicules neufs[...] | B39: Véhicules neufs | C39: [...] | E39: =F39/D$24 -> 0 | F39: 0 | H39: =I39/G$24 -> 0 | I39: 0 | K39: =IF(L39=0,0,L39/J$24) -> 0 | L39: 0 | N39: =L39-I39 -> 0 | P39: =IF(Q39=0,0,Q39/O$24) -> 0 | Q39: 0 | S39: =L39-Q39 -> 0
A40: Véhicules neufs[...] | B40: Véhicules neufs | C40: [...] | E40: =F40/D$24 -> 0 | F40: 0 | H40: =I40/G$24 -> 0 | I40: 0 | K40: =IF(L40=0,0,L40/J$24) -> 0 | L40: 0 | N40: =L40-I40 -> 0 | P40: =IF(Q40=0,0,Q40/O$24) -> 0 | Q40: 0 | S40: =L40-Q40 -> 0
...

Sheet VW 2022-08
C1: Volks | K1: Véhicules neufs | S1: Réalisé, Août 2022
D2: X | E2: O | F2: U | G2: X | H2: O | I2: U | J2: NB | L2: $ | O2: NB | Q2: $ | V2: *** NE PAS EFFACER / Pour An Précédente ***
D3: BUDGET ORIGINAL | G3: BUDGET REVISE | J3: RÉALISATION | M3: ÉCART réel / révisé | O3: ANNÉE PRÉCÉDENTE | R3: ÉCART réel / original | V3: NEUF | W3: 0.45
D4: UNITE | E4: $P/UNITÉ | F4: $PROFITS | G4: UNITE | H4: $P/UNITÉ | I4: $PROFITS | J4: UNITE | K4: $P/UNITE | L4: $PROFITS | M4: UNITÉ | N4: $PROFITS | O4: UNITE | P4: $P/UNITE | Q4: $PROFITS | R4: UNITE | S4: $PROFITS | V4: USAGE | W4: 0.1
A5: Véhicules neufsVentes nettes | B5: Véhicules neufs | C5: Ventes nettes | F5: 3254290.8 | I5: 3254290.8 | L5: 3632125.1 | Q5: 3249436.4 | V5: SERVICE | W5: 0.225
A6: Véhicules neufsAutos détail | B6: Véhicules neufs | C6: Autos détail | D6: 16.59759 | E6: =IF(D6=0,0,F6/D6) -> 1450.6298 | F6: 24076.959 | G6: 16.59759 | H6: =IF(G6=0,0,I6/G6) -> 1450.6298 | I6: 24076.959 | J6: 21 | K6: =IF(J6=0,0,L6/J6) -> 2507.92 | L6: 52666.32 | M6: =J6-G6 -> 4.4024096 | N6: =L6-I6 -> 28589.361 | O6: 24 | P6: =IF(O6=0,0,Q6/O6) -> 1070.9171 | Q6: 25702.01 | R6: =J6-O6 -> -3 | S6: =L6-Q6 -> 26964.31 | V6: CARROSSERIE | W6: 0.025
A7: Véhicules neufsCamions détail | B7: Véhicules neufs | C7: Camions détail | D7: 57.301205 | E7: =IF(D7=0,0,F7/D7) -> 2081.8276 | F7: 119291.23 | G7: 57.301205 | H7: =IF(G7=0,0,I7/G7) -> 2081.8276 | I7: 119291.23 | J7: 50 | K7: =IF(J7=0,0,L7/J7) -> 3039.8858 | L7: 151994.29 | M7: =J7-G7 -> -7.3012048 | N7: =L7-I7 -> 32703.061 | O7: 39 | P7: =IF(O7=0,0,Q7/O7) -> 2067.4385 | Q7: 80630.1 | R7: =J7-O7 -> 11 | S7: =L7-Q7 -> 71364.19 | V7: PIECES | W7: 0.2
A8: Véhicules neufsSprinter | B8: Véhicules neufs | C8: Sprinter | D8: 0 | E8: =IF(D8=0,0,F8/D8) -> 0 | F8: 0 | G8: 0 | H8: =IF(G8=0,0,I8/G8) -> 0 | I8: 0 | J8: 0 | K8: =IF(J8=0,0,L8/J8) -> 0 | L8: 0 | M8: =J8-G8 -> 0 | N8: =L8-I8 -> 0 | O8: 0 | P8: =IF(O8=0,0,Q8/O8) -> 0 | Q8: 0 | R8: =J8-O8 -> 0 | S8: =L8-Q8 -> 0 | W8: =SUM(W3:W7) -> 1
A9: Véhicules neufsMoto détail | B9: Véhicules neufs | C9: Moto détail | D9: 0 | E9: =IF(D9=0,0,F9/D9) -> 0 | F9: 0 | G9: 0 | H9: =IF(G9=0,0,I9/G9) -> 0 | I9: 0 | J9: 0 | K9: =IF(J9=0,0,L9/J9) -> 0 | L9: 0 | M9: =J9-G9 -> 0 | N9: =L9-I9 -> 0 | O9: 0 | P9: =IF(O9=0,0,Q9/O9) -> 0 | Q9: 0 | R9: =J9-O9 -> 0 | S9: =L9-Q9 -> 0
A10: Véhicules neufs[...] | B10: Véhicules neufs | C10: [...] | D10: 0 | E10: =IF(D10=0,0,F10/D10) -> 0 | F10: 0 | G10: 0 | H10: =IF(G10=0,0,I10/G10) -> 0 | I10: 0 | J10: 0 | K10: =IF(J10=0,0,L10/J10) -> 0 | L10: 0 | M10: =J10-G10 -> 0 | N10: =L10-I10 -> 0 | O10: 0 | P10: =IF(O10=0,0,Q10/O10) -> 0 | Q10: 0 | R10: =J10-O10 -> 0 | S10: =L10-Q10 -> 0
A11: Véhicules neufs[...] | B11: Véhicules neufs | C11: [...] | D11: 0 | E11: =IF(D11=0,0,F11/D11) -> 0 | F11: 0 | G11: 0 | H11: =IF(G11=0,0,I11/G11) -> 0 | I11: 0 | J11: 0 | K11: =IF(J11=0,0,L11/J11) -> 0 | L11: 0 | M11: =J11-G11 -> 0 | N11: =L11-I11 -> 0 | O11: 0 | P11: =IF(O11=0,0,Q11/O11) -> 0 | Q11: 0 | R11: =J11-O11 -> 0 | S11: =L11-Q11 -> 0
A12: Véhicules neufs[...] | B12: Véhicules neufs | C12: [...] | D12: 0 | E12: =IF(D12=0,0,F12/D12) -> 0 | F12: 0 | G12: 0 | H12: =IF(G12=0,0,I12/G12) -> 0 | I12: 0 | J12: 0 | K12: =IF(J12=0,0,L12/J12) -> 0 | L12: 0 | M12: =J12-G12 -> 0 | N12: =L12-I12 -> 0 | O12: 0 | P12: =IF(O12=0,0,Q12/O12) -> 0 | Q12: 0 | R12: =J12-O12 -> 0 | S12: =L12-Q12 -> 0
A13: Véhicules neufsTotal Neufs | B13: Véhicules neufs | C13: Total Neufs | D13: =+SUM(D6:D12) -> 73.898795 | E13: =IF(D13<=0,0,F13/D13) -> 1940.0612 | F13: =+SUM(F6:F12) -> 143368.19 | G13: =+SUM(G6:G12) -> 73.898795 | H13: =IF(G13<=0,0,I13/G13) -> 1940.0612 | I13: =+SUM(I6:I12) -> 143368.19 | J13: =+SUM(J6:J12) -> 71 | K13: =IF(J13<=0,0,L13/J13) -> 2882.5438 | L13: =+SUM(L6:L12) -> 204660.61 | M13: =+SUM(M6:M12) -> -2.8987952 | N13: =+SUM(N6:N12) -> 61292.423 | O13: =+SUM(O6:O12) -> 63 | P13: =IF(O13<=0,0,Q13/O13) -> 1687.8113 | Q13: =+SUM(Q6:Q12) -> 106332.11 | R13: =+SUM(R6:R12) -> 8 | S13: =+SUM(S6:S12) -> 98328.5
A14: Véhicules neufs | B14: Véhicules neufs | R14: =R13/O13 -> 0.12698413 | S14: =IF(Q13=0,0,(S13/Q13)) -> 0.92473007
A15: Véhicules neufsEx-Démos et courtoisies | B15: Véhicules neufs | C15: Ex-Démos et courtoisies | D15: 6.9156627 | E15: =IF(D15=0,0,F15/D15) -> 1386.1016 | F15: 9585.8112 | G15: 6.9156627 | H15: =IF(G15=0,0,I15/G15) -> 1386.1016 | I15: 9585.8112 | J15: 2 | K15: =IF(J15=0,0,L15/J15) -> 4516.805 | L15: 9033.61 | M15: =J15-G15 -> -4.9156627 | N15: =L15-I15 -> -552.20119 | O15: 14 | P15: =IF(O15=0,0,Q15/O15) -> 2016.2536 | Q15: 28227.55 | R15: =J15-O15 -> -12 | S15: =L15-Q15 -> -19193.94
A16: Véhicules neufs | B16: Véhicules neufs
A17: Véhicules neufsFlottes | B17: Véhicules neufs | C17: Flottes | D17: 1.2439949 | E17: =IF(D17=0,0,F17/D17) -> 1938.8732 | F17: 2411.9484 | G17: 1.2439949 | H17: =IF(G17=0,0,I17/G17) -> 1938.8732 | I17: 2411.9484 | J17: 4 | K17: =IF(J17=0,0,L17/J17) -> 1549.0925 | L17: 6196.37 | M17: =J17-G17 -> 2.7560051 | N17: =L17-I17 -> 3784.4216 | O17: 1 | P17: =IF(O17=0,0,Q17/O17) -> 983.9 | Q17: 983.9 | R17: =J17-O17 -> 3 | S17: =L17-Q17 -> 5212.47
A18: Véhicules neufs | B18: Véhicules neufs
A19: Véhicules neufsRachat bail | B19: Véhicules neufs | C19: Rachat bail | D19: 0 | E19: =IF(D19=0,0,F19/D19) -> 0 | F19: 4909.3561 | G19: 0 | H19: =IF(G19=0,0,I19/G19) -> 0 | I19: 4909.3561 | L19: 19995.21 | N19: =L19-I19 -> 15085.854 | Q19: 7992.19 | R19: =O19-K19 -> 0 | S19: =L19-Q19 -> 12003.02
A20: Véhicules neufs | B20: Véhicules neufs
A21: Véhicules neufsRev. Finances | B21: Véhicules neufs | C21: Rev. Finances | D21: 0 | E21: =IF(D21=0,0,F21/D21) -> 0 | F21: 2418.2727 | G21: 0 | H21: =IF(G21=0,0,I21/G21) -> 0 | I21: 2418.2727 | K21: =IF(J13=0,0,L21/(J13+J15)) -> 172.24973 | L21: 12574.23 | N21: =L21-I21 -> 10155.957 | P21: =IF(O13=0,0,Q21/(O13+O15)) -> 0 | Q21: 0 | R21: =O21-K21 -> -172.24973 | S21: =L21-Q21 -> 12574.23
A22: Véhicules neufsRev. Protections | B22: Véhicules neufs | C22: Rev. Protections | D22: 0 | E22: =IF(D22=0,0,F22/D22) -> 0 | F22: 64673.337 | G22: 0 | H22: =IF(G22=0,0,I22/G22) -> 0 | I22: 64673.337 | K22: =IF(J13=0,0,L22/(J13+J15)) -> 810.39493 | L22: 59158.83 | N22: =L22-I22 -> -5514.5067 | P22: =IF(O13=0,0,Q22/(O13+O15)) -> 927.02481 | Q22: 71380.91 | R22: =O22-K22 -> -810.39493 | S22: =L22-Q22 -> -12222.08
A23: Véhicules neufsRev. Autres | B23: Véhicules neufs | C23: Rev. Autres | D23: 0 | E23: =IF(D23=0,0,F23/D23) -> 0 | F23: 1600.6798 | G23: 0 | H23: =IF(G23=0,0,I23/G23) -> 0 | I23: 1600.6798 | K23: =IF(J13=0,0,L23/(J13+J15)) -> 16.719726 | L23: 1220.54 | N23: =L23-I23 -> -380.13978 | P23: =IF(O13=0,0,Q23/(O13+O15)) -> 16.993117 | Q23: 1308.47 | R23: =O23-K23 -> -16.719726 | S23: =L23-Q23 -> -87.93
A24: Véhicules neufsTotal F&I | B24: Véhicules neufs | C24: Total F&I | D24: =+D15+D13 -> 80.814458 | E24: =IF(D24<=0,0,F24/D24) -> 850 | F24: =F21+F22+F23 -> 68692.289 | G24: =+G15+G13 -> 80.814458 | H24: =IF(G24<=0,0,I24/G24) -> 850 | I24: =I21+I22+I23 -> 68692.289 | J24: =+J15+J13 -> 73 | K24: =IF(J24<=0,0,L24/J24) -> 999.36438 | L24: =L21+L22+L23 -> 72953.6 | M24: =J24-G24 -> -7.8144578 | N24: =L24-I24 -> 4261.3108 | O24: =+O15+O13 -> 77 | P24: =IF(O24<=0,0,Q24/O24) -> 944.01792 | Q24: =Q21+Q22+Q23 -> 72689.38 | S24: =L24-Q24 -> 264.22
A25: Véhicules neufs | B25: Véhicules neufs | N25: =IF(N24=0,0,N24/I24) -> 0.062034777 | S25: =IF(Q24=0,0,(S24/Q24)) -> 0.0036349189
A26: Véhicules neufs | B26: Véhicules neufs
A27: Véhicules neufsTotal Dépt. Neufs | B27: Véhicules neufs | C27: Total Dépt. Neufs | D27: =+D13+D15+D17 -> 82.058453 | E27: =IF(D27<=0,0,F27/D27) -> 2790.2987 | F27: =F13+F17+F24+F19+F15 -> 228967.59 | G27: =+G13+G15+G17 -> 82.058453 | H27: =IF(G27<=0,0,I27/G27) -> 2790.2987 | I27: =I13+I17+I24+I19+I15 -> 228967.59 | J27: =+J13+J15+J17 -> 77 | K27: =IF(J27<=0,0,L27/J27) -> 4062.8494 | L27: =L13+L17+L24+L19+L15 -> 312839.4 | M27: =J27-G27 -> -5.0584528 | N27: =L27-I27 -> 83871.808 | O27: =+O13+O15+O17 -> 78 | P27: =IF(O27<=0,0,Q27/O27) -> 2772.1171 | Q27: =Q13+Q17+Q24+Q19+Q15 -> 216225.13 | R27: =J27-O27 -> -1 | S27: =L27-Q27 -> 96614.27
A28: Véhicules neufs | B28: Véhicules neufs | M28: =M27/G27 -> -0.061644506 | N28: =N27/I27 -> 0.36630427 | R28: =R27/O27 -> -0.012820513 | S28: =IF(Q27=0,0,S27/Q27) -> 0.44682258
A29: Véhicules neufs | B29: Véhicules neufs
A30: Véhicules neufsDEPENSES | B30: Véhicules neufs | C30: DEPENSES
A31: Véhicules neufsComm. vendeurs | B31: Véhicules neufs | C31: Comm. vendeurs | D31: =F31/(F15+F13+F17) -> 0.31779577 | E31: =F31/D$24 -> 610.96296 | F31: 49374.64 | G31: =I31/(I15+I13) -> 0.32280712 | H31: =I31/G$24 -> 610.96296 | I31: 49374.64 | J31: =L31/(L15+L13+L17) -> 0.22464749 | K31: =IF(L31=0,0,L31/J$24) -> 676.68315 | L31: 49397.87 | N31: =L31-I31 -> 23.229578 | P31: =IF(Q31=0,0,Q31/O$24) -> 598.30338 | Q31: 46069.36 | S31: =L31-Q31 -> 3328.51
A32: Véhicules neufsComm. F&I | B32: Véhicules neufs | C32: Comm. F&I | D32: =F32/F24 -> 0.3 | E32: =F32/D$24 -> 255 | F32: 20607.687 | G32: =I32/I24 -> 0.3 | H32: =I32/G$24 -> 255 | I32: 20607.687 | J32: =L32/L24 -> 0.37722868 | K32: =IF(L32=0,0,L32/J$24) -> 376.9889 | L32: 27520.19 | N32: =L32-I32 -> 6912.5033 | P32: =IF(Q32=0,0,Q32/O$24) -> 272.32532 | Q32: 20969.05 | S32: =L32-Q32 -> 6551.14 | U32: =(L32+L112)/(L104+L24+L19) -> 0.3095684 | V32: <<- F&A total Neuf Usagé Rachat
A33: Véhicules neufsFrais de livraison | B33: Véhicules neufs | C33: Frais de livraison | E33: =F33/D$24 -> 167.8493 | F33: 13564.65 | H33: =I33/G$24 -> 167.8493 | I33: 13564.65 | K33: =IF(L33=0,0,L33/J$24) -> 24.27137 | L33: 1771.81 | N33: =L33-I33 -> -11792.84 | P33: =IF(Q33=0,0,Q33/O$24) -> 130.65442 | Q33: 10060.39 | S33: =L33-Q33 -> -8288.58
A34: Véhicules neufsService gratuit 1 | B34: Véhicules neufs | C34: Service gratuit 1 | E34: =F34/D$24 -> 7.3548076 | F34: 594.37479 | H34: =I34/G$24 -> 7.3548076 | I34: 594.37479 | K34: =IF(L34=0,0,L34/J$24) -> 0 | L34: 0 | N34: =L34-I34 -> -594.37479 | P34: =IF(Q34=0,0,Q34/O$24) -> 7.3462338 | Q34: 565.66 | S34: =L34-Q34 -> -565.66
A35: Véhicules neufsEntretien stock | B35: Véhicules neufs | C35: Entretien stock | E35: =F35/D$24 -> 17.733118 | F35: 1433.0923 | H35: =I35/G$24 -> 17.733118 | I35: 1433.0923 | K35: =IF(L35=0,0,L35/J$24) -> 60.332329 | L35: 4404.26 | N35: =L35-I35 -> 2971.1677 | P35: =IF(Q35=0,0,Q35/O$24) -> 40.73 | Q35: 3136.21 | S35: =L35-Q35 -> 1268.05
A36: Véhicules neufsPublicité 1 | B36: Véhicules neufs | C36: Publicité 1 | E36: =F36/D$24 -> 195.93765 | F36: 15834.595 | H36: =I36/G$24 -> 195.93765 | I36: 15834.595 | K36: =IF(L36=0,0,L36/J$24) -> 48.655068 | L36: 3551.82 | N36: =L36-I36 -> -12282.775 | P36: =IF(Q36=0,0,Q36/O$24) -> 161.78143 | Q36: 12457.17 | S36: =L36-Q36 -> -8905.35
A37: Véhicules neufsIntérêt de gros | B37: Véhicules neufs | C37: Intérêt de gros | E37: =F37/D$24 -> 96.0289 | F37: 7760.5235 | H37: =I37/G$24 -> 96.0289 | I37: 7760.5235 | K37: =IF(L37=0,0,L37/J$24) -> 51.69 | L37: 3773.37 | N37: =L37-I37 -> -3987.1535 | P37: =IF(Q37=0,0,Q37/O$24) -> 155.30104 | Q37: 11958.18 | S37: =L37-Q37 -> -8184.81
A38: Véhicules neufs[...] | B38: Véhicules neufs | C38: [...] | E38: =F38/D$24 -> 0 | F38: 0 | H38: =I38/G$24 -> 0 | I38: 0 | K38: =IF(L38=0,0,L38/J$24) -> 0 | L38: 0 | N38: =L38-I38 -> 0 | P38: =IF(Q38=0,0,Q38/O$24) -> 0 | Q38: 0 | S38: =L38-Q38 -> 0
A39: Véhicules neufs[...] | B39: Véhicules neufs | C39: [...] | E39: =F39/D$24 -> 0 | F39: 0 | H39: =I39/G$24 -> 0 | I39: 0 | K39: =IF(L39=0,0,L39/J$24) -> 0 | L39: 0 | N39: =L39-I39 -> 0 | P39: =IF(Q39=0,0,Q39/O$24) -> 0 | Q39: 0 | S39: =L39-Q39 -> 0
A40: Véhicules neufs[...] | B40: Véhicules neufs | C40: [...] | E40: =F40/D$24 -> 0 | F40: 0 | H40: =I40/G$24 -> 0 | I40: 0 | K40: =IF(L40=0,0,L40/J$24) -> 0 | L40: 0 | N40: =L40-I40 -> 0 | P40: =IF(Q40=0,0,Q40/O$24) -> 0 | Q40: 0 | S40: =L40-Q40 -> 0
...

Sheet VW 2022-09
C1: Volks | K1: Véhicules neufs | S1: Réalisé, Septembre 2022
D2: X | E2: O | F2: U | G2: X | H2: O | I2: U | J2: NB | L2: $ | O2: NB | Q2: $ | V2: *** NE PAS EFFACER / Pour An Précédente ***
D3: BUDGET ORIGINAL | G3: BUDGET REVISE | J3: RÉALISATION | M3: ÉCART réel / révisé | O3: ANNÉE PRÉCÉDENTE | R3: ÉCART réel / original | V3: NEUF | W3: 0.45
D4: UNITE | E4: $P/UNITÉ | F4: $PROFITS | G4: UNITE | H4: $P/UNITÉ | I4: $PROFITS | J4: UNITE | K4: $P/UNITE | L4: $PROFITS | M4: UNITÉ | N4: $PROFITS | O4: UNITE | P4: $P/UNITE | Q4: $PROFITS | R4: UNITE | S4: $PROFITS | V4: USAGE | W4: 0.1
A5: Véhicules neufsVentes nettes | B5: Véhicules neufs | C5: Ventes nettes | F5: 2857426.1 | I5: 2857426.1 | L5: 2490545.3 | Q5: 3613426.6 | V5: SERVICE | W5: 0.225
A6: Véhicules neufsAutos détail | B6: Véhicules neufs | C6: Autos détail | D6: 14.573494 | E6: =IF(D6=0,0,F6/D6) -> 1450.6298 | F6: 21140.744 | G6: 14.573494 | H6: =IF(G6=0,0,I6/G6) -> 1450.6298 | I6: 21140.744 | J6: 16 | K6: =IF(J6=0,0,L6/J6) -> 1902.4 | L6: 30438.4 | M6: =J6-G6 -> 1.426506 | N6: =L6-I6 -> 9297.6559 | O6: 35 | P6: =IF(O6=0,0,Q6/O6) -> 1269.0223 | Q6: 44415.78 | R6: =J6-O6 -> -19 | S6: =L6-Q6 -> -13977.38 | V6: CARROSSERIE | W6: 0.025
A7: Véhicules neufsCamions détail | B7: Véhicules neufs | C7: Camions détail | D7: 50.313253 | E7: =IF(D7=0,0,F7/D7) -> 2081.8276 | F7: 104743.52 | G7: 50.313253 | H7: =IF(G7=0,0,I7/G7) -> 2081.8276 | I7: 104743.52 | J7: 33 | K7: =IF(J7=0,0,L7/J7) -> 2621.6852 | L7: 86515.61 | M7: =J7-G7 -> -17.313253 | N7: =L7-I7 -> -18227.908 | O7: 49 | P7: =IF(O7=0,0,Q7/O7) -> 2305.1553 | Q7: 112952.61 | R7: =J7-O7 -> -16 | S7: =L7-Q7 -> -26437 | V7: PIECES | W7: 0.2
A8: Véhicules neufsSprinter | B8: Véhicules neufs | C8: Sprinter | D8: 0 | E8: =IF(D8=0,0,F8/D8) -> 0 | F8: 0 | G8: 0 | H8: =IF(G8=0,0,I8/G8) -> 0 | I8: 0 | J8: 0 | K8: =IF(J8=0,0,L8/J8) -> 0 | L8: 0 | M8: =J8-G8 -> 0 | N8: =L8-I8 -> 0 | O8: 0 | P8: =IF(O8=0,0,Q8/O8) -> 0 | Q8: 0 | R8: =J8-O8 -> 0 | S8: =L8-Q8 -> 0 | W8: =SUM(W3:W7) -> 1
A9: Véhicules neufsMoto détail | B9: Véhicules neufs | C9: Moto détail | D9: 0 | E9: =IF(D9=0,0,F9/D9) -> 0 | F9: 0 | G9: 0 | H9: =IF(G9=0,0,I9/G9) -> 0 | I9: 0 | J9: 0 | K9: =IF(J9=0,0,L9/J9) -> 0 | L9: 0 | M9: =J9-G9 -> 0 | N9: =L9-I9 -> 0 | O9: 0 | P9: =IF(O9=0,0,Q9/O9) -> 0 | Q9: 0 | R9: =J9-O9 -> 0 | S9: =L9-Q9 -> 0
A10: Véhicules neufs[...] | B10: Véhicules neufs | C10: [...] | D10: 0 | E10: =IF(D10=0,0,F10/D10) -> 0 | F10: 0 | G10: 0 | H10: =IF(G10=0,0,I10/G10) -> 0 | I10: 0 | J10: 0 | K10: =IF(J10=0,0,L10/J10) -> 0 | L10: 0 | M10: =J10-G10 -> 0 | N10: =L10-I10 -> 0 | O10: 0 | P10: =IF(O10=0,0,Q10/O10) -> 0 | Q10: 0 | R10: =J10-O10 -> 0 | S10: =L10-Q10 -> 0
A11: Véhicules neufs[...] | B11: Véhicules neufs | C11: [...] | D11: 0 | E11: =IF(D11=0,0,F11/D11) -> 0 | F11: 0 | G11: 0 | H11: =IF(G11=0,0,I11/G11) -> 0 | I11: 0 | J11: 0 | K11: =IF(J11=0,0,L11/J11) -> 0 | L11: 0 | M11: =J11-G11 -> 0 | N11: =L11-I11 -> 0 | O11: 0 | P11: =IF(O11=0,0,Q11/O11) -> 0 | Q11: 0 | R11: =J11-O11 -> 0 | S11: =L11-Q11 -> 0
A12: Véhicules neufs[...] | B12: Véhicules neufs | C12: [...] | D12: 0 | E12: =IF(D12=0,0,F12/D12) -> 0 | F12: 0 | G12: 0 | H12: =IF(G12=0,0,I12/G12) -> 0 | I12: 0 | J12: 0 | K12: =IF(J12=0,0,L12/J12) -> 0 | L12: 0 | M12: =J12-G12 -> 0 | N12: =L12-I12 -> 0 | O12: 0 | P12: =IF(O12=0,0,Q12/O12) -> 0 | Q12: 0 | R12: =J12-O12 -> 0 | S12: =L12-Q12 -> 0
A13: Véhicules neufsTotal Neufs | B13: Véhicules neufs | C13: Total Neufs | D13: =+SUM(D6:D12) -> 64.886747 | E13: =IF(D13<=0,0,F13/D13) -> 1940.0612 | F13: =+SUM(F6:F12) -> 125884.26 | G13: =+SUM(G6:G12) -> 64.886747 | H13: =IF(G13<=0,0,I13/G13) -> 1940.0612 | I13: =+SUM(I6:I12) -> 125884.26 | J13: =+SUM(J6:J12) -> 49 | K13: =IF(J13<=0,0,L13/J13) -> 2386.8165 | L13: =+SUM(L6:L12) -> 116954.01 | M13: =+SUM(M6:M12) -> -15.886747 | N13: =+SUM(N6:N12) -> -8930.2522 | O13: =+SUM(O6:O12) -> 84 | P13: =IF(O13<=0,0,Q13/O13) -> 1873.4332 | Q13: =+SUM(Q6:Q12) -> 157368.39 | R13: =+SUM(R6:R12) -> -35 | S13: =+SUM(S6:S12) -> -40414.38
A14: Véhicules neufs | B14: Véhicules neufs | R14: =R13/O13 -> -0.41666667 | S14: =IF(Q13=0,0,(S13/Q13)) -> -0.25681384
A15: Véhicules neufsEx-Démos et courtoisies | B15: Véhicules neufs | C15: Ex-Démos et courtoisies | D15: 6.0722892 | E15: =IF(D15=0,0,F15/D15) -> 1386.1016 | F15: 8416.8098 | G15: 6.0722892 | H15: =IF(G15=0,0,I15/G15) -> 1386.1016 | I15: 8416.8098 | J15: 1 | K15: =IF(J15=0,0,L15/J15) -> 239.68 | L15: 239.68 | M15: =J15-G15 -> -5.0722892 | N15: =L15-I15 -> -8177.1298 | O15: 7 | P15: =IF(O15=0,0,Q15/O15) -> 505.77714 | Q15: 3540.44 | R15: =J15-O15 -> -6 | S15: =L15-Q15 -> -3300.76
A16: Véhicules neufs | B16: Véhicules neufs
A17: Véhicules neufsFlottes | B17: Véhicules neufs | C17: Flottes | D17: 1.0922882 | E17: =IF(D17=0,0,F17/D17) -> 1938.8732 | F17: 2117.8084 | G17: 1.0922882 | H17: =IF(G17=0,0,I17/G17) -> 1938.8732 | I17: 2117.8084 | J17: 3 | K17: =IF(J17=0,0,L17/J17) -> 1695.91 | L17: 5087.73 | M17: =J17-G17 -> 1.9077118 | N17: =L17-I17 -> 2969.9216 | O17: 0 | P17: =IF(O17=0,0,Q17/O17) -> 0 | Q17: 0 | R17: =J17-O17 -> 3 | S17: =L17-Q17 -> 5087.73
A18: Véhicules neufs | B18: Véhicules neufs
A19: Véhicules neufsRachat bail | B19: Véhicules neufs | C19: Rachat bail | D19: 0 | E19: =IF(D19=0,0,F19/D19) -> 0 | F19: 4909.3561 | G19: 0 | H19: =IF(G19=0,0,I19/G19) -> 0 | I19: 4909.3561 | L19: 13692.75 | N19: =L19-I19 -> 8783.3939 | Q19: 5452.6 | R19: =O19-K19 -> 0 | S19: =L19-Q19 -> 8240.15
A20: Véhicules neufs | B20: Véhicules neufs
A21: Véhicules neufsRev. Finances | B21: Véhicules neufs | C21: Rev. Finances | D21: 0 | E21: =IF(D21=0,0,F21/D21) -> 0 | F21: 2123.3614 | G21: 0 | H21: =IF(G21=0,0,I21/G21) -> 0 | I21: 2123.3614 | K21: =IF(J13=0,0,L21/(J13+J15)) -> 211.384 | L21: 10569.2 | N21: =L21-I21 -> 8445.8386 | P21: =IF(O13=0,0,Q21/(O13+O15)) -> 17.566923 | Q21: 1598.59 | R21: =O21-K21 -> -211.384 | S21: =L21-Q21 -> 8970.61
A22: Véhicules neufsRev. Protections | B22: Véhicules neufs | C22: Rev. Protections | D22: 0 | E22: =IF(D22=0,0,F22/D22) -> 0 | F22: 56786.344 | G22: 0 | H22: =IF(G22=0,0,I22/G22) -> 0 | I22: 56786.344 | K22: =IF(J13=0,0,L22/(J13+J15)) -> 866.2176 | L22: 43310.88 | N22: =L22-I22 -> -13475.464 | P22: =IF(O13=0,0,Q22/(O13+O15)) -> 841.79264 | Q22: 76603.13 | R22: =O22-K22 -> -866.2176 | S22: =L22-Q22 -> -33292.25
A23: Véhicules neufsRev. Autres | B23: Véhicules neufs | C23: Rev. Autres | D23: 0 | E23: =IF(D23=0,0,F23/D23) -> 0 | F23: 1405.4749 | G23: 0 | H23: =IF(G23=0,0,I23/G23) -> 0 | I23: 1405.4749 | K23: =IF(J13=0,0,L23/(J13+J15)) -> 32.4756 | L23: 1623.78 | N23: =L23-I23 -> 218.30507 | P23: =IF(O13=0,0,Q23/(O13+O15)) -> 18.563297 | Q23: 1689.26 | R23: =O23-K23 -> -32.4756 | S23: =L23-Q23 -> -65.48
A24: Véhicules neufsTotal F&I | B24: Véhicules neufs | C24: Total F&I | D24: =+D15+D13 -> 70.959036 | E24: =IF(D24<=0,0,F24/D24) -> 850 | F24: =F21+F22+F23 -> 60315.181 | G24: =+G15+G13 -> 70.959036 | H24: =IF(G24<=0,0,I24/G24) -> 850 | I24: =I21+I22+I23 -> 60315.181 | J24: =+J15+J13 -> 50 | K24: =IF(J24<=0,0,L24/J24) -> 1110.0772 | L24: =L21+L22+L23 -> 55503.86 | M24: =J24-G24 -> -20.959036 | N24: =L24-I24 -> -4811.3207 | O24: =+O15+O13 -> 91 | P24: =IF(O24<=0,0,Q24/O24) -> 877.92286 | Q24: =Q21+Q22+Q23 -> 79890.98 | S24: =L24-Q24 -> -24387.12
A25: Véhicules neufs | B25: Véhicules neufs | N25: =IF(N24=0,0,N24/I24) -> -0.079769648 | S25: =IF(Q24=0,0,(S24/Q24)) -> -0.30525499
A26: Véhicules neufs | B26: Véhicules neufs
A27: Véhicules neufsTotal Dépt. Neufs | B27: Véhicules neufs | C27: Total Dépt. Neufs | D27: =+D13+D15+D17 -> 72.051324 | E27: =IF(D27<=0,0,F27/D27) -> 2798.6081 | F27: =F13+F17+F24+F19+F15 -> 201643.42 | G27: =+G13+G15+G17 -> 72.051324 | H27: =IF(G27<=0,0,I27/G27) -> 2798.6081 | I27: =I13+I17+I24+I19+I15 -> 201643.42 | J27: =+J13+J15+J17 -> 53 | K27: =IF(J27<=0,0,L27/J27) -> 3612.793 | L27: =L13+L17+L24+L19+L15 -> 191478.03 | M27: =J27-G27 -> -19.051324 | N27: =L27-I27 -> -10165.387 | O27: =+O13+O15+O17 -> 91 | P27: =IF(O27<=0,0,Q27/O27) -> 2706.0704 | Q27: =Q13+Q17+Q24+Q19+Q15 -> 246252.41 | R27: =J27-O27 -> -38 | S27: =L27-Q27 -> -54774.38
A28: Véhicules neufs | B28: Véhicules neufs | M28: =M27/G27 -> -0.26441324 | N28: =N27/I27 -> -0.05041269 | R28: =R27/O27 -> -0.41758242 | S28: =IF(Q27=0,0,S27/Q27) -> -0.22243185
A29: Véhicules neufs | B29: Véhicules neufs
A30: Véhicules neufsDEPENSES | B30: Véhicules neufs | C30: DEPENSES
A31: Véhicules neufsComm. vendeurs | B31: Véhicules neufs | C31: Comm. vendeurs | D31: =F31/(F15+F13+F17) -> 0.32409988 | E31: =F31/D$24 -> 623.08263 | F31: 44213.343 | G31: =I31/(I15+I13) -> 0.32921065 | H31: =I31/G$24 -> 623.08263 | I31: 44213.343 | J31: =L31/(L15+L13+L17) -> 0.31406537 | K31: =IF(L31=0,0,L31/J$24) -> 768.0872 | L31: 38404.36 | N31: =L31-I31 -> -5808.9828 | P31: =IF(Q31=0,0,Q31/O$24) -> 631.62824 | Q31: 57478.17 | S31: =L31-Q31 -> -19073.81
A32: Véhicules neufsComm. F&I | B32: Véhicules neufs | C32: Comm. F&I | D32: =F32/F24 -> 0.3 | E32: =F32/D$24 -> 255 | F32: 18094.554 | G32: =I32/I24 -> 0.3 | H32: =I32/G$24 -> 255 | I32: 18094.554 | J32: =L32/L24 -> 0.34749475 | K32: =IF(L32=0,0,L32/J$24) -> 385.746 | L32: 19287.3 | N32: =L32-I32 -> 1192.7458 | P32: =IF(Q32=0,0,Q32/O$24) -> 259.28209 | Q32: 23594.67 | S32: =L32-Q32 -> -4307.37 | U32: =(L32+L112)/(L104+L24+L19) -> 0.23827681 | V32: <<- F&A total Neuf Usagé Rachat
A33: Véhicules neufsFrais de livraison | B33: Véhicules neufs | C33: Frais de livraison | E33: =F33/D$24 -> 167.8493 | F33: 11910.425 | H33: =I33/G$24 -> 167.8493 | I33: 11910.425 | K33: =IF(L33=0,0,L33/J$24) -> -22.501 | L33: -1125.05 | N33: =L33-I33 -> -13035.475 | P33: =IF(Q33=0,0,Q33/O$24) -> 109.96538 | Q33: 10006.85 | S33: =L33-Q33 -> -11131.9
A34: Véhicules neufsService gratuit 1 | B34: Véhicules neufs | C34: Service gratuit 1 | E34: =F34/D$24 -> 7.3548076 | F34: 521.89006 | H34: =I34/G$24 -> 7.3548076 | I34: 521.89006 | K34: =IF(L34=0,0,L34/J$24) -> 0.58 | L34: 29 | N34: =L34-I34 -> -492.89006 | P34: =IF(Q34=0,0,Q34/O$24) -> 18.107692 | Q34: 1647.8 | S34: =L34-Q34 -> -1618.8
A35: Véhicules neufsEntretien stock | B35: Véhicules neufs | C35: Entretien stock | E35: =F35/D$24 -> 17.733118 | F35: 1258.325 | H35: =I35/G$24 -> 17.733118 | I35: 1258.325 | K35: =IF(L35=0,0,L35/J$24) -> 71.9218 | L35: 3596.09 | N35: =L35-I35 -> 2337.765 | P35: =IF(Q35=0,0,Q35/O$24) -> 10.88989 | Q35: 990.98 | S35: =L35-Q35 -> 2605.11
A36: Véhicules neufsPublicité 1 | B36: Véhicules neufs | C36: Publicité 1 | E36: =F36/D$24 -> 195.93765 | F36: 13903.547 | H36: =I36/G$24 -> 195.93765 | I36: 13903.547 | K36: =IF(L36=0,0,L36/J$24) -> 40.1874 | L36: 2009.37 | N36: =L36-I36 -> -11894.177 | P36: =IF(Q36=0,0,Q36/O$24) -> 59.356374 | Q36: 5401.43 | S36: =L36-Q36 -> -3392.06
A37: Véhicules neufsIntérêt de gros | B37: Véhicules neufs | C37: Intérêt de gros | E37: =F37/D$24 -> 117.38963 | F37: 8329.8552 | H37: =I37/G$24 -> 117.38963 | I37: 8329.8552 | K37: =IF(L37=0,0,L37/J$24) -> 105.5194 | L37: 5275.97 | N37: =L37-I37 -> -3053.8852 | P37: =IF(Q37=0,0,Q37/O$24) -> 143.12824 | Q37: 13024.67 | S37: =L37-Q37 -> -7748.7
A38: Véhicules neufs[...] | B38: Véhicules neufs | C38: [...] | E38: =F38/D$24 -> 0 | F38: 0 | H38: =I38/G$24 -> 0 | I38: 0 | K38: =IF(L38=0,0,L38/J$24) -> 0 | L38: 0 | N38: =L38-I38 -> 0 | P38: =IF(Q38=0,0,Q38/O$24) -> 0 | Q38: 0 | S38: =L38-Q38 -> 0
A39: Véhicules neufs[...] | B39: Véhicules neufs | C39: [...] | E39: =F39/D$24 -> 0 | F39: 0 | H39: =I39/G$24 -> 0 | I39: 0 | K39: =IF(L39=0,0,L39/J$24) -> 0 | L39: 0 | N39: =L39-I39 -> 0 | P39: =IF(Q39=0,0,Q39/O$24) -> 0 | Q39: 0 | S39: =L39-Q39 -> 0
A40: Véhicules neufs[...] | B40: Véhicules neufs | C40: [...] | E40: =F40/D$24 -> 0 | F40: 0 | H40: =I40/G$24 -> 0 | I40: 0 | K40: =IF(L40=0,0,L40/J$24) -> 0 | L40: 0 | N40: =L40-I40 -> 0 | P40: =IF(Q40=0,0,Q40/O$24) -> 0 | Q40: 0 | S40: =L40-Q40 -> 0
...

Sheet END
