Workbook
Name _Dates_Conc: [1]Dealers!$BF$37:$KA$63
Name _scen: '[1]Scen & Sens'!$E$26
Name _scen1: '[1]Scen & Sens'!$E$27
Name _scen2: '[1]Scen & Sens'!$E$28
Name _SCenarios: '[1]Scen & Sens'!$J$26:$O$26
Name _Sens1: '[1]Scen & Sens'!$F$9
Name _Sens2: '[1]Scen & Sens'!$F$10
Name _sensRes1: '[1]Scen & Sens'!$E$15
Name _sensRes2: '[1]Scen & Sens'!$E$16
Name _sensRes3: '[1]Scen & Sens'!$E$17
Name _sensRes4: '[1]Scen & Sens'!$E$18
Name _sensRes5: '[1]Scen & Sens'!$E$19
Name _sensRes6: '[1]Scen & Sens'!$E$20
Name _sensRes7: '[1]Scen & Sens'!$E$21
Name DateRange: [1]Volkswagen!$BF$6:$DY$6
Name Monetary_Unit: [1]Parameters!$B$15
Name Months: [1]Parameters!$E$9:$E$20
Name Rng_Dealers_Names: [1]!Tbl_Dealers[Dealer Name]
Name Rng_Dlr_Dates: [1]!Tbl_V_Dlr_Dates[Date]
Name Titre: [1]Front!$A$9

Sheet Paramètre
B3: VOLKS QUARTER | C3: Volks T2 2022
B6: BUDGET | F6: BUDGET RÉVISÉ | J6: ACTUAL | N6: LAST YEAR
B7: Ventes | C7: Profits bruts | D7: BAIIA | E7: EBIT | F7: Ventes | G7: Profits bruts | H7: BAIIA | I7: EBIT | J7: Ventes | K7: Profits bruts | L7: BAIIA | M7: EBIT | N7: Ventes | O7: Profits bruts | P7: BAIIA | Q7: EBIT
A8: CTRL | B8: =+B9-B10 -> 0 | C8: =+C9-C10 -> 0 | D8: =+D9-D10 -> 0 | E8: =+E9-E10 -> 0 | F8: =+F9-F10 -> 0 | G8: =+G9-G10 -> 0 | H8: =+H9-H10 -> 0 | I8: =+I9-I10 -> 0 | ... Q8: =+Q9-Q10 -> 0
A9: CONSO | B9: =+Conso!$Z$405 -> 16697118 | C9: =+Conso!$Z$406 -> 2208574.1 | D9: =+Conso!$Z$482 -> 799210.12 | E9: =+Conso!$Z$497 -> 775508.74 | F9: =+Conso!$AC$405 -> 16697118 | G9: =+Conso!$AC$406 -> 2208574.1 | H9: =+Conso!$AC$482 -> 799210.12 | I9: =+Conso!$AC$497 -> 775508.74 | J9: =+Conso!$AF$405 -> 14021677 | K9: =+Conso!$AF$406 -> 2196862.7 | L9: =+Conso!$AF$482 -> 639346.24 | M9: =+Conso!$AF$497 -> 625122.37 | N9: =+Conso!$AL$405 -> 17043863 | O9: =+Conso!$AL$406 -> 2012370.4 | P9: =+Conso!$AL$482 -> 730595.95 | Q9: =+Conso!$AL$497 -> 749828.63
A10: TOTAL | B10: =+SUM(B11:B13) -> 16697118 | C10: =+SUM(C11:C13) -> 2208574.1 | D10: =+SUM(D11:D13) -> 799210.12 | E10: =+SUM(E11:E13) -> 775508.74 | F10: =+SUM(F11:F13) -> 16697118 | G10: =+SUM(G11:G13) -> 2208574.1 | H10: =+SUM(H11:H13) -> 799210.12 | I10: =+SUM(I11:I13) -> 775508.74 | ... Q10: =+SUM(Q11:Q13) -> 749828.63
A11: AUDI 1 | B11: =+'VW 2022-04'!$Z$405 -> 5458038.9 | C11: =+'VW 2022-04'!$Z$406 -> 748131.55 | D11: =+'VW 2022-04'!$Z$482 -> 268136.2 | E11: =+'VW 2022-04'!$Z$497 -> 260233.46 | F11: =+'VW 2022-04'!$AC$405 -> 5458038.9 | G11: =+'VW 2022-04'!$AC$406 -> 748131.55 | H11: =+'VW 2022-04'!$AC$482 -> 268136.2 | I11: =+'VW 2022-04'!$AC$497 -> 260233.46 | J11: =+'VW 2022-04'!$AF$405 -> 3776991 | K11: =+'VW 2022-04'!$AF$406 -> 649075.44 | L11: =+'VW 2022-04'!$AF$482 -> 152748.42 | M11: =+'VW 2022-04'!$AF$497 -> 148007.13 | N11: =+'VW 2022-04'!$AL$405 -> 5242313.3 | O11: =+'VW 2022-04'!$AL$406 -> 640912.74 | P11: =+'VW 2022-04'!$AL$482 -> 194923.31 | Q11: =+'VW 2022-04'!$AL$497 -> 187231.25
A12: AUDI 2 | B12: =+'VW 2022-05'!$Z$405 -> 6023595.8 | C12: =+'VW 2022-05'!$Z$406 -> 766209.11 | D12: =+'VW 2022-05'!$Z$482 -> 291103.22 | E12: =+'VW 2022-05'!$Z$497 -> 283199.85 | F12: =+'VW 2022-05'!$AC$405 -> 6023595.8 | G12: =+'VW 2022-05'!$AC$406 -> 766209.11 | H12: =+'VW 2022-05'!$AC$482 -> 291103.22 | I12: =+'VW 2022-05'!$AC$497 -> 283199.85 | J12: =+'VW 2022-05'!$AF$405 -> 4721471.7 | K12: =+'VW 2022-05'!$AF$406 -> 749925.49 | L12: =+'VW 2022-05'!$AF$482 -> 218438.19 | M12: =+'VW 2022-05'!$AF$497 -> 213696.9 | N12: =+'VW 2022-05'!$AL$405 -> 5900774.7 | O12: =+'VW 2022-05'!$AL$406 -> 685728.85 | P12: =+'VW 2022-05'!$AL$482 -> 267836.32 | Q12: =+'VW 2022-05'!$AL$497 -> 281298.69
A13: AUDI 3 | B13: =+'VW 2022-06'!$Z$405 -> 5215482.8 | C13: =+'VW 2022-06'!$Z$406 -> 694233.43 | D13: =+'VW 2022-06'!$Z$482 -> 239970.71 | E13: =+'VW 2022-06'!$Z$497 -> 232075.44 | F13: =+'VW 2022-06'!$AC$405 -> 5215482.8 | G13: =+'VW 2022-06'!$AC$406 -> 694233.43 | H13: =+'VW 2022-06'!$AC$482 -> 239970.71 | I13: =+'VW 2022-06'!$AC$497 -> 232075.44 | J13: =+'VW 2022-06'!$AF$405 -> 5523213.9 | K13: =+'VW 2022-06'!$AF$406 -> 797861.77 | L13: =+'VW 2022-06'!$AF$482 -> 268159.63 | M13: =+'VW 2022-06'!$AF$497 -> 263418.34 | N13: =+'VW 2022-06'!$AL$405 -> 5900774.7 | O13: =+'VW 2022-06'!$AL$406 -> 685728.85 | P13: =+'VW 2022-06'!$AL$482 -> 267836.32 | Q13: =+'VW 2022-06'!$AL$497 -> 281298.69

Sheet Conso
C1: Conso | K1: Véhicules neufs | S1: =CONCATENATE("Réalisé"," ",Paramètre!$C$2," ",Paramètre!$C$3) -> Réalisé Volks T2 2022 | V1: BUDGET | W1: RÉVISÉ | X1: ACTUAL | Y1: LY
D2: X | E2: O | F2: U | G2: X | H2: O | I2: U
D3: BUDGET ORIGINAL | G3: BUDGET REVISE | J3: RÉALISATION | M3: ÉCART réel / révisé | O3: ANNÉE PRÉCÉDENTE | R3: ÉCART réel / original
D4: UNITE | E4: $P/UNITÉ | F4: $PROFITS | G4: UNITE | H4: $P/UNITÉ | I4: $PROFITS | J4: UNITE | K4: $P/UNITE | L4: $PROFITS | M4: UNITÉ | N4: $PROFITS | O4: UNITE | P4: $P/UNITE | Q4: $PROFITS | R4: UNITE | S4: $PROFITS | V4: =+SUM(V5:V398) -> 0 | W4: =+SUM(W5:W398) -> 0 | X4: =+SUM(X5:X398) -> 0 | Y4: =+SUM(Y5:Y398) -> 0
A5: =+B5&C5 -> Véhicules neufsVentes nettes | B5: =+$K$1 -> Véhicules neufs | C5: Ventes nettes | F5: =+SUM(START:END!F5) -> 10000991 | I5: =+SUM(START:END!I5) -> 10000991 | L5: =+SUM(START:END!L5) -> 7004013.6 | Q5: =+SUM(START:END!Q5) -> 10902850
A6: =+B6&C6 -> Véhicules neufsAutos détail | B6: =+$K$1 -> Véhicules neufs | C6: Autos détail | D6: =+SUM(START:END!D6) -> 51.007229 | E6: =IF(D6=0,0,F6/D6) -> 1450.6298 | F6: =+SUM(START:END!F6) -> 73992.604 | G6: =+SUM(START:END!G6) -> 51.007229 | H6: =IF(G6=0,0,I6/G6) -> 1450.6298 | I6: =+SUM(START:END!I6) -> 73992.604 | J6: =+SUM(START:END!J6) -> 25 | K6: =IF(J6=0,0,L6/J6) -> 2750.1316 | L6: =+SUM(START:END!L6) -> 68753.29 | M6: =J6-G6 -> -26.007229 | N6: =L6-I6 -> -5239.3143 | O6: =+SUM(START:END!O6) -> 74 | P6: =IF(O6=0,0,Q6/O6) -> 843.59338 | Q6: =+SUM(START:END!Q6) -> 62425.91 | R6: =J6-O6 -> -49 | S6: =L6-Q6 -> 6327.38
A7: =+B7&C7 -> Véhicules neufsCamions détail | B7: =+$K$1 -> Véhicules neufs | C7: Camions détail | D7: =+SUM(START:END!D7) -> 176.09639 | E7: =IF(D7=0,0,F7/D7) -> 2081.8276 | F7: =+SUM(START:END!F7) -> 366602.31 | G7: =+SUM(START:END!G7) -> 176.09639 | H7: =IF(G7=0,0,I7/G7) -> 2081.8276 | I7: =+SUM(START:END!I7) -> 366602.31 | J7: =+SUM(START:END!J7) -> 101 | K7: =IF(J7=0,0,L7/J7) -> 3759.3914 | L7: =+SUM(START:END!L7) -> 379698.53 | M7: =J7-G7 -> -75.096386 | N7: =L7-I7 -> 13096.217 | O7: =+SUM(START:END!O7) -> 157 | P7: =IF(O7=0,0,Q7/O7) -> 2137.3047 | Q7: =+SUM(START:END!Q7) -> 335556.84 | R7: =J7-O7 -> -56 | S7: =L7-Q7 -> 44141.69
A8: =+B8&C8 -> Véhicules neufsSprinter | B8: =+$K$1 -> Véhicules neufs | C8: Sprinter | D8: =+SUM(START:END!D8) -> 0 | E8: =IF(D8=0,0,F8/D8) -> 0 | F8: =+SUM(START:END!F8) -> 0 | G8: =+SUM(START:END!G8) -> 0 | H8: =IF(G8=0,0,I8/G8) -> 0 | I8: =+SUM(START:END!I8) -> 0 | J8: =+SUM(START:END!J8) -> 0 | K8: =IF(J8=0,0,L8/J8) -> 0 | L8: =+SUM(START:END!L8) -> 0 | M8: =J8-G8 -> 0 | N8: =L8-I8 -> 0 | O8: =+SUM(START:END!O8) -> 0 | P8: =IF(O8=0,0,Q8/O8) -> 0 | Q8: =+SUM(START:END!Q8) -> 0 | R8: =J8-O8 -> 0 | S8: =L8-Q8 -> 0
A9: =+B9&C9 -> Véhicules neufsMoto détail | B9: =+$K$1 -> Véhicules neufs | C9: Moto détail | D9: =+SUM(START:END!D9) -> 0 | E9: =IF(D9=0,0,F9/D9) -> 0 | F9: =+SUM(START:END!F9) -> 0 | G9: =+SUM(START:END!G9) -> 0 | H9: =IF(G9=0,0,I9/G9) -> 0 | I9: =+SUM(START:END!I9) -> 0 | J9: =+SUM(START:END!J9) -> 0 | K9: =IF(J9=0,0,L9/J9) -> 0 | L9: =+SUM(START:END!L9) -> 0 | M9: =J9-G9 -> 0 | N9: =L9-I9 -> 0 | O9: =+SUM(START:END!O9) -> 0 | P9: =IF(O9=0,0,Q9/O9) -> 0 | Q9: =+SUM(START:END!Q9) -> 0 | R9: =J9-O9 -> 0 | S9: =L9-Q9 -> 0
A10: =+B10&C10 -> Véhicules neufs[...] | B10: =+$K$1 -> Véhicules neufs | C10: [...] | D10: =+SUM(START:END!D10) -> 0 | E10: =IF(D10=0,0,F10/D10) -> 0 | F10: =+SUM(START:END!F10) -> 0 | G10: =+SUM(START:END!G10) -> 0 | H10: =IF(G10=0,0,I10/G10) -> 0 | I10: =+SUM(START:END!I10) -> 0 | J10: =+SUM(START:END!J10) -> 0 | K10: =IF(J10=0,0,L10/J10) -> 0 | L10: =+SUM(START:END!L10) -> 0 | M10: =J10-G10 -> 0 | N10: =L10-I10 -> 0 | O10: =+SUM(START:END!O10) -> 0 | P10: =IF(O10=0,0,Q10/O10) -> 0 | Q10: =+SUM(START:END!Q10) -> 0 | R10: =J10-O10 -> 0 | S10: =L10-Q10 -> 0
A11: =+B11&C11 -> Véhicules neufs[...] | B11: =+$K$1 -> Véhicules neufs | C11: [...] | D11: =+SUM(START:END!D11) -> 0 | E11: =IF(D11=0,0,F11/D11) -> 0 | F11: =+SUM(START:END!F11) -> 0 | G11: =+SUM(START:END!G11) -> 0 | H11: =IF(G11=0,0,I11/G11) -> 0 | I11: =+SUM(START:END!I11) -> 0 | J11: =+SUM(START:END!J11) -> 0 | K11: =IF(J11=0,0,L11/J11) -> 0 | L11: =+SUM(START:END!L11) -> 0 | M11: =J11-G11 -> 0 | N11: =L11-I11 -> 0 | O11: =+SUM(START:END!O11) -> 0 | P11: =IF(O11=0,0,Q11/O11) -> 0 | Q11: =+SUM(START:END!Q11) -> 0 | R11: =J11-O11 -> 0 | S11: =L11-Q11 -> 0
A12: =+B12&C12 -> Véhicules neufs[...] | B12: =+$K$1 -> Véhicules neufs | C12: [...] | D12: =+SUM(START:END!D12) -> 0 | E12: =IF(D12=0,0,F12/D12) -> 0 | F12: =+SUM(START:END!F12) -> 0 | G12: =+SUM(START:END!G12) -> 0 | H12: =IF(G12=0,0,I12/G12) -> 0 | I12: =+SUM(START:END!I12) -> 0 | J12: =+SUM(START:END!J12) -> 0 | K12: =IF(J12=0,0,L12/J12) -> 0 | L12: =+SUM(START:END!L12) -> 0 | M12: =J12-G12 -> 0 | N12: =L12-I12 -> 0 | O12: =+SUM(START:END!O12) -> 0 | P12: =IF(O12=0,0,Q12/O12) -> 0 | Q12: =+SUM(START:END!Q12) -> 0 | R12: =J12-O12 -> 0 | S12: =L12-Q12 -> 0
A13: =+B13&C13 -> Véhicules neufsTotal Neufs | B13: =+$K$1 -> Véhicules neufs | C13: Total Neufs | D13: =+SUM(D6:D12) -> 227.10361 | E13: =IF(D13<=0,0,F13/D13) -> 1940.0612 | F13: =+SUM(F6:F12) -> 440594.92 | G13: =+SUM(G6:G12) -> 227.10361 | H13: =IF(G13<=0,0,I13/G13) -> 1940.0612 | I13: =+SUM(I6:I12) -> 440594.92 | J13: =+SUM(J6:J12) -> 126 | K13: =IF(J13<=0,0,L13/J13) -> 3559.1414 | L13: =+SUM(L6:L12) -> 448451.82 | M13: =+SUM(M6:M12) -> -101.10361 | N13: =+SUM(N6:N12) -> 7856.9024 | O13: =+SUM(O6:O12) -> 231 | P13: =IF(O13<=0,0,Q13/O13) -> 1722.869 | Q13: =+SUM(Q6:Q12) -> 397982.75 | R13: =+SUM(R6:R12) -> -105 | S13: =+SUM(S6:S12) -> 50469.07 | V13: =+SUM(START:END!D13)-D13 -> 0 | W13: =+SUM(START:END!G13)-G13 -> 0 | X13: =+SUM(START:END!J13)-J13 -> 0 | Y13: =+SUM(START:END!O13)-O13 -> 0
A14: =+B14&C14 -> Véhicules neufs | B14: =+$K$1 -> Véhicules neufs | M14: =IF(G13=0,0,M13/G13) -> -0.44518717 | N14: =IF(I13=0,0,N13/I13) -> 0.017832485 | R14: =R13/O13 -> -0.45454545 | S14: =IF(Q13=0,0,(S13/Q13)) -> 0.1268122
A15: =+B15&C15 -> Véhicules neufsEx-Démos et courtoisies | B15: =+$K$1 -> Véhicules neufs | C15: Ex-Démos et courtoisies | D15: =+SUM(START:END!D15) -> 21.253012 | E15: =IF(D15=0,0,F15/D15) -> 1386.1016 | F15: =+SUM(START:END!F15) -> 29458.834 | G15: =+SUM(START:END!G15) -> 21.253012 | H15: =IF(G15=0,0,I15/G15) -> 1386.1016 | I15: =+SUM(START:END!I15) -> 29458.834 | J15: =+SUM(START:END!J15) -> 9 | K15: =IF(J15=0,0,L15/J15) -> 3915.0822 | L15: =+SUM(START:END!L15) -> 35235.74 | M15: =J15-G15 -> -12.253012 | N15: =L15-I15 -> 5776.9056 | O15: =+SUM(START:END!O15) -> 11 | P15: =IF(O15=0,0,Q15/O15) -> 2049.3845 | Q15: =+SUM(START:END!Q15) -> 22543.23 | R15: =J15-O15 -> -2 | S15: =L15-Q15 -> 12692.51 | V15: =+SUM(START:END!D15)-D15 -> 0 | W15: =+SUM(START:END!G15)-G15 -> 0 | X15: =+SUM(START:END!J15)-J15 -> 0 | Y15: =+SUM(START:END!O15)-O15 -> 0
A16: =+B16&C16 -> Véhicules neufs | B16: =+$K$1 -> Véhicules neufs
A17: =+B17&C17 -> Véhicules neufsFlottes | B17: =+$K$1 -> Véhicules neufs | C17: Flottes | D17: =+SUM(START:END!D17) -> 3.8230088 | E17: =IF(D17=0,0,F17/D17) -> 1938.8732 | F17: =+SUM(START:END!F17) -> 7412.3293 | G17: =+SUM(START:END!G17) -> 3.8230088 | H17: =IF(G17=0,0,I17/G17) -> 1938.8732 | I17: =+SUM(START:END!I17) -> 7412.3293 | J17: =+SUM(START:END!J17) -> 0 | K17: =IF(J17=0,0,L17/J17) -> 0 | L17: =+SUM(START:END!L17) -> 0 | M17: =J17-G17 -> -3.8230088 | N17: =L17-I17 -> -7412.3293 | O17: =+SUM(START:END!O17) -> 13 | P17: =IF(O17=0,0,Q17/O17) -> 2639.8062 | Q17: =+SUM(START:END!Q17) -> 34317.48 | R17: =J17-O17 -> -13 | S17: =L17-Q17 -> -34317.48 | V17: =+SUM(START:END!D17)-D17 -> 0 | W17: =+SUM(START:END!G17)-G17 -> 0 | X17: =+SUM(START:END!J17)-J17 -> 0 | Y17: =+SUM(START:END!O17)-O17 -> 0
A18: =+B18&C18 -> Véhicules neufs | B18: =+$K$1 -> Véhicules neufs
A19: =+B19&C19 -> Véhicules neufsRachat bail | B19: =+$K$1 -> Véhicules neufs | C19: Rachat bail | F19: =+SUM(START:END!F19) -> 25248.117 | I19: =+SUM(START:END!I19) -> 25248.117 | L19: =+SUM(START:END!L19) -> 34859.95 | N19: =L19-I19 -> 9611.8331 | Q19: =+SUM(START:END!Q19) -> 22670.95 | R19: =O19-K19 -> 0 | S19: =L19-Q19 -> 12189
A20: =+B20&C20 -> Véhicules neufs | B20: =+$K$1 -> Véhicules neufs
A21: =+B21&C21 -> Véhicules neufsRev. Finances | B21: =+$K$1 -> Véhicules neufs | C21: Rev. Finances | D21: 0 | E21: =IF(D21=0,0,F21/D21) -> 0 | F21: =+SUM(START:END!F21) -> 7431.7648 | G21: 0 | H21: =IF(G21=0,0,I21/G21) -> 0 | I21: =+SUM(START:END!I21) -> 7431.7648 | K21: =IF(J13=0,0,L21/(J13+J15)) -> 223.14963 | L21: =+SUM(START:END!L21) -> 30125.2 | N21: =L21-I21 -> 22693.435 | P21: =IF(O13=0,0,Q21/(O13+O15)) -> 26.407025 | Q21: =+SUM(START:END!Q21) -> 6390.5 | R21: =O21-K21 -> -223.14963 | S21: =L21-Q21 -> 23734.7
A22: =+B22&C22 -> Véhicules neufsRev. Protections | B22: =+$K$1 -> Véhicules neufs | C22: Rev. Protections | D22: 0 | E22: =IF(D22=0,0,F22/D22) -> 0 | F22: =+SUM(START:END!F22) -> 198752.21 | G22: 0 | H22: =IF(G22=0,0,I22/G22) -> 0 | I22: =+SUM(START:END!I22) -> 198752.21 | K22: =IF(J13=0,0,L22/(J13+J15)) -> 931.79037 | L22: =+SUM(START:END!L22) -> 125791.7 | N22: =L22-I22 -> -72960.505 | P22: =IF(O13=0,0,Q22/(O13+O15)) -> 764.76496 | Q22: =+SUM(START:END!Q22) -> 185073.12 | R22: =O22-K22 -> -931.79037 | S22: =L22-Q22 -> -59281.42
A23: =+B23&C23 -> Véhicules neufsRev. Autres | B23: =+$K$1 -> Véhicules neufs | C23: Rev. Autres | D23: 0 | E23: =IF(D23=0,0,F23/D23) -> 0 | F23: =+SUM(START:END!F23) -> 4919.1622 | G23: 0 | H23: =IF(G23=0,0,I23/G23) -> 0 | I23: =+SUM(START:END!I23) -> 4919.1622 | K23: =IF(J13=0,0,L23/(J13+J15)) -> 16.451185 | L23: =+SUM(START:END!L23) -> 2220.91 | N23: =L23-I23 -> -2698.2522 | P23: =IF(O13=0,0,Q23/(O13+O15)) -> 17.06219 | Q23: =+SUM(START:END!Q23) -> 4129.05 | R23: =O23-K23 -> -16.451185 | S23: =L23-Q23 -> -1908.14
A24: =+B24&C24 -> Véhicules neufsTotal F&I | B24: =+$K$1 -> Véhicules neufs | C24: Total F&I | D24: =+D15+D13 -> 248.35663 | E24: =IF(D24<=0,0,F24/D24) -> 850 | F24: =F21+F22+F23 -> 211103.13 | G24: =+G15+G13 -> 248.35663 | H24: =IF(G24<=0,0,I24/G24) -> 850 | I24: =I21+I22+I23 -> 211103.13 | J24: =+J15+J13 -> 135 | K24: =IF(J24<=0,0,L24/J24) -> 1171.3912 | L24: =L21+L22+L23 -> 158137.81 | M24: =J24-G24 -> -113.35663 | N24: =L24-I24 -> -52965.323 | O24: =+O15+O13 -> 242 | P24: =IF(O24<=0,0,Q24/O24) -> 808.23417 | Q24: =Q21+Q22+Q23 -> 195592.67 | S24: =L24-Q24 -> -37454.86 | V24: =+SUM(START:END!D24)-D24 -> 0 | W24: =+SUM(START:END!G24)-G24 -> 0 | X24: =+SUM(START:END!J24)-J24 -> 0 | Y24: =+SUM(START:END!O24)-O24 -> 0
A25: =+B25&C25 -> Véhicules neufs | B25: =+$K$1 -> Véhicules neufs | N25: =IF(N24=0,0,N24/I24) -> -0.25089785 | S25: =IF(Q24=0,0,(S24/Q24)) -> -0.19149419
A26: =+B26&C26 -> Véhicules neufs | B26: =+$K$1 -> Véhicules neufs
A27: =+B27&C27 -> Véhicules neufsTotal Dépt. Neufs | B27: =+$K$1 -> Véhicules neufs | C27: Total Dépt. Neufs | D27: =+D13+D15+D17 -> 252.17964 | E27: =IF(D27<=0,0,F27/D27) -> 2830.5907 | F27: =F13+F17+F24+F19+F15 -> 713817.33 | G27: =+G13+G15+G17 -> 252.17964 | H27: =IF(G27<=0,0,I27/G27) -> 2830.5907 | I27: =I13+I17+I24+I19+I15 -> 713817.33 | J27: =+J13+J15+J17 -> 135 | K27: =IF(J27<=0,0,L27/J27) -> 5012.4839 | L27: =L13+L17+L24+L19+L15 -> 676685.32 | M27: =J27-G27 -> -117.17964 | N27: =L27-I27 -> -37132.011 | O27: =+O13+O15+O17 -> 255 | P27: =IF(O27<=0,0,Q27/O27) -> 2639.6356 | Q27: =Q13+Q17+Q24+Q19+Q15 -> 673107.08 | R27: =J27-O27 -> -120 | S27: =L27-Q27 -> 3578.24 | V27: =+SUM(START:END!D27)-D27 -> 0 | W27: =+SUM(START:END!G27)-G27 -> 0 | X27: =+SUM(START:END!J27)-J27 -> 0 | Y27: =+SUM(START:END!O27)-O27 -> 0
A28: =+B28&C28 -> Véhicules neufs | B28: =+$K$1 -> Véhicules neufs | M28: =M27/G27 -> -0.46466732 | N28: =N27/I27 -> -0.052018926 | R28: =R27/O27 -> -0.47058824 | S28: =IF(Q27=0,0,S27/Q27) -> 0.0053160041
A29: =+B29&C29 -> Véhicules neufs | B29: =+$K$1 -> Véhicules neufs
A30: =+B30&C30 -> Véhicules neufsDEPENSES | B30: =+$K$1 -> Véhicules neufs | C30: DEPENSES
A31: =+B31&C31 -> Véhicules neufsComm. vendeurs | B31: =+$K$1 -> Véhicules neufs | C31: Comm. vendeurs | E31: =F31/D$24 -> 604.44008 | F31: =+SUM(START:END!F31) -> 150116.7 | H31: =I31/G$24 -> 604.44008 | I31: =+SUM(START:END!I31) -> 150116.7 | J31: =L31/L13 -> 0.3086142 | K31: =IF(L31=0,0,L31/J$24) -> 1025.1748 | L31: =+SUM(START:END!L31) -> 138398.6 | N31: =L31-I31 -> -11718.1 | P31: =IF(Q31=0,0,Q31/O$24) -> 610.77686 | Q31: =+SUM(START:END!Q31) -> 147808 | S31: =L31-Q31 -> -9409.4
A32: =+B32&C32 -> Véhicules neufsComm. F&I | B32: =+$K$1 -> Véhicules neufs | C32: Comm. F&I | E32: =F32/D$24 -> 255 | F32: =+SUM(START:END!F32) -> 63330.94 | H32: =I32/G$24 -> 255 | I32: =+SUM(START:END!I32) -> 63330.94 | J32: =L32/L24 -> 0.34819927 | K32: =IF(L32=0,0,L32/J$24) -> 407.87756 | L32: =+SUM(START:END!L32) -> 55063.47 | N32: =L32-I32 -> -8267.4698 | P32: =IF(Q32=0,0,Q32/O$24) -> 251.3676 | Q32: =+SUM(START:END!Q32) -> 60830.96 | S32: =L32-Q32 -> -5767.49
A33: =+B33&C33 -> Véhicules neufsFrais de livraison | B33: =+$K$1 -> Véhicules neufs | C33: Frais de livraison | E33: =F33/D$24 -> 167.8493 | F33: =+SUM(START:END!F33) -> 41686.486 | H33: =I33/G$24 -> 167.8493 | I33: =+SUM(START:END!I33) -> 41686.486 | K33: =IF(L33=0,0,L33/J$24) -> 106.88356 | L33: =+SUM(START:END!L33) -> 14429.28 | N33: =L33-I33 -> -27257.206 | P33: =IF(Q33=0,0,Q33/O$24) -> 106.07401 | Q33: =+SUM(START:END!Q33) -> 25669.91 | S33: =L33-Q33 -> -11240.63
A34: =+B34&C34 -> Véhicules neufsService gratuit 1 | B34: =+$K$1 -> Véhicules neufs | C34: Service gratuit 1 | E34: =F34/D$24 -> 7.3548076 | F34: =+SUM(START:END!F34) -> 1826.6152 | H34: =I34/G$24 -> 7.3548076 | I34: =+SUM(START:END!I34) -> 1826.6152 | K34: =IF(L34=0,0,L34/J$24) -> 5.2612593 | L34: =+SUM(START:END!L34) -> 710.27 | N34: =L34-I34 -> -1116.3452 | P34: =IF(Q34=0,0,Q34/O$24) -> 7.9414876 | Q34: =+SUM(START:END!Q34) -> 1921.84 | S34: =L34-Q34 -> -1211.57
A35: =+B35&C35 -> Véhicules neufsEntretien stock | B35: =+$K$1 -> Véhicules neufs | C35: Entretien stock | E35: =F35/D$24 -> 17.733118 | F35: =+SUM(START:END!F35) -> 4404.1374 | H35: =I35/G$24 -> 17.733118 | I35: =+SUM(START:END!I35) -> 4404.1374 | K35: =IF(L35=0,0,L35/J$24) -> 91.270667 | L35: =+SUM(START:END!L35) -> 12321.54 | N35: =L35-I35 -> 7917.4026 | P35: =IF(Q35=0,0,Q35/O$24) -> 13.545992 | Q35: =+SUM(START:END!Q35) -> 3278.13 | S35: =L35-Q35 -> 9043.41
A36: =+B36&C36 -> Véhicules neufsPublicité 1 | B36: =+$K$1 -> Véhicules neufs | C36: Publicité 1 | E36: =F36/D$24 -> 195.93765 | F36: =+SUM(START:END!F36) -> 48662.414 | H36: =I36/G$24 -> 195.93765 | I36: =+SUM(START:END!I36) -> 48662.414 | K36: =IF(L36=0,0,L36/J$24) -> 291.42074 | L36: =+SUM(START:END!L36) -> 39341.8 | N36: =L36-I36 -> -9320.6145 | P36: =IF(Q36=0,0,Q36/O$24) -> 136.67541 | Q36: =+SUM(START:END!Q36) -> 33075.45 | S36: =L36-Q36 -> 6266.35
A37: =+B37&C37 -> Véhicules neufsIntérêt de gros | B37: =+$K$1 -> Véhicules neufs | C37: Intérêt de gros | E37: =F37/D$24 -> 92.935022 | F37: =+SUM(START:END!F37) -> 23081.029 | H37: =I37/G$24 -> 92.935022 | I37: =+SUM(START:END!I37) -> 23081.029 | K37: =IF(L37=0,0,L37/J$24) -> 6.2387407 | L37: =+SUM(START:END!L37) -> 842.23 | N37: =L37-I37 -> -22238.799 | P37: =IF(Q37=0,0,Q37/O$24) -> 179.57818 | Q37: =+SUM(START:END!Q37) -> 43457.92 | S37: =L37-Q37 -> -42615.69
A38: =+B38&C38 -> Véhicules neufs[...] | B38: =+$K$1 -> Véhicules neufs | C38: [...] | E38: =F38/D$24 -> 0 | F38: =+SUM(START:END!F38) -> 0 | H38: =I38/G$24 -> 0 | I38: =+SUM(START:END!I38) -> 0 | K38: =IF(L38=0,0,L38/J$24) -> 0 | L38: =+SUM(START:END!L38) -> 0 | N38: =L38-I38 -> 0 | P38: =IF(Q38=0,0,Q38/O$24) -> 0 | Q38: =+SUM(START:END!Q38) -> 0 | S38: =L38-Q38 -> 0
A39: =+B39&C39 -> Véhicules neufs[...] | B39: =+$K$1 -> Véhicules neufs | C39: [...] | E39: =F39/D$24 -> 0 | F39: =+SUM(START:END!F39) -> 0 | H39: =I39/G$24 -> 0 | I39: =+SUM(START:END!I39) -> 0 | K39: =IF(L39=0,0,L39/J$24) -> 0 | L39: =+SUM(START:END!L39) -> 0 | N39: =L39-I39 -> 0 | P39: =IF(Q39=0,0,Q39/O$24) -> 0 | Q39: =+SUM(START:END!Q39) -> 0 | S39: =L39-Q39 -> 0
A40: =+B40&C40 -> Véhicules neufs[...] | B40: =+$K$1 -> Véhicules neufs | C40: [...] | E40: =F40/D$24 -> 0 | F40: =+SUM(START:END!F40) -> 0 | H40: =I40/G$24 -> 0 | I40: =+SUM(START:END!I40) -> 0 | K40: =IF(L40=0,0,L40/J$24) -> 0 | L40: =+SUM(START:END!L40) -> 0 | N40: =L40-I40 -> 0 | P40: =IF(Q40=0,0,Q40/O$24) -> 0 | Q40: =+SUM(START:END!Q40) -> 0 | S40: =L40-Q40 -> 0
...

Sheet START

Sheet VW 2022-04
C1: Volks | K1: Véhicules neufs | S1: Réalisé, Avril 2022
D2: X | E2: O | F2: U | G2: X | H2: O | I2: U | J2: NB | L2: $ | O2: NB | Q2: $ | V2: *** *** NE PAS EFFACER *** ***
D3: BUDGET ORIGINAL | G3: BUDGET REVISE | J3: RÉALISATION | M3: ÉCART réel / révisé | O3: ANNÉE PRÉCÉDENTE | R3: ÉCART réel / original | V3: NEUF | W3: 0.45
D4: UNITE | E4: $P/UNITÉ | F4: $PROFITS | G4: UNITE | H4: $P/UNITÉ | I4: $PROFITS | J4: UNITE | K4: $P/UNITE | L4: $PROFITS | M4: UNITÉ | N4: $PROFITS | O4: UNITE | P4: $P/UNITE | Q4: $PROFITS | R4: UNITE | S4: $PROFITS | V4: USAGE | W4: 0.1
A5: Véhicules neufsVentes nettes | B5: Véhicules neufs | C5: Ventes nettes | F5: 3254290.8 | I5: 3254290.8 | L5: 1766312.5 | Q5: 3244693.3 | V5: SERVICE | W5: 0.225
A6: Véhicules neufsAutos détail | B6: Véhicules neufs | C6: Autos détail | D6: 16.59759 | E6: 1450.6298 | F6: 24076.959 | G6: 16.59759 | H6: 1450.6298 | I6: 24076.959 | J6: 9 | K6: 2549.2733 | L6: 22943.46 | M6: -7.5975904 | N6: -1133.4986 | O6: 24 | P6: 474.33792 | Q6: 11384.11 | R6: -15 | S6: 11559.35 | V6: CARROSSERIE | W6: 0.025
A7: Véhicules neufsCamions détail | B7: Véhicules neufs | C7: Camions détail | D7: 57.301205 | E7: 2081.8276 | F7: 119291.23 | G7: 57.301205 | H7: 2081.8276 | I7: 119291.23 | J7: 22 | K7: 3588.6732 | L7: 78950.81 | M7: -35.301205 | N7: -40340.419 | O7: 41 | P7: 2167.9161 | Q7: 88884.56 | R7: -19 | S7: -9933.75 | V7: PIECES | W7: 0.2
A8: Véhicules neufsSprinter | B8: Véhicules neufs | C8: Sprinter | D8: 0 | E8: 0 | F8: 0 | G8: 0 | H8: 0 | I8: 0 | J8: 0 | K8: 0 | L8: 0 | M8: 0 | N8: 0 | O8: 0 | P8: 0 | Q8: 0 | R8: 0 | S8: 0 | W8: 1
A9: Véhicules neufsMoto détail | B9: Véhicules neufs | C9: Moto détail | D9: 0 | E9: 0 | F9: 0 | G9: 0 | H9: 0 | I9: 0 | J9: 0 | K9: 0 | L9: 0 | M9: 0 | N9: 0 | O9: 0 | P9: 0 | Q9: 0 | R9: 0 | S9: 0
A10: Véhicules neufs[...] | B10: Véhicules neufs | C10: [...] | D10: 0 | E10: 0 | F10: 0 | G10: 0 | H10: 0 | I10: 0 | J10: 0 | K10: 0 | L10: 0 | M10: 0 | N10: 0 | O10: 0 | P10: 0 | Q10: 0 | R10: 0 | S10: 0
A11: Véhicules neufs[...] | B11: Véhicules neufs | C11: [...] | D11: 0 | E11: 0 | F11: 0 | G11: 0 | H11: 0 | I11: 0 | J11: 0 | K11: 0 | L11: 0 | M11: 0 | N11: 0 | O11: 0 | P11: 0 | Q11: 0 | R11: 0 | S11: 0
A12: Véhicules neufs[...] | B12: Véhicules neufs | C12: [...] | D12: 0 | E12: 0 | F12: 0 | G12: 0 | H12: 0 | I12: 0 | J12: 0 | K12: 0 | L12: 0 | M12: 0 | N12: 0 | O12: 0 | P12: 0 | Q12: 0 | R12: 0 | S12: 0
A13: Véhicules neufsTotal Neufs | B13: Véhicules neufs | C13: Total Neufs | D13: 73.898795 | E13: 1940.0612 | F13: 143368.19 | G13: 73.898795 | H13: 1940.0612 | I13: 143368.19 | J13: 31 | K13: 3286.9119 | L13: 101894.27 | M13: -42.898795 | N13: -41473.917 | O13: 65 | P13: 1542.5949 | Q13: 100268.67 | R13: -34 | S13: 1625.6
A14: Véhicules neufs | B14: Véhicules neufs | R14: -0.52307692 | S14: 0.016212442
A15: Véhicules neufsEx-Démos et courtoisies | B15: Véhicules neufs | C15: Ex-Démos et courtoisies | D15: 6.9156627 | E15: 1386.1016 | F15: 9585.8112 | G15: 6.9156627 | H15: 1386.1016 | I15: 9585.8112 | J15: 2 | K15: 4555.475 | L15: 9110.95 | M15: -4.9156627 | N15: -474.86119 | O15: 3 | P15: 1041.6767 | Q15: 3125.03 | R15: -1 | S15: 5985.92
A16: Véhicules neufs | B16: Véhicules neufs
A17: Véhicules neufsFlottes | B17: Véhicules neufs | C17: Flottes | D17: 1.2439949 | E17: 1938.8732 | F17: 2411.9484 | G17: 1.2439949 | H17: 1938.8732 | I17: 2411.9484 | J17: 0 | K17: 0 | L17: 0 | M17: -1.2439949 | N17: -2411.9484 | O17: 5 | P17: 2400.116 | Q17: 12000.58 | R17: -5 | S17: -12000.58
A18: Véhicules neufs | B18: Véhicules neufs
A19: Véhicules neufsRachat bail | B19: Véhicules neufs | C19: Rachat bail | D19: 0 | E19: 0 | F19: 8416.039 | G19: 0 | H19: 0 | I19: 8416.039 | L19: 11555.79 | N19: 3139.751 | Q19: 10386.97 | R19: 0 | S19: 1168.82
A20: Véhicules neufs | B20: Véhicules neufs
A21: Véhicules neufsRev. Finances | B21: Véhicules neufs | C21: Rev. Finances | D21: 0 | E21: 0 | F21: 2418.2727 | G21: 0 | H21: 0 | I21: 2418.2727 | K21: 196.24152 | L21: 6475.97 | N21: 4057.6973 | P21: 93.977941 | Q21: 6390.5 | R21: -196.24152 | S21: 85.47
A22: Véhicules neufsRev. Protections | B22: Véhicules neufs | C22: Rev. Protections | D22: 0 | E22: 0 | F22: 64673.337 | G22: 0 | H22: 0 | I22: 64673.337 | K22: 797.35424 | L22: 26312.69 | N22: -38360.647 | P22: 763.56294 | Q22: 51922.28 | R22: -797.35424 | S22: -25609.59
A23: Véhicules neufsRev. Autres | B23: Véhicules neufs | C23: Rev. Autres | D23: 0 | E23: 0 | F23: 1600.6798 | G23: 0 | H23: 0 | I23: 1600.6798 | K23: 35.381515 | L23: 1167.59 | N23: -433.08978 | P23: 14.451618 | Q23: 982.71 | R23: -35.381515 | S23: 184.88
A24: Véhicules neufsTotal F&I | B24: Véhicules neufs | C24: Total F&I | D24: 80.814458 | E24: 850 | F24: 68692.289 | G24: 80.814458 | H24: 850 | I24: 68692.289 | J24: 33 | K24: 1028.9773 | L24: 33956.25 | M24: -47.814458 | N24: -34736.039 | O24: 68 | P24: 871.9925 | Q24: 59295.49 | S24: -25339.24
A25: Véhicules neufs | B25: Véhicules neufs | N25: -0.50567596 | S25: -0.4273384
A26: Véhicules neufs | B26: Véhicules neufs
A27: Véhicules neufsTotal Dépt. Neufs | B27: Véhicules neufs | C27: Total Dépt. Neufs | D27: 82.058453 | E27: 2833.0326 | F27: 232474.28 | G27: 82.058453 | H27: 2833.0326 | I27: 232474.28 | J27: 33 | K27: 4742.9473 | L27: 156517.26 | M27: -49.058453 | N27: -75957.015 | O27: 73 | P27: 2535.2978 | Q27: 185076.74 | R27: -40 | S27: -28559.48
A28: Véhicules neufs | B28: Véhicules neufs | M28: -0.59784765 | N28: -0.32673299 | R28: -0.54794521 | S28: -0.15431156
A29: Véhicules neufs | B29: Véhicules neufs
A30: Véhicules neufsDEPENSES | B30: Véhicules neufs | C30: DEPENSES
A31: Véhicules neufsComm. vendeurs | B31: Véhicules neufs | C31: Comm. vendeurs | D31: 0.31966893 | E31: 605.02343 | F31: 48894.64 | G31: 0.31966893 | H31: 605.02343 | I31: 48894.64 | J31: 0.31139094 | K31: 1047.4552 | L31: 34566.02 | N31: -14328.62 | P31: 609.35206 | Q31: 41435.94 | S31: -6869.92
A32: Véhicules neufsComm. F&I | B32: Véhicules neufs | C32: Comm. F&I | D32: 0.3 | E32: 255 | F32: 20607.687 | G32: 0.3 | H32: 255 | I32: 20607.687 | J32: 0.35133797 | K32: 361.51879 | L32: 11930.12 | N32: -8677.5667 | P32: 278.43412 | Q32: 18933.52 | S32: -7003.4
A33: Véhicules neufsFrais de livraison | B33: Véhicules neufs | C33: Frais de livraison | E33: 167.8493 | F33: 13564.65 | H33: 167.8493 | I33: 13564.65 | K33: 149.40182 | L33: 4930.26 | N33: -8634.3904 | P33: 186.22485 | Q33: 12663.29 | S33: -7733.03
A34: Véhicules neufsService gratuit 1 | B34: Véhicules neufs | C34: Service gratuit 1 | E34: 7.3548076 | F34: 594.37479 | H34: 7.3548076 | I34: 594.37479 | K34: 3.9393939 | L34: 130 | N34: -464.37479 | P34: 10.717647 | Q34: 728.8 | S34: -598.8
A35: Véhicules neufsEntretien stock | B35: Véhicules neufs | C35: Entretien stock | E35: 17.733118 | F35: 1433.0923 | H35: 17.733118 | I35: 1433.0923 | K35: 120.78636 | L35: 3985.95 | N35: 2552.8577 | P35: 13.796029 | Q35: 938.13 | S35: 3047.82
A36: Véhicules neufsPublicité 1 | B36: Véhicules neufs | C36: Publicité 1 | E36: 195.93765 | F36: 15834.595 | H36: 195.93765 | I36: 15834.595 | K36: 401.51273 | L36: 13249.92 | N36: -2584.6752 | P36: 179.49603 | Q36: 12205.73 | S36: 1044.19
A37: Véhicules neufsIntérêt de gros | B37: Véhicules neufs | C37: Intérêt de gros | E37: 101.02946 | F37: 8164.6412 | H37: 101.02946 | I37: 8164.6412 | K37: 10.32303 | L37: 340.66 | N37: -7823.9812 | P37: 226.95059 | Q37: 15432.64 | S37: -15091.98
A38: Véhicules neufs[...] | B38: Véhicules neufs | C38: [...] | E38: 0 | F38: 0 | H38: 0 | I38: 0 | K38: 0 | L38: 0 | N38: 0 | P38: 0 | Q38: 0 | S38: 0
A39: Véhicules neufs[...] | B39: Véhicules neufs | C39: [...] | E39: 0 | F39: 0 | H39: 0 | I39: 0 | K39: 0 | L39: 0 | N39: 0 | P39: 0 | Q39: 0 | S39: 0
A40: Véhicules neufs[...] | B40: Véhicules neufs | C40: [...] | E40: 0 | F40: 0 | H40: 0 | I40: 0 | K40: 0 | L40: 0 | N40: 0 | P40: 0 | Q40: 0 | S40: 0
...

Sheet VW 2022-05
C1: Volks | K1: Véhicules neufs | S1: Réalisé, Mai 2022
D2: X | E2: O | F2: U | G2: X | H2: O | I2: U | J2: NB | L2: $ | O2: NB | Q2: $ | V2: *** *** NE PAS EFFACER *** ***
D3: BUDGET ORIGINAL | G3: BUDGET REVISE | J3: RÉALISATION | M3: ÉCART réel / révisé | O3: ANNÉE PRÉCÉDENTE | R3: ÉCART réel / original | V3: NEUF | W3: 0.45
D4: UNITE | E4: $P/UNITÉ | F4: $PROFITS | G4: UNITE | H4: $P/UNITÉ | I4: $PROFITS | J4: UNITE | K4: $P/UNITE | L4: $PROFITS | M4: UNITÉ | N4: $PROFITS | O4: UNITE | P4: $P/UNITE | Q4: $PROFITS | R4: UNITE | S4: $PROFITS | V4: USAGE | W4: 0.1
A5: Véhicules neufsVentes nettes | B5: Véhicules neufs | C5: Ventes nettes | F5: 3809901.5 | I5: 3809901.5 | L5: 2400932.7 | Q5: 3829078.6 | V5: SERVICE | W5: 0.225
A6: Véhicules neufsAutos détail | B6: Véhicules neufs | C6: Autos détail | D6: 19.431325 | E6: 1450.6298 | F6: 28187.659 | G6: 19.431325 | H6: 1450.6298 | I6: 28187.659 | J6: 7 | K6: 3196.7429 | L6: 22377.2 | M6: -12.431325 | N6: -5810.4588 | O6: 25 | P6: 1020.836 | Q6: 25520.9 | R6: -18 | S6: -3143.7 | V6: CARROSSERIE | W6: 0.025
A7: Véhicules neufsCamions détail | B7: Véhicules neufs | C7: Camions détail | D7: 67.084337 | E7: 2081.8276 | F7: 139658.02 | G7: 67.084337 | H7: 2081.8276 | I7: 139658.02 | J7: 36 | K7: 3783.5983 | L7: 136209.54 | M7: -31.084337 | N7: -3448.4841 | O7: 58 | P7: 2126.4852 | Q7: 123336.14 | R7: -22 | S7: 12873.4 | V7: PIECES | W7: 0.2
A8: Véhicules neufsSprinter | B8: Véhicules neufs | C8: Sprinter | D8: 0 | E8: 0 | F8: 0 | G8: 0 | H8: 0 | I8: 0 | J8: 0 | K8: 0 | L8: 0 | M8: 0 | N8: 0 | O8: 0 | P8: 0 | Q8: 0 | R8: 0 | S8: 0 | W8: 1
A9: Véhicules neufsMoto détail | B9: Véhicules neufs | C9: Moto détail | D9: 0 | E9: 0 | F9: 0 | G9: 0 | H9: 0 | I9: 0 | J9: 0 | K9: 0 | L9: 0 | M9: 0 | N9: 0 | O9: 0 | P9: 0 | Q9: 0 | R9: 0 | S9: 0
A10: Véhicules neufs[...] | B10: Véhicules neufs | C10: [...] | D10: 0 | E10: 0 | F10: 0 | G10: 0 | H10: 0 | I10: 0 | J10: 0 | K10: 0 | L10: 0 | M10: 0 | N10: 0 | O10: 0 | P10: 0 | Q10: 0 | R10: 0 | S10: 0
A11: Véhicules neufs[...] | B11: Véhicules neufs | C11: [...] | D11: 0 | E11: 0 | F11: 0 | G11: 0 | H11: 0 | I11: 0 | J11: 0 | K11: 0 | L11: 0 | M11: 0 | N11: 0 | O11: 0 | P11: 0 | Q11: 0 | R11: 0 | S11: 0
A12: Véhicules neufs[...] | B12: Véhicules neufs | C12: [...] | D12: 0 | E12: 0 | F12: 0 | G12: 0 | H12: 0 | I12: 0 | J12: 0 | K12: 0 | L12: 0 | M12: 0 | N12: 0 | O12: 0 | P12: 0 | Q12: 0 | R12: 0 | S12: 0
A13: Véhicules neufsTotal Neufs | B13: Véhicules neufs | C13: Total Neufs | D13: 86.515663 | E13: 1940.0612 | F13: 167845.68 | G13: 86.515663 | H13: 1940.0612 | I13: 167845.68 | J13: 43 | K13: 3688.0637 | L13: 158586.74 | M13: -43.515663 | N13: -9258.9429 | O13: 83 | P13: 1793.4583 | Q13: 148857.04 | R13: -40 | S13: 9729.7
A14: Véhicules neufs | B14: Véhicules neufs | R14: -0.48192771 | S14: 0.065362713
A15: Véhicules neufsEx-Démos et courtoisies | B15: Véhicules neufs | C15: Ex-Démos et courtoisies | D15: 8.0963855 | E15: 1386.1016 | F15: 11222.413 | G15: 8.0963855 | H15: 1386.1016 | I15: 11222.413 | J15: 3 | K15: 5865.1167 | L15: 17595.35 | M15: -5.0963855 | N15: 6372.9369 | O15: 4 | P15: 2427.275 | Q15: 9709.1 | R15: -1 | S15: 7886.25
A16: Véhicules neufs | B16: Véhicules neufs
A17: Véhicules neufsFlottes | B17: Véhicules neufs | C17: Flottes | D17: 1.4563843 | E17: 1938.8732 | F17: 2823.7445 | G17: 1.4563843 | H17: 1938.8732 | I17: 2823.7445 | J17: 0 | K17: 0 | L17: 0 | M17: -1.4563843 | N17: -2823.7445 | O17: 4 | P17: 2789.6125 | Q17: 11158.45 | R17: -4 | S17: -11158.45
A18: Véhicules neufs | B18: Véhicules neufs
A19: Véhicules neufsRachat bail | B19: Véhicules neufs | C19: Rachat bail | D19: 0 | E19: 0 | F19: 8416.039 | G19: 0 | H19: 0 | I19: 8416.039 | L19: 10153.06 | N19: 1737.021 | Q19: 6141.99 | R19: 0 | S19: 4011.07
A20: Véhicules neufs | B20: Véhicules neufs
A21: Véhicules neufsRev. Finances | B21: Véhicules neufs | C21: Rev. Finances | D21: 0 | E21: 0 | F21: 2831.1485 | G21: 0 | H21: 0 | I21: 2831.1485 | K21: 235.93391 | L21: 10852.96 | N21: 8021.8115 | P21: 0 | Q21: 0 | R21: -235.93391 | S21: 10852.96
A22: Véhicules neufsRev. Protections | B22: Véhicules neufs | C22: Rev. Protections | D22: 0 | E22: 0 | F22: 75715.126 | G22: 0 | H22: 0 | I22: 75715.126 | K22: 1009.41 | L22: 46432.86 | N22: -29282.266 | P22: 765.23471 | Q22: 66575.42 | R22: -1009.41 | S22: -20142.56
A23: Véhicules neufsRev. Autres | B23: Véhicules neufs | C23: Rev. Autres | D23: 0 | E23: 0 | F23: 1873.9666 | G23: 0 | H23: 0 | I23: 1873.9666 | K23: 6.1243478 | L23: 281.72 | N23: -1592.2466 | P23: 18.082414 | Q23: 1573.17 | R23: -6.1243478 | S23: -1291.45
A24: Véhicules neufsTotal F&I | B24: Véhicules neufs | C24: Total F&I | D24: 94.612048 | E24: 850 | F24: 80420.241 | G24: 94.612048 | H24: 850 | I24: 80420.241 | J24: 46 | K24: 1251.4683 | L24: 57567.54 | M24: -48.612048 | N24: -22852.701 | O24: 87 | P24: 783.31713 | Q24: 68148.59 | S24: -10581.05
A25: Véhicules neufs | B25: Véhicules neufs | N25: -0.28416603 | S25: -0.1552644
A26: Véhicules neufs | B26: Véhicules neufs
A27: Véhicules neufsTotal Dépt. Neufs | B27: Véhicules neufs | C27: Total Dépt. Neufs | D27: 96.068433 | E27: 2818.0758 | F27: 270728.12 | G27: 96.068433 | H27: 2818.0758 | I27: 270728.12 | J27: 46 | K27: 5302.2324 | L27: 243902.69 | M27: -50.068433 | N27: -26825.43 | O27: 91 | P27: 2681.4854 | Q27: 244015.17 | R27: -45 | S27: -112.48
A28: Véhicules neufs | B28: Véhicules neufs | M28: -0.52117466 | N28: -0.099086236 | R28: -0.49450549 | S28: -0.00046095495
A29: Véhicules neufs | B29: Véhicules neufs
A30: Véhicules neufsDEPENSES | B30: Véhicules neufs | C30: DEPENSES
A31: Véhicules neufsComm. vendeurs | B31: Véhicules neufs | C31: Comm. vendeurs | D31: 0.31286677 | E31: 592.14929 | F31: 56024.457 | G31: 0.31286677 | H31: 592.14929 | I31: 56024.457 | J31: 0.28520487 | K31: 1092.3476 | L31: 50247.99 | N31: -5776.4671 | P31: 611.33368 | Q31: 53186.03 | S31: -2938.04
A32: Véhicules neufsComm. F&I | B32: Véhicules neufs | C32: Comm. F&I | D32: 0.3 | E32: 255 | F32: 24126.072 | G32: 0.3 | H32: 255 | I32: 24126.072 | J32: 0.36279907 | K32: 454.03152 | L32: 20885.45 | N32: -3240.6223 | P32: 240.78989 | Q32: 20948.72 | S32: -63.27 | U32: 0.29703872 | V32: <<- F&A total Neuf Usagé Rachat
A33: Véhicules neufsFrais de livraison | B33: Véhicules neufs | C33: Frais de livraison | E33: 167.8493 | F33: 15880.566 | H33: 167.8493 | I33: 15880.566 | K33: 104.73239 | L33: 4817.69 | N33: -11062.876 | P33: 74.75069 | Q33: 6503.31 | S33: -1685.62
A34: Véhicules neufsService gratuit 1 | B34: Véhicules neufs | C34: Service gratuit 1 | E34: 7.3548076 | F34: 695.85341 | H34: 7.3548076 | I34: 695.85341 | K34: 0 | L34: 0 | N34: -695.85341 | P34: 6.8565517 | Q34: 596.52 | S34: -596.52
A35: Véhicules neufsEntretien stock | B35: Véhicules neufs | C35: Entretien stock | E35: 17.733118 | F35: 1677.7666 | H35: 17.733118 | I35: 1677.7666 | K35: 100.76913 | L35: 4635.38 | N35: 2957.6134 | P35: 13.448276 | Q35: 1170 | S35: 3465.38
A36: Véhicules neufsPublicité 1 | B36: Véhicules neufs | C36: Publicité 1 | E36: 195.93765 | F36: 18538.063 | H36: 195.93765 | I36: 18538.063 | K36: 382.71152 | L36: 17604.73 | N36: -933.33265 | P36: 119.94092 | Q36: 10434.86 | S36: 7169.87
A37: Véhicules neufsIntérêt de gros | B37: Véhicules neufs | C37: Intérêt de gros | E37: 83.856314 | F37: 7933.8176 | H37: 83.856314 | I37: 7933.8176 | K37: 5.9121739 | L37: 271.96 | N37: -7661.8576 | P37: 161.06483 | Q37: 14012.64 | S37: -13740.68
A38: Véhicules neufs[...] | B38: Véhicules neufs | C38: [...] | E38: 0 | F38: 0 | H38: 0 | I38: 0 | K38: 0 | L38: 0 | N38: 0 | P38: 0 | Q38: 0 | S38: 0
A39: Véhicules neufs[...] | B39: Véhicules neufs | C39: [...] | E39: 0 | F39: 0 | H39: 0 | I39: 0 | K39: 0 | L39: 0 | N39: 0 | P39: 0 | Q39: 0 | S39: 0
A40: Véhicules neufs[...] | B40: Véhicules neufs | C40: [...] | E40: 0 | F40: 0 | H40: 0 | I40: 0 | K40: 0 | L40: 0 | N40: 0 | P40: 0 | Q40: 0 | S40: 0
...

Sheet VW 2022-06
C1: Volks | K1: Véhicules neufs | S1: Réalisé, Juin 2022
D2: X | E2: O | F2: U | G2: X | H2: O | I2: U | J2: NB | L2: $ | O2: NB | Q2: $ | V2: *** *** NE PAS EFFACER *** ***
D3: BUDGET ORIGINAL | G3: BUDGET REVISE | J3: RÉALISATION | M3: ÉCART réel / révisé | O3: ANNÉE PRÉCÉDENTE | R3: ÉCART réel / original | V3: NEUF | W3: 0.45
D4: UNITE | E4: $P/UNITÉ | F4: $PROFITS | G4: UNITE | H4: $P/UNITÉ | I4: $PROFITS | J4: UNITE | K4: $P/UNITE | L4: $PROFITS | M4: UNITÉ | N4: $PROFITS | O4: UNITE | P4: $P/UNITE | Q4: $PROFITS | R4: UNITE | S4: $PROFITS | V4: USAGE | W4: 0.1
A5: Véhicules neufsVentes nettes | B5: Véhicules neufs | C5: Ventes nettes | F5: 2936799 | I5: 2936799 | L5: 2836768.3 | Q5: 3829078.6 | V5: SERVICE | W5: 0.225
A6: Véhicules neufsAutos détail | B6: Véhicules neufs | C6: Autos détail | D6: 14.978313 | E6: 1450.6298 | F6: 21727.987 | G6: 14.978313 | H6: 1450.6298 | I6: 21727.987 | J6: 9 | K6: 2603.6256 | L6: 23432.63 | M6: -5.9783133 | N6: 1704.643 | O6: 25 | P6: 1020.836 | Q6: 25520.9 | R6: -16 | S6: -2088.27 | V6: CARROSSERIE | W6: 0.025
A7: Véhicules neufsCamions détail | B7: Véhicules neufs | C7: Camions détail | D7: 51.710843 | E7: 2081.8276 | F7: 107653.06 | G7: 51.710843 | H7: 2081.8276 | I7: 107653.06 | J7: 43 | K7: 3826.4693 | L7: 164538.18 | M7: -8.7108434 | N7: 56885.12 | O7: 58 | P7: 2126.4852 | Q7: 123336.14 | R7: -15 | S7: 41202.04 | V7: PIECES | W7: 0.2
A8: Véhicules neufsSprinter | B8: Véhicules neufs | C8: Sprinter | D8: 0 | E8: 0 | F8: 0 | G8: 0 | H8: 0 | I8: 0 | J8: 0 | K8: 0 | L8: 0 | M8: 0 | N8: 0 | O8: 0 | P8: 0 | Q8: 0 | R8: 0 | S8: 0 | W8: 1
A9: Véhicules neufsMoto détail | B9: Véhicules neufs | C9: Moto détail | D9: 0 | E9: 0 | F9: 0 | G9: 0 | H9: 0 | I9: 0 | J9: 0 | K9: 0 | L9: 0 | M9: 0 | N9: 0 | O9: 0 | P9: 0 | Q9: 0 | R9: 0 | S9: 0
A10: Véhicules neufs[...] | B10: Véhicules neufs | C10: [...] | D10: 0 | E10: 0 | F10: 0 | G10: 0 | H10: 0 | I10: 0 | J10: 0 | K10: 0 | L10: 0 | M10: 0 | N10: 0 | O10: 0 | P10: 0 | Q10: 0 | R10: 0 | S10: 0
A11: Véhicules neufs[...] | B11: Véhicules neufs | C11: [...] | D11: 0 | E11: 0 | F11: 0 | G11: 0 | H11: 0 | I11: 0 | J11: 0 | K11: 0 | L11: 0 | M11: 0 | N11: 0 | O11: 0 | P11: 0 | Q11: 0 | R11: 0 | S11: 0
A12: Véhicules neufs[...] | B12: Véhicules neufs | C12: [...] | D12: 0 | E12: 0 | F12: 0 | G12: 0 | H12: 0 | I12: 0 | J12: 0 | K12: 0 | L12: 0 | M12: 0 | N12: 0 | O12: 0 | P12: 0 | Q12: 0 | R12: 0 | S12: 0
A13: Véhicules neufsTotal Neufs | B13: Véhicules neufs | C13: Total Neufs | D13: 66.689157 | E13: 1940.0612 | F13: 129381.05 | G13: 66.689157 | H13: 1940.0612 | I13: 129381.05 | J13: 52 | K13: 3614.8233 | L13: 187970.81 | M13: -14.689157 | N13: 58589.763 | O13: 83 | P13: 1793.4583 | Q13: 148857.04 | R13: -31 | S13: 39113.77
A14: Véhicules neufs | B14: Véhicules neufs | R14: -0.37349398 | S14: 0.26276063
A15: Véhicules neufsEx-Démos et courtoisies | B15: Véhicules neufs | C15: Ex-Démos et courtoisies | D15: 6.2409639 | E15: 1386.1016 | F15: 8650.6101 | G15: 6.2409639 | H15: 1386.1016 | I15: 8650.6101 | J15: 4 | K15: 2132.36 | L15: 8529.44 | M15: -2.2409639 | N15: -121.1701 | O15: 4 | P15: 2427.275 | Q15: 9709.1 | R15: 0 | S15: -1179.66
A16: Véhicules neufs | B16: Véhicules neufs
A17: Véhicules neufsFlottes | B17: Véhicules neufs | C17: Flottes | D17: 1.1226296 | E17: 1938.8732 | F17: 2176.6364 | G17: 1.1226296 | H17: 1938.8732 | I17: 2176.6364 | J17: 0 | K17: 0 | L17: 0 | M17: -1.1226296 | N17: -2176.6364 | O17: 4 | P17: 2789.6125 | Q17: 11158.45 | R17: -4 | S17: -11158.45
A18: Véhicules neufs | B18: Véhicules neufs
A19: Véhicules neufsRachat bail | B19: Véhicules neufs | C19: Rachat bail | D19: 0 | E19: 0 | F19: 8416.039 | G19: 0 | H19: 0 | I19: 8416.039 | L19: 13151.1 | N19: 4735.061 | Q19: 6141.99 | R19: 0 | S19: 7009.11
A20: Véhicules neufs | B20: Véhicules neufs
A21: Véhicules neufsRev. Finances | B21: Véhicules neufs | C21: Rev. Finances | D21: 0 | E21: 0 | F21: 2182.3436 | G21: 0 | H21: 0 | I21: 2182.3436 | K21: 228.50482 | L21: 12796.27 | N21: 10613.926 | P21: 0 | Q21: 0 | R21: -228.50482 | S21: 12796.27
A22: Véhicules neufsRev. Protections | B22: Véhicules neufs | C22: Rev. Protections | D22: 0 | E22: 0 | F22: 58363.743 | G22: 0 | H22: 0 | I22: 58363.743 | K22: 947.25268 | L22: 53046.15 | N22: -5317.5929 | P22: 765.23471 | Q22: 66575.42 | R22: -947.25268 | S22: -13529.27
A23: Véhicules neufsRev. Autres | B23: Véhicules neufs | C23: Rev. Autres | D23: 0 | E23: 0 | F23: 1444.5159 | G23: 0 | H23: 0 | I23: 1444.5159 | K23: 13.778571 | L23: 771.6 | N23: -672.9159 | P23: 18.082414 | Q23: 1573.17 | R23: -13.778571 | S23: -801.57
A24: Véhicules neufsTotal F&I | B24: Véhicules neufs | C24: Total F&I | D24: 72.93012 | E24: 850 | F24: 61990.602 | G24: 72.93012 | H24: 850 | I24: 61990.602 | J24: 56 | K24: 1189.5361 | L24: 66614.02 | M24: -16.93012 | N24: 4623.4176 | O24: 87 | P24: 783.31713 | Q24: 68148.59 | S24: -1534.57
A25: Véhicules neufs | B25: Véhicules neufs | N25: 0.074582556 | S25: -0.022518001
A26: Véhicules neufs | B26: Véhicules neufs
A27: Véhicules neufsTotal Dépt. Neufs | B27: Véhicules neufs | C27: Total Dépt. Neufs | D27: 74.05275 | E27: 2844.1204 | F27: 210614.94 | G27: 74.05275 | H27: 2844.1204 | I27: 210614.94 | J27: 56 | K27: 4933.3102 | L27: 276265.37 | M27: -18.05275 | N27: 65650.435 | O27: 91 | P27: 2681.4854 | Q27: 244015.17 | R27: -35 | S27: 32250.2
A28: Véhicules neufs | B28: Véhicules neufs | M28: -0.2437823 | N28: 0.31170835 | R28: -0.38461538 | S28: 0.13216473
A29: Véhicules neufs | B29: Véhicules neufs
A30: Véhicules neufsDEPENSES | B30: Véhicules neufs | C30: DEPENSES
A31: Véhicules neufsComm. vendeurs | B31: Véhicules neufs | C31: Comm. vendeurs | D31: 0.32744374 | E31: 619.73848 | F31: 45197.602 | G31: 0.32744374 | H31: 619.73848 | I31: 45197.602 | J31: 0.27269477 | K31: 956.86768 | L31: 53584.59 | N31: 8386.9877 | P31: 611.33368 | Q31: 53186.03 | S31: 398.56
A32: Véhicules neufsComm. F&I | B32: Véhicules neufs | C32: Comm. F&I | D32: 0.3 | E32: 255 | F32: 18597.181 | G32: 0.3 | H32: 255 | I32: 18597.181 | J32: 0.33398225 | K32: 397.28393 | L32: 22247.9 | N32: 3650.7193 | P32: 240.78989 | Q32: 20948.72 | S32: 1299.18 | U32: 0.291325 | V32: <<- F&A total Neuf Usagé Rachat
A33: Véhicules neufsFrais de livraison | B33: Véhicules neufs | C33: Frais de livraison | E33: 167.8493 | F33: 12241.27 | H33: 167.8493 | I33: 12241.27 | K33: 83.595179 | L33: 4681.33 | N33: -7559.9398 | P33: 74.75069 | Q33: 6503.31 | S33: -1821.98
A34: Véhicules neufsService gratuit 1 | B34: Véhicules neufs | C34: Service gratuit 1 | E34: 7.3548076 | F34: 536.38701 | H34: 7.3548076 | I34: 536.38701 | K34: 10.361964 | L34: 580.27 | N34: 43.882994 | P34: 6.8565517 | Q34: 596.52 | S34: -16.25
A35: Véhicules neufsEntretien stock | B35: Véhicules neufs | C35: Entretien stock | E35: 17.733118 | F35: 1293.2784 | H35: 17.733118 | I35: 1293.2784 | K35: 66.075179 | L35: 3700.21 | N35: 2406.9316 | P35: 13.448276 | Q35: 1170 | S35: 2530.21
A36: Véhicules neufsPublicité 1 | B36: Véhicules neufs | C36: Publicité 1 | E36: 195.93765 | F36: 14289.757 | H36: 195.93765 | I36: 14289.757 | K36: 151.55625 | L36: 8487.15 | N36: -5802.6066 | P36: 119.94092 | Q36: 10434.86 | S36: -1947.71
A37: Véhicules neufsIntérêt de gros | B37: Véhicules neufs | C37: Intérêt de gros | E37: 95.743292 | F37: 6982.5698 | H37: 95.743292 | I37: 6982.5698 | K37: 4.1001786 | L37: 229.61 | N37: -6752.9598 | P37: 161.06483 | Q37: 14012.64 | S37: -13783.03
A38: Véhicules neufs[...] | B38: Véhicules neufs | C38: [...] | E38: 0 | F38: 0 | H38: 0 | I38: 0 | K38: 0 | L38: 0 | N38: 0 | P38: 0 | Q38: 0 | S38: 0
A39: Véhicules neufs[...] | B39: Véhicules neufs | C39: [...] | E39: 0 | F39: 0 | H39: 0 | I39: 0 | K39: 0 | L39: 0 | N39: 0 | P39: 0 | Q39: 0 | S39: 0
A40: Véhicules neufs[...] | B40: Véhicules neufs | C40: [...] | E40: 0 | F40: 0 | H40: 0 | I40: 0 | K40: 0 | L40: 0 | N40: 0 | P40: 0 | Q40: 0 | S40: 0
...

Sheet END
