Workbook
Name _Dates_Conc: [1]Dealers!$BF$37:$KA$63
Name _scen: '[1]Scen & Sens'!$E$26
Name _scen1: '[1]Scen & Sens'!$E$27
Name _scen2: '[1]Scen & Sens'!$E$28
Name _SCenarios: '[1]Scen & Sens'!$J$26:$O$26
Name _Sens1: '[1]Scen & Sens'!$F$9
Name _Sens2: '[1]Scen & Sens'!$F$10
Name _sensRes1: '[1]Scen & Sens'!$E$15
Name _sensRes2: '[1]Scen & Sens'!$E$16
Name _sensRes3: '[1]Scen & Sens'!$E$17
Name _sensRes4: '[1]Scen & Sens'!$E$18
Name _sensRes5: '[1]Scen & Sens'!$E$19
Name _sensRes6: '[1]Scen & Sens'!$E$20
Name _sensRes7: '[1]Scen & Sens'!$E$21
Name DateRange: [1]Volkswagen!$BF$6:$DY$6
Name Monetary_Unit: [1]Parameters!$B$15
Name Months: [1]Parameters!$E$9:$E$20
Name Rng_Dealers_Names: [1]!Tbl_Dealers[Dealer Name]
Name Rng_Dlr_Dates: [1]!Tbl_V_Dlr_Dates[Date]
Name Titre: [1]Front!$A$9

Sheet Parametres
A1: Compagnie | B1: Volks
G2: 1-Mémo | M2: Mois | N2: YTD
A3: Mois Courant | B3: Juillet | C3: =+VLOOKUP(B3,$K$3:$L$14,2,0) -> 7 | G3: 10-Compte compteur | K3: Janvier | L3: 1 | M3: =+IF($K3=$B$3,"X","") | N3: =+IF(K3=B3,"X",IF(L3<=$C$3,"X","")) -> X
A4: Année | B4: 2021 | K4: Février | L4: 2 | M4: =+IF($K4=$B$3,"X","") | N4: =+IF(K4=B4,"X",IF(L4<=$C$3,"X","")) -> X
K5: Mars | L5: 3 | M5: =+IF($K5=$B$3,"X","") | N5: =+IF(K5=B5,"X",IF(L5<=$C$3,"X","")) -> X
K6: Avril | L6: 4 | M6: =+IF($K6=$B$3,"X","") | N6: =+IF(K6=B6,"X",IF(L6<=$C$3,"X","")) -> X
K7: Mai | L7: 5 | M7: =+IF($K7=$B$3,"X","") | N7: =+IF(K7=B7,"X",IF(L7<=$C$3,"X","")) -> X
K8: Juin | L8: 6 | M8: =+IF($K8=$B$3,"X","") | N8: =+IF(K8=B8,"X",IF(L8<=$C$3,"X","")) -> X
A9: Sélectionner le mois en B3 | K9: Juillet | L9: 7 | M9: =+IF($K9=$B$3,"X","") -> X | N9: =+IF(K9=B9,"X",IF(L9<=$C$3,"X","")) -> X
A10: Coller les balances de vérification respectives en cellule A1 dans les onglets BV_Data_An_Cour et BV_Data_An_Prec | K10: Août | L10: 8 | M10: =+IF($K10=$B$3,"X","") | N10: =+IF(K10=B10,"X",IF(L10<=$C$3,"X",""))
A11: Vérifier s'il y a des #N/A dans les colonnes T à X des onlgets de BV | K11: Septembre | L11: 9 | M11: =+IF($K11=$B$3,"X","") | N11: =+IF(K11=B11,"X",IF(L11<=$C$3,"X",""))
A12: Vérifier les chiffres avec l'état financier et les réalisés an passé pour les résultat net mois et aad | K12: Octobre | L12: 10 | M12: =+IF($K12=$B$3,"X","") | N12: =+IF(K12=B12,"X",IF(L12<=$C$3,"X",""))
K13: Novembre | L13: 11 | M13: =+IF($K13=$B$3,"X","") | N13: =+IF(K13=B13,"X",IF(L13<=$C$3,"X",""))
K14: Décembre | L14: 12 | M14: =+IF($K14=$B$3,"X","") | N14: =+IF(K14=B14,"X",IF(L14<=$C$3,"X",""))

Sheet Bilan
A1: BILAN
A2: =+Parametres!B1 -> Volks
A3: =CONCATENATE("",,Parametres!B3," ",Parametres!B4) -> Juillet 2021
A5: Encaisse | B5: =SUMIFS(BV_Data_An_Cour!$P:$P,BV_Data_An_Cour!$U:$U,$A$1,BV_Data_An_Cour!$V:$V,$A5) -> 2944397.2 | D5: Marge de crédit | E5: =-SUMIFS(BV_Data_An_Cour!$P:$P,BV_Data_An_Cour!$U:$U,$A$1,BV_Data_An_Cour!$V:$V,$D5) -> 0
A6: Total Trésorerie et équivalent de Trésorerie | B6: =SUM(B5) -> 2944397.2
D7: Portion Court Terme de la Dette Long Terme | E7: =-SUMIFS(BV_Data_An_Cour!$P:$P,BV_Data_An_Cour!$U:$U,$A$1,BV_Data_An_Cour!$V:$V,$D7) -> 15810
A8: Recevables Contrats en Transit | B8: =SUMIFS(BV_Data_An_Cour!$P:$P,BV_Data_An_Cour!$U:$U,$A$1,BV_Data_An_Cour!$V:$V,$A8) -> 1666307.6
A9: Recevables Véhicules | B9: =SUMIFS(BV_Data_An_Cour!$P:$P,BV_Data_An_Cour!$U:$U,$A$1,BV_Data_An_Cour!$V:$V,$A9) -> 546645.85 | D9: Avances à payer | E9: =-SUMIFS(BV_Data_An_Cour!$P:$P,BV_Data_An_Cour!$U:$U,$A$1,BV_Data_An_Cour!$V:$V,$D9) -> 0
A10: Recevables Manufacturier | B10: =SUMIFS(BV_Data_An_Cour!$P:$P,BV_Data_An_Cour!$U:$U,$A$1,BV_Data_An_Cour!$V:$V,$A10) -> 71675.2 | D10: Comptes à Payer Fournisseurs | E10: =-SUMIFS(BV_Data_An_Cour!$P:$P,BV_Data_An_Cour!$U:$U,$A$1,BV_Data_An_Cour!$V:$V,$D10) -> -33718.73
A11: Recevables Pièces et Service | B11: =SUMIFS(BV_Data_An_Cour!$P:$P,BV_Data_An_Cour!$U:$U,$A$1,BV_Data_An_Cour!$V:$V,$A11) -> 66411.53 | D11: Taxes de Vente à Payer | E11: =-SUMIFS(BV_Data_An_Cour!$P:$P,BV_Data_An_Cour!$U:$U,$A$1,BV_Data_An_Cour!$V:$V,$D11) -> 117748.01
A12: Recevables Garantie Manufacturier | B12: =SUMIFS(BV_Data_An_Cour!$P:$P,BV_Data_An_Cour!$U:$U,$A$1,BV_Data_An_Cour!$V:$V,$A12) -> 38372.53 | D12: Impôts à payer | E12: =-SUMIFS(BV_Data_An_Cour!$P:$P,BV_Data_An_Cour!$U:$U,$A$1,BV_Data_An_Cour!$V:$V,$D12) -> 0
A13: Recevables Carrosserie | B13: =SUMIFS(BV_Data_An_Cour!$P:$P,BV_Data_An_Cour!$U:$U,$A$1,BV_Data_An_Cour!$V:$V,$A13) -> 54647.81 | D13: Dépôts de Client | E13: =-SUMIFS(BV_Data_An_Cour!$P:$P,BV_Data_An_Cour!$U:$U,$A$1,BV_Data_An_Cour!$V:$V,$D13) -> 9100
A14: Recevables Intercos | B14: =SUMIFS(BV_Data_An_Cour!$P:$P,BV_Data_An_Cour!$U:$U,$A$1,BV_Data_An_Cour!$V:$V,$A14) -> 0 | D14: Payables Intercos | E14: =-SUMIFS(BV_Data_An_Cour!$P:$P,BV_Data_An_Cour!$U:$U,$A$1,BV_Data_An_Cour!$V:$V,$D14) -> 0
A15: Recevables Autres | B15: =SUMIFS(BV_Data_An_Cour!$P:$P,BV_Data_An_Cour!$U:$U,$A$1,BV_Data_An_Cour!$V:$V,$A15) -> 29985.38 | D15: Autres Comptes à Payer | E15: =-SUMIFS(BV_Data_An_Cour!$P:$P,BV_Data_An_Cour!$U:$U,$A$1,BV_Data_An_Cour!$V:$V,$D15) -> 580214.5
A16: Total Comptes à Recevoir | B16: =+SUM(B8:B15) -> 2474045.9 | D16: Total Comptes à Payer | E16: =+SUM(E10:E15) -> 673343.78
A18: Inventaire Véhicules Neufs | B18: =SUMIFS(BV_Data_An_Cour!$P:$P,BV_Data_An_Cour!$U:$U,$A$1,BV_Data_An_Cour!$V:$V,$A18) -> 3530870.4 | D18: Effet à Payer Véhicules Neufs | E18: =-SUMIFS(BV_Data_An_Cour!$P:$P,BV_Data_An_Cour!$U:$U,$A$1,BV_Data_An_Cour!$V:$V,$D18) -> 4931928.2
A19: Inventaire Véhicules Usagés | B19: =SUMIFS(BV_Data_An_Cour!$P:$P,BV_Data_An_Cour!$U:$U,$A$1,BV_Data_An_Cour!$V:$V,$A19) -> 1562180.4 | D19: Effet à Payer Véhicules Usagés | E19: =-SUMIFS(BV_Data_An_Cour!$P:$P,BV_Data_An_Cour!$U:$U,$A$1,BV_Data_An_Cour!$V:$V,$D19) -> 228133.97
A20: Inventaire Pièces, Pneus, Huile | B20: =SUMIFS(BV_Data_An_Cour!$P:$P,BV_Data_An_Cour!$U:$U,$A$1,BV_Data_An_Cour!$V:$V,$A20) -> 369414.57 | D20: Total Effets à Payer | E20: =+SUM(E18:E19) -> 5160062.2
A21: Total Inventaires | B21: =SUM(B18:B20) -> 5462465.4
D22: Salaires à Payer | E22: =-SUMIFS(BV_Data_An_Cour!$P:$P,BV_Data_An_Cour!$U:$U,$A$1,BV_Data_An_Cour!$V:$V,$D22) -> 464492.82
A23: Avances à recevoir | B23: =SUMIFS(BV_Data_An_Cour!$P:$P,BV_Data_An_Cour!$U:$U,$A$1,BV_Data_An_Cour!$V:$V,$A23) -> 0 | D23: DAS à Payer | E23: =-SUMIFS(BV_Data_An_Cour!$P:$P,BV_Data_An_Cour!$U:$U,$A$1,BV_Data_An_Cour!$V:$V,$D23) -> 29866.74
A24: Travaux en Cours | B24: =SUMIFS(BV_Data_An_Cour!$P:$P,BV_Data_An_Cour!$U:$U,$A$1,BV_Data_An_Cour!$V:$V,$A24) -> 5371.65 | D24: Autres Courus | E24: =-SUMIFS(BV_Data_An_Cour!$P:$P,BV_Data_An_Cour!$U:$U,$A$1,BV_Data_An_Cour!$V:$V,$D24) -> 22803.08
A25: Sous-Traitance | B25: =SUMIFS(BV_Data_An_Cour!$P:$P,BV_Data_An_Cour!$U:$U,$A$1,BV_Data_An_Cour!$V:$V,$A25) -> -3074.39 | D25: [...] | E25: =-SUMIFS(BV_Data_An_Cour!$P:$P,BV_Data_An_Cour!$U:$U,$A$1,BV_Data_An_Cour!$V:$V,$D25) -> 0
A26: Frais Payés d'Avance | B26: =SUMIFS(BV_Data_An_Cour!$P:$P,BV_Data_An_Cour!$U:$U,$A$1,BV_Data_An_Cour!$V:$V,$A26) -> 149519.69 | D26: [...] | E26: =-SUMIFS(BV_Data_An_Cour!$P:$P,BV_Data_An_Cour!$U:$U,$A$1,BV_Data_An_Cour!$V:$V,$D26) -> 0
A27: [...] | B27: =SUMIFS(BV_Data_An_Cour!$P:$P,BV_Data_An_Cour!$U:$U,$A$1,BV_Data_An_Cour!$V:$V,$A27) -> 0 | D27: [...] | E27: =-SUMIFS(BV_Data_An_Cour!$P:$P,BV_Data_An_Cour!$U:$U,$A$1,BV_Data_An_Cour!$V:$V,$D27) -> 0
A28: [...] | B28: =SUMIFS(BV_Data_An_Cour!$P:$P,BV_Data_An_Cour!$U:$U,$A$1,BV_Data_An_Cour!$V:$V,$A28) -> 0 | D28: Total Frais Courus | E28: =SUM(E22:E24) -> 517162.64
A29: [...] | B29: =SUMIFS(BV_Data_An_Cour!$P:$P,BV_Data_An_Cour!$U:$U,$A$1,BV_Data_An_Cour!$V:$V,$A29) -> 0
A30: Total Autres | B30: =SUM(B23:B29) -> 151816.95 | D30: Total Passif Court Terme | E30: =+E5+E7+E16+E20+E28 -> 6366378.6
A32: Total Actif Court Terme | B32: =+B6+B16+B21+B30 -> 11032725
D33: Impôts Futurs à payer | E33: =-SUMIFS(BV_Data_An_Cour!$P:$P,BV_Data_An_Cour!$U:$U,$A$1,BV_Data_An_Cour!$V:$V,$D33) -> 0
A35: Terrain | B35: =SUMIFS(BV_Data_An_Cour!$P:$P,BV_Data_An_Cour!$U:$U,$A$1,BV_Data_An_Cour!$V:$V,$A35) -> 0 | D35: Avances Long Terme à Payer | E35: =-SUMIFS(BV_Data_An_Cour!$P:$P,BV_Data_An_Cour!$U:$U,$A$1,BV_Data_An_Cour!$V:$V,$D35) -> 0
A36: Bâtisse | B36: =SUMIFS(BV_Data_An_Cour!$P:$P,BV_Data_An_Cour!$U:$U,$A$1,BV_Data_An_Cour!$V:$V,$A36) -> 0 | D36: Hypothèque à Payer | E36: =-SUMIFS(BV_Data_An_Cour!$P:$P,BV_Data_An_Cour!$U:$U,$A$1,BV_Data_An_Cour!$V:$V,$D36) -> 0
A37: Améliorations Locatives | B37: =SUMIFS(BV_Data_An_Cour!$P:$P,BV_Data_An_Cour!$U:$U,$A$1,BV_Data_An_Cour!$V:$V,$A37) -> 1124.31 | D37: Dette à Long Terme | E37: =-SUMIFS(BV_Data_An_Cour!$P:$P,BV_Data_An_Cour!$U:$U,$A$1,BV_Data_An_Cour!$V:$V,$D37) -> 18936.25
A38: Améliorations Locatives Permanentes | B38: =SUMIFS(BV_Data_An_Cour!$P:$P,BV_Data_An_Cour!$U:$U,$A$1,BV_Data_An_Cour!$V:$V,$A38) -> 0 | D38: Autres Dettes à Long Terme | E38: =-SUMIFS(BV_Data_An_Cour!$P:$P,BV_Data_An_Cour!$U:$U,$A$1,BV_Data_An_Cour!$V:$V,$D38) -> 0
A39: Équipements Service | B39: =SUMIFS(BV_Data_An_Cour!$P:$P,BV_Data_An_Cour!$U:$U,$A$1,BV_Data_An_Cour!$V:$V,$A39) -> 170958.8 | D39: [...] | E39: =-SUMIFS(BV_Data_An_Cour!$P:$P,BV_Data_An_Cour!$U:$U,$A$1,BV_Data_An_Cour!$V:$V,$D39) -> 0
A40: Mobilier | B40: =SUMIFS(BV_Data_An_Cour!$P:$P,BV_Data_An_Cour!$U:$U,$A$1,BV_Data_An_Cour!$V:$V,$A40) -> 33260.95 | D40: [...] | E40: =-SUMIFS(BV_Data_An_Cour!$P:$P,BV_Data_An_Cour!$U:$U,$A$1,BV_Data_An_Cour!$V:$V,$D40) -> 0
A41: Équipements Informatique | B41: =SUMIFS(BV_Data_An_Cour!$P:$P,BV_Data_An_Cour!$U:$U,$A$1,BV_Data_An_Cour!$V:$V,$A41) -> 21190.07 | D41: [...] | E41: =-SUMIFS(BV_Data_An_Cour!$P:$P,BV_Data_An_Cour!$U:$U,$A$1,BV_Data_An_Cour!$V:$V,$D41) -> 0
A42: Équipements Téléphonique | B42: =SUMIFS(BV_Data_An_Cour!$P:$P,BV_Data_An_Cour!$U:$U,$A$1,BV_Data_An_Cour!$V:$V,$A42) -> 0 | D42: Total Passif long terme | E42: =+SUM(E33:E38) -> 18936.25
A43: Enseigne | B43: =SUMIFS(BV_Data_An_Cour!$P:$P,BV_Data_An_Cour!$U:$U,$A$1,BV_Data_An_Cour!$V:$V,$A43) -> 0.01
A44: Total Immobilisations Nettes | B44: =SUM(B35:B43) -> 226534.14
...

Sheet Budget original
B1: ="Budget 2021 Mensuel Révisé"&" "&Parametres!$B$1 -> Budget 2021 Mensuel Révisé Volks
B2: Mois | F2: =+IF(Parametres!$B$3=F$6,"X","") | G2: =+IF(Parametres!$B$3=F$6,"O","") | H2: =+IF(Parametres!$B$3=F$6,"U","") | I2: =+IF(Parametres!$B$3=I$6,"X","") | J2: =+IF(Parametres!$B$3=I$6,"O","") | K2: =+IF(Parametres!$B$3=I$6,"U","") | L2: =+IF(Parametres!$B$3=L$6,"X","") | M2: =+IF(Parametres!$B$3=L$6,"O","") | N2: =+IF(Parametres!$B$3=L$6,"U","") | O2: =+IF(Parametres!$B$3=O$6,"X","") | P2: =+IF(Parametres!$B$3=O$6,"O","") | Q2: =+IF(Parametres!$B$3=O$6,"U","") | R2: =+IF(Parametres!$B$3=R$6,"X","") | S2: =+IF(Parametres!$B$3=R$6,"O","") | T2: =+IF(Parametres!$B$3=R$6,"U","") | U2: =+IF(Parametres!$B$3=U$6,"X","") | V2: =+IF(Parametres!$B$3=U$6,"O","") | W2: =+IF(Parametres!$B$3=U$6,"U","") | X2: =+IF(Parametres!$B$3=X$6,"X","") -> X | Y2: =+IF(Parametres!$B$3=X$6,"O","") -> O | Z2: =+IF(Parametres!$B$3=X$6,"U","") -> U | AA2: =+IF(Parametres!$B$3=AA$6,"X","") | AB2: =+IF(Parametres!$B$3=AA$6,"O","") | AC2: =+IF(Parametres!$B$3=AA$6,"U","") | AD2: =+IF(Parametres!$B$3=AD$6,"X","") | AE2: =+IF(Parametres!$B$3=AD$6,"O","") | AF2: =+IF(Parametres!$B$3=AD$6,"U","") | AG2: =+IF(Parametres!$B$3=AG$6,"X","") | AH2: =+IF(Parametres!$B$3=AG$6,"O","") | AI2: =+IF(Parametres!$B$3=AG$6,"U","") | AJ2: =+IF(Parametres!$B$3=AJ$6,"X","") | AK2: =+IF(Parametres!$B$3=AJ$6,"O","") | AL2: =+IF(Parametres!$B$3=AJ$6,"U","") | AM2: =+IF(Parametres!$B$3=AM$6,"X","") | AN2: =+IF(Parametres!$B$3=AM$6,"O","") | AO2: =+IF(Parametres!$B$3=AM$6,"U","")
B3: YTD | F3: =+IF(VLOOKUP(F$6,Parametres!$K$3:$N$14,4,0)="X","X","") -> X | G3: =+IF(VLOOKUP(F$6,Parametres!$K$3:$N$14,4,0)="X","O","") -> O | H3: =+IF(VLOOKUP(F$6,Parametres!$K$3:$N$14,4,0)="X","U","") -> U | I3: =+IF(VLOOKUP(I$6,Parametres!$K$3:$N$14,4,0)="X","X","") -> X | J3: =+IF(VLOOKUP(I$6,Parametres!$K$3:$N$14,4,0)="X","O","") -> O | K3: =+IF(VLOOKUP(I$6,Parametres!$K$3:$N$14,4,0)="X","U","") -> U | L3: =+IF(VLOOKUP(L$6,Parametres!$K$3:$N$14,4,0)="X","X","") -> X | M3: =+IF(VLOOKUP(L$6,Parametres!$K$3:$N$14,4,0)="X","O","") -> O | N3: =+IF(VLOOKUP(L$6,Parametres!$K$3:$N$14,4,0)="X","U","") -> U | O3: =+IF(VLOOKUP(O$6,Parametres!$K$3:$N$14,4,0)="X","X","") -> X | P3: =+IF(VLOOKUP(O$6,Parametres!$K$3:$N$14,4,0)="X","O","") -> O | Q3: =+IF(VLOOKUP(O$6,Parametres!$K$3:$N$14,4,0)="X","U","") -> U | R3: =+IF(VLOOKUP(R$6,Parametres!$K$3:$N$14,4,0)="X","X","") -> X | S3: =+IF(VLOOKUP(R$6,Parametres!$K$3:$N$14,4,0)="X","O","") -> O | T3: =+IF(VLOOKUP(R$6,Parametres!$K$3:$N$14,4,0)="X","U","") -> U | U3: =+IF(VLOOKUP(U$6,Parametres!$K$3:$N$14,4,0)="X","X","") -> X | V3: =+IF(VLOOKUP(U$6,Parametres!$K$3:$N$14,4,0)="X","O","") -> O | W3: =+IF(VLOOKUP(U$6,Parametres!$K$3:$N$14,4,0)="X","U","") -> U | X3: =+IF(VLOOKUP(X$6,Parametres!$K$3:$N$14,4,0)="X","X","") -> X | Y3: =+IF(VLOOKUP(X$6,Parametres!$K$3:$N$14,4,0)="X","O","") -> O | Z3: =+IF(VLOOKUP(X$6,Parametres!$K$3:$N$14,4,0)="X","U","") -> U | AA3: =+IF(VLOOKUP(AA$6,Parametres!$K$3:$N$14,4,0)="X","X","") | AB3: =+IF(VLOOKUP(AA$6,Parametres!$K$3:$N$14,4,0)="X","O","") | AC3: =+IF(VLOOKUP(AA$6,Parametres!$K$3:$N$14,4,0)="X","U","") | AD3: =+IF(VLOOKUP(AD$6,Parametres!$K$3:$N$14,4,0)="X","X","") | AE3: =+IF(VLOOKUP(AD$6,Parametres!$K$3:$N$14,4,0)="X","O","") | AF3: =+IF(VLOOKUP(AD$6,Parametres!$K$3:$N$14,4,0)="X","U","") | AG3: =+IF(VLOOKUP(AG$6,Parametres!$K$3:$N$14,4,0)="X","X","") | AH3: =+IF(VLOOKUP(AG$6,Parametres!$K$3:$N$14,4,0)="X","O","") | AI3: =+IF(VLOOKUP(AG$6,Parametres!$K$3:$N$14,4,0)="X","U","") | AJ3: =+IF(VLOOKUP(AJ$6,Parametres!$K$3:$N$14,4,0)="X","X","") | AK3: =+IF(VLOOKUP(AJ$6,Parametres!$K$3:$N$14,4,0)="X","O","") | AL3: =+IF(VLOOKUP(AJ$6,Parametres!$K$3:$N$14,4,0)="X","U","") | AM3: =+IF(VLOOKUP(AM$6,Parametres!$K$3:$N$14,4,0)="X","X","") | AN3: =+IF(VLOOKUP(AM$6,Parametres!$K$3:$N$14,4,0)="X","O","") | AO3: =+IF(VLOOKUP(AM$6,Parametres!$K$3:$N$14,4,0)="X","U","")
B4: Budget 2021 | C4: Véhicules neufs
B6: Mois | C6: 2021 | F6: Janvier | I6: Février | L6: Mars | O6: Avril | R6: Mai | U6: Juin | X6: Juillet | AA6: Août | AD6: Septembre | AG6: Octobre | AJ6: Novembre | AM6: Décembre
C7: UNITE | D7: $P/UNITE | E7: $PROFITS | F7: UNITE | G7: $P/UNITE | H7: $PROFITS | I7: UNITE | J7: $P/UNITE | K7: $PROFITS | L7: UNITE | M7: $P/UNITE | N7: $PROFITS | O7: UNITE | P7: $P/UNITE | Q7: $PROFITS | R7: UNITE | S7: $P/UNITE | T7: $PROFITS | U7: UNITE | V7: $P/UNITE | W7: $PROFITS | X7: UNITE | Y7: $P/UNITE | Z7: $PROFITS | AA7: UNITE | AB7: $P/UNITE | AC7: $PROFITS | AD7: UNITE | AE7: $P/UNITE | AF7: $PROFITS | AG7: UNITE | AH7: $P/UNITE | AI7: $PROFITS | AJ7: UNITE | AK7: $P/UNITE | AL7: $PROFITS | AM7: UNITE | AN7: $P/UNITE | AO7: $PROFITS
A8: =+$C$4&B8 -> Véhicules neufsVentes nettes | B8: Ventes nettes | E8: =+SUM(H8,K8,N8,Q8,T8,W8,Z8,AC8,AF8,AI8,AL8,AO8) -> 9553310.1 | H8: 1882577.9 | K8: 446219.11 | N8: 678330.08 | Q8: 751340.66 | T8: 981796.55 | W8: 691716.4 | Z8: 688676.89 | AC8: 729220.97 | AF8: 799077.54 | AI8: 991144.07 | AL8: 576007.02 | AO8: 337202.89
A9: =+$C$4&B9 -> Véhicules neufsAutos détail | B9: Autos détail | C9: =+SUM(F9,I9,L9,O9,R9,U9,X9,AA9,AD9,AG9,AJ9,AM9) -> 303 | D9: =IF(C9=0,0,E9/C9) -> 955.05622 | E9: =+SUM(H9,K9,N9,Q9,T9,W9,Z9,AC9,AF9,AI9,AL9,AO9) -> 289382.03 | F9: 23.607096 | G9: =IF(F9=0,0,H9/F9) -> 955.05622 | H9: 22546.103 | I9: 16.252745 | J9: =IF(I9=0,0,K9/I9) -> 955.05622 | K9: 15522.285 | L9: 24.706978 | M9: =IF(L9=0,0,N9/L9) -> 955.05622 | N9: 23596.553 | O9: 27.36626 | P9: =IF(O9=0,0,Q9/O9) -> 955.05622 | Q9: 26136.316 | R9: 35.76021 | S9: =IF(R9=0,0,T9/R9) -> 955.05622 | T9: 34153.01 | U9: 25.194551 | V9: =IF(U9=0,0,W9/U9) -> 955.05622 | W9: 24062.213 | X9: 25.083842 | Y9: =IF(X9=0,0,Z9/X9) -> 955.05622 | Z9: 23956.48 | AA9: 26.560589 | AB9: =IF(AA9=0,0,AC9/AA9) -> 955.05622 | AC9: 25366.856 | AD9: 29.104991 | AE9: =IF(AD9=0,0,AF9/AD9) -> 955.05622 | AF9: 27796.903 | AG9: 36.100676 | AH9: =IF(AG9=0,0,AI9/AG9) -> 955.05622 | AI9: 34478.176 | AJ9: 20.980041 | AK9: =IF(AJ9=0,0,AL9/AJ9) -> 955.05622 | AL9: 20037.118 | AM9: 12.282021 | AN9: =IF(AM9=0,0,AO9/AM9) -> 955.05622 | AO9: 11730.021
A10: =+$C$4&B10 -> Véhicules neufsCamions détail | B10: Camions détail | C10: =+SUM(F10,I10,L10,O10,R10,U10,X10,AA10,AD10,AG10,AJ10,AM10) -> 407 | D10: =IF(C10=0,0,E10/C10) -> 1702.6669 | E10: =+SUM(H10,K10,N10,Q10,T10,W10,Z10,AC10,AF10,AI10,AL10,AO10) -> 692985.42 | F10: 31.709861 | G10: =IF(F10=0,0,H10/F10) -> 1702.6669 | H10: 53991.33 | I10: 21.831245 | J10: =IF(I10=0,0,K10/I10) -> 1702.6669 | K10: 37171.338 | L10: 33.187261 | M10: =IF(L10=0,0,N10/L10) -> 1702.6669 | N10: 56506.85 | O10: 36.759299 | P10: =IF(O10=0,0,Q10/O10) -> 1702.6669 | Q10: 62588.841 | R10: 48.034341 | S10: =IF(R10=0,0,T10/R10) -> 1702.6669 | T10: 81786.481 | U10: 33.842186 | V10: =IF(U10=0,0,W10/U10) -> 1702.6669 | W10: 57621.969 | X10: 33.693478 | Y10: =IF(X10=0,0,Z10/X10) -> 1702.6669 | Z10: 57368.769 | AA10: 35.677095 | AB10: =IF(AA10=0,0,AC10/AA10) -> 1702.6669 | AC10: 60746.208 | AD10: 39.094824 | AE10: =IF(AD10=0,0,AF10/AD10) -> 1702.6669 | AF10: 66565.461 | AG10: 48.491668 | AH10: =IF(AG10=0,0,AI10/AG10) -> 1702.6669 | AI10: 82565.157 | AJ10: 28.181111 | AK10: =IF(AJ10=0,0,AL10/AJ10) -> 1702.6669 | AL10: 47983.044 | AM10: 16.497633 | AN10: =IF(AM10=0,0,AO10/AM10) -> 1702.6669 | AO10: 28089.973
A11: =+$C$4&B11 -> Véhicules neufsSprinter | B11: Sprinter | C11: =+SUM(F11,I11,L11,O11,R11,U11,X11,AA11,AD11,AG11,AJ11,AM11) -> 0 | D11: =IF(C11=0,0,E11/C11) -> 0 | E11: =+SUM(H11,K11,N11,Q11,T11,W11,Z11,AC11,AF11,AI11,AL11,AO11) -> 0 | G11: =IF(F11=0,0,H11/F11) -> 0 | J11: =IF(I11=0,0,K11/I11) -> 0 | M11: =IF(L11=0,0,N11/L11) -> 0 | P11: =IF(O11=0,0,Q11/O11) -> 0 | S11: =IF(R11=0,0,T11/R11) -> 0 | V11: =IF(U11=0,0,W11/U11) -> 0 | Y11: =IF(X11=0,0,Z11/X11) -> 0 | AB11: =IF(AA11=0,0,AC11/AA11) -> 0 | AE11: =IF(AD11=0,0,AF11/AD11) -> 0 | AH11: =IF(AG11=0,0,AI11/AG11) -> 0 | AK11: =IF(AJ11=0,0,AL11/AJ11) -> 0 | AN11: =IF(AM11=0,0,AO11/AM11) -> 0
A12: =+$C$4&B12 -> Véhicules neufsMoto détail | B12: Moto détail | C12: =+SUM(F12,I12,L12,O12,R12,U12,X12,AA12,AD12,AG12,AJ12,AM12) -> 0 | D12: =IF(C12=0,0,E12/C12) -> 0 | E12: =+SUM(H12,K12,N12,Q12,T12,W12,Z12,AC12,AF12,AI12,AL12,AO12) -> 0 | G12: =IF(F12=0,0,H12/F12) -> 0 | J12: =IF(I12=0,0,K12/I12) -> 0 | M12: =IF(L12=0,0,N12/L12) -> 0 | P12: =IF(O12=0,0,Q12/O12) -> 0 | S12: =IF(R12=0,0,T12/R12) -> 0 | V12: =IF(U12=0,0,W12/U12) -> 0 | Y12: =IF(X12=0,0,Z12/X12) -> 0 | AB12: =IF(AA12=0,0,AC12/AA12) -> 0 | AE12: =IF(AD12=0,0,AF12/AD12) -> 0 | AH12: =IF(AG12=0,0,AI12/AG12) -> 0 | AK12: =IF(AJ12=0,0,AL12/AJ12) -> 0 | AN12: =IF(AM12=0,0,AO12/AM12) -> 0
A13: =+$C$4&B13 -> Véhicules neufs[...] | B13: [...] | C13: =+SUM(F13,I13,L13,O13,R13,U13,X13,AA13,AD13,AG13,AJ13,AM13) -> 0 | D13: =IF(C13=0,0,E13/C13) -> 0 | E13: =+SUM(H13,K13,N13,Q13,T13,W13,Z13,AC13,AF13,AI13,AL13,AO13) -> 0 | G13: =IF(F13=0,0,H13/F13) -> 0 | J13: =IF(I13=0,0,K13/I13) -> 0 | M13: =IF(L13=0,0,N13/L13) -> 0 | P13: =IF(O13=0,0,Q13/O13) -> 0 | S13: =IF(R13=0,0,T13/R13) -> 0 | V13: =IF(U13=0,0,W13/U13) -> 0 | Y13: =IF(X13=0,0,Z13/X13) -> 0 | AB13: =IF(AA13=0,0,AC13/AA13) -> 0 | AE13: =IF(AD13=0,0,AF13/AD13) -> 0 | AH13: =IF(AG13=0,0,AI13/AG13) -> 0 | AK13: =IF(AJ13=0,0,AL13/AJ13) -> 0 | AN13: =IF(AM13=0,0,AO13/AM13) -> 0
A14: =+$C$4&B14 -> Véhicules neufs[...] | B14: [...] | C14: =+SUM(F14,I14,L14,O14,R14,U14,X14,AA14,AD14,AG14,AJ14,AM14) -> 0 | D14: =IF(C14=0,0,E14/C14) -> 0 | E14: =+SUM(H14,K14,N14,Q14,T14,W14,Z14,AC14,AF14,AI14,AL14,AO14) -> 0 | G14: =IF(F14=0,0,H14/F14) -> 0 | J14: =IF(I14=0,0,K14/I14) -> 0 | M14: =IF(L14=0,0,N14/L14) -> 0 | P14: =IF(O14=0,0,Q14/O14) -> 0 | S14: =IF(R14=0,0,T14/R14) -> 0 | V14: =IF(U14=0,0,W14/U14) -> 0 | Y14: =IF(X14=0,0,Z14/X14) -> 0 | AB14: =IF(AA14=0,0,AC14/AA14) -> 0 | AE14: =IF(AD14=0,0,AF14/AD14) -> 0 | AH14: =IF(AG14=0,0,AI14/AG14) -> 0 | AK14: =IF(AJ14=0,0,AL14/AJ14) -> 0 | AN14: =IF(AM14=0,0,AO14/AM14) -> 0
A15: =+$C$4&B15 -> Véhicules neufs[...] | B15: [...] | C15: =+SUM(F15,I15,L15,O15,R15,U15,X15,AA15,AD15,AG15,AJ15,AM15) -> 0 | D15: =IF(C15=0,0,E15/C15) -> 0 | E15: =+SUM(H15,K15,N15,Q15,T15,W15,Z15,AC15,AF15,AI15,AL15,AO15) -> 0 | G15: =IF(F15=0,0,H15/F15) -> 0 | J15: =IF(I15=0,0,K15/I15) -> 0 | M15: =IF(L15=0,0,N15/L15) -> 0 | P15: =IF(O15=0,0,Q15/O15) -> 0 | S15: =IF(R15=0,0,T15/R15) -> 0 | V15: =IF(U15=0,0,W15/U15) -> 0 | Y15: =IF(X15=0,0,Z15/X15) -> 0 | AB15: =IF(AA15=0,0,AC15/AA15) -> 0 | AE15: =IF(AD15=0,0,AF15/AD15) -> 0 | AH15: =IF(AG15=0,0,AI15/AG15) -> 0 | AK15: =IF(AJ15=0,0,AL15/AJ15) -> 0 | AN15: =IF(AM15=0,0,AO15/AM15) -> 0
A16: =+$C$4&B16 -> Véhicules neufsTotal Neufs | B16: Total Neufs | C16: =+SUM(C9:C15) -> 710 | D16: =IF(C16<=0,0,E16/C16) -> 1383.6161 | E16: =+SUM(E9:E15) -> 982367.45 | F16: =+SUM(F9:F15) -> 55.316957 | G16: =IF(F16<=0,0,H16/F16) -> 1383.6161 | H16: =+SUM(H9:H15) -> 76537.434 | I16: =+SUM(I9:I15) -> 38.08399 | J16: =IF(I16<=0,0,K16/I16) -> 1383.6161 | K16: =+SUM(K9:K15) -> 52693.623 | L16: =+SUM(L9:L15) -> 57.894239 | M16: =IF(L16<=0,0,N16/L16) -> 1383.6161 | N16: =+SUM(N9:N15) -> 80103.403 | O16: =+SUM(O9:O15) -> 64.125559 | P16: =IF(O16<=0,0,Q16/O16) -> 1383.6161 | Q16: =+SUM(Q9:Q15) -> 88725.158 | R16: =+SUM(R9:R15) -> 83.79455 | S16: =IF(R16<=0,0,T16/R16) -> 1383.6161 | T16: =+SUM(T9:T15) -> 115939.49 | U16: =+SUM(U9:U15) -> 59.036736 | V16: =IF(U16<=0,0,W16/U16) -> 1383.6161 | W16: =+SUM(W9:W15) -> 81684.181 | X16: =+SUM(X9:X15) -> 58.77732 | Y16: =IF(X16<=0,0,Z16/X16) -> 1383.6161 | Z16: =+SUM(Z9:Z15) -> 81325.249 | AA16: =+SUM(AA9:AA15) -> 62.237684 | AB16: =IF(AA16<=0,0,AC16/AA16) -> 1383.6161 | AC16: =+SUM(AC9:AC15) -> 86113.064 | AD16: =+SUM(AD9:AD15) -> 68.199815 | AE16: =IF(AD16<=0,0,AF16/AD16) -> 1383.6161 | AF16: =+SUM(AF9:AF15) -> 94362.364 | AG16: =+SUM(AG9:AG15) -> 84.592344 | AH16: =IF(AG16<=0,0,AI16/AG16) -> 1383.6161 | AI16: =+SUM(AI9:AI15) -> 117043.33 | AJ16: =+SUM(AJ9:AJ15) -> 49.161152 | AK16: =IF(AJ16<=0,0,AL16/AJ16) -> 1383.6161 | AL16: =+SUM(AL9:AL15) -> 68020.163 | AM16: =+SUM(AM9:AM15) -> 28.779654 | AN16: =IF(AM16<=0,0,AO16/AM16) -> 1383.6161 | AO16: =+SUM(AO9:AO15) -> 39819.993
A17: =+$C$4&B17 -> Véhicules neufs
A18: =+$C$4&B18 -> Véhicules neufsEx-Démos et courtoisies | B18: Ex-Démos et courtoisies | C18: =+SUM(F18,I18,L18,O18,R18,U18,X18,AA18,AD18,AG18,AJ18,AM18) -> 74 | D18: =IF(C18=0,0,E18/C18) -> 790.03378 | E18: =+SUM(H18,K18,N18,Q18,T18,W18,Z18,AC18,AF18,AI18,AL18,AO18) -> 58462.5 | F18: 5.7654293 | G18: =IF(F18=0,0,H18/F18) -> 790.03378 | H18: 4554.8839 | I18: 3.9693173 | J18: =IF(I18=0,0,K18/I18) -> 790.03378 | K18: 3135.8947 | L18: 6.0340474 | M18: =IF(L18=0,0,N18/L18) -> 790.03378 | N18: 4767.1013 | O18: 6.683509 | P18: =IF(O18=0,0,Q18/O18) -> 790.03378 | Q18: 5280.1979 | R18: 8.7335165 | S18: =IF(R18=0,0,T18/R18) -> 790.03378 | T18: 6899.7731 | U18: 6.1531246 | V18: =IF(U18=0,0,W18/U18) -> 790.03378 | W18: 4861.1763 | X18: 6.1260869 | Y18: =IF(X18=0,0,Z18/X18) -> 790.03378 | Z18: 4839.8156 | AA18: 6.4867445 | AB18: =IF(AA18=0,0,AC18/AA18) -> 790.03378 | AC18: 5124.7473 | AD18: 7.1081497 | AE18: =IF(AD18=0,0,AF18/AD18) -> 790.03378 | AF18: 5615.6784 | AG18: 8.8166669 | AH18: =IF(AG18=0,0,AI18/AG18) -> 790.03378 | AI18: 6965.4647 | AJ18: 5.1238383 | AK18: =IF(AJ18=0,0,AL18/AJ18) -> 790.03378 | AL18: 4048.0054 | AM18: 2.9995696 | AN18: =IF(AM18=0,0,AO18/AM18) -> 790.03378 | AO18: 2369.7613
A19: =+$C$4&B19 -> Véhicules neufs
A20: =+$C$4&B20 -> Véhicules neufsFlottes | B20: Flottes | C20: =+SUM(F20,I20,L20,O20,R20,U20,X20,AA20,AD20,AG20,AJ20,AM20) -> 25 | D20: =IF(C20=0,0,E20/C20) -> 800 | E20: =+SUM(H20,K20,N20,Q20,T20,W20,Z20,AC20,AF20,AI20,AL20,AO20) -> 20000 | F20: 0 | G20: =IF(F20=0,0,H20/F20) -> 0 | H20: 0 | I20: 1.4542911 | J20: =IF(I20=0,0,K20/I20) -> 800 | K20: 1163.4329 | L20: 2.2107736 | M20: =IF(L20=0,0,N20/L20) -> 800 | N20: 1768.6189 | O20: 2.4487254 | P20: =IF(O20=0,0,Q20/O20) -> 800 | Q20: 1958.9803 | R20: 3.1998137 | S20: =IF(R20=0,0,T20/R20) -> 800 | T20: 2559.8509 | U20: 2.2544015 | V20: =IF(U20=0,0,W20/U20) -> 800 | W20: 1803.5212 | X20: 2.2444953 | Y20: =IF(X20=0,0,Z20/X20) -> 800 | Z20: 1795.5962 | AA20: 2.3766342 | AB20: =IF(AA20=0,0,AC20/AA20) -> 800 | AC20: 1901.3073 | AD20: 2.6043066 | AE20: =IF(AD20=0,0,AF20/AD20) -> 800 | AF20: 2083.4453 | AG20: 3.2302786 | AH20: =IF(AG20=0,0,AI20/AG20) -> 800 | AI20: 2584.2229 | AJ20: 1.8772883 | AK20: =IF(AJ20=0,0,AL20/AJ20) -> 800 | AL20: 1501.8306 | AM20: 1.0989919 | AN20: =IF(AM20=0,0,AO20/AM20) -> 800 | AO20: 879.1935
A21: =+$C$4&B21 -> Véhicules neufs
A22: =+$C$4&B22 -> Véhicules neufsRachat bail | B22: Rachat bail | E22: =+SUM(H22,K22,N22,Q22,T22,W22,Z22,AC22,AF22,AI22,AL22,AO22) -> 60000 | H22: 5000 | K22: 5000 | N22: 5000 | Q22: 5000 | T22: 5000 | W22: 5000 | Z22: 5000 | AC22: 5000 | AF22: 5000 | AI22: 5000 | AL22: 5000 | AO22: 5000
A23: =+$C$4&B23 -> Véhicules neufs
A24: =+$C$4&B24 -> Véhicules neufsRev. Finances | B24: Rev. Finances | D24: =IF(C16=0,0,E24/(C16+C18)) -> 94.079794 | E24: =+SUM(H24,K24,N24,Q24,T24,W24,Z24,AC24,AF24,AI24,AL24,AO24) -> 73758.559 | G24: =IF(F16=0,0,H24/(F16+F18)) -> 94.079794 | H24: 5746.6183 | J24: =IF(I16=0,0,K24/(I16+I18)) -> 94.079794 | K24: 3956.3665 | M24: =IF(L16=0,0,N24/(L16+L18)) -> 94.079794 | N24: 6014.36 | P24: =IF(O16=0,0,Q24/(O16+O18)) -> 94.079794 | Q24: 6661.7025 | S24: =IF(R16=0,0,T24/(R16+R18)) -> 94.079794 | T24: 8705.0215 | V24: =IF(U16=0,0,W24/(U16+U18)) -> 94.079794 | W24: 6133.0487 | Y24: =IF(X16=0,0,Z24/(X16+X18)) -> 94.079794 | Z24: 6106.0992 | AB24: =IF(AA16=0,0,AC24/(AA16+AA18)) -> 94.079794 | AC24: 6465.5801 | AE24: =IF(AD16=0,0,AF24/(AD16+AD18)) -> 94.079794 | AF24: 7084.9578 | AH24: =IF(AG16=0,0,AI24/(AG16+AG18)) -> 94.079794 | AI24: 8787.9005 | AK24: =IF(AJ16=0,0,AL24/(AJ16+AJ18)) -> 94.079794 | AL24: 5107.1207 | AN24: =IF(AM16=0,0,AO24/(AM16+AM18)) -> 94.079794 | AO24: 2989.7828
A25: =+$C$4&B25 -> Véhicules neufsRev. Protections | B25: Rev. Protections | D25: =IF(C16=0,0,E25/(C16+C18)) -> 737.32304 | E25: =+SUM(H25,K25,N25,Q25,T25,W25,Z25,AC25,AF25,AI25,AL25,AO25) -> 578061.26 | G25: =IF(F16=0,0,H25/(F16+F18)) -> 737.32304 | H25: 45037.45 | J25: =IF(I16=0,0,K25/(I16+I18)) -> 737.32304 | K25: 31006.872 | M25: =IF(L16=0,0,N25/(L16+L18)) -> 737.32304 | N25: 47135.798 | P25: =IF(O16=0,0,Q25/(O16+O18)) -> 737.32304 | Q25: 52209.157 | S25: =IF(R16=0,0,T25/(R16+R18)) -> 737.32304 | T25: 68223.075 | V25: =IF(U16=0,0,W25/(U16+U18)) -> 737.32304 | W25: 48065.986 | Y25: =IF(X16=0,0,Z25/(X16+X18)) -> 737.32304 | Z25: 47854.777 | AB25: =IF(AA16=0,0,AC25/(AA16+AA18)) -> 737.32304 | AC25: 50672.104 | AE25: =IF(AD16=0,0,AF25/(AD16+AD18)) -> 737.32304 | AF25: 55526.297 | AH25: =IF(AG16=0,0,AI25/(AG16+AG18)) -> 737.32304 | AI25: 68872.616 | AK25: =IF(AJ16=0,0,AL25/(AJ16+AJ18)) -> 737.32304 | AL25: 40025.574 | AN25: =IF(AM16=0,0,AO25/(AM16+AM18)) -> 737.32304 | AO25: 23431.554
A26: =+$C$4&B26 -> Véhicules neufsRev. Autres | B26: Rev. Autres | D26: =IF(C16=0,0,E26/(C16+C18)) -> 18.597169 | E26: =+SUM(H26,K26,N26,Q26,T26,W26,Z26,AC26,AF26,AI26,AL26,AO26) -> 14580.18 | G26: =IF(F16=0,0,H26/(F16+F18)) -> 18.597169 | H26: 1135.9594 | J26: =IF(I16=0,0,K26/(I16+I18)) -> 18.597169 | K26: 782.07244 | M26: =IF(L16=0,0,N26/(L16+L18)) -> 18.597169 | N26: 1188.8851 | P26: =IF(O16=0,0,Q26/(O16+O18)) -> 18.597169 | Q26: 1316.8482 | S26: =IF(R16=0,0,T26/(R16+R18)) -> 18.597169 | T26: 1720.7601 | V26: =IF(U16=0,0,W26/(U16+U18)) -> 18.597169 | W26: 1212.3468 | Y26: =IF(X16=0,0,Z26/(X16+X18)) -> 18.597169 | Z26: 1207.0196 | AB26: =IF(AA16=0,0,AC26/(AA16+AA18)) -> 18.597169 | AC26: 1278.0798 | AE26: =IF(AD16=0,0,AF26/(AD16+AD18)) -> 18.597169 | AF26: 1400.5149 | AH26: =IF(AG16=0,0,AI26/(AG16+AG18)) -> 18.597169 | AI26: 1737.1431 | AK26: =IF(AJ16=0,0,AL26/(AJ16+AJ18)) -> 18.597169 | AL26: 1009.5471 | AN26: =IF(AM16=0,0,AO26/(AM16+AM18)) -> 18.597169 | AO26: 591.00358
A27: =+$C$4&B27 -> Véhicules neufsTotal F&I | B27: Total F&I | C27: =+C18+C16 -> 784 | D27: =IF(C27<=0,0,E27/C27) -> 850 | E27: =E24+E25+E26 -> 666400 | F27: =+F18+F16 -> 61.082386 | G27: =IF(F27<=0,0,H27/F27) -> 850 | H27: =H24+H25+H26 -> 51920.028 | I27: =+I18+I16 -> 42.053307 | J27: =IF(I27<=0,0,K27/I27) -> 850 | K27: =K24+K25+K26 -> 35745.311 | L27: =+L18+L16 -> 63.928286 | M27: =IF(L27<=0,0,N27/L27) -> 850 | N27: =N24+N25+N26 -> 54339.043 | O27: =+O18+O16 -> 70.809068 | P27: =IF(O27<=0,0,Q27/O27) -> 850 | Q27: =Q24+Q25+Q26 -> 60187.708 | R27: =+R18+R16 -> 92.528067 | S27: =IF(R27<=0,0,T27/R27) -> 850 | T27: =$T$24+$T$25+$T$26 -> 78648.857 | U27: =+U18+U16 -> 65.189861 | V27: =IF(U27<=0,0,W27/U27) -> 850 | W27: =W24+W25+W26 -> 55411.382 | X27: =+X18+X16 -> 64.903407 | Y27: =IF(X27<=0,0,Z27/X27) -> 850 | Z27: =Z24+Z25+Z26 -> 55167.896 | AA27: =+AA18+AA16 -> 68.724428 | AB27: =IF(AA27<=0,0,AC27/AA27) -> 850 | AC27: =AC24+AC25+AC26 -> 58415.764 | AD27: =+AD18+AD16 -> 75.307965 | AE27: =IF(AD27<=0,0,AF27/AD27) -> 850 | AF27: =AF24+AF25+AF26 -> 64011.77 | AG27: =+AG18+AG16 -> 93.409011 | AH27: =IF(AG27<=0,0,AI27/AG27) -> 850 | AI27: =AI24+AI25+AI26 -> 79397.659 | AJ27: =+AJ18+AJ16 -> 54.28499 | AK27: =IF(AJ27<=0,0,AL27/AJ27) -> 850 | AL27: =AL24+AL25+AL26 -> 46142.241 | AM27: =+AM18+AM16 -> 31.779223 | AN27: =IF(AM27<=0,0,AO27/AM27) -> 850 | AO27: =AO24+AO25+AO26 -> 27012.34
A28: =+$C$4&B28 -> Véhicules neufs
A29: =+$C$4&B29 -> Véhicules neufs
A30: =+$C$4&B30 -> Véhicules neufsTotal Dépt. Neufs | B30: Total Dépt. Neufs | C30: =+C16+C18+C20 -> 809 | D30: =IF(C30<=0,0,E30/C30) -> 2209.1841 | E30: =E16+E20+E27+E22+E18 -> 1787230 | F30: =+F16+F18+F20 -> 61.082386 | G30: =IF(F30<=0,0,H30/F30) -> 2259.4459 | H30: =H16+H20+H27+H22+H18 -> 138012.35 | I30: =+I16+I18+I20 -> 43.507598 | J30: =IF(I30<=0,0,K30/I30) -> 2246.4642 | K30: =K16+K20+K27+K22+K18 -> 97738.262 | L30: =+L16+L18+L20 -> 66.13906 | M30: =IF(L30<=0,0,N30/L30) -> 2207.14 | N30: =N16+N20+N27+N22+N18 -> 145978.17 | O30: =+O16+O18+O20 -> 73.257793 | P30: =IF(O30<=0,0,Q30/O30) -> 2199.7939 | Q30: =Q16+Q20+Q27+Q22+Q18 -> 161152.04 | R30: =+R16+R18+R20 -> 95.727881 | S30: =IF(R30<=0,0,T30/R30) -> 2183.7731 | T30: =T16+T20+T27+T22+T18 -> 209047.97 | U30: =+U16+U18+U20 -> 67.444263 | V30: =IF(U30<=0,0,W30/U30) -> 2205.677 | W30: =W16+W20+W27+W22+W18 -> 148760.26 | X30: =+X16+X18+X20 -> 67.147902 | Y30: =IF(X30<=0,0,Z30/X30) -> 2206.0042 | Z30: =Z16+Z20+Z27+Z22+Z18 -> 148128.56 | AA30: =+AA16+AA18+AA20 -> 71.101063 | AB30: =IF(AA30<=0,0,AC30/AA30) -> 2201.8642 | AC30: =AC16+AC20+AC27+AC22+AC18 -> 156554.88 | AD30: =+AD16+AD18+AD20 -> 77.912271 | AE30: =IF(AD30<=0,0,AF30/AD30) -> 2195.7165 | AF30: =AF16+AF20+AF27+AF22+AF18 -> 171073.26 | AG30: =+AG16+AG18+AG20 -> 96.63929 | AH30: =IF(AG30<=0,0,AI30/AG30) -> 2183.2805 | AI30: =AI16+AI20+AI27+AI22+AI18 -> 210990.68 | AJ30: =+AJ16+AJ18+AJ20 -> 56.162278 | AK30: =IF(AJ30<=0,0,AL30/AJ30) -> 2220.5695 | AL30: =AL16+AL20+AL27+AL22+AL18 -> 124712.24 | AM30: =+AM16+AM18+AM20 -> 32.878215 | AN30: =IF(AM30<=0,0,AO30/AM30) -> 2283.6181 | AO30: =AO16+AO20+AO27+AO22+AO18 -> 75081.288
A31: =+$C$4&B31 -> Véhicules neufs
A32: =+$C$4&B32 -> Véhicules neufs
A33: =+$C$4&B33 -> Véhicules neufsDEPENSES | B33: DEPENSES
A34: =+$C$4&B34 -> Véhicules neufsComm. vendeurs | B34: Comm. vendeurs | C34: =E34/(E16+E18) -> 0.29080739 | D34: =IF(E34=0,0,E34/C$27) -> 386.07276 | E34: =+SUM(H34,K34,N34,Q34,T34,W34,Z34,AC34,AF34,AI34,AL34,AO34) -> 302681.05 | F34: =H34/(H16+H18) -> 0.29186552 | G34: =IF(H34=0,0,H34/F$27) -> 387.47753 | H34: 23668.052 | I34: =K34/(K16+K18) -> 0.32814705 | J34: =IF(K34=0,0,K34/I$27) -> 435.64449 | K34: 18320.292 | L34: =N34/(N16+N18) -> 0.29618008 | M34: =IF(N34=0,0,N34/L$27) -> 393.20549 | N34: 25136.953 | O34: =Q34/(Q16+Q18) -> 0.28622244 | P34: =IF(Q34=0,0,Q34/O$27) -> 379.98583 | Q34: 26906.443 | R34: =T34/(T16+T18) -> 0.26854424 | S34: =IF(T34=0,0,T34/R$27) -> 356.51645 | T34: 32987.778 | U34: =W34/(W16+W18) -> 0.29202669 | V34: =IF(W34=0,0,W34/U$27) -> 387.69149 | W34: 25273.555 | X34: =Z34/(Z16+Z18) -> 0.2950188 | Y34: =IF(Z34=0,0,Z34/X$27) -> 391.66378 | Z34: 25420.314 | AA34: =AC34/(AC16+AC18) -> 0.28826499 | AB34: =IF(AC34=0,0,AC34/AA$27) -> 382.69749 | AC34: 26300.666 | AD34: =AF34/(AF16+AF18) -> 0.28219976 | AE34: =IF(AF34=0,0,AF34/AD$27) -> 374.64536 | AF34: 28213.779 | AG34: =AI34/(AI16+AI18) -> 0.26993062 | AH34: =IF(AI34=0,0,AI34/AG$27) -> 358.35698 | AI34: 33473.772 | AJ34: =AL34/(AL16+AL18) -> 0.30671936 | AK34: =IF(AL34=0,0,AL34/AJ$27) -> 407.19732 | AL34: 22104.703 | AM34: =AO34/(AO16+AO18) -> 0.3525676 | AN34: =IF(AO34=0,0,AO34/AM$27) -> 468.06495 | AO34: 14874.741
A35: =+$C$4&B35 -> Véhicules neufsComm. F&I | B35: Comm. F&I | C35: =E35/E27 -> 0.3 | D35: =IF(E35=0,0,E35/C$27) -> 255 | E35: =+SUM(H35,K35,N35,Q35,T35,W35,Z35,AC35,AF35,AI35,AL35,AO35) -> 199920 | F35: =H35/H27 -> 0.3 | G35: =IF(H35=0,0,H35/F$27) -> 255 | H35: 15576.008 | I35: =K35/K27 -> 0.3 | J35: =IF(K35=0,0,K35/I$27) -> 255 | K35: 10723.593 | L35: =N35/N27 -> 0.3 | M35: =IF(N35=0,0,N35/L$27) -> 255 | N35: 16301.713 | O35: =Q35/Q27 -> 0.3 | P35: =IF(Q35=0,0,Q35/O$27) -> 255 | Q35: 18056.312 | R35: =T35/T27 -> 0.3 | S35: =IF(T35=0,0,T35/R$27) -> 255 | T35: 23594.657 | U35: =W35/W27 -> 0.3 | V35: =IF(W35=0,0,W35/U$27) -> 255 | W35: 16623.415 | X35: =Z35/Z27 -> 0.3 | Y35: =IF(Z35=0,0,Z35/X$27) -> 255 | Z35: 16550.369 | AA35: =AC35/AC27 -> 0.3 | AB35: =IF(AC35=0,0,AC35/AA$27) -> 255 | AC35: 17524.729 | AD35: =AF35/AF27 -> 0.3 | AE35: =IF(AF35=0,0,AF35/AD$27) -> 255 | AF35: 19203.531 | AG35: =AI35/AI27 -> 0.3 | AH35: =IF(AI35=0,0,AI35/AG$27) -> 255 | AI35: 23819.298 | AJ35: =AL35/AL27 -> 0.3 | AK35: =IF(AL35=0,0,AL35/AJ$27) -> 255 | AL35: 13842.672 | AM35: =AO35/AO27 -> 0.3 | AN35: =IF(AO35=0,0,AO35/AM$27) -> 255 | AO35: 8103.702
A36: =+$C$4&B36 -> Véhicules neufsFrais de livraison | B36: Frais de livraison | D36: =IF(E36=0,0,E36/C$27) -> 197 | E36: =+SUM(H36,K36,N36,Q36,T36,W36,Z36,AC36,AF36,AI36,AL36,AO36) -> 154448 | G36: =IF(H36=0,0,H36/F$27) -> 197 | H36: 12033.23 | J36: =IF(K36=0,0,K36/I$27) -> 197 | K36: 8284.5015 | M36: =IF(N36=0,0,N36/L$27) -> 197 | N36: 12593.872 | P36: =IF(Q36=0,0,Q36/O$27) -> 197 | Q36: 13949.386 | S36: =IF(T36=0,0,T36/R$27) -> 197 | T36: 18228.029 | V36: =IF(W36=0,0,W36/U$27) -> 197 | W36: 12842.403 | Y36: =IF(Z36=0,0,Z36/X$27) -> 197 | Z36: 12785.971 | AB36: =IF(AC36=0,0,AC36/AA$27) -> 197 | AC36: 13538.712 | AE36: =IF(AF36=0,0,AF36/AD$27) -> 197 | AF36: 14835.669 | AH36: =IF(AI36=0,0,AI36/AG$27) -> 197 | AI36: 18401.575 | AK36: =IF(AL36=0,0,AL36/AJ$27) -> 197 | AL36: 10694.143 | AN36: =IF(AO36=0,0,AO36/AM$27) -> 197 | AO36: 6260.507
A37: =+$C$4&B37 -> Véhicules neufsService gratuit 1 | B37: Service gratuit 1 | D37: =IF(E37=0,0,E37/C$27) -> 6 | E37: =+SUM(H37,K37,N37,Q37,T37,W37,Z37,AC37,AF37,AI37,AL37,AO37) -> 4704 | G37: =IF(H37=0,0,H37/F$27) -> 6 | H37: 366.49431 | J37: =IF(K37=0,0,K37/I$27) -> 6 | K37: 252.31984 | M37: =IF(N37=0,0,N37/L$27) -> 6 | N37: 383.56972 | P37: =IF(Q37=0,0,Q37/O$27) -> 6 | Q37: 424.85441 | S37: =IF(T37=0,0,T37/R$27) -> 6 | T37: 555.1684 | V37: =IF(W37=0,0,W37/U$27) -> 6 | W37: 391.13917 | Y37: =IF(Z37=0,0,Z37/X$27) -> 6 | Z37: 389.42044 | AB37: =IF(AC37=0,0,AC37/AA$27) -> 6 | AC37: 412.34657 | AE37: =IF(AF37=0,0,AF37/AD$27) -> 6 | AF37: 451.84779 | AH37: =IF(AI37=0,0,AI37/AG$27) -> 6 | AI37: 560.45407 | AK37: =IF(AL37=0,0,AL37/AJ$27) -> 6 | AL37: 325.70994 | AN37: =IF(AO37=0,0,AO37/AM$27) -> 6 | AO37: 190.67534
A38: =+$C$4&B38 -> Véhicules neufsEntretien stock | B38: Entretien stock | D38: =IF(E38=0,0,E38/C$27) -> 34 | E38: =+SUM(H38,K38,N38,Q38,T38,W38,Z38,AC38,AF38,AI38,AL38,AO38) -> 26656 | G38: =IF(H38=0,0,H38/F$27) -> 34 | H38: 2076.8011 | J38: =IF(K38=0,0,K38/I$27) -> 34 | K38: 1429.8124 | M38: =IF(N38=0,0,N38/L$27) -> 34 | N38: 2173.5617 | P38: =IF(Q38=0,0,Q38/O$27) -> 34 | Q38: 2407.5083 | S38: =IF(T38=0,0,T38/R$27) -> 34 | T38: 3145.9543 | V38: =IF(W38=0,0,W38/U$27) -> 34 | W38: 2216.4553 | Y38: =IF(Z38=0,0,Z38/X$27) -> 34 | Z38: 2206.7158 | AB38: =IF(AC38=0,0,AC38/AA$27) -> 34 | AC38: 2336.6306 | AE38: =IF(AF38=0,0,AF38/AD$27) -> 34 | AF38: 2560.4708 | AH38: =IF(AI38=0,0,AI38/AG$27) -> 34 | AI38: 3175.9064 | AK38: =IF(AL38=0,0,AL38/AJ$27) -> 34 | AL38: 1845.6897 | AN38: =IF(AO38=0,0,AO38/AM$27) -> 34 | AO38: 1080.4936
A39: =+$C$4&B39 -> Véhicules neufsPublicité 1 | B39: Publicité 1 | D39: =IF(E39=0,0,E39/C$27) -> 180.66964 | E39: =+SUM(H39,K39,N39,Q39,T39,W39,Z39,AC39,AF39,AI39,AL39,AO39) -> 141645 | G39: =IF(H39=0,0,H39/F$27) -> 180.66964 | H39: 11035.733 | J39: =IF(K39=0,0,K39/I$27) -> 180.66964 | K39: 7597.756 | M39: =IF(N39=0,0,N39/L$27) -> 180.66964 | N39: 11549.901 | P39: =IF(Q39=0,0,Q39/O$27) -> 180.66964 | Q39: 12793.049 | S39: =IF(T39=0,0,T39/R$27) -> 180.66964 | T39: 16717.013 | V39: =IF(W39=0,0,W39/U$27) -> 180.66964 | W39: 11777.829 | Y39: =IF(Z39=0,0,Z39/X$27) -> 180.66964 | Z39: 11726.075 | AB39: =IF(AC39=0,0,AC39/AA$27) -> 180.66964 | AC39: 12416.418 | AE39: =IF(AF39=0,0,AF39/AD$27) -> 180.66964 | AF39: 13605.863 | AH39: =IF(AI39=0,0,AI39/AG$27) -> 180.66964 | AI39: 16876.173 | AK39: =IF(AL39=0,0,AL39/AJ$27) -> 180.66964 | AL39: 9807.6498 | AN39: =IF(AO39=0,0,AO39/AM$27) -> 180.66964 | AO39: 5741.5409
A40: =+$C$4&B40 -> Véhicules neufsIntérêt de gros | B40: Intérêt de gros | D40: =IF(E40=0,0,E40/C$27) -> 224.43136 | E40: =+SUM(H40,K40,N40,Q40,T40,W40,Z40,AC40,AF40,AI40,AL40,AO40) -> 175954.18 | G40: =IF(H40=0,0,H40/F$27) -> 226.99495 | H40: 13865.393 | J40: =IF(K40=0,0,K40/I$27) -> 332.88053 | K40: 13998.727 | M40: =IF(N40=0,0,N40/L$27) -> 231.24629 | N40: 14783.179 | P40: =IF(Q40=0,0,Q40/O$27) -> 219.79355 | Q40: 15563.376 | S40: =IF(T40=0,0,T40/R$27) -> 166.54498 | T40: 15410.085 | V40: =IF(W40=0,0,W40/U$27) -> 224.82774 | W40: 14656.489 | Y40: =IF(Z40=0,0,Z40/X$27) -> 227.30566 | Z40: 14752.912 | AB40: =IF(AC40=0,0,AC40/AA$27) -> 218.79769 | AC40: 15036.746 | AE40: =IF(AF40=0,0,AF40/AD$27) -> 208.61189 | AF40: 15710.137 | AH40: =IF(AI40=0,0,AI40/AG$27) -> 162.04683 | AI40: 15136.634 | AK40: =IF(AL40=0,0,AL40/AJ$27) -> 247.86566 | AL40: 13455.385 | AN40: =IF(AO40=0,0,AO40/AM$27) -> 427.48427 | AO40: 13585.118
A41: =+$C$4&B41 -> Véhicules neufs[...] | B41: [...] | D41: =IF(E41=0,0,E41/C$27) -> 0 | E41: =+SUM(H41,K41,N41,Q41,T41,W41,Z41,AC41,AF41,AI41,AL41,AO41) -> 0 | G41: =IF(H41=0,0,H41/F$27) -> 0 | J41: =IF(K41=0,0,K41/I$27) -> 0 | M41: =IF(N41=0,0,N41/L$27) -> 0 | P41: =IF(Q41=0,0,Q41/O$27) -> 0 | S41: =IF(T41=0,0,T41/R$27) -> 0 | V41: =IF(W41=0,0,W41/U$27) -> 0 | Y41: =IF(Z41=0,0,Z41/X$27) -> 0 | AB41: =IF(AC41=0,0,AC41/AA$27) -> 0 | AE41: =IF(AF41=0,0,AF41/AD$27) -> 0 | AH41: =IF(AI41=0,0,AI41/AG$27) -> 0 | AK41: =IF(AL41=0,0,AL41/AJ$27) -> 0 | AN41: =IF(AO41=0,0,AO41/AM$27) -> 0
...

Sheet 2pager
B1: =Parametres!$B$1&" "&"2 pager"&" "&Parametres!$B$3&" "&Parametres!$B$4 -> Volks 2 pager Juillet 2021
B3: New | C3: Actual | D3: Forecast | E3: Budget | F3: 2019 | G3: ▲ Forecast | H3: ▲ Budget | I3: ▲2019 | J3: % ▲ Forecast | K3: % ▲ Budget | L3: % ▲ 2019 | M3: Commentaires
B4: Units | C4: =+Print_Mois!$J$13+Print_Mois!$J$15 -> 67 | D4: =+Print_Mois!$G$13+Print_Mois!$G$15 -> 65 | E4: =+Print_Mois!$D$13+Print_Mois!$D$15 -> 64.903407 | F4: =+Print_Mois!$O$13+Print_Mois!$O$15 -> 59 | G4: =+IFERROR($C4-D4,"") -> 2 | H4: =+IFERROR($C4-E4,"") -> 2.0965929 | I4: =+IFERROR($C4-F4,"") -> 8 | J4: =+IFERROR(G4/ABS($D4),"") -> 0.030769231 | K4: =+IFERROR(H4/ABS($E4),"") -> 0.032303279 | L4: =+IFERROR(I4/ABS($F4),"") -> 0.13559322 | M4: relache de réserve +$58.55/u 67 véhicules vendu égal au budget avec une marge à $1,908 (incluant détail, ex démo courtoisie et flotte), +595/u vs budget de $1,313. Le profit F&I est de $851 vs budget à $850. Donnant une avance de $42k au niveau du brute. Avec des coût variable additionnel requis pour supporter le un brute à la hausse ainsi qu'une bonne gestion des semi-fixes et fixes, le profit net départemental est supérieur au budget de $33,469.
B5: Front Margin | C5: =+Print_Mois!$L$13+Print_Mois!$L$15 -> 128105.64 | D5: =+Print_Mois!$I$13+Print_Mois!$I$15 -> 86165.064 | E5: =+Print_Mois!$F$13+Print_Mois!$F$15 -> 86165.064 | F5: =+Print_Mois!$Q$13+Print_Mois!$Q$15 -> 30261.78 | G5: =+IFERROR($C5-D5,"") -> 41940.576 | H5: =+IFERROR($C5-E5,"") -> 41940.576 | I5: =+IFERROR($C5-F5,"") -> 97843.86 | J5: =+IFERROR(G5/ABS($D5),"") -> 0.48674688 | K5: =+IFERROR(H5/ABS($E5),"") -> 0.48674688 | L5: =+IFERROR(I5/ABS($F5),"") -> 3.2332487
B6: Front margin / unit | C6: =+C5/C4 -> 1912.0245 | D6: =+D5/D4 -> 1325.6164 | E6: =+E5/E4 -> 1327.5892 | F6: =+F5/F4 -> 512.91153 | G6: =+IFERROR($C6-D6,"") -> 586.40811 | H6: =+IFERROR($C6-E6,"") -> 584.43525 | I6: =+IFERROR($C6-F6,"") -> 1399.113 | J6: =+IFERROR(G6/ABS($D6),"") -> 0.44236637 | K6: =+IFERROR(H6/ABS($E6),"") -> 0.44022295 | L6: =+IFERROR(I6/ABS($F6),"") -> 2.7277861
B7: $ Salaires et commission | C7: =+Print_Mois!$L$31 -> 38166.44 | D7: =+Print_Mois!$I$31 -> 25420.314 | E7: =+Print_Mois!$F$31 -> 25420.314 | F7: =+Print_Mois!$Q$31 -> 37735.24 | G7: =+IFERROR($C7-D7,"") -> 12746.126 | H7: =+IFERROR($C7-E7,"") -> 12746.126 | I7: =+IFERROR($C7-F7,"") -> 431.2 | J7: =+IFERROR(G7/ABS($D7),"") -> 0.50141499 | K7: =+IFERROR(H7/ABS($E7),"") -> 0.50141499 | L7: =+IFERROR(I7/ABS($F7),"") -> 0.011426984
B8: % Salaires et commission | C8: =+C7/C5 -> 0.29792943 | D8: =+D7/D5 -> 0.2950188 | E8: =+E7/E5 -> 0.2950188 | F8: =+F7/F5 -> 1.2469604 | G8: =+IFERROR($C8-D8,"") -> 0.0029106287 | H8: =+IFERROR($C8-E8,"") -> 0.0029106287 | I8: =+IFERROR($C8-F8,"") -> -0.94903093 | J8: =+IFERROR(G8/ABS($D8),"") -> 0.0098659092 | K8: =+IFERROR(H8/ABS($E8),"") -> 0.0098659092 | L8: =+IFERROR(I8/ABS($F8),"") -> -0.76107546
B9: Back Margin | C9: =+Print_Mois!$L$24 -> 57002.59 | D9: =+Print_Mois!$I$24 -> 55167.896 | E9: =+Print_Mois!$F$24 -> 55167.896 | F9: =+Print_Mois!$Q$24 -> 46136.92 | G9: =+IFERROR($C9-D9,"") -> 1834.6939 | H9: =+IFERROR($C9-E9,"") -> 1834.6939 | I9: =+IFERROR($C9-F9,"") -> 10865.67 | J9: =+IFERROR(G9/ABS($D9),"") -> 0.033256551 | K9: =+IFERROR(H9/ABS($E9),"") -> 0.033256551 | L9: =+IFERROR(I9/ABS($F9),"") -> 0.23550922
B10: Back Margin / unit | C10: =+C9/C4 -> 850.78493 | D10: =+D9/D4 -> 848.73686 | E10: =+E9/E4 -> 850 | F10: =+F9/F4 -> 781.98169 | G10: =+IFERROR($C10-D10,"") -> 2.048063 | H10: =+IFERROR($C10-E10,"") -> 0.78492537 | I10: =+IFERROR($C10-F10,"") -> 68.80323 | J10: =+IFERROR(G10/ABS($D10),"") -> 0.0024130718 | K10: =+IFERROR(H10/ABS($E10),"") -> 0.00092344162 | L10: =+IFERROR(I10/ABS($F10),"") -> 0.08798573
B11: $ commission FI | C11: =+Print_Mois!$L$32 -> 17456.85 | D11: =+Print_Mois!$I$32 -> 16550.369 | E11: =+Print_Mois!$F$32 -> 16550.369 | F11: =+Print_Mois!$Q$32 -> 17352.41 | G11: =+IFERROR($C11-D11,"") -> 906.48118 | H11: =+IFERROR($C11-E11,"") -> 906.48118 | I11: =+IFERROR($C11-F11,"") -> 104.44 | J11: =+IFERROR(G11/ABS($D11),"") -> 0.054771056 | K11: =+IFERROR(H11/ABS($E11),"") -> 0.054771056 | L11: =+IFERROR(I11/ABS($F11),"") -> 0.0060187605
B12: % commission FI | C12: =+C11/C9 -> 0.30624661 | D12: =+D11/D9 -> 0.3 | E12: =+E11/E9 -> 0.3 | F12: =+F11/F9 -> 0.37610681 | G12: =+IFERROR($C12-D12,"") -> 0.0062466109 | H12: =+IFERROR($C12-E12,"") -> 0.0062466109 | I12: =+IFERROR($C12-F12,"") -> -0.069860203 | J12: =+IFERROR(G12/ABS($D12),"") -> 0.020822036 | K12: =+IFERROR(H12/ABS($E12),"") -> 0.020822036 | L12: =+IFERROR(I12/ABS($F12),"") -> -0.18574565
B13: Variable fees | C13: =+Print_Mois!$L$41-C7-C11 -> 38465.59 | D13: =+Print_Mois!$I$41-D7-D11 -> 41861.095 | E13: =+Print_Mois!$F$41-E7-E11 -> 41861.095 | F13: =+Print_Mois!$Q$41-F7-F11 -> 48048.31 | G13: =+IFERROR($C13-D13,"") -> -3395.5047 | H13: =+IFERROR($C13-E13,"") -> -3395.5047 | I13: =+IFERROR($C13-F13,"") -> -9582.72 | J13: =+IFERROR(G13/ABS($D13),"") -> -0.081113614 | K13: =+IFERROR(H13/ABS($E13),"") -> -0.081113614 | L13: =+IFERROR(I13/ABS($F13),"") -> -0.19943927
B14: Variable fees / units | C14: =+C13/C4 -> 574.11328 | D14: =+D13/D4 -> 644.01684 | E14: =+E13/E4 -> 644.9753 | F14: =+F13/F4 -> 814.37814 | G14: =+IFERROR($C14-D14,"") -> -69.903557 | H14: =+IFERROR($C14-E14,"") -> -70.862019 | I14: =+IFERROR($C14-F14,"") -> -240.26485 | J14: =+IFERROR(G14/ABS($D14),"") -> -0.10854306 | K14: =+IFERROR(H14/ABS($E14),"") -> -0.1098678 | L14: =+IFERROR(I14/ABS($F14),"") -> -0.29502861
B15: Other Revenues | C15: =+Print_Mois!$L$83 -> 77999 | D15: =+Print_Mois!$I$83 -> 78695.959 | E15: =+Print_Mois!$F$83 -> 78695.959 | F15: =+Print_Mois!$Q$83 -> 174797.39 | G15: =+IFERROR($C15-D15,"") -> -696.95947 | H15: =+IFERROR($C15-E15,"") -> -696.95947 | I15: =+IFERROR($C15-F15,"") -> -96798.39 | J15: =+IFERROR(G15/ABS($D15),"") -> -0.0088563565 | K15: =+IFERROR(H15/ABS($E15),"") -> -0.0088563565 | L15: =+IFERROR(I15/ABS($F15),"") -> -0.5537748
B16: Inventory
B17: Units | C17: 123 | D17: 160 | E17: 160 | F17: 384 | G17: =+IFERROR($C17-D17,"") -> -37 | H17: =+IFERROR($C17-E17,"") -> -37 | I17: =+IFERROR($C17-F17,"") -> -261 | J17: =+IFERROR(G17/ABS($D17),"") -> -0.23125 | K17: =+IFERROR(H17/ABS($E17),"") -> -0.23125 | L17: =+IFERROR(I17/ABS($F17),"") -> -0.6796875
B18: $ | C18: 3719512 | D18: 5114383 | E18: 5114383 | F18: 12243411 | G18: =+IFERROR($C18-D18,"") -> -1394871 | H18: =+IFERROR($C18-E18,"") -> -1394871 | I18: =+IFERROR($C18-F18,"") -> -8523899 | J18: =+IFERROR(G18/ABS($D18),"") -> -0.27273495 | K18: =+IFERROR(H18/ABS($E18),"") -> -0.27273495 | L18: =+IFERROR(I18/ABS($F18),"") -> -0.69620296
B20: Used | C20: Actual | D20: Forecast | E20: Budget | F20: 2019 | G20: ▲ Forecast | H20: ▲ Budget | I20: ▲2019 | J20: % ▲ Forecast | K20: % ▲ Budget | L20: % ▲ 2019 | M20: Commentaires
B21: Units | C21: =+Print_Mois!$J$96 -> 41 | D21: =+Print_Mois!$G$96 -> 36.391956 | E21: =+Print_Mois!$D$96 -> 36.391956 | F21: =+Print_Mois!$O$96 -> 42 | G21: =+IFERROR($C21-D21,"") -> 4.6080439 | H21: =+IFERROR($C21-E21,"") -> 4.6080439 | I21: =+IFERROR($C21-F21,"") -> -1 | J21: =+IFERROR(G21/ABS($D21),"") -> 0.1266226 | K21: =+IFERROR(H21/ABS($E21),"") -> 0.1266226 | L21: =+IFERROR(I21/ABS($F21),"") -> -0.023809524 | M21: Ventes de 41 véhicules détails vs budget de 36 avec marge de $1,630 vs $750. Le profit F&I est de $2,530 vs $1,715. Wholesale +$3,868. Un gain de $85k sur le brute vs le budget. Avec des coût variable additionnel requis pour supporter le un brute à la hausse ainsi qu'une bonne gestion des semi-fixes et fixes, le profit net départemental est supérieur au budget de $70,205.
B22: Front Margin | C22: =+Print_Mois!$L$96 -> 66839.73 | D22: =+Print_Mois!$I$96 -> 27293.967 | E22: =+Print_Mois!$F$96 -> 27293.967 | F22: =+Print_Mois!$Q$96 -> 28894.13 | G22: =+IFERROR($C22-D22,"") -> 39545.763 | H22: =+IFERROR($C22-E22,"") -> 39545.763 | I22: =+IFERROR($C22-F22,"") -> 37945.6 | J22: =+IFERROR(G22/ABS($D22),"") -> 1.4488829 | K22: =+IFERROR(H22/ABS($E22),"") -> 1.4488829 | L22: =+IFERROR(I22/ABS($F22),"") -> 1.3132633
B23: Front margin / unit | C23: =+C22/C21 -> 1630.2373 | D23: =+D22/D21 -> 750 | E23: =+E22/E21 -> 750 | F23: =+F22/F21 -> 687.95548 | G23: =+IFERROR($C23-D23,"") -> 880.23732 | H23: =+IFERROR($C23-E23,"") -> 880.23732 | I23: =+IFERROR($C23-F23,"") -> 942.28184 | J23: =+IFERROR(G23/ABS($D23),"") -> 1.1736498 | K23: =+IFERROR(H23/ABS($E23),"") -> 1.1736498 | L23: =+IFERROR(I23/ABS($F23),"") -> 1.3696843
B24: $ Salaires et commission | C24: =+Print_Mois!$L$111 -> 26233.91 | D24: =+Print_Mois!$I$111 -> 15257.358 | E24: =+Print_Mois!$F$111 -> 15257.358 | F24: =+Print_Mois!$Q$111 -> 12144.98 | G24: =+IFERROR($C24-D24,"") -> 10976.552 | H24: =+IFERROR($C24-E24,"") -> 10976.552 | I24: =+IFERROR($C24-F24,"") -> 14088.93 | J24: =+IFERROR(G24/ABS($D24),"") -> 0.71942675 | K24: =+IFERROR(H24/ABS($E24),"") -> 0.71942675 | L24: =+IFERROR(I24/ABS($F24),"") -> 1.160062
B25: % Salaires et commission | C25: =+C24/C22 -> 0.39248977 | D25: =+D24/D22 -> 0.55900113 | E25: =+E24/E22 -> 0.55900113 | F25: =+F24/F22 -> 0.4203269 | G25: =+IFERROR($C25-D25,"") -> -0.16651136 | H25: =+IFERROR($C25-E25,"") -> -0.16651136 | I25: =+IFERROR($C25-F25,"") -> -0.027837131 | J25: =+IFERROR(G25/ABS($D25),"") -> -0.29787303 | K25: =+IFERROR(H25/ABS($E25),"") -> -0.29787303 | L25: =+IFERROR(I25/ABS($F25),"") -> -0.066227336
B26: Back Margin | C26: =+Print_Mois!$L$104 -> 103716.73 | D26: =+Print_Mois!$I$104 -> 62426.747 | E26: =+Print_Mois!$F$104 -> 62426.747 | F26: =+Print_Mois!$Q$104 -> 55072.92 | G26: =+IFERROR($C26-D26,"") -> 41289.983 | H26: =+IFERROR($C26-E26,"") -> 41289.983 | I26: =+IFERROR($C26-F26,"") -> 48643.81 | J26: =+IFERROR(G26/ABS($D26),"") -> 0.66141493 | K26: =+IFERROR(H26/ABS($E26),"") -> 0.66141493 | L26: =+IFERROR(I26/ABS($F26),"") -> 0.88326186
B27: Back Margin / unit | C27: =+C26/C21 -> 2529.6763 | D27: =+D26/D21 -> 1715.3996 | E27: =+E26/E21 -> 1715.3996 | F27: =+F26/F21 -> 1311.26 | G27: =+IFERROR($C27-D27,"") -> 814.27673 | H27: =+IFERROR($C27-E27,"") -> 814.27673 | I27: =+IFERROR($C27-F27,"") -> 1218.4163 | J27: =+IFERROR(G27/ABS($D27),"") -> 0.47468632 | K27: =+IFERROR(H27/ABS($E27),"") -> 0.47468632 | L27: =+IFERROR(I27/ABS($F27),"") -> 0.92919508
B28: $ commission FI | C28: =+Print_Mois!$L$112 -> 31761.74 | D28: =+Print_Mois!$I$112 -> 18728.024 | E28: =+Print_Mois!$F$112 -> 18728.024 | F28: =+Print_Mois!$Q$112 -> 18574.12 | G28: =+IFERROR($C28-D28,"") -> 13033.716 | H28: =+IFERROR($C28-E28,"") -> 13033.716 | I28: =+IFERROR($C28-F28,"") -> 13187.62 | J28: =+IFERROR(G28/ABS($D28),"") -> 0.69594719 | K28: =+IFERROR(H28/ABS($E28),"") -> 0.69594719 | L28: =+IFERROR(I28/ABS($F28),"") -> 0.70999972
B29: % commission FI | C29: =+C28/C26 -> 0.30623545 | D29: =+D28/D26 -> 0.3 | E29: =+E28/E26 -> 0.3 | F29: =+F28/F26 -> 0.33726412 | G29: =+IFERROR($C29-D29,"") -> 0.006235455 | H29: =+IFERROR($C29-E29,"") -> 0.006235455 | I29: =+IFERROR($C29-F29,"") -> -0.031028667 | J29: =+IFERROR(G29/ABS($D29),"") -> 0.02078485 | K29: =+IFERROR(H29/ABS($E29),"") -> 0.02078485 | L29: =+IFERROR(I29/ABS($F29),"") -> -0.09200109
B30: Variable fees | C30: =+Print_Mois!$L$121-C24-C28 -> 10681.4 | D30: =+Print_Mois!$I$121-D24-D28 -> 10371.824 | E30: =+Print_Mois!$F$121-E24-E28 -> 10371.824 | F30: =+Print_Mois!$Q$121-F24-F28 -> 10381.3 | G30: =+IFERROR($C30-D30,"") -> 309.57614 | H30: =+IFERROR($C30-E30,"") -> 309.57614 | I30: =+IFERROR($C30-F30,"") -> 300.1 | J30: =+IFERROR(G30/ABS($D30),"") -> 0.029847802 | K30: =+IFERROR(H30/ABS($E30),"") -> 0.029847802 | L30: =+IFERROR(I30/ABS($F30),"") -> 0.028907748
B31: Variable fees / units | C31: =+C30/C21 -> 260.52195 | D31: =+D30/D21 -> 285.0032 | E31: =+E30/E21 -> 285.0032 | F31: =+F30/F21 -> 247.17381 | G31: =+IFERROR($C31-D31,"") -> -24.481247 | H31: =+IFERROR($C31-E31,"") -> -24.481247 | I31: =+IFERROR($C31-F31,"") -> 13.348142 | J31: =+IFERROR(G31/ABS($D31),"") -> -0.085898148 | K31: =+IFERROR(H31/ABS($E31),"") -> -0.085898148 | L31: =+IFERROR(I31/ABS($F31),"") -> 0.054003059
B32: Other Revenues | C32: =+Print_Mois!$L$162 -> 14309 | D32: =+Print_Mois!$I$162 -> 11430.713 | E32: =+Print_Mois!$F$162 -> 11430.713 | F32: =+Print_Mois!$Q$162 -> 14658 | G32: =+IFERROR($C32-D32,"") -> 2878.2866 | H32: =+IFERROR($C32-E32,"") -> 2878.2866 | I32: =+IFERROR($C32-F32,"") -> -349 | J32: =+IFERROR(G32/ABS($D32),"") -> 0.25180288 | K32: =+IFERROR(H32/ABS($E32),"") -> 0.25180288 | L32: =+IFERROR(I32/ABS($F32),"") -> -0.023809524
B33: Inventory
B34: Units | C34: 112 | D34: 67 | E34: 67 | F34: 92 | G34: =+IFERROR($C34-D34,"") -> 45 | H34: =+IFERROR($C34-E34,"") -> 45 | I34: =+IFERROR($C34-F34,"") -> 20 | J34: =+IFERROR(G34/ABS($D34),"") -> 0.67164179 | K34: =+IFERROR(H34/ABS($E34),"") -> 0.67164179 | L34: =+IFERROR(I34/ABS($F34),"") -> 0.2173913
B35: $ | C35: 1977452 | D35: 1114394 | E35: 1114394 | F35: 1449455 | G35: =+IFERROR($C35-D35,"") -> 863058 | H35: =+IFERROR($C35-E35,"") -> 863058 | I35: =+IFERROR($C35-F35,"") -> 527997 | J35: =+IFERROR(G35/ABS($D35),"") -> 0.77446397 | K35: =+IFERROR(H35/ABS($E35),"") -> 0.77446397 | L35: =+IFERROR(I35/ABS($F35),"") -> 0.36427278
B37: Service | C37: Actual | D37: Forecast | E37: Budget | F37: 2019 | G37: ▲ Forecast | H37: ▲ Budget | I37: ▲2019 | J37: % ▲ Forecast | K37: % ▲ Budget | L37: % ▲ 2019 | M37: Commentaires
B38: Revenus | C38: =+Print_Mois!$K$193 -> 196189.13 | D38: =+Print_Mois!$H$193 -> 247658.03 | E38: =+Print_Mois!$E$193 -> 247658.03 | F38: =+Print_Mois!$P$193 -> 258925.92 | G38: =+IFERROR($C38-D38,"") -> -51468.9 | H38: =+IFERROR($C38-E38,"") -> -51468.9 | I38: =+IFERROR($C38-F38,"") -> -62736.79 | J38: =+IFERROR(G38/ABS($D38),"") -> -0.20782246 | K38: =+IFERROR(H38/ABS($E38),"") -> -0.20782246 | L38: =+IFERROR(I38/ABS($F38),"") -> -0.24229629 | M38: Brute $29,352 inférieur au budget de $164,630. Provenant de garantie (-$20,648) et client(-$9,071). Avec des dépenses inférieurs au budget, le profit départemental est supérieur au budget +$5,907. À la carrosserie, un brute et net inférieur au budget de $9,819 et $6,646 respectivement.
B39: Gross margin | C39: =+Print_Mois!$L$193 -> 135278.67 | D39: =+Print_Mois!$I$193 -> 164630.45 | E39: =+Print_Mois!$F$193 -> 164630.45 | F39: =+Print_Mois!$Q$193 -> 172064.04 | G39: =+IFERROR($C39-D39,"") -> -29351.781 | H39: =+IFERROR($C39-E39,"") -> -29351.781 | I39: =+IFERROR($C39-F39,"") -> -36785.37 | J39: =+IFERROR(G39/ABS($D39),"") -> -0.1782889 | K39: =+IFERROR(H39/ABS($E39),"") -> -0.1782889 | L39: =+IFERROR(I39/ABS($F39),"") -> -0.21378883
B40: $ Revenus / #WO client | C40: =+Print_Mois!$K$171/Print_Mois!$J$171 -> 230.39338 | D40: =+IFERROR(Print_Mois!$H$171/Print_Mois!$G$171,"") -> 245.43849 | E40: =+IFERROR(Print_Mois!$E$171/Print_Mois!$D$171,"") -> 245.43849 | F40: =+Print_Mois!$P$171/Print_Mois!$O$171 -> 247.29385 | G40: =+IFERROR($C40-D40,"") -> -15.045102 | H40: =+IFERROR($C40-E40,"") -> -15.045102 | I40: =+IFERROR($C40-F40,"") -> -16.900471 | J40: =+IFERROR(G40/ABS($D40),"") -> -0.061298869 | K40: =+IFERROR(H40/ABS($E40),"") -> -0.061298869 | L40: =+IFERROR(I40/ABS($F40),"") -> -0.068341652
B41: $ Revenus / #WO garantie | C41: =+Print_Mois!$K$174/Print_Mois!$J$174 -> 242.45703 | D41: =+IFERROR(Print_Mois!$H$174/Print_Mois!$G$174,"") -> 176.734 | E41: =+IFERROR(Print_Mois!$E$174/Print_Mois!$D$174,"") -> 176.734 | F41: =+Print_Mois!$P$174/Print_Mois!$O$174 -> 206.70971 | G41: =+IFERROR($C41-D41,"") -> 65.723025 | H41: =+IFERROR($C41-E41,"") -> 65.723025 | I41: =+IFERROR($C41-F41,"") -> 35.747318 | J41: =+IFERROR(G41/ABS($D41),"") -> 0.37187538 | K41: =+IFERROR(H41/ABS($E41),"") -> 0.37187538 | L41: =+IFERROR(I41/ABS($F41),"") -> 0.17293488
B42: Lost time | C42: =+Print_Mois!$L$183 -> -2113.92 | D42: =+Print_Mois!$I$183 -> -3947.042 | E42: =+Print_Mois!$F$183 -> -3947.042 | F42: =+Print_Mois!$Q$183 -> -2108.7 | G42: =+IFERROR($C42-D42,"") -> 1833.122 | H42: =+IFERROR($C42-E42,"") -> 1833.122 | I42: =+IFERROR($C42-F42,"") -> -5.22 | J42: =+IFERROR(G42/ABS($D42),"") -> 0.46442932 | K42: =+IFERROR(H42/ABS($E42),"") -> 0.46442932 | L42: =+IFERROR(I42/ABS($F42),"") -> -0.0024754588
B43: Total salaries | C43: =+Print_Mois!$L$209 -> 83603.23 | D43: =+Print_Mois!$I$209 -> 115233.15 | E43: =+Print_Mois!$F$209 -> 115233.15 | F43: =+Print_Mois!$Q$209 -> 87754.11 | G43: =+IFERROR($C43-D43,"") -> -31629.922 | H43: =+IFERROR($C43-E43,"") -> -31629.922 | I43: =+IFERROR($C43-F43,"") -> -4150.88 | J43: =+IFERROR(G43/ABS($D43),"") -> -0.2744863 | K43: =+IFERROR(H43/ABS($E43),"") -> -0.2744863 | L43: =+IFERROR(I43/ABS($F43),"") -> -0.04730126
...

Sheet Budget révisé
B1: ="Budget 2021 Mensuel Révisé"&" "&Parametres!$B$1 -> Budget 2021 Mensuel Révisé Volks
B2: Mois | F2: =+IF(Parametres!$B$3=F$6,"X","") | G2: =+IF(Parametres!$B$3=F$6,"O","") | H2: =+IF(Parametres!$B$3=F$6,"U","") | I2: =+IF(Parametres!$B$3=I$6,"X","") | J2: =+IF(Parametres!$B$3=I$6,"O","") | K2: =+IF(Parametres!$B$3=I$6,"U","") | L2: =+IF(Parametres!$B$3=L$6,"X","") | M2: =+IF(Parametres!$B$3=L$6,"O","") | N2: =+IF(Parametres!$B$3=L$6,"U","") | O2: =+IF(Parametres!$B$3=O$6,"X","") | P2: =+IF(Parametres!$B$3=O$6,"O","") | Q2: =+IF(Parametres!$B$3=O$6,"U","") | R2: =+IF(Parametres!$B$3=R$6,"X","") | S2: =+IF(Parametres!$B$3=R$6,"O","") | T2: =+IF(Parametres!$B$3=R$6,"U","") | U2: =+IF(Parametres!$B$3=U$6,"X","") | V2: =+IF(Parametres!$B$3=U$6,"O","") | W2: =+IF(Parametres!$B$3=U$6,"U","") | X2: =+IF(Parametres!$B$3=X$6,"X","") -> X | Y2: =+IF(Parametres!$B$3=X$6,"O","") -> O | Z2: =+IF(Parametres!$B$3=X$6,"U","") -> U | AA2: =+IF(Parametres!$B$3=AA$6,"X","") | AB2: =+IF(Parametres!$B$3=AA$6,"O","") | AC2: =+IF(Parametres!$B$3=AA$6,"U","") | AD2: =+IF(Parametres!$B$3=AD$6,"X","") | AE2: =+IF(Parametres!$B$3=AD$6,"O","") | AF2: =+IF(Parametres!$B$3=AD$6,"U","") | AG2: =+IF(Parametres!$B$3=AG$6,"X","") | AH2: =+IF(Parametres!$B$3=AG$6,"O","") | AI2: =+IF(Parametres!$B$3=AG$6,"U","") | AJ2: =+IF(Parametres!$B$3=AJ$6,"X","") | AK2: =+IF(Parametres!$B$3=AJ$6,"O","") | AL2: =+IF(Parametres!$B$3=AJ$6,"U","") | AM2: =+IF(Parametres!$B$3=AM$6,"X","") | AN2: =+IF(Parametres!$B$3=AM$6,"O","") | AO2: =+IF(Parametres!$B$3=AM$6,"U","")
B3: YTD | F3: =+IF(VLOOKUP(F$6,Parametres!$K$3:$N$14,4,0)="X","X","") -> X | G3: =+IF(VLOOKUP(F$6,Parametres!$K$3:$N$14,4,0)="X","O","") -> O | H3: =+IF(VLOOKUP(F$6,Parametres!$K$3:$N$14,4,0)="X","U","") -> U | I3: =+IF(VLOOKUP(I$6,Parametres!$K$3:$N$14,4,0)="X","X","") -> X | J3: =+IF(VLOOKUP(I$6,Parametres!$K$3:$N$14,4,0)="X","O","") -> O | K3: =+IF(VLOOKUP(I$6,Parametres!$K$3:$N$14,4,0)="X","U","") -> U | L3: =+IF(VLOOKUP(L$6,Parametres!$K$3:$N$14,4,0)="X","X","") -> X | M3: =+IF(VLOOKUP(L$6,Parametres!$K$3:$N$14,4,0)="X","O","") -> O | N3: =+IF(VLOOKUP(L$6,Parametres!$K$3:$N$14,4,0)="X","U","") -> U | O3: =+IF(VLOOKUP(O$6,Parametres!$K$3:$N$14,4,0)="X","X","") -> X | P3: =+IF(VLOOKUP(O$6,Parametres!$K$3:$N$14,4,0)="X","O","") -> O | Q3: =+IF(VLOOKUP(O$6,Parametres!$K$3:$N$14,4,0)="X","U","") -> U | R3: =+IF(VLOOKUP(R$6,Parametres!$K$3:$N$14,4,0)="X","X","") -> X | S3: =+IF(VLOOKUP(R$6,Parametres!$K$3:$N$14,4,0)="X","O","") -> O | T3: =+IF(VLOOKUP(R$6,Parametres!$K$3:$N$14,4,0)="X","U","") -> U | U3: =+IF(VLOOKUP(U$6,Parametres!$K$3:$N$14,4,0)="X","X","") -> X | V3: =+IF(VLOOKUP(U$6,Parametres!$K$3:$N$14,4,0)="X","O","") -> O | W3: =+IF(VLOOKUP(U$6,Parametres!$K$3:$N$14,4,0)="X","U","") -> U | X3: =+IF(VLOOKUP(X$6,Parametres!$K$3:$N$14,4,0)="X","X","") -> X | Y3: =+IF(VLOOKUP(X$6,Parametres!$K$3:$N$14,4,0)="X","O","") -> O | Z3: =+IF(VLOOKUP(X$6,Parametres!$K$3:$N$14,4,0)="X","U","") -> U | AA3: =+IF(VLOOKUP(AA$6,Parametres!$K$3:$N$14,4,0)="X","X","") | AB3: =+IF(VLOOKUP(AA$6,Parametres!$K$3:$N$14,4,0)="X","O","") | AC3: =+IF(VLOOKUP(AA$6,Parametres!$K$3:$N$14,4,0)="X","U","") | AD3: =+IF(VLOOKUP(AD$6,Parametres!$K$3:$N$14,4,0)="X","X","") | AE3: =+IF(VLOOKUP(AD$6,Parametres!$K$3:$N$14,4,0)="X","O","") | AF3: =+IF(VLOOKUP(AD$6,Parametres!$K$3:$N$14,4,0)="X","U","") | AG3: =+IF(VLOOKUP(AG$6,Parametres!$K$3:$N$14,4,0)="X","X","") | AH3: =+IF(VLOOKUP(AG$6,Parametres!$K$3:$N$14,4,0)="X","O","") | AI3: =+IF(VLOOKUP(AG$6,Parametres!$K$3:$N$14,4,0)="X","U","") | AJ3: =+IF(VLOOKUP(AJ$6,Parametres!$K$3:$N$14,4,0)="X","X","") | AK3: =+IF(VLOOKUP(AJ$6,Parametres!$K$3:$N$14,4,0)="X","O","") | AL3: =+IF(VLOOKUP(AJ$6,Parametres!$K$3:$N$14,4,0)="X","U","") | AM3: =+IF(VLOOKUP(AM$6,Parametres!$K$3:$N$14,4,0)="X","X","") | AN3: =+IF(VLOOKUP(AM$6,Parametres!$K$3:$N$14,4,0)="X","O","") | AO3: =+IF(VLOOKUP(AM$6,Parametres!$K$3:$N$14,4,0)="X","U","")
B4: Budget 2021 | C4: Véhicules neufs
B6: Mois | C6: 2021 | F6: Janvier | I6: Février | L6: Mars | O6: Avril | R6: Mai | U6: Juin | X6: Juillet | AA6: Août | AD6: Septembre | AG6: Octobre | AJ6: Novembre | AM6: Décembre
C7: UNITE | D7: $P/UNITE | E7: $PROFITS | F7: UNITE | G7: $P/UNITE | H7: $PROFITS | I7: UNITE | J7: $P/UNITE | K7: $PROFITS | L7: UNITE | M7: $P/UNITE | N7: $PROFITS | O7: UNITE | P7: $P/UNITE | Q7: $PROFITS | R7: UNITE | S7: $P/UNITE | T7: $PROFITS | U7: UNITE | V7: $P/UNITE | W7: $PROFITS | X7: UNITE | Y7: $P/UNITE | Z7: $PROFITS | AA7: UNITE | AB7: $P/UNITE | AC7: $PROFITS | AD7: UNITE | AE7: $P/UNITE | AF7: $PROFITS | AG7: UNITE | AH7: $P/UNITE | AI7: $PROFITS | AJ7: UNITE | AK7: $P/UNITE | AL7: $PROFITS | AM7: UNITE | AN7: $P/UNITE | AO7: $PROFITS
