Workbook
Name _Dates_Conc: [1]Dealers!$BF$37:$KA$63
Name _scen: '[1]Scen & Sens'!$E$26
Name _scen1: '[1]Scen & Sens'!$E$27
Name _scen2: '[1]Scen & Sens'!$E$28
Name _SCenarios: '[1]Scen & Sens'!$J$26:$O$26
Name _Sens1: '[1]Scen & Sens'!$F$9
Name _Sens2: '[1]Scen & Sens'!$F$10
Name _sensRes1: '[1]Scen & Sens'!$E$15
Name _sensRes2: '[1]Scen & Sens'!$E$16
Name _sensRes3: '[1]Scen & Sens'!$E$17
Name _sensRes4: '[1]Scen & Sens'!$E$18
Name _sensRes5: '[1]Scen & Sens'!$E$19
Name _sensRes6: '[1]Scen & Sens'!$E$20
Name _sensRes7: '[1]Scen & Sens'!$E$21
Name DateRange: [1]Volkswagen!$BF$6:$DY$6
Name Monetary_Unit: [1]Parameters!$B$15
Name Months: [1]Parameters!$E$9:$E$20
Name Rng_Dealers_Names: [1]!Tbl_Dealers[Dealer Name]
Name Rng_Dlr_Dates: [1]!Tbl_V_Dlr_Dates[Date]
Name Ticker: #REF!
Name Ticker: #REF!
Name Titre: [1]Front!$A$9

Sheet Paramètre
B3: VOLKS QUARTER | C3: Volks Juin / Juillet 2023
B6: BUDGET | F6: BUDGET RÉVISÉ | J6: ACTUAL | N6: LAST YEAR
B7: Ventes | C7: Profits bruts | D7: BAIIA | E7: EBIT | F7: Ventes | G7: Profits bruts | H7: BAIIA | I7: EBIT | J7: Ventes | K7: Profits bruts | L7: BAIIA | M7: EBIT | N7: Ventes | O7: Profits bruts | P7: BAIIA | Q7: EBIT
A8: CTRL | B8: =+B9-B10 -> #REF! | C8: =+C9-C10 -> #REF! | D8: =+D9-D10 -> #REF! | E8: =+E9-E10 -> #REF! | F8: =+F9-F10 -> #REF! | G8: =+G9-G10 -> #REF! | H8: =+H9-H10 -> #REF! | I8: =+I9-I10 -> #REF! | ... Q8: =+Q9-Q10 -> #REF!
A9: CONSO | B9: =+Conso!$Z$405 -> 9346028.8 | C9: =+Conso!$Z$406 -> 1339678.4 | D9: =+Conso!$Z$482 -> 359006.39 | E9: =+Conso!$Z$497 -> 348823.91 | F9: =+Conso!$AC$405 -> 0 | G9: =+Conso!$AC$406 -> 0 | H9: =+Conso!$AC$482 -> 0 | I9: =+Conso!$AC$497 -> 0 | J9: =+Conso!$AF$405 -> 10172890 | K9: =+Conso!$AF$406 -> 1288302.5 | L9: =+Conso!$AF$482 -> 361518.19 | M9: =+Conso!$AF$497 -> 352889.19 | N9: =+Conso!$AL$405 -> 10597373 | O9: =+Conso!$AL$406 -> 1497150.1 | P9: =+Conso!$AL$482 -> 519977.36 | Q9: =+Conso!$AL$497 -> 510494.78
A10: TOTAL | B10: =+SUM(B11:B13) -> #REF! | C10: =+SUM(C11:C13) -> #REF! | D10: =+SUM(D11:D13) -> #REF! | E10: =+SUM(E11:E13) -> #REF! | F10: =+SUM(F11:F13) -> #REF! | G10: =+SUM(G11:G13) -> #REF! | H10: =+SUM(H11:H13) -> #REF! | I10: =+SUM(I11:I13) -> #REF! | ... Q10: =+SUM(Q11:Q13) -> #REF!
A11: AUDI 1 | B11: =+#REF! -> #REF! | C11: =+#REF! -> #REF! | D11: =+#REF! -> #REF! | E11: =+#REF! -> #REF! | F11: =+#REF! -> #REF! | G11: =+#REF! -> #REF! | H11: =+#REF! -> #REF! | I11: =+#REF! -> #REF! | ... Q11: =+#REF! -> #REF!
A12: AUDI 2 | B12: =+#REF! -> #REF! | C12: =+#REF! -> #REF! | D12: =+#REF! -> #REF! | E12: =+#REF! -> #REF! | F12: =+#REF! -> #REF! | G12: =+#REF! -> #REF! | H12: =+#REF! -> #REF! | I12: =+#REF! -> #REF! | ... Q12: =+#REF! -> #REF!
A13: AUDI 3 | B13: =+#REF! -> #REF! | C13: =+#REF! -> #REF! | D13: =+#REF! -> #REF! | E13: =+#REF! -> #REF! | F13: =+#REF! -> #REF! | G13: =+#REF! -> #REF! | H13: =+#REF! -> #REF! | I13: =+#REF! -> #REF! | ... Q13: =+#REF! -> #REF!

Sheet Conso
C1: Conso | K1: Véhicules neufs | S1: =CONCATENATE(Paramètre!$C$2," ",Paramètre!$C$3) -> Volks Juin / Juillet 2023
D2: X | E2: O | F2: U | G2: X | H2: O | I2: U
D3: BUDGET ORIGINAL | G3: BUDGET REVISE | J3: RÉALISATION | M3: ÉCART réel / Budget | O3: ANNÉE PRÉCÉDENTE | R3: ECART (réel/ Ann.Préc.)
D4: UNITE | E4: $P/UNITÉ | F4: $PROFITS | G4: UNITE | H4: $P/UNITÉ | I4: $PROFITS | J4: UNITE | K4: $P/UNITE | L4: $PROFITS | M4: UNITÉS | N4: $PROFITS | O4: UNITE | P4: $P/UNITE | Q4: $PROFITS | R4: UNITÉS | S4: $PROFITS
A5: =+B5&C5 -> Véhicules neufsVentes nettes | B5: =+$K$1 -> Véhicules neufs | C5: Ventes nettes | F5: =+SUM(START:END!F5) -> 4632530.7 | I5: =+SUM(START:END!I5) -> 0 | L5: =+SUM(START:END!L5) -> 4973516.2 | Q5: =+SUM(START:END!Q5) -> 5493835.3
A6: =+B6&C6 -> Véhicules neufsAutos détail | B6: =+$K$1 -> Véhicules neufs | C6: Autos détail | D6: =+SUM(START:END!D6) -> 19.737143 | E6: =IF(D6=0,0,F6/D6) -> 1988.434 | F6: =+SUM(START:END!F6) -> 39246.006 | G6: =+SUM(START:END!G6) -> 0 | H6: =IF(G6=0,0,I6/G6) -> 0 | I6: =+SUM(START:END!I6) -> 0 | J6: =+SUM(START:END!J6) -> 28 | K6: =IF(J6=0,0,L6/J6) -> 2008.6254 | L6: =+SUM(START:END!L6) -> 56241.51 | M6: =J6-D6 -> 8.2628571 | N6: =L6-F6 -> 16995.504 | O6: =+SUM(START:END!O6) -> 22 | P6: =IF(O6=0,0,Q6/O6) -> 2731.0177 | Q6: =+SUM(START:END!Q6) -> 60082.39 | R6: =J6-O6 -> 6 | S6: =L6-Q6 -> -3840.88
A7: =+B7&C7 -> Véhicules neufsCamions détail | B7: =+$K$1 -> Véhicules neufs | C7: Camions détail | D7: =+SUM(START:END!D7) -> 78.940677 | E7: =IF(D7=0,0,F7/D7) -> 2556.3336 | F7: =+SUM(START:END!F7) -> 201798.71 | G7: =+SUM(START:END!G7) -> 0 | H7: =IF(G7=0,0,I7/G7) -> 0 | I7: =+SUM(START:END!I7) -> 0 | J7: =+SUM(START:END!J7) -> 63 | K7: =IF(J7=0,0,L7/J7) -> 2495.4514 | L7: =+SUM(START:END!L7) -> 157213.44 | M7: =J7-D7 -> -15.940677 | N7: =L7-F7 -> -44585.267 | O7: =+SUM(START:END!O7) -> 80 | P7: =IF(O7=0,0,Q7/O7) -> 3573.0596 | Q7: =+SUM(START:END!Q7) -> 285844.77 | R7: =J7-O7 -> -17 | S7: =L7-Q7 -> -128631.33
A8: =+B8&C8 -> Véhicules neufsSprinter | B8: =+$K$1 -> Véhicules neufs | C8: Sprinter | D8: =+SUM(START:END!D8) -> 0 | E8: =IF(D8=0,0,F8/D8) -> 0 | F8: =+SUM(START:END!F8) -> 0 | G8: =+SUM(START:END!G8) -> 0 | H8: =IF(G8=0,0,I8/G8) -> 0 | I8: =+SUM(START:END!I8) -> 0 | J8: =+SUM(START:END!J8) -> 0 | K8: =IF(J8=0,0,L8/J8) -> 0 | L8: =+SUM(START:END!L8) -> 0 | M8: =J8-D8 -> 0 | N8: =L8-F8 -> 0 | O8: =+SUM(START:END!O8) -> 0 | P8: =IF(O8=0,0,Q8/O8) -> 0 | Q8: =+SUM(START:END!Q8) -> 0 | R8: =J8-O8 -> 0 | S8: =L8-Q8 -> 0
A9: =+B9&C9 -> Véhicules neufsMoto détail | B9: =+$K$1 -> Véhicules neufs | C9: Moto détail | D9: =+SUM(START:END!D9) -> 0 | E9: =IF(D9=0,0,F9/D9) -> 0 | F9: =+SUM(START:END!F9) -> 0 | G9: =+SUM(START:END!G9) -> 0 | H9: =IF(G9=0,0,I9/G9) -> 0 | I9: =+SUM(START:END!I9) -> 0 | J9: =+SUM(START:END!J9) -> 0 | K9: =IF(J9=0,0,L9/J9) -> 0 | L9: =+SUM(START:END!L9) -> 0 | M9: =J9-D9 -> 0 | N9: =L9-F9 -> 0 | O9: =+SUM(START:END!O9) -> 0 | P9: =IF(O9=0,0,Q9/O9) -> 0 | Q9: =+SUM(START:END!Q9) -> 0 | R9: =J9-O9 -> 0 | S9: =L9-Q9 -> 0
A10: =+B10&C10 -> Véhicules neufs[...] | B10: =+$K$1 -> Véhicules neufs | C10: [...] | D10: =+SUM(START:END!D10) -> 0 | E10: =IF(D10=0,0,F10/D10) -> 0 | F10: =+SUM(START:END!F10) -> 0 | G10: =+SUM(START:END!G10) -> 0 | H10: =IF(G10=0,0,I10/G10) -> 0 | I10: =+SUM(START:END!I10) -> 0 | J10: =+SUM(START:END!J10) -> 0 | K10: =IF(J10=0,0,L10/J10) -> 0 | L10: =+SUM(START:END!L10) -> 0 | M10: =J10-D10 -> 0 | N10: =L10-F10 -> 0 | O10: =+SUM(START:END!O10) -> 0 | P10: =IF(O10=0,0,Q10/O10) -> 0 | Q10: =+SUM(START:END!Q10) -> 0 | R10: =J10-O10 -> 0 | S10: =L10-Q10 -> 0
A11: =+B11&C11 -> Véhicules neufs[...] | B11: =+$K$1 -> Véhicules neufs | C11: [...] | D11: =+SUM(START:END!D11) -> 0 | E11: =IF(D11=0,0,F11/D11) -> 0 | F11: =+SUM(START:END!F11) -> 0 | G11: =+SUM(START:END!G11) -> 0 | H11: =IF(G11=0,0,I11/G11) -> 0 | I11: =+SUM(START:END!I11) -> 0 | J11: =+SUM(START:END!J11) -> 0 | K11: =IF(J11=0,0,L11/J11) -> 0 | L11: =+SUM(START:END!L11) -> 0 | M11: =J11-D11 -> 0 | N11: =L11-F11 -> 0 | O11: =+SUM(START:END!O11) -> 0 | P11: =IF(O11=0,0,Q11/O11) -> 0 | Q11: =+SUM(START:END!Q11) -> 0 | R11: =J11-O11 -> 0 | S11: =L11-Q11 -> 0
A12: =+B12&C12 -> Véhicules neufs[...] | B12: =+$K$1 -> Véhicules neufs | C12: [...] | D12: =+SUM(START:END!D12) -> 0 | E12: =IF(D12=0,0,F12/D12) -> 0 | F12: =+SUM(START:END!F12) -> 0 | G12: =+SUM(START:END!G12) -> 0 | H12: =IF(G12=0,0,I12/G12) -> 0 | I12: =+SUM(START:END!I12) -> 0 | J12: =+SUM(START:END!J12) -> 0 | K12: =IF(J12=0,0,L12/J12) -> 0 | L12: =+SUM(START:END!L12) -> 0 | M12: =J12-D12 -> 0 | N12: =L12-F12 -> 0 | O12: =+SUM(START:END!O12) -> 0 | P12: =IF(O12=0,0,Q12/O12) -> 0 | Q12: =+SUM(START:END!Q12) -> 0 | R12: =J12-O12 -> 0 | S12: =L12-Q12 -> 0
A13: =+B13&C13 -> Véhicules neufsTotal Neufs | B13: =+$K$1 -> Véhicules neufs | C13: Total Neufs | D13: =+SUM(D6:D12) -> 98.677819 | E13: =IF(D13<=0,0,F13/D13) -> 2442.7446 | F13: =+SUM(F6:F12) -> 241044.71 | G13: =+SUM(G6:G12) -> 0 | H13: =IF(G13<=0,0,I13/G13) -> 0 | I13: =+SUM(I6:I12) -> 0 | J13: =+SUM(J6:J12) -> 91 | K13: =IF(J13<=0,0,L13/J13) -> 2345.6588 | L13: =+SUM(L6:L12) -> 213454.95 | M13: =+SUM(M6:M12) -> -7.6778194 | N13: =+SUM(N6:N12) -> -27589.762 | O13: =+SUM(O6:O12) -> 102 | P13: =IF(O13<=0,0,Q13/O13) -> 3391.4427 | Q13: =+SUM(Q6:Q12) -> 345927.16 | R13: =+SUM(R6:R12) -> -11 | S13: =+SUM(S6:S12) -> -132472.21
A14: =+B14&C14 -> Véhicules neufs | B14: =+$K$1 -> Véhicules neufs | M14: =IF(D13=0,0,M13/D13) -> -0.077806943 | N14: =IF(F13=0,0,N13/F13) -> -0.11445911 | R14: =R13/O13 -> -0.10784314 | S14: =IF(Q13=0,0,(S13/Q13)) -> -0.38294828
A15: =+B15&C15 -> Véhicules neufsEx-Démos et courtoisies | B15: =+$K$1 -> Véhicules neufs | C15: Ex-Démos et courtoisies | D15: =+SUM(START:END!D15) -> 4.7142857 | E15: =IF(D15=0,0,F15/D15) -> 2442.5492 | F15: =+SUM(START:END!F15) -> 11514.875 | G15: =+SUM(START:END!G15) -> 0 | H15: =IF(G15=0,0,I15/G15) -> 0 | I15: =+SUM(START:END!I15) -> 0 | J15: =+SUM(START:END!J15) -> 5 | K15: =IF(J15=0,0,L15/J15) -> 1105.4 | L15: =+SUM(START:END!L15) -> 5527 | M15: =J15-D15 -> 0.28571429 | N15: =L15-F15 -> -5987.8748 | O15: =+SUM(START:END!O15) -> 7 | P15: =IF(O15=0,0,Q15/O15) -> 2501.0343 | Q15: =+SUM(START:END!Q15) -> 17507.24 | R15: =J15-O15 -> -2 | S15: =L15-Q15 -> -11980.24
A16: =+B16&C16 -> Véhicules neufs | B16: =+$K$1 -> Véhicules neufs
A17: =+B17&C17 -> Véhicules neufsFlottes | B17: =+$K$1 -> Véhicules neufs | C17: Flottes | D17: =+SUM(START:END!D17) -> 3.7714286 | E17: =IF(D17=0,0,F17/D17) -> 2442.5492 | F17: =+SUM(START:END!F17) -> 9211.8998 | G17: =+SUM(START:END!G17) -> 0 | H17: =IF(G17=0,0,I17/G17) -> 0 | I17: =+SUM(START:END!I17) -> 0 | J17: =+SUM(START:END!J17) -> 3 | K17: =IF(J17=0,0,L17/J17) -> 3401.6467 | L17: =+SUM(START:END!L17) -> 10204.94 | M17: =J17-D17 -> -0.77142857 | N17: =L17-F17 -> 993.04016 | O17: =+SUM(START:END!O17) -> 2 | P17: =IF(O17=0,0,Q17/O17) -> 4190.8 | Q17: =+SUM(START:END!Q17) -> 8381.6 | R17: =J17-O17 -> 1 | S17: =L17-Q17 -> 1823.34
A18: =+B18&C18 -> Véhicules neufs | B18: =+$K$1 -> Véhicules neufs
A19: =+B19&C19 -> Véhicules neufsRachat bail | B19: =+$K$1 -> Véhicules neufs | C19: Rachat bail | F19: =+SUM(START:END!F19) -> 21120 | I19: =+SUM(START:END!I19) -> 0 | L19: =+SUM(START:END!L19) -> 22871.75 | N19: =L19-F19 -> 1751.75 | Q19: =+SUM(START:END!Q19) -> 27119.43 | R19: =O19-K19 -> 0 | S19: =L19-Q19 -> -4247.68
A20: =+B20&C20 -> Véhicules neufs | B20: =+$K$1 -> Véhicules neufs
A21: =+B21&C21 -> Véhicules neufsRev. Finances | B21: =+$K$1 -> Véhicules neufs | C21: Rev. Finances | D21: 0 | E21: =IF(D21=0,0,F21/D21) -> 0 | F21: =+SUM(START:END!F21) -> 17783.442 | G21: 0 | H21: =IF(G21=0,0,I21/G21) -> 0 | I21: =+SUM(START:END!I21) -> 0 | K21: =IF(J13=0,0,L21/(J13+J15)) -> 153.78583 | L21: =+SUM(START:END!L21) -> 14763.44 | N21: =L21-F21 -> -3020.0021 | P21: =IF(O13=0,0,Q21/(O13+O15)) -> 218.88321 | Q21: =+SUM(START:END!Q21) -> 23858.27 | R21: =O21-K21 -> -153.78583 | S21: =L21-Q21 -> -9094.83
A22: =+B22&C22 -> Véhicules neufsRev. Protections | B22: =+$K$1 -> Véhicules neufs | C22: Rev. Protections | D22: 0 | E22: =IF(D22=0,0,F22/D22) -> 0 | F22: =+SUM(START:END!F22) -> 97808.931 | G22: 0 | H22: =IF(G22=0,0,I22/G22) -> 0 | I22: =+SUM(START:END!I22) -> 0 | K22: =IF(J13=0,0,L22/(J13+J15)) -> 966.72667 | L22: =+SUM(START:END!L22) -> 92805.76 | N22: =L22-F22 -> -5003.1715 | P22: =IF(O13=0,0,Q22/(O13+O15)) -> 994.12339 | Q22: =+SUM(START:END!Q22) -> 108359.45 | R22: =O22-K22 -> -966.72667 | S22: =L22-Q22 -> -15553.69
A23: =+B23&C23 -> Véhicules neufsRev. Autres | B23: =+$K$1 -> Véhicules neufs | C23: Rev. Autres | D23: 0 | E23: =IF(D23=0,0,F23/D23) -> 0 | F23: =+SUM(START:END!F23) -> 2998.371 | G23: 0 | H23: =IF(G23=0,0,I23/G23) -> 0 | I23: =+SUM(START:END!I23) -> 0 | K23: =IF(J13=0,0,L23/(J13+J15)) -> 0 | L23: =+SUM(START:END!L23) -> 0 | N23: =L23-F23 -> -2998.371 | P23: =IF(O13=0,0,Q23/(O13+O15)) -> 20.206789 | Q23: =+SUM(START:END!Q23) -> 2202.54 | R23: =O23-K23 -> 0 | S23: =L23-Q23 -> -2202.54
A24: =+B24&C24 -> Véhicules neufsTotal F&I | B24: =+$K$1 -> Véhicules neufs | C24: Total F&I | D24: =+D15+D13 -> 103.39211 | E24: =IF(D24<=0,0,F24/D24) -> 1147 | F24: =F21+F22+F23 -> 118590.74 | G24: =+G15+G13 -> 0 | H24: =IF(G24<=0,0,I24/G24) -> 0 | I24: =I21+I22+I23 -> 0 | J24: =+J15+J13 -> 96 | K24: =IF(J24<=0,0,L24/J24) -> 1120.5125 | L24: =L21+L22+L23 -> 107569.2 | M24: =J24-D24 -> -7.3921051 | N24: =L24-F24 -> -11021.545 | O24: =+O15+O13 -> 109 | P24: =IF(O24<=0,0,Q24/O24) -> 1233.2134 | Q24: =Q21+Q22+Q23 -> 134420.26 | S24: =L24-Q24 -> -26851.06
A25: =+B25&C25 -> Véhicules neufs | B25: =+$K$1 -> Véhicules neufs | N25: =IF(N24=0,0,N24/F24) -> -0.092937646 | S25: =IF(Q24=0,0,(S24/Q24)) -> -0.19975456
A26: =+B26&C26 -> Véhicules neufs | B26: =+$K$1 -> Véhicules neufs
A27: =+B27&C27 -> Véhicules neufsTotal Dépt. Neufs | B27: =+$K$1 -> Véhicules neufs | C27: Total Dépt. Neufs | D27: =+D13+D15+D17 -> 107.16353 | E27: =IF(D27<=0,0,F27/D27) -> 3746.4445 | F27: =F13+F17+F24+F19+F15 -> 401482.23 | G27: =+G13+G15+G17 -> 0 | H27: =IF(G27<=0,0,I27/G27) -> 0 | I27: =I13+I17+I24+I19+I15 -> 0 | J27: =+J13+J15+J17 -> 99 | K27: =IF(J27<=0,0,L27/J27) -> 3632.6044 | L27: =L13+L17+L24+L19+L15 -> 359627.84 | M27: =J27-D27 -> -8.1635337 | N27: =L27-F27 -> -41854.392 | O27: =+O13+O15+O17 -> 111 | P27: =IF(O27<=0,0,Q27/O27) -> 4805.0062 | Q27: =Q13+Q17+Q24+Q19+Q15 -> 533355.69 | R27: =J27-O27 -> -12 | S27: =L27-Q27 -> -173727.85
A28: =+B28&C28 -> Véhicules neufs | B28: =+$K$1 -> Véhicules neufs | M28: =M27/D27 -> -0.07617828 | N28: =N27/F27 -> -0.10424967 | R28: =R27/O27 -> -0.10810811 | S28: =IF(Q27=0,0,S27/Q27) -> -0.32572606
A29: =+B29&C29 -> Véhicules neufs | B29: =+$K$1 -> Véhicules neufs
A30: =+B30&C30 -> Véhicules neufsDEPENSES | B30: =+$K$1 -> Véhicules neufs | C30: DEPENSES
A31: =+B31&C31 -> Véhicules neufsComm. vendeurs | B31: =+$K$1 -> Véhicules neufs | C31: Comm. vendeurs | E31: =F31/D$24 -> 776.22221 | F31: =+SUM(START:END!F31) -> 80255.248 | H31: =I31/G$24 -> #DIV/0! | I31: =+SUM(START:END!I31) -> 0 | J31: =L31/L13 -> 0.35962595 | K31: =IF(L31=0,0,L31/J$24) -> 799.62437 | L31: =+SUM(START:END!L31) -> 76763.94 | N31: =L31-F31 -> -3491.308 | P31: =IF(Q31=0,0,Q31/O$24) -> 1010.7386 | Q31: =+SUM(START:END!Q31) -> 110170.51 | S31: =L31-Q31 -> -33406.57
A32: =+B32&C32 -> Véhicules neufsComm. F&I | B32: =+$K$1 -> Véhicules neufs | C32: Comm. F&I | E32: =F32/D$24 -> 344.1 | F32: =+SUM(START:END!F32) -> 35577.223 | H32: =I32/G$24 -> #DIV/0! | I32: =+SUM(START:END!I32) -> 0 | J32: =L32/L24 -> 0.3004188 | K32: =IF(L32=0,0,L32/J$24) -> 336.62302 | L32: =+SUM(START:END!L32) -> 32315.81 | N32: =L32-F32 -> -3261.4134 | P32: =IF(Q32=0,0,Q32/O$24) -> 410.26229 | Q32: =+SUM(START:END!Q32) -> 44718.59 | S32: =L32-Q32 -> -12402.78
A33: =+B33&C33 -> Véhicules neufsFrais de livraison | B33: =+$K$1 -> Véhicules neufs | C33: Frais de livraison | E33: =F33/D$24 -> 113.25898 | F33: =+SUM(START:END!F33) -> 11710.084 | H33: =I33/G$24 -> #DIV/0! | I33: =+SUM(START:END!I33) -> 0 | K33: =IF(L33=0,0,L33/J$24) -> 126.76219 | L33: =+SUM(START:END!L33) -> 12169.17 | N33: =L33-F33 -> 459.08598 | P33: =IF(Q33=0,0,Q33/O$24) -> 113.8745 | Q33: =+SUM(START:END!Q33) -> 12412.32 | S33: =L33-Q33 -> -243.15
A34: =+B34&C34 -> Véhicules neufsService gratuit 1 | B34: =+$K$1 -> Véhicules neufs | C34: Service gratuit 1 | E34: =F34/D$24 -> 5.1177856 | F34: =+SUM(START:END!F34) -> 529.13863 | H34: =I34/G$24 -> #DIV/0! | I34: =+SUM(START:END!I34) -> 0 | K34: =IF(L34=0,0,L34/J$24) -> 0.41666667 | L34: =+SUM(START:END!L34) -> 40 | N34: =L34-F34 -> -489.13863 | P34: =IF(Q34=0,0,Q34/O$24) -> 7.0702752 | Q34: =+SUM(START:END!Q34) -> 770.66 | S34: =L34-Q34 -> -730.66
A35: =+B35&C35 -> Véhicules neufsEntretien stock | B35: =+$K$1 -> Véhicules neufs | C35: Entretien stock | E35: =F35/D$24 -> 105.01044 | F35: =+SUM(START:END!F35) -> 10857.251 | H35: =I35/G$24 -> #DIV/0! | I35: =+SUM(START:END!I35) -> 0 | K35: =IF(L35=0,0,L35/J$24) -> 89.656562 | L35: =+SUM(START:END!L35) -> 8607.03 | N35: =L35-F35 -> -2250.2208 | P35: =IF(Q35=0,0,Q35/O$24) -> 119.64138 | Q35: =+SUM(START:END!Q35) -> 13040.91 | S35: =L35-Q35 -> -4433.88
A36: =+B36&C36 -> Véhicules neufsPublicité 1 | B36: =+$K$1 -> Véhicules neufs | C36: Publicité 1 | E36: =F36/D$24 -> 300.75552 | F36: =+SUM(START:END!F36) -> 31095.747 | H36: =I36/G$24 -> #DIV/0! | I36: =+SUM(START:END!I36) -> 0 | K36: =IF(L36=0,0,L36/J$24) -> 135.52729 | L36: =+SUM(START:END!L36) -> 13010.62 | N36: =L36-F36 -> -18085.127 | P36: =IF(Q36=0,0,Q36/O$24) -> 168.27872 | Q36: =+SUM(START:END!Q36) -> 18342.38 | S36: =L36-Q36 -> -5331.76
A37: =+B37&C37 -> Véhicules neufsIntérêt de gros | B37: =+$K$1 -> Véhicules neufs | C37: Intérêt de gros | E37: =F37/D$24 -> 48.257416 | F37: =+SUM(START:END!F37) -> 4989.4358 | H37: =I37/G$24 -> #DIV/0! | I37: =+SUM(START:END!I37) -> 0 | K37: =IF(L37=0,0,L37/J$24) -> 86.082917 | L37: =+SUM(START:END!L37) -> 8263.96 | N37: =L37-F37 -> 3274.5242 | P37: =IF(Q37=0,0,Q37/O$24) -> 12.485413 | Q37: =+SUM(START:END!Q37) -> 1360.91 | S37: =L37-Q37 -> 6903.05
A38: =+B38&C38 -> Véhicules neufs[...] | B38: =+$K$1 -> Véhicules neufs | C38: [...] | E38: =F38/D$24 -> 0 | F38: =+SUM(START:END!F38) -> 0 | H38: =I38/G$24 -> #DIV/0! | I38: =+SUM(START:END!I38) -> 0 | K38: =IF(L38=0,0,L38/J$24) -> 0 | L38: =+SUM(START:END!L38) -> 0 | N38: =L38-F38 -> 0 | P38: =IF(Q38=0,0,Q38/O$24) -> 0 | Q38: =+SUM(START:END!Q38) -> 0 | S38: =L38-Q38 -> 0
A39: =+B39&C39 -> Véhicules neufs[...] | B39: =+$K$1 -> Véhicules neufs | C39: [...] | E39: =F39/D$24 -> 0 | F39: =+SUM(START:END!F39) -> 0 | H39: =I39/G$24 -> #DIV/0! | I39: =+SUM(START:END!I39) -> 0 | K39: =IF(L39=0,0,L39/J$24) -> 0 | L39: =+SUM(START:END!L39) -> 0 | N39: =L39-F39 -> 0 | P39: =IF(Q39=0,0,Q39/O$24) -> 0 | Q39: =+SUM(START:END!Q39) -> 0 | S39: =L39-Q39 -> 0
A40: =+B40&C40 -> Véhicules neufs[...] | B40: =+$K$1 -> Véhicules neufs | C40: [...] | E40: =F40/D$24 -> 0 | F40: =+SUM(START:END!F40) -> 0 | H40: =I40/G$24 -> #DIV/0! | I40: =+SUM(START:END!I40) -> 0 | K40: =IF(L40=0,0,L40/J$24) -> 0 | L40: =+SUM(START:END!L40) -> 0 | N40: =L40-F40 -> 0 | P40: =IF(Q40=0,0,Q40/O$24) -> 0 | Q40: =+SUM(START:END!Q40) -> 0 | S40: =L40-Q40 -> 0
...

Sheet START

Sheet Juillet 2023
C1: =[5]Parametres!B1 -> Volks | K1: Véhicules neufs | S1: =CONCATENATE("Réalisé,"," ",[5]Parametres!B3," ",[5]Parametres!B4) -> Réalisé, Juillet 2023
D2: X | E2: O | F2: U | J2: NB | L2: $ | O2: NB | Q2: $ | V2: *** NE PAS EFFACER / Pour An Précédente ***
D3: BUDGET ORIGINAL | J3: RÉALISATION | M3: ÉCART réel / Budget | O3: ANNÉE PRÉCÉDENTE | R3: ECART (réel/ Ann.Préc.) | V3: NEUF | W3: 0.45
D4: UNITÉS | E4: $P/UNITÉ | F4: $PROFITS | J4: UNITÉS | K4: $P/UNITE | L4: $PROFITS | M4: UNITÉS | N4: $PROFITS | O4: UNITÉS | P4: $P/UNITE | Q4: $PROFITS | R4: UNITÉS | S4: $PROFITS | V4: USAGE | W4: 0.1
A5: Véhicules neufsVentes nettes | B5: Véhicules neufs | C5: Ventes nettes | F5: {=+INDEX('[5]Budget original'!$A$2:$AO$500,MATCH($A5,'[5]Budget original'!$A$2:$A$500,0),MATCH(F$2,'[5]Budget original'!$A$2:$AO$2,0))} -> 2357227.3 | L5: =-SUMIFS([5]BV_Data_An_Cour!$O:$O,[5]BV_Data_An_Cour!$X:$X,"Oui",[5]BV_Data_An_Cour!$U:$U,$B5) -> 2122186.9 | Q5: =-SUMIFS([5]BV_Data_An_Prec!$O:$O,[5]BV_Data_An_Prec!$X:$X,"Oui",[5]BV_Data_An_Prec!$U:$U,$B5) -> 2657067 | V5: SERVICE | W5: 0.225
A6: Véhicules neufsAutos détail | B6: Véhicules neufs | C6: Autos détail | D6: {=+INDEX('[5]Budget original'!$A$2:$AO$500,MATCH($A6,'[5]Budget original'!$A$2:$A$500,0),MATCH(D$2,'[5]Budget original'!$A$2:$AO$2,0))} -> 10.048 | E6: =IF(D6=0,0,F6/D6) -> 1988.434 | F6: {=+INDEX('[5]Budget original'!$A$2:$AO$500,MATCH($A6,'[5]Budget original'!$A$2:$A$500,0),MATCH(F$2,'[5]Budget original'!$A$2:$AO$2,0))} -> 19979.785 | J6: =-SUMIFS([5]BV_Data_An_Cour!$O:$O,[5]BV_Data_An_Cour!$U:$U,$B6,[5]BV_Data_An_Cour!$V:$V,$C6,[5]BV_Data_An_Cour!$W:$W,J$2) -> 12 | K6: =IF(J6=0,0,L6/J6) -> 1882.1942 | L6: =-SUMIFS([5]BV_Data_An_Cour!$O:$O,[5]BV_Data_An_Cour!$U:$U,$B6,[5]BV_Data_An_Cour!$V:$V,$C6,[5]BV_Data_An_Cour!$W:$W,L$2) -> 22586.33 | M6: =J6-D6 -> 1.952 | N6: =L6-F6 -> 2606.5452 | O6: =-SUMIFS([5]BV_Data_An_Prec!$O:$O,[5]BV_Data_An_Prec!$U:$U,$B6,[5]BV_Data_An_Prec!$V:$V,$C6,[5]BV_Data_An_Prec!$W:$W,O$2) -> 13 | P6: =IF(O6=0,0,Q6/O6) -> 2819.2123 | Q6: =-SUMIFS([5]BV_Data_An_Prec!$O:$O,[5]BV_Data_An_Prec!$U:$U,$B6,[5]BV_Data_An_Prec!$V:$V,$C6,[5]BV_Data_An_Prec!$W:$W,Q$2) -> 36649.76 | R6: =J6-O6 -> -1 | S6: =L6-Q6 -> -14063.43 | V6: CARROSSERIE | W6: 0.025
A7: Véhicules neufsCamions détail | B7: Véhicules neufs | C7: Camions détail | D7: {=+INDEX('[5]Budget original'!$A$2:$AO$500,MATCH($A7,'[5]Budget original'!$A$2:$A$500,0),MATCH(D$2,'[5]Budget original'!$A$2:$AO$2,0))} -> 40.187981 | E7: =IF(D7=0,0,F7/D7) -> 2556.3336 | F7: {=+INDEX('[5]Budget original'!$A$2:$AO$500,MATCH($A7,'[5]Budget original'!$A$2:$A$500,0),MATCH(F$2,'[5]Budget original'!$A$2:$AO$2,0))} -> 102733.89 | J7: =-SUMIFS([5]BV_Data_An_Cour!$O:$O,[5]BV_Data_An_Cour!$U:$U,$B7,[5]BV_Data_An_Cour!$V:$V,$C7,[5]BV_Data_An_Cour!$W:$W,J$2) -> 24 | K7: =IF(J7=0,0,L7/J7) -> 2577.0196 | L7: =-SUMIFS([5]BV_Data_An_Cour!$O:$O,[5]BV_Data_An_Cour!$U:$U,$B7,[5]BV_Data_An_Cour!$V:$V,$C7,[5]BV_Data_An_Cour!$W:$W,L$2) -> 61848.47 | M7: =J7-D7 -> -16.187981 | N7: =L7-F7 -> -40885.417 | O7: =-SUMIFS([5]BV_Data_An_Prec!$O:$O,[5]BV_Data_An_Prec!$U:$U,$B7,[5]BV_Data_An_Prec!$V:$V,$C7,[5]BV_Data_An_Prec!$W:$W,O$2) -> 37 | P7: =IF(O7=0,0,Q7/O7) -> 3278.5565 | Q7: =-SUMIFS([5]BV_Data_An_Prec!$O:$O,[5]BV_Data_An_Prec!$U:$U,$B7,[5]BV_Data_An_Prec!$V:$V,$C7,[5]BV_Data_An_Prec!$W:$W,Q$2) -> 121306.59 | R7: =J7-O7 -> -13 | S7: =L7-Q7 -> -59458.12 | V7: PIECES | W7: 0.2
A8: Véhicules neufsSprinter | B8: Véhicules neufs | C8: Sprinter | D8: {=+INDEX('[5]Budget original'!$A$2:$AO$500,MATCH($A8,'[5]Budget original'!$A$2:$A$500,0),MATCH(D$2,'[5]Budget original'!$A$2:$AO$2,0))} -> 0 | E8: =IF(D8=0,0,F8/D8) -> 0 | F8: {=+INDEX('[5]Budget original'!$A$2:$AO$500,MATCH($A8,'[5]Budget original'!$A$2:$A$500,0),MATCH(F$2,'[5]Budget original'!$A$2:$AO$2,0))} -> 0 | J8: =-SUMIFS([5]BV_Data_An_Cour!$O:$O,[5]BV_Data_An_Cour!$U:$U,$B8,[5]BV_Data_An_Cour!$V:$V,$C8,[5]BV_Data_An_Cour!$W:$W,J$2) -> 0 | K8: =IF(J8=0,0,L8/J8) -> 0 | L8: =-SUMIFS([5]BV_Data_An_Cour!$O:$O,[5]BV_Data_An_Cour!$U:$U,$B8,[5]BV_Data_An_Cour!$V:$V,$C8,[5]BV_Data_An_Cour!$W:$W,L$2) -> 0 | M8: =J8-D8 -> 0 | N8: =L8-F8 -> 0 | O8: =-SUMIFS([5]BV_Data_An_Prec!$O:$O,[5]BV_Data_An_Prec!$U:$U,$B8,[5]BV_Data_An_Prec!$V:$V,$C8,[5]BV_Data_An_Prec!$W:$W,O$2) -> 0 | P8: =IF(O8=0,0,Q8/O8) -> 0 | Q8: =-SUMIFS([5]BV_Data_An_Prec!$O:$O,[5]BV_Data_An_Prec!$U:$U,$B8,[5]BV_Data_An_Prec!$V:$V,$C8,[5]BV_Data_An_Prec!$W:$W,Q$2) -> 0 | R8: =J8-O8 -> 0 | S8: =L8-Q8 -> 0 | W8: =SUM(W3:W7) -> 1
A9: Véhicules neufsMoto détail | B9: Véhicules neufs | C9: Moto détail | D9: {=+INDEX('[5]Budget original'!$A$2:$AO$500,MATCH($A9,'[5]Budget original'!$A$2:$A$500,0),MATCH(D$2,'[5]Budget original'!$A$2:$AO$2,0))} -> 0 | E9: =IF(D9=0,0,F9/D9) -> 0 | F9: {=+INDEX('[5]Budget original'!$A$2:$AO$500,MATCH($A9,'[5]Budget original'!$A$2:$A$500,0),MATCH(F$2,'[5]Budget original'!$A$2:$AO$2,0))} -> 0 | J9: =-SUMIFS([5]BV_Data_An_Cour!$O:$O,[5]BV_Data_An_Cour!$U:$U,$B9,[5]BV_Data_An_Cour!$V:$V,$C9,[5]BV_Data_An_Cour!$W:$W,J$2) -> 0 | K9: =IF(J9=0,0,L9/J9) -> 0 | L9: =-SUMIFS([5]BV_Data_An_Cour!$O:$O,[5]BV_Data_An_Cour!$U:$U,$B9,[5]BV_Data_An_Cour!$V:$V,$C9,[5]BV_Data_An_Cour!$W:$W,L$2) -> 0 | M9: =J9-D9 -> 0 | N9: =L9-F9 -> 0 | O9: =-SUMIFS([5]BV_Data_An_Prec!$O:$O,[5]BV_Data_An_Prec!$U:$U,$B9,[5]BV_Data_An_Prec!$V:$V,$C9,[5]BV_Data_An_Prec!$W:$W,O$2) -> 0 | P9: =IF(O9=0,0,Q9/O9) -> 0 | Q9: =-SUMIFS([5]BV_Data_An_Prec!$O:$O,[5]BV_Data_An_Prec!$U:$U,$B9,[5]BV_Data_An_Prec!$V:$V,$C9,[5]BV_Data_An_Prec!$W:$W,Q$2) -> 0 | R9: =J9-O9 -> 0 | S9: =L9-Q9 -> 0
A10: Véhicules neufs[...] | B10: Véhicules neufs | C10: [...] | D10: 0 | E10: =IF(D10=0,0,F10/D10) -> 0 | F10: {=+INDEX('[5]Budget original'!$A$2:$AO$500,MATCH($A10,'[5]Budget original'!$A$2:$A$500,0),MATCH(F$2,'[5]Budget original'!$A$2:$AO$2,0))} -> 0 | J10: =-SUMIFS([5]BV_Data_An_Cour!$O:$O,[5]BV_Data_An_Cour!$U:$U,$B10,[5]BV_Data_An_Cour!$V:$V,$C10,[5]BV_Data_An_Cour!$W:$W,J$2) -> 0 | K10: =IF(J10=0,0,L10/J10) -> 0 | L10: =-SUMIFS([5]BV_Data_An_Cour!$O:$O,[5]BV_Data_An_Cour!$U:$U,$B10,[5]BV_Data_An_Cour!$V:$V,$C10,[5]BV_Data_An_Cour!$W:$W,L$2) -> 0 | M10: =J10-D10 -> 0 | N10: =L10-F10 -> 0 | O10: =-SUMIFS([5]BV_Data_An_Prec!$O:$O,[5]BV_Data_An_Prec!$U:$U,$B10,[5]BV_Data_An_Prec!$V:$V,$C10,[5]BV_Data_An_Prec!$W:$W,O$2) -> 0 | P10: =IF(O10=0,0,Q10/O10) -> 0 | Q10: =-SUMIFS([5]BV_Data_An_Prec!$O:$O,[5]BV_Data_An_Prec!$U:$U,$B10,[5]BV_Data_An_Prec!$V:$V,$C10,[5]BV_Data_An_Prec!$W:$W,Q$2) -> 0 | R10: =J10-O10 -> 0 | S10: =L10-Q10 -> 0
A11: Véhicules neufs[...] | B11: Véhicules neufs | C11: [...] | D11: 0 | E11: =IF(D11=0,0,F11/D11) -> 0 | F11: {=+INDEX('[5]Budget original'!$A$2:$AO$500,MATCH($A11,'[5]Budget original'!$A$2:$A$500,0),MATCH(F$2,'[5]Budget original'!$A$2:$AO$2,0))} -> 0 | J11: =-SUMIFS([5]BV_Data_An_Cour!$O:$O,[5]BV_Data_An_Cour!$U:$U,$B11,[5]BV_Data_An_Cour!$V:$V,$C11,[5]BV_Data_An_Cour!$W:$W,J$2) -> 0 | K11: =IF(J11=0,0,L11/J11) -> 0 | L11: =-SUMIFS([5]BV_Data_An_Cour!$O:$O,[5]BV_Data_An_Cour!$U:$U,$B11,[5]BV_Data_An_Cour!$V:$V,$C11,[5]BV_Data_An_Cour!$W:$W,L$2) -> 0 | M11: =J11-D11 -> 0 | N11: =L11-F11 -> 0 | O11: =-SUMIFS([5]BV_Data_An_Prec!$O:$O,[5]BV_Data_An_Prec!$U:$U,$B11,[5]BV_Data_An_Prec!$V:$V,$C11,[5]BV_Data_An_Prec!$W:$W,O$2) -> 0 | P11: =IF(O11=0,0,Q11/O11) -> 0 | Q11: =-SUMIFS([5]BV_Data_An_Prec!$O:$O,[5]BV_Data_An_Prec!$U:$U,$B11,[5]BV_Data_An_Prec!$V:$V,$C11,[5]BV_Data_An_Prec!$W:$W,Q$2) -> 0 | R11: =J11-O11 -> 0 | S11: =L11-Q11 -> 0
A12: Véhicules neufs[...] | B12: Véhicules neufs | C12: [...] | D12: 0 | E12: =IF(D12=0,0,F12/D12) -> 0 | F12: {=+INDEX('[5]Budget original'!$A$2:$AO$500,MATCH($A12,'[5]Budget original'!$A$2:$A$500,0),MATCH(F$2,'[5]Budget original'!$A$2:$AO$2,0))} -> 0 | J12: =-SUMIFS([5]BV_Data_An_Cour!$O:$O,[5]BV_Data_An_Cour!$U:$U,$B12,[5]BV_Data_An_Cour!$V:$V,$C12,[5]BV_Data_An_Cour!$W:$W,J$2) -> 0 | K12: =IF(J12=0,0,L12/J12) -> 0 | L12: =-SUMIFS([5]BV_Data_An_Cour!$O:$O,[5]BV_Data_An_Cour!$U:$U,$B12,[5]BV_Data_An_Cour!$V:$V,$C12,[5]BV_Data_An_Cour!$W:$W,L$2) -> 0 | M12: =J12-D12 -> 0 | N12: =L12-F12 -> 0 | O12: =-SUMIFS([5]BV_Data_An_Prec!$O:$O,[5]BV_Data_An_Prec!$U:$U,$B12,[5]BV_Data_An_Prec!$V:$V,$C12,[5]BV_Data_An_Prec!$W:$W,O$2) -> 0 | P12: =IF(O12=0,0,Q12/O12) -> 0 | Q12: =-SUMIFS([5]BV_Data_An_Prec!$O:$O,[5]BV_Data_An_Prec!$U:$U,$B12,[5]BV_Data_An_Prec!$V:$V,$C12,[5]BV_Data_An_Prec!$W:$W,Q$2) -> 0 | R12: =J12-O12 -> 0 | S12: =L12-Q12 -> 0
A13: Véhicules neufsTotal Neufs | B13: Véhicules neufs | C13: Total Neufs | D13: =+SUM(D6:D12) -> 50.235981 | E13: =IF(D13<=0,0,F13/D13) -> 2442.7446 | F13: =+SUM(F6:F12) -> 122713.67 | J13: =+SUM(J6:J12) -> 36 | K13: =IF(J13<=0,0,L13/J13) -> 2345.4111 | L13: =+SUM(L6:L12) -> 84434.8 | M13: =+SUM(M6:M12) -> -14.235981 | N13: =+SUM(N6:N12) -> -38278.872 | O13: =+SUM(O6:O12) -> 50 | P13: =IF(O13<=0,0,Q13/O13) -> 3159.127 | Q13: =+SUM(Q6:Q12) -> 157956.35 | R13: =+SUM(R6:R12) -> -14 | S13: =+SUM(S6:S12) -> -73521.55
A14: Véhicules neufs | B14: Véhicules neufs | M14: =IF(D13=0,0,M13/D13) -> -0.28338216 | N14: =IF(F13=0,0,N13/F13) -> -0.31193649 | R14: =R13/O13 -> -0.28 | S14: =IF(Q13=0,0,(S13/Q13)) -> -0.46545486 | AD14: 20 | AE14: 1000 | AF14: =AD14*AE14 -> 20000
A15: Véhicules neufsEx-Démos et courtoisies | B15: Véhicules neufs | C15: Ex-Démos et courtoisies | D15: {=+INDEX('[5]Budget original'!$A$2:$AO$500,MATCH($A15,'[5]Budget original'!$A$2:$A$500,0),MATCH(D$2,'[5]Budget original'!$A$2:$AO$2,0))} -> 2.4 | E15: =IF(D15=0,0,F15/D15) -> 2442.5492 | F15: {=+INDEX('[5]Budget original'!$A$2:$AO$500,MATCH($A15,'[5]Budget original'!$A$2:$A$500,0),MATCH(F$2,'[5]Budget original'!$A$2:$AO$2,0))} -> 5862.1181 | J15: =-SUMIFS([5]BV_Data_An_Cour!$O:$O,[5]BV_Data_An_Cour!$U:$U,$B15,[5]BV_Data_An_Cour!$V:$V,$C15,[5]BV_Data_An_Cour!$W:$W,J$2) -> 3 | K15: =IF(J15=0,0,L15/J15) -> 851.18 | L15: =-SUMIFS([5]BV_Data_An_Cour!$O:$O,[5]BV_Data_An_Cour!$U:$U,$B15,[5]BV_Data_An_Cour!$V:$V,$C15,[5]BV_Data_An_Cour!$W:$W,L$2) -> 2553.54 | M15: =J15-D15 -> 0.6 | N15: =L15-F15 -> -3308.5781 | O15: =-SUMIFS([5]BV_Data_An_Prec!$O:$O,[5]BV_Data_An_Prec!$U:$U,$B15,[5]BV_Data_An_Prec!$V:$V,$C15,[5]BV_Data_An_Prec!$W:$W,O$2) -> 3 | P15: =IF(O15=0,0,Q15/O15) -> 2992.6 | Q15: =-SUMIFS([5]BV_Data_An_Prec!$O:$O,[5]BV_Data_An_Prec!$U:$U,$B15,[5]BV_Data_An_Prec!$V:$V,$C15,[5]BV_Data_An_Prec!$W:$W,Q$2) -> 8977.8 | R15: =J15-O15 -> 0 | S15: =L15-Q15 -> -6424.26 | AD15: 25 | AE15: =AF15/AD15 -> 800 | AF15: =AF14 -> 20000
A16: Véhicules neufs | B16: Véhicules neufs
A17: Véhicules neufsFlottes | B17: Véhicules neufs | C17: Flottes | D17: {=+INDEX('[5]Budget original'!$A$2:$AO$500,MATCH($A17,'[5]Budget original'!$A$2:$A$500,0),MATCH(D$2,'[5]Budget original'!$A$2:$AO$2,0))} -> 1.92 | E17: =IF(D17=0,0,F17/D17) -> 2442.5492 | F17: {=+INDEX('[5]Budget original'!$A$2:$AO$500,MATCH($A17,'[5]Budget original'!$A$2:$A$500,0),MATCH(F$2,'[5]Budget original'!$A$2:$AO$2,0))} -> 4689.6945 | J17: =-SUMIFS([5]BV_Data_An_Cour!$O:$O,[5]BV_Data_An_Cour!$U:$U,$B17,[5]BV_Data_An_Cour!$V:$V,$C17,[5]BV_Data_An_Cour!$W:$W,J$2) -> 1 | K17: =IF(J17=0,0,L17/J17) -> 4279.05 | L17: =-SUMIFS([5]BV_Data_An_Cour!$O:$O,[5]BV_Data_An_Cour!$U:$U,$B17,[5]BV_Data_An_Cour!$V:$V,$C17,[5]BV_Data_An_Cour!$W:$W,L$2) -> 4279.05 | M17: =J17-D17 -> -0.92 | N17: =L17-F17 -> -410.64446 | O17: =-SUMIFS([5]BV_Data_An_Prec!$O:$O,[5]BV_Data_An_Prec!$U:$U,$B17,[5]BV_Data_An_Prec!$V:$V,$C17,[5]BV_Data_An_Prec!$W:$W,O$2) -> 2 | P17: =IF(O17=0,0,Q17/O17) -> 4190.8 | Q17: =-SUMIFS([5]BV_Data_An_Prec!$O:$O,[5]BV_Data_An_Prec!$U:$U,$B17,[5]BV_Data_An_Prec!$V:$V,$C17,[5]BV_Data_An_Prec!$W:$W,Q$2) -> 8381.6 | R17: =J17-O17 -> -1 | S17: =L17-Q17 -> -4102.55 | V17: =+L13+L15+L17-4000 -> 87267.39
A18: Véhicules neufs | B18: Véhicules neufs | V18: =+L31/V17 -> 0.37581129
A19: Véhicules neufsRachat bail | B19: Véhicules neufs | C19: Rachat bail | D19: {=+INDEX('[5]Budget original'!$A$2:$AO$500,MATCH($A19,'[5]Budget original'!$A$2:$A$500,0),MATCH(D$2,'[5]Budget original'!$A$2:$AO$2,0))} -> 0 | E19: =IF(D19=0,0,F19/D19) -> 0 | F19: {=+INDEX('[5]Budget original'!$A$2:$AO$500,MATCH($A19,'[5]Budget original'!$A$2:$A$500,0),MATCH(F$2,'[5]Budget original'!$A$2:$AO$2,0))} -> 9600 | L19: =-SUMIFS([5]BV_Data_An_Cour!$O:$O,[5]BV_Data_An_Cour!$U:$U,$B19,[5]BV_Data_An_Cour!$V:$V,$C19,[5]BV_Data_An_Cour!$W:$W,L$2) -> 9971 | N19: =L19-F19 -> 371 | Q19: =-SUMIFS([5]BV_Data_An_Prec!$O:$O,[5]BV_Data_An_Prec!$U:$U,$B19,[5]BV_Data_An_Prec!$V:$V,$C19,[5]BV_Data_An_Prec!$W:$W,Q$2) -> 13968.33 | R19: =O19-K19 -> 0 | S19: =L19-Q19 -> -3997.33
A20: Véhicules neufs | B20: Véhicules neufs
A21: Véhicules neufsRev. Finances | B21: Véhicules neufs | C21: Rev. Finances | D21: {=+INDEX('[5]Budget original'!$A$2:$AO$500,MATCH($A21,'[5]Budget original'!$A$2:$A$500,0),MATCH(D$2,'[5]Budget original'!$A$2:$AO$2,0))} -> 0 | E21: =IF(D21=0,0,F21/D21) -> 0 | F21: {=+INDEX('[5]Budget original'!$A$2:$AO$500,MATCH($A21,'[5]Budget original'!$A$2:$A$500,0),MATCH(F$2,'[5]Budget original'!$A$2:$AO$2,0))} -> 9053.3887 | K21: =IF(J13=0,0,L21/(J13+J15)) -> 247.8859 | L21: =-SUMIFS([5]BV_Data_An_Cour!$O:$O,[5]BV_Data_An_Cour!$U:$U,$B21,[5]BV_Data_An_Cour!$V:$V,$C21,[5]BV_Data_An_Cour!$W:$W,L$2) -> 9667.55 | N21: =L21-F21 -> 614.1613 | P21: =IF(O13=0,0,Q21/(O13+O15)) -> 208.71698 | Q21: =-SUMIFS([5]BV_Data_An_Prec!$O:$O,[5]BV_Data_An_Prec!$U:$U,$B21,[5]BV_Data_An_Prec!$V:$V,$C21,[5]BV_Data_An_Prec!$W:$W,Q$2) -> 11062 | R21: =O21-K21 -> -247.8859 | S21: =L21-Q21 -> -1394.45
A22: Véhicules neufsRev. Protections | B22: Véhicules neufs | C22: Rev. Protections | D22: {=+INDEX('[5]Budget original'!$A$2:$AO$500,MATCH($A22,'[5]Budget original'!$A$2:$A$500,0),MATCH(D$2,'[5]Budget original'!$A$2:$AO$2,0))} -> 0 | E22: =IF(D22=0,0,F22/D22) -> 0 | F22: {=+INDEX('[5]Budget original'!$A$2:$AO$500,MATCH($A22,'[5]Budget original'!$A$2:$A$500,0),MATCH(F$2,'[5]Budget original'!$A$2:$AO$2,0))} -> 49793.638 | K22: =IF(J13=0,0,L22/(J13+J15)) -> 1110.4236 | L22: =-SUMIFS([5]BV_Data_An_Cour!$O:$O,[5]BV_Data_An_Cour!$U:$U,$B22,[5]BV_Data_An_Cour!$V:$V,$C22,[5]BV_Data_An_Cour!$W:$W,L$2) -> 43306.52 | N22: =L22-F22 -> -6487.1178 | P22: =IF(O13=0,0,Q22/(O13+O15)) -> 1043.6472 | Q22: =-SUMIFS([5]BV_Data_An_Prec!$O:$O,[5]BV_Data_An_Prec!$U:$U,$B22,[5]BV_Data_An_Prec!$V:$V,$C22,[5]BV_Data_An_Prec!$W:$W,Q$2) -> 55313.3 | R22: =O22-K22 -> -1110.4236 | S22: =L22-Q22 -> -12006.78
A23: Véhicules neufsRev. Autres | B23: Véhicules neufs | C23: Rev. Autres | D23: {=+INDEX('[5]Budget original'!$A$2:$AO$500,MATCH($A23,'[5]Budget original'!$A$2:$A$500,0),MATCH(D$2,'[5]Budget original'!$A$2:$AO$2,0))} -> 0 | E23: =IF(D23=0,0,F23/D23) -> 0 | F23: {=+INDEX('[5]Budget original'!$A$2:$AO$500,MATCH($A23,'[5]Budget original'!$A$2:$A$500,0),MATCH(F$2,'[5]Budget original'!$A$2:$AO$2,0))} -> 1526.4434 | K23: =IF(J13=0,0,L23/(J13+J15)) -> 0 | L23: =-SUMIFS([5]BV_Data_An_Cour!$O:$O,[5]BV_Data_An_Cour!$U:$U,$B23,[5]BV_Data_An_Cour!$V:$V,$C23,[5]BV_Data_An_Cour!$W:$W,L$2) -> 0 | N23: =L23-F23 -> -1526.4434 | P23: =IF(O13=0,0,Q23/(O13+O15)) -> 26.998868 | Q23: =-SUMIFS([5]BV_Data_An_Prec!$O:$O,[5]BV_Data_An_Prec!$U:$U,$B23,[5]BV_Data_An_Prec!$V:$V,$C23,[5]BV_Data_An_Prec!$W:$W,Q$2) -> 1430.94 | R23: =O23-K23 -> 0 | S23: =L23-Q23 -> -1430.94
A24: Véhicules neufsTotal F&I | B24: Véhicules neufs | C24: Total F&I | D24: =+D15+D13 -> 52.635981 | E24: =IF(D24<=0,0,F24/D24) -> 1147 | F24: =F21+F22+F23 -> 60373.47 | J24: =+J15+J13 -> 39 | K24: =IF(J24<=0,0,L24/J24) -> 1358.3095 | L24: =L21+L22+L23 -> 52974.07 | M24: =J24-D24 -> -13.635981 | N24: =L24-F24 -> -7399.4 | O24: =+O15+O13 -> 53 | P24: =IF(O24<=0,0,Q24/O24) -> 1279.363 | Q24: =Q21+Q22+Q23 -> 67806.24 | S24: =L24-Q24 -> -14832.17
A25: Véhicules neufs | B25: Véhicules neufs | N25: =IF(N24=0,0,N24/F24) -> -0.12256046 | S25: =IF(Q24=0,0,(S24/Q24)) -> -0.21874344
A26: Véhicules neufs | B26: Véhicules neufs
A27: Véhicules neufsTotal Dépt. Neufs | B27: Véhicules neufs | C27: Total Dépt. Neufs | D27: =+D13+D15+D17 -> 54.555981 | E27: =IF(D27<=0,0,F27/D27) -> 3725.3286 | F27: =F13+F17+F24+F19+F15 -> 203238.95 | J27: =+J13+J15+J17 -> 40 | K27: =IF(J27<=0,0,L27/J27) -> 3855.3115 | L27: =L13+L17+L24+L19+L15 -> 154212.46 | M27: =J27-D27 -> -14.555981 | N27: =L27-F27 -> -49026.494 | O27: =+O13+O15+O17 -> 55 | P27: =IF(O27<=0,0,Q27/O27) -> 4674.3695 | Q27: =Q13+Q17+Q24+Q19+Q15 -> 257090.32 | R27: =J27-O27 -> -15 | S27: =L27-Q27 -> -102877.86
A28: Véhicules neufs | B28: Véhicules neufs | L28: =L27/F27 -> 0.75877413 | M28: =M27/D27 -> -0.26680816 | N28: =N27/F27 -> -0.24122587 | R28: =R27/O27 -> -0.27272727 | S28: =IF(Q27=0,0,S27/Q27) -> -0.40016232
A29: Véhicules neufs | B29: Véhicules neufs
A30: Véhicules neufsDEPENSES | B30: Véhicules neufs | C30: DEPENSES
A31: Véhicules neufsComm. vendeurs | B31: Véhicules neufs | C31: Comm. vendeurs | D31: =F31/(F15+F13+F17) -> 0.30450317 | E31: =F31/D$24 -> 770.95101 | F31: {=+INDEX('[5]Budget original'!$A$2:$AO$500,MATCH($A31,'[5]Budget original'!$A$2:$A$500,0),MATCH(F$2,'[5]Budget original'!$A$2:$AO$2,0))} -> 40579.763 | J31: =L31/(L15+L13+L17) -> 0.3593405 | K31: =IF(L31=0,0,L31/J$24) -> 840.92487 | L31: =SUMIFS([5]BV_Data_An_Cour!$O:$O,[5]BV_Data_An_Cour!$U:$U,$B31,[5]BV_Data_An_Cour!$V:$V,$C31,[5]BV_Data_An_Cour!$W:$W,L$2) -> 32796.07 | N31: =L31-F31 -> -7783.6926 | P31: =IF(Q31=0,0,Q31/O$24) -> 1067.6589 | Q31: =SUMIFS([5]BV_Data_An_Prec!$O:$O,[5]BV_Data_An_Prec!$U:$U,$B31,[5]BV_Data_An_Prec!$V:$V,$C31,[5]BV_Data_An_Prec!$W:$W,Q$2) -> 56585.92 | S31: =L31-Q31 -> -23789.85
A32: Véhicules neufsComm. F&I | B32: Véhicules neufs | C32: Comm. F&I | D32: =F32/F24 -> 0.3 | E32: =F32/D$24 -> 344.1 | F32: {=+INDEX('[5]Budget original'!$A$2:$AO$500,MATCH($A32,'[5]Budget original'!$A$2:$A$500,0),MATCH(F$2,'[5]Budget original'!$A$2:$AO$2,0))} -> 18112.041 | J32: =L32/L24 -> 0.30073846 | K32: =IF(L32=0,0,L32/J$24) -> 408.4959 | L32: =SUMIFS([5]BV_Data_An_Cour!$O:$O,[5]BV_Data_An_Cour!$U:$U,$B32,[5]BV_Data_An_Cour!$V:$V,$C32,[5]BV_Data_An_Cour!$W:$W,L$2) -> 15931.34 | N32: =L32-F32 -> -2180.701 | P32: =IF(Q32=0,0,Q32/O$24) -> 423.97528 | Q32: =SUMIFS([5]BV_Data_An_Prec!$O:$O,[5]BV_Data_An_Prec!$U:$U,$B32,[5]BV_Data_An_Prec!$V:$V,$C32,[5]BV_Data_An_Prec!$W:$W,Q$2) -> 22470.69 | S32: =L32-Q32 -> -6539.35 | U32: =(L32+L112)/(L104+L24+L19) -> 0.26707524 | V32: <<- F&A total Neuf Usagé Rachat | X32: =L24*U32 -> 14148.063 | Y32: =+L32-X32 -> 1783.2773
A33: Véhicules neufsFrais de livraison | B33: Véhicules neufs | C33: Frais de livraison | E33: =F33/D$24 -> 113.25898 | F33: {=+INDEX('[5]Budget original'!$A$2:$AO$500,MATCH($A33,'[5]Budget original'!$A$2:$A$500,0),MATCH(F$2,'[5]Budget original'!$A$2:$AO$2,0))} -> 5961.4973 | K33: =IF(L33=0,0,L33/J$24) -> 168.41974 | L33: =SUMIFS([5]BV_Data_An_Cour!$O:$O,[5]BV_Data_An_Cour!$U:$U,$B33,[5]BV_Data_An_Cour!$V:$V,$C33,[5]BV_Data_An_Cour!$W:$W,L$2) -> 6568.37 | N33: =L33-F33 -> 606.87268 | P33: =IF(Q33=0,0,Q33/O$24) -> 145.86774 | Q33: =SUMIFS([5]BV_Data_An_Prec!$O:$O,[5]BV_Data_An_Prec!$U:$U,$B33,[5]BV_Data_An_Prec!$V:$V,$C33,[5]BV_Data_An_Prec!$W:$W,Q$2) -> 7730.99 | S33: =L33-Q33 -> -1162.62
A34: Véhicules neufsService gratuit 1 | B34: Véhicules neufs | C34: Service gratuit 1 | E34: =F34/D$24 -> 5.1177856 | F34: {=+INDEX('[5]Budget original'!$A$2:$AO$500,MATCH($A34,'[5]Budget original'!$A$2:$A$500,0),MATCH(F$2,'[5]Budget original'!$A$2:$AO$2,0))} -> 269.37967 | K34: =IF(L34=0,0,L34/J$24) -> 1.025641 | L34: =SUMIFS([5]BV_Data_An_Cour!$O:$O,[5]BV_Data_An_Cour!$U:$U,$B34,[5]BV_Data_An_Cour!$V:$V,$C34,[5]BV_Data_An_Cour!$W:$W,L$2) -> 40 | N34: =L34-F34 -> -229.37967 | P34: =IF(Q34=0,0,Q34/O$24) -> 3.5922642 | Q34: =SUMIFS([5]BV_Data_An_Prec!$O:$O,[5]BV_Data_An_Prec!$U:$U,$B34,[5]BV_Data_An_Prec!$V:$V,$C34,[5]BV_Data_An_Prec!$W:$W,Q$2) -> 190.39 | S34: =L34-Q34 -> -150.39
A35: Véhicules neufsEntretien stock | B35: Véhicules neufs | C35: Entretien stock | E35: =F35/D$24 -> 105.01044 | F35: {=+INDEX('[5]Budget original'!$A$2:$AO$500,MATCH($A35,'[5]Budget original'!$A$2:$A$500,0),MATCH(F$2,'[5]Budget original'!$A$2:$AO$2,0))} -> 5527.3277 | K35: =IF(L35=0,0,L35/J$24) -> 118.07769 | L35: =SUMIFS([5]BV_Data_An_Cour!$O:$O,[5]BV_Data_An_Cour!$U:$U,$B35,[5]BV_Data_An_Cour!$V:$V,$C35,[5]BV_Data_An_Cour!$W:$W,L$2) -> 4605.03 | N35: =L35-F35 -> -922.29768 | P35: =IF(Q35=0,0,Q35/O$24) -> 176.23962 | Q35: =SUMIFS([5]BV_Data_An_Prec!$O:$O,[5]BV_Data_An_Prec!$U:$U,$B35,[5]BV_Data_An_Prec!$V:$V,$C35,[5]BV_Data_An_Prec!$W:$W,Q$2) -> 9340.7 | S35: =L35-Q35 -> -4735.67
A36: Véhicules neufsPublicité 1 | B36: Véhicules neufs | C36: Publicité 1 | E36: =F36/D$24 -> 300.75552 | F36: {=+INDEX('[5]Budget original'!$A$2:$AO$500,MATCH($A36,'[5]Budget original'!$A$2:$A$500,0),MATCH(F$2,'[5]Budget original'!$A$2:$AO$2,0))} -> 15830.562 | K36: =IF(L36=0,0,L36/J$24) -> 154.58692 | L36: =SUMIFS([5]BV_Data_An_Cour!$O:$O,[5]BV_Data_An_Cour!$U:$U,$B36,[5]BV_Data_An_Cour!$V:$V,$C36,[5]BV_Data_An_Cour!$W:$W,L$2) -> 6028.89 | N36: =L36-F36 -> -9801.6719 | P36: =IF(Q36=0,0,Q36/O$24) -> 185.94774 | Q36: =SUMIFS([5]BV_Data_An_Prec!$O:$O,[5]BV_Data_An_Prec!$U:$U,$B36,[5]BV_Data_An_Prec!$V:$V,$C36,[5]BV_Data_An_Prec!$W:$W,Q$2) -> 9855.23 | S36: =L36-Q36 -> -3826.34
A37: Véhicules neufsIntérêt de gros | B37: Véhicules neufs | C37: Intérêt de gros | E37: =F37/D$24 -> 50.687592 | F37: {=+INDEX('[5]Budget original'!$A$2:$AO$500,MATCH($A37,'[5]Budget original'!$A$2:$A$500,0),MATCH(F$2,'[5]Budget original'!$A$2:$AO$2,0))} -> 2667.9911 | K37: =IF(L37=0,0,L37/J$24) -> 90.482564 | L37: =SUMIFS([5]BV_Data_An_Cour!$O:$O,[5]BV_Data_An_Cour!$U:$U,$B37,[5]BV_Data_An_Cour!$V:$V,$C37,[5]BV_Data_An_Cour!$W:$W,L$2) -> 3528.82 | N37: =L37-F37 -> 860.82887 | P37: =IF(Q37=0,0,Q37/O$24) -> 21.345283 | Q37: =SUMIFS([5]BV_Data_An_Prec!$O:$O,[5]BV_Data_An_Prec!$U:$U,$B37,[5]BV_Data_An_Prec!$V:$V,$C37,[5]BV_Data_An_Prec!$W:$W,Q$2) -> 1131.3 | S37: =L37-Q37 -> 2397.52
A38: Véhicules neufs[...] | B38: Véhicules neufs | C38: [...] | E38: =F38/D$24 -> 0 | F38: {=+INDEX('[5]Budget original'!$A$2:$AO$500,MATCH($A38,'[5]Budget original'!$A$2:$A$500,0),MATCH(F$2,'[5]Budget original'!$A$2:$AO$2,0))} -> 0 | K38: =IF(L38=0,0,L38/J$24) -> 0 | L38: =SUMIFS([5]BV_Data_An_Cour!$O:$O,[5]BV_Data_An_Cour!$U:$U,$B38,[5]BV_Data_An_Cour!$V:$V,$C38,[5]BV_Data_An_Cour!$W:$W,L$2) -> 0 | N38: =L38-F38 -> 0 | P38: =IF(Q38=0,0,Q38/O$24) -> 0 | Q38: =SUMIFS([5]BV_Data_An_Prec!$O:$O,[5]BV_Data_An_Prec!$U:$U,$B38,[5]BV_Data_An_Prec!$V:$V,$C38,[5]BV_Data_An_Prec!$W:$W,Q$2) -> 0 | S38: =L38-Q38 -> 0
A39: Véhicules neufs[...] | B39: Véhicules neufs | C39: [...] | E39: =F39/D$24 -> 0 | F39: {=+INDEX('[5]Budget original'!$A$2:$AO$500,MATCH($A39,'[5]Budget original'!$A$2:$A$500,0),MATCH(F$2,'[5]Budget original'!$A$2:$AO$2,0))} -> 0 | K39: =IF(L39=0,0,L39/J$24) -> 0 | L39: =SUMIFS([5]BV_Data_An_Cour!$O:$O,[5]BV_Data_An_Cour!$U:$U,$B39,[5]BV_Data_An_Cour!$V:$V,$C39,[5]BV_Data_An_Cour!$W:$W,L$2) -> 0 | N39: =L39-F39 -> 0 | P39: =IF(Q39=0,0,Q39/O$24) -> 0 | Q39: =SUMIFS([5]BV_Data_An_Prec!$O:$O,[5]BV_Data_An_Prec!$U:$U,$B39,[5]BV_Data_An_Prec!$V:$V,$C39,[5]BV_Data_An_Prec!$W:$W,Q$2) -> 0 | S39: =L39-Q39 -> 0
A40: Véhicules neufs[...] | B40: Véhicules neufs | C40: [...] | E40: =F40/D$24 -> 0 | F40: {=+INDEX('[5]Budget original'!$A$2:$AO$500,MATCH($A40,'[5]Budget original'!$A$2:$A$500,0),MATCH(F$2,'[5]Budget original'!$A$2:$AO$2,0))} -> 0 | K40: =IF(L40=0,0,L40/J$24) -> 0 | L40: =SUMIFS([5]BV_Data_An_Cour!$O:$O,[5]BV_Data_An_Cour!$U:$U,$B40,[5]BV_Data_An_Cour!$V:$V,$C40,[5]BV_Data_An_Cour!$W:$W,L$2) -> 0 | N40: =L40-F40 -> 0 | P40: =IF(Q40=0,0,Q40/O$24) -> 0 | Q40: =SUMIFS([5]BV_Data_An_Prec!$O:$O,[5]BV_Data_An_Prec!$U:$U,$B40,[5]BV_Data_An_Prec!$V:$V,$C40,[5]BV_Data_An_Prec!$W:$W,Q$2) -> 0 | S40: =L40-Q40 -> 0
...

Sheet Juin 2023
C1: =[6]Parametres!B1 -> Volks | K1: Véhicules neufs | S1: =CONCATENATE("Réalisé,"," ",[6]Parametres!B3," ",[6]Parametres!B4) -> Réalisé, Juin 2023
D2: X | E2: O | F2: U | J2: NB | L2: $ | O2: NB | Q2: $ | V2: *** NE PAS EFFACER / Pour An Précédente ***
D3: BUDGET ORIGINAL | J3: RÉALISATION | M3: ÉCART réel / Budget | O3: ANNÉE PRÉCÉDENTE | R3: ECART (réel/ Ann.Préc.) | V3: NEUF | W3: 0.45
D4: UNITÉS | E4: $P/UNITÉ | F4: $PROFITS | J4: UNITÉS | K4: $P/UNITE | L4: $PROFITS | M4: UNITÉS | N4: $PROFITS | O4: UNITÉS | P4: $P/UNITE | Q4: $PROFITS | R4: UNITÉS | S4: $PROFITS | V4: USAGE | W4: 0.1
A5: Véhicules neufsVentes nettes | B5: Véhicules neufs | C5: Ventes nettes | F5: {=+INDEX('[6]Budget original'!$A$2:$AO$500,MATCH($A5,'[6]Budget original'!$A$2:$A$500,0),MATCH(F$2,'[6]Budget original'!$A$2:$AO$2,0))} -> 2275303.5 | L5: =-SUMIFS([6]BV_Data_An_Cour!$O:$O,[6]BV_Data_An_Cour!$X:$X,"Oui",[6]BV_Data_An_Cour!$U:$U,$B5) -> 2851329.3 | Q5: =-SUMIFS([6]BV_Data_An_Prec!$O:$O,[6]BV_Data_An_Prec!$X:$X,"Oui",[6]BV_Data_An_Prec!$U:$U,$B5) -> 2836768.3 | V5: SERVICE | W5: 0.225
A6: Véhicules neufsAutos détail | B6: Véhicules neufs | C6: Autos détail | D6: {=+INDEX('[6]Budget original'!$A$2:$AO$500,MATCH($A6,'[6]Budget original'!$A$2:$A$500,0),MATCH(D$2,'[6]Budget original'!$A$2:$AO$2,0))} -> 9.6891429 | E6: =IF(D6=0,0,F6/D6) -> 1988.434 | F6: {=+INDEX('[6]Budget original'!$A$2:$AO$500,MATCH($A6,'[6]Budget original'!$A$2:$A$500,0),MATCH(F$2,'[6]Budget original'!$A$2:$AO$2,0))} -> 19266.221 | J6: =-SUMIFS([6]BV_Data_An_Cour!$O:$O,[6]BV_Data_An_Cour!$U:$U,$B6,[6]BV_Data_An_Cour!$V:$V,$C6,[6]BV_Data_An_Cour!$W:$W,J$2) -> 16 | K6: =IF(J6=0,0,L6/J6) -> 2103.4488 | L6: =-SUMIFS([6]BV_Data_An_Cour!$O:$O,[6]BV_Data_An_Cour!$U:$U,$B6,[6]BV_Data_An_Cour!$V:$V,$C6,[6]BV_Data_An_Cour!$W:$W,L$2) -> 33655.18 | M6: =J6-D6 -> 6.3108571 | N6: =L6-F6 -> 14388.959 | O6: =-SUMIFS([6]BV_Data_An_Prec!$O:$O,[6]BV_Data_An_Prec!$U:$U,$B6,[6]BV_Data_An_Prec!$V:$V,$C6,[6]BV_Data_An_Prec!$W:$W,O$2) -> 9 | P6: =IF(O6=0,0,Q6/O6) -> 2603.6256 | Q6: =-SUMIFS([6]BV_Data_An_Prec!$O:$O,[6]BV_Data_An_Prec!$U:$U,$B6,[6]BV_Data_An_Prec!$V:$V,$C6,[6]BV_Data_An_Prec!$W:$W,Q$2) -> 23432.63 | R6: =J6-O6 -> 7 | S6: =L6-Q6 -> 10222.55 | V6: CARROSSERIE | W6: 0.025
A7: Véhicules neufsCamions détail | B7: Véhicules neufs | C7: Camions détail | D7: {=+INDEX('[6]Budget original'!$A$2:$AO$500,MATCH($A7,'[6]Budget original'!$A$2:$A$500,0),MATCH(D$2,'[6]Budget original'!$A$2:$AO$2,0))} -> 38.752696 | E7: =IF(D7=0,0,F7/D7) -> 2556.3336 | F7: {=+INDEX('[6]Budget original'!$A$2:$AO$500,MATCH($A7,'[6]Budget original'!$A$2:$A$500,0),MATCH(F$2,'[6]Budget original'!$A$2:$AO$2,0))} -> 99064.82 | J7: =-SUMIFS([6]BV_Data_An_Cour!$O:$O,[6]BV_Data_An_Cour!$U:$U,$B7,[6]BV_Data_An_Cour!$V:$V,$C7,[6]BV_Data_An_Cour!$W:$W,J$2) -> 39 | K7: =IF(J7=0,0,L7/J7) -> 2445.2556 | L7: =-SUMIFS([6]BV_Data_An_Cour!$O:$O,[6]BV_Data_An_Cour!$U:$U,$B7,[6]BV_Data_An_Cour!$V:$V,$C7,[6]BV_Data_An_Cour!$W:$W,L$2) -> 95364.97 | M7: =J7-D7 -> 0.24730423 | N7: =L7-F7 -> -3699.8496 | O7: =-SUMIFS([6]BV_Data_An_Prec!$O:$O,[6]BV_Data_An_Prec!$U:$U,$B7,[6]BV_Data_An_Prec!$V:$V,$C7,[6]BV_Data_An_Prec!$W:$W,O$2) -> 43 | P7: =IF(O7=0,0,Q7/O7) -> 3826.4693 | Q7: =-SUMIFS([6]BV_Data_An_Prec!$O:$O,[6]BV_Data_An_Prec!$U:$U,$B7,[6]BV_Data_An_Prec!$V:$V,$C7,[6]BV_Data_An_Prec!$W:$W,Q$2) -> 164538.18 | R7: =J7-O7 -> -4 | S7: =L7-Q7 -> -69173.21 | V7: PIECES | W7: 0.2
A8: Véhicules neufsSprinter | B8: Véhicules neufs | C8: Sprinter | D8: {=+INDEX('[6]Budget original'!$A$2:$AO$500,MATCH($A8,'[6]Budget original'!$A$2:$A$500,0),MATCH(D$2,'[6]Budget original'!$A$2:$AO$2,0))} -> 0 | E8: =IF(D8=0,0,F8/D8) -> 0 | F8: {=+INDEX('[6]Budget original'!$A$2:$AO$500,MATCH($A8,'[6]Budget original'!$A$2:$A$500,0),MATCH(F$2,'[6]Budget original'!$A$2:$AO$2,0))} -> 0 | J8: =-SUMIFS([6]BV_Data_An_Cour!$O:$O,[6]BV_Data_An_Cour!$U:$U,$B8,[6]BV_Data_An_Cour!$V:$V,$C8,[6]BV_Data_An_Cour!$W:$W,J$2) -> 0 | K8: =IF(J8=0,0,L8/J8) -> 0 | L8: =-SUMIFS([6]BV_Data_An_Cour!$O:$O,[6]BV_Data_An_Cour!$U:$U,$B8,[6]BV_Data_An_Cour!$V:$V,$C8,[6]BV_Data_An_Cour!$W:$W,L$2) -> 0 | M8: =J8-D8 -> 0 | N8: =L8-F8 -> 0 | O8: =-SUMIFS([6]BV_Data_An_Prec!$O:$O,[6]BV_Data_An_Prec!$U:$U,$B8,[6]BV_Data_An_Prec!$V:$V,$C8,[6]BV_Data_An_Prec!$W:$W,O$2) -> 0 | P8: =IF(O8=0,0,Q8/O8) -> 0 | Q8: =-SUMIFS([6]BV_Data_An_Prec!$O:$O,[6]BV_Data_An_Prec!$U:$U,$B8,[6]BV_Data_An_Prec!$V:$V,$C8,[6]BV_Data_An_Prec!$W:$W,Q$2) -> 0 | R8: =J8-O8 -> 0 | S8: =L8-Q8 -> 0 | W8: =SUM(W3:W7) -> 1
A9: Véhicules neufsMoto détail | B9: Véhicules neufs | C9: Moto détail | D9: {=+INDEX('[6]Budget original'!$A$2:$AO$500,MATCH($A9,'[6]Budget original'!$A$2:$A$500,0),MATCH(D$2,'[6]Budget original'!$A$2:$AO$2,0))} -> 0 | E9: =IF(D9=0,0,F9/D9) -> 0 | F9: {=+INDEX('[6]Budget original'!$A$2:$AO$500,MATCH($A9,'[6]Budget original'!$A$2:$A$500,0),MATCH(F$2,'[6]Budget original'!$A$2:$AO$2,0))} -> 0 | J9: =-SUMIFS([6]BV_Data_An_Cour!$O:$O,[6]BV_Data_An_Cour!$U:$U,$B9,[6]BV_Data_An_Cour!$V:$V,$C9,[6]BV_Data_An_Cour!$W:$W,J$2) -> 0 | K9: =IF(J9=0,0,L9/J9) -> 0 | L9: =-SUMIFS([6]BV_Data_An_Cour!$O:$O,[6]BV_Data_An_Cour!$U:$U,$B9,[6]BV_Data_An_Cour!$V:$V,$C9,[6]BV_Data_An_Cour!$W:$W,L$2) -> 0 | M9: =J9-D9 -> 0 | N9: =L9-F9 -> 0 | O9: =-SUMIFS([6]BV_Data_An_Prec!$O:$O,[6]BV_Data_An_Prec!$U:$U,$B9,[6]BV_Data_An_Prec!$V:$V,$C9,[6]BV_Data_An_Prec!$W:$W,O$2) -> 0 | P9: =IF(O9=0,0,Q9/O9) -> 0 | Q9: =-SUMIFS([6]BV_Data_An_Prec!$O:$O,[6]BV_Data_An_Prec!$U:$U,$B9,[6]BV_Data_An_Prec!$V:$V,$C9,[6]BV_Data_An_Prec!$W:$W,Q$2) -> 0 | R9: =J9-O9 -> 0 | S9: =L9-Q9 -> 0
A10: Véhicules neufs[...] | B10: Véhicules neufs | C10: [...] | D10: 0 | E10: =IF(D10=0,0,F10/D10) -> 0 | F10: {=+INDEX('[6]Budget original'!$A$2:$AO$500,MATCH($A10,'[6]Budget original'!$A$2:$A$500,0),MATCH(F$2,'[6]Budget original'!$A$2:$AO$2,0))} -> 0 | J10: =-SUMIFS([6]BV_Data_An_Cour!$O:$O,[6]BV_Data_An_Cour!$U:$U,$B10,[6]BV_Data_An_Cour!$V:$V,$C10,[6]BV_Data_An_Cour!$W:$W,J$2) -> 0 | K10: =IF(J10=0,0,L10/J10) -> 0 | L10: =-SUMIFS([6]BV_Data_An_Cour!$O:$O,[6]BV_Data_An_Cour!$U:$U,$B10,[6]BV_Data_An_Cour!$V:$V,$C10,[6]BV_Data_An_Cour!$W:$W,L$2) -> 0 | M10: =J10-D10 -> 0 | N10: =L10-F10 -> 0 | O10: =-SUMIFS([6]BV_Data_An_Prec!$O:$O,[6]BV_Data_An_Prec!$U:$U,$B10,[6]BV_Data_An_Prec!$V:$V,$C10,[6]BV_Data_An_Prec!$W:$W,O$2) -> 0 | P10: =IF(O10=0,0,Q10/O10) -> 0 | Q10: =-SUMIFS([6]BV_Data_An_Prec!$O:$O,[6]BV_Data_An_Prec!$U:$U,$B10,[6]BV_Data_An_Prec!$V:$V,$C10,[6]BV_Data_An_Prec!$W:$W,Q$2) -> 0 | R10: =J10-O10 -> 0 | S10: =L10-Q10 -> 0
A11: Véhicules neufs[...] | B11: Véhicules neufs | C11: [...] | D11: 0 | E11: =IF(D11=0,0,F11/D11) -> 0 | F11: {=+INDEX('[6]Budget original'!$A$2:$AO$500,MATCH($A11,'[6]Budget original'!$A$2:$A$500,0),MATCH(F$2,'[6]Budget original'!$A$2:$AO$2,0))} -> 0 | J11: =-SUMIFS([6]BV_Data_An_Cour!$O:$O,[6]BV_Data_An_Cour!$U:$U,$B11,[6]BV_Data_An_Cour!$V:$V,$C11,[6]BV_Data_An_Cour!$W:$W,J$2) -> 0 | K11: =IF(J11=0,0,L11/J11) -> 0 | L11: =-SUMIFS([6]BV_Data_An_Cour!$O:$O,[6]BV_Data_An_Cour!$U:$U,$B11,[6]BV_Data_An_Cour!$V:$V,$C11,[6]BV_Data_An_Cour!$W:$W,L$2) -> 0 | M11: =J11-D11 -> 0 | N11: =L11-F11 -> 0 | O11: =-SUMIFS([6]BV_Data_An_Prec!$O:$O,[6]BV_Data_An_Prec!$U:$U,$B11,[6]BV_Data_An_Prec!$V:$V,$C11,[6]BV_Data_An_Prec!$W:$W,O$2) -> 0 | P11: =IF(O11=0,0,Q11/O11) -> 0 | Q11: =-SUMIFS([6]BV_Data_An_Prec!$O:$O,[6]BV_Data_An_Prec!$U:$U,$B11,[6]BV_Data_An_Prec!$V:$V,$C11,[6]BV_Data_An_Prec!$W:$W,Q$2) -> 0 | R11: =J11-O11 -> 0 | S11: =L11-Q11 -> 0
A12: Véhicules neufs[...] | B12: Véhicules neufs | C12: [...] | D12: 0 | E12: =IF(D12=0,0,F12/D12) -> 0 | F12: {=+INDEX('[6]Budget original'!$A$2:$AO$500,MATCH($A12,'[6]Budget original'!$A$2:$A$500,0),MATCH(F$2,'[6]Budget original'!$A$2:$AO$2,0))} -> 0 | J12: =-SUMIFS([6]BV_Data_An_Cour!$O:$O,[6]BV_Data_An_Cour!$U:$U,$B12,[6]BV_Data_An_Cour!$V:$V,$C12,[6]BV_Data_An_Cour!$W:$W,J$2) -> 0 | K12: =IF(J12=0,0,L12/J12) -> 0 | L12: =-SUMIFS([6]BV_Data_An_Cour!$O:$O,[6]BV_Data_An_Cour!$U:$U,$B12,[6]BV_Data_An_Cour!$V:$V,$C12,[6]BV_Data_An_Cour!$W:$W,L$2) -> 0 | M12: =J12-D12 -> 0 | N12: =L12-F12 -> 0 | O12: =-SUMIFS([6]BV_Data_An_Prec!$O:$O,[6]BV_Data_An_Prec!$U:$U,$B12,[6]BV_Data_An_Prec!$V:$V,$C12,[6]BV_Data_An_Prec!$W:$W,O$2) -> 0 | P12: =IF(O12=0,0,Q12/O12) -> 0 | Q12: =-SUMIFS([6]BV_Data_An_Prec!$O:$O,[6]BV_Data_An_Prec!$U:$U,$B12,[6]BV_Data_An_Prec!$V:$V,$C12,[6]BV_Data_An_Prec!$W:$W,Q$2) -> 0 | R12: =J12-O12 -> 0 | S12: =L12-Q12 -> 0
A13: Véhicules neufsTotal Neufs | B13: Véhicules neufs | C13: Total Neufs | D13: =+SUM(D6:D12) -> 48.441839 | E13: =IF(D13<=0,0,F13/D13) -> 2442.7446 | F13: =+SUM(F6:F12) -> 118331.04 | J13: =+SUM(J6:J12) -> 55 | K13: =IF(J13<=0,0,L13/J13) -> 2345.8209 | L13: =+SUM(L6:L12) -> 129020.15 | M13: =+SUM(M6:M12) -> 6.5581614 | N13: =+SUM(N6:N12) -> 10689.109 | O13: =+SUM(O6:O12) -> 52 | P13: =IF(O13<=0,0,Q13/O13) -> 3614.8233 | Q13: =+SUM(Q6:Q12) -> 187970.81 | R13: =+SUM(R6:R12) -> 3 | S13: =+SUM(S6:S12) -> -58950.66
A14: Véhicules neufs | B14: Véhicules neufs | M14: =IF(D13=0,0,M13/D13) -> 0.13538217 | N14: =IF(F13=0,0,N13/F13) -> 0.090332252 | R14: =R13/O13 -> 0.057692308 | S14: =IF(Q13=0,0,(S13/Q13)) -> -0.31361603 | AD14: 20 | AE14: 1000 | AF14: =AD14*AE14 -> 20000
A15: Véhicules neufsEx-Démos et courtoisies | B15: Véhicules neufs | C15: Ex-Démos et courtoisies | D15: {=+INDEX('[6]Budget original'!$A$2:$AO$500,MATCH($A15,'[6]Budget original'!$A$2:$A$500,0),MATCH(D$2,'[6]Budget original'!$A$2:$AO$2,0))} -> 2.3142857 | E15: =IF(D15=0,0,F15/D15) -> 2442.5492 | F15: {=+INDEX('[6]Budget original'!$A$2:$AO$500,MATCH($A15,'[6]Budget original'!$A$2:$A$500,0),MATCH(F$2,'[6]Budget original'!$A$2:$AO$2,0))} -> 5652.7567 | J15: =-SUMIFS([6]BV_Data_An_Cour!$O:$O,[6]BV_Data_An_Cour!$U:$U,$B15,[6]BV_Data_An_Cour!$V:$V,$C15,[6]BV_Data_An_Cour!$W:$W,J$2) -> 2 | K15: =IF(J15=0,0,L15/J15) -> 1486.73 | L15: =-SUMIFS([6]BV_Data_An_Cour!$O:$O,[6]BV_Data_An_Cour!$U:$U,$B15,[6]BV_Data_An_Cour!$V:$V,$C15,[6]BV_Data_An_Cour!$W:$W,L$2) -> 2973.46 | M15: =J15-D15 -> -0.31428571 | N15: =L15-F15 -> -2679.2967 | O15: =-SUMIFS([6]BV_Data_An_Prec!$O:$O,[6]BV_Data_An_Prec!$U:$U,$B15,[6]BV_Data_An_Prec!$V:$V,$C15,[6]BV_Data_An_Prec!$W:$W,O$2) -> 4 | P15: =IF(O15=0,0,Q15/O15) -> 2132.36 | Q15: =-SUMIFS([6]BV_Data_An_Prec!$O:$O,[6]BV_Data_An_Prec!$U:$U,$B15,[6]BV_Data_An_Prec!$V:$V,$C15,[6]BV_Data_An_Prec!$W:$W,Q$2) -> 8529.44 | R15: =J15-O15 -> -2 | S15: =L15-Q15 -> -5555.98 | AD15: 25 | AE15: =AF15/AD15 -> 800 | AF15: =AF14 -> 20000
A16: Véhicules neufs | B16: Véhicules neufs
A17: Véhicules neufsFlottes | B17: Véhicules neufs | C17: Flottes | D17: {=+INDEX('[6]Budget original'!$A$2:$AO$500,MATCH($A17,'[6]Budget original'!$A$2:$A$500,0),MATCH(D$2,'[6]Budget original'!$A$2:$AO$2,0))} -> 1.8514286 | E17: =IF(D17=0,0,F17/D17) -> 2442.5492 | F17: {=+INDEX('[6]Budget original'!$A$2:$AO$500,MATCH($A17,'[6]Budget original'!$A$2:$A$500,0),MATCH(F$2,'[6]Budget original'!$A$2:$AO$2,0))} -> 4522.2054 | J17: =-SUMIFS([6]BV_Data_An_Cour!$O:$O,[6]BV_Data_An_Cour!$U:$U,$B17,[6]BV_Data_An_Cour!$V:$V,$C17,[6]BV_Data_An_Cour!$W:$W,J$2) -> 2 | K17: =IF(J17=0,0,L17/J17) -> 2962.945 | L17: =-SUMIFS([6]BV_Data_An_Cour!$O:$O,[6]BV_Data_An_Cour!$U:$U,$B17,[6]BV_Data_An_Cour!$V:$V,$C17,[6]BV_Data_An_Cour!$W:$W,L$2) -> 5925.89 | M17: =J17-D17 -> 0.14857143 | N17: =L17-F17 -> 1403.6846 | O17: =-SUMIFS([6]BV_Data_An_Prec!$O:$O,[6]BV_Data_An_Prec!$U:$U,$B17,[6]BV_Data_An_Prec!$V:$V,$C17,[6]BV_Data_An_Prec!$W:$W,O$2) -> 0 | P17: =IF(O17=0,0,Q17/O17) -> 0 | Q17: =-SUMIFS([6]BV_Data_An_Prec!$O:$O,[6]BV_Data_An_Prec!$U:$U,$B17,[6]BV_Data_An_Prec!$V:$V,$C17,[6]BV_Data_An_Prec!$W:$W,Q$2) -> 0 | R17: =J17-O17 -> 2 | S17: =L17-Q17 -> 5925.89 | V17: =+L13+L15+L17-4000 -> 133919.5
A18: Véhicules neufs | B18: Véhicules neufs | V18: =+L31/V17 -> 0.32831567
A19: Véhicules neufsRachat bail | B19: Véhicules neufs | C19: Rachat bail | D19: {=+INDEX('[6]Budget original'!$A$2:$AO$500,MATCH($A19,'[6]Budget original'!$A$2:$A$500,0),MATCH(D$2,'[6]Budget original'!$A$2:$AO$2,0))} -> 0 | E19: =IF(D19=0,0,F19/D19) -> 0 | F19: {=+INDEX('[6]Budget original'!$A$2:$AO$500,MATCH($A19,'[6]Budget original'!$A$2:$A$500,0),MATCH(F$2,'[6]Budget original'!$A$2:$AO$2,0))} -> 11520 | L19: =-SUMIFS([6]BV_Data_An_Cour!$O:$O,[6]BV_Data_An_Cour!$U:$U,$B19,[6]BV_Data_An_Cour!$V:$V,$C19,[6]BV_Data_An_Cour!$W:$W,L$2) -> 12900.75 | N19: =L19-F19 -> 1380.75 | Q19: =-SUMIFS([6]BV_Data_An_Prec!$O:$O,[6]BV_Data_An_Prec!$U:$U,$B19,[6]BV_Data_An_Prec!$V:$V,$C19,[6]BV_Data_An_Prec!$W:$W,Q$2) -> 13151.1 | R19: =O19-K19 -> 0 | S19: =L19-Q19 -> -250.35
A20: Véhicules neufs | B20: Véhicules neufs
A21: Véhicules neufsRev. Finances | B21: Véhicules neufs | C21: Rev. Finances | D21: {=+INDEX('[6]Budget original'!$A$2:$AO$500,MATCH($A21,'[6]Budget original'!$A$2:$A$500,0),MATCH(D$2,'[6]Budget original'!$A$2:$AO$2,0))} -> 0 | E21: =IF(D21=0,0,F21/D21) -> 0 | F21: {=+INDEX('[6]Budget original'!$A$2:$AO$500,MATCH($A21,'[6]Budget original'!$A$2:$A$500,0),MATCH(F$2,'[6]Budget original'!$A$2:$AO$2,0))} -> 8730.0534 | K21: =IF(J13=0,0,L21/(J13+J15)) -> 89.401579 | L21: =-SUMIFS([6]BV_Data_An_Cour!$O:$O,[6]BV_Data_An_Cour!$U:$U,$B21,[6]BV_Data_An_Cour!$V:$V,$C21,[6]BV_Data_An_Cour!$W:$W,L$2) -> 5095.89 | N21: =L21-F21 -> -3634.1634 | P21: =IF(O13=0,0,Q21/(O13+O15)) -> 228.50482 | Q21: =-SUMIFS([6]BV_Data_An_Prec!$O:$O,[6]BV_Data_An_Prec!$U:$U,$B21,[6]BV_Data_An_Prec!$V:$V,$C21,[6]BV_Data_An_Prec!$W:$W,Q$2) -> 12796.27 | R21: =O21-K21 -> -89.401579 | S21: =L21-Q21 -> -7700.38
A22: Véhicules neufsRev. Protections | B22: Véhicules neufs | C22: Rev. Protections | D22: {=+INDEX('[6]Budget original'!$A$2:$AO$500,MATCH($A22,'[6]Budget original'!$A$2:$A$500,0),MATCH(D$2,'[6]Budget original'!$A$2:$AO$2,0))} -> 0 | E22: =IF(D22=0,0,F22/D22) -> 0 | F22: {=+INDEX('[6]Budget original'!$A$2:$AO$500,MATCH($A22,'[6]Budget original'!$A$2:$A$500,0),MATCH(F$2,'[6]Budget original'!$A$2:$AO$2,0))} -> 48015.294 | K22: =IF(J13=0,0,L22/(J13+J15)) -> 868.40772 | L22: =-SUMIFS([6]BV_Data_An_Cour!$O:$O,[6]BV_Data_An_Cour!$U:$U,$B22,[6]BV_Data_An_Cour!$V:$V,$C22,[6]BV_Data_An_Cour!$W:$W,L$2) -> 49499.24 | N22: =L22-F22 -> 1483.9464 | P22: =IF(O13=0,0,Q22/(O13+O15)) -> 947.25268 | Q22: =-SUMIFS([6]BV_Data_An_Prec!$O:$O,[6]BV_Data_An_Prec!$U:$U,$B22,[6]BV_Data_An_Prec!$V:$V,$C22,[6]BV_Data_An_Prec!$W:$W,Q$2) -> 53046.15 | R22: =O22-K22 -> -868.40772 | S22: =L22-Q22 -> -3546.91
A23: Véhicules neufsRev. Autres | B23: Véhicules neufs | C23: Rev. Autres | D23: {=+INDEX('[6]Budget original'!$A$2:$AO$500,MATCH($A23,'[6]Budget original'!$A$2:$A$500,0),MATCH(D$2,'[6]Budget original'!$A$2:$AO$2,0))} -> 0 | E23: =IF(D23=0,0,F23/D23) -> 0 | F23: {=+INDEX('[6]Budget original'!$A$2:$AO$500,MATCH($A23,'[6]Budget original'!$A$2:$A$500,0),MATCH(F$2,'[6]Budget original'!$A$2:$AO$2,0))} -> 1471.9276 | K23: =IF(J13=0,0,L23/(J13+J15)) -> 0 | L23: =-SUMIFS([6]BV_Data_An_Cour!$O:$O,[6]BV_Data_An_Cour!$U:$U,$B23,[6]BV_Data_An_Cour!$V:$V,$C23,[6]BV_Data_An_Cour!$W:$W,L$2) -> 0 | N23: =L23-F23 -> -1471.9276 | P23: =IF(O13=0,0,Q23/(O13+O15)) -> 13.778571 | Q23: =-SUMIFS([6]BV_Data_An_Prec!$O:$O,[6]BV_Data_An_Prec!$U:$U,$B23,[6]BV_Data_An_Prec!$V:$V,$C23,[6]BV_Data_An_Prec!$W:$W,Q$2) -> 771.6 | R23: =O23-K23 -> 0 | S23: =L23-Q23 -> -771.6
A24: Véhicules neufsTotal F&I | B24: Véhicules neufs | C24: Total F&I | D24: =+D15+D13 -> 50.756124 | E24: =IF(D24<=0,0,F24/D24) -> 1147 | F24: =F21+F22+F23 -> 58217.275 | J24: =+J15+J13 -> 57 | K24: =IF(J24<=0,0,L24/J24) -> 957.8093 | L24: =L21+L22+L23 -> 54595.13 | M24: =J24-D24 -> 6.2438757 | N24: =L24-F24 -> -3622.1446 | O24: =+O15+O13 -> 56 | P24: =IF(O24<=0,0,Q24/O24) -> 1189.5361 | Q24: =Q21+Q22+Q23 -> 66614.02 | S24: =L24-Q24 -> -12018.89
A25: Véhicules neufs | B25: Véhicules neufs | N25: =IF(N24=0,0,N24/F24) -> -0.062217695 | S25: =IF(Q24=0,0,(S24/Q24)) -> -0.18042583
A26: Véhicules neufs | B26: Véhicules neufs
A27: Véhicules neufsTotal Dépt. Neufs | B27: Véhicules neufs | C27: Total Dépt. Neufs | D27: =+D13+D15+D17 -> 52.607553 | E27: =IF(D27<=0,0,F27/D27) -> 3768.3425 | F27: =F13+F17+F24+F19+F15 -> 198243.28 | J27: =+J13+J15+J17 -> 59 | K27: =IF(J27<=0,0,L27/J27) -> 3481.6166 | L27: =L13+L17+L24+L19+L15 -> 205415.38 | M27: =J27-D27 -> 6.3924471 | N27: =L27-F27 -> 7172.1026 | O27: =+O13+O15+O17 -> 56 | P27: =IF(O27<=0,0,Q27/O27) -> 4933.3102 | Q27: =Q13+Q17+Q24+Q19+Q15 -> 276265.37 | R27: =J27-O27 -> 3 | S27: =L27-Q27 -> -70849.99
A28: Véhicules neufs | B28: Véhicules neufs | L28: =L27/F27 -> 1.0361783 | M28: =M27/D27 -> 0.12151196 | N28: =N27/F27 -> 0.036178289 | R28: =R27/O27 -> 0.053571429 | S28: =IF(Q27=0,0,S27/Q27) -> -0.25645628
A29: Véhicules neufs | B29: Véhicules neufs
A30: Véhicules neufsDEPENSES | B30: Véhicules neufs | C30: DEPENSES
A31: Véhicules neufsComm. vendeurs | B31: Véhicules neufs | C31: Comm. vendeurs | D31: =F31/(F15+F13+F17) -> 0.30874422 | E31: =F31/D$24 -> 781.68863 | F31: {=+INDEX('[6]Budget original'!$A$2:$AO$500,MATCH($A31,'[6]Budget original'!$A$2:$A$500,0),MATCH(F$2,'[6]Budget original'!$A$2:$AO$2,0))} -> 39675.485 | J31: =L31/(L15+L13+L17) -> 0.31879372 | K31: =IF(L31=0,0,L31/J$24) -> 771.36614 | L31: =SUMIFS([6]BV_Data_An_Cour!$O:$O,[6]BV_Data_An_Cour!$U:$U,$B31,[6]BV_Data_An_Cour!$V:$V,$C31,[6]BV_Data_An_Cour!$W:$W,L$2) -> 43967.87 | N31: =L31-F31 -> 4292.3846 | P31: =IF(Q31=0,0,Q31/O$24) -> 956.86768 | Q31: =SUMIFS([6]BV_Data_An_Prec!$O:$O,[6]BV_Data_An_Prec!$U:$U,$B31,[6]BV_Data_An_Prec!$V:$V,$C31,[6]BV_Data_An_Prec!$W:$W,Q$2) -> 53584.59 | S31: =L31-Q31 -> -9616.72
