Workbook
Name _Dates_Conc: [1]Dealers!$BF$37:$KA$63
Name _scen: '[1]Scen & Sens'!$E$26
Name _scen1: '[1]Scen & Sens'!$E$27
Name _scen2: '[1]Scen & Sens'!$E$28
Name _SCenarios: '[1]Scen & Sens'!$J$26:$O$26
Name _Sens1: '[1]Scen & Sens'!$F$9
Name _Sens2: '[1]Scen & Sens'!$F$10
Name _sensRes1: '[1]Scen & Sens'!$E$15
Name _sensRes2: '[1]Scen & Sens'!$E$16
Name _sensRes3: '[1]Scen & Sens'!$E$17
Name _sensRes4: '[1]Scen & Sens'!$E$18
Name _sensRes5: '[1]Scen & Sens'!$E$19
Name _sensRes6: '[1]Scen & Sens'!$E$20
Name _sensRes7: '[1]Scen & Sens'!$E$21
Name DateRange: [1]Volkswagen!$BF$6:$DY$6
Name Monetary_Unit: [1]Parameters!$B$15
Name Months: [1]Parameters!$E$9:$E$20
Name Rng_Dealers_Names: [1]!Tbl_Dealers[Dealer Name]
Name Rng_Dlr_Dates: [1]!Tbl_V_Dlr_Dates[Date]
Name Titre: [1]Front!$A$9

Sheet Parametres
A1: Compagnie | B1: Volks
G2: 1-Mémo | M2: Mois | N2: YTD
A3: Mois Courant | B3: Janvier | C3: =+VLOOKUP(B3,$K$3:$L$14,2,0) -> 1 | G3: 10-Compte compteur | K3: Janvier | L3: 1 | M3: =+IF($K3=$B$3,"X","") -> X | N3: =+IF(K3=B3,"X",IF(L3<=$C$3,"X","")) -> X
A4: Année | B4: 2021 | K4: Février | L4: 2 | M4: =+IF($K4=$B$3,"X","") | N4: =+IF(K4=B4,"X",IF(L4<=$C$3,"X",""))
K5: Mars | L5: 3 | M5: =+IF($K5=$B$3,"X","") | N5: =+IF(K5=B5,"X",IF(L5<=$C$3,"X",""))
K6: Avril | L6: 4 | M6: =+IF($K6=$B$3,"X","") | N6: =+IF(K6=B6,"X",IF(L6<=$C$3,"X",""))
K7: Mai | L7: 5 | M7: =+IF($K7=$B$3,"X","") | N7: =+IF(K7=B7,"X",IF(L7<=$C$3,"X",""))
K8: Juin | L8: 6 | M8: =+IF($K8=$B$3,"X","") | N8: =+IF(K8=B8,"X",IF(L8<=$C$3,"X",""))
A9: Sélectionner le mois en B3 | K9: Juillet | L9: 7 | M9: =+IF($K9=$B$3,"X","") | N9: =+IF(K9=B9,"X",IF(L9<=$C$3,"X",""))
A10: Coller les balances de vérification respectives en cellule A1 dans les onglets BV_Data_An_Cour et BV_Data_An_Prec | K10: Août | L10: 8 | M10: =+IF($K10=$B$3,"X","") | N10: =+IF(K10=B10,"X",IF(L10<=$C$3,"X",""))
A11: Vérifier s'il y a des #N/A dans les colonnes T à X des onlgets de BV | K11: Septembre | L11: 9 | M11: =+IF($K11=$B$3,"X","") | N11: =+IF(K11=B11,"X",IF(L11<=$C$3,"X",""))
A12: Vérifier les chiffres avec l'état financier et les réalisés an passé pour les résultat net mois et aad | K12: Octobre | L12: 10 | M12: =+IF($K12=$B$3,"X","") | N12: =+IF(K12=B12,"X",IF(L12<=$C$3,"X",""))
K13: Novembre | L13: 11 | M13: =+IF($K13=$B$3,"X","") | N13: =+IF(K13=B13,"X",IF(L13<=$C$3,"X",""))
K14: Décembre | L14: 12 | M14: =+IF($K14=$B$3,"X","") | N14: =+IF(K14=B14,"X",IF(L14<=$C$3,"X",""))

Sheet Bilan
A1: BILAN
A2: =+Parametres!B1 -> Volks
A3: =CONCATENATE("",,Parametres!B3," ",Parametres!B4) -> Janvier 2021
A5: Encaisse | B5: =SUMIFS(BV_Data_An_Cour!$P:$P,BV_Data_An_Cour!$U:$U,$A$1,BV_Data_An_Cour!$V:$V,$A5) -> 2590519 | D5: Marge de crédit | E5: =-SUMIFS(BV_Data_An_Cour!$P:$P,BV_Data_An_Cour!$U:$U,$A$1,BV_Data_An_Cour!$V:$V,$D5) -> 0
A6: Total Trésorerie et équivalent de Trésorerie | B6: =SUM(B5) -> 2590519
D7: Portion Court Terme de la Dette Long Terme | E7: =-SUMIFS(BV_Data_An_Cour!$P:$P,BV_Data_An_Cour!$U:$U,$A$1,BV_Data_An_Cour!$V:$V,$D7) -> 15810
A8: Recevables Contrats en Transit | B8: =SUMIFS(BV_Data_An_Cour!$P:$P,BV_Data_An_Cour!$U:$U,$A$1,BV_Data_An_Cour!$V:$V,$A8) -> 495338.93
A9: Recevables Véhicules | B9: =SUMIFS(BV_Data_An_Cour!$P:$P,BV_Data_An_Cour!$U:$U,$A$1,BV_Data_An_Cour!$V:$V,$A9) -> 200708.19 | D9: Avances à payer | E9: =-SUMIFS(BV_Data_An_Cour!$P:$P,BV_Data_An_Cour!$U:$U,$A$1,BV_Data_An_Cour!$V:$V,$D9) -> 0
A10: Recevables Manufacturier | B10: =SUMIFS(BV_Data_An_Cour!$P:$P,BV_Data_An_Cour!$U:$U,$A$1,BV_Data_An_Cour!$V:$V,$A10) -> 61395.65 | D10: Comptes à Payer Fournisseurs | E10: =-SUMIFS(BV_Data_An_Cour!$P:$P,BV_Data_An_Cour!$U:$U,$A$1,BV_Data_An_Cour!$V:$V,$D10) -> -144792.09
A11: Recevables Pièces et Service | B11: =SUMIFS(BV_Data_An_Cour!$P:$P,BV_Data_An_Cour!$U:$U,$A$1,BV_Data_An_Cour!$V:$V,$A11) -> 81355.21 | D11: Taxes de Vente à Payer | E11: =-SUMIFS(BV_Data_An_Cour!$P:$P,BV_Data_An_Cour!$U:$U,$A$1,BV_Data_An_Cour!$V:$V,$D11) -> 58712.32
A12: Recevables Garantie Manufacturier | B12: =SUMIFS(BV_Data_An_Cour!$P:$P,BV_Data_An_Cour!$U:$U,$A$1,BV_Data_An_Cour!$V:$V,$A12) -> 87408.31 | D12: Impôts à payer | E12: =-SUMIFS(BV_Data_An_Cour!$P:$P,BV_Data_An_Cour!$U:$U,$A$1,BV_Data_An_Cour!$V:$V,$D12) -> 0
A13: Recevables Carrosserie | B13: =SUMIFS(BV_Data_An_Cour!$P:$P,BV_Data_An_Cour!$U:$U,$A$1,BV_Data_An_Cour!$V:$V,$A13) -> 29016.22 | D13: Dépôts de Client | E13: =-SUMIFS(BV_Data_An_Cour!$P:$P,BV_Data_An_Cour!$U:$U,$A$1,BV_Data_An_Cour!$V:$V,$D13) -> 3850
A14: Recevables Intercos | B14: =SUMIFS(BV_Data_An_Cour!$P:$P,BV_Data_An_Cour!$U:$U,$A$1,BV_Data_An_Cour!$V:$V,$A14) -> 0 | D14: Payables Intercos | E14: =-SUMIFS(BV_Data_An_Cour!$P:$P,BV_Data_An_Cour!$U:$U,$A$1,BV_Data_An_Cour!$V:$V,$D14) -> 0
A15: Recevables Autres | B15: =SUMIFS(BV_Data_An_Cour!$P:$P,BV_Data_An_Cour!$U:$U,$A$1,BV_Data_An_Cour!$V:$V,$A15) -> 56528.55 | D15: Autres Comptes à Payer | E15: =-SUMIFS(BV_Data_An_Cour!$P:$P,BV_Data_An_Cour!$U:$U,$A$1,BV_Data_An_Cour!$V:$V,$D15) -> 230899.55
A16: Total Comptes à Recevoir | B16: =+SUM(B8:B15) -> 1011751.1 | D16: Total Comptes à Payer | E16: =+SUM(E10:E15) -> 148669.78
A18: Inventaire Véhicules Neufs | B18: =SUMIFS(BV_Data_An_Cour!$P:$P,BV_Data_An_Cour!$U:$U,$A$1,BV_Data_An_Cour!$V:$V,$A18) -> 3553237 | D18: Effet à Payer Véhicules Neufs | E18: =-SUMIFS(BV_Data_An_Cour!$P:$P,BV_Data_An_Cour!$U:$U,$A$1,BV_Data_An_Cour!$V:$V,$D18) -> 4383477.9
A19: Inventaire Véhicules Usagés | B19: =SUMIFS(BV_Data_An_Cour!$P:$P,BV_Data_An_Cour!$U:$U,$A$1,BV_Data_An_Cour!$V:$V,$A19) -> 1282311.2 | D19: Effet à Payer Véhicules Usagés | E19: =-SUMIFS(BV_Data_An_Cour!$P:$P,BV_Data_An_Cour!$U:$U,$A$1,BV_Data_An_Cour!$V:$V,$D19) -> 345495.8
A20: Inventaire Pièces, Pneus, Huile | B20: =SUMIFS(BV_Data_An_Cour!$P:$P,BV_Data_An_Cour!$U:$U,$A$1,BV_Data_An_Cour!$V:$V,$A20) -> 389300.39 | D20: Total Effets à Payer | E20: =+SUM(E18:E19) -> 4728973.7
A21: Total Inventaires | B21: =SUM(B18:B20) -> 5224848.6
D22: Salaires à Payer | E22: =-SUMIFS(BV_Data_An_Cour!$P:$P,BV_Data_An_Cour!$U:$U,$A$1,BV_Data_An_Cour!$V:$V,$D22) -> 371498.91
A23: Avances à recevoir | B23: =SUMIFS(BV_Data_An_Cour!$P:$P,BV_Data_An_Cour!$U:$U,$A$1,BV_Data_An_Cour!$V:$V,$A23) -> 0 | D23: DAS à Payer | E23: =-SUMIFS(BV_Data_An_Cour!$P:$P,BV_Data_An_Cour!$U:$U,$A$1,BV_Data_An_Cour!$V:$V,$D23) -> 20587.13
A24: Travaux en Cours | B24: =SUMIFS(BV_Data_An_Cour!$P:$P,BV_Data_An_Cour!$U:$U,$A$1,BV_Data_An_Cour!$V:$V,$A24) -> 7123.04 | D24: Autres Courus | E24: =-SUMIFS(BV_Data_An_Cour!$P:$P,BV_Data_An_Cour!$U:$U,$A$1,BV_Data_An_Cour!$V:$V,$D24) -> 34676.97
A25: Sous-Traitance | B25: =SUMIFS(BV_Data_An_Cour!$P:$P,BV_Data_An_Cour!$U:$U,$A$1,BV_Data_An_Cour!$V:$V,$A25) -> -4121.42 | D25: [...] | E25: =-SUMIFS(BV_Data_An_Cour!$P:$P,BV_Data_An_Cour!$U:$U,$A$1,BV_Data_An_Cour!$V:$V,$D25) -> 0
A26: Frais Payés d'Avance | B26: =SUMIFS(BV_Data_An_Cour!$P:$P,BV_Data_An_Cour!$U:$U,$A$1,BV_Data_An_Cour!$V:$V,$A26) -> 98829.07 | D26: [...] | E26: =-SUMIFS(BV_Data_An_Cour!$P:$P,BV_Data_An_Cour!$U:$U,$A$1,BV_Data_An_Cour!$V:$V,$D26) -> 0
A27: [...] | B27: =SUMIFS(BV_Data_An_Cour!$P:$P,BV_Data_An_Cour!$U:$U,$A$1,BV_Data_An_Cour!$V:$V,$A27) -> 0 | D27: [...] | E27: =-SUMIFS(BV_Data_An_Cour!$P:$P,BV_Data_An_Cour!$U:$U,$A$1,BV_Data_An_Cour!$V:$V,$D27) -> 0
A28: [...] | B28: =SUMIFS(BV_Data_An_Cour!$P:$P,BV_Data_An_Cour!$U:$U,$A$1,BV_Data_An_Cour!$V:$V,$A28) -> 0 | D28: Total Frais Courus | E28: =SUM(E22:E24) -> 426763.01
A29: [...] | B29: =SUMIFS(BV_Data_An_Cour!$P:$P,BV_Data_An_Cour!$U:$U,$A$1,BV_Data_An_Cour!$V:$V,$A29) -> 0
A30: Total Autres | B30: =SUM(B23:B29) -> 101830.69 | D30: Total Passif Court Terme | E30: =+E5+E7+E16+E20+E28 -> 5320216.5
A32: Total Actif Court Terme | B32: =+B6+B16+B21+B30 -> 8928949.4
D33: Impôts Futurs à payer | E33: =-SUMIFS(BV_Data_An_Cour!$P:$P,BV_Data_An_Cour!$U:$U,$A$1,BV_Data_An_Cour!$V:$V,$D33) -> 0
A35: Terrain | B35: =SUMIFS(BV_Data_An_Cour!$P:$P,BV_Data_An_Cour!$U:$U,$A$1,BV_Data_An_Cour!$V:$V,$A35) -> 0 | D35: Avances Long Terme à Payer | E35: =-SUMIFS(BV_Data_An_Cour!$P:$P,BV_Data_An_Cour!$U:$U,$A$1,BV_Data_An_Cour!$V:$V,$D35) -> 0
A36: Bâtisse | B36: =SUMIFS(BV_Data_An_Cour!$P:$P,BV_Data_An_Cour!$U:$U,$A$1,BV_Data_An_Cour!$V:$V,$A36) -> 0 | D36: Hypothèque à Payer | E36: =-SUMIFS(BV_Data_An_Cour!$P:$P,BV_Data_An_Cour!$U:$U,$A$1,BV_Data_An_Cour!$V:$V,$D36) -> 0
A37: Améliorations Locatives | B37: =SUMIFS(BV_Data_An_Cour!$P:$P,BV_Data_An_Cour!$U:$U,$A$1,BV_Data_An_Cour!$V:$V,$A37) -> 969.31 | D37: Dette à Long Terme | E37: =-SUMIFS(BV_Data_An_Cour!$P:$P,BV_Data_An_Cour!$U:$U,$A$1,BV_Data_An_Cour!$V:$V,$D37) -> 27109
A38: Améliorations Locatives Permanentes | B38: =SUMIFS(BV_Data_An_Cour!$P:$P,BV_Data_An_Cour!$U:$U,$A$1,BV_Data_An_Cour!$V:$V,$A38) -> 0 | D38: Autres Dettes à Long Terme | E38: =-SUMIFS(BV_Data_An_Cour!$P:$P,BV_Data_An_Cour!$U:$U,$A$1,BV_Data_An_Cour!$V:$V,$D38) -> 0
A39: Équipements Service | B39: =SUMIFS(BV_Data_An_Cour!$P:$P,BV_Data_An_Cour!$U:$U,$A$1,BV_Data_An_Cour!$V:$V,$A39) -> 185175.8 | D39: [...] | E39: =-SUMIFS(BV_Data_An_Cour!$P:$P,BV_Data_An_Cour!$U:$U,$A$1,BV_Data_An_Cour!$V:$V,$D39) -> 0
A40: Mobilier | B40: =SUMIFS(BV_Data_An_Cour!$P:$P,BV_Data_An_Cour!$U:$U,$A$1,BV_Data_An_Cour!$V:$V,$A40) -> 35713.95 | D40: [...] | E40: =-SUMIFS(BV_Data_An_Cour!$P:$P,BV_Data_An_Cour!$U:$U,$A$1,BV_Data_An_Cour!$V:$V,$D40) -> 0
A41: Équipements Informatique | B41: =SUMIFS(BV_Data_An_Cour!$P:$P,BV_Data_An_Cour!$U:$U,$A$1,BV_Data_An_Cour!$V:$V,$A41) -> 24410.66 | D41: [...] | E41: =-SUMIFS(BV_Data_An_Cour!$P:$P,BV_Data_An_Cour!$U:$U,$A$1,BV_Data_An_Cour!$V:$V,$D41) -> 0
A42: Équipements Téléphonique | B42: =SUMIFS(BV_Data_An_Cour!$P:$P,BV_Data_An_Cour!$U:$U,$A$1,BV_Data_An_Cour!$V:$V,$A42) -> 20 | D42: Total Passif long terme | E42: =+SUM(E33:E38) -> 27109
A43: Enseigne | B43: =SUMIFS(BV_Data_An_Cour!$P:$P,BV_Data_An_Cour!$U:$U,$A$1,BV_Data_An_Cour!$V:$V,$A43) -> -184.99
A44: Total Immobilisations Nettes | B44: =SUM(B35:B43) -> 246104.73
...

Sheet Budget original
B1: ="Budget 2021 Mensuel"&" "&Parametres!$B$1 -> Budget 2021 Mensuel Volks
B2: Mois | F2: =+IF(Parametres!$B$3=F$6,"X","") -> X | G2: =+IF(Parametres!$B$3=F$6,"O","") -> O | H2: =+IF(Parametres!$B$3=F$6,"U","") -> U | I2: =+IF(Parametres!$B$3=I$6,"X","") | J2: =+IF(Parametres!$B$3=I$6,"O","") | K2: =+IF(Parametres!$B$3=I$6,"U","") | L2: =+IF(Parametres!$B$3=L$6,"X","") | M2: =+IF(Parametres!$B$3=L$6,"O","") | N2: =+IF(Parametres!$B$3=L$6,"U","") | O2: =+IF(Parametres!$B$3=O$6,"X","") | P2: =+IF(Parametres!$B$3=O$6,"O","") | Q2: =+IF(Parametres!$B$3=O$6,"U","") | R2: =+IF(Parametres!$B$3=R$6,"X","") | S2: =+IF(Parametres!$B$3=R$6,"O","") | T2: =+IF(Parametres!$B$3=R$6,"U","") | U2: =+IF(Parametres!$B$3=U$6,"X","") | V2: =+IF(Parametres!$B$3=U$6,"O","") | W2: =+IF(Parametres!$B$3=U$6,"U","") | X2: =+IF(Parametres!$B$3=X$6,"X","") | Y2: =+IF(Parametres!$B$3=X$6,"O","") | Z2: =+IF(Parametres!$B$3=X$6,"U","") | AA2: =+IF(Parametres!$B$3=AA$6,"X","") | AB2: =+IF(Parametres!$B$3=AA$6,"O","") | AC2: =+IF(Parametres!$B$3=AA$6,"U","") | AD2: =+IF(Parametres!$B$3=AD$6,"X","") | AE2: =+IF(Parametres!$B$3=AD$6,"O","") | AF2: =+IF(Parametres!$B$3=AD$6,"U","") | AG2: =+IF(Parametres!$B$3=AG$6,"X","") | AH2: =+IF(Parametres!$B$3=AG$6,"O","") | AI2: =+IF(Parametres!$B$3=AG$6,"U","") | AJ2: =+IF(Parametres!$B$3=AJ$6,"X","") | AK2: =+IF(Parametres!$B$3=AJ$6,"O","") | AL2: =+IF(Parametres!$B$3=AJ$6,"U","") | AM2: =+IF(Parametres!$B$3=AM$6,"X","") | AN2: =+IF(Parametres!$B$3=AM$6,"O","") | AO2: =+IF(Parametres!$B$3=AM$6,"U","")
B3: YTD | F3: =+IF(VLOOKUP(F$6,Parametres!$K$3:$N$14,4,0)="X","X","") -> X | G3: =+IF(VLOOKUP(F$6,Parametres!$K$3:$N$14,4,0)="X","O","") -> O | H3: =+IF(VLOOKUP(F$6,Parametres!$K$3:$N$14,4,0)="X","U","") -> U | I3: =+IF(VLOOKUP(I$6,Parametres!$K$3:$N$14,4,0)="X","X","") | J3: =+IF(VLOOKUP(I$6,Parametres!$K$3:$N$14,4,0)="X","O","") | K3: =+IF(VLOOKUP(I$6,Parametres!$K$3:$N$14,4,0)="X","U","") | L3: =+IF(VLOOKUP(L$6,Parametres!$K$3:$N$14,4,0)="X","X","") | M3: =+IF(VLOOKUP(L$6,Parametres!$K$3:$N$14,4,0)="X","O","") | N3: =+IF(VLOOKUP(L$6,Parametres!$K$3:$N$14,4,0)="X","U","") | O3: =+IF(VLOOKUP(O$6,Parametres!$K$3:$N$14,4,0)="X","X","") | P3: =+IF(VLOOKUP(O$6,Parametres!$K$3:$N$14,4,0)="X","O","") | Q3: =+IF(VLOOKUP(O$6,Parametres!$K$3:$N$14,4,0)="X","U","") | R3: =+IF(VLOOKUP(R$6,Parametres!$K$3:$N$14,4,0)="X","X","") | S3: =+IF(VLOOKUP(R$6,Parametres!$K$3:$N$14,4,0)="X","O","") | T3: =+IF(VLOOKUP(R$6,Parametres!$K$3:$N$14,4,0)="X","U","") | U3: =+IF(VLOOKUP(U$6,Parametres!$K$3:$N$14,4,0)="X","X","") | V3: =+IF(VLOOKUP(U$6,Parametres!$K$3:$N$14,4,0)="X","O","") | W3: =+IF(VLOOKUP(U$6,Parametres!$K$3:$N$14,4,0)="X","U","") | X3: =+IF(VLOOKUP(X$6,Parametres!$K$3:$N$14,4,0)="X","X","") | Y3: =+IF(VLOOKUP(X$6,Parametres!$K$3:$N$14,4,0)="X","O","") | Z3: =+IF(VLOOKUP(X$6,Parametres!$K$3:$N$14,4,0)="X","U","") | AA3: =+IF(VLOOKUP(AA$6,Parametres!$K$3:$N$14,4,0)="X","X","") | AB3: =+IF(VLOOKUP(AA$6,Parametres!$K$3:$N$14,4,0)="X","O","") | AC3: =+IF(VLOOKUP(AA$6,Parametres!$K$3:$N$14,4,0)="X","U","") | AD3: =+IF(VLOOKUP(AD$6,Parametres!$K$3:$N$14,4,0)="X","X","") | AE3: =+IF(VLOOKUP(AD$6,Parametres!$K$3:$N$14,4,0)="X","O","") | AF3: =+IF(VLOOKUP(AD$6,Parametres!$K$3:$N$14,4,0)="X","U","") | AG3: =+IF(VLOOKUP(AG$6,Parametres!$K$3:$N$14,4,0)="X","X","") | AH3: =+IF(VLOOKUP(AG$6,Parametres!$K$3:$N$14,4,0)="X","O","") | AI3: =+IF(VLOOKUP(AG$6,Parametres!$K$3:$N$14,4,0)="X","U","") | AJ3: =+IF(VLOOKUP(AJ$6,Parametres!$K$3:$N$14,4,0)="X","X","") | AK3: =+IF(VLOOKUP(AJ$6,Parametres!$K$3:$N$14,4,0)="X","O","") | AL3: =+IF(VLOOKUP(AJ$6,Parametres!$K$3:$N$14,4,0)="X","U","") | AM3: =+IF(VLOOKUP(AM$6,Parametres!$K$3:$N$14,4,0)="X","X","") | AN3: =+IF(VLOOKUP(AM$6,Parametres!$K$3:$N$14,4,0)="X","O","") | AO3: =+IF(VLOOKUP(AM$6,Parametres!$K$3:$N$14,4,0)="X","U","")
B4: Budget 2021 | C4: Véhicules neufs
B6: Mois | C6: TOTAL | F6: Janvier | I6: Février | L6: Mars | O6: Avril | R6: Mai | U6: Juin | X6: Juillet | AA6: Août | AD6: Septembre | AG6: Octobre | AJ6: Novembre | AM6: Décembre
C7: UNITE | D7: $P/UNITE | E7: $PROFITS | F7: UNITE | G7: $P/UNITE | H7: $PROFITS | I7: UNITE | J7: $P/UNITE | K7: $PROFITS | L7: UNITE | M7: $P/UNITE | N7: $PROFITS | O7: UNITE | P7: $P/UNITE | Q7: $PROFITS | R7: UNITE | S7: $P/UNITE | T7: $PROFITS | U7: UNITE | V7: $P/UNITE | W7: $PROFITS | X7: UNITE | Y7: $P/UNITE | Z7: $PROFITS | AA7: UNITE | AB7: $P/UNITE | AC7: $PROFITS | AD7: UNITE | AE7: $P/UNITE | AF7: $PROFITS | AG7: UNITE | AH7: $P/UNITE | AI7: $PROFITS | AJ7: UNITE | AK7: $P/UNITE | AL7: $PROFITS | AM7: UNITE | AN7: $P/UNITE | AO7: $PROFITS
A8: =+$C$4&B8 -> Véhicules neufsVentes nettes | B8: Ventes nettes | E8: =+SUM(H8,K8,N8,Q8,T8,W8,Z8,AC8,AF8,AI8,AL8,AO8) -> 9553310.1 | H8: 1882577.9 | K8: 446219.11 | N8: 678330.08 | Q8: 751340.66 | T8: 981796.55 | W8: 691716.4 | Z8: 688676.89 | AC8: 729220.97 | AF8: 799077.54 | AI8: 991144.07 | AL8: 576007.02 | AO8: 337202.89
A9: =+$C$4&B9 -> Véhicules neufsAutos détail | B9: Autos détail | C9: =+SUM(F9,I9,L9,O9,R9,U9,X9,AA9,AD9,AG9,AJ9,AM9) -> 303 | D9: =IF(C9=0,0,E9/C9) -> 604.29043 | E9: =+SUM(H9,K9,N9,Q9,T9,W9,Z9,AC9,AF9,AI9,AL9,AO9) -> 183100 | F9: 23.607096 | G9: =IF(F9=0,0,H9/F9) -> 604.29043 | H9: 14265.542 | I9: 16.252745 | J9: =IF(I9=0,0,K9/I9) -> 604.29043 | K9: 9821.3783 | L9: 24.706978 | M9: =IF(L9=0,0,N9/L9) -> 604.29043 | N9: 14930.19 | O9: 27.36626 | P9: =IF(O9=0,0,Q9/O9) -> 604.29043 | Q9: 16537.169 | R9: 35.76021 | S9: =IF(R9=0,0,T9/R9) -> 604.29043 | T9: 21609.552 | U9: 25.194551 | V9: =IF(U9=0,0,W9/U9) -> 604.29043 | W9: 15224.826 | X9: 25.083842 | Y9: =IF(X9=0,0,Z9/X9) -> 604.29043 | Z9: 15157.926 | AA9: 26.560589 | AB9: =IF(AA9=0,0,AC9/AA9) -> 604.29043 | AC9: 16050.31 | AD9: 29.104991 | AE9: =IF(AD9=0,0,AF9/AD9) -> 604.29043 | AF9: 17587.868 | AG9: 36.100676 | AH9: =IF(AG9=0,0,AI9/AG9) -> 604.29043 | AI9: 21815.293 | AJ9: 20.980041 | AK9: =IF(AJ9=0,0,AL9/AJ9) -> 604.29043 | AL9: 12678.038 | AM9: 12.282021 | AN9: =IF(AM9=0,0,AO9/AM9) -> 604.29043 | AO9: 7421.9079
A10: =+$C$4&B10 -> Véhicules neufsCamions détail | B10: Camions détail | C10: =+SUM(F10,I10,L10,O10,R10,U10,X10,AA10,AD10,AG10,AJ10,AM10) -> 407 | D10: =IF(C10=0,0,E10/C10) -> 1315.4791 | E10: =+SUM(H10,K10,N10,Q10,T10,W10,Z10,AC10,AF10,AI10,AL10,AO10) -> 535400 | F10: 31.709861 | G10: =IF(F10=0,0,H10/F10) -> 1315.4791 | H10: 41713.66 | I10: 21.831245 | J10: =IF(I10=0,0,K10/I10) -> 1315.4791 | K10: 28718.547 | L10: 33.187261 | M10: =IF(L10=0,0,N10/L10) -> 1315.4791 | N10: 43657.149 | O10: 36.759299 | P10: =IF(O10=0,0,Q10/O10) -> 1315.4791 | Q10: 48356.09 | R10: 48.034341 | S10: =IF(R10=0,0,T10/R10) -> 1315.4791 | T10: 63188.172 | U10: 33.842186 | V10: =IF(U10=0,0,W10/U10) -> 1315.4791 | W10: 44518.688 | X10: 33.693478 | Y10: =IF(X10=0,0,Z10/X10) -> 1315.4791 | Z10: 44323.067 | AA10: 35.677095 | AB10: =IF(AA10=0,0,AC10/AA10) -> 1315.4791 | AC10: 46932.473 | AD10: 39.094824 | AE10: =IF(AD10=0,0,AF10/AD10) -> 1315.4791 | AF10: 51428.424 | AG10: 48.491668 | AH10: =IF(AG10=0,0,AI10/AG10) -> 1315.4791 | AI10: 63789.776 | AJ10: 28.181111 | AK10: =IF(AJ10=0,0,AL10/AJ10) -> 1315.4791 | AL10: 37071.663 | AM10: 16.497633 | AN10: =IF(AM10=0,0,AO10/AM10) -> 1315.4791 | AO10: 21702.291
A11: =+$C$4&B11 -> Véhicules neufsSprinter | B11: Sprinter | C11: =+SUM(F11,I11,L11,O11,R11,U11,X11,AA11,AD11,AG11,AJ11,AM11) -> 0 | D11: =IF(C11=0,0,E11/C11) -> 0 | E11: =+SUM(H11,K11,N11,Q11,T11,W11,Z11,AC11,AF11,AI11,AL11,AO11) -> 0 | G11: =IF(F11=0,0,H11/F11) -> 0 | J11: =IF(I11=0,0,K11/I11) -> 0 | M11: =IF(L11=0,0,N11/L11) -> 0 | P11: =IF(O11=0,0,Q11/O11) -> 0 | S11: =IF(R11=0,0,T11/R11) -> 0 | V11: =IF(U11=0,0,W11/U11) -> 0 | Y11: =IF(X11=0,0,Z11/X11) -> 0 | AB11: =IF(AA11=0,0,AC11/AA11) -> 0 | AE11: =IF(AD11=0,0,AF11/AD11) -> 0 | AH11: =IF(AG11=0,0,AI11/AG11) -> 0 | AK11: =IF(AJ11=0,0,AL11/AJ11) -> 0 | AN11: =IF(AM11=0,0,AO11/AM11) -> 0
A12: =+$C$4&B12 -> Véhicules neufsMoto détail | B12: Moto détail | C12: =+SUM(F12,I12,L12,O12,R12,U12,X12,AA12,AD12,AG12,AJ12,AM12) -> 0 | D12: =IF(C12=0,0,E12/C12) -> 0 | E12: =+SUM(H12,K12,N12,Q12,T12,W12,Z12,AC12,AF12,AI12,AL12,AO12) -> 0 | G12: =IF(F12=0,0,H12/F12) -> 0 | J12: =IF(I12=0,0,K12/I12) -> 0 | M12: =IF(L12=0,0,N12/L12) -> 0 | P12: =IF(O12=0,0,Q12/O12) -> 0 | S12: =IF(R12=0,0,T12/R12) -> 0 | V12: =IF(U12=0,0,W12/U12) -> 0 | Y12: =IF(X12=0,0,Z12/X12) -> 0 | AB12: =IF(AA12=0,0,AC12/AA12) -> 0 | AE12: =IF(AD12=0,0,AF12/AD12) -> 0 | AH12: =IF(AG12=0,0,AI12/AG12) -> 0 | AK12: =IF(AJ12=0,0,AL12/AJ12) -> 0 | AN12: =IF(AM12=0,0,AO12/AM12) -> 0
A13: =+$C$4&B13 -> Véhicules neufs[...] | B13: [...] | C13: =+SUM(F13,I13,L13,O13,R13,U13,X13,AA13,AD13,AG13,AJ13,AM13) -> 0 | D13: =IF(C13=0,0,E13/C13) -> 0 | E13: =+SUM(H13,K13,N13,Q13,T13,W13,Z13,AC13,AF13,AI13,AL13,AO13) -> 0 | G13: =IF(F13=0,0,H13/F13) -> 0 | J13: =IF(I13=0,0,K13/I13) -> 0 | M13: =IF(L13=0,0,N13/L13) -> 0 | P13: =IF(O13=0,0,Q13/O13) -> 0 | S13: =IF(R13=0,0,T13/R13) -> 0 | V13: =IF(U13=0,0,W13/U13) -> 0 | Y13: =IF(X13=0,0,Z13/X13) -> 0 | AB13: =IF(AA13=0,0,AC13/AA13) -> 0 | AE13: =IF(AD13=0,0,AF13/AD13) -> 0 | AH13: =IF(AG13=0,0,AI13/AG13) -> 0 | AK13: =IF(AJ13=0,0,AL13/AJ13) -> 0 | AN13: =IF(AM13=0,0,AO13/AM13) -> 0
A14: =+$C$4&B14 -> Véhicules neufs[...] | B14: [...] | C14: =+SUM(F14,I14,L14,O14,R14,U14,X14,AA14,AD14,AG14,AJ14,AM14) -> 0 | D14: =IF(C14=0,0,E14/C14) -> 0 | E14: =+SUM(H14,K14,N14,Q14,T14,W14,Z14,AC14,AF14,AI14,AL14,AO14) -> 0 | G14: =IF(F14=0,0,H14/F14) -> 0 | J14: =IF(I14=0,0,K14/I14) -> 0 | M14: =IF(L14=0,0,N14/L14) -> 0 | P14: =IF(O14=0,0,Q14/O14) -> 0 | S14: =IF(R14=0,0,T14/R14) -> 0 | V14: =IF(U14=0,0,W14/U14) -> 0 | Y14: =IF(X14=0,0,Z14/X14) -> 0 | AB14: =IF(AA14=0,0,AC14/AA14) -> 0 | AE14: =IF(AD14=0,0,AF14/AD14) -> 0 | AH14: =IF(AG14=0,0,AI14/AG14) -> 0 | AK14: =IF(AJ14=0,0,AL14/AJ14) -> 0 | AN14: =IF(AM14=0,0,AO14/AM14) -> 0
A15: =+$C$4&B15 -> Véhicules neufs[...] | B15: [...] | C15: =+SUM(F15,I15,L15,O15,R15,U15,X15,AA15,AD15,AG15,AJ15,AM15) -> 0 | D15: =IF(C15=0,0,E15/C15) -> 0 | E15: =+SUM(H15,K15,N15,Q15,T15,W15,Z15,AC15,AF15,AI15,AL15,AO15) -> 0 | G15: =IF(F15=0,0,H15/F15) -> 0 | J15: =IF(I15=0,0,K15/I15) -> 0 | M15: =IF(L15=0,0,N15/L15) -> 0 | P15: =IF(O15=0,0,Q15/O15) -> 0 | S15: =IF(R15=0,0,T15/R15) -> 0 | V15: =IF(U15=0,0,W15/U15) -> 0 | Y15: =IF(X15=0,0,Z15/X15) -> 0 | AB15: =IF(AA15=0,0,AC15/AA15) -> 0 | AE15: =IF(AD15=0,0,AF15/AD15) -> 0 | AH15: =IF(AG15=0,0,AI15/AG15) -> 0 | AK15: =IF(AJ15=0,0,AL15/AJ15) -> 0 | AN15: =IF(AM15=0,0,AO15/AM15) -> 0
A16: =+$C$4&B16 -> Véhicules neufsTotal Neufs | B16: Total Neufs | C16: =+SUM(C9:C15) -> 710 | D16: =IF(C16<=0,0,E16/C16) -> 1011.9718 | E16: =+SUM(E9:E15) -> 718500 | F16: =+SUM(F9:F15) -> 55.316957 | G16: =IF(F16<=0,0,H16/F16) -> 1011.9718 | H16: =+SUM(H9:H15) -> 55979.202 | I16: =+SUM(I9:I15) -> 38.08399 | J16: =IF(I16<=0,0,K16/I16) -> 1011.9718 | K16: =+SUM(K9:K15) -> 38539.925 | L16: =+SUM(L9:L15) -> 57.894239 | M16: =IF(L16<=0,0,N16/L16) -> 1011.9718 | N16: =+SUM(N9:N15) -> 58587.339 | O16: =+SUM(O9:O15) -> 64.125559 | P16: =IF(O16<=0,0,Q16/O16) -> 1011.9718 | Q16: =+SUM(Q9:Q15) -> 64893.259 | R16: =+SUM(R9:R15) -> 83.79455 | S16: =IF(R16<=0,0,T16/R16) -> 1011.9718 | T16: =+SUM(T9:T15) -> 84797.725 | U16: =+SUM(U9:U15) -> 59.036736 | V16: =IF(U16<=0,0,W16/U16) -> 1011.9718 | W16: =+SUM(W9:W15) -> 59743.514 | X16: =+SUM(X9:X15) -> 58.77732 | Y16: =IF(X16<=0,0,Z16/X16) -> 1011.9718 | Z16: =+SUM(Z9:Z15) -> 59480.992 | AA16: =+SUM(AA9:AA15) -> 62.237684 | AB16: =IF(AA16<=0,0,AC16/AA16) -> 1011.9718 | AC16: =+SUM(AC9:AC15) -> 62982.783 | AD16: =+SUM(AD9:AD15) -> 68.199815 | AE16: =IF(AD16<=0,0,AF16/AD16) -> 1011.9718 | AF16: =+SUM(AF9:AF15) -> 69016.292 | AG16: =+SUM(AG9:AG15) -> 84.592344 | AH16: =IF(AG16<=0,0,AI16/AG16) -> 1011.9718 | AI16: =+SUM(AI9:AI15) -> 85605.069 | AJ16: =+SUM(AJ9:AJ15) -> 49.161152 | AK16: =IF(AJ16<=0,0,AL16/AJ16) -> 1011.9718 | AL16: =+SUM(AL9:AL15) -> 49749.701 | AM16: =+SUM(AM9:AM15) -> 28.779654 | AN16: =IF(AM16<=0,0,AO16/AM16) -> 1011.9718 | AO16: =+SUM(AO9:AO15) -> 29124.199
A17: =+$C$4&B17 -> Véhicules neufs
A18: =+$C$4&B18 -> Véhicules neufsEx-Démos et courtoisies | B18: Ex-Démos et courtoisies | C18: =+SUM(F18,I18,L18,O18,R18,U18,X18,AA18,AD18,AG18,AJ18,AM18) -> 74 | D18: =IF(C18=0,0,E18/C18) -> 400 | E18: =+SUM(H18,K18,N18,Q18,T18,W18,Z18,AC18,AF18,AI18,AL18,AO18) -> 29600 | F18: 5.7654293 | G18: =IF(F18=0,0,H18/F18) -> 400 | H18: 2306.1717 | I18: 3.9693173 | J18: =IF(I18=0,0,K18/I18) -> 400 | K18: 1587.7269 | L18: 6.0340474 | M18: =IF(L18=0,0,N18/L18) -> 400 | N18: 2413.619 | O18: 6.683509 | P18: =IF(O18=0,0,Q18/O18) -> 400 | Q18: 2673.4036 | R18: 8.7335165 | S18: =IF(R18=0,0,T18/R18) -> 400 | T18: 3493.4066 | U18: 6.1531246 | V18: =IF(U18=0,0,W18/U18) -> 400 | W18: 2461.2499 | X18: 6.1260869 | Y18: =IF(X18=0,0,Z18/X18) -> 400 | Z18: 2450.4348 | AA18: 6.4867445 | AB18: =IF(AA18=0,0,AC18/AA18) -> 400 | AC18: 2594.6978 | AD18: 7.1081497 | AE18: =IF(AD18=0,0,AF18/AD18) -> 400 | AF18: 2843.2599 | AG18: 8.8166669 | AH18: =IF(AG18=0,0,AI18/AG18) -> 400 | AI18: 3526.6667 | AJ18: 5.1238383 | AK18: =IF(AJ18=0,0,AL18/AJ18) -> 400 | AL18: 2049.5353 | AM18: 2.9995696 | AN18: =IF(AM18=0,0,AO18/AM18) -> 400 | AO18: 1199.8278
A19: =+$C$4&B19 -> Véhicules neufs
A20: =+$C$4&B20 -> Véhicules neufsFlottes | B20: Flottes | C20: =+SUM(F20,I20,L20,O20,R20,U20,X20,AA20,AD20,AG20,AJ20,AM20) -> 0 | D20: =IF(C20=0,0,E20/C20) -> 0 | E20: =+SUM(H20,K20,N20,Q20,T20,W20,Z20,AC20,AF20,AI20,AL20,AO20) -> 0 | F20: 0 | G20: =IF(F20=0,0,H20/F20) -> 0 | H20: 0 | I20: 0 | J20: =IF(I20=0,0,K20/I20) -> 0 | K20: 0 | L20: 0 | M20: =IF(L20=0,0,N20/L20) -> 0 | N20: 0 | O20: 0 | P20: =IF(O20=0,0,Q20/O20) -> 0 | Q20: 0 | R20: 0 | S20: =IF(R20=0,0,T20/R20) -> 0 | T20: 0 | U20: 0 | V20: =IF(U20=0,0,W20/U20) -> 0 | W20: 0 | X20: 0 | Y20: =IF(X20=0,0,Z20/X20) -> 0 | Z20: 0 | AA20: 0 | AB20: =IF(AA20=0,0,AC20/AA20) -> 0 | AC20: 0 | AD20: 0 | AE20: =IF(AD20=0,0,AF20/AD20) -> 0 | AF20: 0 | AG20: 0 | AH20: =IF(AG20=0,0,AI20/AG20) -> 0 | AI20: 0 | AJ20: 0 | AK20: =IF(AJ20=0,0,AL20/AJ20) -> 0 | AL20: 0 | AM20: 0 | AN20: =IF(AM20=0,0,AO20/AM20) -> 0 | AO20: 0
A21: =+$C$4&B21 -> Véhicules neufs
A22: =+$C$4&B22 -> Véhicules neufsRachat bail | B22: Rachat bail | E22: =+SUM(H22,K22,N22,Q22,T22,W22,Z22,AC22,AF22,AI22,AL22,AO22) -> 60000 | H22: 5000 | K22: 5000 | N22: 5000 | Q22: 5000 | T22: 5000 | W22: 5000 | Z22: 5000 | AC22: 5000 | AF22: 5000 | AI22: 5000 | AL22: 5000 | AO22: 5000
A23: =+$C$4&B23 -> Véhicules neufs
A24: =+$C$4&B24 -> Véhicules neufsRev. Finances | B24: Rev. Finances | D24: =IF(C16=0,0,E24/(C16+C18)) -> 94.079794 | E24: =+SUM(H24,K24,N24,Q24,T24,W24,Z24,AC24,AF24,AI24,AL24,AO24) -> 73758.559 | G24: =IF(F16=0,0,H24/(F16+F18)) -> 94.079794 | H24: 5746.6183 | J24: =IF(I16=0,0,K24/(I16+I18)) -> 94.079794 | K24: 3956.3665 | M24: =IF(L16=0,0,N24/(L16+L18)) -> 94.079794 | N24: 6014.36 | P24: =IF(O16=0,0,Q24/(O16+O18)) -> 94.079794 | Q24: 6661.7025 | S24: =IF(R16=0,0,T24/(R16+R18)) -> 94.079794 | T24: 8705.0215 | V24: =IF(U16=0,0,W24/(U16+U18)) -> 94.079794 | W24: 6133.0487 | Y24: =IF(X16=0,0,Z24/(X16+X18)) -> 94.079794 | Z24: 6106.0992 | AB24: =IF(AA16=0,0,AC24/(AA16+AA18)) -> 94.079794 | AC24: 6465.5801 | AE24: =IF(AD16=0,0,AF24/(AD16+AD18)) -> 94.079794 | AF24: 7084.9578 | AH24: =IF(AG16=0,0,AI24/(AG16+AG18)) -> 94.079794 | AI24: 8787.9005 | AK24: =IF(AJ16=0,0,AL24/(AJ16+AJ18)) -> 94.079794 | AL24: 5107.1207 | AN24: =IF(AM16=0,0,AO24/(AM16+AM18)) -> 94.079794 | AO24: 2989.7828
A25: =+$C$4&B25 -> Véhicules neufsRev. Protections | B25: Rev. Protections | D25: =IF(C16=0,0,E25/(C16+C18)) -> 737.32304 | E25: =+SUM(H25,K25,N25,Q25,T25,W25,Z25,AC25,AF25,AI25,AL25,AO25) -> 578061.26 | G25: =IF(F16=0,0,H25/(F16+F18)) -> 737.32304 | H25: 45037.45 | J25: =IF(I16=0,0,K25/(I16+I18)) -> 737.32304 | K25: 31006.872 | M25: =IF(L16=0,0,N25/(L16+L18)) -> 737.32304 | N25: 47135.798 | P25: =IF(O16=0,0,Q25/(O16+O18)) -> 737.32304 | Q25: 52209.157 | S25: =IF(R16=0,0,T25/(R16+R18)) -> 737.32304 | T25: 68223.075 | V25: =IF(U16=0,0,W25/(U16+U18)) -> 737.32304 | W25: 48065.986 | Y25: =IF(X16=0,0,Z25/(X16+X18)) -> 737.32304 | Z25: 47854.777 | AB25: =IF(AA16=0,0,AC25/(AA16+AA18)) -> 737.32304 | AC25: 50672.104 | AE25: =IF(AD16=0,0,AF25/(AD16+AD18)) -> 737.32304 | AF25: 55526.297 | AH25: =IF(AG16=0,0,AI25/(AG16+AG18)) -> 737.32304 | AI25: 68872.616 | AK25: =IF(AJ16=0,0,AL25/(AJ16+AJ18)) -> 737.32304 | AL25: 40025.574 | AN25: =IF(AM16=0,0,AO25/(AM16+AM18)) -> 737.32304 | AO25: 23431.554
A26: =+$C$4&B26 -> Véhicules neufsRev. Autres | B26: Rev. Autres | D26: =IF(C16=0,0,E26/(C16+C18)) -> 18.597169 | E26: =+SUM(H26,K26,N26,Q26,T26,W26,Z26,AC26,AF26,AI26,AL26,AO26) -> 14580.18 | G26: =IF(F16=0,0,H26/(F16+F18)) -> 18.597169 | H26: 1135.9594 | J26: =IF(I16=0,0,K26/(I16+I18)) -> 18.597169 | K26: 782.07244 | M26: =IF(L16=0,0,N26/(L16+L18)) -> 18.597169 | N26: 1188.8851 | P26: =IF(O16=0,0,Q26/(O16+O18)) -> 18.597169 | Q26: 1316.8482 | S26: =IF(R16=0,0,T26/(R16+R18)) -> 18.597169 | T26: 1720.7601 | V26: =IF(U16=0,0,W26/(U16+U18)) -> 18.597169 | W26: 1212.3468 | Y26: =IF(X16=0,0,Z26/(X16+X18)) -> 18.597169 | Z26: 1207.0196 | AB26: =IF(AA16=0,0,AC26/(AA16+AA18)) -> 18.597169 | AC26: 1278.0798 | AE26: =IF(AD16=0,0,AF26/(AD16+AD18)) -> 18.597169 | AF26: 1400.5149 | AH26: =IF(AG16=0,0,AI26/(AG16+AG18)) -> 18.597169 | AI26: 1737.1431 | AK26: =IF(AJ16=0,0,AL26/(AJ16+AJ18)) -> 18.597169 | AL26: 1009.5471 | AN26: =IF(AM16=0,0,AO26/(AM16+AM18)) -> 18.597169 | AO26: 591.00358
A27: =+$C$4&B27 -> Véhicules neufsTotal F&I | B27: Total F&I | C27: =+C18+C16 -> 784 | D27: =IF(C27<=0,0,E27/C27) -> 850 | E27: =E24+E25+E26 -> 666400 | F27: =+F18+F16 -> 61.082386 | G27: =IF(F27<=0,0,H27/F27) -> 850 | H27: =H24+H25+H26 -> 51920.028 | I27: =+I18+I16 -> 42.053307 | J27: =IF(I27<=0,0,K27/I27) -> 850 | K27: =K24+K25+K26 -> 35745.311 | L27: =+L18+L16 -> 63.928286 | M27: =IF(L27<=0,0,N27/L27) -> 850 | N27: =N24+N25+N26 -> 54339.043 | O27: =+O18+O16 -> 70.809068 | P27: =IF(O27<=0,0,Q27/O27) -> 850 | Q27: =Q24+Q25+Q26 -> 60187.708 | R27: =+R18+R16 -> 92.528067 | S27: =IF(R27<=0,0,T27/R27) -> 850 | T27: =$T$24+$T$25+$T$26 -> 78648.857 | U27: =+U18+U16 -> 65.189861 | V27: =IF(U27<=0,0,W27/U27) -> 850 | W27: =W24+W25+W26 -> 55411.382 | X27: =+X18+X16 -> 64.903407 | Y27: =IF(X27<=0,0,Z27/X27) -> 850 | Z27: =Z24+Z25+Z26 -> 55167.896 | AA27: =+AA18+AA16 -> 68.724428 | AB27: =IF(AA27<=0,0,AC27/AA27) -> 850 | AC27: =AC24+AC25+AC26 -> 58415.764 | AD27: =+AD18+AD16 -> 75.307965 | AE27: =IF(AD27<=0,0,AF27/AD27) -> 850 | AF27: =AF24+AF25+AF26 -> 64011.77 | AG27: =+AG18+AG16 -> 93.409011 | AH27: =IF(AG27<=0,0,AI27/AG27) -> 850 | AI27: =AI24+AI25+AI26 -> 79397.659 | AJ27: =+AJ18+AJ16 -> 54.28499 | AK27: =IF(AJ27<=0,0,AL27/AJ27) -> 850 | AL27: =AL24+AL25+AL26 -> 46142.241 | AM27: =+AM18+AM16 -> 31.779223 | AN27: =IF(AM27<=0,0,AO27/AM27) -> 850 | AO27: =AO24+AO25+AO26 -> 27012.34
A28: =+$C$4&B28 -> Véhicules neufs
A29: =+$C$4&B29 -> Véhicules neufs
A30: =+$C$4&B30 -> Véhicules neufsTotal Dépt. Neufs | B30: Total Dépt. Neufs | C30: =+C16+C18+C20 -> 784 | D30: =IF(C30<=0,0,E30/C30) -> 1880.7398 | E30: =E16+E20+E27+E22+E18 -> 1474500 | F30: =+F16+F18+F20 -> 61.082386 | G30: =IF(F30<=0,0,H30/F30) -> 1886.0658 | H30: =H16+H20+H27+H22+H18 -> 115205.4 | I30: =+I16+I18+I20 -> 42.053307 | J30: =IF(I30<=0,0,K30/I30) -> 1923.1059 | K30: =K16+K20+K27+K22+K18 -> 80872.963 | L30: =+L16+L18+L20 -> 63.928286 | M30: =IF(L30<=0,0,N30/L30) -> 1882.4218 | N30: =N16+N20+N27+N22+N18 -> 120340 | O30: =+O16+O18+O20 -> 70.809068 | P30: =IF(O30<=0,0,Q30/O30) -> 1874.8216 | Q30: =Q16+Q20+Q27+Q22+Q18 -> 132754.37 | R30: =+R16+R18+R20 -> 92.528067 | S30: =IF(R30<=0,0,T30/R30) -> 1858.2468 | T30: =T16+T20+T27+T22+T18 -> 171939.99 | U30: =+U16+U18+U20 -> 65.189861 | V30: =IF(U30<=0,0,W30/U30) -> 1880.9082 | W30: =W16+W20+W27+W22+W18 -> 122616.15 | X30: =+X16+X18+X20 -> 64.903407 | Y30: =IF(X30<=0,0,Z30/X30) -> 1881.2467 | Z30: =Z16+Z20+Z27+Z22+Z18 -> 122099.32 | AA30: =+AA16+AA18+AA20 -> 68.724428 | AB30: =IF(AA30<=0,0,AC30/AA30) -> 1876.9635 | AC30: =AC16+AC20+AC27+AC22+AC18 -> 128993.24 | AD30: =+AD16+AD18+AD20 -> 75.307965 | AE30: =IF(AD30<=0,0,AF30/AD30) -> 1870.6032 | AF30: =AF16+AF20+AF27+AF22+AF18 -> 140871.32 | AG30: =+AG16+AG18+AG20 -> 93.409011 | AH30: =IF(AG30<=0,0,AI30/AG30) -> 1857.7372 | AI30: =AI16+AI20+AI27+AI22+AI18 -> 173529.4 | AJ30: =+AJ16+AJ18+AJ20 -> 54.28499 | AK30: =IF(AJ30<=0,0,AL30/AJ30) -> 1896.3157 | AL30: =AL16+AL20+AL27+AL22+AL18 -> 102941.48 | AM30: =+AM16+AM18+AM20 -> 31.779223 | AN30: =IF(AM30<=0,0,AO30/AM30) -> 1961.5447 | AO30: =AO16+AO20+AO27+AO22+AO18 -> 62336.367
A31: =+$C$4&B31 -> Véhicules neufs
A32: =+$C$4&B32 -> Véhicules neufs
A33: =+$C$4&B33 -> Véhicules neufsDEPENSES | B33: DEPENSES
A34: =+$C$4&B34 -> Véhicules neufsComm. vendeurs | B34: Comm. vendeurs | C34: =E34/(E16+E18) -> 0.39740476 | D34: =IF(E34=0,0,E34/C$27) -> 379.20727 | E34: =+SUM(H34,K34,N34,Q34,T34,W34,Z34,AC34,AF34,AI34,AL34,AO34) -> 297298.5 | F34: =H34/(H16+H18) -> 0.40539344 | G34: =IF(H34=0,0,H34/F$27) -> 386.83015 | H34: 23628.508 | I34: =K34/(K16+K18) -> 0.44880474 | J34: =IF(K34=0,0,K34/I$27) -> 428.25361 | K34: 18009.481 | L34: =N34/(N16+N18) -> 0.40432916 | M34: =IF(N34=0,0,N34/L$27) -> 385.8146 | N34: 24664.466 | O34: =Q34/(Q16+Q18) -> 0.39047512 | P34: =IF(Q34=0,0,Q34/O$27) -> 372.59495 | Q34: 26383.101 | R34: =T34/(T16+T18) -> 0.36587948 | S34: =IF(T34=0,0,T34/R$27) -> 349.12556 | T34: 32303.913 | U34: =W34/(W16+W18) -> 0.39855056 | V34: =IF(W34=0,0,W34/U$27) -> 380.30061 | W34: 24791.744 | X34: =Z34/(Z16+Z18) -> 0.40271347 | Y34: =IF(Z34=0,0,Z34/X$27) -> 384.27289 | Z34: 24940.62 | AA34: =AC34/(AC16+AC18) -> 0.39331691 | AB34: =IF(AC34=0,0,AC34/AA$27) -> 375.3066 | AC34: 25792.732 | AD34: =AF34/(AF16+AF18) -> 0.38487837 | AE34: =IF(AF34=0,0,AF34/AD$27) -> 367.25447 | AF34: 27657.187 | AG34: =AI34/(AI16+AI18) -> 0.36780834 | AH34: =IF(AI34=0,0,AI34/AG$27) -> 350.9661 | AI34: 32783.396 | AJ34: =AL34/(AL16+AL18) -> 0.41899244 | AK34: =IF(AL34=0,0,AL34/AJ$27) -> 399.80644 | AL34: 21703.488 | AM34: =AO34/(AO16+AO18) -> 0.482781 | AN34: =IF(AO34=0,0,AO34/AM$27) -> 460.67406 | AO34: 14639.864
A35: =+$C$4&B35 -> Véhicules neufsComm. F&I | B35: Comm. F&I | C35: =E35/E27 -> 0.3 | D35: =IF(E35=0,0,E35/C$27) -> 255 | E35: =+SUM(H35,K35,N35,Q35,T35,W35,Z35,AC35,AF35,AI35,AL35,AO35) -> 199920 | F35: =H35/H27 -> 0.3 | G35: =IF(H35=0,0,H35/F$27) -> 255 | H35: 15576.008 | I35: =K35/K27 -> 0.3 | J35: =IF(K35=0,0,K35/I$27) -> 255 | K35: 10723.593 | L35: =N35/N27 -> 0.3 | M35: =IF(N35=0,0,N35/L$27) -> 255 | N35: 16301.713 | O35: =Q35/Q27 -> 0.3 | P35: =IF(Q35=0,0,Q35/O$27) -> 255 | Q35: 18056.312 | R35: =T35/T27 -> 0.3 | S35: =IF(T35=0,0,T35/R$27) -> 255 | T35: 23594.657 | U35: =W35/W27 -> 0.3 | V35: =IF(W35=0,0,W35/U$27) -> 255 | W35: 16623.415 | X35: =Z35/Z27 -> 0.3 | Y35: =IF(Z35=0,0,Z35/X$27) -> 255 | Z35: 16550.369 | AA35: =AC35/AC27 -> 0.3 | AB35: =IF(AC35=0,0,AC35/AA$27) -> 255 | AC35: 17524.729 | AD35: =AF35/AF27 -> 0.3 | AE35: =IF(AF35=0,0,AF35/AD$27) -> 255 | AF35: 19203.531 | AG35: =AI35/AI27 -> 0.3 | AH35: =IF(AI35=0,0,AI35/AG$27) -> 255 | AI35: 23819.298 | AJ35: =AL35/AL27 -> 0.3 | AK35: =IF(AL35=0,0,AL35/AJ$27) -> 255 | AL35: 13842.672 | AM35: =AO35/AO27 -> 0.3 | AN35: =IF(AO35=0,0,AO35/AM$27) -> 255 | AO35: 8103.702
A36: =+$C$4&B36 -> Véhicules neufsFrais de livraison | B36: Frais de livraison | D36: =IF(E36=0,0,E36/C$27) -> 197 | E36: =+SUM(H36,K36,N36,Q36,T36,W36,Z36,AC36,AF36,AI36,AL36,AO36) -> 154448 | G36: =IF(H36=0,0,H36/F$27) -> 197 | H36: 12033.23 | J36: =IF(K36=0,0,K36/I$27) -> 197 | K36: 8284.5015 | M36: =IF(N36=0,0,N36/L$27) -> 197 | N36: 12593.872 | P36: =IF(Q36=0,0,Q36/O$27) -> 197 | Q36: 13949.386 | S36: =IF(T36=0,0,T36/R$27) -> 197 | T36: 18228.029 | V36: =IF(W36=0,0,W36/U$27) -> 197 | W36: 12842.403 | Y36: =IF(Z36=0,0,Z36/X$27) -> 197 | Z36: 12785.971 | AB36: =IF(AC36=0,0,AC36/AA$27) -> 197 | AC36: 13538.712 | AE36: =IF(AF36=0,0,AF36/AD$27) -> 197 | AF36: 14835.669 | AH36: =IF(AI36=0,0,AI36/AG$27) -> 197 | AI36: 18401.575 | AK36: =IF(AL36=0,0,AL36/AJ$27) -> 197 | AL36: 10694.143 | AN36: =IF(AO36=0,0,AO36/AM$27) -> 197 | AO36: 6260.507
A37: =+$C$4&B37 -> Véhicules neufsService gratuit 1 | B37: Service gratuit 1 | D37: =IF(E37=0,0,E37/C$27) -> 6 | E37: =+SUM(H37,K37,N37,Q37,T37,W37,Z37,AC37,AF37,AI37,AL37,AO37) -> 4704 | G37: =IF(H37=0,0,H37/F$27) -> 6 | H37: 366.49431 | J37: =IF(K37=0,0,K37/I$27) -> 6 | K37: 252.31984 | M37: =IF(N37=0,0,N37/L$27) -> 6 | N37: 383.56972 | P37: =IF(Q37=0,0,Q37/O$27) -> 6 | Q37: 424.85441 | S37: =IF(T37=0,0,T37/R$27) -> 6 | T37: 555.1684 | V37: =IF(W37=0,0,W37/U$27) -> 6 | W37: 391.13917 | Y37: =IF(Z37=0,0,Z37/X$27) -> 6 | Z37: 389.42044 | AB37: =IF(AC37=0,0,AC37/AA$27) -> 6 | AC37: 412.34657 | AE37: =IF(AF37=0,0,AF37/AD$27) -> 6 | AF37: 451.84779 | AH37: =IF(AI37=0,0,AI37/AG$27) -> 6 | AI37: 560.45407 | AK37: =IF(AL37=0,0,AL37/AJ$27) -> 6 | AL37: 325.70994 | AN37: =IF(AO37=0,0,AO37/AM$27) -> 6 | AO37: 190.67534
A38: =+$C$4&B38 -> Véhicules neufsEntretien stock | B38: Entretien stock | D38: =IF(E38=0,0,E38/C$27) -> 34 | E38: =+SUM(H38,K38,N38,Q38,T38,W38,Z38,AC38,AF38,AI38,AL38,AO38) -> 26656 | G38: =IF(H38=0,0,H38/F$27) -> 34 | H38: 2076.8011 | J38: =IF(K38=0,0,K38/I$27) -> 34 | K38: 1429.8124 | M38: =IF(N38=0,0,N38/L$27) -> 34 | N38: 2173.5617 | P38: =IF(Q38=0,0,Q38/O$27) -> 34 | Q38: 2407.5083 | S38: =IF(T38=0,0,T38/R$27) -> 34 | T38: 3145.9543 | V38: =IF(W38=0,0,W38/U$27) -> 34 | W38: 2216.4553 | Y38: =IF(Z38=0,0,Z38/X$27) -> 34 | Z38: 2206.7158 | AB38: =IF(AC38=0,0,AC38/AA$27) -> 34 | AC38: 2336.6306 | AE38: =IF(AF38=0,0,AF38/AD$27) -> 34 | AF38: 2560.4708 | AH38: =IF(AI38=0,0,AI38/AG$27) -> 34 | AI38: 3175.9064 | AK38: =IF(AL38=0,0,AL38/AJ$27) -> 34 | AL38: 1845.6897 | AN38: =IF(AO38=0,0,AO38/AM$27) -> 34 | AO38: 1080.4936
A39: =+$C$4&B39 -> Véhicules neufsPublicité 1 | B39: Publicité 1 | D39: =IF(E39=0,0,E39/C$27) -> 180.66964 | E39: =+SUM(H39,K39,N39,Q39,T39,W39,Z39,AC39,AF39,AI39,AL39,AO39) -> 141645 | G39: =IF(H39=0,0,H39/F$27) -> 180.66964 | H39: 11035.733 | J39: =IF(K39=0,0,K39/I$27) -> 180.66964 | K39: 7597.756 | M39: =IF(N39=0,0,N39/L$27) -> 180.66964 | N39: 11549.901 | P39: =IF(Q39=0,0,Q39/O$27) -> 180.66964 | Q39: 12793.049 | S39: =IF(T39=0,0,T39/R$27) -> 180.66964 | T39: 16717.013 | V39: =IF(W39=0,0,W39/U$27) -> 180.66964 | W39: 11777.829 | Y39: =IF(Z39=0,0,Z39/X$27) -> 180.66964 | Z39: 11726.075 | AB39: =IF(AC39=0,0,AC39/AA$27) -> 180.66964 | AC39: 12416.418 | AE39: =IF(AF39=0,0,AF39/AD$27) -> 180.66964 | AF39: 13605.863 | AH39: =IF(AI39=0,0,AI39/AG$27) -> 180.66964 | AI39: 16876.173 | AK39: =IF(AL39=0,0,AL39/AJ$27) -> 180.66964 | AL39: 9807.6498 | AN39: =IF(AO39=0,0,AO39/AM$27) -> 180.66964 | AO39: 5741.5409
A40: =+$C$4&B40 -> Véhicules neufsIntérêt de gros | B40: Intérêt de gros | D40: =IF(E40=0,0,E40/C$27) -> 222.74973 | E40: =+SUM(H40,K40,N40,Q40,T40,W40,Z40,AC40,AF40,AI40,AL40,AO40) -> 174635.78 | G40: =IF(H40=0,0,H40/F$27) -> 226.36716 | H40: 13827.046 | J40: =IF(K40=0,0,K40/I$27) -> 330.58249 | K40: 13902.087 | M40: =IF(N40=0,0,N40/L$27) -> 229.32443 | N40: 14660.318 | P40: =IF(Q40=0,0,Q40/O$27) -> 217.69014 | Q40: 15414.436 | S40: =IF(T40=0,0,T40/R$27) -> 164.99068 | T40: 15266.269 | V40: =IF(W40=0,0,W40/U$27) -> 223.00803 | W40: 14537.863 | Y40: =IF(Z40=0,0,Z40/X$27) -> 225.42826 | Z40: 14631.062 | AB40: =IF(AC40=0,0,AC40/AA$27) -> 216.88662 | AC40: 14905.409 | AE40: =IF(AF40=0,0,AF40/AD$27) -> 206.569 | AF40: 15556.291 | AH40: =IF(AI40=0,0,AI40/AG$27) -> 160.60504 | AI40: 15001.958 | AK40: =IF(AL40=0,0,AL40/AJ$27) -> 246.41998 | AL40: 13376.906 | AN40: =IF(AO40=0,0,AO40/AM$27) -> 426.57241 | AO40: 13556.14
A41: =+$C$4&B41 -> Véhicules neufs[...] | B41: [...] | D41: =IF(E41=0,0,E41/C$27) -> 0 | E41: =+SUM(H41,K41,N41,Q41,T41,W41,Z41,AC41,AF41,AI41,AL41,AO41) -> 0 | G41: =IF(H41=0,0,H41/F$27) -> 0 | J41: =IF(K41=0,0,K41/I$27) -> 0 | M41: =IF(N41=0,0,N41/L$27) -> 0 | P41: =IF(Q41=0,0,Q41/O$27) -> 0 | S41: =IF(T41=0,0,T41/R$27) -> 0 | V41: =IF(W41=0,0,W41/U$27) -> 0 | Y41: =IF(Z41=0,0,Z41/X$27) -> 0 | AB41: =IF(AC41=0,0,AC41/AA$27) -> 0 | AE41: =IF(AF41=0,0,AF41/AD$27) -> 0 | AH41: =IF(AI41=0,0,AI41/AG$27) -> 0 | AK41: =IF(AL41=0,0,AL41/AJ$27) -> 0 | AN41: =IF(AO41=0,0,AO41/AM$27) -> 0
...

Sheet 2pager
B1: =Parametres!$B$1&" "&"2 pager"&" "&Parametres!$B$3&" "&Parametres!$B$4 -> Volks 2 pager Janvier 2021
B3: New | C3: Actual | D3: Forecast | E3: Budget | F3: 2019 | G3: ▲ Forecast | H3: ▲ Budget | I3: ▲2019 | J3: % ▲ Forecast | K3: % ▲ Budget | L3: % ▲ 2019 | M3: Commentaires
B4: Units | C4: =+Print_Mois!$J$13+Print_Mois!$J$15 -> 24 | G4: =+$C4-D4 -> 24 | H4: =+$C4-E4 -> 24 | I4: =+$C4-F4 -> 24 | J4: =+G4/$C4 -> 1 | K4: =+H4/$C4 -> 1 | L4: =+I4/$C4 -> 1
B5: Front Margin | C5: =+Print_Mois!$L$13+Print_Mois!$L$15 -> 29294.35 | G5: =+$C5-D5 -> 29294.35 | H5: =+$C5-E5 -> 29294.35 | I5: =+$C5-F5 -> 29294.35 | J5: =+G5/$C5 -> 1 | K5: =+H5/$C5 -> 1 | L5: =+I5/$C5 -> 1
B6: Front margin / unit | C6: =+C5/C4 -> 1220.5979 | G6: =+$C6-D6 -> 1220.5979 | H6: =+$C6-E6 -> 1220.5979 | I6: =+$C6-F6 -> 1220.5979 | J6: =+G6/$C6 -> 1 | K6: =+H6/$C6 -> 1 | L6: =+I6/$C6 -> 1
B7: $ Salaires et commission | C7: =+Print_Mois!$L$31 -> 19537.41 | G7: =+$C7-D7 -> 19537.41 | H7: =+$C7-E7 -> 19537.41 | I7: =+$C7-F7 -> 19537.41 | J7: =+G7/$C7 -> 1 | K7: =+H7/$C7 -> 1 | L7: =+I7/$C7 -> 1
B8: % Salaires et commission | C8: =+C7/C5 -> 0.66693441 | G8: =+$C8-D8 -> 0.66693441 | H8: =+$C8-E8 -> 0.66693441 | I8: =+$C8-F8 -> 0.66693441 | J8: =+G8/$C8 -> 1 | K8: =+H8/$C8 -> 1 | L8: =+I8/$C8 -> 1
B9: Back Margin | C9: =+Print_Mois!$L$24 -> 16592.42 | G9: =+$C9-D9 -> 16592.42 | H9: =+$C9-E9 -> 16592.42 | I9: =+$C9-F9 -> 16592.42 | J9: =+G9/$C9 -> 1 | K9: =+H9/$C9 -> 1 | L9: =+I9/$C9 -> 1
B10: Back Margin / unit | C10: =+C9/C4 -> 691.35083 | G10: =+$C10-D10 -> 691.35083 | H10: =+$C10-E10 -> 691.35083 | I10: =+$C10-F10 -> 691.35083 | J10: =+G10/$C10 -> 1 | K10: =+H10/$C10 -> 1 | L10: =+I10/$C10 -> 1
B11: $ commission FI | C11: =+Print_Mois!$L$32 -> 4892.97 | G11: =+$C11-D11 -> 4892.97 | H11: =+$C11-E11 -> 4892.97 | I11: =+$C11-F11 -> 4892.97 | J11: =+G11/$C11 -> 1 | K11: =+H11/$C11 -> 1 | L11: =+I11/$C11 -> 1
B12: % commission FI | C12: =+C11/C9 -> 0.29489188 | G12: =+$C12-D12 -> 0.29489188 | H12: =+$C12-E12 -> 0.29489188 | I12: =+$C12-F12 -> 0.29489188 | J12: =+G12/$C12 -> 1 | K12: =+H12/$C12 -> 1 | L12: =+I12/$C12 -> 1
B13: Variable fees | C13: =+Print_Mois!$L$41-C7-C11 -> 24307.7 | G13: =+$C13-D13 -> 24307.7 | H13: =+$C13-E13 -> 24307.7 | I13: =+$C13-F13 -> 24307.7 | J13: =+G13/$C13 -> 1 | K13: =+H13/$C13 -> 1 | L13: =+I13/$C13 -> 1
B14: Variable fees / units | C14: =+C13/C4 -> 1012.8208 | G14: =+$C14-D14 -> 1012.8208 | H14: =+$C14-E14 -> 1012.8208 | J14: =+G14/$C14 -> 1 | K14: =+H14/$C14 -> 1 | L14: =+I14/$C14 -> 0
B15: Other Revenues | C15: =+Print_Mois!$L$83 -> 40102 | G15: =+$C15-D15 -> 40102 | H15: =+$C15-E15 -> 40102 | I15: =+$C15-F15 -> 40102 | J15: =+G15/$C15 -> 1 | K15: =+H15/$C15 -> 1 | L15: =+I15/$C15 -> 1
B16: Inventory
B17: Units | G17: =+$C17-D17 -> 0 | H17: =+$C17-E17 -> 0 | I17: =+$C17-F17 -> 0
B18: $ | G18: =+$C18-D18 -> 0 | H18: =+$C18-E18 -> 0 | I18: =+$C18-F18 -> 0
B20: Used | C20: Actual | D20: Forecast | E20: Budget | F20: 2019 | G20: ▲ Forecast | H20: ▲ Budget | I20: ▲2019 | J20: % ▲ Forecast | K20: % ▲ Budget | L20: % ▲ 2019 | M20: Commentaires
B21: Units | C21: =+Print_Mois!$J$96 -> 15 | G21: =+$C21-D21 -> 15 | H21: =+$C21-E21 -> 15 | I21: =+$C21-F21 -> 15 | J21: =+G21/$C21 -> 1 | K21: =+H21/$C21 -> 1 | L21: =+I21/$C21 -> 1
B22: Front Margin | C22: =+Print_Mois!$L$96 -> 15381.96 | G22: =+$C22-D22 -> 15381.96 | H22: =+$C22-E22 -> 15381.96 | I22: =+$C22-F22 -> 15381.96 | J22: =+G22/$C22 -> 1 | K22: =+H22/$C22 -> 1 | L22: =+I22/$C22 -> 1
B23: Front margin / unit | C23: =+C22/C21 -> 1025.464 | G23: =+$C23-D23 -> 1025.464 | H23: =+$C23-E23 -> 1025.464 | I23: =+$C23-F23 -> 1025.464 | J23: =+G23/$C23 -> 1 | K23: =+H23/$C23 -> 1 | L23: =+I23/$C23 -> 1
B24: $ Salaires et commission | C24: =+Print_Mois!$L$111 -> 7775.77 | G24: =+$C24-D24 -> 7775.77 | H24: =+$C24-E24 -> 7775.77 | I24: =+$C24-F24 -> 7775.77 | J24: =+G24/$C24 -> 1 | K24: =+H24/$C24 -> 1 | L24: =+I24/$C24 -> 1
B25: % Salaires et commission | C25: =+C24/C22 -> 0.5055123 | G25: =+$C25-D25 -> 0.5055123 | H25: =+$C25-E25 -> 0.5055123 | I25: =+$C25-F25 -> 0.5055123 | J25: =+G25/$C25 -> 1 | K25: =+H25/$C25 -> 1 | L25: =+I25/$C25 -> 1
B26: Back Margin | C26: =+Print_Mois!$L$104 -> 25575.14 | G26: =+$C26-D26 -> 25575.14 | H26: =+$C26-E26 -> 25575.14 | I26: =+$C26-F26 -> 25575.14 | J26: =+G26/$C26 -> 1 | K26: =+H26/$C26 -> 1 | L26: =+I26/$C26 -> 1
B27: Back Margin / unit | C27: =+C26/C21 -> 1705.0093 | G27: =+$C27-D27 -> 1705.0093 | H27: =+$C27-E27 -> 1705.0093 | I27: =+$C27-F27 -> 1705.0093 | J27: =+G27/$C27 -> 1 | K27: =+H27/$C27 -> 1 | L27: =+I27/$C27 -> 1
B28: $ commission FI | C28: =+Print_Mois!$L$112 -> 7393.7 | G28: =+$C28-D28 -> 7393.7 | H28: =+$C28-E28 -> 7393.7 | I28: =+$C28-F28 -> 7393.7 | J28: =+G28/$C28 -> 1 | K28: =+H28/$C28 -> 1 | L28: =+I28/$C28 -> 1
B29: % commission FI | C29: =+C28/C26 -> 0.28909715 | G29: =+$C29-D29 -> 0.28909715 | H29: =+$C29-E29 -> 0.28909715 | I29: =+$C29-F29 -> 0.28909715 | J29: =+G29/$C29 -> 1 | K29: =+H29/$C29 -> 1 | L29: =+I29/$C29 -> 1
B30: Variable fees | C30: =+Print_Mois!$L$121-C24-C28 -> 7844.01 | G30: =+$C30-D30 -> 7844.01 | H30: =+$C30-E30 -> 7844.01 | I30: =+$C30-F30 -> 7844.01 | J30: =+G30/$C30 -> 1 | K30: =+H30/$C30 -> 1 | L30: =+I30/$C30 -> 1
B31: Variable fees / units | C31: =+C30/C21 -> 522.934 | G31: =+$C31-D31 -> 522.934 | H31: =+$C31-E31 -> 522.934 | J31: =+G31/$C31 -> 1 | K31: =+H31/$C31 -> 1 | L31: =+I31/$C31 -> 0
B32: Other Revenues | C32: =+Print_Mois!$L$162 -> 5235 | G32: =+$C32-D32 -> 5235 | H32: =+$C32-E32 -> 5235 | I32: =+$C32-F32 -> 5235
B33: Inventory
B34: Units | G34: =+$C34-D34 -> 0 | H34: =+$C34-E34 -> 0 | I34: =+$C34-F34 -> 0
B35: $ | G35: =+$C35-D35 -> 0 | H35: =+$C35-E35 -> 0 | I35: =+$C35-F35 -> 0
B37: Service | C37: Actual | D37: Forecast | E37: Budget | F37: 2019 | G37: ▲ Forecast | H37: ▲ Budget | I37: ▲2019 | J37: % ▲ Forecast | K37: % ▲ Budget | L37: % ▲ 2019 | M37: Commentaires
B38: Revenus | C38: =+Print_Mois!$K$193 -> 158971.35 | G38: =+$C38-D38 -> 158971.35 | H38: =+$C38-E38 -> 158971.35 | I38: =+$C38-F38 -> 158971.35 | J38: =+G38/$C38 -> 1 | K38: =+H38/$C38 -> 1 | L38: =+I38/$C38 -> 1
B39: Gross margin | C39: =+Print_Mois!$L$193 -> 108076.14 | G39: =+$C39-D39 -> 108076.14 | H39: =+$C39-E39 -> 108076.14 | I39: =+$C39-F39 -> 108076.14 | J39: =+G39/$C39 -> 1 | K39: =+H39/$C39 -> 1 | L39: =+I39/$C39 -> 1
B40: $ Revenus / #WO client | C40: =+Print_Mois!$K$171/Print_Mois!$J$171 -> 239.94537 | G40: =+$C40-D40 -> 239.94537 | H40: =+$C40-E40 -> 239.94537 | I40: =+$C40-F40 -> 239.94537 | J40: =+G40/$C40 -> 1 | K40: =+H40/$C40 -> 1 | L40: =+I40/$C40 -> 1
B41: $ Revenus / #WO garantie | C41: =+Print_Mois!$K$174/Print_Mois!$J$174 -> 233.67803 | G41: =+$C41-D41 -> 233.67803 | H41: =+$C41-E41 -> 233.67803 | I41: =+$C41-F41 -> 233.67803 | J41: =+G41/$C41 -> 1 | K41: =+H41/$C41 -> 1 | L41: =+I41/$C41 -> 1
B42: Lost time | C42: =+Print_Mois!$L$183 -> -868.59 | G42: =+$C42-D42 -> -868.59 | H42: =+$C42-E42 -> -868.59 | I42: =+$C42-F42 -> -868.59 | J42: =+G42/$C42 -> 1 | K42: =+H42/$C42 -> 1 | L42: =+I42/$C42 -> 1
B43: Total salaries | C43: =+Print_Mois!$L$209 -> 83100.21 | G43: =+$C43-D43 -> 83100.21 | H43: =+$C43-E43 -> 83100.21 | I43: =+$C43-F43 -> 83100.21 | J43: =+G43/$C43 -> 1 | K43: =+H43/$C43 -> 1 | L43: =+I43/$C43 -> 1
...

Sheet Budget révisé
B1: ="Budget 2021 Mensuel Révisé"&" "&Parametres!$B$1 -> Budget 2021 Mensuel Révisé Volks
B2: Mois | F2: =+IF(Parametres!$B$3=F$6,"X","") -> X | G2: =+IF(Parametres!$B$3=F$6,"O","") -> O | H2: =+IF(Parametres!$B$3=F$6,"U","") -> U | I2: =+IF(Parametres!$B$3=I$6,"X","") | J2: =+IF(Parametres!$B$3=I$6,"O","") | K2: =+IF(Parametres!$B$3=I$6,"U","") | L2: =+IF(Parametres!$B$3=L$6,"X","") | M2: =+IF(Parametres!$B$3=L$6,"O","") | N2: =+IF(Parametres!$B$3=L$6,"U","") | O2: =+IF(Parametres!$B$3=O$6,"X","") | P2: =+IF(Parametres!$B$3=O$6,"O","") | Q2: =+IF(Parametres!$B$3=O$6,"U","") | R2: =+IF(Parametres!$B$3=R$6,"X","") | S2: =+IF(Parametres!$B$3=R$6,"O","") | T2: =+IF(Parametres!$B$3=R$6,"U","") | U2: =+IF(Parametres!$B$3=U$6,"X","") | V2: =+IF(Parametres!$B$3=U$6,"O","") | W2: =+IF(Parametres!$B$3=U$6,"U","") | X2: =+IF(Parametres!$B$3=X$6,"X","") | Y2: =+IF(Parametres!$B$3=X$6,"O","") | Z2: =+IF(Parametres!$B$3=X$6,"U","") | AA2: =+IF(Parametres!$B$3=AA$6,"X","") | AB2: =+IF(Parametres!$B$3=AA$6,"O","") | AC2: =+IF(Parametres!$B$3=AA$6,"U","") | AD2: =+IF(Parametres!$B$3=AD$6,"X","") | AE2: =+IF(Parametres!$B$3=AD$6,"O","") | AF2: =+IF(Parametres!$B$3=AD$6,"U","") | AG2: =+IF(Parametres!$B$3=AG$6,"X","") | AH2: =+IF(Parametres!$B$3=AG$6,"O","") | AI2: =+IF(Parametres!$B$3=AG$6,"U","") | AJ2: =+IF(Parametres!$B$3=AJ$6,"X","") | AK2: =+IF(Parametres!$B$3=AJ$6,"O","") | AL2: =+IF(Parametres!$B$3=AJ$6,"U","") | AM2: =+IF(Parametres!$B$3=AM$6,"X","") | AN2: =+IF(Parametres!$B$3=AM$6,"O","") | AO2: =+IF(Parametres!$B$3=AM$6,"U","")
B3: YTD | F3: =+IF(VLOOKUP(F$6,Parametres!$K$3:$N$14,4,0)="X","X","") -> X | G3: =+IF(VLOOKUP(F$6,Parametres!$K$3:$N$14,4,0)="X","O","") -> O | H3: =+IF(VLOOKUP(F$6,Parametres!$K$3:$N$14,4,0)="X","U","") -> U | I3: =+IF(VLOOKUP(I$6,Parametres!$K$3:$N$14,4,0)="X","X","") | J3: =+IF(VLOOKUP(I$6,Parametres!$K$3:$N$14,4,0)="X","O","") | K3: =+IF(VLOOKUP(I$6,Parametres!$K$3:$N$14,4,0)="X","U","") | L3: =+IF(VLOOKUP(L$6,Parametres!$K$3:$N$14,4,0)="X","X","") | M3: =+IF(VLOOKUP(L$6,Parametres!$K$3:$N$14,4,0)="X","O","") | N3: =+IF(VLOOKUP(L$6,Parametres!$K$3:$N$14,4,0)="X","U","") | O3: =+IF(VLOOKUP(O$6,Parametres!$K$3:$N$14,4,0)="X","X","") | P3: =+IF(VLOOKUP(O$6,Parametres!$K$3:$N$14,4,0)="X","O","") | Q3: =+IF(VLOOKUP(O$6,Parametres!$K$3:$N$14,4,0)="X","U","") | R3: =+IF(VLOOKUP(R$6,Parametres!$K$3:$N$14,4,0)="X","X","") | S3: =+IF(VLOOKUP(R$6,Parametres!$K$3:$N$14,4,0)="X","O","") | T3: =+IF(VLOOKUP(R$6,Parametres!$K$3:$N$14,4,0)="X","U","") | U3: =+IF(VLOOKUP(U$6,Parametres!$K$3:$N$14,4,0)="X","X","") | V3: =+IF(VLOOKUP(U$6,Parametres!$K$3:$N$14,4,0)="X","O","") | W3: =+IF(VLOOKUP(U$6,Parametres!$K$3:$N$14,4,0)="X","U","") | X3: =+IF(VLOOKUP(X$6,Parametres!$K$3:$N$14,4,0)="X","X","") | Y3: =+IF(VLOOKUP(X$6,Parametres!$K$3:$N$14,4,0)="X","O","") | Z3: =+IF(VLOOKUP(X$6,Parametres!$K$3:$N$14,4,0)="X","U","") | AA3: =+IF(VLOOKUP(AA$6,Parametres!$K$3:$N$14,4,0)="X","X","") | AB3: =+IF(VLOOKUP(AA$6,Parametres!$K$3:$N$14,4,0)="X","O","") | AC3: =+IF(VLOOKUP(AA$6,Parametres!$K$3:$N$14,4,0)="X","U","") | AD3: =+IF(VLOOKUP(AD$6,Parametres!$K$3:$N$14,4,0)="X","X","") | AE3: =+IF(VLOOKUP(AD$6,Parametres!$K$3:$N$14,4,0)="X","O","") | AF3: =+IF(VLOOKUP(AD$6,Parametres!$K$3:$N$14,4,0)="X","U","") | AG3: =+IF(VLOOKUP(AG$6,Parametres!$K$3:$N$14,4,0)="X","X","") | AH3: =+IF(VLOOKUP(AG$6,Parametres!$K$3:$N$14,4,0)="X","O","") | AI3: =+IF(VLOOKUP(AG$6,Parametres!$K$3:$N$14,4,0)="X","U","") | AJ3: =+IF(VLOOKUP(AJ$6,Parametres!$K$3:$N$14,4,0)="X","X","") | AK3: =+IF(VLOOKUP(AJ$6,Parametres!$K$3:$N$14,4,0)="X","O","") | AL3: =+IF(VLOOKUP(AJ$6,Parametres!$K$3:$N$14,4,0)="X","U","") | AM3: =+IF(VLOOKUP(AM$6,Parametres!$K$3:$N$14,4,0)="X","X","") | AN3: =+IF(VLOOKUP(AM$6,Parametres!$K$3:$N$14,4,0)="X","O","") | AO3: =+IF(VLOOKUP(AM$6,Parametres!$K$3:$N$14,4,0)="X","U","")
B4: Budget 2021 | C4: Véhicules neufs
B6: Mois | C6: TOTAL | F6: Janvier | I6: Février | L6: Mars | O6: Avril | R6: Mai | U6: Juin | X6: Juillet | AA6: Août | AD6: Septembre | AG6: Octobre | AJ6: Novembre | AM6: Décembre
C7: UNITE | D7: $P/UNITE | E7: $PROFITS | F7: UNITE | G7: $P/UNITE | H7: $PROFITS | I7: UNITE | J7: $P/UNITE | K7: $PROFITS | L7: UNITE | M7: $P/UNITE | N7: $PROFITS | O7: UNITE | P7: $P/UNITE | Q7: $PROFITS | R7: UNITE | S7: $P/UNITE | T7: $PROFITS | U7: UNITE | V7: $P/UNITE | W7: $PROFITS | X7: UNITE | Y7: $P/UNITE | Z7: $PROFITS | AA7: UNITE | AB7: $P/UNITE | AC7: $PROFITS | AD7: UNITE | AE7: $P/UNITE | AF7: $PROFITS | AG7: UNITE | AH7: $P/UNITE | AI7: $PROFITS | AJ7: UNITE | AK7: $P/UNITE | AL7: $PROFITS | AM7: UNITE | AN7: $P/UNITE | AO7: $PROFITS
A8: =+$C$4&B8 -> Véhicules neufsVentes nettes | B8: Ventes nettes | E8: =+SUM(H8,K8,N8,Q8,T8,W8,Z8,AC8,AF8,AI8,AL8,AO8) -> 9553310.1 | H8: 1882577.9 | K8: 446219.11 | N8: 678330.08 | Q8: 751340.66 | T8: 981796.55 | W8: 691716.4 | Z8: 688676.89 | AC8: 729220.97 | AF8: 799077.54 | AI8: 991144.07 | AL8: 576007.02 | AO8: 337202.89
A9: =+$C$4&B9 -> Véhicules neufsAutos détail | B9: Autos détail | C9: =+SUM(F9,I9,L9,O9,R9,U9,X9,AA9,AD9,AG9,AJ9,AM9) -> 303 | D9: =IF(C9=0,0,E9/C9) -> 604.29043 | E9: =+SUM(H9,K9,N9,Q9,T9,W9,Z9,AC9,AF9,AI9,AL9,AO9) -> 183100 | F9: 23.607096 | G9: =IF(F9=0,0,H9/F9) -> 604.29043 | H9: 14265.542 | I9: 16.252745 | J9: =IF(I9=0,0,K9/I9) -> 604.29043 | K9: 9821.3783 | L9: 24.706978 | M9: =IF(L9=0,0,N9/L9) -> 604.29043 | N9: 14930.19 | O9: 27.36626 | P9: =IF(O9=0,0,Q9/O9) -> 604.29043 | Q9: 16537.169 | R9: 35.76021 | S9: =IF(R9=0,0,T9/R9) -> 604.29043 | T9: 21609.552 | U9: 25.194551 | V9: =IF(U9=0,0,W9/U9) -> 604.29043 | W9: 15224.826 | X9: 25.083842 | Y9: =IF(X9=0,0,Z9/X9) -> 604.29043 | Z9: 15157.926 | AA9: 26.560589 | AB9: =IF(AA9=0,0,AC9/AA9) -> 604.29043 | AC9: 16050.31 | AD9: 29.104991 | AE9: =IF(AD9=0,0,AF9/AD9) -> 604.29043 | AF9: 17587.868 | AG9: 36.100676 | AH9: =IF(AG9=0,0,AI9/AG9) -> 604.29043 | AI9: 21815.293 | AJ9: 20.980041 | AK9: =IF(AJ9=0,0,AL9/AJ9) -> 604.29043 | AL9: 12678.038 | AM9: 12.282021 | AN9: =IF(AM9=0,0,AO9/AM9) -> 604.29043 | AO9: 7421.9079
A10: =+$C$4&B10 -> Véhicules neufsCamions détail | B10: Camions détail | C10: =+SUM(F10,I10,L10,O10,R10,U10,X10,AA10,AD10,AG10,AJ10,AM10) -> 407 | D10: =IF(C10=0,0,E10/C10) -> 1315.4791 | E10: =+SUM(H10,K10,N10,Q10,T10,W10,Z10,AC10,AF10,AI10,AL10,AO10) -> 535400 | F10: 31.709861 | G10: =IF(F10=0,0,H10/F10) -> 1315.4791 | H10: 41713.66 | I10: 21.831245 | J10: =IF(I10=0,0,K10/I10) -> 1315.4791 | K10: 28718.547 | L10: 33.187261 | M10: =IF(L10=0,0,N10/L10) -> 1315.4791 | N10: 43657.149 | O10: 36.759299 | P10: =IF(O10=0,0,Q10/O10) -> 1315.4791 | Q10: 48356.09 | R10: 48.034341 | S10: =IF(R10=0,0,T10/R10) -> 1315.4791 | T10: 63188.172 | U10: 33.842186 | V10: =IF(U10=0,0,W10/U10) -> 1315.4791 | W10: 44518.688 | X10: 33.693478 | Y10: =IF(X10=0,0,Z10/X10) -> 1315.4791 | Z10: 44323.067 | AA10: 35.677095 | AB10: =IF(AA10=0,0,AC10/AA10) -> 1315.4791 | AC10: 46932.473 | AD10: 39.094824 | AE10: =IF(AD10=0,0,AF10/AD10) -> 1315.4791 | AF10: 51428.424 | AG10: 48.491668 | AH10: =IF(AG10=0,0,AI10/AG10) -> 1315.4791 | AI10: 63789.776 | AJ10: 28.181111 | AK10: =IF(AJ10=0,0,AL10/AJ10) -> 1315.4791 | AL10: 37071.663 | AM10: 16.497633 | AN10: =IF(AM10=0,0,AO10/AM10) -> 1315.4791 | AO10: 21702.291
A11: =+$C$4&B11 -> Véhicules neufsSprinter | B11: Sprinter | C11: =+SUM(F11,I11,L11,O11,R11,U11,X11,AA11,AD11,AG11,AJ11,AM11) -> 0 | D11: =IF(C11=0,0,E11/C11) -> 0 | E11: =+SUM(H11,K11,N11,Q11,T11,W11,Z11,AC11,AF11,AI11,AL11,AO11) -> 0 | G11: =IF(F11=0,0,H11/F11) -> 0 | J11: =IF(I11=0,0,K11/I11) -> 0 | M11: =IF(L11=0,0,N11/L11) -> 0 | P11: =IF(O11=0,0,Q11/O11) -> 0 | S11: =IF(R11=0,0,T11/R11) -> 0 | V11: =IF(U11=0,0,W11/U11) -> 0 | Y11: =IF(X11=0,0,Z11/X11) -> 0 | AB11: =IF(AA11=0,0,AC11/AA11) -> 0 | AE11: =IF(AD11=0,0,AF11/AD11) -> 0 | AH11: =IF(AG11=0,0,AI11/AG11) -> 0 | AK11: =IF(AJ11=0,0,AL11/AJ11) -> 0 | AN11: =IF(AM11=0,0,AO11/AM11) -> 0
A12: =+$C$4&B12 -> Véhicules neufsMoto détail | B12: Moto détail | C12: =+SUM(F12,I12,L12,O12,R12,U12,X12,AA12,AD12,AG12,AJ12,AM12) -> 0 | D12: =IF(C12=0,0,E12/C12) -> 0 | E12: =+SUM(H12,K12,N12,Q12,T12,W12,Z12,AC12,AF12,AI12,AL12,AO12) -> 0 | G12: =IF(F12=0,0,H12/F12) -> 0 | J12: =IF(I12=0,0,K12/I12) -> 0 | M12: =IF(L12=0,0,N12/L12) -> 0 | P12: =IF(O12=0,0,Q12/O12) -> 0 | S12: =IF(R12=0,0,T12/R12) -> 0 | V12: =IF(U12=0,0,W12/U12) -> 0 | Y12: =IF(X12=0,0,Z12/X12) -> 0 | AB12: =IF(AA12=0,0,AC12/AA12) -> 0 | AE12: =IF(AD12=0,0,AF12/AD12) -> 0 | AH12: =IF(AG12=0,0,AI12/AG12) -> 0 | AK12: =IF(AJ12=0,0,AL12/AJ12) -> 0 | AN12: =IF(AM12=0,0,AO12/AM12) -> 0
A13: =+$C$4&B13 -> Véhicules neufs[...] | B13: [...] | C13: =+SUM(F13,I13,L13,O13,R13,U13,X13,AA13,AD13,AG13,AJ13,AM13) -> 0 | D13: =IF(C13=0,0,E13/C13) -> 0 | E13: =+SUM(H13,K13,N13,Q13,T13,W13,Z13,AC13,AF13,AI13,AL13,AO13) -> 0 | G13: =IF(F13=0,0,H13/F13) -> 0 | J13: =IF(I13=0,0,K13/I13) -> 0 | M13: =IF(L13=0,0,N13/L13) -> 0 | P13: =IF(O13=0,0,Q13/O13) -> 0 | S13: =IF(R13=0,0,T13/R13) -> 0 | V13: =IF(U13=0,0,W13/U13) -> 0 | Y13: =IF(X13=0,0,Z13/X13) -> 0 | AB13: =IF(AA13=0,0,AC13/AA13) -> 0 | AE13: =IF(AD13=0,0,AF13/AD13) -> 0 | AH13: =IF(AG13=0,0,AI13/AG13) -> 0 | AK13: =IF(AJ13=0,0,AL13/AJ13) -> 0 | AN13: =IF(AM13=0,0,AO13/AM13) -> 0
A14: =+$C$4&B14 -> Véhicules neufs[...] | B14: [...] | C14: =+SUM(F14,I14,L14,O14,R14,U14,X14,AA14,AD14,AG14,AJ14,AM14) -> 0 | D14: =IF(C14=0,0,E14/C14) -> 0 | E14: =+SUM(H14,K14,N14,Q14,T14,W14,Z14,AC14,AF14,AI14,AL14,AO14) -> 0 | G14: =IF(F14=0,0,H14/F14) -> 0 | J14: =IF(I14=0,0,K14/I14) -> 0 | M14: =IF(L14=0,0,N14/L14) -> 0 | P14: =IF(O14=0,0,Q14/O14) -> 0 | S14: =IF(R14=0,0,T14/R14) -> 0 | V14: =IF(U14=0,0,W14/U14) -> 0 | Y14: =IF(X14=0,0,Z14/X14) -> 0 | AB14: =IF(AA14=0,0,AC14/AA14) -> 0 | AE14: =IF(AD14=0,0,AF14/AD14) -> 0 | AH14: =IF(AG14=0,0,AI14/AG14) -> 0 | AK14: =IF(AJ14=0,0,AL14/AJ14) -> 0 | AN14: =IF(AM14=0,0,AO14/AM14) -> 0
A15: =+$C$4&B15 -> Véhicules neufs[...] | B15: [...] | C15: =+SUM(F15,I15,L15,O15,R15,U15,X15,AA15,AD15,AG15,AJ15,AM15) -> 0 | D15: =IF(C15=0,0,E15/C15) -> 0 | E15: =+SUM(H15,K15,N15,Q15,T15,W15,Z15,AC15,AF15,AI15,AL15,AO15) -> 0 | G15: =IF(F15=0,0,H15/F15) -> 0 | J15: =IF(I15=0,0,K15/I15) -> 0 | M15: =IF(L15=0,0,N15/L15) -> 0 | P15: =IF(O15=0,0,Q15/O15) -> 0 | S15: =IF(R15=0,0,T15/R15) -> 0 | V15: =IF(U15=0,0,W15/U15) -> 0 | Y15: =IF(X15=0,0,Z15/X15) -> 0 | AB15: =IF(AA15=0,0,AC15/AA15) -> 0 | AE15: =IF(AD15=0,0,AF15/AD15) -> 0 | AH15: =IF(AG15=0,0,AI15/AG15) -> 0 | AK15: =IF(AJ15=0,0,AL15/AJ15) -> 0 | AN15: =IF(AM15=0,0,AO15/AM15) -> 0
A16: =+$C$4&B16 -> Véhicules neufsTotal Neufs | B16: Total Neufs | C16: =+SUM(C9:C15) -> 710 | D16: =IF(C16<=0,0,E16/C16) -> 1011.9718 | E16: =+SUM(E9:E15) -> 718500 | F16: =+SUM(F9:F15) -> 55.316957 | G16: =IF(F16<=0,0,H16/F16) -> 1011.9718 | H16: =+SUM(H9:H15) -> 55979.202 | I16: =+SUM(I9:I15) -> 38.08399 | J16: =IF(I16<=0,0,K16/I16) -> 1011.9718 | K16: =+SUM(K9:K15) -> 38539.925 | L16: =+SUM(L9:L15) -> 57.894239 | M16: =IF(L16<=0,0,N16/L16) -> 1011.9718 | N16: =+SUM(N9:N15) -> 58587.339 | O16: =+SUM(O9:O15) -> 64.125559 | P16: =IF(O16<=0,0,Q16/O16) -> 1011.9718 | Q16: =+SUM(Q9:Q15) -> 64893.259 | R16: =+SUM(R9:R15) -> 83.79455 | S16: =IF(R16<=0,0,T16/R16) -> 1011.9718 | T16: =+SUM(T9:T15) -> 84797.725 | U16: =+SUM(U9:U15) -> 59.036736 | V16: =IF(U16<=0,0,W16/U16) -> 1011.9718 | W16: =+SUM(W9:W15) -> 59743.514 | X16: =+SUM(X9:X15) -> 58.77732 | Y16: =IF(X16<=0,0,Z16/X16) -> 1011.9718 | Z16: =+SUM(Z9:Z15) -> 59480.992 | AA16: =+SUM(AA9:AA15) -> 62.237684 | AB16: =IF(AA16<=0,0,AC16/AA16) -> 1011.9718 | AC16: =+SUM(AC9:AC15) -> 62982.783 | AD16: =+SUM(AD9:AD15) -> 68.199815 | AE16: =IF(AD16<=0,0,AF16/AD16) -> 1011.9718 | AF16: =+SUM(AF9:AF15) -> 69016.292 | AG16: =+SUM(AG9:AG15) -> 84.592344 | AH16: =IF(AG16<=0,0,AI16/AG16) -> 1011.9718 | AI16: =+SUM(AI9:AI15) -> 85605.069 | AJ16: =+SUM(AJ9:AJ15) -> 49.161152 | AK16: =IF(AJ16<=0,0,AL16/AJ16) -> 1011.9718 | AL16: =+SUM(AL9:AL15) -> 49749.701 | AM16: =+SUM(AM9:AM15) -> 28.779654 | AN16: =IF(AM16<=0,0,AO16/AM16) -> 1011.9718 | AO16: =+SUM(AO9:AO15) -> 29124.199
A17: =+$C$4&B17 -> Véhicules neufs
A18: =+$C$4&B18 -> Véhicules neufsEx-Démos et courtoisies | B18: Ex-Démos et courtoisies | C18: =+SUM(F18,I18,L18,O18,R18,U18,X18,AA18,AD18,AG18,AJ18,AM18) -> 74 | D18: =IF(C18=0,0,E18/C18) -> 400 | E18: =+SUM(H18,K18,N18,Q18,T18,W18,Z18,AC18,AF18,AI18,AL18,AO18) -> 29600 | F18: 5.7654293 | G18: =IF(F18=0,0,H18/F18) -> 400 | H18: 2306.1717 | I18: 3.9693173 | J18: =IF(I18=0,0,K18/I18) -> 400 | K18: 1587.7269 | L18: 6.0340474 | M18: =IF(L18=0,0,N18/L18) -> 400 | N18: 2413.619 | O18: 6.683509 | P18: =IF(O18=0,0,Q18/O18) -> 400 | Q18: 2673.4036 | R18: 8.7335165 | S18: =IF(R18=0,0,T18/R18) -> 400 | T18: 3493.4066 | U18: 6.1531246 | V18: =IF(U18=0,0,W18/U18) -> 400 | W18: 2461.2499 | X18: 6.1260869 | Y18: =IF(X18=0,0,Z18/X18) -> 400 | Z18: 2450.4348 | AA18: 6.4867445 | AB18: =IF(AA18=0,0,AC18/AA18) -> 400 | AC18: 2594.6978 | AD18: 7.1081497 | AE18: =IF(AD18=0,0,AF18/AD18) -> 400 | AF18: 2843.2599 | AG18: 8.8166669 | AH18: =IF(AG18=0,0,AI18/AG18) -> 400 | AI18: 3526.6667 | AJ18: 5.1238383 | AK18: =IF(AJ18=0,0,AL18/AJ18) -> 400 | AL18: 2049.5353 | AM18: 2.9995696 | AN18: =IF(AM18=0,0,AO18/AM18) -> 400 | AO18: 1199.8278
A19: =+$C$4&B19 -> Véhicules neufs
A20: =+$C$4&B20 -> Véhicules neufsFlottes | B20: Flottes | C20: =+SUM(F20,I20,L20,O20,R20,U20,X20,AA20,AD20,AG20,AJ20,AM20) -> 0 | D20: =IF(C20=0,0,E20/C20) -> 0 | E20: =+SUM(H20,K20,N20,Q20,T20,W20,Z20,AC20,AF20,AI20,AL20,AO20) -> 0 | F20: 0 | G20: =IF(F20=0,0,H20/F20) -> 0 | H20: 0 | I20: 0 | J20: =IF(I20=0,0,K20/I20) -> 0 | K20: 0 | L20: 0 | M20: =IF(L20=0,0,N20/L20) -> 0 | N20: 0 | O20: 0 | P20: =IF(O20=0,0,Q20/O20) -> 0 | Q20: 0 | R20: 0 | S20: =IF(R20=0,0,T20/R20) -> 0 | T20: 0 | U20: 0 | V20: =IF(U20=0,0,W20/U20) -> 0 | W20: 0 | X20: 0 | Y20: =IF(X20=0,0,Z20/X20) -> 0 | Z20: 0 | AA20: 0 | AB20: =IF(AA20=0,0,AC20/AA20) -> 0 | AC20: 0 | AD20: 0 | AE20: =IF(AD20=0,0,AF20/AD20) -> 0 | AF20: 0 | AG20: 0 | AH20: =IF(AG20=0,0,AI20/AG20) -> 0 | AI20: 0 | AJ20: 0 | AK20: =IF(AJ20=0,0,AL20/AJ20) -> 0 | AL20: 0 | AM20: 0 | AN20: =IF(AM20=0,0,AO20/AM20) -> 0 | AO20: 0
A21: =+$C$4&B21 -> Véhicules neufs
A22: =+$C$4&B22 -> Véhicules neufsRachat bail | B22: Rachat bail | E22: =+SUM(H22,K22,N22,Q22,T22,W22,Z22,AC22,AF22,AI22,AL22,AO22) -> 60000 | H22: 5000 | K22: 5000 | N22: 5000 | Q22: 5000 | T22: 5000 | W22: 5000 | Z22: 5000 | AC22: 5000 | AF22: 5000 | AI22: 5000 | AL22: 5000 | AO22: 5000
A23: =+$C$4&B23 -> Véhicules neufs
