Workbook
Name _Dates_Conc: [1]Dealers!$BF$37:$KA$63
Name _scen: '[1]Scen & Sens'!$E$26
Name _scen1: '[1]Scen & Sens'!$E$27
Name _scen2: '[1]Scen & Sens'!$E$28
Name _SCenarios: '[1]Scen & Sens'!$J$26:$O$26
Name _Sens1: '[1]Scen & Sens'!$F$9
Name _Sens2: '[1]Scen & Sens'!$F$10
Name _sensRes1: '[1]Scen & Sens'!$E$15
Name _sensRes2: '[1]Scen & Sens'!$E$16
Name _sensRes3: '[1]Scen & Sens'!$E$17
Name _sensRes4: '[1]Scen & Sens'!$E$18
Name _sensRes5: '[1]Scen & Sens'!$E$19
Name _sensRes6: '[1]Scen & Sens'!$E$20
Name _sensRes7: '[1]Scen & Sens'!$E$21
Name DateRange: [1]Volkswagen!$BF$6:$DY$6
Name Monetary_Unit: [1]Parameters!$B$15
Name Months: [1]Parameters!$E$9:$E$20
Name Rng_Dealers_Names: [1]!Tbl_Dealers[Dealer Name]
Name Rng_Dlr_Dates: [1]!Tbl_V_Dlr_Dates[Date]
Name Ticker: #REF!
Name Ticker: #REF!
Name Ticker: #REF!
Name Titre: [1]Front!$A$9

Sheet Paramètre
B3: VOLKS QUARTER | C3: Volks T3 2023
B6: BUDGET | F6: BUDGET RÉVISÉ | J6: ACTUAL | N6: LAST YEAR
B7: Ventes | C7: Profits bruts | D7: BAIIA | E7: EBIT | F7: Ventes | G7: Profits bruts | H7: BAIIA | I7: EBIT | J7: Ventes | K7: Profits bruts | L7: BAIIA | M7: EBIT | N7: Ventes | O7: Profits bruts | P7: BAIIA | Q7: EBIT
A8: CTRL | B8: =+B9-B10 -> #REF! | C8: =+C9-C10 -> #REF! | D8: =+D9-D10 -> #REF! | E8: =+E9-E10 -> #REF! | F8: =+F9-F10 -> #REF! | G8: =+G9-G10 -> #REF! | H8: =+H9-H10 -> #REF! | I8: =+I9-I10 -> #REF! | ... Q8: =+Q9-Q10 -> #REF!
A9: CONSO | B9: =+Conso!$Z$405 -> 14227382 | C9: =+Conso!$Z$406 -> 1964256.6 | D9: =+Conso!$Z$482 -> 516253.45 | E9: =+Conso!$Z$497 -> 500994.61 | F9: =+Conso!$AC$405 -> 0 | G9: =+Conso!$AC$406 -> 0 | H9: =+Conso!$AC$482 -> 0 | I9: =+Conso!$AC$497 -> 0 | J9: =+Conso!$AF$405 -> 14540993 | K9: =+Conso!$AF$406 -> 1891334.5 | L9: =+Conso!$AF$482 -> 537161.11 | M9: =+Conso!$AF$497 -> 524217.61 | N9: =+Conso!$AL$405 -> 16244538 | O9: =+Conso!$AL$406 -> 2131722.3 | P9: =+Conso!$AL$482 -> 790555.84 | Q9: =+Conso!$AL$497 -> 776331.97
A10: TOTAL | B10: =+SUM(B11:B13) -> #REF! | C10: =+SUM(C11:C13) -> #REF! | D10: =+SUM(D11:D13) -> #REF! | E10: =+SUM(E11:E13) -> #REF! | F10: =+SUM(F11:F13) -> #REF! | G10: =+SUM(G11:G13) -> #REF! | H10: =+SUM(H11:H13) -> #REF! | I10: =+SUM(I11:I13) -> #REF! | ... Q10: =+SUM(Q11:Q13) -> #REF!
A11: AUDI 1 | B11: =+#REF! -> #REF! | C11: =+#REF! -> #REF! | D11: =+#REF! -> #REF! | E11: =+#REF! -> #REF! | F11: =+#REF! -> #REF! | G11: =+#REF! -> #REF! | H11: =+#REF! -> #REF! | I11: =+#REF! -> #REF! | ... Q11: =+#REF! -> #REF!
A12: AUDI 2 | B12: =+#REF! -> #REF! | C12: =+#REF! -> #REF! | D12: =+#REF! -> #REF! | E12: =+#REF! -> #REF! | F12: =+#REF! -> #REF! | G12: =+#REF! -> #REF! | H12: =+#REF! -> #REF! | I12: =+#REF! -> #REF! | ... Q12: =+#REF! -> #REF!
A13: AUDI 3 | B13: =+#REF! -> #REF! | C13: =+#REF! -> #REF! | D13: =+#REF! -> #REF! | E13: =+#REF! -> #REF! | F13: =+#REF! -> #REF! | G13: =+#REF! -> #REF! | H13: =+#REF! -> #REF! | I13: =+#REF! -> #REF! | ... Q13: =+#REF! -> #REF!

Sheet Conso
C1: Conso | K1: Véhicules neufs | S1: =CONCATENATE("Réalisé"," ",Paramètre!$C$2," ",Paramètre!$C$3) -> Réalisé Volks T3 2023
D2: X | E2: O | F2: U | G2: X | H2: O | I2: U
D3: BUDGET ORIGINAL | G3: BUDGET REVISE | J3: RÉALISATION | M3: ÉCART réel / Budget | O3: ANNÉE PRÉCÉDENTE | R3: ECART (réel/ Ann.Préc.)
D4: UNITE | E4: $P/UNITÉ | F4: $PROFITS | G4: UNITE | H4: $P/UNITÉ | I4: $PROFITS | J4: UNITE | K4: $P/UNITE | L4: $PROFITS | M4: UNITÉS | N4: $PROFITS | O4: UNITE | P4: $P/UNITE | Q4: $PROFITS | R4: UNITÉS | S4: $PROFITS
A5: =+B5&C5 -> Véhicules neufsVentes nettes | B5: =+$K$1 -> Véhicules neufs | C5: Ventes nettes | F5: =+SUM(START:END!F5) -> 7317453.3 | I5: =+SUM(START:END!I5) -> 0 | L5: =+SUM(START:END!L5) -> 7302296.1 | Q5: =+SUM(START:END!Q5) -> 8779737.5
A6: =+B6&C6 -> Véhicules neufsAutos détail | B6: =+$K$1 -> Véhicules neufs | C6: Autos détail | D6: =+SUM(START:END!D6) -> 31.220571 | E6: =IF(D6=0,0,F6/D6) -> 1988.434 | F6: =+SUM(START:END!F6) -> 62080.046 | G6: =+SUM(START:END!G6) -> 0 | H6: =IF(G6=0,0,I6/G6) -> 0 | I6: =+SUM(START:END!I6) -> 0 | J6: =+SUM(START:END!J6) -> 50 | K6: =IF(J6=0,0,L6/J6) -> 2046.4024 | L6: =+SUM(START:END!L6) -> 102320.12 | M6: =J6-D6 -> 18.779429 | N6: =L6-F6 -> 40240.074 | O6: =+SUM(START:END!O6) -> 50 | P6: =IF(O6=0,0,Q6/O6) -> 2395.0896 | Q6: =+SUM(START:END!Q6) -> 119754.48 | R6: =J6-O6 -> 0 | S6: =L6-Q6 -> -17434.36
A7: =+B7&C7 -> Véhicules neufsCamions détail | B7: =+$K$1 -> Véhicules neufs | C7: Camions détail | D7: =+SUM(START:END!D7) -> 124.8698 | E7: =IF(D7=0,0,F7/D7) -> 2556.3336 | F7: =+SUM(START:END!F7) -> 319208.86 | G7: =+SUM(START:END!G7) -> 0 | H7: =IF(G7=0,0,I7/G7) -> 0 | I7: =+SUM(START:END!I7) -> 0 | J7: =+SUM(START:END!J7) -> 82 | K7: =IF(J7=0,0,L7/J7) -> 2576.8304 | L7: =+SUM(START:END!L7) -> 211300.09 | M7: =J7-D7 -> -42.869797 | N7: =L7-F7 -> -107908.77 | O7: =+SUM(START:END!O7) -> 120 | P7: =IF(O7=0,0,Q7/O7) -> 2998.4707 | Q7: =+SUM(START:END!Q7) -> 359816.49 | R7: =J7-O7 -> -38 | S7: =L7-Q7 -> -148516.4
A8: =+B8&C8 -> Véhicules neufsSprinter | B8: =+$K$1 -> Véhicules neufs | C8: Sprinter | D8: =+SUM(START:END!D8) -> 0 | E8: =IF(D8=0,0,F8/D8) -> 0 | F8: =+SUM(START:END!F8) -> 0 | G8: =+SUM(START:END!G8) -> 0 | H8: =IF(G8=0,0,I8/G8) -> 0 | I8: =+SUM(START:END!I8) -> 0 | J8: =+SUM(START:END!J8) -> 0 | K8: =IF(J8=0,0,L8/J8) -> 0 | L8: =+SUM(START:END!L8) -> 0 | M8: =J8-D8 -> 0 | N8: =L8-F8 -> 0 | O8: =+SUM(START:END!O8) -> 0 | P8: =IF(O8=0,0,Q8/O8) -> 0 | Q8: =+SUM(START:END!Q8) -> 0 | R8: =J8-O8 -> 0 | S8: =L8-Q8 -> 0
A9: =+B9&C9 -> Véhicules neufsMoto détail | B9: =+$K$1 -> Véhicules neufs | C9: Moto détail | D9: =+SUM(START:END!D9) -> 0 | E9: =IF(D9=0,0,F9/D9) -> 0 | F9: =+SUM(START:END!F9) -> 0 | G9: =+SUM(START:END!G9) -> 0 | H9: =IF(G9=0,0,I9/G9) -> 0 | I9: =+SUM(START:END!I9) -> 0 | J9: =+SUM(START:END!J9) -> 0 | K9: =IF(J9=0,0,L9/J9) -> 0 | L9: =+SUM(START:END!L9) -> 0 | M9: =J9-D9 -> 0 | N9: =L9-F9 -> 0 | O9: =+SUM(START:END!O9) -> 0 | P9: =IF(O9=0,0,Q9/O9) -> 0 | Q9: =+SUM(START:END!Q9) -> 0 | R9: =J9-O9 -> 0 | S9: =L9-Q9 -> 0
A10: =+B10&C10 -> Véhicules neufs[...] | B10: =+$K$1 -> Véhicules neufs | C10: [...] | D10: =+SUM(START:END!D10) -> 0 | E10: =IF(D10=0,0,F10/D10) -> 0 | F10: =+SUM(START:END!F10) -> 0 | G10: =+SUM(START:END!G10) -> 0 | H10: =IF(G10=0,0,I10/G10) -> 0 | I10: =+SUM(START:END!I10) -> 0 | J10: =+SUM(START:END!J10) -> 0 | K10: =IF(J10=0,0,L10/J10) -> 0 | L10: =+SUM(START:END!L10) -> 0 | M10: =J10-D10 -> 0 | N10: =L10-F10 -> 0 | O10: =+SUM(START:END!O10) -> 0 | P10: =IF(O10=0,0,Q10/O10) -> 0 | Q10: =+SUM(START:END!Q10) -> 0 | R10: =J10-O10 -> 0 | S10: =L10-Q10 -> 0
A11: =+B11&C11 -> Véhicules neufs[...] | B11: =+$K$1 -> Véhicules neufs | C11: [...] | D11: =+SUM(START:END!D11) -> 0 | E11: =IF(D11=0,0,F11/D11) -> 0 | F11: =+SUM(START:END!F11) -> 0 | G11: =+SUM(START:END!G11) -> 0 | H11: =IF(G11=0,0,I11/G11) -> 0 | I11: =+SUM(START:END!I11) -> 0 | J11: =+SUM(START:END!J11) -> 0 | K11: =IF(J11=0,0,L11/J11) -> 0 | L11: =+SUM(START:END!L11) -> 0 | M11: =J11-D11 -> 0 | N11: =L11-F11 -> 0 | O11: =+SUM(START:END!O11) -> 0 | P11: =IF(O11=0,0,Q11/O11) -> 0 | Q11: =+SUM(START:END!Q11) -> 0 | R11: =J11-O11 -> 0 | S11: =L11-Q11 -> 0
A12: =+B12&C12 -> Véhicules neufs[...] | B12: =+$K$1 -> Véhicules neufs | C12: [...] | D12: =+SUM(START:END!D12) -> 0 | E12: =IF(D12=0,0,F12/D12) -> 0 | F12: =+SUM(START:END!F12) -> 0 | G12: =+SUM(START:END!G12) -> 0 | H12: =IF(G12=0,0,I12/G12) -> 0 | I12: =+SUM(START:END!I12) -> 0 | J12: =+SUM(START:END!J12) -> 0 | K12: =IF(J12=0,0,L12/J12) -> 0 | L12: =+SUM(START:END!L12) -> 0 | M12: =J12-D12 -> 0 | N12: =L12-F12 -> 0 | O12: =+SUM(START:END!O12) -> 0 | P12: =IF(O12=0,0,Q12/O12) -> 0 | Q12: =+SUM(START:END!Q12) -> 0 | R12: =J12-O12 -> 0 | S12: =L12-Q12 -> 0
A13: =+B13&C13 -> Véhicules neufsTotal Neufs | B13: =+$K$1 -> Véhicules neufs | C13: Total Neufs | D13: =+SUM(D6:D12) -> 156.09037 | E13: =IF(D13<=0,0,F13/D13) -> 2442.7446 | F13: =+SUM(F6:F12) -> 381288.91 | G13: =+SUM(G6:G12) -> 0 | H13: =IF(G13<=0,0,I13/G13) -> 0 | I13: =+SUM(I6:I12) -> 0 | J13: =+SUM(J6:J12) -> 132 | K13: =IF(J13<=0,0,L13/J13) -> 2375.9107 | L13: =+SUM(L6:L12) -> 313620.21 | M13: =+SUM(M6:M12) -> -24.090369 | N13: =+SUM(N6:N12) -> -67668.699 | O13: =+SUM(O6:O12) -> 170 | P13: =IF(O13<=0,0,Q13/O13) -> 2821.0057 | Q13: =+SUM(Q6:Q12) -> 479570.97 | R13: =+SUM(R6:R12) -> -38 | S13: =+SUM(S6:S12) -> -165950.76
A14: =+B14&C14 -> Véhicules neufs | B14: =+$K$1 -> Véhicules neufs | M14: =IF(D13=0,0,M13/D13) -> -0.15433604 | N14: =IF(F13=0,0,N13/F13) -> -0.17747356 | R14: =R13/O13 -> -0.22352941 | S14: =IF(Q13=0,0,(S13/Q13)) -> -0.34604004
A15: =+B15&C15 -> Véhicules neufsEx-Démos et courtoisies | B15: =+$K$1 -> Véhicules neufs | C15: Ex-Démos et courtoisies | D15: =+SUM(START:END!D15) -> 7.4571429 | E15: =IF(D15=0,0,F15/D15) -> 2442.5492 | F15: =+SUM(START:END!F15) -> 18214.438 | G15: =+SUM(START:END!G15) -> 0 | H15: =IF(G15=0,0,I15/G15) -> 0 | I15: =+SUM(START:END!I15) -> 0 | J15: =+SUM(START:END!J15) -> 12 | K15: =IF(J15=0,0,L15/J15) -> 1085.3925 | L15: =+SUM(START:END!L15) -> 13024.71 | M15: =J15-D15 -> 4.5428571 | N15: =L15-F15 -> -5189.7283 | O15: =+SUM(START:END!O15) -> 6 | P15: =IF(O15=0,0,Q15/O15) -> 3041.8483 | Q15: =+SUM(START:END!Q15) -> 18251.09 | R15: =J15-O15 -> 6 | S15: =L15-Q15 -> -5226.38
A16: =+B16&C16 -> Véhicules neufs | B16: =+$K$1 -> Véhicules neufs
A17: =+B17&C17 -> Véhicules neufsFlottes | B17: =+$K$1 -> Véhicules neufs | C17: Flottes | D17: =+SUM(START:END!D17) -> 5.9657143 | E17: =IF(D17=0,0,F17/D17) -> 2442.5492 | F17: =+SUM(START:END!F17) -> 14571.551 | G17: =+SUM(START:END!G17) -> 0 | H17: =IF(G17=0,0,I17/G17) -> 0 | I17: =+SUM(START:END!I17) -> 0 | J17: =+SUM(START:END!J17) -> 6 | K17: =IF(J17=0,0,L17/J17) -> 3562.0233 | L17: =+SUM(START:END!L17) -> 21372.14 | M17: =J17-D17 -> 0.034285714 | N17: =L17-F17 -> 6800.5893 | O17: =+SUM(START:END!O17) -> 9 | P17: =IF(O17=0,0,Q17/O17) -> 2185.0778 | Q17: =+SUM(START:END!Q17) -> 19665.7 | R17: =J17-O17 -> -3 | S17: =L17-Q17 -> 1706.44
A18: =+B18&C18 -> Véhicules neufs | B18: =+$K$1 -> Véhicules neufs
A19: =+B19&C19 -> Véhicules neufsRachat bail | B19: =+$K$1 -> Véhicules neufs | C19: Rachat bail | F19: =+SUM(START:END!F19) -> 23040 | I19: =+SUM(START:END!I19) -> 0 | L19: =+SUM(START:END!L19) -> 25661.02 | N19: =L19-F19 -> 2621.02 | Q19: =+SUM(START:END!Q19) -> 47656.29 | R19: =O19-K19 -> 0 | S19: =L19-Q19 -> -21995.27
A20: =+B20&C20 -> Véhicules neufs | B20: =+$K$1 -> Véhicules neufs
A21: =+B21&C21 -> Véhicules neufsRev. Finances | B21: =+$K$1 -> Véhicules neufs | C21: Rev. Finances | D21: 0 | E21: =IF(D21=0,0,F21/D21) -> 0 | F21: =+SUM(START:END!F21) -> 28130.172 | G21: 0 | H21: =IF(G21=0,0,I21/G21) -> 0 | I21: =+SUM(START:END!I21) -> 0 | K21: =IF(J13=0,0,L21/(J13+J15)) -> 163.83465 | L21: =+SUM(START:END!L21) -> 23592.19 | N21: =L21-F21 -> -4537.982 | P21: =IF(O13=0,0,Q21/(O13+O15)) -> 194.34903 | Q21: =+SUM(START:END!Q21) -> 34205.43 | R21: =O21-K21 -> -163.83465 | S21: =L21-Q21 -> -10613.24
A22: =+B22&C22 -> Véhicules neufsRev. Protections | B22: =+$K$1 -> Véhicules neufs | C22: Rev. Protections | D22: 0 | E22: =IF(D22=0,0,F22/D22) -> 0 | F22: =+SUM(START:END!F22) -> 154715.95 | G22: 0 | H22: =IF(G22=0,0,I22/G22) -> 0 | I22: =+SUM(START:END!I22) -> 0 | K22: =IF(J13=0,0,L22/(J13+J15)) -> 1082.3578 | L22: =+SUM(START:END!L22) -> 155859.52 | N22: =L22-F22 -> 1143.5739 | P22: =IF(O13=0,0,Q22/(O13+O15)) -> 896.49438 | Q22: =+SUM(START:END!Q22) -> 157783.01 | R22: =O22-K22 -> -1082.3578 | S22: =L22-Q22 -> -1923.49
A23: =+B23&C23 -> Véhicules neufsRev. Autres | B23: =+$K$1 -> Véhicules neufs | C23: Rev. Autres | D23: 0 | E23: =IF(D23=0,0,F23/D23) -> 0 | F23: =+SUM(START:END!F23) -> 4742.8778 | G23: 0 | H23: =IF(G23=0,0,I23/G23) -> 0 | I23: =+SUM(START:END!I23) -> 0 | K23: =IF(J13=0,0,L23/(J13+J15)) -> 8.1495833 | L23: =+SUM(START:END!L23) -> 1173.54 | N23: =L23-F23 -> -3569.3378 | P23: =IF(O13=0,0,Q23/(O13+O15)) -> 24.29125 | Q23: =+SUM(START:END!Q23) -> 4275.26 | R23: =O23-K23 -> -8.1495833 | S23: =L23-Q23 -> -3101.72
A24: =+B24&C24 -> Véhicules neufsTotal F&I | B24: =+$K$1 -> Véhicules neufs | C24: Total F&I | D24: =+D15+D13 -> 163.54751 | E24: =IF(D24<=0,0,F24/D24) -> 1147 | F24: =F21+F22+F23 -> 187589 | G24: =+G15+G13 -> 0 | H24: =IF(G24<=0,0,I24/G24) -> 0 | I24: =I21+I22+I23 -> 0 | J24: =+J15+J13 -> 144 | K24: =IF(J24<=0,0,L24/J24) -> 1254.342 | L24: =L21+L22+L23 -> 180625.25 | M24: =J24-D24 -> -19.547512 | N24: =L24-F24 -> -6963.746 | O24: =+O15+O13 -> 176 | P24: =IF(O24<=0,0,Q24/O24) -> 1115.1347 | Q24: =Q21+Q22+Q23 -> 196263.7 | S24: =L24-Q24 -> -15638.45
A25: =+B25&C25 -> Véhicules neufs | B25: =+$K$1 -> Véhicules neufs | N25: =IF(N24=0,0,N24/F24) -> -0.037122359 | S25: =IF(Q24=0,0,(S24/Q24)) -> -0.079680807
A26: =+B26&C26 -> Véhicules neufs | B26: =+$K$1 -> Véhicules neufs
A27: =+B27&C27 -> Véhicules neufsTotal Dépt. Neufs | B27: =+$K$1 -> Véhicules neufs | C27: Total Dépt. Neufs | D27: =+D13+D15+D17 -> 169.51323 | E27: =IF(D27<=0,0,F27/D27) -> 3685.2811 | F27: =F13+F17+F24+F19+F15 -> 624703.89 | G27: =+G13+G15+G17 -> 0 | H27: =IF(G27<=0,0,I27/G27) -> 0 | I27: =I13+I17+I24+I19+I15 -> 0 | J27: =+J13+J15+J17 -> 150 | K27: =IF(J27<=0,0,L27/J27) -> 3695.3555 | L27: =L13+L17+L24+L19+L15 -> 554303.33 | M27: =J27-D27 -> -19.513226 | N27: =L27-F27 -> -70400.564 | O27: =+O13+O15+O17 -> 185 | P27: =IF(O27<=0,0,Q27/O27) -> 4115.7176 | Q27: =Q13+Q17+Q24+Q19+Q15 -> 761407.75 | R27: =J27-O27 -> -35 | S27: =L27-Q27 -> -207104.42
A28: =+B28&C28 -> Véhicules neufs | B28: =+$K$1 -> Véhicules neufs | M28: =M27/D27 -> -0.1151133 | N28: =N27/F27 -> -0.11269429 | R28: =R27/O27 -> -0.18918919 | S28: =IF(Q27=0,0,S27/Q27) -> -0.27200199
A29: =+B29&C29 -> Véhicules neufs | B29: =+$K$1 -> Véhicules neufs
A30: =+B30&C30 -> Véhicules neufsDEPENSES | B30: =+$K$1 -> Véhicules neufs | C30: DEPENSES
A31: =+B31&C31 -> Véhicules neufsComm. vendeurs | B31: =+$K$1 -> Véhicules neufs | C31: Comm. vendeurs | E31: =F31/D$24 -> 769.7587 | F31: =+SUM(START:END!F31) -> 125892.12 | H31: =I31/G$24 -> #DIV/0! | I31: =+SUM(START:END!I31) -> 0 | J31: =L31/L13 -> 0.3139336 | K31: =IF(L31=0,0,L31/J$24) -> 683.72167 | L31: =+SUM(START:END!L31) -> 98455.92 | N31: =L31-F31 -> -27436.2 | P31: =IF(Q31=0,0,Q31/O$24) -> 820.38722 | Q31: =+SUM(START:END!Q31) -> 144388.15 | S31: =L31-Q31 -> -45932.23
A32: =+B32&C32 -> Véhicules neufsComm. F&I | B32: =+$K$1 -> Véhicules neufs | C32: Comm. F&I | E32: =F32/D$24 -> 344.1 | F32: =+SUM(START:END!F32) -> 56276.699 | H32: =I32/G$24 -> #DIV/0! | I32: =+SUM(START:END!I32) -> 0 | J32: =L32/L24 -> 0.30029207 | K32: =IF(L32=0,0,L32/J$24) -> 376.66896 | L32: =+SUM(START:END!L32) -> 54240.33 | N32: =L32-F32 -> -2036.3688 | P32: =IF(Q32=0,0,Q32/O$24) -> 393.62602 | Q32: =+SUM(START:END!Q32) -> 69278.18 | S32: =L32-Q32 -> -15037.85
A33: =+B33&C33 -> Véhicules neufsFrais de livraison | B33: =+$K$1 -> Véhicules neufs | C33: Frais de livraison | E33: =F33/D$24 -> 113.25898 | F33: =+SUM(START:END!F33) -> 18523.224 | H33: =I33/G$24 -> #DIV/0! | I33: =+SUM(START:END!I33) -> 0 | K33: =IF(L33=0,0,L33/J$24) -> 120.79181 | L33: =+SUM(START:END!L33) -> 17394.02 | N33: =L33-F33 -> -1129.2038 | P33: =IF(Q33=0,0,Q33/O$24) -> 47.600852 | Q33: =+SUM(START:END!Q33) -> 8377.75 | S33: =L33-Q33 -> 9016.27
A34: =+B34&C34 -> Véhicules neufsService gratuit 1 | B34: =+$K$1 -> Véhicules neufs | C34: Service gratuit 1 | E34: =F34/D$24 -> 5.1177856 | F34: =+SUM(START:END!F34) -> 837.00111 | H34: =I34/G$24 -> #DIV/0! | I34: =+SUM(START:END!I34) -> 0 | K34: =IF(L34=0,0,L34/J$24) -> 2.4093056 | L34: =+SUM(START:END!L34) -> 346.94 | N34: =L34-F34 -> -490.06111 | P34: =IF(Q34=0,0,Q34/O$24) -> 1.2465341 | Q34: =+SUM(START:END!Q34) -> 219.39 | S34: =L34-Q34 -> 127.55
A35: =+B35&C35 -> Véhicules neufsEntretien stock | B35: =+$K$1 -> Véhicules neufs | C35: Entretien stock | E35: =F35/D$24 -> 105.01044 | F35: =+SUM(START:END!F35) -> 17174.197 | H35: =I35/G$24 -> #DIV/0! | I35: =+SUM(START:END!I35) -> 0 | K35: =IF(L35=0,0,L35/J$24) -> 89.936389 | L35: =+SUM(START:END!L35) -> 12950.84 | N35: =L35-F35 -> -4223.3567 | P35: =IF(Q35=0,0,Q35/O$24) -> 98.528693 | Q35: =+SUM(START:END!Q35) -> 17341.05 | S35: =L35-Q35 -> -4390.21
A36: =+B36&C36 -> Véhicules neufsPublicité 1 | B36: =+$K$1 -> Véhicules neufs | C36: Publicité 1 | E36: =F36/D$24 -> 300.75552 | F36: =+SUM(START:END!F36) -> 49187.817 | H36: =I36/G$24 -> #DIV/0! | I36: =+SUM(START:END!I36) -> 0 | K36: =IF(L36=0,0,L36/J$24) -> 94.534722 | L36: =+SUM(START:END!L36) -> 13613 | N36: =L36-F36 -> -35574.817 | P36: =IF(Q36=0,0,Q36/O$24) -> 87.593295 | Q36: =+SUM(START:END!Q36) -> 15416.42 | S36: =L36-Q36 -> -1803.42
A37: =+B37&C37 -> Véhicules neufsIntérêt de gros | B37: =+$K$1 -> Véhicules neufs | C37: Intérêt de gros | E37: =F37/D$24 -> 56.151613 | F37: =+SUM(START:END!F37) -> 9183.4566 | H37: =I37/G$24 -> #DIV/0! | I37: =+SUM(START:END!I37) -> 0 | K37: =IF(L37=0,0,L37/J$24) -> 60.152292 | L37: =+SUM(START:END!L37) -> 8661.93 | N37: =L37-F37 -> -521.52657 | P37: =IF(Q37=0,0,Q37/O$24) -> 57.844545 | Q37: =+SUM(START:END!Q37) -> 10180.64 | S37: =L37-Q37 -> -1518.71
A38: =+B38&C38 -> Véhicules neufs[...] | B38: =+$K$1 -> Véhicules neufs | C38: [...] | E38: =F38/D$24 -> 0 | F38: =+SUM(START:END!F38) -> 0 | H38: =I38/G$24 -> #DIV/0! | I38: =+SUM(START:END!I38) -> 0 | K38: =IF(L38=0,0,L38/J$24) -> 0 | L38: =+SUM(START:END!L38) -> 0 | N38: =L38-F38 -> 0 | P38: =IF(Q38=0,0,Q38/O$24) -> 0 | Q38: =+SUM(START:END!Q38) -> 0 | S38: =L38-Q38 -> 0
A39: =+B39&C39 -> Véhicules neufs[...] | B39: =+$K$1 -> Véhicules neufs | C39: [...] | E39: =F39/D$24 -> 0 | F39: =+SUM(START:END!F39) -> 0 | H39: =I39/G$24 -> #DIV/0! | I39: =+SUM(START:END!I39) -> 0 | K39: =IF(L39=0,0,L39/J$24) -> 0 | L39: =+SUM(START:END!L39) -> 0 | N39: =L39-F39 -> 0 | P39: =IF(Q39=0,0,Q39/O$24) -> 0 | Q39: =+SUM(START:END!Q39) -> 0 | S39: =L39-Q39 -> 0
A40: =+B40&C40 -> Véhicules neufs[...] | B40: =+$K$1 -> Véhicules neufs | C40: [...] | E40: =F40/D$24 -> 0 | F40: =+SUM(START:END!F40) -> 0 | H40: =I40/G$24 -> #DIV/0! | I40: =+SUM(START:END!I40) -> 0 | K40: =IF(L40=0,0,L40/J$24) -> 0 | L40: =+SUM(START:END!L40) -> 0 | N40: =L40-F40 -> 0 | P40: =IF(Q40=0,0,Q40/O$24) -> 0 | Q40: =+SUM(START:END!Q40) -> 0 | S40: =L40-Q40 -> 0
...

Sheet START

Sheet 2023-07
C1: Volks | K1: Véhicules neufs | S1: Réalisé, Juillet 2023
D2: X | E2: O | F2: U | J2: NB | L2: $ | O2: NB | Q2: $ | V2: *** NE PAS EFFACER / Pour An Précédente ***
D3: BUDGET ORIGINAL | J3: RÉALISATION | M3: ÉCART réel / Budget | O3: ANNÉE PRÉCÉDENTE | R3: ECART (réel/ Ann.Préc.) | V3: NEUF | W3: 0.45
D4: UNITÉS | E4: $P/UNITÉ | F4: $PROFITS | J4: UNITÉS | K4: $P/UNITE | L4: $PROFITS | M4: UNITÉS | N4: $PROFITS | O4: UNITÉS | P4: $P/UNITE | Q4: $PROFITS | R4: UNITÉS | S4: $PROFITS | V4: USAGE | W4: 0.1
A5: Véhicules neufsVentes nettes | B5: Véhicules neufs | C5: Ventes nettes | F5: 2357227.3 | L5: 2122186.9 | Q5: 2657067 | V5: SERVICE | W5: 0.225
A6: Véhicules neufsAutos détail | B6: Véhicules neufs | C6: Autos détail | D6: 10.048 | E6: 1988.434 | F6: 19979.785 | J6: 12 | K6: 1882.1942 | L6: 22586.33 | M6: 1.952 | N6: 2606.5452 | O6: 13 | P6: 2819.2123 | Q6: 36649.76 | R6: -1 | S6: -14063.43 | V6: CARROSSERIE | W6: 0.025
A7: Véhicules neufsCamions détail | B7: Véhicules neufs | C7: Camions détail | D7: 40.187981 | E7: 2556.3336 | F7: 102733.89 | J7: 24 | K7: 2577.0196 | L7: 61848.47 | M7: -16.187981 | N7: -40885.417 | O7: 37 | P7: 3278.5565 | Q7: 121306.59 | R7: -13 | S7: -59458.12 | V7: PIECES | W7: 0.2
A8: Véhicules neufsSprinter | B8: Véhicules neufs | C8: Sprinter | D8: 0 | E8: 0 | F8: 0 | J8: 0 | K8: 0 | L8: 0 | M8: 0 | N8: 0 | O8: 0 | P8: 0 | Q8: 0 | R8: 0 | S8: 0 | W8: 1
A9: Véhicules neufsMoto détail | B9: Véhicules neufs | C9: Moto détail | D9: 0 | E9: 0 | F9: 0 | J9: 0 | K9: 0 | L9: 0 | M9: 0 | N9: 0 | O9: 0 | P9: 0 | Q9: 0 | R9: 0 | S9: 0
A10: Véhicules neufs[...] | B10: Véhicules neufs | C10: [...] | D10: 0 | E10: 0 | F10: 0 | J10: 0 | K10: 0 | L10: 0 | M10: 0 | N10: 0 | O10: 0 | P10: 0 | Q10: 0 | R10: 0 | S10: 0
A11: Véhicules neufs[...] | B11: Véhicules neufs | C11: [...] | D11: 0 | E11: 0 | F11: 0 | J11: 0 | K11: 0 | L11: 0 | M11: 0 | N11: 0 | O11: 0 | P11: 0 | Q11: 0 | R11: 0 | S11: 0
A12: Véhicules neufs[...] | B12: Véhicules neufs | C12: [...] | D12: 0 | E12: 0 | F12: 0 | J12: 0 | K12: 0 | L12: 0 | M12: 0 | N12: 0 | O12: 0 | P12: 0 | Q12: 0 | R12: 0 | S12: 0
A13: Véhicules neufsTotal Neufs | B13: Véhicules neufs | C13: Total Neufs | D13: 50.235981 | E13: 2442.7446 | F13: 122713.67 | J13: 36 | K13: 2345.4111 | L13: 84434.8 | M13: -14.235981 | N13: -38278.872 | O13: 50 | P13: 3159.127 | Q13: 157956.35 | R13: -14 | S13: -73521.55
A14: Véhicules neufs | B14: Véhicules neufs | M14: -0.28338216 | N14: -0.31193649 | R14: -0.28 | S14: -0.46545486 | AD14: 20 | AE14: 1000 | AF14: 20000
A15: Véhicules neufsEx-Démos et courtoisies | B15: Véhicules neufs | C15: Ex-Démos et courtoisies | D15: 2.4 | E15: 2442.5492 | F15: 5862.1181 | J15: 3 | K15: 851.18 | L15: 2553.54 | M15: 0.6 | N15: -3308.5781 | O15: 3 | P15: 2992.6 | Q15: 8977.8 | R15: 0 | S15: -6424.26 | AD15: 25 | AE15: 800 | AF15: 20000
A16: Véhicules neufs | B16: Véhicules neufs
A17: Véhicules neufsFlottes | B17: Véhicules neufs | C17: Flottes | D17: 1.92 | E17: 2442.5492 | F17: 4689.6945 | J17: 1 | K17: 4279.05 | L17: 4279.05 | M17: -0.92 | N17: -410.64446 | O17: 2 | P17: 4190.8 | Q17: 8381.6 | R17: -1 | S17: -4102.55 | V17: 87267.39
A18: Véhicules neufs | B18: Véhicules neufs | V18: 0.37581129
A19: Véhicules neufsRachat bail | B19: Véhicules neufs | C19: Rachat bail | D19: 0 | E19: 0 | F19: 9600 | L19: 9971 | N19: 371 | Q19: 13968.33 | R19: 0 | S19: -3997.33
A20: Véhicules neufs | B20: Véhicules neufs
A21: Véhicules neufsRev. Finances | B21: Véhicules neufs | C21: Rev. Finances | D21: 0 | E21: 0 | F21: 9053.3887 | K21: 247.8859 | L21: 9667.55 | N21: 614.1613 | P21: 208.71698 | Q21: 11062 | R21: -247.8859 | S21: -1394.45
A22: Véhicules neufsRev. Protections | B22: Véhicules neufs | C22: Rev. Protections | D22: 0 | E22: 0 | F22: 49793.638 | K22: 1110.4236 | L22: 43306.52 | N22: -6487.1178 | P22: 1043.6472 | Q22: 55313.3 | R22: -1110.4236 | S22: -12006.78
A23: Véhicules neufsRev. Autres | B23: Véhicules neufs | C23: Rev. Autres | D23: 0 | E23: 0 | F23: 1526.4434 | K23: 0 | L23: 0 | N23: -1526.4434 | P23: 26.998868 | Q23: 1430.94 | R23: 0 | S23: -1430.94
A24: Véhicules neufsTotal F&I | B24: Véhicules neufs | C24: Total F&I | D24: 52.635981 | E24: 1147 | F24: 60373.47 | J24: 39 | K24: 1358.3095 | L24: 52974.07 | M24: -13.635981 | N24: -7399.4 | O24: 53 | P24: 1279.363 | Q24: 67806.24 | S24: -14832.17
A25: Véhicules neufs | B25: Véhicules neufs | N25: -0.12256046 | S25: -0.21874344
A26: Véhicules neufs | B26: Véhicules neufs
A27: Véhicules neufsTotal Dépt. Neufs | B27: Véhicules neufs | C27: Total Dépt. Neufs | D27: 54.555981 | E27: 3725.3286 | F27: 203238.95 | J27: 40 | K27: 3855.3115 | L27: 154212.46 | M27: -14.555981 | N27: -49026.494 | O27: 55 | P27: 4674.3695 | Q27: 257090.32 | R27: -15 | S27: -102877.86
A28: Véhicules neufs | B28: Véhicules neufs | L28: 0.75877413 | M28: -0.26680816 | N28: -0.24122587 | R28: -0.27272727 | S28: -0.40016232
A29: Véhicules neufs | B29: Véhicules neufs
A30: Véhicules neufsDEPENSES | B30: Véhicules neufs | C30: DEPENSES
A31: Véhicules neufsComm. vendeurs | B31: Véhicules neufs | C31: Comm. vendeurs | D31: 0.30450317 | E31: 770.95101 | F31: 40579.763 | J31: 0.3593405 | K31: 840.92487 | L31: 32796.07 | N31: -7783.6926 | P31: 1067.6589 | Q31: 56585.92 | S31: -23789.85
A32: Véhicules neufsComm. F&I | B32: Véhicules neufs | C32: Comm. F&I | D32: 0.3 | E32: 344.1 | F32: 18112.041 | J32: 0.30073846 | K32: 408.4959 | L32: 15931.34 | N32: -2180.701 | P32: 423.97528 | Q32: 22470.69 | S32: -6539.35 | U32: 0.26707524 | V32: <<- F&A total Neuf Usagé Rachat | X32: 14148.063 | Y32: 1783.2773
A33: Véhicules neufsFrais de livraison | B33: Véhicules neufs | C33: Frais de livraison | E33: 113.25898 | F33: 5961.4973 | K33: 168.41974 | L33: 6568.37 | N33: 606.87268 | P33: 145.86774 | Q33: 7730.99 | S33: -1162.62
A34: Véhicules neufsService gratuit 1 | B34: Véhicules neufs | C34: Service gratuit 1 | E34: 5.1177856 | F34: 269.37967 | K34: 1.025641 | L34: 40 | N34: -229.37967 | P34: 3.5922642 | Q34: 190.39 | S34: -150.39
A35: Véhicules neufsEntretien stock | B35: Véhicules neufs | C35: Entretien stock | E35: 105.01044 | F35: 5527.3277 | K35: 118.07769 | L35: 4605.03 | N35: -922.29768 | P35: 176.23962 | Q35: 9340.7 | S35: -4735.67
A36: Véhicules neufsPublicité 1 | B36: Véhicules neufs | C36: Publicité 1 | E36: 300.75552 | F36: 15830.562 | K36: 154.58692 | L36: 6028.89 | N36: -9801.6719 | P36: 185.94774 | Q36: 9855.23 | S36: -3826.34
A37: Véhicules neufsIntérêt de gros | B37: Véhicules neufs | C37: Intérêt de gros | E37: 50.687592 | F37: 2667.9911 | K37: 90.482564 | L37: 3528.82 | N37: 860.82887 | P37: 21.345283 | Q37: 1131.3 | S37: 2397.52
A38: Véhicules neufs[...] | B38: Véhicules neufs | C38: [...] | E38: 0 | F38: 0 | K38: 0 | L38: 0 | N38: 0 | P38: 0 | Q38: 0 | S38: 0
A39: Véhicules neufs[...] | B39: Véhicules neufs | C39: [...] | E39: 0 | F39: 0 | K39: 0 | L39: 0 | N39: 0 | P39: 0 | Q39: 0 | S39: 0
A40: Véhicules neufs[...] | B40: Véhicules neufs | C40: [...] | E40: 0 | F40: 0 | K40: 0 | L40: 0 | N40: 0 | P40: 0 | Q40: 0 | S40: 0
...

Sheet 2023-08
C1: Volks | K1: Véhicules neufs | S1: Réalisé, Août 2023
D2: X | E2: O | F2: U | J2: NB | L2: $ | O2: NB | Q2: $ | V2: *** NE PAS EFFACER / Pour An Précédente ***
D3: BUDGET ORIGINAL | J3: RÉALISATION | M3: ÉCART réel / Budget | O3: ANNÉE PRÉCÉDENTE | R3: ECART (réel/ Ann.Préc.) | V3: NEUF | W3: 0.45
D4: UNITÉS | E4: $P/UNITÉ | F4: $PROFITS | J4: UNITÉS | K4: $P/UNITE | L4: $PROFITS | M4: UNITÉS | N4: $PROFITS | O4: UNITÉS | P4: $P/UNITE | Q4: $PROFITS | R4: UNITÉS | S4: $PROFITS | V4: USAGE | W4: 0.1
A5: Véhicules neufsVentes nettes | B5: Véhicules neufs | C5: Ventes nettes | F5: 2438191.1 | L5: 2567524.5 | Q5: 3632125.1 | V5: SERVICE | W5: 0.225
A6: Véhicules neufsAutos détail | B6: Véhicules neufs | C6: Autos détail | D6: 10.406857 | E6: 1988.434 | F6: 20693.349 | J6: 21 | K6: 2336.3824 | L6: 49064.03 | M6: 10.593143 | N6: 28370.681 | O6: 21 | P6: 2507.92 | Q6: 52666.32 | R6: 0 | S6: -3602.29 | V6: CARROSSERIE | W6: 0.025
A7: Véhicules neufsCamions détail | B7: Véhicules neufs | C7: Camions détail | D7: 41.623266 | E7: 2556.3336 | F7: 106402.95 | J7: 22 | K7: 2712.29 | L7: 59670.38 | M7: -19.623266 | N7: -46732.574 | O7: 50 | P7: 3039.8858 | Q7: 151994.29 | R7: -28 | S7: -92323.91 | V7: PIECES | W7: 0.2
A8: Véhicules neufsSprinter | B8: Véhicules neufs | C8: Sprinter | D8: 0 | E8: 0 | F8: 0 | J8: 0 | K8: 0 | L8: 0 | M8: 0 | N8: 0 | O8: 0 | P8: 0 | Q8: 0 | R8: 0 | S8: 0 | W8: 1
A9: Véhicules neufsMoto détail | B9: Véhicules neufs | C9: Moto détail | D9: 0 | E9: 0 | F9: 0 | J9: 0 | K9: 0 | L9: 0 | M9: 0 | N9: 0 | O9: 0 | P9: 0 | Q9: 0 | R9: 0 | S9: 0
A10: Véhicules neufs[...] | B10: Véhicules neufs | C10: [...] | D10: 0 | E10: 0 | F10: 0 | J10: 0 | K10: 0 | L10: 0 | M10: 0 | N10: 0 | O10: 0 | P10: 0 | Q10: 0 | R10: 0 | S10: 0
A11: Véhicules neufs[...] | B11: Véhicules neufs | C11: [...] | D11: 0 | E11: 0 | F11: 0 | J11: 0 | K11: 0 | L11: 0 | M11: 0 | N11: 0 | O11: 0 | P11: 0 | Q11: 0 | R11: 0 | S11: 0
A12: Véhicules neufs[...] | B12: Véhicules neufs | C12: [...] | D12: 0 | E12: 0 | F12: 0 | J12: 0 | K12: 0 | L12: 0 | M12: 0 | N12: 0 | O12: 0 | P12: 0 | Q12: 0 | R12: 0 | S12: 0
A13: Véhicules neufsTotal Neufs | B13: Véhicules neufs | C13: Total Neufs | D13: 52.030123 | E13: 2442.7446 | F13: 127096.3 | J13: 43 | K13: 2528.7072 | L13: 108734.41 | M13: -9.030123 | N13: -18361.893 | O13: 71 | P13: 2882.5438 | Q13: 204660.61 | R13: -28 | S13: -95926.2
A14: Véhicules neufs | B14: Véhicules neufs | M14: -0.17355567 | N14: -0.14447228 | R14: -0.3943662 | S14: -0.46870866 | AD14: 20 | AE14: 1000 | AF14: 20000
A15: Véhicules neufsEx-Démos et courtoisies | B15: Véhicules neufs | C15: Ex-Démos et courtoisies | D15: 2.4857143 | E15: 2442.5492 | F15: 6071.4794 | J15: 8 | K15: 1186.9175 | L15: 9495.34 | M15: 5.5142857 | N15: 3423.8606 | O15: 2 | P15: 4516.805 | Q15: 9033.61 | R15: 6 | S15: 461.73 | AD15: 25 | AE15: 800 | AF15: 20000
A16: Véhicules neufs | B16: Véhicules neufs
A17: Véhicules neufsFlottes | B17: Véhicules neufs | C17: Flottes | D17: 1.9885714 | E17: 2442.5492 | F17: 4857.1836 | J17: 4 | K17: 3473.7725 | L17: 13895.09 | M17: 2.0114286 | N17: 9037.9064 | O17: 4 | P17: 1549.0925 | Q17: 6196.37 | R17: 0 | S17: 7698.72 | V17: 128124.84
A18: Véhicules neufs | B18: Véhicules neufs | V18: 0.32626078
A19: Véhicules neufsRachat bail | B19: Véhicules neufs | C19: Rachat bail | D19: 0 | E19: 0 | F19: 6720 | L19: 7757.94 | N19: 1037.94 | Q19: 19995.21 | R19: 0 | S19: -12237.27
A20: Véhicules neufs | B20: Véhicules neufs
A21: Véhicules neufsRev. Finances | B21: Véhicules neufs | C21: Rev. Finances | D21: 0 | E21: 0 | F21: 9376.724 | K21: 175.29412 | L21: 8940 | N21: -436.72401 | P21: 172.24973 | Q21: 12574.23 | R21: -175.29412 | S21: -3634.23
A22: Véhicules neufsRev. Protections | B22: Véhicules neufs | C22: Rev. Protections | D22: 0 | E22: 0 | F22: 51571.982 | K22: 1030.0339 | L22: 52531.73 | N22: 959.74795 | P22: 810.39493 | Q22: 59158.83 | R22: -1030.0339 | S22: -6627.1
A23: Véhicules neufsRev. Autres | B23: Véhicules neufs | C23: Rev. Autres | D23: 0 | E23: 0 | F23: 1580.9593 | K23: 12.943529 | L23: 660.12 | N23: -920.83928 | P23: 16.719726 | Q23: 1220.54 | R23: -12.943529 | S23: -560.42
A24: Véhicules neufsTotal F&I | B24: Véhicules neufs | C24: Total F&I | D24: 54.515837 | E24: 1147 | F24: 62529.665 | J24: 51 | K24: 1218.2716 | L24: 62131.85 | M24: -3.5158373 | N24: -397.81533 | O24: 73 | P24: 999.36438 | Q24: 72953.6 | S24: -10821.75
A25: Véhicules neufs | B25: Véhicules neufs | N25: -0.0063620256 | S25: -0.14833744
A26: Véhicules neufs | B26: Véhicules neufs
A27: Véhicules neufsTotal Dépt. Neufs | B27: Véhicules neufs | C27: Total Dépt. Neufs | D27: 56.504409 | E27: 3668.2913 | F27: 207274.63 | J27: 55 | K27: 3672.9933 | L27: 202014.63 | M27: -1.5044087 | N27: -5260.0013 | O27: 77 | P27: 4062.8494 | Q27: 312839.4 | R27: -22 | S27: -110824.77
A28: Véhicules neufs | B28: Véhicules neufs | L28: 0.97462303 | M28: -0.026624625 | N28: -0.025376966 | R28: -0.28571429 | S28: -0.35425452
A29: Véhicules neufs | B29: Véhicules neufs
A30: Véhicules neufsDEPENSES | B30: Véhicules neufs | C30: DEPENSES
A31: Véhicules neufsComm. vendeurs | B31: Véhicules neufs | C31: Comm. vendeurs | D31: 0.30577106 | E31: 774.16109 | F31: 42204.04 | J31: 0.31638343 | K31: 819.64922 | L31: 41802.11 | N31: -401.92986 | P31: 676.68315 | Q31: 49397.87 | S31: -7595.76
A32: Véhicules neufsComm. F&I | B32: Véhicules neufs | C32: Comm. F&I | D32: 0.3 | E32: 344.1 | F32: 18758.9 | J32: 0.2998974 | K32: 365.35647 | L32: 18633.18 | N32: -125.7196 | P32: 376.9889 | Q32: 27520.19 | S32: -8887.01 | U32: 0.2844261 | V32: <<- F&A total Neuf Usagé Rachat | X32: 17671.92 | Y32: 961.26013
A33: Véhicules neufsFrais de livraison | B33: Véhicules neufs | C33: Frais de livraison | E33: 113.25898 | F33: 6174.4079 | K33: 121.67235 | L33: 6205.29 | N33: 30.88206 | P33: 24.27137 | Q33: 1771.81 | S33: 4433.48
A34: Véhicules neufsService gratuit 1 | B34: Véhicules neufs | C34: Service gratuit 1 | E34: 5.1177856 | F34: 279.00037 | K34: 1.8039216 | L34: 92 | N34: -187.00037 | P34: 0 | Q34: 0 | S34: 92
A35: Véhicules neufsEntretien stock | B35: Véhicules neufs | C35: Entretien stock | E35: 105.01044 | F35: 5724.7322 | K35: 78.708235 | L35: 4014.12 | N35: -1710.6122 | P35: 60.332329 | Q35: 4404.26 | S35: -390.14
A36: Véhicules neufsPublicité 1 | B36: Véhicules neufs | C36: Publicité 1 | E36: 300.75552 | F36: 16395.939 | K36: 40.121961 | L36: 2046.22 | N36: -14349.719 | P36: 48.655068 | Q36: 3551.82 | S36: -1505.6
A37: Véhicules neufsIntérêt de gros | B37: Véhicules neufs | C37: Intérêt de gros | E37: 53.963736 | F37: 2941.8783 | K37: 0 | L37: 0 | N37: -2941.8783 | P37: 51.69 | Q37: 3773.37 | S37: -3773.37
A38: Véhicules neufs[...] | B38: Véhicules neufs | C38: [...] | E38: 0 | F38: 0 | K38: 0 | L38: 0 | N38: 0 | P38: 0 | Q38: 0 | S38: 0
A39: Véhicules neufs[...] | B39: Véhicules neufs | C39: [...] | E39: 0 | F39: 0 | K39: 0 | L39: 0 | N39: 0 | P39: 0 | Q39: 0 | S39: 0
A40: Véhicules neufs[...] | B40: Véhicules neufs | C40: [...] | E40: 0 | F40: 0 | K40: 0 | L40: 0 | N40: 0 | P40: 0 | Q40: 0 | S40: 0
...

Sheet 2023-09
C1: Volks | K1: Véhicules neufs | S1: Réalisé, Septembre 2023
D2: X | E2: O | F2: U | J2: NB | L2: $ | O2: NB | Q2: $ | V2: *** NE PAS EFFACER / Pour An Précédente ***
D3: BUDGET ORIGINAL | J3: RÉALISATION | M3: ÉCART réel / Budget | O3: ANNÉE PRÉCÉDENTE | R3: ECART (réel/ Ann.Préc.) | V3: NEUF | W3: 0.45
D4: UNITÉS | E4: $P/UNITÉ | F4: $PROFITS | J4: UNITÉS | K4: $P/UNITE | L4: $PROFITS | M4: UNITÉS | N4: $PROFITS | O4: UNITÉS | P4: $P/UNITE | Q4: $PROFITS | R4: UNITÉS | S4: $PROFITS | V4: USAGE | W4: 0.1
A5: Véhicules neufsVentes nettes | B5: Véhicules neufs | C5: Ventes nettes | F5: 2522034.9 | L5: 2612584.6 | Q5: 2490545.3 | V5: SERVICE | W5: 0.225
A6: Véhicules neufsAutos détail | B6: Véhicules neufs | C6: Autos détail | D6: 10.765714 | E6: 1988.434 | F6: 21406.912 | J6: 17 | K6: 1804.1035 | L6: 30669.76 | M6: 6.2342857 | N6: 9262.8477 | O6: 16 | P6: 1902.4 | Q6: 30438.4 | R6: 1 | S6: 231.36 | V6: CARROSSERIE | W6: 0.025
A7: Véhicules neufsCamions détail | B7: Véhicules neufs | C7: Camions détail | D7: 43.058551 | E7: 2556.3336 | F7: 110072.02 | J7: 36 | K7: 2493.9233 | L7: 89781.24 | M7: -7.0585509 | N7: -20290.782 | O7: 33 | P7: 2621.6852 | Q7: 86515.61 | R7: 3 | S7: 3265.63 | V7: PIECES | W7: 0.2
A8: Véhicules neufsSprinter | B8: Véhicules neufs | C8: Sprinter | D8: 0 | E8: 0 | F8: 0 | J8: 0 | K8: 0 | L8: 0 | M8: 0 | N8: 0 | O8: 0 | P8: 0 | Q8: 0 | R8: 0 | S8: 0 | W8: 1
A9: Véhicules neufsMoto détail | B9: Véhicules neufs | C9: Moto détail | D9: 0 | E9: 0 | F9: 0 | J9: 0 | K9: 0 | L9: 0 | M9: 0 | N9: 0 | O9: 0 | P9: 0 | Q9: 0 | R9: 0 | S9: 0
A10: Véhicules neufs[...] | B10: Véhicules neufs | C10: [...] | D10: 0 | E10: 0 | F10: 0 | J10: 0 | K10: 0 | L10: 0 | M10: 0 | N10: 0 | O10: 0 | P10: 0 | Q10: 0 | R10: 0 | S10: 0
A11: Véhicules neufs[...] | B11: Véhicules neufs | C11: [...] | D11: 0 | E11: 0 | F11: 0 | J11: 0 | K11: 0 | L11: 0 | M11: 0 | N11: 0 | O11: 0 | P11: 0 | Q11: 0 | R11: 0 | S11: 0
A12: Véhicules neufs[...] | B12: Véhicules neufs | C12: [...] | D12: 0 | E12: 0 | F12: 0 | J12: 0 | K12: 0 | L12: 0 | M12: 0 | N12: 0 | O12: 0 | P12: 0 | Q12: 0 | R12: 0 | S12: 0
A13: Véhicules neufsTotal Neufs | B13: Véhicules neufs | C13: Total Neufs | D13: 53.824265 | E13: 2442.7446 | F13: 131478.93 | J13: 53 | K13: 2272.6604 | L13: 120451 | M13: -0.82426514 | N13: -11027.934 | O13: 49 | P13: 2386.8165 | Q13: 116954.01 | R13: 4 | S13: 3496.99
A14: Véhicules neufs | B14: Véhicules neufs | M14: -0.015314006 | N14: -0.083876053 | R14: 0.081632653 | S14: 0.029900557 | AD14: 20 | AE14: 1000 | AF14: 20000
A15: Véhicules neufsEx-Démos et courtoisies | B15: Véhicules neufs | C15: Ex-Démos et courtoisies | D15: 2.5714286 | E15: 2442.5492 | F15: 6280.8408 | J15: 1 | K15: 975.83 | L15: 975.83 | M15: -1.5714286 | N15: -5305.0108 | O15: 1 | P15: 239.68 | Q15: 239.68 | R15: 0 | S15: 736.15 | AD15: 25 | AE15: 800 | AF15: 20000
A16: Véhicules neufs | B16: Véhicules neufs
A17: Véhicules neufsFlottes | B17: Véhicules neufs | C17: Flottes | D17: 2.0571429 | E17: 2442.5492 | F17: 5024.6726 | J17: 1 | K17: 3198 | L17: 3198 | M17: -1.0571429 | N17: -1826.6726 | O17: 3 | P17: 1695.91 | Q17: 5087.73 | R17: -2 | S17: -1889.73 | V17: 120624.83
A18: Véhicules neufs | B18: Véhicules neufs | V18: 0.19778465
A19: Véhicules neufsRachat bail | B19: Véhicules neufs | C19: Rachat bail | D19: 0 | E19: 0 | F19: 6720 | L19: 7932.08 | N19: 1212.08 | Q19: 13692.75 | R19: 0 | S19: -5760.67
A20: Véhicules neufs | B20: Véhicules neufs
A21: Véhicules neufsRev. Finances | B21: Véhicules neufs | C21: Rev. Finances | D21: 0 | E21: 0 | F21: 9700.0593 | K21: 92.308148 | L21: 4984.64 | N21: -4715.4193 | P21: 211.384 | Q21: 10569.2 | R21: -92.308148 | S21: -5584.56
A22: Véhicules neufsRev. Protections | B22: Véhicules neufs | C22: Rev. Protections | D22: 0 | E22: 0 | F22: 53350.326 | K22: 1111.505 | L22: 60021.27 | N22: 6670.9437 | P22: 866.2176 | Q22: 43310.88 | R22: -1111.505 | S22: 16710.39
A23: Véhicules neufsRev. Autres | B23: Véhicules neufs | C23: Rev. Autres | D23: 0 | E23: 0 | F23: 1635.4751 | K23: 9.5077778 | L23: 513.42 | N23: -1122.0551 | P23: 32.4756 | Q23: 1623.78 | R23: -9.5077778 | S23: -1110.36
A24: Véhicules neufsTotal F&I | B24: Véhicules neufs | C24: Total F&I | D24: 56.395694 | E24: 1147 | F24: 64685.861 | J24: 54 | K24: 1213.3209 | L24: 65519.33 | M24: -2.3956937 | N24: 833.46931 | O24: 50 | P24: 1110.0772 | Q24: 55503.86 | S24: 10015.47
A25: Véhicules neufs | B25: Véhicules neufs | N25: 0.012884876 | S25: 0.18044637
A26: Véhicules neufs | B26: Véhicules neufs
A27: Véhicules neufsTotal Dépt. Neufs | B27: Véhicules neufs | C27: Total Dépt. Neufs | D27: 58.452837 | E27: 3664.327 | F27: 214190.31 | J27: 55 | K27: 3601.3862 | L27: 198076.24 | M27: -3.4528366 | N27: -16114.068 | O27: 53 | P27: 3612.793 | Q27: 191478.03 | R27: 2 | S27: 6598.21
A28: Véhicules neufs | B28: Véhicules neufs | L28: 0.92476752 | M28: -0.059070471 | N28: -0.075232481 | R28: 0.037735849 | S28: 0.034459358
A29: Véhicules neufs | B29: Véhicules neufs
A30: Véhicules neufsDEPENSES | B30: Véhicules neufs | C30: DEPENSES
A31: Véhicules neufsComm. vendeurs | B31: Véhicules neufs | C31: Comm. vendeurs | D31: 0.30191185 | E31: 764.39023 | F31: 43108.317 | J31: 0.19143649 | K31: 441.81 | L31: 23857.74 | N31: -19250.577 | P31: 768.0872 | Q31: 38404.36 | S31: -14546.62
A32: Véhicules neufsComm. F&I | B32: Véhicules neufs | C32: Comm. F&I | D32: 0.3 | E32: 344.1 | F32: 19405.758 | J32: 0.30030542 | K32: 364.36685 | L32: 19675.81 | N32: 270.05179 | P32: 385.746 | Q32: 19287.3 | S32: 388.51 | U32: 0.2823413 | V32: <<- F&A total Neuf Usagé Rachat | X32: 18498.813 | Y32: 1176.997
A33: Véhicules neufsFrais de livraison | B33: Véhicules neufs | C33: Frais de livraison | E33: 113.25898 | F33: 6387.3186 | K33: 85.562222 | L33: 4620.36 | N33: -1766.9586 | P33: -22.501 | Q33: -1125.05 | S33: 5745.41
A34: Véhicules neufsService gratuit 1 | B34: Véhicules neufs | C34: Service gratuit 1 | E34: 5.1177856 | F34: 288.62107 | K34: 3.9803704 | L34: 214.94 | N34: -73.681072 | P34: 0.58 | Q34: 29 | S34: 185.94
A35: Véhicules neufsEntretien stock | B35: Véhicules neufs | C35: Entretien stock | E35: 105.01044 | F35: 5922.1368 | K35: 80.216481 | L35: 4331.69 | N35: -1590.4468 | P35: 71.9218 | Q35: 3596.09 | S35: 735.6
A36: Véhicules neufsPublicité 1 | B36: Véhicules neufs | C36: Publicité 1 | E36: 300.75552 | F36: 16961.316 | K36: 102.55352 | L36: 5537.89 | N36: -11423.426 | P36: 40.1874 | Q36: 2009.37 | S36: 3528.52
A37: Véhicules neufsIntérêt de gros | B37: Véhicules neufs | C37: Intérêt de gros | E37: 63.366313 | F37: 3573.5872 | K37: 95.057593 | L37: 5133.11 | N37: 1559.5228 | P37: 105.5194 | Q37: 5275.97 | S37: -142.86
A38: Véhicules neufs[...] | B38: Véhicules neufs | C38: [...] | E38: 0 | F38: 0 | K38: 0 | L38: 0 | N38: 0 | P38: 0 | Q38: 0 | S38: 0
A39: Véhicules neufs[...] | B39: Véhicules neufs | C39: [...] | E39: 0 | F39: 0 | K39: 0 | L39: 0 | N39: 0 | P39: 0 | Q39: 0 | S39: 0
A40: Véhicules neufs[...] | B40: Véhicules neufs | C40: [...] | E40: 0 | F40: 0 | K40: 0 | L40: 0 | N40: 0 | P40: 0 | Q40: 0 | S40: 0
...

Sheet END
